Workbook

Sheet Instances
B1: memelingo-1/all-opts_mlp-tplp-ht_15_100 | F1: memelingo-1/all-opts_mlp-tplp-ht_15_150 | J1: memelingo-1/all-opts_mlp-tplp-ht_15_200 | N1: memelingo-1/all-opts_mlp-tplp-ht_15_30 | R1: memelingo-1/all-opts_mlp-tplp-ht_15_50 | V1: memelingo-1/all-opts_mlp-tplp-ht_20_100 | Z1: memelingo-1/all-opts_mlp-tplp-ht_20_150 | AD1: memelingo-1/all-opts_mlp-tplp-ht_20_200 | AH1: memelingo-1/all-opts_mlp-tplp-ht_20_30 | AL1: memelingo-1/all-opts_mlp-tplp-ht_20_50 | AP1: memelingo-1/all-opts_mlp-tplp-ht_25_100 | AT1: memelingo-1/all-opts_mlp-tplp-ht_25_150 | AX1: memelingo-1/all-opts_mlp-tplp-ht_25_200 | BB1: memelingo-1/all-opts_mlp-tplp-ht_25_30 | BF1: memelingo-1/all-opts_mlp-tplp-ht_25_50 | BJ1: memelingo-1/all-opts_mlp-tplp-ht_30_100 | BN1: memelingo-1/all-opts_mlp-tplp-ht_30_150 | BR1: memelingo-1/all-opts_mlp-tplp-ht_30_200 | BV1: memelingo-1/all-opts_mlp-tplp-ht_30_30 | BZ1: memelingo-1/all-opts_mlp-tplp-ht_30_50 | CD1: memelingo-1/all-opts_mlp-tplp-ht_35_100 | CH1: memelingo-1/all-opts_mlp-tplp-ht_35_150 | CL1: memelingo-1/all-opts_mlp-tplp-ht_35_200 | CP1: memelingo-1/all-opts_mlp-tplp-ht_35_30 | CT1: memelingo-1/all-opts_mlp-tplp-ht_35_50 | CX1: memelingo-1/all-opts_mlp-tplp-htc_15_100 | DB1: memelingo-1/all-opts_mlp-tplp-htc_15_150 | DF1: memelingo-1/all-opts_mlp-tplp-htc_15_200 | DJ1: memelingo-1/all-opts_mlp-tplp-htc_15_30 | DN1: memelingo-1/all-opts_mlp-tplp-htc_15_50 | DR1: memelingo-1/all-opts_mlp-tplp-htc_20_100 | DV1: memelingo-1/all-opts_mlp-tplp-htc_20_150 | DZ1: memelingo-1/all-opts_mlp-tplp-htc_20_200 | ED1: memelingo-1/all-opts_mlp-tplp-htc_20_30 | EH1: memelingo-1/all-opts_mlp-tplp-htc_20_50 | EL1: memelingo-1/all-opts_mlp-tplp-htc_25_100 | EP1: memelingo-1/all-opts_mlp-tplp-htc_25_150 | ET1: memelingo-1/all-opts_mlp-tplp-htc_25_200 | EX1: memelingo-1/all-opts_mlp-tplp-htc_25_30 | FB1: memelingo-1/all-opts_mlp-tplp-htc_25_50 | FF1: memelingo-1/all-opts_mlp-tplp-htc_30_100 | FJ1: memelingo-1/all-opts_mlp-tplp-htc_30_150 | FN1: memelingo-1/all-opts_mlp-tplp-htc_30_200 | FR1: memelingo-1/all-opts_mlp-tplp-htc_30_30 | FV1: memelingo-1/all-opts_mlp-tplp-htc_30_50 | FZ1: memelingo-1/all-opts_mlp-tplp-htc_35_100 | GD1: memelingo-1/all-opts_mlp-tplp-htc_35_150 | GH1: memelingo-1/all-opts_mlp-tplp-htc_35_200 | GL1: memelingo-1/all-opts_mlp-tplp-htc_35_30 | GP1: memelingo-1/all-opts_mlp-tplp-htc_35_50 | GT1: memelingo-1/all-opts_mlp-tplp-htcdl_15_100 | GX1: memelingo-1/all-opts_mlp-tplp-htcdl_15_150 | HB1: memelingo-1/all-opts_mlp-tplp-htcdl_15_200 | HF1: memelingo-1/all-opts_mlp-tplp-htcdl_15_30 | HJ1: memelingo-1/all-opts_mlp-tplp-htcdl_15_50 | HN1: memelingo-1/all-opts_mlp-tplp-htcdl_20_100 | HR1: memelingo-1/all-opts_mlp-tplp-htcdl_20_150 | HV1: memelingo-1/all-opts_mlp-tplp-htcdl_20_200 | HZ1: memelingo-1/all-opts_mlp-tplp-htcdl_20_30 | ID1: memelingo-1/all-opts_mlp-tplp-htcdl_20_50 | IH1: memelingo-1/all-opts_mlp-tplp-htcdl_25_100 | IL1: memelingo-1/all-opts_mlp-tplp-htcdl_25_150 | IP1: memelingo-1/all-opts_mlp-tplp-htcdl_25_200 | IT1: memelingo-1/all-opts_mlp-tplp-htcdl_25_30 | IX1: memelingo-1/all-opts_mlp-tplp-htcdl_25_50 | JB1: memelingo-1/all-opts_mlp-tplp-htcdl_30_100 | JF1: memelingo-1/all-opts_mlp-tplp-htcdl_30_150 | JJ1: memelingo-1/all-opts_mlp-tplp-htcdl_30_200 | JN1: memelingo-1/all-opts_mlp-tplp-htcdl_30_30 | JR1: memelingo-1/all-opts_mlp-tplp-htcdl_30_50 | JV1: memelingo-1/all-opts_mlp-tplp-htcdl_35_100 | JZ1: memelingo-1/all-opts_mlp-tplp-htcdl_35_150 | KD1: memelingo-1/all-opts_mlp-tplp-htcdl_35_200 | KH1: memelingo-1/all-opts_mlp-tplp-htcdl_35_30 | KL1: memelingo-1/all-opts_mlp-tplp-htcdl_35_50 | KP1: min | KS1: median | KV1: max
B2: time | C2: stime | D2: status | E2: rules | F2: time | G2: stime | H2: status | I2: rules | J2: time | K2: stime | L2: status | M2: rules | N2: time | O2: stime | P2: status | Q2: rules | R2: time | S2: stime | T2: status | U2: rules | V2: time | W2: stime | X2: status | Y2: rules | Z2: time | AA2: stime | AB2: status | AC2: rules | AD2: time | AE2: stime | AF2: status | AG2: rules | AH2: time | AI2: stime | AJ2: status | AK2: rules | AL2: time | AM2: stime | AN2: status | AO2: rules | AP2: time | AQ2: stime | AR2: status | AS2: rules | AT2: time | AU2: stime | AV2: status | AW2: rules | AX2: time | AY2: stime | AZ2: status | BA2: rules | BB2: time | BC2: stime | BD2: status | BE2: rules | BF2: time | BG2: stime | BH2: status | BI2: rules | BJ2: time | BK2: stime | BL2: status | BM2: rules | BN2: time | BO2: stime | BP2: status | BQ2: rules | BR2: time | BS2: stime | BT2: status | BU2: rules | BV2: time | BW2: stime | BX2: status | BY2: rules | BZ2: time | CA2: stime | CB2: status | CC2: rules | CD2: time | CE2: stime | CF2: status | CG2: rules | CH2: time | CI2: stime | CJ2: status | CK2: rules | CL2: time | CM2: stime | CN2: status | CO2: rules | CP2: time | CQ2: stime | CR2: status | CS2: rules | CT2: time | CU2: stime | CV2: status | CW2: rules | CX2: time | CY2: stime | CZ2: status | DA2: rules | DB2: time | DC2: stime | DD2: status | DE2: rules | DF2: time | DG2: stime | DH2: status | DI2: rules | DJ2: time | DK2: stime | DL2: status | DM2: rules | DN2: time | DO2: stime | DP2: status | DQ2: rules | DR2: time | DS2: stime | DT2: status | DU2: rules | DV2: time | DW2: stime | DX2: status | DY2: rules | DZ2: time | EA2: stime | EB2: status | EC2: rules | ED2: time | EE2: stime | EF2: status | EG2: rules | EH2: time | EI2: stime | EJ2: status | EK2: rules | EL2: time | EM2: stime | EN2: status | EO2: rules | EP2: time | EQ2: stime | ER2: status | ES2: rules | ET2: time | EU2: stime | EV2: status | EW2: rules | EX2: time | EY2: stime | EZ2: status | FA2: rules | FB2: time | FC2: stime | FD2: status | FE2: rules | FF2: time | FG2: stime | FH2: status | FI2: rules | FJ2: time | FK2: stime | FL2: status | FM2: rules | FN2: time | FO2: stime | FP2: status | FQ2: rules | FR2: time | FS2: stime | FT2: status | FU2: rules | FV2: time | FW2: stime | FX2: status | FY2: rules | FZ2: time | GA2: stime | GB2: status | GC2: rules | GD2: time | GE2: stime | GF2: status | GG2: rules | GH2: time | GI2: stime | GJ2: status | GK2: rules | GL2: time | GM2: stime | GN2: status | GO2: rules | GP2: time | GQ2: stime | GR2: status | GS2: rules | GT2: time | GU2: stime | GV2: status | GW2: rules | GX2: time | GY2: stime | GZ2: status | HA2: rules | HB2: time | HC2: stime | HD2: status | HE2: rules | HF2: time | HG2: stime | HH2: status | HI2: rules | HJ2: time | HK2: stime | HL2: status | HM2: rules | HN2: time | HO2: stime | HP2: status | HQ2: rules | HR2: time | HS2: stime | HT2: status | HU2: rules | HV2: time | HW2: stime | HX2: status | HY2: rules | HZ2: time | IA2: stime | IB2: status | IC2: rules | ID2: time | IE2: stime | IF2: status | IG2: rules | IH2: time | II2: stime | IJ2: status | IK2: rules | IL2: time | IM2: stime | IN2: status | IO2: rules | IP2: time | IQ2: stime | IR2: status | IS2: rules | IT2: time | IU2: stime | IV2: status | IW2: rules | IX2: time | IY2: stime | IZ2: status | JA2: rules | JB2: time | JC2: stime | JD2: status | JE2: rules | JF2: time | JG2: stime | JH2: status | JI2: rules | JJ2: time | JK2: stime | JL2: status | JM2: rules | JN2: time | JO2: stime | JP2: status | JQ2: rules | JR2: time | JS2: stime | JT2: status | JU2: rules | JV2: time | JW2: stime | JX2: status | JY2: rules | JZ2: time | KA2: stime | KB2: status | KC2: rules | KD2: time | KE2: stime | KF2: status | KG2: rules | KH2: time | KI2: stime | KJ2: status | KK2: rules | KL2: time | KM2: stime | KN2: status | KO2: rules | KP2: time | KQ2: stime | KR2: rules | KS2: time | KT2: stime | KU2: rules | KV2: time | KW2: stime | KX2: rules
A3: instances/random_x8_y8_a3 | B3: 1200 | F3: 1200 | J3: 1200 | N3: 1200 | O3: 1169.5 | P3: UNKNOWN | Q3: 1652707 | R3: 1200 | S3: 1160.95 | T3: UNKNOWN | U3: 2964587 | V3: 1200 | Z3: 1200 | AD3: 1200 | AE3: 0 | AF3: UNKNOWN | AG3: 0 | AH3: 1200 | AI3: 1141.22 | AJ3: UNKNOWN | AK3: 2428127 | AL3: 1200 | AM3: 1129.02 | AN3: UNKNOWN | AO3: 4612107 | AP3: 1200 | AT3: 1200 | AU3: 0 | AV3: UNKNOWN | AW3: 0 | AX3: 1200 | AY3: 0 | AZ3: UNKNOWN | BA3: 0 | BB3: 1200 | BC3: 1093.43 | BD3: UNKNOWN | BE3: 3247497 | BF3: 1200 | BG3: 1077.46 | BH3: UNKNOWN | BI3: 6399827 | BJ3: 1200 | BN3: 1200 | BO3: 0 | BP3: UNKNOWN | BQ3: 0 | BR3: 1200 | BS3: 0 | BT3: UNKNOWN | BU3: 0 | BV3: 1200 | BW3: 976.11 | BX3: UNKNOWN | BY3: 4086046 | BZ3: 1200 | CA3: 949.8 | CB3: UNKNOWN | CC3: 8230497 | CD3: 1200 | CH3: 1200 | CI3: 0 | CJ3: UNKNOWN | CK3: 0 | CL3: 1200 | CM3: 0 | CN3: UNKNOWN | CO3: 0 | CP3: 38.25 | CQ3: 0 | CR3: UNSATISFIABLE | CS3: 9632742 | CT3: 1200 | CX3: 1200 | CY3: 1172.56 | CZ3: UNKNOWN | DA3: 1141869 | DB3: 1200 | DC3: 1170.15 | DD3: UNKNOWN | DE3: 1141869 | DF3: 1200 | DG3: 1171.92 | DH3: UNKNOWN | DI3: 1141869 | DJ3: 1200 | DK3: 1170.13 | DL3: UNKNOWN | DM3: 1141869 | DN3: 1200 | DO3: 1171.35 | DP3: UNKNOWN | DQ3: 1141869 | DR3: 1200 | DS3: 1148.02 | DT3: UNKNOWN | DU3: 1693539 | DV3: 1200 | DW3: 1152.11 | DX3: UNKNOWN | DY3: 1693539 | DZ3: 1200 | EA3: 1146.33 | EB3: UNKNOWN | EC3: 1693539 | ED3: 1200 | EE3: 1147.48 | EF3: UNKNOWN | EG3: 1693539 | EH3: 1200 | EI3: 1148.25 | EJ3: UNKNOWN | EK3: 1693539 | EL3: 1200 | EM3: 1124.91 | EN3: UNKNOWN | EO3: 2352184 | EP3: 786.51 | EQ3: 707.89 | ER3: SATISFIABLE | ES3: 2352184 | ET3: 1200 | EU3: 1106.61 | EV3: UNKNOWN | EW3: 2352184 | EX3: 1200 | EY3: 1095.82 | EZ3: UNKNOWN | FA3: 2352184 | FB3: 1182.22 | FC3: 1075.59 | FD3: SATISFIABLE | FE3: 2352184 | FF3: 1200 | FG3: 987.38 | FH3: UNKNOWN | FI3: 3117804 | FJ3: 1200 | FK3: 1045.23 | FL3: UNKNOWN | FM3: 3117804 | FN3: 835.22 | FO3: 604.29 | FP3: SATISFIABLE | FQ3: 3117804 | FR3: 196.38 | FS3: 3.77 | FT3: UNSATISFIABLE | FU3: 3117804 | FV3: 1200 | FW3: 995.1 | FX3: UNKNOWN | FY3: 3117804 | FZ3: 595.15 | GA3: 181.74 | GB3: SATISFIABLE | GC3: 3990399 | GD3: 497.24 | GE3: 75.61 | GF3: SATISFIABLE | GG3: 3990399 | GH3: 503.25 | GI3: 67.41 | GJ3: SATISFIABLE | GK3: 3990399 | GL3: 412.18 | GM3: 0 | GN3: UNSATISFIABLE | GO3: 7980798 | GP3: 696.56 | GQ3: 268.83 | GR3: SATISFIABLE | GS3: 3990399 | GT3: 1200 | GU3: 1170.89 | GV3: UNKNOWN | GW3: 1141869 | GX3: 1200 | GY3: 1170.51 | GZ3: UNKNOWN | HA3: 1141869 | HB3: 1200 | HC3: 1170.02 | HD3: UNKNOWN | HE3: 1141869 | HF3: 1200 | HG3: 1172.85 | HH3: UNKNOWN | HI3: 1141869 | HJ3: 1200 | HK3: 1171.93 | HL3: UNKNOWN | HM3: 1141869 | HN3: 1200 | HO3: 1157.47 | HP3: UNKNOWN | HQ3: 1693539 | HR3: 1200 | HS3: 1153.3 | HT3: UNKNOWN | HU3: 1693539 | HV3: 1200 | HW3: 1155.78 | HX3: UNKNOWN | HY3: 1693539 | HZ3: 1200 | IA3: 1147.73 | IB3: UNKNOWN | IC3: 1693539 | ID3: 1200 | IE3: 1146.15 | IF3: UNKNOWN | IG3: 1693539 | IH3: 1200 | II3: 1122.83 | IJ3: UNKNOWN | IK3: 2352184 | IL3: 1200 | IM3: 1120.57 | IN3: UNKNOWN | IO3: 2352184 | IP3: 1200 | IQ3: 1122.28 | IR3: UNKNOWN | IS3: 2352184 | IT3: 1200 | IU3: 1123.77 | IV3: UNKNOWN | IW3: 2352184 | IX3: 1200 | IY3: 1121.3 | IZ3: UNKNOWN | JA3: 2352184 | JB3: 1200 | JC3: 1057.68 | JD3: UNKNOWN | JE3: 3117804 | JF3: 1200 | JG3: 1059.84 | JH3: UNKNOWN | JI3: 3117804 | JJ3: 1200 | JK3: 1057.99 | JL3: UNKNOWN | JM3: 3117804 | JN3: 1200 | JO3: 1063.03 | JP3: UNKNOWN | JQ3: 3117804 | JR3: 1200 | JS3: 1056.87 | JT3: UNKNOWN | JU3: 3117804 | JV3: 1200 | JW3: 884.69 | JX3: UNKNOWN | JY3: 3990399 | JZ3: 1200 | KA3: 880.56 | KB3: UNKNOWN | KC3: 3990399 | KD3: 1200 | KE3: 881.95 | KF3: UNKNOWN | KG3: 3990399 | KH3: 320.22 | KI3: 0 | KJ3: UNSATISFIABLE | KK3: 3990399 | KL3: 1200 | KM3: 881.09 | KN3: UNKNOWN | KO3: 3990399 | KP3: =MIN($B3,$F3,$J3,$N3,$R3,$V3,$Z3,$AD3,$AH3,$AL3,$AP3,$AT3,$AX3,$BB3,$BF3,$BJ3,$BN3,$BR3,$BV3,$BZ3,$CD3,$CH3,$CL3,$CP3,$CT3,$CX3,$DB3,$DF3,$DJ3,$DN3,$DR3,$DV3,$DZ3,$ED3,$EH3,$EL3,$EP3,$ET3,$EX3,$FB3,$FF3,$FJ3,$FN3,$FR3,$FV3,$FZ3,$GD3,$GH3,$GL3,$GP3,$GT3,$GX3,$HB3,$HF3,$HJ3,$HN3,$HR3,$HV3,$HZ3,$ID3,$IH3,$IL3,$IP3,$IT3,$IX3,$JB3,$JF3,$JJ3,$JN3,$JR3,$JV3,$JZ3,$KD3,$KH3,$KL3) -> 0 | KQ3: =MIN($C3,$G3,$K3,$O3,$S3,$W3,$AA3,$AE3,$AI3,$AM3,$AQ3,$AU3,$AY3,$BC3,$BG3,$BK3,$BO3,$BS3,$BW3,$CA3,$CE3,$CI3,$CM3,$CQ3,$CU3,$CY3,$DC3,$DG3,$DK3,$DO3,$DS3,$DW3,$EA3,$EE3,$EI3,$EM3,$EQ3,$EU3,$EY3,$FC3,$FG3,$FK3,$FO3,$FS3,$FW3,$GA3,$GE3,$GI3,$GM3,$GQ3,$GU3,$GY3,$HC3,$HG3,$HK3,$HO3,$HS3,$HW3,$IA3,$IE3,$II3,$IM3,$IQ3,$IU3,$IY3,$JC3,$JG3,$JK3,$JO3,$JS3,$JW3,$KA3,$KE3,$KI3,$KM3) -> 0 | KR3: =MIN($E3,$I3,$M3,$Q3,$U3,$Y3,$AC3,$AG3,$AK3,$AO3,$AS3,$AW3,$BA3,$BE3,$BI3,$BM3,$BQ3,$BU3,$BY3,$CC3,$CG3,$CK3,$CO3,$CS3,$CW3,$DA3,$DE3,$DI3,$DM3,$DQ3,$DU3,$DY3,$EC3,$EG3,$EK3,$EO3,$ES3,$EW3,$FA3,$FE3,$FI3,$FM3,$FQ3,$FU3,$FY3,$GC3,$GG3,$GK3,$GO3,$GS3,$GW3,$HA3,$HE3,$HI3,$HM3,$HQ3,$HU3,$HY3,$IC3,$IG3,$IK3,$IO3,$IS3,$IW3,$JA3,$JE3,$JI3,$JM3,$JQ3,$JU3,$JY3,$KC3,$KG3,$KK3,$KO3) -> 0 | KS3: =MEDIAN($B3,$F3,$J3,$N3,$R3,$V3,$Z3,$AD3,$AH3,$AL3,$AP3,$AT3,$AX3,$BB3,$BF3,$BJ3,$BN3,$BR3,$BV3,$BZ3,$CD3,$CH3,$CL3,$CP3,$CT3,$CX3,$DB3,$DF3,$DJ3,$DN3,$DR3,$DV3,$DZ3,$ED3,$EH3,$EL3,$EP3,$ET3,$EX3,$FB3,$FF3,$FJ3,$FN3,$FR3,$FV3,$FZ3,$GD3,$GH3,$GL3,$GP3,$GT3,$GX3,$HB3,$HF3,$HJ3,$HN3,$HR3,$HV3,$HZ3,$ID3,$IH3,$IL3,$IP3,$IT3,$IX3,$JB3,$JF3,$JJ3,$JN3,$JR3,$JV3,$JZ3,$KD3,$KH3,$KL3) -> 0 | KT3: =MEDIAN($C3,$G3,$K3,$O3,$S3,$W3,$AA3,$AE3,$AI3,$AM3,$AQ3,$AU3,$AY3,$BC3,$BG3,$BK3,$BO3,$BS3,$BW3,$CA3,$CE3,$CI3,$CM3,$CQ3,$CU3,$CY3,$DC3,$DG3,$DK3,$DO3,$DS3,$DW3,$EA3,$EE3,$EI3,$EM3,$EQ3,$EU3,$EY3,$FC3,$FG3,$FK3,$FO3,$FS3,$FW3,$GA3,$GE3,$GI3,$GM3,$GQ3,$GU3,$GY3,$HC3,$HG3,$HK3,$HO3,$HS3,$HW3,$IA3,$IE3,$II3,$IM3,$IQ3,$IU3,$IY3,$JC3,$JG3,$JK3,$JO3,$JS3,$JW3,$KA3,$KE3,$KI3,$KM3) -> 0 | KU3: =MEDIAN($E3,$I3,$M3,$Q3,$U3,$Y3,$AC3,$AG3,$AK3,$AO3,$AS3,$AW3,$BA3,$BE3,$BI3,$BM3,$BQ3,$BU3,$BY3,$CC3,$CG3,$CK3,$CO3,$CS3,$CW3,$DA3,$DE3,$DI3,$DM3,$DQ3,$DU3,$DY3,$EC3,$EG3,$EK3,$EO3,$ES3,$EW3,$FA3,$FE3,$FI3,$FM3,$FQ3,$FU3,$FY3,$GC3,$GG3,$GK3,$GO3,$GS3,$GW3,$HA3,$HE3,$HI3,$HM3,$HQ3,$HU3,$HY3,$IC3,$IG3,$IK3,$IO3,$IS3,$IW3,$JA3,$JE3,$JI3,$JM3,$JQ3,$JU3,$JY3,$KC3,$KG3,$KK3,$KO3) -> 0 | KV3: =MAX($B3,$F3,$J3,$N3,$R3,$V3,$Z3,$AD3,$AH3,$AL3,$AP3,$AT3,$AX3,$BB3,$BF3,$BJ3,$BN3,$BR3,$BV3,$BZ3,$CD3,$CH3,$CL3,$CP3,$CT3,$CX3,$DB3,$DF3,$DJ3,$DN3,$DR3,$DV3,$DZ3,$ED3,$EH3,$EL3,$EP3,$ET3,$EX3,$FB3,$FF3,$FJ3,$FN3,$FR3,$FV3,$FZ3,$GD3,$GH3,$GL3,$GP3,$GT3,$GX3,$HB3,$HF3,$HJ3,$HN3,$HR3,$HV3,$HZ3,$ID3,$IH3,$IL3,$IP3,$IT3,$IX3,$JB3,$JF3,$JJ3,$JN3,$JR3,$JV3,$JZ3,$KD3,$KH3,$KL3) -> 0 | KW3: =MAX($C3,$G3,$K3,$O3,$S3,$W3,$AA3,$AE3,$AI3,$AM3,$AQ3,$AU3,$AY3,$BC3,$BG3,$BK3,$BO3,$BS3,$BW3,$CA3,$CE3,$CI3,$CM3,$CQ3,$CU3,$CY3,$DC3,$DG3,$DK3,$DO3,$DS3,$DW3,$EA3,$EE3,$EI3,$EM3,$EQ3,$EU3,$EY3,$FC3,$FG3,$FK3,$FO3,$FS3,$FW3,$GA3,$GE3,$GI3,$GM3,$GQ3,$GU3,$GY3,$HC3,$HG3,$HK3,$HO3,$HS3,$HW3,$IA3,$IE3,$II3,$IM3,$IQ3,$IU3,$IY3,$JC3,$JG3,$JK3,$JO3,$JS3,$JW3,$KA3,$KE3,$KI3,$KM3) -> 0 | KX3: =MAX($E3,$I3,$M3,$Q3,$U3,$Y3,$AC3,$AG3,$AK3,$AO3,$AS3,$AW3,$BA3,$BE3,$BI3,$BM3,$BQ3,$BU3,$BY3,$CC3,$CG3,$CK3,$CO3,$CS3,$CW3,$DA3,$DE3,$DI3,$DM3,$DQ3,$DU3,$DY3,$EC3,$EG3,$EK3,$EO3,$ES3,$EW3,$FA3,$FE3,$FI3,$FM3,$FQ3,$FU3,$FY3,$GC3,$GG3,$GK3,$GO3,$GS3,$GW3,$HA3,$HE3,$HI3,$HM3,$HQ3,$HU3,$HY3,$IC3,$IG3,$IK3,$IO3,$IS3,$IW3,$JA3,$JE3,$JI3,$JM3,$JQ3,$JU3,$JY3,$KC3,$KG3,$KK3,$KO3) -> 0
A4: instances/room_x8_y8_a3 | B4: 94.32 | C4: 3.93 | D4: SATISFIABLE | E4: 9918884 | F4: 230.57 | G4: 61.15 | H4: SATISFIABLE | I4: 21732584 | J4: 591.92 | K4: 300.41 | L4: SATISFIABLE | M4: 38566284 | N4: 42.3 | O4: 5.56 | P4: SATISFIABLE | Q4: 1813304 | R4: 69.64 | S4: 22.39 | T4: SATISFIABLE | U4: 3125184 | V4: 160.66 | W4: 14.82 | X4: SATISFIABLE | Y4: 16654809 | Z4: 446.74 | AA4: 145.75 | AB4: SATISFIABLE | AC4: 37533759 | AD4: 1200 | AE4: 0 | AF4: UNKNOWN | AG4: 0 | AH4: 93.17 | AI4: 26.74 | AJ4: SATISFIABLE | AK4: 2661879 | AL4: 683.01 | AM4: 599.43 | AN4: SATISFIABLE | AO4: 4845859 | AP4: 315.67 | AQ4: 45.28 | AR4: SATISFIABLE | AS4: 24616909 | AT4: 1200 | AU4: 0 | AV4: UNKNOWN | AW4: 0 | AX4: 1200 | AY4: 0 | AZ4: UNKNOWN | BA4: 0 | BB4: 710.54 | BC4: 581.97 | BD4: SATISFIABLE | BE4: 3568504 | BF4: 181.47 | BG4: 21.67 | BH4: SATISFIABLE | BI4: 6720834 | BJ4: 543.52 | BK4: 205.42 | BL4: SATISFIABLE | BM4: 33526684 | BN4: 1200 | BO4: 0 | BP4: UNKNOWN | BQ4: 0 | BR4: 1200 | BS4: 0 | BT4: UNKNOWN | BU4: 0 | BV4: 483.23 | BW4: 183.44 | BX4: SATISFIABLE | BY4: 4508408 | BZ4: 450.88 | CA4: 207.17 | CB4: SATISFIABLE | CC4: 8652859 | CD4: 1200 | CE4: 0 | CF4: UNKNOWN | CG4: 0 | CH4: 1200 | CI4: 0 | CJ4: UNKNOWN | CK4: 0 | CL4: 1200 | CM4: 0 | CN4: UNKNOWN | CO4: 0 | CP4: 41.93 | CQ4: 0 | CR4: UNSATISFIABLE | CS4: 10670582 | CT4: 713.13 | CU4: 162.62 | CV4: SATISFIABLE | CW4: 10563434 | CX4: 72.75 | CY4: 37.18 | CZ4: SATISFIABLE | DA4: 1303633 | DB4: 58.63 | DC4: 24.3 | DD4: SATISFIABLE | DE4: 1303633 | DF4: 50.1 | DG4: 14.45 | DH4: SATISFIABLE | DI4: 1303633 | DJ4: 33.72 | DK4: 1.61 | DL4: SATISFIABLE | DM4: 1303633 | DN4: 32.85 | DO4: 1.18 | DP4: SATISFIABLE | DQ4: 1303633 | DR4: 303.3 | DS4: 238.27 | DT4: SATISFIABLE | DU4: 1928458 | DV4: 120.53 | DW4: 52.33 | DX4: SATISFIABLE | DY4: 1928458 | DZ4: 78.12 | EA4: 13.4 | EB4: SATISFIABLE | EC4: 1928458 | ED4: 71.63 | EE4: 5.78 | EF4: SATISFIABLE | EG4: 1928458 | EH4: 97.34 | EI4: 32.78 | EJ4: SATISFIABLE | EK4: 1928458 | EL4: 99.05 | EM4: 5.06 | EN4: SATISFIABLE | EO4: 2674358 | EP4: 169.88 | EQ4: 67.62 | ER4: SATISFIABLE | ES4: 2674358 | ET4: 188.2 | EU4: 47.62 | EV4: SATISFIABLE | EW4: 2674358 | EX4: 435.6 | EY4: 294.86 | EZ4: SATISFIABLE | FA4: 2674358 | FB4: 123.72 | FC4: 29.06 | FD4: SATISFIABLE | FE4: 2674358 | FF4: 260.97 | FG4: 39.34 | FH4: SATISFIABLE | FI4: 3541333 | FJ4: 349.98 | FK4: 42.73 | FL4: SATISFIABLE | FM4: 3541333 | FN4: 353.99 | FO4: 51.12 | FP4: SATISFIABLE | FQ4: 3541333 | FR4: 318.44 | FS4: 9.24 | FT4: SATISFIABLE | FU4: 3541333 | FV4: 287.32 | FW4: 42.69 | FX4: SATISFIABLE | FY4: 3541333 | FZ4: 1020.76 | GA4: 446.74 | GB4: SATISFIABLE | GC4: 4529383 | GD4: 600.89 | GE4: 33.33 | GF4: SATISFIABLE | GG4: 4529383 | GH4: 621.07 | GI4: 69.01 | GJ4: SATISFIABLE | GK4: 4529383 | GL4: 575.29 | GM4: 0 | GN4: UNSATISFIABLE | GO4: 9058766 | GP4: 573.68 | GQ4: 9.23 | GR4: SATISFIABLE | GS4: 4529383 | GT4: 335.96 | GU4: 303.27 | GV4: SATISFIABLE | GW4: 1303633 | GX4: 350.38 | GY4: 319.35 | GZ4: SATISFIABLE | HA4: 1303633 | HB4: 357.95 | HC4: 321.7 | HD4: SATISFIABLE | HE4: 1303633 | HF4: 140.97 | HG4: 106.59 | HH4: SATISFIABLE | HI4: 1303633 | HJ4: 358.72 | HK4: 322.92 | HL4: SATISFIABLE | HM4: 1303633 | HN4: 385.02 | HO4: 330.09 | HP4: SATISFIABLE | HQ4: 1928458 | HR4: 379.9 | HS4: 327.55 | HT4: SATISFIABLE | HU4: 1928458 | HV4: 384.03 | HW4: 328.4 | HX4: SATISFIABLE | HY4: 1928458 | HZ4: 327.86 | IA4: 261.78 | IB4: SATISFIABLE | IC4: 1928458 | ID4: 464.55 | IE4: 402.87 | IF4: SATISFIABLE | IG4: 1928458 | IH4: 726.94 | II4: 629.79 | IJ4: SATISFIABLE | IK4: 2674358 | IL4: 715.21 | IM4: 619.09 | IN4: SATISFIABLE | IO4: 2674358 | IP4: 712.78 | IQ4: 619.36 | IR4: SATISFIABLE | IS4: 2674358 | IT4: 661.22 | IU4: 566.14 | IV4: SATISFIABLE | IW4: 2674358 | IX4: 521.27 | IY4: 422.56 | IZ4: SATISFIABLE | JA4: 2674358 | JB4: 1200 | JC4: 992.29 | JD4: UNKNOWN | JE4: 3541333 | JF4: 1200 | JG4: 993 | JH4: UNKNOWN | JI4: 3541333 | JJ4: 1200 | JK4: 992.04 | JL4: UNKNOWN | JM4: 3541333 | JN4: 951.41 | JO4: 744.77 | JP4: SATISFIABLE | JQ4: 3541333 | JR4: 1200 | JS4: 999.96 | JT4: UNKNOWN | JU4: 3541333 | JV4: 1200 | JW4: 773.76 | JX4: UNKNOWN | JY4: 4529383 | JZ4: 1200 | KA4: 771.3 | KB4: UNKNOWN | KC4: 4529383 | KD4: 1200 | KE4: 772.33 | KF4: UNKNOWN | KG4: 4529383 | KH4: 433.94 | KI4: 0 | KJ4: UNSATISFIABLE | KK4: 4529383 | KL4: 1200 | KM4: 744.32 | KN4: UNKNOWN | KO4: 4529383 | KP4: =MIN($B4,$F4,$J4,$N4,$R4,$V4,$Z4,$AD4,$AH4,$AL4,$AP4,$AT4,$AX4,$BB4,$BF4,$BJ4,$BN4,$BR4,$BV4,$BZ4,$CD4,$CH4,$CL4,$CP4,$CT4,$CX4,$DB4,$DF4,$DJ4,$DN4,$DR4,$DV4,$DZ4,$ED4,$EH4,$EL4,$EP4,$ET4,$EX4,$FB4,$FF4,$FJ4,$FN4,$FR4,$FV4,$FZ4,$GD4,$GH4,$GL4,$GP4,$GT4,$GX4,$HB4,$HF4,$HJ4,$HN4,$HR4,$HV4,$HZ4,$ID4,$IH4,$IL4,$IP4,$IT4,$IX4,$JB4,$JF4,$JJ4,$JN4,$JR4,$JV4,$JZ4,$KD4,$KH4,$KL4) -> 0 | KQ4: =MIN($C4,$G4,$K4,$O4,$S4,$W4,$AA4,$AE4,$AI4,$AM4,$AQ4,$AU4,$AY4,$BC4,$BG4,$BK4,$BO4,$BS4,$BW4,$CA4,$CE4,$CI4,$CM4,$CQ4,$CU4,$CY4,$DC4,$DG4,$DK4,$DO4,$DS4,$DW4,$EA4,$EE4,$EI4,$EM4,$EQ4,$EU4,$EY4,$FC4,$FG4,$FK4,$FO4,$FS4,$FW4,$GA4,$GE4,$GI4,$GM4,$GQ4,$GU4,$GY4,$HC4,$HG4,$HK4,$HO4,$HS4,$HW4,$IA4,$IE4,$II4,$IM4,$IQ4,$IU4,$IY4,$JC4,$JG4,$JK4,$JO4,$JS4,$JW4,$KA4,$KE4,$KI4,$KM4) -> 0 | KR4: =MIN($E4,$I4,$M4,$Q4,$U4,$Y4,$AC4,$AG4,$AK4,$AO4,$AS4,$AW4,$BA4,$BE4,$BI4,$BM4,$BQ4,$BU4,$BY4,$CC4,$CG4,$CK4,$CO4,$CS4,$CW4,$DA4,$DE4,$DI4,$DM4,$DQ4,$DU4,$DY4,$EC4,$EG4,$EK4,$EO4,$ES4,$EW4,$FA4,$FE4,$FI4,$FM4,$FQ4,$FU4,$FY4,$GC4,$GG4,$GK4,$GO4,$GS4,$GW4,$HA4,$HE4,$HI4,$HM4,$HQ4,$HU4,$HY4,$IC4,$IG4,$IK4,$IO4,$IS4,$IW4,$JA4,$JE4,$JI4,$JM4,$JQ4,$JU4,$JY4,$KC4,$KG4,$KK4,$KO4) -> 0 | KS4: =MEDIAN($B4,$F4,$J4,$N4,$R4,$V4,$Z4,$AD4,$AH4,$AL4,$AP4,$AT4,$AX4,$BB4,$BF4,$BJ4,$BN4,$BR4,$BV4,$BZ4,$CD4,$CH4,$CL4,$CP4,$CT4,$CX4,$DB4,$DF4,$DJ4,$DN4,$DR4,$DV4,$DZ4,$ED4,$EH4,$EL4,$EP4,$ET4,$EX4,$FB4,$FF4,$FJ4,$FN4,$FR4,$FV4,$FZ4,$GD4,$GH4,$GL4,$GP4,$GT4,$GX4,$HB4,$HF4,$HJ4,$HN4,$HR4,$HV4,$HZ4,$ID4,$IH4,$IL4,$IP4,$IT4,$IX4,$JB4,$JF4,$JJ4,$JN4,$JR4,$JV4,$JZ4,$KD4,$KH4,$KL4) -> 0 | KT4: =MEDIAN($C4,$G4,$K4,$O4,$S4,$W4,$AA4,$AE4,$AI4,$AM4,$AQ4,$AU4,$AY4,$BC4,$BG4,$BK4,$BO4,$BS4,$BW4,$CA4,$CE4,$CI4,$CM4,$CQ4,$CU4,$CY4,$DC4,$DG4,$DK4,$DO4,$DS4,$DW4,$EA4,$EE4,$EI4,$EM4,$EQ4,$EU4,$EY4,$FC4,$FG4,$FK4,$FO4,$FS4,$FW4,$GA4,$GE4,$GI4,$GM4,$GQ4,$GU4,$GY4,$HC4,$HG4,$HK4,$HO4,$HS4,$HW4,$IA4,$IE4,$II4,$IM4,$IQ4,$IU4,$IY4,$JC4,$JG4,$JK4,$JO4,$JS4,$JW4,$KA4,$KE4,$KI4,$KM4) -> 0 | KU4: =MEDIAN($E4,$I4,$M4,$Q4,$U4,$Y4,$AC4,$AG4,$AK4,$AO4,$AS4,$AW4,$BA4,$BE4,$BI4,$BM4,$BQ4,$BU4,$BY4,$CC4,$CG4,$CK4,$CO4,$CS4,$CW4,$DA4,$DE4,$DI4,$DM4,$DQ4,$DU4,$DY4,$EC4,$EG4,$EK4,$EO4,$ES4,$EW4,$FA4,$FE4,$FI4,$FM4,$FQ4,$FU4,$FY4,$GC4,$GG4,$GK4,$GO4,$GS4,$GW4,$HA4,$HE4,$HI4,$HM4,$HQ4,$HU4,$HY4,$IC4,$IG4,$IK4,$IO4,$IS4,$IW4,$JA4,$JE4,$JI4,$JM4,$JQ4,$JU4,$JY4,$KC4,$KG4,$KK4,$KO4) -> 0 | KV4: =MAX($B4,$F4,$J4,$N4,$R4,$V4,$Z4,$AD4,$AH4,$AL4,$AP4,$AT4,$AX4,$BB4,$BF4,$BJ4,$BN4,$BR4,$BV4,$BZ4,$CD4,$CH4,$CL4,$CP4,$CT4,$CX4,$DB4,$DF4,$DJ4,$DN4,$DR4,$DV4,$DZ4,$ED4,$EH4,$EL4,$EP4,$ET4,$EX4,$FB4,$FF4,$FJ4,$FN4,$FR4,$FV4,$FZ4,$GD4,$GH4,$GL4,$GP4,$GT4,$GX4,$HB4,$HF4,$HJ4,$HN4,$HR4,$HV4,$HZ4,$ID4,$IH4,$IL4,$IP4,$IT4,$IX4,$JB4,$JF4,$JJ4,$JN4,$JR4,$JV4,$JZ4,$KD4,$KH4,$KL4) -> 0 | KW4: =MAX($C4,$G4,$K4,$O4,$S4,$W4,$AA4,$AE4,$AI4,$AM4,$AQ4,$AU4,$AY4,$BC4,$BG4,$BK4,$BO4,$BS4,$BW4,$CA4,$CE4,$CI4,$CM4,$CQ4,$CU4,$CY4,$DC4,$DG4,$DK4,$DO4,$DS4,$DW4,$EA4,$EE4,$EI4,$EM4,$EQ4,$EU4,$EY4,$FC4,$FG4,$FK4,$FO4,$FS4,$FW4,$GA4,$GE4,$GI4,$GM4,$GQ4,$GU4,$GY4,$HC4,$HG4,$HK4,$HO4,$HS4,$HW4,$IA4,$IE4,$II4,$IM4,$IQ4,$IU4,$IY4,$JC4,$JG4,$JK4,$JO4,$JS4,$JW4,$KA4,$KE4,$KI4,$KM4) -> 0 | KX4: =MAX($E4,$I4,$M4,$Q4,$U4,$Y4,$AC4,$AG4,$AK4,$AO4,$AS4,$AW4,$BA4,$BE4,$BI4,$BM4,$BQ4,$BU4,$BY4,$CC4,$CG4,$CK4,$CO4,$CS4,$CW4,$DA4,$DE4,$DI4,$DM4,$DQ4,$DU4,$DY4,$EC4,$EG4,$EK4,$EO4,$ES4,$EW4,$FA4,$FE4,$FI4,$FM4,$FQ4,$FU4,$FY4,$GC4,$GG4,$GK4,$GO4,$GS4,$GW4,$HA4,$HE4,$HI4,$HM4,$HQ4,$HU4,$HY4,$IC4,$IG4,$IK4,$IO4,$IS4,$IW4,$JA4,$JE4,$JI4,$JM4,$JQ4,$JU4,$JY4,$KC4,$KG4,$KK4,$KO4) -> 0
A5: instances/warehouse_x8_y8_a3 | B5: 1200 | F5: 1200 | J5: 1200 | N5: 1200 | O5: 1181.33 | P5: UNKNOWN | Q5: 1136938 | R5: 1200 | S5: 1172.84 | T5: UNKNOWN | U5: 2448818 | V5: 1200 | Z5: 1200 | AD5: 1200 | AE5: 0 | AF5: UNKNOWN | AG5: 0 | AH5: 197.42 | AI5: 166.6 | AJ5: SATISFIABLE | AK5: 1661758 | AL5: 436.02 | AM5: 391.77 | AN5: SATISFIABLE | AO5: 3845738 | AP5: 659.46 | AQ5: 493.81 | AR5: SATISFIABLE | AS5: 23229733 | AT5: 1200 | AU5: 0 | AV5: UNKNOWN | AW5: 0 | AX5: 1200 | AY5: 0 | AZ5: UNKNOWN | BA5: 0 | BB5: 412.03 | BC5: 366.63 | BD5: SATISFIABLE | BE5: 2181328 | BF5: 67.77 | BG5: 3.7 | BH5: SATISFIABLE | BI5: 5333658 | BJ5: 224.69 | BK5: 27.45 | BL5: SATISFIABLE | BM5: 31689153 | BN5: 1200 | BO5: 0 | BP5: UNKNOWN | BQ5: 0 | BR5: 1200 | BS5: 0 | BT5: UNKNOWN | BU5: 0 | BV5: 1101.64 | BW5: 1029.78 | BX5: SATISFIABLE | BY5: 2670877 | BZ5: 95.92 | CA5: 17.21 | CB5: SATISFIABLE | CC5: 6815328 | CD5: 702.29 | CE5: 394.09 | CF5: SATISFIABLE | CG5: 40773198 | CH5: 1200 | CI5: 0 | CJ5: UNKNOWN | CK5: 0 | CL5: 1200 | CM5: 0 | CN5: UNKNOWN | CO5: 0 | CP5: 25.69 | CQ5: 0 | CR5: UNSATISFIABLE | CS5: 6137944 | CT5: 361.7 | CU5: 224.95 | CV5: SATISFIABLE | CW5: 8212248 | CX5: 1200 | CY5: 1183.49 | CZ5: UNKNOWN | DA5: 622122 | DB5: 1200 | DC5: 1186.6 | DD5: UNKNOWN | DE5: 622122 | DF5: 1200 | DG5: 1183.85 | DH5: UNKNOWN | DI5: 622122 | DJ5: 1200 | DK5: 1182.89 | DL5: UNKNOWN | DM5: 622122 | DN5: 1200 | DO5: 1184.28 | DP5: UNKNOWN | DQ5: 622122 | DR5: 43.66 | DS5: 17.91 | DT5: SATISFIABLE | DU5: 923192 | DV5: 57.93 | DW5: 30.89 | DX5: SATISFIABLE | DY5: 923192 | DZ5: 792.28 | EA5: 765.75 | EB5: SATISFIABLE | EC5: 923192 | ED5: 135.53 | EE5: 108.83 | EF5: SATISFIABLE | EG5: 923192 | EH5: 286.13 | EI5: 263.35 | EJ5: SATISFIABLE | EK5: 923192 | EL5: 62.92 | EM5: 26.62 | EN5: SATISFIABLE | EO5: 1282037 | EP5: 40.53 | EQ5: 4.69 | ER5: SATISFIABLE | ES5: 1282037 | ET5: 36.54 | EU5: 1.3 | EV5: SATISFIABLE | EW5: 1282037 | EX5: 53.01 | EY5: 10.53 | EZ5: SATISFIABLE | FA5: 1282037 | FB5: 47.64 | FC5: 9.25 | FD5: SATISFIABLE | FE5: 1282037 | FF5: 83.03 | FG5: 30.23 | FH5: SATISFIABLE | FI5: 1698657 | FJ5: 120.26 | FK5: 51.82 | FL5: SATISFIABLE | FM5: 1698657 | FN5: 132.91 | FO5: 68.16 | FP5: SATISFIABLE | FQ5: 1698657 | FR5: 64.4 | FS5: 1.73 | FT5: SATISFIABLE | FU5: 1698657 | FV5: 80.05 | FW5: 12.4 | FX5: SATISFIABLE | FY5: 1698657 | FZ5: 170.97 | GA5: 57.2 | GB5: SATISFIABLE | GC5: 2173052 | GD5: 338.36 | GE5: 226.21 | GF5: SATISFIABLE | GG5: 2173052 | GH5: 155.68 | GI5: 50.17 | GJ5: SATISFIABLE | GK5: 2173052 | GL5: 113.52 | GM5: 0 | GN5: UNSATISFIABLE | GO5: 4346104 | GP5: 114.03 | GQ5: 3.6 | GR5: SATISFIABLE | GS5: 2173052 | GT5: 501.07 | GU5: 483.43 | GV5: SATISFIABLE | GW5: 622122 | GX5: 411.65 | GY5: 393.68 | GZ5: SATISFIABLE | HA5: 622122 | HB5: 503.56 | HC5: 485.65 | HD5: SATISFIABLE | HE5: 622122 | HF5: 509 | HG5: 492.45 | HH5: SATISFIABLE | HI5: 622122 | HJ5: 503.46 | HK5: 485.27 | HL5: SATISFIABLE | HM5: 622122 | HN5: 232.71 | HO5: 210.03 | HP5: SATISFIABLE | HQ5: 923192 | HR5: 243.02 | HS5: 216.8 | HT5: SATISFIABLE | HU5: 923192 | HV5: 231.21 | HW5: 207.56 | HX5: SATISFIABLE | HY5: 923192 | HZ5: 416.29 | IA5: 388.49 | IB5: SATISFIABLE | IC5: 923192 | ID5: 300.61 | IE5: 274.17 | IF5: SATISFIABLE | IG5: 923192 | IH5: 522.78 | II5: 486.26 | IJ5: SATISFIABLE | IK5: 1282037 | IL5: 520.43 | IM5: 484.99 | IN5: SATISFIABLE | IO5: 1282037 | IP5: 522.04 | IQ5: 486.31 | IR5: SATISFIABLE | IS5: 1282037 | IT5: 667.28 | IU5: 629.45 | IV5: SATISFIABLE | IW5: 1282037 | IX5: 521.21 | IY5: 484.91 | IZ5: SATISFIABLE | JA5: 1282037 | JB5: 656.81 | JC5: 603.17 | JD5: SATISFIABLE | JE5: 1698657 | JF5: 657.85 | JG5: 601.92 | JH5: SATISFIABLE | JI5: 1698657 | JJ5: 661.46 | JK5: 606.07 | JL5: SATISFIABLE | JM5: 1698657 | JN5: 519.86 | JO5: 467.27 | JP5: SATISFIABLE | JQ5: 1698657 | JR5: 654.04 | JS5: 598.44 | JT5: SATISFIABLE | JU5: 1698657 | JV5: 1014.08 | JW5: 930.52 | JX5: SATISFIABLE | JY5: 2173052 | JZ5: 1015.42 | KA5: 930.87 | KB5: SATISFIABLE | KC5: 2173052 | KD5: 1012.18 | KE5: 929.44 | KF5: SATISFIABLE | KG5: 2173052 | KH5: 83.25 | KI5: 0 | KJ5: UNSATISFIABLE | KK5: 2173052 | KL5: 934.5 | KM5: 852.58 | KN5: SATISFIABLE | KO5: 2173052 | KP5: =MIN($B5,$F5,$J5,$N5,$R5,$V5,$Z5,$AD5,$AH5,$AL5,$AP5,$AT5,$AX5,$BB5,$BF5,$BJ5,$BN5,$BR5,$BV5,$BZ5,$CD5,$CH5,$CL5,$CP5,$CT5,$CX5,$DB5,$DF5,$DJ5,$DN5,$DR5,$DV5,$DZ5,$ED5,$EH5,$EL5,$EP5,$ET5,$EX5,$FB5,$FF5,$FJ5,$FN5,$FR5,$FV5,$FZ5,$GD5,$GH5,$GL5,$GP5,$GT5,$GX5,$HB5,$HF5,$HJ5,$HN5,$HR5,$HV5,$HZ5,$ID5,$IH5,$IL5,$IP5,$IT5,$IX5,$JB5,$JF5,$JJ5,$JN5,$JR5,$JV5,$JZ5,$KD5,$KH5,$KL5) -> 0 | KQ5: =MIN($C5,$G5,$K5,$O5,$S5,$W5,$AA5,$AE5,$AI5,$AM5,$AQ5,$AU5,$AY5,$BC5,$BG5,$BK5,$BO5,$BS5,$BW5,$CA5,$CE5,$CI5,$CM5,$CQ5,$CU5,$CY5,$DC5,$DG5,$DK5,$DO5,$DS5,$DW5,$EA5,$EE5,$EI5,$EM5,$EQ5,$EU5,$EY5,$FC5,$FG5,$FK5,$FO5,$FS5,$FW5,$GA5,$GE5,$GI5,$GM5,$GQ5,$GU5,$GY5,$HC5,$HG5,$HK5,$HO5,$HS5,$HW5,$IA5,$IE5,$II5,$IM5,$IQ5,$IU5,$IY5,$JC5,$JG5,$JK5,$JO5,$JS5,$JW5,$KA5,$KE5,$KI5,$KM5) -> 0 | KR5: =MIN($E5,$I5,$M5,$Q5,$U5,$Y5,$AC5,$AG5,$AK5,$AO5,$AS5,$AW5,$BA5,$BE5,$BI5,$BM5,$BQ5,$BU5,$BY5,$CC5,$CG5,$CK5,$CO5,$CS5,$CW5,$DA5,$DE5,$DI5,$DM5,$DQ5,$DU5,$DY5,$EC5,$EG5,$EK5,$EO5,$ES5,$EW5,$FA5,$FE5,$FI5,$FM5,$FQ5,$FU5,$FY5,$GC5,$GG5,$GK5,$GO5,$GS5,$GW5,$HA5,$HE5,$HI5,$HM5,$HQ5,$HU5,$HY5,$IC5,$IG5,$IK5,$IO5,$IS5,$IW5,$JA5,$JE5,$JI5,$JM5,$JQ5,$JU5,$JY5,$KC5,$KG5,$KK5,$KO5) -> 0 | KS5: =MEDIAN($B5,$F5,$J5,$N5,$R5,$V5,$Z5,$AD5,$AH5,$AL5,$AP5,$AT5,$AX5,$BB5,$BF5,$BJ5,$BN5,$BR5,$BV5,$BZ5,$CD5,$CH5,$CL5,$CP5,$CT5,$CX5,$DB5,$DF5,$DJ5,$DN5,$DR5,$DV5,$DZ5,$ED5,$EH5,$EL5,$EP5,$ET5,$EX5,$FB5,$FF5,$FJ5,$FN5,$FR5,$FV5,$FZ5,$GD5,$GH5,$GL5,$GP5,$GT5,$GX5,$HB5,$HF5,$HJ5,$HN5,$HR5,$HV5,$HZ5,$ID5,$IH5,$IL5,$IP5,$IT5,$IX5,$JB5,$JF5,$JJ5,$JN5,$JR5,$JV5,$JZ5,$KD5,$KH5,$KL5) -> 0 | KT5: =MEDIAN($C5,$G5,$K5,$O5,$S5,$W5,$AA5,$AE5,$AI5,$AM5,$AQ5,$AU5,$AY5,$BC5,$BG5,$BK5,$BO5,$BS5,$BW5,$CA5,$CE5,$CI5,$CM5,$CQ5,$CU5,$CY5,$DC5,$DG5,$DK5,$DO5,$DS5,$DW5,$EA5,$EE5,$EI5,$EM5,$EQ5,$EU5,$EY5,$FC5,$FG5,$FK5,$FO5,$FS5,$FW5,$GA5,$GE5,$GI5,$GM5,$GQ5,$GU5,$GY5,$HC5,$HG5,$HK5,$HO5,$HS5,$HW5,$IA5,$IE5,$II5,$IM5,$IQ5,$IU5,$IY5,$JC5,$JG5,$JK5,$JO5,$JS5,$JW5,$KA5,$KE5,$KI5,$KM5) -> 0 | KU5: =MEDIAN($E5,$I5,$M5,$Q5,$U5,$Y5,$AC5,$AG5,$AK5,$AO5,$AS5,$AW5,$BA5,$BE5,$BI5,$BM5,$BQ5,$BU5,$BY5,$CC5,$CG5,$CK5,$CO5,$CS5,$CW5,$DA5,$DE5,$DI5,$DM5,$DQ5,$DU5,$DY5,$EC5,$EG5,$EK5,$EO5,$ES5,$EW5,$FA5,$FE5,$FI5,$FM5,$FQ5,$FU5,$FY5,$GC5,$GG5,$GK5,$GO5,$GS5,$GW5,$HA5,$HE5,$HI5,$HM5,$HQ5,$HU5,$HY5,$IC5,$IG5,$IK5,$IO5,$IS5,$IW5,$JA5,$JE5,$JI5,$JM5,$JQ5,$JU5,$JY5,$KC5,$KG5,$KK5,$KO5) -> 0 | KV5: =MAX($B5,$F5,$J5,$N5,$R5,$V5,$Z5,$AD5,$AH5,$AL5,$AP5,$AT5,$AX5,$BB5,$BF5,$BJ5,$BN5,$BR5,$BV5,$BZ5,$CD5,$CH5,$CL5,$CP5,$CT5,$CX5,$DB5,$DF5,$DJ5,$DN5,$DR5,$DV5,$DZ5,$ED5,$EH5,$EL5,$EP5,$ET5,$EX5,$FB5,$FF5,$FJ5,$FN5,$FR5,$FV5,$FZ5,$GD5,$GH5,$GL5,$GP5,$GT5,$GX5,$HB5,$HF5,$HJ5,$HN5,$HR5,$HV5,$HZ5,$ID5,$IH5,$IL5,$IP5,$IT5,$IX5,$JB5,$JF5,$JJ5,$JN5,$JR5,$JV5,$JZ5,$KD5,$KH5,$KL5) -> 0 | KW5: =MAX($C5,$G5,$K5,$O5,$S5,$W5,$AA5,$AE5,$AI5,$AM5,$AQ5,$AU5,$AY5,$BC5,$BG5,$BK5,$BO5,$BS5,$BW5,$CA5,$CE5,$CI5,$CM5,$CQ5,$CU5,$CY5,$DC5,$DG5,$DK5,$DO5,$DS5,$DW5,$EA5,$EE5,$EI5,$EM5,$EQ5,$EU5,$EY5,$FC5,$FG5,$FK5,$FO5,$FS5,$FW5,$GA5,$GE5,$GI5,$GM5,$GQ5,$GU5,$GY5,$HC5,$HG5,$HK5,$HO5,$HS5,$HW5,$IA5,$IE5,$II5,$IM5,$IQ5,$IU5,$IY5,$JC5,$JG5,$JK5,$JO5,$JS5,$JW5,$KA5,$KE5,$KI5,$KM5) -> 0 | KX5: =MAX($E5,$I5,$M5,$Q5,$U5,$Y5,$AC5,$AG5,$AK5,$AO5,$AS5,$AW5,$BA5,$BE5,$BI5,$BM5,$BQ5,$BU5,$BY5,$CC5,$CG5,$CK5,$CO5,$CS5,$CW5,$DA5,$DE5,$DI5,$DM5,$DQ5,$DU5,$DY5,$EC5,$EG5,$EK5,$EO5,$ES5,$EW5,$FA5,$FE5,$FI5,$FM5,$FQ5,$FU5,$FY5,$GC5,$GG5,$GK5,$GO5,$GS5,$GW5,$HA5,$HE5,$HI5,$HM5,$HQ5,$HU5,$HY5,$IC5,$IG5,$IK5,$IO5,$IS5,$IW5,$JA5,$JE5,$JI5,$JM5,$JQ5,$JU5,$JY5,$KC5,$KG5,$KK5,$KO5) -> 0
A7: SUM | B7: =SUM(B$3:B$5) -> 0 | C7: =SUM(C$3:C$5) -> 0 | E7: =SUM(E$3:E$5) -> 0 | F7: =SUM(F$3:F$5) -> 0 | G7: =SUM(G$3:G$5) -> 0 | I7: =SUM(I$3:I$5) -> 0 | J7: =SUM(J$3:J$5) -> 0 | K7: =SUM(K$3:K$5) -> 0 | M7: =SUM(M$3:M$5) -> 0 | N7: =SUM(N$3:N$5) -> 0 | O7: =SUM(O$3:O$5) -> 0 | Q7: =SUM(Q$3:Q$5) -> 0 | R7: =SUM(R$3:R$5) -> 0 | S7: =SUM(S$3:S$5) -> 0 | U7: =SUM(U$3:U$5) -> 0 | V7: =SUM(V$3:V$5) -> 0 | W7: =SUM(W$3:W$5) -> 0 | Y7: =SUM(Y$3:Y$5) -> 0 | Z7: =SUM(Z$3:Z$5) -> 0 | AA7: =SUM(AA$3:AA$5) -> 0 | AC7: =SUM(AC$3:AC$5) -> 0 | AD7: =SUM(AD$3:AD$5) -> 0 | AE7: =SUM(AE$3:AE$5) -> 0 | AG7: =SUM(AG$3:AG$5) -> 0 | AH7: =SUM(AH$3:AH$5) -> 0 | AI7: =SUM(AI$3:AI$5) -> 0 | AK7: =SUM(AK$3:AK$5) -> 0 | AL7: =SUM(AL$3:AL$5) -> 0 | AM7: =SUM(AM$3:AM$5) -> 0 | AO7: =SUM(AO$3:AO$5) -> 0 | AP7: =SUM(AP$3:AP$5) -> 0 | AQ7: =SUM(AQ$3:AQ$5) -> 0 | AS7: =SUM(AS$3:AS$5) -> 0 | AT7: =SUM(AT$3:AT$5) -> 0 | AU7: =SUM(AU$3:AU$5) -> 0 | AW7: =SUM(AW$3:AW$5) -> 0 | AX7: =SUM(AX$3:AX$5) -> 0 | AY7: =SUM(AY$3:AY$5) -> 0 | BA7: =SUM(BA$3:BA$5) -> 0 | BB7: =SUM(BB$3:BB$5) -> 0 | BC7: =SUM(BC$3:BC$5) -> 0 | BE7: =SUM(BE$3:BE$5) -> 0 | BF7: =SUM(BF$3:BF$5) -> 0 | BG7: =SUM(BG$3:BG$5) -> 0 | BI7: =SUM(BI$3:BI$5) -> 0 | BJ7: =SUM(BJ$3:BJ$5) -> 0 | BK7: =SUM(BK$3:BK$5) -> 0 | BM7: =SUM(BM$3:BM$5) -> 0 | BN7: =SUM(BN$3:BN$5) -> 0 | BO7: =SUM(BO$3:BO$5) -> 0 | BQ7: =SUM(BQ$3:BQ$5) -> 0 | BR7: =SUM(BR$3:BR$5) -> 0 | BS7: =SUM(BS$3:BS$5) -> 0 | BU7: =SUM(BU$3:BU$5) -> 0 | BV7: =SUM(BV$3:BV$5) -> 0 | BW7: =SUM(BW$3:BW$5) -> 0 | BY7: =SUM(BY$3:BY$5) -> 0 | BZ7: =SUM(BZ$3:BZ$5) -> 0 | CA7: =SUM(CA$3:CA$5) -> 0 | CC7: =SUM(CC$3:CC$5) -> 0 | CD7: =SUM(CD$3:CD$5) -> 0 | CE7: =SUM(CE$3:CE$5) -> 0 | CG7: =SUM(CG$3:CG$5) -> 0 | CH7: =SUM(CH$3:CH$5) -> 0 | CI7: =SUM(CI$3:CI$5) -> 0 | CK7: =SUM(CK$3:CK$5) -> 0 | CL7: =SUM(CL$3:CL$5) -> 0 | CM7: =SUM(CM$3:CM$5) -> 0 | CO7: =SUM(CO$3:CO$5) -> 0 | CP7: =SUM(CP$3:CP$5) -> 0 | CQ7: =SUM(CQ$3:CQ$5) -> 0 | CS7: =SUM(CS$3:CS$5) -> 0 | CT7: =SUM(CT$3:CT$5) -> 0 | CU7: =SUM(CU$3:CU$5) -> 0 | CW7: =SUM(CW$3:CW$5) -> 0 | CX7: =SUM(CX$3:CX$5) -> 0 | CY7: =SUM(CY$3:CY$5) -> 0 | DA7: =SUM(DA$3:DA$5) -> 0 | DB7: =SUM(DB$3:DB$5) -> 0 | DC7: =SUM(DC$3:DC$5) -> 0 | DE7: =SUM(DE$3:DE$5) -> 0 | DF7: =SUM(DF$3:DF$5) -> 0 | DG7: =SUM(DG$3:DG$5) -> 0 | DI7: =SUM(DI$3:DI$5) -> 0 | DJ7: =SUM(DJ$3:DJ$5) -> 0 | DK7: =SUM(DK$3:DK$5) -> 0 | DM7: =SUM(DM$3:DM$5) -> 0 | DN7: =SUM(DN$3:DN$5) -> 0 | DO7: =SUM(DO$3:DO$5) -> 0 | DQ7: =SUM(DQ$3:DQ$5) -> 0 | DR7: =SUM(DR$3:DR$5) -> 0 | DS7: =SUM(DS$3:DS$5) -> 0 | DU7: =SUM(DU$3:DU$5) -> 0 | DV7: =SUM(DV$3:DV$5) -> 0 | DW7: =SUM(DW$3:DW$5) -> 0 | DY7: =SUM(DY$3:DY$5) -> 0 | DZ7: =SUM(DZ$3:DZ$5) -> 0 | EA7: =SUM(EA$3:EA$5) -> 0 | EC7: =SUM(EC$3:EC$5) -> 0 | ED7: =SUM(ED$3:ED$5) -> 0 | EE7: =SUM(EE$3:EE$5) -> 0 | EG7: =SUM(EG$3:EG$5) -> 0 | EH7: =SUM(EH$3:EH$5) -> 0 | EI7: =SUM(EI$3:EI$5) -> 0 | EK7: =SUM(EK$3:EK$5) -> 0 | EL7: =SUM(EL$3:EL$5) -> 0 | EM7: =SUM(EM$3:EM$5) -> 0 | EO7: =SUM(EO$3:EO$5) -> 0 | EP7: =SUM(EP$3:EP$5) -> 0 | EQ7: =SUM(EQ$3:EQ$5) -> 0 | ES7: =SUM(ES$3:ES$5) -> 0 | ET7: =SUM(ET$3:ET$5) -> 0 | EU7: =SUM(EU$3:EU$5) -> 0 | EW7: =SUM(EW$3:EW$5) -> 0 | EX7: =SUM(EX$3:EX$5) -> 0 | EY7: =SUM(EY$3:EY$5) -> 0 | FA7: =SUM(FA$3:FA$5) -> 0 | FB7: =SUM(FB$3:FB$5) -> 0 | FC7: =SUM(FC$3:FC$5) -> 0 | FE7: =SUM(FE$3:FE$5) -> 0 | FF7: =SUM(FF$3:FF$5) -> 0 | FG7: =SUM(FG$3:FG$5) -> 0 | FI7: =SUM(FI$3:FI$5) -> 0 | FJ7: =SUM(FJ$3:FJ$5) -> 0 | FK7: =SUM(FK$3:FK$5) -> 0 | FM7: =SUM(FM$3:FM$5) -> 0 | FN7: =SUM(FN$3:FN$5) -> 0 | FO7: =SUM(FO$3:FO$5) -> 0 | FQ7: =SUM(FQ$3:FQ$5) -> 0 | FR7: =SUM(FR$3:FR$5) -> 0 | FS7: =SUM(FS$3:FS$5) -> 0 | FU7: =SUM(FU$3:FU$5) -> 0 | FV7: =SUM(FV$3:FV$5) -> 0 | FW7: =SUM(FW$3:FW$5) -> 0 | FY7: =SUM(FY$3:FY$5) -> 0 | FZ7: =SUM(FZ$3:FZ$5) -> 0 | GA7: =SUM(GA$3:GA$5) -> 0 | GC7: =SUM(GC$3:GC$5) -> 0 | GD7: =SUM(GD$3:GD$5) -> 0 | GE7: =SUM(GE$3:GE$5) -> 0 | GG7: =SUM(GG$3:GG$5) -> 0 | GH7: =SUM(GH$3:GH$5) -> 0 | GI7: =SUM(GI$3:GI$5) -> 0 | GK7: =SUM(GK$3:GK$5) -> 0 | GL7: =SUM(GL$3:GL$5) -> 0 | GM7: =SUM(GM$3:GM$5) -> 0 | GO7: =SUM(GO$3:GO$5) -> 0 | GP7: =SUM(GP$3:GP$5) -> 0 | GQ7: =SUM(GQ$3:GQ$5) -> 0 | GS7: =SUM(GS$3:GS$5) -> 0 | GT7: =SUM(GT$3:GT$5) -> 0 | GU7: =SUM(GU$3:GU$5) -> 0 | GW7: =SUM(GW$3:GW$5) -> 0 | GX7: =SUM(GX$3:GX$5) -> 0 | GY7: =SUM(GY$3:GY$5) -> 0 | HA7: =SUM(HA$3:HA$5) -> 0 | HB7: =SUM(HB$3:HB$5) -> 0 | HC7: =SUM(HC$3:HC$5) -> 0 | HE7: =SUM(HE$3:HE$5) -> 0 | HF7: =SUM(HF$3:HF$5) -> 0 | HG7: =SUM(HG$3:HG$5) -> 0 | HI7: =SUM(HI$3:HI$5) -> 0 | HJ7: =SUM(HJ$3:HJ$5) -> 0 | HK7: =SUM(HK$3:HK$5) -> 0 | HM7: =SUM(HM$3:HM$5) -> 0 | HN7: =SUM(HN$3:HN$5) -> 0 | HO7: =SUM(HO$3:HO$5) -> 0 | HQ7: =SUM(HQ$3:HQ$5) -> 0 | HR7: =SUM(HR$3:HR$5) -> 0 | HS7: =SUM(HS$3:HS$5) -> 0 | HU7: =SUM(HU$3:HU$5) -> 0 | HV7: =SUM(HV$3:HV$5) -> 0 | HW7: =SUM(HW$3:HW$5) -> 0 | HY7: =SUM(HY$3:HY$5) -> 0 | HZ7: =SUM(HZ$3:HZ$5) -> 0 | IA7: =SUM(IA$3:IA$5) -> 0 | IC7: =SUM(IC$3:IC$5) -> 0 | ID7: =SUM(ID$3:ID$5) -> 0 | IE7: =SUM(IE$3:IE$5) -> 0 | IG7: =SUM(IG$3:IG$5) -> 0 | IH7: =SUM(IH$3:IH$5) -> 0 | II7: =SUM(II$3:II$5) -> 0 | IK7: =SUM(IK$3:IK$5) -> 0 | IL7: =SUM(IL$3:IL$5) -> 0 | IM7: =SUM(IM$3:IM$5) -> 0 | IO7: =SUM(IO$3:IO$5) -> 0 | IP7: =SUM(IP$3:IP$5) -> 0 | IQ7: =SUM(IQ$3:IQ$5) -> 0 | IS7: =SUM(IS$3:IS$5) -> 0 | IT7: =SUM(IT$3:IT$5) -> 0 | IU7: =SUM(IU$3:IU$5) -> 0 | IW7: =SUM(IW$3:IW$5) -> 0 | IX7: =SUM(IX$3:IX$5) -> 0 | IY7: =SUM(IY$3:IY$5) -> 0 | JA7: =SUM(JA$3:JA$5) -> 0 | JB7: =SUM(JB$3:JB$5) -> 0 | JC7: =SUM(JC$3:JC$5) -> 0 | JE7: =SUM(JE$3:JE$5) -> 0 | JF7: =SUM(JF$3:JF$5) -> 0 | JG7: =SUM(JG$3:JG$5) -> 0 | JI7: =SUM(JI$3:JI$5) -> 0 | JJ7: =SUM(JJ$3:JJ$5) -> 0 | JK7: =SUM(JK$3:JK$5) -> 0 | JM7: =SUM(JM$3:JM$5) -> 0 | JN7: =SUM(JN$3:JN$5) -> 0 | JO7: =SUM(JO$3:JO$5) -> 0 | JQ7: =SUM(JQ$3:JQ$5) -> 0 | JR7: =SUM(JR$3:JR$5) -> 0 | JS7: =SUM(JS$3:JS$5) -> 0 | JU7: =SUM(JU$3:JU$5) -> 0 | JV7: =SUM(JV$3:JV$5) -> 0 | JW7: =SUM(JW$3:JW$5) -> 0 | JY7: =SUM(JY$3:JY$5) -> 0 | JZ7: =SUM(JZ$3:JZ$5) -> 0 | KA7: =SUM(KA$3:KA$5) -> 0 | KC7: =SUM(KC$3:KC$5) -> 0 | KD7: =SUM(KD$3:KD$5) -> 0 | KE7: =SUM(KE$3:KE$5) -> 0 | KG7: =SUM(KG$3:KG$5) -> 0 | KH7: =SUM(KH$3:KH$5) -> 0 | KI7: =SUM(KI$3:KI$5) -> 0 | KK7: =SUM(KK$3:KK$5) -> 0 | KL7: =SUM(KL$3:KL$5) -> 0 | KM7: =SUM(KM$3:KM$5) -> 0 | KO7: =SUM(KO$3:KO$5) -> 0 | KP7: =SUM(KP$3:KP$5) -> 0 | KQ7: =SUM(KQ$3:KQ$5) -> 0 | KR7: =SUM(KR$3:KR$5) -> 0 | KS7: =SUM(KS$3:KS$5) -> 0 | KT7: =SUM(KT$3:KT$5) -> 0 | KU7: =SUM(KU$3:KU$5) -> 0 | KV7: =SUM(KV$3:KV$5) -> 0 | ... KX7: =SUM(KX$3:KX$5) -> 0
A8: AVG | B8: =AVERAGE(B$3:B$5) -> 0 | C8: =AVERAGE(C$3:C$5) -> 0 | E8: =AVERAGE(E$3:E$5) -> 0 | F8: =AVERAGE(F$3:F$5) -> 0 | G8: =AVERAGE(G$3:G$5) -> 0 | I8: =AVERAGE(I$3:I$5) -> 0 | J8: =AVERAGE(J$3:J$5) -> 0 | K8: =AVERAGE(K$3:K$5) -> 0 | M8: =AVERAGE(M$3:M$5) -> 0 | N8: =AVERAGE(N$3:N$5) -> 0 | O8: =AVERAGE(O$3:O$5) -> 0 | Q8: =AVERAGE(Q$3:Q$5) -> 0 | R8: =AVERAGE(R$3:R$5) -> 0 | S8: =AVERAGE(S$3:S$5) -> 0 | U8: =AVERAGE(U$3:U$5) -> 0 | V8: =AVERAGE(V$3:V$5) -> 0 | W8: =AVERAGE(W$3:W$5) -> 0 | Y8: =AVERAGE(Y$3:Y$5) -> 0 | Z8: =AVERAGE(Z$3:Z$5) -> 0 | AA8: =AVERAGE(AA$3:AA$5) -> 0 | AC8: =AVERAGE(AC$3:AC$5) -> 0 | AD8: =AVERAGE(AD$3:AD$5) -> 0 | AE8: =AVERAGE(AE$3:AE$5) -> 0 | AG8: =AVERAGE(AG$3:AG$5) -> 0 | AH8: =AVERAGE(AH$3:AH$5) -> 0 | AI8: =AVERAGE(AI$3:AI$5) -> 0 | AK8: =AVERAGE(AK$3:AK$5) -> 0 | AL8: =AVERAGE(AL$3:AL$5) -> 0 | AM8: =AVERAGE(AM$3:AM$5) -> 0 | AO8: =AVERAGE(AO$3:AO$5) -> 0 | AP8: =AVERAGE(AP$3:AP$5) -> 0 | AQ8: =AVERAGE(AQ$3:AQ$5) -> 0 | AS8: =AVERAGE(AS$3:AS$5) -> 0 | AT8: =AVERAGE(AT$3:AT$5) -> 0 | AU8: =AVERAGE(AU$3:AU$5) -> 0 | AW8: =AVERAGE(AW$3:AW$5) -> 0 | AX8: =AVERAGE(AX$3:AX$5) -> 0 | AY8: =AVERAGE(AY$3:AY$5) -> 0 | BA8: =AVERAGE(BA$3:BA$5) -> 0 | BB8: =AVERAGE(BB$3:BB$5) -> 0 | BC8: =AVERAGE(BC$3:BC$5) -> 0 | BE8: =AVERAGE(BE$3:BE$5) -> 0 | BF8: =AVERAGE(BF$3:BF$5) -> 0 | BG8: =AVERAGE(BG$3:BG$5) -> 0 | BI8: =AVERAGE(BI$3:BI$5) -> 0 | BJ8: =AVERAGE(BJ$3:BJ$5) -> 0 | BK8: =AVERAGE(BK$3:BK$5) -> 0 | BM8: =AVERAGE(BM$3:BM$5) -> 0 | BN8: =AVERAGE(BN$3:BN$5) -> 0 | BO8: =AVERAGE(BO$3:BO$5) -> 0 | BQ8: =AVERAGE(BQ$3:BQ$5) -> 0 | BR8: =AVERAGE(BR$3:BR$5) -> 0 | BS8: =AVERAGE(BS$3:BS$5) -> 0 | BU8: =AVERAGE(BU$3:BU$5) -> 0 | BV8: =AVERAGE(BV$3:BV$5) -> 0 | BW8: =AVERAGE(BW$3:BW$5) -> 0 | BY8: =AVERAGE(BY$3:BY$5) -> 0 | BZ8: =AVERAGE(BZ$3:BZ$5) -> 0 | CA8: =AVERAGE(CA$3:CA$5) -> 0 | CC8: =AVERAGE(CC$3:CC$5) -> 0 | CD8: =AVERAGE(CD$3:CD$5) -> 0 | CE8: =AVERAGE(CE$3:CE$5) -> 0 | CG8: =AVERAGE(CG$3:CG$5) -> 0 | CH8: =AVERAGE(CH$3:CH$5) -> 0 | CI8: =AVERAGE(CI$3:CI$5) -> 0 | CK8: =AVERAGE(CK$3:CK$5) -> 0 | CL8: =AVERAGE(CL$3:CL$5) -> 0 | CM8: =AVERAGE(CM$3:CM$5) -> 0 | CO8: =AVERAGE(CO$3:CO$5) -> 0 | CP8: =AVERAGE(CP$3:CP$5) -> 0 | CQ8: =AVERAGE(CQ$3:CQ$5) -> 0 | CS8: =AVERAGE(CS$3:CS$5) -> 0 | CT8: =AVERAGE(CT$3:CT$5) -> 0 | CU8: =AVERAGE(CU$3:CU$5) -> 0 | CW8: =AVERAGE(CW$3:CW$5) -> 0 | CX8: =AVERAGE(CX$3:CX$5) -> 0 | CY8: =AVERAGE(CY$3:CY$5) -> 0 | DA8: =AVERAGE(DA$3:DA$5) -> 0 | DB8: =AVERAGE(DB$3:DB$5) -> 0 | DC8: =AVERAGE(DC$3:DC$5) -> 0 | DE8: =AVERAGE(DE$3:DE$5) -> 0 | DF8: =AVERAGE(DF$3:DF$5) -> 0 | DG8: =AVERAGE(DG$3:DG$5) -> 0 | DI8: =AVERAGE(DI$3:DI$5) -> 0 | DJ8: =AVERAGE(DJ$3:DJ$5) -> 0 | DK8: =AVERAGE(DK$3:DK$5) -> 0 | DM8: =AVERAGE(DM$3:DM$5) -> 0 | DN8: =AVERAGE(DN$3:DN$5) -> 0 | DO8: =AVERAGE(DO$3:DO$5) -> 0 | DQ8: =AVERAGE(DQ$3:DQ$5) -> 0 | DR8: =AVERAGE(DR$3:DR$5) -> 0 | DS8: =AVERAGE(DS$3:DS$5) -> 0 | DU8: =AVERAGE(DU$3:DU$5) -> 0 | DV8: =AVERAGE(DV$3:DV$5) -> 0 | DW8: =AVERAGE(DW$3:DW$5) -> 0 | DY8: =AVERAGE(DY$3:DY$5) -> 0 | DZ8: =AVERAGE(DZ$3:DZ$5) -> 0 | EA8: =AVERAGE(EA$3:EA$5) -> 0 | EC8: =AVERAGE(EC$3:EC$5) -> 0 | ED8: =AVERAGE(ED$3:ED$5) -> 0 | EE8: =AVERAGE(EE$3:EE$5) -> 0 | EG8: =AVERAGE(EG$3:EG$5) -> 0 | EH8: =AVERAGE(EH$3:EH$5) -> 0 | EI8: =AVERAGE(EI$3:EI$5) -> 0 | EK8: =AVERAGE(EK$3:EK$5) -> 0 | EL8: =AVERAGE(EL$3:EL$5) -> 0 | EM8: =AVERAGE(EM$3:EM$5) -> 0 | EO8: =AVERAGE(EO$3:EO$5) -> 0 | EP8: =AVERAGE(EP$3:EP$5) -> 0 | EQ8: =AVERAGE(EQ$3:EQ$5) -> 0 | ES8: =AVERAGE(ES$3:ES$5) -> 0 | ET8: =AVERAGE(ET$3:ET$5) -> 0 | EU8: =AVERAGE(EU$3:EU$5) -> 0 | EW8: =AVERAGE(EW$3:EW$5) -> 0 | EX8: =AVERAGE(EX$3:EX$5) -> 0 | EY8: =AVERAGE(EY$3:EY$5) -> 0 | FA8: =AVERAGE(FA$3:FA$5) -> 0 | FB8: =AVERAGE(FB$3:FB$5) -> 0 | FC8: =AVERAGE(FC$3:FC$5) -> 0 | FE8: =AVERAGE(FE$3:FE$5) -> 0 | FF8: =AVERAGE(FF$3:FF$5) -> 0 | FG8: =AVERAGE(FG$3:FG$5) -> 0 | FI8: =AVERAGE(FI$3:FI$5) -> 0 | FJ8: =AVERAGE(FJ$3:FJ$5) -> 0 | FK8: =AVERAGE(FK$3:FK$5) -> 0 | FM8: =AVERAGE(FM$3:FM$5) -> 0 | FN8: =AVERAGE(FN$3:FN$5) -> 0 | FO8: =AVERAGE(FO$3:FO$5) -> 0 | FQ8: =AVERAGE(FQ$3:FQ$5) -> 0 | FR8: =AVERAGE(FR$3:FR$5) -> 0 | FS8: =AVERAGE(FS$3:FS$5) -> 0 | FU8: =AVERAGE(FU$3:FU$5) -> 0 | FV8: =AVERAGE(FV$3:FV$5) -> 0 | FW8: =AVERAGE(FW$3:FW$5) -> 0 | FY8: =AVERAGE(FY$3:FY$5) -> 0 | FZ8: =AVERAGE(FZ$3:FZ$5) -> 0 | GA8: =AVERAGE(GA$3:GA$5) -> 0 | GC8: =AVERAGE(GC$3:GC$5) -> 0 | GD8: =AVERAGE(GD$3:GD$5) -> 0 | GE8: =AVERAGE(GE$3:GE$5) -> 0 | GG8: =AVERAGE(GG$3:GG$5) -> 0 | GH8: =AVERAGE(GH$3:GH$5) -> 0 | GI8: =AVERAGE(GI$3:GI$5) -> 0 | GK8: =AVERAGE(GK$3:GK$5) -> 0 | GL8: =AVERAGE(GL$3:GL$5) -> 0 | GM8: =AVERAGE(GM$3:GM$5) -> 0 | GO8: =AVERAGE(GO$3:GO$5) -> 0 | GP8: =AVERAGE(GP$3:GP$5) -> 0 | GQ8: =AVERAGE(GQ$3:GQ$5) -> 0 | GS8: =AVERAGE(GS$3:GS$5) -> 0 | GT8: =AVERAGE(GT$3:GT$5) -> 0 | GU8: =AVERAGE(GU$3:GU$5) -> 0 | GW8: =AVERAGE(GW$3:GW$5) -> 0 | GX8: =AVERAGE(GX$3:GX$5) -> 0 | GY8: =AVERAGE(GY$3:GY$5) -> 0 | HA8: =AVERAGE(HA$3:HA$5) -> 0 | HB8: =AVERAGE(HB$3:HB$5) -> 0 | HC8: =AVERAGE(HC$3:HC$5) -> 0 | HE8: =AVERAGE(HE$3:HE$5) -> 0 | HF8: =AVERAGE(HF$3:HF$5) -> 0 | HG8: =AVERAGE(HG$3:HG$5) -> 0 | HI8: =AVERAGE(HI$3:HI$5) -> 0 | HJ8: =AVERAGE(HJ$3:HJ$5) -> 0 | HK8: =AVERAGE(HK$3:HK$5) -> 0 | HM8: =AVERAGE(HM$3:HM$5) -> 0 | HN8: =AVERAGE(HN$3:HN$5) -> 0 | HO8: =AVERAGE(HO$3:HO$5) -> 0 | HQ8: =AVERAGE(HQ$3:HQ$5) -> 0 | HR8: =AVERAGE(HR$3:HR$5) -> 0 | HS8: =AVERAGE(HS$3:HS$5) -> 0 | HU8: =AVERAGE(HU$3:HU$5) -> 0 | HV8: =AVERAGE(HV$3:HV$5) -> 0 | HW8: =AVERAGE(HW$3:HW$5) -> 0 | HY8: =AVERAGE(HY$3:HY$5) -> 0 | HZ8: =AVERAGE(HZ$3:HZ$5) -> 0 | IA8: =AVERAGE(IA$3:IA$5) -> 0 | IC8: =AVERAGE(IC$3:IC$5) -> 0 | ID8: =AVERAGE(ID$3:ID$5) -> 0 | IE8: =AVERAGE(IE$3:IE$5) -> 0 | IG8: =AVERAGE(IG$3:IG$5) -> 0 | IH8: =AVERAGE(IH$3:IH$5) -> 0 | II8: =AVERAGE(II$3:II$5) -> 0 | IK8: =AVERAGE(IK$3:IK$5) -> 0 | IL8: =AVERAGE(IL$3:IL$5) -> 0 | IM8: =AVERAGE(IM$3:IM$5) -> 0 | IO8: =AVERAGE(IO$3:IO$5) -> 0 | IP8: =AVERAGE(IP$3:IP$5) -> 0 | IQ8: =AVERAGE(IQ$3:IQ$5) -> 0 | IS8: =AVERAGE(IS$3:IS$5) -> 0 | IT8: =AVERAGE(IT$3:IT$5) -> 0 | IU8: =AVERAGE(IU$3:IU$5) -> 0 | IW8: =AVERAGE(IW$3:IW$5) -> 0 | IX8: =AVERAGE(IX$3:IX$5) -> 0 | IY8: =AVERAGE(IY$3:IY$5) -> 0 | JA8: =AVERAGE(JA$3:JA$5) -> 0 | JB8: =AVERAGE(JB$3:JB$5) -> 0 | JC8: =AVERAGE(JC$3:JC$5) -> 0 | JE8: =AVERAGE(JE$3:JE$5) -> 0 | JF8: =AVERAGE(JF$3:JF$5) -> 0 | JG8: =AVERAGE(JG$3:JG$5) -> 0 | JI8: =AVERAGE(JI$3:JI$5) -> 0 | JJ8: =AVERAGE(JJ$3:JJ$5) -> 0 | JK8: =AVERAGE(JK$3:JK$5) -> 0 | JM8: =AVERAGE(JM$3:JM$5) -> 0 | JN8: =AVERAGE(JN$3:JN$5) -> 0 | JO8: =AVERAGE(JO$3:JO$5) -> 0 | JQ8: =AVERAGE(JQ$3:JQ$5) -> 0 | JR8: =AVERAGE(JR$3:JR$5) -> 0 | JS8: =AVERAGE(JS$3:JS$5) -> 0 | JU8: =AVERAGE(JU$3:JU$5) -> 0 | JV8: =AVERAGE(JV$3:JV$5) -> 0 | JW8: =AVERAGE(JW$3:JW$5) -> 0 | JY8: =AVERAGE(JY$3:JY$5) -> 0 | JZ8: =AVERAGE(JZ$3:JZ$5) -> 0 | KA8: =AVERAGE(KA$3:KA$5) -> 0 | KC8: =AVERAGE(KC$3:KC$5) -> 0 | KD8: =AVERAGE(KD$3:KD$5) -> 0 | KE8: =AVERAGE(KE$3:KE$5) -> 0 | KG8: =AVERAGE(KG$3:KG$5) -> 0 | KH8: =AVERAGE(KH$3:KH$5) -> 0 | KI8: =AVERAGE(KI$3:KI$5) -> 0 | KK8: =AVERAGE(KK$3:KK$5) -> 0 | KL8: =AVERAGE(KL$3:KL$5) -> 0 | KM8: =AVERAGE(KM$3:KM$5) -> 0 | KO8: =AVERAGE(KO$3:KO$5) -> 0 | KP8: =AVERAGE(KP$3:KP$5) -> 0 | KQ8: =AVERAGE(KQ$3:KQ$5) -> 0 | KR8: =AVERAGE(KR$3:KR$5) -> 0 | KS8: =AVERAGE(KS$3:KS$5) -> 0 | KT8: =AVERAGE(KT$3:KT$5) -> 0 | KU8: =AVERAGE(KU$3:KU$5) -> 0 | KV8: =AVERAGE(KV$3:KV$5) -> 0 | ... KX8: =AVERAGE(KX$3:KX$5) -> 0
A9: DEV | B9: =STDEV(B$3:B$5) -> 0 | C9: =STDEV(C$3:C$5) -> 0 | E9: =STDEV(E$3:E$5) -> 0 | F9: =STDEV(F$3:F$5) -> 0 | G9: =STDEV(G$3:G$5) -> 0 | I9: =STDEV(I$3:I$5) -> 0 | J9: =STDEV(J$3:J$5) -> 0 | K9: =STDEV(K$3:K$5) -> 0 | M9: =STDEV(M$3:M$5) -> 0 | N9: =STDEV(N$3:N$5) -> 0 | O9: =STDEV(O$3:O$5) -> 0 | Q9: =STDEV(Q$3:Q$5) -> 0 | R9: =STDEV(R$3:R$5) -> 0 | S9: =STDEV(S$3:S$5) -> 0 | U9: =STDEV(U$3:U$5) -> 0 | V9: =STDEV(V$3:V$5) -> 0 | W9: =STDEV(W$3:W$5) -> 0 | Y9: =STDEV(Y$3:Y$5) -> 0 | Z9: =STDEV(Z$3:Z$5) -> 0 | AA9: =STDEV(AA$3:AA$5) -> 0 | AC9: =STDEV(AC$3:AC$5) -> 0 | AD9: =STDEV(AD$3:AD$5) -> 0 | AE9: =STDEV(AE$3:AE$5) -> 0 | AG9: =STDEV(AG$3:AG$5) -> 0 | AH9: =STDEV(AH$3:AH$5) -> 0 | AI9: =STDEV(AI$3:AI$5) -> 0 | AK9: =STDEV(AK$3:AK$5) -> 0 | AL9: =STDEV(AL$3:AL$5) -> 0 | AM9: =STDEV(AM$3:AM$5) -> 0 | AO9: =STDEV(AO$3:AO$5) -> 0 | AP9: =STDEV(AP$3:AP$5) -> 0 | AQ9: =STDEV(AQ$3:AQ$5) -> 0 | AS9: =STDEV(AS$3:AS$5) -> 0 | AT9: =STDEV(AT$3:AT$5) -> 0 | AU9: =STDEV(AU$3:AU$5) -> 0 | AW9: =STDEV(AW$3:AW$5) -> 0 | AX9: =STDEV(AX$3:AX$5) -> 0 | AY9: =STDEV(AY$3:AY$5) -> 0 | BA9: =STDEV(BA$3:BA$5) -> 0 | BB9: =STDEV(BB$3:BB$5) -> 0 | BC9: =STDEV(BC$3:BC$5) -> 0 | BE9: =STDEV(BE$3:BE$5) -> 0 | BF9: =STDEV(BF$3:BF$5) -> 0 | BG9: =STDEV(BG$3:BG$5) -> 0 | BI9: =STDEV(BI$3:BI$5) -> 0 | BJ9: =STDEV(BJ$3:BJ$5) -> 0 | BK9: =STDEV(BK$3:BK$5) -> 0 | BM9: =STDEV(BM$3:BM$5) -> 0 | BN9: =STDEV(BN$3:BN$5) -> 0 | BO9: =STDEV(BO$3:BO$5) -> 0 | BQ9: =STDEV(BQ$3:BQ$5) -> 0 | BR9: =STDEV(BR$3:BR$5) -> 0 | BS9: =STDEV(BS$3:BS$5) -> 0 | BU9: =STDEV(BU$3:BU$5) -> 0 | BV9: =STDEV(BV$3:BV$5) -> 0 | BW9: =STDEV(BW$3:BW$5) -> 0 | BY9: =STDEV(BY$3:BY$5) -> 0 | BZ9: =STDEV(BZ$3:BZ$5) -> 0 | CA9: =STDEV(CA$3:CA$5) -> 0 | CC9: =STDEV(CC$3:CC$5) -> 0 | CD9: =STDEV(CD$3:CD$5) -> 0 | CE9: =STDEV(CE$3:CE$5) -> 0 | CG9: =STDEV(CG$3:CG$5) -> 0 | CH9: =STDEV(CH$3:CH$5) -> 0 | CI9: =STDEV(CI$3:CI$5) -> 0 | CK9: =STDEV(CK$3:CK$5) -> 0 | CL9: =STDEV(CL$3:CL$5) -> 0 | CM9: =STDEV(CM$3:CM$5) -> 0 | CO9: =STDEV(CO$3:CO$5) -> 0 | CP9: =STDEV(CP$3:CP$5) -> 0 | CQ9: =STDEV(CQ$3:CQ$5) -> 0 | CS9: =STDEV(CS$3:CS$5) -> 0 | CT9: =STDEV(CT$3:CT$5) -> 0 | CU9: =STDEV(CU$3:CU$5) -> 0 | CW9: =STDEV(CW$3:CW$5) -> 0 | CX9: =STDEV(CX$3:CX$5) -> 0 | CY9: =STDEV(CY$3:CY$5) -> 0 | DA9: =STDEV(DA$3:DA$5) -> 0 | DB9: =STDEV(DB$3:DB$5) -> 0 | DC9: =STDEV(DC$3:DC$5) -> 0 | DE9: =STDEV(DE$3:DE$5) -> 0 | DF9: =STDEV(DF$3:DF$5) -> 0 | DG9: =STDEV(DG$3:DG$5) -> 0 | DI9: =STDEV(DI$3:DI$5) -> 0 | DJ9: =STDEV(DJ$3:DJ$5) -> 0 | DK9: =STDEV(DK$3:DK$5) -> 0 | DM9: =STDEV(DM$3:DM$5) -> 0 | DN9: =STDEV(DN$3:DN$5) -> 0 | DO9: =STDEV(DO$3:DO$5) -> 0 | DQ9: =STDEV(DQ$3:DQ$5) -> 0 | DR9: =STDEV(DR$3:DR$5) -> 0 | DS9: =STDEV(DS$3:DS$5) -> 0 | DU9: =STDEV(DU$3:DU$5) -> 0 | DV9: =STDEV(DV$3:DV$5) -> 0 | DW9: =STDEV(DW$3:DW$5) -> 0 | DY9: =STDEV(DY$3:DY$5) -> 0 | DZ9: =STDEV(DZ$3:DZ$5) -> 0 | EA9: =STDEV(EA$3:EA$5) -> 0 | EC9: =STDEV(EC$3:EC$5) -> 0 | ED9: =STDEV(ED$3:ED$5) -> 0 | EE9: =STDEV(EE$3:EE$5) -> 0 | EG9: =STDEV(EG$3:EG$5) -> 0 | EH9: =STDEV(EH$3:EH$5) -> 0 | EI9: =STDEV(EI$3:EI$5) -> 0 | EK9: =STDEV(EK$3:EK$5) -> 0 | EL9: =STDEV(EL$3:EL$5) -> 0 | EM9: =STDEV(EM$3:EM$5) -> 0 | EO9: =STDEV(EO$3:EO$5) -> 0 | EP9: =STDEV(EP$3:EP$5) -> 0 | EQ9: =STDEV(EQ$3:EQ$5) -> 0 | ES9: =STDEV(ES$3:ES$5) -> 0 | ET9: =STDEV(ET$3:ET$5) -> 0 | EU9: =STDEV(EU$3:EU$5) -> 0 | EW9: =STDEV(EW$3:EW$5) -> 0 | EX9: =STDEV(EX$3:EX$5) -> 0 | EY9: =STDEV(EY$3:EY$5) -> 0 | FA9: =STDEV(FA$3:FA$5) -> 0 | FB9: =STDEV(FB$3:FB$5) -> 0 | FC9: =STDEV(FC$3:FC$5) -> 0 | FE9: =STDEV(FE$3:FE$5) -> 0 | FF9: =STDEV(FF$3:FF$5) -> 0 | FG9: =STDEV(FG$3:FG$5) -> 0 | FI9: =STDEV(FI$3:FI$5) -> 0 | FJ9: =STDEV(FJ$3:FJ$5) -> 0 | FK9: =STDEV(FK$3:FK$5) -> 0 | FM9: =STDEV(FM$3:FM$5) -> 0 | FN9: =STDEV(FN$3:FN$5) -> 0 | FO9: =STDEV(FO$3:FO$5) -> 0 | FQ9: =STDEV(FQ$3:FQ$5) -> 0 | FR9: =STDEV(FR$3:FR$5) -> 0 | FS9: =STDEV(FS$3:FS$5) -> 0 | FU9: =STDEV(FU$3:FU$5) -> 0 | FV9: =STDEV(FV$3:FV$5) -> 0 | FW9: =STDEV(FW$3:FW$5) -> 0 | FY9: =STDEV(FY$3:FY$5) -> 0 | FZ9: =STDEV(FZ$3:FZ$5) -> 0 | GA9: =STDEV(GA$3:GA$5) -> 0 | GC9: =STDEV(GC$3:GC$5) -> 0 | GD9: =STDEV(GD$3:GD$5) -> 0 | GE9: =STDEV(GE$3:GE$5) -> 0 | GG9: =STDEV(GG$3:GG$5) -> 0 | GH9: =STDEV(GH$3:GH$5) -> 0 | GI9: =STDEV(GI$3:GI$5) -> 0 | GK9: =STDEV(GK$3:GK$5) -> 0 | GL9: =STDEV(GL$3:GL$5) -> 0 | GM9: =STDEV(GM$3:GM$5) -> 0 | GO9: =STDEV(GO$3:GO$5) -> 0 | GP9: =STDEV(GP$3:GP$5) -> 0 | GQ9: =STDEV(GQ$3:GQ$5) -> 0 | GS9: =STDEV(GS$3:GS$5) -> 0 | GT9: =STDEV(GT$3:GT$5) -> 0 | GU9: =STDEV(GU$3:GU$5) -> 0 | GW9: =STDEV(GW$3:GW$5) -> 0 | GX9: =STDEV(GX$3:GX$5) -> 0 | GY9: =STDEV(GY$3:GY$5) -> 0 | HA9: =STDEV(HA$3:HA$5) -> 0 | HB9: =STDEV(HB$3:HB$5) -> 0 | HC9: =STDEV(HC$3:HC$5) -> 0 | HE9: =STDEV(HE$3:HE$5) -> 0 | HF9: =STDEV(HF$3:HF$5) -> 0 | HG9: =STDEV(HG$3:HG$5) -> 0 | HI9: =STDEV(HI$3:HI$5) -> 0 | HJ9: =STDEV(HJ$3:HJ$5) -> 0 | HK9: =STDEV(HK$3:HK$5) -> 0 | HM9: =STDEV(HM$3:HM$5) -> 0 | HN9: =STDEV(HN$3:HN$5) -> 0 | HO9: =STDEV(HO$3:HO$5) -> 0 | HQ9: =STDEV(HQ$3:HQ$5) -> 0 | HR9: =STDEV(HR$3:HR$5) -> 0 | HS9: =STDEV(HS$3:HS$5) -> 0 | HU9: =STDEV(HU$3:HU$5) -> 0 | HV9: =STDEV(HV$3:HV$5) -> 0 | HW9: =STDEV(HW$3:HW$5) -> 0 | HY9: =STDEV(HY$3:HY$5) -> 0 | HZ9: =STDEV(HZ$3:HZ$5) -> 0 | IA9: =STDEV(IA$3:IA$5) -> 0 | IC9: =STDEV(IC$3:IC$5) -> 0 | ID9: =STDEV(ID$3:ID$5) -> 0 | IE9: =STDEV(IE$3:IE$5) -> 0 | IG9: =STDEV(IG$3:IG$5) -> 0 | IH9: =STDEV(IH$3:IH$5) -> 0 | II9: =STDEV(II$3:II$5) -> 0 | IK9: =STDEV(IK$3:IK$5) -> 0 | IL9: =STDEV(IL$3:IL$5) -> 0 | IM9: =STDEV(IM$3:IM$5) -> 0 | IO9: =STDEV(IO$3:IO$5) -> 0 | IP9: =STDEV(IP$3:IP$5) -> 0 | IQ9: =STDEV(IQ$3:IQ$5) -> 0 | IS9: =STDEV(IS$3:IS$5) -> 0 | IT9: =STDEV(IT$3:IT$5) -> 0 | IU9: =STDEV(IU$3:IU$5) -> 0 | IW9: =STDEV(IW$3:IW$5) -> 0 | IX9: =STDEV(IX$3:IX$5) -> 0 | IY9: =STDEV(IY$3:IY$5) -> 0 | JA9: =STDEV(JA$3:JA$5) -> 0 | JB9: =STDEV(JB$3:JB$5) -> 0 | JC9: =STDEV(JC$3:JC$5) -> 0 | JE9: =STDEV(JE$3:JE$5) -> 0 | JF9: =STDEV(JF$3:JF$5) -> 0 | JG9: =STDEV(JG$3:JG$5) -> 0 | JI9: =STDEV(JI$3:JI$5) -> 0 | JJ9: =STDEV(JJ$3:JJ$5) -> 0 | JK9: =STDEV(JK$3:JK$5) -> 0 | JM9: =STDEV(JM$3:JM$5) -> 0 | JN9: =STDEV(JN$3:JN$5) -> 0 | JO9: =STDEV(JO$3:JO$5) -> 0 | JQ9: =STDEV(JQ$3:JQ$5) -> 0 | JR9: =STDEV(JR$3:JR$5) -> 0 | JS9: =STDEV(JS$3:JS$5) -> 0 | JU9: =STDEV(JU$3:JU$5) -> 0 | JV9: =STDEV(JV$3:JV$5) -> 0 | JW9: =STDEV(JW$3:JW$5) -> 0 | JY9: =STDEV(JY$3:JY$5) -> 0 | JZ9: =STDEV(JZ$3:JZ$5) -> 0 | KA9: =STDEV(KA$3:KA$5) -> 0 | KC9: =STDEV(KC$3:KC$5) -> 0 | KD9: =STDEV(KD$3:KD$5) -> 0 | KE9: =STDEV(KE$3:KE$5) -> 0 | KG9: =STDEV(KG$3:KG$5) -> 0 | KH9: =STDEV(KH$3:KH$5) -> 0 | KI9: =STDEV(KI$3:KI$5) -> 0 | KK9: =STDEV(KK$3:KK$5) -> 0 | KL9: =STDEV(KL$3:KL$5) -> 0 | KM9: =STDEV(KM$3:KM$5) -> 0 | KO9: =STDEV(KO$3:KO$5) -> 0 | KP9: =STDEV(KP$3:KP$5) -> 0 | KQ9: =STDEV(KQ$3:KQ$5) -> 0 | KR9: =STDEV(KR$3:KR$5) -> 0 | KS9: =STDEV(KS$3:KS$5) -> 0 | KT9: =STDEV(KT$3:KT$5) -> 0 | KU9: =STDEV(KU$3:KU$5) -> 0 | KV9: =STDEV(KV$3:KV$5) -> 0 | ... KX9: =STDEV(KX$3:KX$5) -> 0
