Workbook

Sheet Instances
B1: memelingo-1/lambda-large_30_mlp-tplp-htc | F1: memelingo-1/lambda-large_30_mlp-tplp-htcdl | J1: memelingo-1/lambda-large_35_mlp-tplp-htc | N1: memelingo-1/lambda-large_35_mlp-tplp-htcdl | R1: memelingo-1/lambda-large_40_mlp-tplp-htc | V1: memelingo-1/lambda-large_40_mlp-tplp-htcdl | Z1: memelingo-1/lambda-large_45_mlp-tplp-htc | AD1: memelingo-1/lambda-large_45_mlp-tplp-htcdl | AH1: memelingo-1/lambda-large_50_mlp-tplp-htc | AL1: memelingo-1/lambda-large_50_mlp-tplp-htcdl | AP1: memelingo-1/lambda-large_55_mlp-tplp-htc | AT1: memelingo-1/lambda-large_55_mlp-tplp-htcdl | AX1: memelingo-1/lambda-large_60_mlp-tplp-htc | BB1: memelingo-1/lambda-large_60_mlp-tplp-htcdl | BF1: memelingo-1/lambda-small_10_mlp-tplp-ht | BJ1: memelingo-1/lambda-small_10_mlp-tplp-htc | BN1: memelingo-1/lambda-small_10_mlp-tplp-htcdl | BR1: memelingo-1/lambda-small_12_mlp-tplp-ht | BV1: memelingo-1/lambda-small_12_mlp-tplp-htc | BZ1: memelingo-1/lambda-small_12_mlp-tplp-htcdl | CD1: memelingo-1/lambda-small_14_mlp-tplp-ht | CH1: memelingo-1/lambda-small_14_mlp-tplp-htc | CL1: memelingo-1/lambda-small_14_mlp-tplp-htcdl | CP1: memelingo-1/lambda-small_16_mlp-tplp-ht | CT1: memelingo-1/lambda-small_16_mlp-tplp-htc | CX1: memelingo-1/lambda-small_16_mlp-tplp-htcdl | DB1: memelingo-1/lambda-small_18_mlp-tplp-ht | DF1: memelingo-1/lambda-small_18_mlp-tplp-htc | DJ1: memelingo-1/lambda-small_18_mlp-tplp-htcdl | DN1: memelingo-1/lambda-small_20_mlp-tplp-ht | DR1: memelingo-1/lambda-small_20_mlp-tplp-htc | DV1: memelingo-1/lambda-small_20_mlp-tplp-htcdl | DZ1: memelingo-1/lambda-small_22_mlp-tplp-ht | ED1: memelingo-1/lambda-small_22_mlp-tplp-htc | EH1: memelingo-1/lambda-small_22_mlp-tplp-htcdl | EL1: min | EO1: median | ER1: max
B2: time | C2: stime | D2: status | E2: rules | F2: time | G2: stime | H2: status | I2: rules | J2: time | K2: stime | L2: status | M2: rules | N2: time | O2: stime | P2: status | Q2: rules | R2: time | S2: stime | T2: status | U2: rules | V2: time | W2: stime | X2: status | Y2: rules | Z2: time | AA2: stime | AB2: status | AC2: rules | AD2: time | AE2: stime | AF2: status | AG2: rules | AH2: time | AI2: stime | AJ2: status | AK2: rules | AL2: time | AM2: stime | AN2: status | AO2: rules | AP2: time | AQ2: stime | AR2: status | AS2: rules | AT2: time | AU2: stime | AV2: status | AW2: rules | AX2: time | AY2: stime | AZ2: status | BA2: rules | BB2: time | BC2: stime | BD2: status | BE2: rules | BF2: time | BG2: stime | BH2: status | BI2: rules | BJ2: time | BK2: stime | BL2: status | BM2: rules | BN2: time | BO2: stime | BP2: status | BQ2: rules | BR2: time | BS2: stime | BT2: status | BU2: rules | BV2: time | BW2: stime | BX2: status | BY2: rules | BZ2: time | CA2: stime | CB2: status | CC2: rules | CD2: time | CE2: stime | CF2: status | CG2: rules | CH2: time | CI2: stime | CJ2: status | CK2: rules | CL2: time | CM2: stime | CN2: status | CO2: rules | CP2: time | CQ2: stime | CR2: status | CS2: rules | CT2: time | CU2: stime | CV2: status | CW2: rules | CX2: time | CY2: stime | CZ2: status | DA2: rules | DB2: time | DC2: stime | DD2: status | DE2: rules | DF2: time | DG2: stime | DH2: status | DI2: rules | DJ2: time | DK2: stime | DL2: status | DM2: rules | DN2: time | DO2: stime | DP2: status | DQ2: rules | DR2: time | DS2: stime | DT2: status | DU2: rules | DV2: time | DW2: stime | DX2: status | DY2: rules | DZ2: time | EA2: stime | EB2: status | EC2: rules | ED2: time | EE2: stime | EF2: status | EG2: rules | EH2: time | EI2: stime | EJ2: status | EK2: rules | EL2: time | EM2: stime | EN2: rules | EO2: time | EP2: stime | EQ2: rules | ER2: time | ES2: stime | ET2: rules
A3: instances/ft06 | BF3: 320.78 | BG3: 306.46 | BH3: UNSATISFIABLE | BI3: 1706377 | BJ3: 10.83 | BK3: 3.62 | BL3: UNSATISFIABLE | BM3: 77480 | BN3: 9.55 | BO3: 1.95 | BP3: SATISFIABLE | BQ3: 77470 | BR3: 186.22 | BS3: 165.76 | BT3: SATISFIABLE | BU3: 2382465 | BV3: 12.61 | BW3: 5.05 | BX3: SATISFIABLE | BY3: 99618 | BZ3: 12.43 | CA3: 4.6 | CB3: SATISFIABLE | CC3: 99606 | CD3: 312.71 | CE3: 290.81 | CF3: SATISFIABLE | CG3: 3130110 | CH3: 21.76 | CI3: 13.25 | CJ3: SATISFIABLE | CK3: 124172 | CL3: 16.76 | CM3: 8.74 | CN3: SATISFIABLE | CO3: 124158 | CP3: 338.49 | CQ3: 310.84 | CR3: SATISFIABLE | CS3: 3933988 | CT3: 13.7 | CU3: 5.08 | CV3: SATISFIABLE | CW3: 151142 | CX3: 22.37 | CY3: 14.01 | CZ3: SATISFIABLE | DA3: 151126 | DB3: 131.53 | DC3: 98.55 | DD3: SATISFIABLE | DE3: 4779687 | DF3: 12.49 | DG3: 3.52 | DH3: SATISFIABLE | DI3: 180528 | DJ3: 28.88 | DK3: 19.91 | DL3: SATISFIABLE | DM3: 180510 | DN3: 69.84 | DO3: 30.71 | DP3: SATISFIABLE | DQ3: 5653707 | DR3: 13.83 | DS3: 4.66 | DT3: SATISFIABLE | DU3: 212330 | DV3: 43.6 | DW3: 34.53 | DX3: SATISFIABLE | DY3: 212310 | DZ3: 110.07 | EA3: 64.4 | EB3: SATISFIABLE | EC3: 6543460 | ED3: 14.3 | EE3: 5.29 | EF3: SATISFIABLE | EG3: 246548 | EH3: 53.45 | EI3: 44.7 | EJ3: SATISFIABLE | EK3: 246526 | EL3: =MIN($B3,$F3,$J3,$N3,$R3,$V3,$Z3,$AD3,$AH3,$AL3,$AP3,$AT3,$AX3,$BB3,$BF3,$BJ3,$BN3,$BR3,$BV3,$BZ3,$CD3,$CH3,$CL3,$CP3,$CT3,$CX3,$DB3,$DF3,$DJ3,$DN3,$DR3,$DV3,$DZ3,$ED3,$EH3) -> 0 | EM3: =MIN($C3,$G3,$K3,$O3,$S3,$W3,$AA3,$AE3,$AI3,$AM3,$AQ3,$AU3,$AY3,$BC3,$BG3,$BK3,$BO3,$BS3,$BW3,$CA3,$CE3,$CI3,$CM3,$CQ3,$CU3,$CY3,$DC3,$DG3,$DK3,$DO3,$DS3,$DW3,$EA3,$EE3,$EI3) -> 0 | EN3: =MIN($E3,$I3,$M3,$Q3,$U3,$Y3,$AC3,$AG3,$AK3,$AO3,$AS3,$AW3,$BA3,$BE3,$BI3,$BM3,$BQ3,$BU3,$BY3,$CC3,$CG3,$CK3,$CO3,$CS3,$CW3,$DA3,$DE3,$DI3,$DM3,$DQ3,$DU3,$DY3,$EC3,$EG3,$EK3) -> 0 | EO3: =MEDIAN($B3,$F3,$J3,$N3,$R3,$V3,$Z3,$AD3,$AH3,$AL3,$AP3,$AT3,$AX3,$BB3,$BF3,$BJ3,$BN3,$BR3,$BV3,$BZ3,$CD3,$CH3,$CL3,$CP3,$CT3,$CX3,$DB3,$DF3,$DJ3,$DN3,$DR3,$DV3,$DZ3,$ED3,$EH3) -> 0 | EP3: =MEDIAN($C3,$G3,$K3,$O3,$S3,$W3,$AA3,$AE3,$AI3,$AM3,$AQ3,$AU3,$AY3,$BC3,$BG3,$BK3,$BO3,$BS3,$BW3,$CA3,$CE3,$CI3,$CM3,$CQ3,$CU3,$CY3,$DC3,$DG3,$DK3,$DO3,$DS3,$DW3,$EA3,$EE3,$EI3) -> 0 | EQ3: =MEDIAN($E3,$I3,$M3,$Q3,$U3,$Y3,$AC3,$AG3,$AK3,$AO3,$AS3,$AW3,$BA3,$BE3,$BI3,$BM3,$BQ3,$BU3,$BY3,$CC3,$CG3,$CK3,$CO3,$CS3,$CW3,$DA3,$DE3,$DI3,$DM3,$DQ3,$DU3,$DY3,$EC3,$EG3,$EK3) -> 0 | ER3: =MAX($B3,$F3,$J3,$N3,$R3,$V3,$Z3,$AD3,$AH3,$AL3,$AP3,$AT3,$AX3,$BB3,$BF3,$BJ3,$BN3,$BR3,$BV3,$BZ3,$CD3,$CH3,$CL3,$CP3,$CT3,$CX3,$DB3,$DF3,$DJ3,$DN3,$DR3,$DV3,$DZ3,$ED3,$EH3) -> 0 | ES3: =MAX($C3,$G3,$K3,$O3,$S3,$W3,$AA3,$AE3,$AI3,$AM3,$AQ3,$AU3,$AY3,$BC3,$BG3,$BK3,$BO3,$BS3,$BW3,$CA3,$CE3,$CI3,$CM3,$CQ3,$CU3,$CY3,$DC3,$DG3,$DK3,$DO3,$DS3,$DW3,$EA3,$EE3,$EI3) -> 0 | ET3: =MAX($E3,$I3,$M3,$Q3,$U3,$Y3,$AC3,$AG3,$AK3,$AO3,$AS3,$AW3,$BA3,$BE3,$BI3,$BM3,$BQ3,$BU3,$BY3,$CC3,$CG3,$CK3,$CO3,$CS3,$CW3,$DA3,$DE3,$DI3,$DM3,$DQ3,$DU3,$DY3,$EC3,$EG3,$EK3) -> 0
A4: instances/ft10const10 | B4: 1200 | D4: UNKNOWN | F4: 87.94 | G4: 69.4 | H4: SATISFIABLE | I4: 1120051 | J4: 1200 | L4: UNKNOWN | N4: 161.84 | O4: 140.85 | P4: SATISFIABLE | Q4: 1445626 | R4: 1200 | T4: UNKNOWN | V4: 234.91 | W4: 209.72 | X4: SATISFIABLE | Y4: 1811326 | Z4: 1200 | AB4: UNKNOWN | AD4: 299.43 | AE4: 269.8 | AF4: SATISFIABLE | AG4: 2217151 | AH4: 1200 | AJ4: UNKNOWN | AL4: 497.9 | AM4: 464.12 | AN4: SATISFIABLE | AO4: 2663101 | AP4: 1200 | AR4: UNKNOWN | AT4: 810.46 | AU4: 772.75 | AV4: SATISFIABLE | AW4: 3149176 | AX4: 1200 | AZ4: UNKNOWN | BB4: 912.57 | BC4: 867.15 | BD4: SATISFIABLE | BE4: 3675376 | EL4: =MIN($B4,$F4,$J4,$N4,$R4,$V4,$Z4,$AD4,$AH4,$AL4,$AP4,$AT4,$AX4,$BB4,$BF4,$BJ4,$BN4,$BR4,$BV4,$BZ4,$CD4,$CH4,$CL4,$CP4,$CT4,$CX4,$DB4,$DF4,$DJ4,$DN4,$DR4,$DV4,$DZ4,$ED4,$EH4) -> 0 | EM4: =MIN($C4,$G4,$K4,$O4,$S4,$W4,$AA4,$AE4,$AI4,$AM4,$AQ4,$AU4,$AY4,$BC4,$BG4,$BK4,$BO4,$BS4,$BW4,$CA4,$CE4,$CI4,$CM4,$CQ4,$CU4,$CY4,$DC4,$DG4,$DK4,$DO4,$DS4,$DW4,$EA4,$EE4,$EI4) -> 0 | EN4: =MIN($E4,$I4,$M4,$Q4,$U4,$Y4,$AC4,$AG4,$AK4,$AO4,$AS4,$AW4,$BA4,$BE4,$BI4,$BM4,$BQ4,$BU4,$BY4,$CC4,$CG4,$CK4,$CO4,$CS4,$CW4,$DA4,$DE4,$DI4,$DM4,$DQ4,$DU4,$DY4,$EC4,$EG4,$EK4) -> 0 | EO4: =MEDIAN($B4,$F4,$J4,$N4,$R4,$V4,$Z4,$AD4,$AH4,$AL4,$AP4,$AT4,$AX4,$BB4,$BF4,$BJ4,$BN4,$BR4,$BV4,$BZ4,$CD4,$CH4,$CL4,$CP4,$CT4,$CX4,$DB4,$DF4,$DJ4,$DN4,$DR4,$DV4,$DZ4,$ED4,$EH4) -> 0 | EP4: =MEDIAN($C4,$G4,$K4,$O4,$S4,$W4,$AA4,$AE4,$AI4,$AM4,$AQ4,$AU4,$AY4,$BC4,$BG4,$BK4,$BO4,$BS4,$BW4,$CA4,$CE4,$CI4,$CM4,$CQ4,$CU4,$CY4,$DC4,$DG4,$DK4,$DO4,$DS4,$DW4,$EA4,$EE4,$EI4) -> 0 | EQ4: =MEDIAN($E4,$I4,$M4,$Q4,$U4,$Y4,$AC4,$AG4,$AK4,$AO4,$AS4,$AW4,$BA4,$BE4,$BI4,$BM4,$BQ4,$BU4,$BY4,$CC4,$CG4,$CK4,$CO4,$CS4,$CW4,$DA4,$DE4,$DI4,$DM4,$DQ4,$DU4,$DY4,$EC4,$EG4,$EK4) -> 0 | ER4: =MAX($B4,$F4,$J4,$N4,$R4,$V4,$Z4,$AD4,$AH4,$AL4,$AP4,$AT4,$AX4,$BB4,$BF4,$BJ4,$BN4,$BR4,$BV4,$BZ4,$CD4,$CH4,$CL4,$CP4,$CT4,$CX4,$DB4,$DF4,$DJ4,$DN4,$DR4,$DV4,$DZ4,$ED4,$EH4) -> 0 | ES4: =MAX($C4,$G4,$K4,$O4,$S4,$W4,$AA4,$AE4,$AI4,$AM4,$AQ4,$AU4,$AY4,$BC4,$BG4,$BK4,$BO4,$BS4,$BW4,$CA4,$CE4,$CI4,$CM4,$CQ4,$CU4,$CY4,$DC4,$DG4,$DK4,$DO4,$DS4,$DW4,$EA4,$EE4,$EI4) -> 0 | ET4: =MAX($E4,$I4,$M4,$Q4,$U4,$Y4,$AC4,$AG4,$AK4,$AO4,$AS4,$AW4,$BA4,$BE4,$BI4,$BM4,$BQ4,$BU4,$BY4,$CC4,$CG4,$CK4,$CO4,$CS4,$CW4,$DA4,$DE4,$DI4,$DM4,$DQ4,$DU4,$DY4,$EC4,$EG4,$EK4) -> 0
A5: instances/ft10const15 | B5: 1200 | D5: UNKNOWN | F5: 84.47 | G5: 66.77 | H5: SATISFIABLE | I5: 1120051 | J5: 1200 | L5: UNKNOWN | N5: 125.63 | O5: 103.6 | P5: SATISFIABLE | Q5: 1445626 | R5: 1200 | T5: UNKNOWN | V5: 243.3 | W5: 218.23 | X5: SATISFIABLE | Y5: 1811326 | Z5: 1200 | AB5: UNKNOWN | AD5: 316.06 | AE5: 286.12 | AF5: SATISFIABLE | AG5: 2217151 | AH5: 1200 | AJ5: UNKNOWN | AL5: 528.11 | AM5: 497.06 | AN5: SATISFIABLE | AO5: 2663101 | AP5: 1200 | AR5: UNKNOWN | AT5: 765.94 | AU5: 724.64 | AV5: SATISFIABLE | AW5: 3149176 | AX5: 1200 | AZ5: UNKNOWN | BB5: 968.26 | BC5: 922.9 | BD5: SATISFIABLE | BE5: 3675376 | EL5: =MIN($B5,$F5,$J5,$N5,$R5,$V5,$Z5,$AD5,$AH5,$AL5,$AP5,$AT5,$AX5,$BB5,$BF5,$BJ5,$BN5,$BR5,$BV5,$BZ5,$CD5,$CH5,$CL5,$CP5,$CT5,$CX5,$DB5,$DF5,$DJ5,$DN5,$DR5,$DV5,$DZ5,$ED5,$EH5) -> 0 | EM5: =MIN($C5,$G5,$K5,$O5,$S5,$W5,$AA5,$AE5,$AI5,$AM5,$AQ5,$AU5,$AY5,$BC5,$BG5,$BK5,$BO5,$BS5,$BW5,$CA5,$CE5,$CI5,$CM5,$CQ5,$CU5,$CY5,$DC5,$DG5,$DK5,$DO5,$DS5,$DW5,$EA5,$EE5,$EI5) -> 0 | EN5: =MIN($E5,$I5,$M5,$Q5,$U5,$Y5,$AC5,$AG5,$AK5,$AO5,$AS5,$AW5,$BA5,$BE5,$BI5,$BM5,$BQ5,$BU5,$BY5,$CC5,$CG5,$CK5,$CO5,$CS5,$CW5,$DA5,$DE5,$DI5,$DM5,$DQ5,$DU5,$DY5,$EC5,$EG5,$EK5) -> 0 | EO5: =MEDIAN($B5,$F5,$J5,$N5,$R5,$V5,$Z5,$AD5,$AH5,$AL5,$AP5,$AT5,$AX5,$BB5,$BF5,$BJ5,$BN5,$BR5,$BV5,$BZ5,$CD5,$CH5,$CL5,$CP5,$CT5,$CX5,$DB5,$DF5,$DJ5,$DN5,$DR5,$DV5,$DZ5,$ED5,$EH5) -> 0 | EP5: =MEDIAN($C5,$G5,$K5,$O5,$S5,$W5,$AA5,$AE5,$AI5,$AM5,$AQ5,$AU5,$AY5,$BC5,$BG5,$BK5,$BO5,$BS5,$BW5,$CA5,$CE5,$CI5,$CM5,$CQ5,$CU5,$CY5,$DC5,$DG5,$DK5,$DO5,$DS5,$DW5,$EA5,$EE5,$EI5) -> 0 | EQ5: =MEDIAN($E5,$I5,$M5,$Q5,$U5,$Y5,$AC5,$AG5,$AK5,$AO5,$AS5,$AW5,$BA5,$BE5,$BI5,$BM5,$BQ5,$BU5,$BY5,$CC5,$CG5,$CK5,$CO5,$CS5,$CW5,$DA5,$DE5,$DI5,$DM5,$DQ5,$DU5,$DY5,$EC5,$EG5,$EK5) -> 0 | ER5: =MAX($B5,$F5,$J5,$N5,$R5,$V5,$Z5,$AD5,$AH5,$AL5,$AP5,$AT5,$AX5,$BB5,$BF5,$BJ5,$BN5,$BR5,$BV5,$BZ5,$CD5,$CH5,$CL5,$CP5,$CT5,$CX5,$DB5,$DF5,$DJ5,$DN5,$DR5,$DV5,$DZ5,$ED5,$EH5) -> 0 | ES5: =MAX($C5,$G5,$K5,$O5,$S5,$W5,$AA5,$AE5,$AI5,$AM5,$AQ5,$AU5,$AY5,$BC5,$BG5,$BK5,$BO5,$BS5,$BW5,$CA5,$CE5,$CI5,$CM5,$CQ5,$CU5,$CY5,$DC5,$DG5,$DK5,$DO5,$DS5,$DW5,$EA5,$EE5,$EI5) -> 0 | ET5: =MAX($E5,$I5,$M5,$Q5,$U5,$Y5,$AC5,$AG5,$AK5,$AO5,$AS5,$AW5,$BA5,$BE5,$BI5,$BM5,$BQ5,$BU5,$BY5,$CC5,$CG5,$CK5,$CO5,$CS5,$CW5,$DA5,$DE5,$DI5,$DM5,$DQ5,$DU5,$DY5,$EC5,$EG5,$EK5) -> 0
A6: instances/ft10const2 | B6: 1200 | D6: UNKNOWN | F6: 79.55 | G6: 61.49 | H6: SATISFIABLE | I6: 1120051 | J6: 1200 | L6: UNKNOWN | N6: 147.2 | O6: 125.5 | P6: SATISFIABLE | Q6: 1445626 | R6: 1200 | T6: UNKNOWN | V6: 256.59 | W6: 231.86 | X6: SATISFIABLE | Y6: 1811326 | Z6: 1200 | AB6: UNKNOWN | AD6: 387.99 | AE6: 359.23 | AF6: SATISFIABLE | AG6: 2217151 | AH6: 1200 | AJ6: UNKNOWN | AL6: 557.31 | AM6: 525.47 | AN6: SATISFIABLE | AO6: 2663101 | AP6: 1200 | AR6: UNKNOWN | AT6: 874.06 | AU6: 835.2 | AV6: SATISFIABLE | AW6: 3149176 | AX6: 1200 | AZ6: UNKNOWN | BB6: 1200 | BC6: 1156.01 | BD6: UNKNOWN | BE6: 3675376 | EL6: =MIN($B6,$F6,$J6,$N6,$R6,$V6,$Z6,$AD6,$AH6,$AL6,$AP6,$AT6,$AX6,$BB6,$BF6,$BJ6,$BN6,$BR6,$BV6,$BZ6,$CD6,$CH6,$CL6,$CP6,$CT6,$CX6,$DB6,$DF6,$DJ6,$DN6,$DR6,$DV6,$DZ6,$ED6,$EH6) -> 0 | EM6: =MIN($C6,$G6,$K6,$O6,$S6,$W6,$AA6,$AE6,$AI6,$AM6,$AQ6,$AU6,$AY6,$BC6,$BG6,$BK6,$BO6,$BS6,$BW6,$CA6,$CE6,$CI6,$CM6,$CQ6,$CU6,$CY6,$DC6,$DG6,$DK6,$DO6,$DS6,$DW6,$EA6,$EE6,$EI6) -> 0 | EN6: =MIN($E6,$I6,$M6,$Q6,$U6,$Y6,$AC6,$AG6,$AK6,$AO6,$AS6,$AW6,$BA6,$BE6,$BI6,$BM6,$BQ6,$BU6,$BY6,$CC6,$CG6,$CK6,$CO6,$CS6,$CW6,$DA6,$DE6,$DI6,$DM6,$DQ6,$DU6,$DY6,$EC6,$EG6,$EK6) -> 0 | EO6: =MEDIAN($B6,$F6,$J6,$N6,$R6,$V6,$Z6,$AD6,$AH6,$AL6,$AP6,$AT6,$AX6,$BB6,$BF6,$BJ6,$BN6,$BR6,$BV6,$BZ6,$CD6,$CH6,$CL6,$CP6,$CT6,$CX6,$DB6,$DF6,$DJ6,$DN6,$DR6,$DV6,$DZ6,$ED6,$EH6) -> 0 | EP6: =MEDIAN($C6,$G6,$K6,$O6,$S6,$W6,$AA6,$AE6,$AI6,$AM6,$AQ6,$AU6,$AY6,$BC6,$BG6,$BK6,$BO6,$BS6,$BW6,$CA6,$CE6,$CI6,$CM6,$CQ6,$CU6,$CY6,$DC6,$DG6,$DK6,$DO6,$DS6,$DW6,$EA6,$EE6,$EI6) -> 0 | EQ6: =MEDIAN($E6,$I6,$M6,$Q6,$U6,$Y6,$AC6,$AG6,$AK6,$AO6,$AS6,$AW6,$BA6,$BE6,$BI6,$BM6,$BQ6,$BU6,$BY6,$CC6,$CG6,$CK6,$CO6,$CS6,$CW6,$DA6,$DE6,$DI6,$DM6,$DQ6,$DU6,$DY6,$EC6,$EG6,$EK6) -> 0 | ER6: =MAX($B6,$F6,$J6,$N6,$R6,$V6,$Z6,$AD6,$AH6,$AL6,$AP6,$AT6,$AX6,$BB6,$BF6,$BJ6,$BN6,$BR6,$BV6,$BZ6,$CD6,$CH6,$CL6,$CP6,$CT6,$CX6,$DB6,$DF6,$DJ6,$DN6,$DR6,$DV6,$DZ6,$ED6,$EH6) -> 0 | ES6: =MAX($C6,$G6,$K6,$O6,$S6,$W6,$AA6,$AE6,$AI6,$AM6,$AQ6,$AU6,$AY6,$BC6,$BG6,$BK6,$BO6,$BS6,$BW6,$CA6,$CE6,$CI6,$CM6,$CQ6,$CU6,$CY6,$DC6,$DG6,$DK6,$DO6,$DS6,$DW6,$EA6,$EE6,$EI6) -> 0 | ET6: =MAX($E6,$I6,$M6,$Q6,$U6,$Y6,$AC6,$AG6,$AK6,$AO6,$AS6,$AW6,$BA6,$BE6,$BI6,$BM6,$BQ6,$BU6,$BY6,$CC6,$CG6,$CK6,$CO6,$CS6,$CW6,$DA6,$DE6,$DI6,$DM6,$DQ6,$DU6,$DY6,$EC6,$EG6,$EK6) -> 0
A7: instances/ft10const5 | B7: 1200 | D7: UNKNOWN | F7: 88.99 | G7: 69.79 | H7: SATISFIABLE | I7: 1120051 | J7: 1200 | L7: UNKNOWN | N7: 135.33 | O7: 113.62 | P7: SATISFIABLE | Q7: 1445626 | R7: 1200 | T7: UNKNOWN | V7: 209.66 | W7: 184.89 | X7: SATISFIABLE | Y7: 1811326 | Z7: 1200 | AB7: UNKNOWN | AD7: 341.32 | AE7: 311.35 | AF7: SATISFIABLE | AG7: 2217151 | AH7: 1200 | AJ7: UNKNOWN | AL7: 490.64 | AM7: 459.41 | AN7: SATISFIABLE | AO7: 2663101 | AP7: 1200 | AR7: UNKNOWN | AT7: 676.25 | AU7: 638.65 | AV7: SATISFIABLE | AW7: 3149176 | AX7: 1200 | AZ7: UNKNOWN | BB7: 931.44 | BC7: 886.14 | BD7: SATISFIABLE | BE7: 3675376 | EL7: =MIN($B7,$F7,$J7,$N7,$R7,$V7,$Z7,$AD7,$AH7,$AL7,$AP7,$AT7,$AX7,$BB7,$BF7,$BJ7,$BN7,$BR7,$BV7,$BZ7,$CD7,$CH7,$CL7,$CP7,$CT7,$CX7,$DB7,$DF7,$DJ7,$DN7,$DR7,$DV7,$DZ7,$ED7,$EH7) -> 0 | EM7: =MIN($C7,$G7,$K7,$O7,$S7,$W7,$AA7,$AE7,$AI7,$AM7,$AQ7,$AU7,$AY7,$BC7,$BG7,$BK7,$BO7,$BS7,$BW7,$CA7,$CE7,$CI7,$CM7,$CQ7,$CU7,$CY7,$DC7,$DG7,$DK7,$DO7,$DS7,$DW7,$EA7,$EE7,$EI7) -> 0 | EN7: =MIN($E7,$I7,$M7,$Q7,$U7,$Y7,$AC7,$AG7,$AK7,$AO7,$AS7,$AW7,$BA7,$BE7,$BI7,$BM7,$BQ7,$BU7,$BY7,$CC7,$CG7,$CK7,$CO7,$CS7,$CW7,$DA7,$DE7,$DI7,$DM7,$DQ7,$DU7,$DY7,$EC7,$EG7,$EK7) -> 0 | EO7: =MEDIAN($B7,$F7,$J7,$N7,$R7,$V7,$Z7,$AD7,$AH7,$AL7,$AP7,$AT7,$AX7,$BB7,$BF7,$BJ7,$BN7,$BR7,$BV7,$BZ7,$CD7,$CH7,$CL7,$CP7,$CT7,$CX7,$DB7,$DF7,$DJ7,$DN7,$DR7,$DV7,$DZ7,$ED7,$EH7) -> 0 | EP7: =MEDIAN($C7,$G7,$K7,$O7,$S7,$W7,$AA7,$AE7,$AI7,$AM7,$AQ7,$AU7,$AY7,$BC7,$BG7,$BK7,$BO7,$BS7,$BW7,$CA7,$CE7,$CI7,$CM7,$CQ7,$CU7,$CY7,$DC7,$DG7,$DK7,$DO7,$DS7,$DW7,$EA7,$EE7,$EI7) -> 0 | EQ7: =MEDIAN($E7,$I7,$M7,$Q7,$U7,$Y7,$AC7,$AG7,$AK7,$AO7,$AS7,$AW7,$BA7,$BE7,$BI7,$BM7,$BQ7,$BU7,$BY7,$CC7,$CG7,$CK7,$CO7,$CS7,$CW7,$DA7,$DE7,$DI7,$DM7,$DQ7,$DU7,$DY7,$EC7,$EG7,$EK7) -> 0 | ER7: =MAX($B7,$F7,$J7,$N7,$R7,$V7,$Z7,$AD7,$AH7,$AL7,$AP7,$AT7,$AX7,$BB7,$BF7,$BJ7,$BN7,$BR7,$BV7,$BZ7,$CD7,$CH7,$CL7,$CP7,$CT7,$CX7,$DB7,$DF7,$DJ7,$DN7,$DR7,$DV7,$DZ7,$ED7,$EH7) -> 0 | ES7: =MAX($C7,$G7,$K7,$O7,$S7,$W7,$AA7,$AE7,$AI7,$AM7,$AQ7,$AU7,$AY7,$BC7,$BG7,$BK7,$BO7,$BS7,$BW7,$CA7,$CE7,$CI7,$CM7,$CQ7,$CU7,$CY7,$DC7,$DG7,$DK7,$DO7,$DS7,$DW7,$EA7,$EE7,$EI7) -> 0 | ET7: =MAX($E7,$I7,$M7,$Q7,$U7,$Y7,$AC7,$AG7,$AK7,$AO7,$AS7,$AW7,$BA7,$BE7,$BI7,$BM7,$BQ7,$BU7,$BY7,$CC7,$CG7,$CK7,$CO7,$CS7,$CW7,$DA7,$DE7,$DI7,$DM7,$DQ7,$DU7,$DY7,$EC7,$EG7,$EK7) -> 0
A9: SUM | B9: =SUM(B$3:B$7) -> 0 | F9: =SUM(F$3:F$7) -> 0 | G9: =SUM(G$3:G$7) -> 0 | I9: =SUM(I$3:I$7) -> 0 | J9: =SUM(J$3:J$7) -> 0 | N9: =SUM(N$3:N$7) -> 0 | O9: =SUM(O$3:O$7) -> 0 | Q9: =SUM(Q$3:Q$7) -> 0 | R9: =SUM(R$3:R$7) -> 0 | V9: =SUM(V$3:V$7) -> 0 | W9: =SUM(W$3:W$7) -> 0 | Y9: =SUM(Y$3:Y$7) -> 0 | Z9: =SUM(Z$3:Z$7) -> 0 | AD9: =SUM(AD$3:AD$7) -> 0 | AE9: =SUM(AE$3:AE$7) -> 0 | AG9: =SUM(AG$3:AG$7) -> 0 | AH9: =SUM(AH$3:AH$7) -> 0 | AL9: =SUM(AL$3:AL$7) -> 0 | AM9: =SUM(AM$3:AM$7) -> 0 | AO9: =SUM(AO$3:AO$7) -> 0 | AP9: =SUM(AP$3:AP$7) -> 0 | AT9: =SUM(AT$3:AT$7) -> 0 | AU9: =SUM(AU$3:AU$7) -> 0 | AW9: =SUM(AW$3:AW$7) -> 0 | AX9: =SUM(AX$3:AX$7) -> 0 | BB9: =SUM(BB$3:BB$7) -> 0 | BC9: =SUM(BC$3:BC$7) -> 0 | BE9: =SUM(BE$3:BE$7) -> 0 | BF9: =SUM(BF$3:BF$7) -> 0 | BG9: =SUM(BG$3:BG$7) -> 0 | BI9: =SUM(BI$3:BI$7) -> 0 | BJ9: =SUM(BJ$3:BJ$7) -> 0 | BK9: =SUM(BK$3:BK$7) -> 0 | BM9: =SUM(BM$3:BM$7) -> 0 | BN9: =SUM(BN$3:BN$7) -> 0 | BO9: =SUM(BO$3:BO$7) -> 0 | BQ9: =SUM(BQ$3:BQ$7) -> 0 | BR9: =SUM(BR$3:BR$7) -> 0 | BS9: =SUM(BS$3:BS$7) -> 0 | BU9: =SUM(BU$3:BU$7) -> 0 | BV9: =SUM(BV$3:BV$7) -> 0 | BW9: =SUM(BW$3:BW$7) -> 0 | BY9: =SUM(BY$3:BY$7) -> 0 | BZ9: =SUM(BZ$3:BZ$7) -> 0 | CA9: =SUM(CA$3:CA$7) -> 0 | CC9: =SUM(CC$3:CC$7) -> 0 | CD9: =SUM(CD$3:CD$7) -> 0 | CE9: =SUM(CE$3:CE$7) -> 0 | CG9: =SUM(CG$3:CG$7) -> 0 | CH9: =SUM(CH$3:CH$7) -> 0 | CI9: =SUM(CI$3:CI$7) -> 0 | CK9: =SUM(CK$3:CK$7) -> 0 | CL9: =SUM(CL$3:CL$7) -> 0 | CM9: =SUM(CM$3:CM$7) -> 0 | CO9: =SUM(CO$3:CO$7) -> 0 | CP9: =SUM(CP$3:CP$7) -> 0 | CQ9: =SUM(CQ$3:CQ$7) -> 0 | CS9: =SUM(CS$3:CS$7) -> 0 | CT9: =SUM(CT$3:CT$7) -> 0 | CU9: =SUM(CU$3:CU$7) -> 0 | CW9: =SUM(CW$3:CW$7) -> 0 | CX9: =SUM(CX$3:CX$7) -> 0 | CY9: =SUM(CY$3:CY$7) -> 0 | DA9: =SUM(DA$3:DA$7) -> 0 | DB9: =SUM(DB$3:DB$7) -> 0 | DC9: =SUM(DC$3:DC$7) -> 0 | DE9: =SUM(DE$3:DE$7) -> 0 | DF9: =SUM(DF$3:DF$7) -> 0 | DG9: =SUM(DG$3:DG$7) -> 0 | DI9: =SUM(DI$3:DI$7) -> 0 | DJ9: =SUM(DJ$3:DJ$7) -> 0 | DK9: =SUM(DK$3:DK$7) -> 0 | DM9: =SUM(DM$3:DM$7) -> 0 | DN9: =SUM(DN$3:DN$7) -> 0 | DO9: =SUM(DO$3:DO$7) -> 0 | DQ9: =SUM(DQ$3:DQ$7) -> 0 | DR9: =SUM(DR$3:DR$7) -> 0 | DS9: =SUM(DS$3:DS$7) -> 0 | DU9: =SUM(DU$3:DU$7) -> 0 | DV9: =SUM(DV$3:DV$7) -> 0 | DW9: =SUM(DW$3:DW$7) -> 0 | DY9: =SUM(DY$3:DY$7) -> 0 | DZ9: =SUM(DZ$3:DZ$7) -> 0 | EA9: =SUM(EA$3:EA$7) -> 0 | EC9: =SUM(EC$3:EC$7) -> 0 | ED9: =SUM(ED$3:ED$7) -> 0 | EE9: =SUM(EE$3:EE$7) -> 0 | EG9: =SUM(EG$3:EG$7) -> 0 | EH9: =SUM(EH$3:EH$7) -> 0 | EI9: =SUM(EI$3:EI$7) -> 0 | EK9: =SUM(EK$3:EK$7) -> 0 | EL9: =SUM(EL$3:EL$7) -> 0 | EM9: =SUM(EM$3:EM$7) -> 0 | EN9: =SUM(EN$3:EN$7) -> 0 | EO9: =SUM(EO$3:EO$7) -> 0 | EP9: =SUM(EP$3:EP$7) -> 0 | EQ9: =SUM(EQ$3:EQ$7) -> 0 | ER9: =SUM(ER$3:ER$7) -> 0 | ... ET9: =SUM(ET$3:ET$7) -> 0
A10: AVG | B10: =AVERAGE(B$3:B$7) -> 0 | F10: =AVERAGE(F$3:F$7) -> 0 | G10: =AVERAGE(G$3:G$7) -> 0 | I10: =AVERAGE(I$3:I$7) -> 0 | J10: =AVERAGE(J$3:J$7) -> 0 | N10: =AVERAGE(N$3:N$7) -> 0 | O10: =AVERAGE(O$3:O$7) -> 0 | Q10: =AVERAGE(Q$3:Q$7) -> 0 | R10: =AVERAGE(R$3:R$7) -> 0 | V10: =AVERAGE(V$3:V$7) -> 0 | W10: =AVERAGE(W$3:W$7) -> 0 | Y10: =AVERAGE(Y$3:Y$7) -> 0 | Z10: =AVERAGE(Z$3:Z$7) -> 0 | AD10: =AVERAGE(AD$3:AD$7) -> 0 | AE10: =AVERAGE(AE$3:AE$7) -> 0 | AG10: =AVERAGE(AG$3:AG$7) -> 0 | AH10: =AVERAGE(AH$3:AH$7) -> 0 | AL10: =AVERAGE(AL$3:AL$7) -> 0 | AM10: =AVERAGE(AM$3:AM$7) -> 0 | AO10: =AVERAGE(AO$3:AO$7) -> 0 | AP10: =AVERAGE(AP$3:AP$7) -> 0 | AT10: =AVERAGE(AT$3:AT$7) -> 0 | AU10: =AVERAGE(AU$3:AU$7) -> 0 | AW10: =AVERAGE(AW$3:AW$7) -> 0 | AX10: =AVERAGE(AX$3:AX$7) -> 0 | BB10: =AVERAGE(BB$3:BB$7) -> 0 | BC10: =AVERAGE(BC$3:BC$7) -> 0 | BE10: =AVERAGE(BE$3:BE$7) -> 0 | BF10: =AVERAGE(BF$3:BF$7) -> 0 | BG10: =AVERAGE(BG$3:BG$7) -> 0 | BI10: =AVERAGE(BI$3:BI$7) -> 0 | BJ10: =AVERAGE(BJ$3:BJ$7) -> 0 | BK10: =AVERAGE(BK$3:BK$7) -> 0 | BM10: =AVERAGE(BM$3:BM$7) -> 0 | BN10: =AVERAGE(BN$3:BN$7) -> 0 | BO10: =AVERAGE(BO$3:BO$7) -> 0 | BQ10: =AVERAGE(BQ$3:BQ$7) -> 0 | BR10: =AVERAGE(BR$3:BR$7) -> 0 | BS10: =AVERAGE(BS$3:BS$7) -> 0 | BU10: =AVERAGE(BU$3:BU$7) -> 0 | BV10: =AVERAGE(BV$3:BV$7) -> 0 | BW10: =AVERAGE(BW$3:BW$7) -> 0 | BY10: =AVERAGE(BY$3:BY$7) -> 0 | BZ10: =AVERAGE(BZ$3:BZ$7) -> 0 | CA10: =AVERAGE(CA$3:CA$7) -> 0 | CC10: =AVERAGE(CC$3:CC$7) -> 0 | CD10: =AVERAGE(CD$3:CD$7) -> 0 | CE10: =AVERAGE(CE$3:CE$7) -> 0 | CG10: =AVERAGE(CG$3:CG$7) -> 0 | CH10: =AVERAGE(CH$3:CH$7) -> 0 | CI10: =AVERAGE(CI$3:CI$7) -> 0 | CK10: =AVERAGE(CK$3:CK$7) -> 0 | CL10: =AVERAGE(CL$3:CL$7) -> 0 | CM10: =AVERAGE(CM$3:CM$7) -> 0 | CO10: =AVERAGE(CO$3:CO$7) -> 0 | CP10: =AVERAGE(CP$3:CP$7) -> 0 | CQ10: =AVERAGE(CQ$3:CQ$7) -> 0 | CS10: =AVERAGE(CS$3:CS$7) -> 0 | CT10: =AVERAGE(CT$3:CT$7) -> 0 | CU10: =AVERAGE(CU$3:CU$7) -> 0 | CW10: =AVERAGE(CW$3:CW$7) -> 0 | CX10: =AVERAGE(CX$3:CX$7) -> 0 | CY10: =AVERAGE(CY$3:CY$7) -> 0 | DA10: =AVERAGE(DA$3:DA$7) -> 0 | DB10: =AVERAGE(DB$3:DB$7) -> 0 | DC10: =AVERAGE(DC$3:DC$7) -> 0 | DE10: =AVERAGE(DE$3:DE$7) -> 0 | DF10: =AVERAGE(DF$3:DF$7) -> 0 | DG10: =AVERAGE(DG$3:DG$7) -> 0 | DI10: =AVERAGE(DI$3:DI$7) -> 0 | DJ10: =AVERAGE(DJ$3:DJ$7) -> 0 | DK10: =AVERAGE(DK$3:DK$7) -> 0 | DM10: =AVERAGE(DM$3:DM$7) -> 0 | DN10: =AVERAGE(DN$3:DN$7) -> 0 | DO10: =AVERAGE(DO$3:DO$7) -> 0 | DQ10: =AVERAGE(DQ$3:DQ$7) -> 0 | DR10: =AVERAGE(DR$3:DR$7) -> 0 | DS10: =AVERAGE(DS$3:DS$7) -> 0 | DU10: =AVERAGE(DU$3:DU$7) -> 0 | DV10: =AVERAGE(DV$3:DV$7) -> 0 | DW10: =AVERAGE(DW$3:DW$7) -> 0 | DY10: =AVERAGE(DY$3:DY$7) -> 0 | DZ10: =AVERAGE(DZ$3:DZ$7) -> 0 | EA10: =AVERAGE(EA$3:EA$7) -> 0 | EC10: =AVERAGE(EC$3:EC$7) -> 0 | ED10: =AVERAGE(ED$3:ED$7) -> 0 | EE10: =AVERAGE(EE$3:EE$7) -> 0 | EG10: =AVERAGE(EG$3:EG$7) -> 0 | EH10: =AVERAGE(EH$3:EH$7) -> 0 | EI10: =AVERAGE(EI$3:EI$7) -> 0 | EK10: =AVERAGE(EK$3:EK$7) -> 0 | EL10: =AVERAGE(EL$3:EL$7) -> 0 | EM10: =AVERAGE(EM$3:EM$7) -> 0 | EN10: =AVERAGE(EN$3:EN$7) -> 0 | EO10: =AVERAGE(EO$3:EO$7) -> 0 | EP10: =AVERAGE(EP$3:EP$7) -> 0 | EQ10: =AVERAGE(EQ$3:EQ$7) -> 0 | ER10: =AVERAGE(ER$3:ER$7) -> 0 | ... ET10: =AVERAGE(ET$3:ET$7) -> 0
A11: DEV | B11: =STDEV(B$3:B$7) -> 0 | F11: =STDEV(F$3:F$7) -> 0 | G11: =STDEV(G$3:G$7) -> 0 | I11: =STDEV(I$3:I$7) -> 0 | J11: =STDEV(J$3:J$7) -> 0 | N11: =STDEV(N$3:N$7) -> 0 | O11: =STDEV(O$3:O$7) -> 0 | Q11: =STDEV(Q$3:Q$7) -> 0 | R11: =STDEV(R$3:R$7) -> 0 | V11: =STDEV(V$3:V$7) -> 0 | W11: =STDEV(W$3:W$7) -> 0 | Y11: =STDEV(Y$3:Y$7) -> 0 | Z11: =STDEV(Z$3:Z$7) -> 0 | AD11: =STDEV(AD$3:AD$7) -> 0 | AE11: =STDEV(AE$3:AE$7) -> 0 | AG11: =STDEV(AG$3:AG$7) -> 0 | AH11: =STDEV(AH$3:AH$7) -> 0 | AL11: =STDEV(AL$3:AL$7) -> 0 | AM11: =STDEV(AM$3:AM$7) -> 0 | AO11: =STDEV(AO$3:AO$7) -> 0 | AP11: =STDEV(AP$3:AP$7) -> 0 | AT11: =STDEV(AT$3:AT$7) -> 0 | AU11: =STDEV(AU$3:AU$7) -> 0 | AW11: =STDEV(AW$3:AW$7) -> 0 | AX11: =STDEV(AX$3:AX$7) -> 0 | BB11: =STDEV(BB$3:BB$7) -> 0 | BC11: =STDEV(BC$3:BC$7) -> 0 | BE11: =STDEV(BE$3:BE$7) -> 0 | BF11: =STDEV(BF$3:BF$7) -> 0 | BG11: =STDEV(BG$3:BG$7) -> 0 | BI11: =STDEV(BI$3:BI$7) -> 0 | BJ11: =STDEV(BJ$3:BJ$7) -> 0 | BK11: =STDEV(BK$3:BK$7) -> 0 | BM11: =STDEV(BM$3:BM$7) -> 0 | BN11: =STDEV(BN$3:BN$7) -> 0 | BO11: =STDEV(BO$3:BO$7) -> 0 | BQ11: =STDEV(BQ$3:BQ$7) -> 0 | BR11: =STDEV(BR$3:BR$7) -> 0 | BS11: =STDEV(BS$3:BS$7) -> 0 | BU11: =STDEV(BU$3:BU$7) -> 0 | BV11: =STDEV(BV$3:BV$7) -> 0 | BW11: =STDEV(BW$3:BW$7) -> 0 | BY11: =STDEV(BY$3:BY$7) -> 0 | BZ11: =STDEV(BZ$3:BZ$7) -> 0 | CA11: =STDEV(CA$3:CA$7) -> 0 | CC11: =STDEV(CC$3:CC$7) -> 0 | CD11: =STDEV(CD$3:CD$7) -> 0 | CE11: =STDEV(CE$3:CE$7) -> 0 | CG11: =STDEV(CG$3:CG$7) -> 0 | CH11: =STDEV(CH$3:CH$7) -> 0 | CI11: =STDEV(CI$3:CI$7) -> 0 | CK11: =STDEV(CK$3:CK$7) -> 0 | CL11: =STDEV(CL$3:CL$7) -> 0 | CM11: =STDEV(CM$3:CM$7) -> 0 | CO11: =STDEV(CO$3:CO$7) -> 0 | CP11: =STDEV(CP$3:CP$7) -> 0 | CQ11: =STDEV(CQ$3:CQ$7) -> 0 | CS11: =STDEV(CS$3:CS$7) -> 0 | CT11: =STDEV(CT$3:CT$7) -> 0 | CU11: =STDEV(CU$3:CU$7) -> 0 | CW11: =STDEV(CW$3:CW$7) -> 0 | CX11: =STDEV(CX$3:CX$7) -> 0 | CY11: =STDEV(CY$3:CY$7) -> 0 | DA11: =STDEV(DA$3:DA$7) -> 0 | DB11: =STDEV(DB$3:DB$7) -> 0 | DC11: =STDEV(DC$3:DC$7) -> 0 | DE11: =STDEV(DE$3:DE$7) -> 0 | DF11: =STDEV(DF$3:DF$7) -> 0 | DG11: =STDEV(DG$3:DG$7) -> 0 | DI11: =STDEV(DI$3:DI$7) -> 0 | DJ11: =STDEV(DJ$3:DJ$7) -> 0 | DK11: =STDEV(DK$3:DK$7) -> 0 | DM11: =STDEV(DM$3:DM$7) -> 0 | DN11: =STDEV(DN$3:DN$7) -> 0 | DO11: =STDEV(DO$3:DO$7) -> 0 | DQ11: =STDEV(DQ$3:DQ$7) -> 0 | DR11: =STDEV(DR$3:DR$7) -> 0 | DS11: =STDEV(DS$3:DS$7) -> 0 | DU11: =STDEV(DU$3:DU$7) -> 0 | DV11: =STDEV(DV$3:DV$7) -> 0 | DW11: =STDEV(DW$3:DW$7) -> 0 | DY11: =STDEV(DY$3:DY$7) -> 0 | DZ11: =STDEV(DZ$3:DZ$7) -> 0 | EA11: =STDEV(EA$3:EA$7) -> 0 | EC11: =STDEV(EC$3:EC$7) -> 0 | ED11: =STDEV(ED$3:ED$7) -> 0 | EE11: =STDEV(EE$3:EE$7) -> 0 | EG11: =STDEV(EG$3:EG$7) -> 0 | EH11: =STDEV(EH$3:EH$7) -> 0 | EI11: =STDEV(EI$3:EI$7) -> 0 | EK11: =STDEV(EK$3:EK$7) -> 0 | EL11: =STDEV(EL$3:EL$7) -> 0 | EM11: =STDEV(EM$3:EM$7) -> 0 | EN11: =STDEV(EN$3:EN$7) -> 0 | EO11: =STDEV(EO$3:EO$7) -> 0 | EP11: =STDEV(EP$3:EP$7) -> 0 | EQ11: =STDEV(EQ$3:EQ$7) -> 0 | ER11: =STDEV(ER$3:ER$7) -> 0 | ... ET11: =STDEV(ET$3:ET$7) -> 0
A12: DST | B12: =SUMPRODUCT(--(B$3:B$7-$EL$3:$EL$7)^2)^0.5 -> 0 | F12: =SUMPRODUCT(--(F$3:F$7-$EL$3:$EL$7)^2)^0.5 -> 0 | G12: =SUMPRODUCT(--(G$3:G$7-$EM$3:$EM$7)^2)^0.5 -> 0 | I12: =SUMPRODUCT(--(I$3:I$7-$EN$3:$EN$7)^2)^0.5 -> 0 | J12: =SUMPRODUCT(--(J$3:J$7-$EL$3:$EL$7)^2)^0.5 -> 0 | N12: =SUMPRODUCT(--(N$3:N$7-$EL$3:$EL$7)^2)^0.5 -> 0 | O12: =SUMPRODUCT(--(O$3:O$7-$EM$3:$EM$7)^2)^0.5 -> 0 | Q12: =SUMPRODUCT(--(Q$3:Q$7-$EN$3:$EN$7)^2)^0.5 -> 0 | R12: =SUMPRODUCT(--(R$3:R$7-$EL$3:$EL$7)^2)^0.5 -> 0 | V12: =SUMPRODUCT(--(V$3:V$7-$EL$3:$EL$7)^2)^0.5 -> 0 | W12: =SUMPRODUCT(--(W$3:W$7-$EM$3:$EM$7)^2)^0.5 -> 0 | Y12: =SUMPRODUCT(--(Y$3:Y$7-$EN$3:$EN$7)^2)^0.5 -> 0 | Z12: =SUMPRODUCT(--(Z$3:Z$7-$EL$3:$EL$7)^2)^0.5 -> 0 | AD12: =SUMPRODUCT(--(AD$3:AD$7-$EL$3:$EL$7)^2)^0.5 -> 0 | AE12: =SUMPRODUCT(--(AE$3:AE$7-$EM$3:$EM$7)^2)^0.5 -> 0 | AG12: =SUMPRODUCT(--(AG$3:AG$7-$EN$3:$EN$7)^2)^0.5 -> 0 | AH12: =SUMPRODUCT(--(AH$3:AH$7-$EL$3:$EL$7)^2)^0.5 -> 0 | AL12: =SUMPRODUCT(--(AL$3:AL$7-$EL$3:$EL$7)^2)^0.5 -> 0 | AM12: =SUMPRODUCT(--(AM$3:AM$7-$EM$3:$EM$7)^2)^0.5 -> 0 | AO12: =SUMPRODUCT(--(AO$3:AO$7-$EN$3:$EN$7)^2)^0.5 -> 0 | AP12: =SUMPRODUCT(--(AP$3:AP$7-$EL$3:$EL$7)^2)^0.5 -> 0 | AT12: =SUMPRODUCT(--(AT$3:AT$7-$EL$3:$EL$7)^2)^0.5 -> 0 | AU12: =SUMPRODUCT(--(AU$3:AU$7-$EM$3:$EM$7)^2)^0.5 -> 0 | AW12: =SUMPRODUCT(--(AW$3:AW$7-$EN$3:$EN$7)^2)^0.5 -> 0 | AX12: =SUMPRODUCT(--(AX$3:AX$7-$EL$3:$EL$7)^2)^0.5 -> 0 | BB12: =SUMPRODUCT(--(BB$3:BB$7-$EL$3:$EL$7)^2)^0.5 -> 0 | BC12: =SUMPRODUCT(--(BC$3:BC$7-$EM$3:$EM$7)^2)^0.5 -> 0 | BE12: =SUMPRODUCT(--(BE$3:BE$7-$EN$3:$EN$7)^2)^0.5 -> 0 | BF12: =SUMPRODUCT(--(BF$3:BF$7-$EL$3:$EL$7)^2)^0.5 -> 0 | BG12: =SUMPRODUCT(--(BG$3:BG$7-$EM$3:$EM$7)^2)^0.5 -> 0 | BI12: =SUMPRODUCT(--(BI$3:BI$7-$EN$3:$EN$7)^2)^0.5 -> 0 | BJ12: =SUMPRODUCT(--(BJ$3:BJ$7-$EL$3:$EL$7)^2)^0.5 -> 0 | BK12: =SUMPRODUCT(--(BK$3:BK$7-$EM$3:$EM$7)^2)^0.5 -> 0 | BM12: =SUMPRODUCT(--(BM$3:BM$7-$EN$3:$EN$7)^2)^0.5 -> 0 | BN12: =SUMPRODUCT(--(BN$3:BN$7-$EL$3:$EL$7)^2)^0.5 -> 0 | BO12: =SUMPRODUCT(--(BO$3:BO$7-$EM$3:$EM$7)^2)^0.5 -> 0 | BQ12: =SUMPRODUCT(--(BQ$3:BQ$7-$EN$3:$EN$7)^2)^0.5 -> 0 | BR12: =SUMPRODUCT(--(BR$3:BR$7-$EL$3:$EL$7)^2)^0.5 -> 0 | BS12: =SUMPRODUCT(--(BS$3:BS$7-$EM$3:$EM$7)^2)^0.5 -> 0 | BU12: =SUMPRODUCT(--(BU$3:BU$7-$EN$3:$EN$7)^2)^0.5 -> 0 | BV12: =SUMPRODUCT(--(BV$3:BV$7-$EL$3:$EL$7)^2)^0.5 -> 0 | BW12: =SUMPRODUCT(--(BW$3:BW$7-$EM$3:$EM$7)^2)^0.5 -> 0 | BY12: =SUMPRODUCT(--(BY$3:BY$7-$EN$3:$EN$7)^2)^0.5 -> 0 | BZ12: =SUMPRODUCT(--(BZ$3:BZ$7-$EL$3:$EL$7)^2)^0.5 -> 0 | CA12: =SUMPRODUCT(--(CA$3:CA$7-$EM$3:$EM$7)^2)^0.5 -> 0 | CC12: =SUMPRODUCT(--(CC$3:CC$7-$EN$3:$EN$7)^2)^0.5 -> 0 | CD12: =SUMPRODUCT(--(CD$3:CD$7-$EL$3:$EL$7)^2)^0.5 -> 0 | CE12: =SUMPRODUCT(--(CE$3:CE$7-$EM$3:$EM$7)^2)^0.5 -> 0 | CG12: =SUMPRODUCT(--(CG$3:CG$7-$EN$3:$EN$7)^2)^0.5 -> 0 | CH12: =SUMPRODUCT(--(CH$3:CH$7-$EL$3:$EL$7)^2)^0.5 -> 0 | CI12: =SUMPRODUCT(--(CI$3:CI$7-$EM$3:$EM$7)^2)^0.5 -> 0 | CK12: =SUMPRODUCT(--(CK$3:CK$7-$EN$3:$EN$7)^2)^0.5 -> 0 | CL12: =SUMPRODUCT(--(CL$3:CL$7-$EL$3:$EL$7)^2)^0.5 -> 0 | CM12: =SUMPRODUCT(--(CM$3:CM$7-$EM$3:$EM$7)^2)^0.5 -> 0 | CO12: =SUMPRODUCT(--(CO$3:CO$7-$EN$3:$EN$7)^2)^0.5 -> 0 | CP12: =SUMPRODUCT(--(CP$3:CP$7-$EL$3:$EL$7)^2)^0.5 -> 0 | CQ12: =SUMPRODUCT(--(CQ$3:CQ$7-$EM$3:$EM$7)^2)^0.5 -> 0 | CS12: =SUMPRODUCT(--(CS$3:CS$7-$EN$3:$EN$7)^2)^0.5 -> 0 | CT12: =SUMPRODUCT(--(CT$3:CT$7-$EL$3:$EL$7)^2)^0.5 -> 0 | CU12: =SUMPRODUCT(--(CU$3:CU$7-$EM$3:$EM$7)^2)^0.5 -> 0 | CW12: =SUMPRODUCT(--(CW$3:CW$7-$EN$3:$EN$7)^2)^0.5 -> 0 | CX12: =SUMPRODUCT(--(CX$3:CX$7-$EL$3:$EL$7)^2)^0.5 -> 0 | CY12: =SUMPRODUCT(--(CY$3:CY$7-$EM$3:$EM$7)^2)^0.5 -> 0 | DA12: =SUMPRODUCT(--(DA$3:DA$7-$EN$3:$EN$7)^2)^0.5 -> 0 | DB12: =SUMPRODUCT(--(DB$3:DB$7-$EL$3:$EL$7)^2)^0.5 -> 0 | DC12: =SUMPRODUCT(--(DC$3:DC$7-$EM$3:$EM$7)^2)^0.5 -> 0 | DE12: =SUMPRODUCT(--(DE$3:DE$7-$EN$3:$EN$7)^2)^0.5 -> 0 | DF12: =SUMPRODUCT(--(DF$3:DF$7-$EL$3:$EL$7)^2)^0.5 -> 0 | DG12: =SUMPRODUCT(--(DG$3:DG$7-$EM$3:$EM$7)^2)^0.5 -> 0 | DI12: =SUMPRODUCT(--(DI$3:DI$7-$EN$3:$EN$7)^2)^0.5 -> 0 | DJ12: =SUMPRODUCT(--(DJ$3:DJ$7-$EL$3:$EL$7)^2)^0.5 -> 0 | DK12: =SUMPRODUCT(--(DK$3:DK$7-$EM$3:$EM$7)^2)^0.5 -> 0 | DM12: =SUMPRODUCT(--(DM$3:DM$7-$EN$3:$EN$7)^2)^0.5 -> 0 | DN12: =SUMPRODUCT(--(DN$3:DN$7-$EL$3:$EL$7)^2)^0.5 -> 0 | DO12: =SUMPRODUCT(--(DO$3:DO$7-$EM$3:$EM$7)^2)^0.5 -> 0 | DQ12: =SUMPRODUCT(--(DQ$3:DQ$7-$EN$3:$EN$7)^2)^0.5 -> 0 | DR12: =SUMPRODUCT(--(DR$3:DR$7-$EL$3:$EL$7)^2)^0.5 -> 0 | DS12: =SUMPRODUCT(--(DS$3:DS$7-$EM$3:$EM$7)^2)^0.5 -> 0 | DU12: =SUMPRODUCT(--(DU$3:DU$7-$EN$3:$EN$7)^2)^0.5 -> 0 | DV12: =SUMPRODUCT(--(DV$3:DV$7-$EL$3:$EL$7)^2)^0.5 -> 0 | DW12: =SUMPRODUCT(--(DW$3:DW$7-$EM$3:$EM$7)^2)^0.5 -> 0 | DY12: =SUMPRODUCT(--(DY$3:DY$7-$EN$3:$EN$7)^2)^0.5 -> 0 | DZ12: =SUMPRODUCT(--(DZ$3:DZ$7-$EL$3:$EL$7)^2)^0.5 -> 0 | EA12: =SUMPRODUCT(--(EA$3:EA$7-$EM$3:$EM$7)^2)^0.5 -> 0 | EC12: =SUMPRODUCT(--(EC$3:EC$7-$EN$3:$EN$7)^2)^0.5 -> 0 | ED12: =SUMPRODUCT(--(ED$3:ED$7-$EL$3:$EL$7)^2)^0.5 -> 0 | EE12: =SUMPRODUCT(--(EE$3:EE$7-$EM$3:$EM$7)^2)^0.5 -> 0 | EG12: =SUMPRODUCT(--(EG$3:EG$7-$EN$3:$EN$7)^2)^0.5 -> 0 | EH12: =SUMPRODUCT(--(EH$3:EH$7-$EL$3:$EL$7)^2)^0.5 -> 0 | EI12: =SUMPRODUCT(--(EI$3:EI$7-$EM$3:$EM$7)^2)^0.5 -> 0 | EK12: =SUMPRODUCT(--(EK$3:EK$7-$EN$3:$EN$7)^2)^0.5 -> 0
A13: BEST | B13: =SUMPRODUCT(NOT(ISBLANK(B$3:B$7))*(B$3:B$7=$EL$3:$EL$7)) -> 0 | F13: =SUMPRODUCT(NOT(ISBLANK(F$3:F$7))*(F$3:F$7=$EL$3:$EL$7)) -> 0 | G13: =SUMPRODUCT(NOT(ISBLANK(G$3:G$7))*(G$3:G$7=$EM$3:$EM$7)) -> 0 | I13: =SUMPRODUCT(NOT(ISBLANK(I$3:I$7))*(I$3:I$7=$EN$3:$EN$7)) -> 0 | J13: =SUMPRODUCT(NOT(ISBLANK(J$3:J$7))*(J$3:J$7=$EL$3:$EL$7)) -> 0 | N13: =SUMPRODUCT(NOT(ISBLANK(N$3:N$7))*(N$3:N$7=$EL$3:$EL$7)) -> 0 | O13: =SUMPRODUCT(NOT(ISBLANK(O$3:O$7))*(O$3:O$7=$EM$3:$EM$7)) -> 0 | Q13: =SUMPRODUCT(NOT(ISBLANK(Q$3:Q$7))*(Q$3:Q$7=$EN$3:$EN$7)) -> 0 | R13: =SUMPRODUCT(NOT(ISBLANK(R$3:R$7))*(R$3:R$7=$EL$3:$EL$7)) -> 0 | V13: =SUMPRODUCT(NOT(ISBLANK(V$3:V$7))*(V$3:V$7=$EL$3:$EL$7)) -> 0 | W13: =SUMPRODUCT(NOT(ISBLANK(W$3:W$7))*(W$3:W$7=$EM$3:$EM$7)) -> 0 | Y13: =SUMPRODUCT(NOT(ISBLANK(Y$3:Y$7))*(Y$3:Y$7=$EN$3:$EN$7)) -> 0 | Z13: =SUMPRODUCT(NOT(ISBLANK(Z$3:Z$7))*(Z$3:Z$7=$EL$3:$EL$7)) -> 0 | AD13: =SUMPRODUCT(NOT(ISBLANK(AD$3:AD$7))*(AD$3:AD$7=$EL$3:$EL$7)) -> 0 | AE13: =SUMPRODUCT(NOT(ISBLANK(AE$3:AE$7))*(AE$3:AE$7=$EM$3:$EM$7)) -> 0 | AG13: =SUMPRODUCT(NOT(ISBLANK(AG$3:AG$7))*(AG$3:AG$7=$EN$3:$EN$7)) -> 0 | AH13: =SUMPRODUCT(NOT(ISBLANK(AH$3:AH$7))*(AH$3:AH$7=$EL$3:$EL$7)) -> 0 | AL13: =SUMPRODUCT(NOT(ISBLANK(AL$3:AL$7))*(AL$3:AL$7=$EL$3:$EL$7)) -> 0 | AM13: =SUMPRODUCT(NOT(ISBLANK(AM$3:AM$7))*(AM$3:AM$7=$EM$3:$EM$7)) -> 0 | AO13: =SUMPRODUCT(NOT(ISBLANK(AO$3:AO$7))*(AO$3:AO$7=$EN$3:$EN$7)) -> 0 | AP13: =SUMPRODUCT(NOT(ISBLANK(AP$3:AP$7))*(AP$3:AP$7=$EL$3:$EL$7)) -> 0 | AT13: =SUMPRODUCT(NOT(ISBLANK(AT$3:AT$7))*(AT$3:AT$7=$EL$3:$EL$7)) -> 0 | AU13: =SUMPRODUCT(NOT(ISBLANK(AU$3:AU$7))*(AU$3:AU$7=$EM$3:$EM$7)) -> 0 | AW13: =SUMPRODUCT(NOT(ISBLANK(AW$3:AW$7))*(AW$3:AW$7=$EN$3:$EN$7)) -> 0 | AX13: =SUMPRODUCT(NOT(ISBLANK(AX$3:AX$7))*(AX$3:AX$7=$EL$3:$EL$7)) -> 0 | BB13: =SUMPRODUCT(NOT(ISBLANK(BB$3:BB$7))*(BB$3:BB$7=$EL$3:$EL$7)) -> 0 | BC13: =SUMPRODUCT(NOT(ISBLANK(BC$3:BC$7))*(BC$3:BC$7=$EM$3:$EM$7)) -> 0 | BE13: =SUMPRODUCT(NOT(ISBLANK(BE$3:BE$7))*(BE$3:BE$7=$EN$3:$EN$7)) -> 0 | BF13: =SUMPRODUCT(NOT(ISBLANK(BF$3:BF$7))*(BF$3:BF$7=$EL$3:$EL$7)) -> 0 | BG13: =SUMPRODUCT(NOT(ISBLANK(BG$3:BG$7))*(BG$3:BG$7=$EM$3:$EM$7)) -> 0 | BI13: =SUMPRODUCT(NOT(ISBLANK(BI$3:BI$7))*(BI$3:BI$7=$EN$3:$EN$7)) -> 0 | BJ13: =SUMPRODUCT(NOT(ISBLANK(BJ$3:BJ$7))*(BJ$3:BJ$7=$EL$3:$EL$7)) -> 0 | BK13: =SUMPRODUCT(NOT(ISBLANK(BK$3:BK$7))*(BK$3:BK$7=$EM$3:$EM$7)) -> 0 | BM13: =SUMPRODUCT(NOT(ISBLANK(BM$3:BM$7))*(BM$3:BM$7=$EN$3:$EN$7)) -> 0 | BN13: =SUMPRODUCT(NOT(ISBLANK(BN$3:BN$7))*(BN$3:BN$7=$EL$3:$EL$7)) -> 0 | BO13: =SUMPRODUCT(NOT(ISBLANK(BO$3:BO$7))*(BO$3:BO$7=$EM$3:$EM$7)) -> 0 | BQ13: =SUMPRODUCT(NOT(ISBLANK(BQ$3:BQ$7))*(BQ$3:BQ$7=$EN$3:$EN$7)) -> 0 | BR13: =SUMPRODUCT(NOT(ISBLANK(BR$3:BR$7))*(BR$3:BR$7=$EL$3:$EL$7)) -> 0 | BS13: =SUMPRODUCT(NOT(ISBLANK(BS$3:BS$7))*(BS$3:BS$7=$EM$3:$EM$7)) -> 0 | BU13: =SUMPRODUCT(NOT(ISBLANK(BU$3:BU$7))*(BU$3:BU$7=$EN$3:$EN$7)) -> 0 | BV13: =SUMPRODUCT(NOT(ISBLANK(BV$3:BV$7))*(BV$3:BV$7=$EL$3:$EL$7)) -> 0 | BW13: =SUMPRODUCT(NOT(ISBLANK(BW$3:BW$7))*(BW$3:BW$7=$EM$3:$EM$7)) -> 0 | BY13: =SUMPRODUCT(NOT(ISBLANK(BY$3:BY$7))*(BY$3:BY$7=$EN$3:$EN$7)) -> 0 | BZ13: =SUMPRODUCT(NOT(ISBLANK(BZ$3:BZ$7))*(BZ$3:BZ$7=$EL$3:$EL$7)) -> 0 | CA13: =SUMPRODUCT(NOT(ISBLANK(CA$3:CA$7))*(CA$3:CA$7=$EM$3:$EM$7)) -> 0 | CC13: =SUMPRODUCT(NOT(ISBLANK(CC$3:CC$7))*(CC$3:CC$7=$EN$3:$EN$7)) -> 0 | CD13: =SUMPRODUCT(NOT(ISBLANK(CD$3:CD$7))*(CD$3:CD$7=$EL$3:$EL$7)) -> 0 | CE13: =SUMPRODUCT(NOT(ISBLANK(CE$3:CE$7))*(CE$3:CE$7=$EM$3:$EM$7)) -> 0 | CG13: =SUMPRODUCT(NOT(ISBLANK(CG$3:CG$7))*(CG$3:CG$7=$EN$3:$EN$7)) -> 0 | CH13: =SUMPRODUCT(NOT(ISBLANK(CH$3:CH$7))*(CH$3:CH$7=$EL$3:$EL$7)) -> 0 | CI13: =SUMPRODUCT(NOT(ISBLANK(CI$3:CI$7))*(CI$3:CI$7=$EM$3:$EM$7)) -> 0 | CK13: =SUMPRODUCT(NOT(ISBLANK(CK$3:CK$7))*(CK$3:CK$7=$EN$3:$EN$7)) -> 0 | CL13: =SUMPRODUCT(NOT(ISBLANK(CL$3:CL$7))*(CL$3:CL$7=$EL$3:$EL$7)) -> 0 | CM13: =SUMPRODUCT(NOT(ISBLANK(CM$3:CM$7))*(CM$3:CM$7=$EM$3:$EM$7)) -> 0 | CO13: =SUMPRODUCT(NOT(ISBLANK(CO$3:CO$7))*(CO$3:CO$7=$EN$3:$EN$7)) -> 0 | CP13: =SUMPRODUCT(NOT(ISBLANK(CP$3:CP$7))*(CP$3:CP$7=$EL$3:$EL$7)) -> 0 | CQ13: =SUMPRODUCT(NOT(ISBLANK(CQ$3:CQ$7))*(CQ$3:CQ$7=$EM$3:$EM$7)) -> 0 | CS13: =SUMPRODUCT(NOT(ISBLANK(CS$3:CS$7))*(CS$3:CS$7=$EN$3:$EN$7)) -> 0 | CT13: =SUMPRODUCT(NOT(ISBLANK(CT$3:CT$7))*(CT$3:CT$7=$EL$3:$EL$7)) -> 0 | CU13: =SUMPRODUCT(NOT(ISBLANK(CU$3:CU$7))*(CU$3:CU$7=$EM$3:$EM$7)) -> 0 | CW13: =SUMPRODUCT(NOT(ISBLANK(CW$3:CW$7))*(CW$3:CW$7=$EN$3:$EN$7)) -> 0 | CX13: =SUMPRODUCT(NOT(ISBLANK(CX$3:CX$7))*(CX$3:CX$7=$EL$3:$EL$7)) -> 0 | CY13: =SUMPRODUCT(NOT(ISBLANK(CY$3:CY$7))*(CY$3:CY$7=$EM$3:$EM$7)) -> 0 | DA13: =SUMPRODUCT(NOT(ISBLANK(DA$3:DA$7))*(DA$3:DA$7=$EN$3:$EN$7)) -> 0 | DB13: =SUMPRODUCT(NOT(ISBLANK(DB$3:DB$7))*(DB$3:DB$7=$EL$3:$EL$7)) -> 0 | DC13: =SUMPRODUCT(NOT(ISBLANK(DC$3:DC$7))*(DC$3:DC$7=$EM$3:$EM$7)) -> 0 | DE13: =SUMPRODUCT(NOT(ISBLANK(DE$3:DE$7))*(DE$3:DE$7=$EN$3:$EN$7)) -> 0 | DF13: =SUMPRODUCT(NOT(ISBLANK(DF$3:DF$7))*(DF$3:DF$7=$EL$3:$EL$7)) -> 0 | DG13: =SUMPRODUCT(NOT(ISBLANK(DG$3:DG$7))*(DG$3:DG$7=$EM$3:$EM$7)) -> 0 | DI13: =SUMPRODUCT(NOT(ISBLANK(DI$3:DI$7))*(DI$3:DI$7=$EN$3:$EN$7)) -> 0 | DJ13: =SUMPRODUCT(NOT(ISBLANK(DJ$3:DJ$7))*(DJ$3:DJ$7=$EL$3:$EL$7)) -> 0 | DK13: =SUMPRODUCT(NOT(ISBLANK(DK$3:DK$7))*(DK$3:DK$7=$EM$3:$EM$7)) -> 0 | DM13: =SUMPRODUCT(NOT(ISBLANK(DM$3:DM$7))*(DM$3:DM$7=$EN$3:$EN$7)) -> 0 | DN13: =SUMPRODUCT(NOT(ISBLANK(DN$3:DN$7))*(DN$3:DN$7=$EL$3:$EL$7)) -> 0 | DO13: =SUMPRODUCT(NOT(ISBLANK(DO$3:DO$7))*(DO$3:DO$7=$EM$3:$EM$7)) -> 0 | DQ13: =SUMPRODUCT(NOT(ISBLANK(DQ$3:DQ$7))*(DQ$3:DQ$7=$EN$3:$EN$7)) -> 0 | DR13: =SUMPRODUCT(NOT(ISBLANK(DR$3:DR$7))*(DR$3:DR$7=$EL$3:$EL$7)) -> 0 | DS13: =SUMPRODUCT(NOT(ISBLANK(DS$3:DS$7))*(DS$3:DS$7=$EM$3:$EM$7)) -> 0 | DU13: =SUMPRODUCT(NOT(ISBLANK(DU$3:DU$7))*(DU$3:DU$7=$EN$3:$EN$7)) -> 0 | DV13: =SUMPRODUCT(NOT(ISBLANK(DV$3:DV$7))*(DV$3:DV$7=$EL$3:$EL$7)) -> 0 | DW13: =SUMPRODUCT(NOT(ISBLANK(DW$3:DW$7))*(DW$3:DW$7=$EM$3:$EM$7)) -> 0 | DY13: =SUMPRODUCT(NOT(ISBLANK(DY$3:DY$7))*(DY$3:DY$7=$EN$3:$EN$7)) -> 0 | DZ13: =SUMPRODUCT(NOT(ISBLANK(DZ$3:DZ$7))*(DZ$3:DZ$7=$EL$3:$EL$7)) -> 0 | EA13: =SUMPRODUCT(NOT(ISBLANK(EA$3:EA$7))*(EA$3:EA$7=$EM$3:$EM$7)) -> 0 | EC13: =SUMPRODUCT(NOT(ISBLANK(EC$3:EC$7))*(EC$3:EC$7=$EN$3:$EN$7)) -> 0 | ED13: =SUMPRODUCT(NOT(ISBLANK(ED$3:ED$7))*(ED$3:ED$7=$EL$3:$EL$7)) -> 0 | EE13: =SUMPRODUCT(NOT(ISBLANK(EE$3:EE$7))*(EE$3:EE$7=$EM$3:$EM$7)) -> 0 | EG13: =SUMPRODUCT(NOT(ISBLANK(EG$3:EG$7))*(EG$3:EG$7=$EN$3:$EN$7)) -> 0 | EH13: =SUMPRODUCT(NOT(ISBLANK(EH$3:EH$7))*(EH$3:EH$7=$EL$3:$EL$7)) -> 0 | EI13: =SUMPRODUCT(NOT(ISBLANK(EI$3:EI$7))*(EI$3:EI$7=$EM$3:$EM$7)) -> 0 | EK13: =SUMPRODUCT(NOT(ISBLANK(EK$3:EK$7))*(EK$3:EK$7=$EN$3:$EN$7)) -> 0
A14: BETTER | B14: =SUMPRODUCT(NOT(ISBLANK(B$3:B$7))*(B$3:B$7<$EO$3:$EO$7)) -> 0 | F14: =SUMPRODUCT(NOT(ISBLANK(F$3:F$7))*(F$3:F$7<$EO$3:$EO$7)) -> 0 | G14: =SUMPRODUCT(NOT(ISBLANK(G$3:G$7))*(G$3:G$7<$EP$3:$EP$7)) -> 0 | I14: =SUMPRODUCT(NOT(ISBLANK(I$3:I$7))*(I$3:I$7<$EQ$3:$EQ$7)) -> 0 | J14: =SUMPRODUCT(NOT(ISBLANK(J$3:J$7))*(J$3:J$7<$EO$3:$EO$7)) -> 0 | N14: =SUMPRODUCT(NOT(ISBLANK(N$3:N$7))*(N$3:N$7<$EO$3:$EO$7)) -> 0 | O14: =SUMPRODUCT(NOT(ISBLANK(O$3:O$7))*(O$3:O$7<$EP$3:$EP$7)) -> 0 | Q14: =SUMPRODUCT(NOT(ISBLANK(Q$3:Q$7))*(Q$3:Q$7<$EQ$3:$EQ$7)) -> 0 | R14: =SUMPRODUCT(NOT(ISBLANK(R$3:R$7))*(R$3:R$7<$EO$3:$EO$7)) -> 0 | V14: =SUMPRODUCT(NOT(ISBLANK(V$3:V$7))*(V$3:V$7<$EO$3:$EO$7)) -> 0 | W14: =SUMPRODUCT(NOT(ISBLANK(W$3:W$7))*(W$3:W$7<$EP$3:$EP$7)) -> 0 | Y14: =SUMPRODUCT(NOT(ISBLANK(Y$3:Y$7))*(Y$3:Y$7<$EQ$3:$EQ$7)) -> 0 | Z14: =SUMPRODUCT(NOT(ISBLANK(Z$3:Z$7))*(Z$3:Z$7<$EO$3:$EO$7)) -> 0 | AD14: =SUMPRODUCT(NOT(ISBLANK(AD$3:AD$7))*(AD$3:AD$7<$EO$3:$EO$7)) -> 0 | AE14: =SUMPRODUCT(NOT(ISBLANK(AE$3:AE$7))*(AE$3:AE$7<$EP$3:$EP$7)) -> 0 | AG14: =SUMPRODUCT(NOT(ISBLANK(AG$3:AG$7))*(AG$3:AG$7<$EQ$3:$EQ$7)) -> 0 | AH14: =SUMPRODUCT(NOT(ISBLANK(AH$3:AH$7))*(AH$3:AH$7<$EO$3:$EO$7)) -> 0 | AL14: =SUMPRODUCT(NOT(ISBLANK(AL$3:AL$7))*(AL$3:AL$7<$EO$3:$EO$7)) -> 0 | AM14: =SUMPRODUCT(NOT(ISBLANK(AM$3:AM$7))*(AM$3:AM$7<$EP$3:$EP$7)) -> 0 | AO14: =SUMPRODUCT(NOT(ISBLANK(AO$3:AO$7))*(AO$3:AO$7<$EQ$3:$EQ$7)) -> 0 | AP14: =SUMPRODUCT(NOT(ISBLANK(AP$3:AP$7))*(AP$3:AP$7<$EO$3:$EO$7)) -> 0 | AT14: =SUMPRODUCT(NOT(ISBLANK(AT$3:AT$7))*(AT$3:AT$7<$EO$3:$EO$7)) -> 0 | AU14: =SUMPRODUCT(NOT(ISBLANK(AU$3:AU$7))*(AU$3:AU$7<$EP$3:$EP$7)) -> 0 | AW14: =SUMPRODUCT(NOT(ISBLANK(AW$3:AW$7))*(AW$3:AW$7<$EQ$3:$EQ$7)) -> 0 | AX14: =SUMPRODUCT(NOT(ISBLANK(AX$3:AX$7))*(AX$3:AX$7<$EO$3:$EO$7)) -> 0 | BB14: =SUMPRODUCT(NOT(ISBLANK(BB$3:BB$7))*(BB$3:BB$7<$EO$3:$EO$7)) -> 0 | BC14: =SUMPRODUCT(NOT(ISBLANK(BC$3:BC$7))*(BC$3:BC$7<$EP$3:$EP$7)) -> 0 | BE14: =SUMPRODUCT(NOT(ISBLANK(BE$3:BE$7))*(BE$3:BE$7<$EQ$3:$EQ$7)) -> 0 | BF14: =SUMPRODUCT(NOT(ISBLANK(BF$3:BF$7))*(BF$3:BF$7<$EO$3:$EO$7)) -> 0 | BG14: =SUMPRODUCT(NOT(ISBLANK(BG$3:BG$7))*(BG$3:BG$7<$EP$3:$EP$7)) -> 0 | BI14: =SUMPRODUCT(NOT(ISBLANK(BI$3:BI$7))*(BI$3:BI$7<$EQ$3:$EQ$7)) -> 0 | BJ14: =SUMPRODUCT(NOT(ISBLANK(BJ$3:BJ$7))*(BJ$3:BJ$7<$EO$3:$EO$7)) -> 0 | BK14: =SUMPRODUCT(NOT(ISBLANK(BK$3:BK$7))*(BK$3:BK$7<$EP$3:$EP$7)) -> 0 | BM14: =SUMPRODUCT(NOT(ISBLANK(BM$3:BM$7))*(BM$3:BM$7<$EQ$3:$EQ$7)) -> 0 | BN14: =SUMPRODUCT(NOT(ISBLANK(BN$3:BN$7))*(BN$3:BN$7<$EO$3:$EO$7)) -> 0 | BO14: =SUMPRODUCT(NOT(ISBLANK(BO$3:BO$7))*(BO$3:BO$7<$EP$3:$EP$7)) -> 0 | BQ14: =SUMPRODUCT(NOT(ISBLANK(BQ$3:BQ$7))*(BQ$3:BQ$7<$EQ$3:$EQ$7)) -> 0 | BR14: =SUMPRODUCT(NOT(ISBLANK(BR$3:BR$7))*(BR$3:BR$7<$EO$3:$EO$7)) -> 0 | BS14: =SUMPRODUCT(NOT(ISBLANK(BS$3:BS$7))*(BS$3:BS$7<$EP$3:$EP$7)) -> 0 | BU14: =SUMPRODUCT(NOT(ISBLANK(BU$3:BU$7))*(BU$3:BU$7<$EQ$3:$EQ$7)) -> 0 | BV14: =SUMPRODUCT(NOT(ISBLANK(BV$3:BV$7))*(BV$3:BV$7<$EO$3:$EO$7)) -> 0 | BW14: =SUMPRODUCT(NOT(ISBLANK(BW$3:BW$7))*(BW$3:BW$7<$EP$3:$EP$7)) -> 0 | BY14: =SUMPRODUCT(NOT(ISBLANK(BY$3:BY$7))*(BY$3:BY$7<$EQ$3:$EQ$7)) -> 0 | BZ14: =SUMPRODUCT(NOT(ISBLANK(BZ$3:BZ$7))*(BZ$3:BZ$7<$EO$3:$EO$7)) -> 0 | CA14: =SUMPRODUCT(NOT(ISBLANK(CA$3:CA$7))*(CA$3:CA$7<$EP$3:$EP$7)) -> 0 | CC14: =SUMPRODUCT(NOT(ISBLANK(CC$3:CC$7))*(CC$3:CC$7<$EQ$3:$EQ$7)) -> 0 | CD14: =SUMPRODUCT(NOT(ISBLANK(CD$3:CD$7))*(CD$3:CD$7<$EO$3:$EO$7)) -> 0 | CE14: =SUMPRODUCT(NOT(ISBLANK(CE$3:CE$7))*(CE$3:CE$7<$EP$3:$EP$7)) -> 0 | CG14: =SUMPRODUCT(NOT(ISBLANK(CG$3:CG$7))*(CG$3:CG$7<$EQ$3:$EQ$7)) -> 0 | CH14: =SUMPRODUCT(NOT(ISBLANK(CH$3:CH$7))*(CH$3:CH$7<$EO$3:$EO$7)) -> 0 | CI14: =SUMPRODUCT(NOT(ISBLANK(CI$3:CI$7))*(CI$3:CI$7<$EP$3:$EP$7)) -> 0 | CK14: =SUMPRODUCT(NOT(ISBLANK(CK$3:CK$7))*(CK$3:CK$7<$EQ$3:$EQ$7)) -> 0 | CL14: =SUMPRODUCT(NOT(ISBLANK(CL$3:CL$7))*(CL$3:CL$7<$EO$3:$EO$7)) -> 0 | CM14: =SUMPRODUCT(NOT(ISBLANK(CM$3:CM$7))*(CM$3:CM$7<$EP$3:$EP$7)) -> 0 | CO14: =SUMPRODUCT(NOT(ISBLANK(CO$3:CO$7))*(CO$3:CO$7<$EQ$3:$EQ$7)) -> 0 | CP14: =SUMPRODUCT(NOT(ISBLANK(CP$3:CP$7))*(CP$3:CP$7<$EO$3:$EO$7)) -> 0 | CQ14: =SUMPRODUCT(NOT(ISBLANK(CQ$3:CQ$7))*(CQ$3:CQ$7<$EP$3:$EP$7)) -> 0 | CS14: =SUMPRODUCT(NOT(ISBLANK(CS$3:CS$7))*(CS$3:CS$7<$EQ$3:$EQ$7)) -> 0 | CT14: =SUMPRODUCT(NOT(ISBLANK(CT$3:CT$7))*(CT$3:CT$7<$EO$3:$EO$7)) -> 0 | CU14: =SUMPRODUCT(NOT(ISBLANK(CU$3:CU$7))*(CU$3:CU$7<$EP$3:$EP$7)) -> 0 | CW14: =SUMPRODUCT(NOT(ISBLANK(CW$3:CW$7))*(CW$3:CW$7<$EQ$3:$EQ$7)) -> 0 | CX14: =SUMPRODUCT(NOT(ISBLANK(CX$3:CX$7))*(CX$3:CX$7<$EO$3:$EO$7)) -> 0 | CY14: =SUMPRODUCT(NOT(ISBLANK(CY$3:CY$7))*(CY$3:CY$7<$EP$3:$EP$7)) -> 0 | DA14: =SUMPRODUCT(NOT(ISBLANK(DA$3:DA$7))*(DA$3:DA$7<$EQ$3:$EQ$7)) -> 0 | DB14: =SUMPRODUCT(NOT(ISBLANK(DB$3:DB$7))*(DB$3:DB$7<$EO$3:$EO$7)) -> 0 | DC14: =SUMPRODUCT(NOT(ISBLANK(DC$3:DC$7))*(DC$3:DC$7<$EP$3:$EP$7)) -> 0 | DE14: =SUMPRODUCT(NOT(ISBLANK(DE$3:DE$7))*(DE$3:DE$7<$EQ$3:$EQ$7)) -> 0 | DF14: =SUMPRODUCT(NOT(ISBLANK(DF$3:DF$7))*(DF$3:DF$7<$EO$3:$EO$7)) -> 0 | DG14: =SUMPRODUCT(NOT(ISBLANK(DG$3:DG$7))*(DG$3:DG$7<$EP$3:$EP$7)) -> 0 | DI14: =SUMPRODUCT(NOT(ISBLANK(DI$3:DI$7))*(DI$3:DI$7<$EQ$3:$EQ$7)) -> 0 | DJ14: =SUMPRODUCT(NOT(ISBLANK(DJ$3:DJ$7))*(DJ$3:DJ$7<$EO$3:$EO$7)) -> 0 | DK14: =SUMPRODUCT(NOT(ISBLANK(DK$3:DK$7))*(DK$3:DK$7<$EP$3:$EP$7)) -> 0 | DM14: =SUMPRODUCT(NOT(ISBLANK(DM$3:DM$7))*(DM$3:DM$7<$EQ$3:$EQ$7)) -> 0 | DN14: =SUMPRODUCT(NOT(ISBLANK(DN$3:DN$7))*(DN$3:DN$7<$EO$3:$EO$7)) -> 0 | DO14: =SUMPRODUCT(NOT(ISBLANK(DO$3:DO$7))*(DO$3:DO$7<$EP$3:$EP$7)) -> 0 | DQ14: =SUMPRODUCT(NOT(ISBLANK(DQ$3:DQ$7))*(DQ$3:DQ$7<$EQ$3:$EQ$7)) -> 0 | DR14: =SUMPRODUCT(NOT(ISBLANK(DR$3:DR$7))*(DR$3:DR$7<$EO$3:$EO$7)) -> 0 | DS14: =SUMPRODUCT(NOT(ISBLANK(DS$3:DS$7))*(DS$3:DS$7<$EP$3:$EP$7)) -> 0 | DU14: =SUMPRODUCT(NOT(ISBLANK(DU$3:DU$7))*(DU$3:DU$7<$EQ$3:$EQ$7)) -> 0 | DV14: =SUMPRODUCT(NOT(ISBLANK(DV$3:DV$7))*(DV$3:DV$7<$EO$3:$EO$7)) -> 0 | DW14: =SUMPRODUCT(NOT(ISBLANK(DW$3:DW$7))*(DW$3:DW$7<$EP$3:$EP$7)) -> 0 | DY14: =SUMPRODUCT(NOT(ISBLANK(DY$3:DY$7))*(DY$3:DY$7<$EQ$3:$EQ$7)) -> 0 | DZ14: =SUMPRODUCT(NOT(ISBLANK(DZ$3:DZ$7))*(DZ$3:DZ$7<$EO$3:$EO$7)) -> 0 | EA14: =SUMPRODUCT(NOT(ISBLANK(EA$3:EA$7))*(EA$3:EA$7<$EP$3:$EP$7)) -> 0 | EC14: =SUMPRODUCT(NOT(ISBLANK(EC$3:EC$7))*(EC$3:EC$7<$EQ$3:$EQ$7)) -> 0 | ED14: =SUMPRODUCT(NOT(ISBLANK(ED$3:ED$7))*(ED$3:ED$7<$EO$3:$EO$7)) -> 0 | EE14: =SUMPRODUCT(NOT(ISBLANK(EE$3:EE$7))*(EE$3:EE$7<$EP$3:$EP$7)) -> 0 | EG14: =SUMPRODUCT(NOT(ISBLANK(EG$3:EG$7))*(EG$3:EG$7<$EQ$3:$EQ$7)) -> 0 | EH14: =SUMPRODUCT(NOT(ISBLANK(EH$3:EH$7))*(EH$3:EH$7<$EO$3:$EO$7)) -> 0 | EI14: =SUMPRODUCT(NOT(ISBLANK(EI$3:EI$7))*(EI$3:EI$7<$EP$3:$EP$7)) -> 0 | EK14: =SUMPRODUCT(NOT(ISBLANK(EK$3:EK$7))*(EK$3:EK$7<$EQ$3:$EQ$7)) -> 0
A15: WORSE | B15: =SUMPRODUCT((NOT(ISBLANK(B$3:B$7))*(B$3:B$7>$EO$3:$EO$7))+ISBLANK(B$3:B$7)) -> 0 | F15: =SUMPRODUCT((NOT(ISBLANK(F$3:F$7))*(F$3:F$7>$EO$3:$EO$7))+ISBLANK(F$3:F$7)) -> 0 | G15: =SUMPRODUCT((NOT(ISBLANK(G$3:G$7))*(G$3:G$7>$EP$3:$EP$7))+ISBLANK(G$3:G$7)) -> 0 | I15: =SUMPRODUCT((NOT(ISBLANK(I$3:I$7))*(I$3:I$7>$EQ$3:$EQ$7))+ISBLANK(I$3:I$7)) -> 0 | J15: =SUMPRODUCT((NOT(ISBLANK(J$3:J$7))*(J$3:J$7>$EO$3:$EO$7))+ISBLANK(J$3:J$7)) -> 0 | N15: =SUMPRODUCT((NOT(ISBLANK(N$3:N$7))*(N$3:N$7>$EO$3:$EO$7))+ISBLANK(N$3:N$7)) -> 0 | O15: =SUMPRODUCT((NOT(ISBLANK(O$3:O$7))*(O$3:O$7>$EP$3:$EP$7))+ISBLANK(O$3:O$7)) -> 0 | Q15: =SUMPRODUCT((NOT(ISBLANK(Q$3:Q$7))*(Q$3:Q$7>$EQ$3:$EQ$7))+ISBLANK(Q$3:Q$7)) -> 0 | R15: =SUMPRODUCT((NOT(ISBLANK(R$3:R$7))*(R$3:R$7>$EO$3:$EO$7))+ISBLANK(R$3:R$7)) -> 0 | V15: =SUMPRODUCT((NOT(ISBLANK(V$3:V$7))*(V$3:V$7>$EO$3:$EO$7))+ISBLANK(V$3:V$7)) -> 0 | W15: =SUMPRODUCT((NOT(ISBLANK(W$3:W$7))*(W$3:W$7>$EP$3:$EP$7))+ISBLANK(W$3:W$7)) -> 0 | Y15: =SUMPRODUCT((NOT(ISBLANK(Y$3:Y$7))*(Y$3:Y$7>$EQ$3:$EQ$7))+ISBLANK(Y$3:Y$7)) -> 0 | Z15: =SUMPRODUCT((NOT(ISBLANK(Z$3:Z$7))*(Z$3:Z$7>$EO$3:$EO$7))+ISBLANK(Z$3:Z$7)) -> 0 | AD15: =SUMPRODUCT((NOT(ISBLANK(AD$3:AD$7))*(AD$3:AD$7>$EO$3:$EO$7))+ISBLANK(AD$3:AD$7)) -> 0 | AE15: =SUMPRODUCT((NOT(ISBLANK(AE$3:AE$7))*(AE$3:AE$7>$EP$3:$EP$7))+ISBLANK(AE$3:AE$7)) -> 0 | AG15: =SUMPRODUCT((NOT(ISBLANK(AG$3:AG$7))*(AG$3:AG$7>$EQ$3:$EQ$7))+ISBLANK(AG$3:AG$7)) -> 0 | AH15: =SUMPRODUCT((NOT(ISBLANK(AH$3:AH$7))*(AH$3:AH$7>$EO$3:$EO$7))+ISBLANK(AH$3:AH$7)) -> 0 | AL15: =SUMPRODUCT((NOT(ISBLANK(AL$3:AL$7))*(AL$3:AL$7>$EO$3:$EO$7))+ISBLANK(AL$3:AL$7)) -> 0 | AM15: =SUMPRODUCT((NOT(ISBLANK(AM$3:AM$7))*(AM$3:AM$7>$EP$3:$EP$7))+ISBLANK(AM$3:AM$7)) -> 0 | AO15: =SUMPRODUCT((NOT(ISBLANK(AO$3:AO$7))*(AO$3:AO$7>$EQ$3:$EQ$7))+ISBLANK(AO$3:AO$7)) -> 0 | AP15: =SUMPRODUCT((NOT(ISBLANK(AP$3:AP$7))*(AP$3:AP$7>$EO$3:$EO$7))+ISBLANK(AP$3:AP$7)) -> 0 | AT15: =SUMPRODUCT((NOT(ISBLANK(AT$3:AT$7))*(AT$3:AT$7>$EO$3:$EO$7))+ISBLANK(AT$3:AT$7)) -> 0 | AU15: =SUMPRODUCT((NOT(ISBLANK(AU$3:AU$7))*(AU$3:AU$7>$EP$3:$EP$7))+ISBLANK(AU$3:AU$7)) -> 0 | AW15: =SUMPRODUCT((NOT(ISBLANK(AW$3:AW$7))*(AW$3:AW$7>$EQ$3:$EQ$7))+ISBLANK(AW$3:AW$7)) -> 0 | AX15: =SUMPRODUCT((NOT(ISBLANK(AX$3:AX$7))*(AX$3:AX$7>$EO$3:$EO$7))+ISBLANK(AX$3:AX$7)) -> 0 | BB15: =SUMPRODUCT((NOT(ISBLANK(BB$3:BB$7))*(BB$3:BB$7>$EO$3:$EO$7))+ISBLANK(BB$3:BB$7)) -> 0 | BC15: =SUMPRODUCT((NOT(ISBLANK(BC$3:BC$7))*(BC$3:BC$7>$EP$3:$EP$7))+ISBLANK(BC$3:BC$7)) -> 0 | BE15: =SUMPRODUCT((NOT(ISBLANK(BE$3:BE$7))*(BE$3:BE$7>$EQ$3:$EQ$7))+ISBLANK(BE$3:BE$7)) -> 0 | BF15: =SUMPRODUCT((NOT(ISBLANK(BF$3:BF$7))*(BF$3:BF$7>$EO$3:$EO$7))+ISBLANK(BF$3:BF$7)) -> 0 | BG15: =SUMPRODUCT((NOT(ISBLANK(BG$3:BG$7))*(BG$3:BG$7>$EP$3:$EP$7))+ISBLANK(BG$3:BG$7)) -> 0 | BI15: =SUMPRODUCT((NOT(ISBLANK(BI$3:BI$7))*(BI$3:BI$7>$EQ$3:$EQ$7))+ISBLANK(BI$3:BI$7)) -> 0 | BJ15: =SUMPRODUCT((NOT(ISBLANK(BJ$3:BJ$7))*(BJ$3:BJ$7>$EO$3:$EO$7))+ISBLANK(BJ$3:BJ$7)) -> 0 | BK15: =SUMPRODUCT((NOT(ISBLANK(BK$3:BK$7))*(BK$3:BK$7>$EP$3:$EP$7))+ISBLANK(BK$3:BK$7)) -> 0 | BM15: =SUMPRODUCT((NOT(ISBLANK(BM$3:BM$7))*(BM$3:BM$7>$EQ$3:$EQ$7))+ISBLANK(BM$3:BM$7)) -> 0 | BN15: =SUMPRODUCT((NOT(ISBLANK(BN$3:BN$7))*(BN$3:BN$7>$EO$3:$EO$7))+ISBLANK(BN$3:BN$7)) -> 0 | BO15: =SUMPRODUCT((NOT(ISBLANK(BO$3:BO$7))*(BO$3:BO$7>$EP$3:$EP$7))+ISBLANK(BO$3:BO$7)) -> 0 | BQ15: =SUMPRODUCT((NOT(ISBLANK(BQ$3:BQ$7))*(BQ$3:BQ$7>$EQ$3:$EQ$7))+ISBLANK(BQ$3:BQ$7)) -> 0 | BR15: =SUMPRODUCT((NOT(ISBLANK(BR$3:BR$7))*(BR$3:BR$7>$EO$3:$EO$7))+ISBLANK(BR$3:BR$7)) -> 0 | BS15: =SUMPRODUCT((NOT(ISBLANK(BS$3:BS$7))*(BS$3:BS$7>$EP$3:$EP$7))+ISBLANK(BS$3:BS$7)) -> 0 | BU15: =SUMPRODUCT((NOT(ISBLANK(BU$3:BU$7))*(BU$3:BU$7>$EQ$3:$EQ$7))+ISBLANK(BU$3:BU$7)) -> 0 | BV15: =SUMPRODUCT((NOT(ISBLANK(BV$3:BV$7))*(BV$3:BV$7>$EO$3:$EO$7))+ISBLANK(BV$3:BV$7)) -> 0 | BW15: =SUMPRODUCT((NOT(ISBLANK(BW$3:BW$7))*(BW$3:BW$7>$EP$3:$EP$7))+ISBLANK(BW$3:BW$7)) -> 0 | BY15: =SUMPRODUCT((NOT(ISBLANK(BY$3:BY$7))*(BY$3:BY$7>$EQ$3:$EQ$7))+ISBLANK(BY$3:BY$7)) -> 0 | BZ15: =SUMPRODUCT((NOT(ISBLANK(BZ$3:BZ$7))*(BZ$3:BZ$7>$EO$3:$EO$7))+ISBLANK(BZ$3:BZ$7)) -> 0 | CA15: =SUMPRODUCT((NOT(ISBLANK(CA$3:CA$7))*(CA$3:CA$7>$EP$3:$EP$7))+ISBLANK(CA$3:CA$7)) -> 0 | CC15: =SUMPRODUCT((NOT(ISBLANK(CC$3:CC$7))*(CC$3:CC$7>$EQ$3:$EQ$7))+ISBLANK(CC$3:CC$7)) -> 0 | CD15: =SUMPRODUCT((NOT(ISBLANK(CD$3:CD$7))*(CD$3:CD$7>$EO$3:$EO$7))+ISBLANK(CD$3:CD$7)) -> 0 | CE15: =SUMPRODUCT((NOT(ISBLANK(CE$3:CE$7))*(CE$3:CE$7>$EP$3:$EP$7))+ISBLANK(CE$3:CE$7)) -> 0 | CG15: =SUMPRODUCT((NOT(ISBLANK(CG$3:CG$7))*(CG$3:CG$7>$EQ$3:$EQ$7))+ISBLANK(CG$3:CG$7)) -> 0 | CH15: =SUMPRODUCT((NOT(ISBLANK(CH$3:CH$7))*(CH$3:CH$7>$EO$3:$EO$7))+ISBLANK(CH$3:CH$7)) -> 0 | CI15: =SUMPRODUCT((NOT(ISBLANK(CI$3:CI$7))*(CI$3:CI$7>$EP$3:$EP$7))+ISBLANK(CI$3:CI$7)) -> 0 | CK15: =SUMPRODUCT((NOT(ISBLANK(CK$3:CK$7))*(CK$3:CK$7>$EQ$3:$EQ$7))+ISBLANK(CK$3:CK$7)) -> 0 | CL15: =SUMPRODUCT((NOT(ISBLANK(CL$3:CL$7))*(CL$3:CL$7>$EO$3:$EO$7))+ISBLANK(CL$3:CL$7)) -> 0 | CM15: =SUMPRODUCT((NOT(ISBLANK(CM$3:CM$7))*(CM$3:CM$7>$EP$3:$EP$7))+ISBLANK(CM$3:CM$7)) -> 0 | CO15: =SUMPRODUCT((NOT(ISBLANK(CO$3:CO$7))*(CO$3:CO$7>$EQ$3:$EQ$7))+ISBLANK(CO$3:CO$7)) -> 0 | CP15: =SUMPRODUCT((NOT(ISBLANK(CP$3:CP$7))*(CP$3:CP$7>$EO$3:$EO$7))+ISBLANK(CP$3:CP$7)) -> 0 | CQ15: =SUMPRODUCT((NOT(ISBLANK(CQ$3:CQ$7))*(CQ$3:CQ$7>$EP$3:$EP$7))+ISBLANK(CQ$3:CQ$7)) -> 0 | CS15: =SUMPRODUCT((NOT(ISBLANK(CS$3:CS$7))*(CS$3:CS$7>$EQ$3:$EQ$7))+ISBLANK(CS$3:CS$7)) -> 0 | CT15: =SUMPRODUCT((NOT(ISBLANK(CT$3:CT$7))*(CT$3:CT$7>$EO$3:$EO$7))+ISBLANK(CT$3:CT$7)) -> 0 | CU15: =SUMPRODUCT((NOT(ISBLANK(CU$3:CU$7))*(CU$3:CU$7>$EP$3:$EP$7))+ISBLANK(CU$3:CU$7)) -> 0 | CW15: =SUMPRODUCT((NOT(ISBLANK(CW$3:CW$7))*(CW$3:CW$7>$EQ$3:$EQ$7))+ISBLANK(CW$3:CW$7)) -> 0 | CX15: =SUMPRODUCT((NOT(ISBLANK(CX$3:CX$7))*(CX$3:CX$7>$EO$3:$EO$7))+ISBLANK(CX$3:CX$7)) -> 0 | CY15: =SUMPRODUCT((NOT(ISBLANK(CY$3:CY$7))*(CY$3:CY$7>$EP$3:$EP$7))+ISBLANK(CY$3:CY$7)) -> 0 | DA15: =SUMPRODUCT((NOT(ISBLANK(DA$3:DA$7))*(DA$3:DA$7>$EQ$3:$EQ$7))+ISBLANK(DA$3:DA$7)) -> 0 | DB15: =SUMPRODUCT((NOT(ISBLANK(DB$3:DB$7))*(DB$3:DB$7>$EO$3:$EO$7))+ISBLANK(DB$3:DB$7)) -> 0 | DC15: =SUMPRODUCT((NOT(ISBLANK(DC$3:DC$7))*(DC$3:DC$7>$EP$3:$EP$7))+ISBLANK(DC$3:DC$7)) -> 0 | DE15: =SUMPRODUCT((NOT(ISBLANK(DE$3:DE$7))*(DE$3:DE$7>$EQ$3:$EQ$7))+ISBLANK(DE$3:DE$7)) -> 0 | DF15: =SUMPRODUCT((NOT(ISBLANK(DF$3:DF$7))*(DF$3:DF$7>$EO$3:$EO$7))+ISBLANK(DF$3:DF$7)) -> 0 | DG15: =SUMPRODUCT((NOT(ISBLANK(DG$3:DG$7))*(DG$3:DG$7>$EP$3:$EP$7))+ISBLANK(DG$3:DG$7)) -> 0 | DI15: =SUMPRODUCT((NOT(ISBLANK(DI$3:DI$7))*(DI$3:DI$7>$EQ$3:$EQ$7))+ISBLANK(DI$3:DI$7)) -> 0 | DJ15: =SUMPRODUCT((NOT(ISBLANK(DJ$3:DJ$7))*(DJ$3:DJ$7>$EO$3:$EO$7))+ISBLANK(DJ$3:DJ$7)) -> 0 | DK15: =SUMPRODUCT((NOT(ISBLANK(DK$3:DK$7))*(DK$3:DK$7>$EP$3:$EP$7))+ISBLANK(DK$3:DK$7)) -> 0 | DM15: =SUMPRODUCT((NOT(ISBLANK(DM$3:DM$7))*(DM$3:DM$7>$EQ$3:$EQ$7))+ISBLANK(DM$3:DM$7)) -> 0 | DN15: =SUMPRODUCT((NOT(ISBLANK(DN$3:DN$7))*(DN$3:DN$7>$EO$3:$EO$7))+ISBLANK(DN$3:DN$7)) -> 0 | DO15: =SUMPRODUCT((NOT(ISBLANK(DO$3:DO$7))*(DO$3:DO$7>$EP$3:$EP$7))+ISBLANK(DO$3:DO$7)) -> 0 | DQ15: =SUMPRODUCT((NOT(ISBLANK(DQ$3:DQ$7))*(DQ$3:DQ$7>$EQ$3:$EQ$7))+ISBLANK(DQ$3:DQ$7)) -> 0 | DR15: =SUMPRODUCT((NOT(ISBLANK(DR$3:DR$7))*(DR$3:DR$7>$EO$3:$EO$7))+ISBLANK(DR$3:DR$7)) -> 0 | DS15: =SUMPRODUCT((NOT(ISBLANK(DS$3:DS$7))*(DS$3:DS$7>$EP$3:$EP$7))+ISBLANK(DS$3:DS$7)) -> 0 | DU15: =SUMPRODUCT((NOT(ISBLANK(DU$3:DU$7))*(DU$3:DU$7>$EQ$3:$EQ$7))+ISBLANK(DU$3:DU$7)) -> 0 | DV15: =SUMPRODUCT((NOT(ISBLANK(DV$3:DV$7))*(DV$3:DV$7>$EO$3:$EO$7))+ISBLANK(DV$3:DV$7)) -> 0 | DW15: =SUMPRODUCT((NOT(ISBLANK(DW$3:DW$7))*(DW$3:DW$7>$EP$3:$EP$7))+ISBLANK(DW$3:DW$7)) -> 0 | DY15: =SUMPRODUCT((NOT(ISBLANK(DY$3:DY$7))*(DY$3:DY$7>$EQ$3:$EQ$7))+ISBLANK(DY$3:DY$7)) -> 0 | DZ15: =SUMPRODUCT((NOT(ISBLANK(DZ$3:DZ$7))*(DZ$3:DZ$7>$EO$3:$EO$7))+ISBLANK(DZ$3:DZ$7)) -> 0 | EA15: =SUMPRODUCT((NOT(ISBLANK(EA$3:EA$7))*(EA$3:EA$7>$EP$3:$EP$7))+ISBLANK(EA$3:EA$7)) -> 0 | EC15: =SUMPRODUCT((NOT(ISBLANK(EC$3:EC$7))*(EC$3:EC$7>$EQ$3:$EQ$7))+ISBLANK(EC$3:EC$7)) -> 0 | ED15: =SUMPRODUCT((NOT(ISBLANK(ED$3:ED$7))*(ED$3:ED$7>$EO$3:$EO$7))+ISBLANK(ED$3:ED$7)) -> 0 | EE15: =SUMPRODUCT((NOT(ISBLANK(EE$3:EE$7))*(EE$3:EE$7>$EP$3:$EP$7))+ISBLANK(EE$3:EE$7)) -> 0 | EG15: =SUMPRODUCT((NOT(ISBLANK(EG$3:EG$7))*(EG$3:EG$7>$EQ$3:$EQ$7))+ISBLANK(EG$3:EG$7)) -> 0 | EH15: =SUMPRODUCT((NOT(ISBLANK(EH$3:EH$7))*(EH$3:EH$7>$EO$3:$EO$7))+ISBLANK(EH$3:EH$7)) -> 0 | EI15: =SUMPRODUCT((NOT(ISBLANK(EI$3:EI$7))*(EI$3:EI$7>$EP$3:$EP$7))+ISBLANK(EI$3:EI$7)) -> 0 | EK15: =SUMPRODUCT((NOT(ISBLANK(EK$3:EK$7))*(EK$3:EK$7>$EQ$3:$EQ$7))+ISBLANK(EK$3:EK$7)) -> 0
