Workbook

Sheet Instances
B1: memelingo-1/simple_mlp-lpnmr-ht | G1: memelingo-1/simple_mlp-lpnmr-htc | L1: memelingo-1/simple_mlp-lpnmr-htcdl | Q1: memelingo-1/simple_mlp-tplp-ht | V1: memelingo-1/simple_mlp-tplp-htc | AA1: memelingo-1/simple_mlp-tplp-htcdl | AF1: min | AJ1: median | AN1: max
B2: time | C2: stime | D2: status | E2: rules | F2: ctime | G2: time | H2: stime | I2: status | J2: rules | K2: ctime | L2: time | M2: stime | N2: status | O2: rules | P2: ctime | Q2: time | R2: stime | S2: status | T2: rules | U2: ctime | V2: time | W2: stime | X2: status | Y2: rules | Z2: ctime | AA2: time | AB2: stime | AC2: status | AD2: rules | AE2: ctime | AF2: time | AG2: stime | AH2: rules | AI2: ctime | AJ2: time | AK2: stime | AL2: rules | AM2: ctime | AN2: time | AO2: stime | AP2: rules | AQ2: ctime
A3: instances/size-1 | B3: 10.29 | C3: 0.03 | D3: SATISFIABLE | E3: 297060 | F3: 1.956 | G3: 8.38 | H3: 0.01 | I3: SATISFIABLE | J3: 2014 | K3: 0.234 | L3: 8.74 | M3: 0.01 | N3: SATISFIABLE | O3: 2014 | P3: 0.231 | Q3: 7.93 | R3: 0.27 | S3: SATISFIABLE | T3: 334135 | U3: 1.8 | V3: 8.39 | W3: 0.01 | X3: SATISFIABLE | Y3: 2249 | Z3: 0.239 | AA3: 8.28 | AB3: 0.01 | AC3: SATISFIABLE | AD3: 2249 | AE3: 0.275 | AF3: =MIN($B3,$G3,$L3,$Q3,$V3,$AA3) -> 0 | AG3: =MIN($C3,$H3,$M3,$R3,$W3,$AB3) -> 0 | AH3: =MIN($E3,$J3,$O3,$T3,$Y3,$AD3) -> 0 | AI3: =MIN($F3,$K3,$P3,$U3,$Z3,$AE3) -> 0 | AJ3: =MEDIAN($B3,$G3,$L3,$Q3,$V3,$AA3) -> 0 | AK3: =MEDIAN($C3,$H3,$M3,$R3,$W3,$AB3) -> 0 | AL3: =MEDIAN($E3,$J3,$O3,$T3,$Y3,$AD3) -> 0 | AM3: =MEDIAN($F3,$K3,$P3,$U3,$Z3,$AE3) -> 0 | AN3: =MAX($B3,$G3,$L3,$Q3,$V3,$AA3) -> 0 | AO3: =MAX($C3,$H3,$M3,$R3,$W3,$AB3) -> 0 | AP3: =MAX($E3,$J3,$O3,$T3,$Y3,$AD3) -> 0 | AQ3: =MAX($F3,$K3,$P3,$U3,$Z3,$AE3) -> 0
A4: instances/size-10 | B4: 1200 | C4: 0 | D4: UNKNOWN | E4: 0 | F4: 195.713 | G4: 8.48 | H4: 0.01 | I4: SATISFIABLE | J4: 2014 | K4: 0.23 | L4: 8.4 | M4: 0.01 | N4: SATISFIABLE | O4: 2014 | P4: 0.228 | Q4: 1200 | R4: 0 | S4: UNKNOWN | T4: 0 | U4: 233.706 | V4: 8.39 | W4: 0.02 | X4: SATISFIABLE | Y4: 2249 | Z4: 0.236 | AA4: 7.78 | AB4: 0.01 | AC4: SATISFIABLE | AD4: 2249 | AE4: 0.276 | AF4: =MIN($B4,$G4,$L4,$Q4,$V4,$AA4) -> 0 | AG4: =MIN($C4,$H4,$M4,$R4,$W4,$AB4) -> 0 | AH4: =MIN($E4,$J4,$O4,$T4,$Y4,$AD4) -> 0 | AI4: =MIN($F4,$K4,$P4,$U4,$Z4,$AE4) -> 0 | AJ4: =MEDIAN($B4,$G4,$L4,$Q4,$V4,$AA4) -> 0 | AK4: =MEDIAN($C4,$H4,$M4,$R4,$W4,$AB4) -> 0 | AL4: =MEDIAN($E4,$J4,$O4,$T4,$Y4,$AD4) -> 0 | AM4: =MEDIAN($F4,$K4,$P4,$U4,$Z4,$AE4) -> 0 | AN4: =MAX($B4,$G4,$L4,$Q4,$V4,$AA4) -> 0 | AO4: =MAX($C4,$H4,$M4,$R4,$W4,$AB4) -> 0 | AP4: =MAX($E4,$J4,$O4,$T4,$Y4,$AD4) -> 0 | AQ4: =MAX($F4,$K4,$P4,$U4,$Z4,$AE4) -> 0
A5: instances/size-5 | B5: 81.78 | C5: 17.96 | D5: SATISFIABLE | E5: 7527300 | F5: 72.54 | G5: 8.41 | H5: 0.01 | I5: SATISFIABLE | J5: 2014 | K5: 0.216 | L5: 8.73 | M5: 0.01 | N5: SATISFIABLE | O5: 2014 | P5: 0.245 | Q5: 66.96 | R5: 7.2 | S5: SATISFIABLE | T5: 8437935 | U5: 60.122 | V5: 8.37 | W5: 0.02 | X5: SATISFIABLE | Y5: 2249 | Z5: 0.282 | AA5: 8.76 | AB5: 0.01 | AC5: SATISFIABLE | AD5: 2249 | AE5: 0.263 | AF5: =MIN($B5,$G5,$L5,$Q5,$V5,$AA5) -> 0 | AG5: =MIN($C5,$H5,$M5,$R5,$W5,$AB5) -> 0 | AH5: =MIN($E5,$J5,$O5,$T5,$Y5,$AD5) -> 0 | AI5: =MIN($F5,$K5,$P5,$U5,$Z5,$AE5) -> 0 | AJ5: =MEDIAN($B5,$G5,$L5,$Q5,$V5,$AA5) -> 0 | AK5: =MEDIAN($C5,$H5,$M5,$R5,$W5,$AB5) -> 0 | AL5: =MEDIAN($E5,$J5,$O5,$T5,$Y5,$AD5) -> 0 | AM5: =MEDIAN($F5,$K5,$P5,$U5,$Z5,$AE5) -> 0 | AN5: =MAX($B5,$G5,$L5,$Q5,$V5,$AA5) -> 0 | AO5: =MAX($C5,$H5,$M5,$R5,$W5,$AB5) -> 0 | AP5: =MAX($E5,$J5,$O5,$T5,$Y5,$AD5) -> 0 | AQ5: =MAX($F5,$K5,$P5,$U5,$Z5,$AE5) -> 0
A6: instances/size-7 | B6: 142.33 | C6: 16.37 | D6: SATISFIABLE | E6: 14772420 | F6: 132.76 | G6: 8.75 | H6: 0.01 | I6: SATISFIABLE | J6: 2014 | K6: 0.231 | L6: 8.51 | M6: 0.01 | N6: SATISFIABLE | O6: 2014 | P6: 0.229 | Q6: 209.67 | R6: 80.98 | S6: SATISFIABLE | T6: 16555435 | U6: 201.125 | V6: 8.26 | W6: 0.02 | X6: SATISFIABLE | Y6: 2249 | Z6: 0.251 | AA6: 8.13 | AB6: 0.01 | AC6: SATISFIABLE | AD6: 2249 | AE6: 0.243 | AF6: =MIN($B6,$G6,$L6,$Q6,$V6,$AA6) -> 0 | AG6: =MIN($C6,$H6,$M6,$R6,$W6,$AB6) -> 0 | AH6: =MIN($E6,$J6,$O6,$T6,$Y6,$AD6) -> 0 | AI6: =MIN($F6,$K6,$P6,$U6,$Z6,$AE6) -> 0 | AJ6: =MEDIAN($B6,$G6,$L6,$Q6,$V6,$AA6) -> 0 | AK6: =MEDIAN($C6,$H6,$M6,$R6,$W6,$AB6) -> 0 | AL6: =MEDIAN($E6,$J6,$O6,$T6,$Y6,$AD6) -> 0 | AM6: =MEDIAN($F6,$K6,$P6,$U6,$Z6,$AE6) -> 0 | AN6: =MAX($B6,$G6,$L6,$Q6,$V6,$AA6) -> 0 | AO6: =MAX($C6,$H6,$M6,$R6,$W6,$AB6) -> 0 | AP6: =MAX($E6,$J6,$O6,$T6,$Y6,$AD6) -> 0 | AQ6: =MAX($F6,$K6,$P6,$U6,$Z6,$AE6) -> 0
A8: SUM | B8: =SUM(B$3:B$6) -> 0 | C8: =SUM(C$3:C$6) -> 0 | E8: =SUM(E$3:E$6) -> 0 | F8: =SUM(F$3:F$6) -> 0 | G8: =SUM(G$3:G$6) -> 0 | H8: =SUM(H$3:H$6) -> 0 | J8: =SUM(J$3:J$6) -> 0 | K8: =SUM(K$3:K$6) -> 0 | L8: =SUM(L$3:L$6) -> 0 | M8: =SUM(M$3:M$6) -> 0 | O8: =SUM(O$3:O$6) -> 0 | P8: =SUM(P$3:P$6) -> 0 | Q8: =SUM(Q$3:Q$6) -> 0 | R8: =SUM(R$3:R$6) -> 0 | T8: =SUM(T$3:T$6) -> 0 | U8: =SUM(U$3:U$6) -> 0 | V8: =SUM(V$3:V$6) -> 0 | W8: =SUM(W$3:W$6) -> 0 | Y8: =SUM(Y$3:Y$6) -> 0 | Z8: =SUM(Z$3:Z$6) -> 0 | AA8: =SUM(AA$3:AA$6) -> 0 | AB8: =SUM(AB$3:AB$6) -> 0 | AD8: =SUM(AD$3:AD$6) -> 0 | AE8: =SUM(AE$3:AE$6) -> 0 | AF8: =SUM(AF$3:AF$6) -> 0 | AG8: =SUM(AG$3:AG$6) -> 0 | AH8: =SUM(AH$3:AH$6) -> 0 | AI8: =SUM(AI$3:AI$6) -> 0 | AJ8: =SUM(AJ$3:AJ$6) -> 0 | AK8: =SUM(AK$3:AK$6) -> 0 | ... AQ8: =SUM(AQ$3:AQ$6) -> 0
A9: AVG | B9: =AVERAGE(B$3:B$6) -> 0 | C9: =AVERAGE(C$3:C$6) -> 0 | E9: =AVERAGE(E$3:E$6) -> 0 | F9: =AVERAGE(F$3:F$6) -> 0 | G9: =AVERAGE(G$3:G$6) -> 0 | H9: =AVERAGE(H$3:H$6) -> 0 | J9: =AVERAGE(J$3:J$6) -> 0 | K9: =AVERAGE(K$3:K$6) -> 0 | L9: =AVERAGE(L$3:L$6) -> 0 | M9: =AVERAGE(M$3:M$6) -> 0 | O9: =AVERAGE(O$3:O$6) -> 0 | P9: =AVERAGE(P$3:P$6) -> 0 | Q9: =AVERAGE(Q$3:Q$6) -> 0 | R9: =AVERAGE(R$3:R$6) -> 0 | T9: =AVERAGE(T$3:T$6) -> 0 | U9: =AVERAGE(U$3:U$6) -> 0 | V9: =AVERAGE(V$3:V$6) -> 0 | W9: =AVERAGE(W$3:W$6) -> 0 | Y9: =AVERAGE(Y$3:Y$6) -> 0 | Z9: =AVERAGE(Z$3:Z$6) -> 0 | AA9: =AVERAGE(AA$3:AA$6) -> 0 | AB9: =AVERAGE(AB$3:AB$6) -> 0 | AD9: =AVERAGE(AD$3:AD$6) -> 0 | AE9: =AVERAGE(AE$3:AE$6) -> 0 | AF9: =AVERAGE(AF$3:AF$6) -> 0 | AG9: =AVERAGE(AG$3:AG$6) -> 0 | AH9: =AVERAGE(AH$3:AH$6) -> 0 | AI9: =AVERAGE(AI$3:AI$6) -> 0 | AJ9: =AVERAGE(AJ$3:AJ$6) -> 0 | AK9: =AVERAGE(AK$3:AK$6) -> 0 | ... AQ9: =AVERAGE(AQ$3:AQ$6) -> 0
A10: DEV | B10: =STDEV(B$3:B$6) -> 0 | C10: =STDEV(C$3:C$6) -> 0 | E10: =STDEV(E$3:E$6) -> 0 | F10: =STDEV(F$3:F$6) -> 0 | G10: =STDEV(G$3:G$6) -> 0 | H10: =STDEV(H$3:H$6) -> 0 | J10: =STDEV(J$3:J$6) -> 0 | K10: =STDEV(K$3:K$6) -> 0 | L10: =STDEV(L$3:L$6) -> 0 | M10: =STDEV(M$3:M$6) -> 0 | O10: =STDEV(O$3:O$6) -> 0 | P10: =STDEV(P$3:P$6) -> 0 | Q10: =STDEV(Q$3:Q$6) -> 0 | R10: =STDEV(R$3:R$6) -> 0 | T10: =STDEV(T$3:T$6) -> 0 | U10: =STDEV(U$3:U$6) -> 0 | V10: =STDEV(V$3:V$6) -> 0 | W10: =STDEV(W$3:W$6) -> 0 | Y10: =STDEV(Y$3:Y$6) -> 0 | Z10: =STDEV(Z$3:Z$6) -> 0 | AA10: =STDEV(AA$3:AA$6) -> 0 | AB10: =STDEV(AB$3:AB$6) -> 0 | AD10: =STDEV(AD$3:AD$6) -> 0 | AE10: =STDEV(AE$3:AE$6) -> 0 | AF10: =STDEV(AF$3:AF$6) -> 0 | AG10: =STDEV(AG$3:AG$6) -> 0 | AH10: =STDEV(AH$3:AH$6) -> 0 | AI10: =STDEV(AI$3:AI$6) -> 0 | AJ10: =STDEV(AJ$3:AJ$6) -> 0 | AK10: =STDEV(AK$3:AK$6) -> 0 | ... AQ10: =STDEV(AQ$3:AQ$6) -> 0
A11: DST | B11: =SUMPRODUCT(--(B$3:B$6-$AF$3:$AF$6)^2)^0.5 -> 0 | C11: =SUMPRODUCT(--(C$3:C$6-$AG$3:$AG$6)^2)^0.5 -> 0 | E11: =SUMPRODUCT(--(E$3:E$6-$AH$3:$AH$6)^2)^0.5 -> 0 | F11: =SUMPRODUCT(--(F$3:F$6-$AI$3:$AI$6)^2)^0.5 -> 0 | G11: =SUMPRODUCT(--(G$3:G$6-$AF$3:$AF$6)^2)^0.5 -> 0 | H11: =SUMPRODUCT(--(H$3:H$6-$AG$3:$AG$6)^2)^0.5 -> 0 | J11: =SUMPRODUCT(--(J$3:J$6-$AH$3:$AH$6)^2)^0.5 -> 0 | K11: =SUMPRODUCT(--(K$3:K$6-$AI$3:$AI$6)^2)^0.5 -> 0 | L11: =SUMPRODUCT(--(L$3:L$6-$AF$3:$AF$6)^2)^0.5 -> 0 | M11: =SUMPRODUCT(--(M$3:M$6-$AG$3:$AG$6)^2)^0.5 -> 0 | O11: =SUMPRODUCT(--(O$3:O$6-$AH$3:$AH$6)^2)^0.5 -> 0 | P11: =SUMPRODUCT(--(P$3:P$6-$AI$3:$AI$6)^2)^0.5 -> 0 | Q11: =SUMPRODUCT(--(Q$3:Q$6-$AF$3:$AF$6)^2)^0.5 -> 0 | R11: =SUMPRODUCT(--(R$3:R$6-$AG$3:$AG$6)^2)^0.5 -> 0 | T11: =SUMPRODUCT(--(T$3:T$6-$AH$3:$AH$6)^2)^0.5 -> 0 | U11: =SUMPRODUCT(--(U$3:U$6-$AI$3:$AI$6)^2)^0.5 -> 0 | V11: =SUMPRODUCT(--(V$3:V$6-$AF$3:$AF$6)^2)^0.5 -> 0 | W11: =SUMPRODUCT(--(W$3:W$6-$AG$3:$AG$6)^2)^0.5 -> 0 | Y11: =SUMPRODUCT(--(Y$3:Y$6-$AH$3:$AH$6)^2)^0.5 -> 0 | Z11: =SUMPRODUCT(--(Z$3:Z$6-$AI$3:$AI$6)^2)^0.5 -> 0 | AA11: =SUMPRODUCT(--(AA$3:AA$6-$AF$3:$AF$6)^2)^0.5 -> 0 | AB11: =SUMPRODUCT(--(AB$3:AB$6-$AG$3:$AG$6)^2)^0.5 -> 0 | AD11: =SUMPRODUCT(--(AD$3:AD$6-$AH$3:$AH$6)^2)^0.5 -> 0 | AE11: =SUMPRODUCT(--(AE$3:AE$6-$AI$3:$AI$6)^2)^0.5 -> 0
A12: BEST | B12: =SUMPRODUCT(NOT(ISBLANK(B$3:B$6))*(B$3:B$6=$AF$3:$AF$6)) -> 0 | C12: =SUMPRODUCT(NOT(ISBLANK(C$3:C$6))*(C$3:C$6=$AG$3:$AG$6)) -> 0 | E12: =SUMPRODUCT(NOT(ISBLANK(E$3:E$6))*(E$3:E$6=$AH$3:$AH$6)) -> 0 | F12: =SUMPRODUCT(NOT(ISBLANK(F$3:F$6))*(F$3:F$6=$AI$3:$AI$6)) -> 0 | G12: =SUMPRODUCT(NOT(ISBLANK(G$3:G$6))*(G$3:G$6=$AF$3:$AF$6)) -> 0 | H12: =SUMPRODUCT(NOT(ISBLANK(H$3:H$6))*(H$3:H$6=$AG$3:$AG$6)) -> 0 | J12: =SUMPRODUCT(NOT(ISBLANK(J$3:J$6))*(J$3:J$6=$AH$3:$AH$6)) -> 0 | K12: =SUMPRODUCT(NOT(ISBLANK(K$3:K$6))*(K$3:K$6=$AI$3:$AI$6)) -> 0 | L12: =SUMPRODUCT(NOT(ISBLANK(L$3:L$6))*(L$3:L$6=$AF$3:$AF$6)) -> 0 | M12: =SUMPRODUCT(NOT(ISBLANK(M$3:M$6))*(M$3:M$6=$AG$3:$AG$6)) -> 0 | O12: =SUMPRODUCT(NOT(ISBLANK(O$3:O$6))*(O$3:O$6=$AH$3:$AH$6)) -> 0 | P12: =SUMPRODUCT(NOT(ISBLANK(P$3:P$6))*(P$3:P$6=$AI$3:$AI$6)) -> 0 | Q12: =SUMPRODUCT(NOT(ISBLANK(Q$3:Q$6))*(Q$3:Q$6=$AF$3:$AF$6)) -> 0 | R12: =SUMPRODUCT(NOT(ISBLANK(R$3:R$6))*(R$3:R$6=$AG$3:$AG$6)) -> 0 | T12: =SUMPRODUCT(NOT(ISBLANK(T$3:T$6))*(T$3:T$6=$AH$3:$AH$6)) -> 0 | U12: =SUMPRODUCT(NOT(ISBLANK(U$3:U$6))*(U$3:U$6=$AI$3:$AI$6)) -> 0 | V12: =SUMPRODUCT(NOT(ISBLANK(V$3:V$6))*(V$3:V$6=$AF$3:$AF$6)) -> 0 | W12: =SUMPRODUCT(NOT(ISBLANK(W$3:W$6))*(W$3:W$6=$AG$3:$AG$6)) -> 0 | Y12: =SUMPRODUCT(NOT(ISBLANK(Y$3:Y$6))*(Y$3:Y$6=$AH$3:$AH$6)) -> 0 | Z12: =SUMPRODUCT(NOT(ISBLANK(Z$3:Z$6))*(Z$3:Z$6=$AI$3:$AI$6)) -> 0 | AA12: =SUMPRODUCT(NOT(ISBLANK(AA$3:AA$6))*(AA$3:AA$6=$AF$3:$AF$6)) -> 0 | AB12: =SUMPRODUCT(NOT(ISBLANK(AB$3:AB$6))*(AB$3:AB$6=$AG$3:$AG$6)) -> 0 | AD12: =SUMPRODUCT(NOT(ISBLANK(AD$3:AD$6))*(AD$3:AD$6=$AH$3:$AH$6)) -> 0 | AE12: =SUMPRODUCT(NOT(ISBLANK(AE$3:AE$6))*(AE$3:AE$6=$AI$3:$AI$6)) -> 0
A13: BETTER | B13: =SUMPRODUCT(NOT(ISBLANK(B$3:B$6))*(B$3:B$6<$AJ$3:$AJ$6)) -> 0 | C13: =SUMPRODUCT(NOT(ISBLANK(C$3:C$6))*(C$3:C$6<$AK$3:$AK$6)) -> 0 | E13: =SUMPRODUCT(NOT(ISBLANK(E$3:E$6))*(E$3:E$6<$AL$3:$AL$6)) -> 0 | F13: =SUMPRODUCT(NOT(ISBLANK(F$3:F$6))*(F$3:F$6<$AM$3:$AM$6)) -> 0 | G13: =SUMPRODUCT(NOT(ISBLANK(G$3:G$6))*(G$3:G$6<$AJ$3:$AJ$6)) -> 0 | H13: =SUMPRODUCT(NOT(ISBLANK(H$3:H$6))*(H$3:H$6<$AK$3:$AK$6)) -> 0 | J13: =SUMPRODUCT(NOT(ISBLANK(J$3:J$6))*(J$3:J$6<$AL$3:$AL$6)) -> 0 | K13: =SUMPRODUCT(NOT(ISBLANK(K$3:K$6))*(K$3:K$6<$AM$3:$AM$6)) -> 0 | L13: =SUMPRODUCT(NOT(ISBLANK(L$3:L$6))*(L$3:L$6<$AJ$3:$AJ$6)) -> 0 | M13: =SUMPRODUCT(NOT(ISBLANK(M$3:M$6))*(M$3:M$6<$AK$3:$AK$6)) -> 0 | O13: =SUMPRODUCT(NOT(ISBLANK(O$3:O$6))*(O$3:O$6<$AL$3:$AL$6)) -> 0 | P13: =SUMPRODUCT(NOT(ISBLANK(P$3:P$6))*(P$3:P$6<$AM$3:$AM$6)) -> 0 | Q13: =SUMPRODUCT(NOT(ISBLANK(Q$3:Q$6))*(Q$3:Q$6<$AJ$3:$AJ$6)) -> 0 | R13: =SUMPRODUCT(NOT(ISBLANK(R$3:R$6))*(R$3:R$6<$AK$3:$AK$6)) -> 0 | T13: =SUMPRODUCT(NOT(ISBLANK(T$3:T$6))*(T$3:T$6<$AL$3:$AL$6)) -> 0 | U13: =SUMPRODUCT(NOT(ISBLANK(U$3:U$6))*(U$3:U$6<$AM$3:$AM$6)) -> 0 | V13: =SUMPRODUCT(NOT(ISBLANK(V$3:V$6))*(V$3:V$6<$AJ$3:$AJ$6)) -> 0 | W13: =SUMPRODUCT(NOT(ISBLANK(W$3:W$6))*(W$3:W$6<$AK$3:$AK$6)) -> 0 | Y13: =SUMPRODUCT(NOT(ISBLANK(Y$3:Y$6))*(Y$3:Y$6<$AL$3:$AL$6)) -> 0 | Z13: =SUMPRODUCT(NOT(ISBLANK(Z$3:Z$6))*(Z$3:Z$6<$AM$3:$AM$6)) -> 0 | AA13: =SUMPRODUCT(NOT(ISBLANK(AA$3:AA$6))*(AA$3:AA$6<$AJ$3:$AJ$6)) -> 0 | AB13: =SUMPRODUCT(NOT(ISBLANK(AB$3:AB$6))*(AB$3:AB$6<$AK$3:$AK$6)) -> 0 | AD13: =SUMPRODUCT(NOT(ISBLANK(AD$3:AD$6))*(AD$3:AD$6<$AL$3:$AL$6)) -> 0 | AE13: =SUMPRODUCT(NOT(ISBLANK(AE$3:AE$6))*(AE$3:AE$6<$AM$3:$AM$6)) -> 0
A14: WORSE | B14: =SUMPRODUCT((NOT(ISBLANK(B$3:B$6))*(B$3:B$6>$AJ$3:$AJ$6))+ISBLANK(B$3:B$6)) -> 0 | C14: =SUMPRODUCT((NOT(ISBLANK(C$3:C$6))*(C$3:C$6>$AK$3:$AK$6))+ISBLANK(C$3:C$6)) -> 0 | E14: =SUMPRODUCT((NOT(ISBLANK(E$3:E$6))*(E$3:E$6>$AL$3:$AL$6))+ISBLANK(E$3:E$6)) -> 0 | F14: =SUMPRODUCT((NOT(ISBLANK(F$3:F$6))*(F$3:F$6>$AM$3:$AM$6))+ISBLANK(F$3:F$6)) -> 0 | G14: =SUMPRODUCT((NOT(ISBLANK(G$3:G$6))*(G$3:G$6>$AJ$3:$AJ$6))+ISBLANK(G$3:G$6)) -> 0 | H14: =SUMPRODUCT((NOT(ISBLANK(H$3:H$6))*(H$3:H$6>$AK$3:$AK$6))+ISBLANK(H$3:H$6)) -> 0 | J14: =SUMPRODUCT((NOT(ISBLANK(J$3:J$6))*(J$3:J$6>$AL$3:$AL$6))+ISBLANK(J$3:J$6)) -> 0 | K14: =SUMPRODUCT((NOT(ISBLANK(K$3:K$6))*(K$3:K$6>$AM$3:$AM$6))+ISBLANK(K$3:K$6)) -> 0 | L14: =SUMPRODUCT((NOT(ISBLANK(L$3:L$6))*(L$3:L$6>$AJ$3:$AJ$6))+ISBLANK(L$3:L$6)) -> 0 | M14: =SUMPRODUCT((NOT(ISBLANK(M$3:M$6))*(M$3:M$6>$AK$3:$AK$6))+ISBLANK(M$3:M$6)) -> 0 | O14: =SUMPRODUCT((NOT(ISBLANK(O$3:O$6))*(O$3:O$6>$AL$3:$AL$6))+ISBLANK(O$3:O$6)) -> 0 | P14: =SUMPRODUCT((NOT(ISBLANK(P$3:P$6))*(P$3:P$6>$AM$3:$AM$6))+ISBLANK(P$3:P$6)) -> 0 | Q14: =SUMPRODUCT((NOT(ISBLANK(Q$3:Q$6))*(Q$3:Q$6>$AJ$3:$AJ$6))+ISBLANK(Q$3:Q$6)) -> 0 | R14: =SUMPRODUCT((NOT(ISBLANK(R$3:R$6))*(R$3:R$6>$AK$3:$AK$6))+ISBLANK(R$3:R$6)) -> 0 | T14: =SUMPRODUCT((NOT(ISBLANK(T$3:T$6))*(T$3:T$6>$AL$3:$AL$6))+ISBLANK(T$3:T$6)) -> 0 | U14: =SUMPRODUCT((NOT(ISBLANK(U$3:U$6))*(U$3:U$6>$AM$3:$AM$6))+ISBLANK(U$3:U$6)) -> 0 | V14: =SUMPRODUCT((NOT(ISBLANK(V$3:V$6))*(V$3:V$6>$AJ$3:$AJ$6))+ISBLANK(V$3:V$6)) -> 0 | W14: =SUMPRODUCT((NOT(ISBLANK(W$3:W$6))*(W$3:W$6>$AK$3:$AK$6))+ISBLANK(W$3:W$6)) -> 0 | Y14: =SUMPRODUCT((NOT(ISBLANK(Y$3:Y$6))*(Y$3:Y$6>$AL$3:$AL$6))+ISBLANK(Y$3:Y$6)) -> 0 | Z14: =SUMPRODUCT((NOT(ISBLANK(Z$3:Z$6))*(Z$3:Z$6>$AM$3:$AM$6))+ISBLANK(Z$3:Z$6)) -> 0 | AA14: =SUMPRODUCT((NOT(ISBLANK(AA$3:AA$6))*(AA$3:AA$6>$AJ$3:$AJ$6))+ISBLANK(AA$3:AA$6)) -> 0 | AB14: =SUMPRODUCT((NOT(ISBLANK(AB$3:AB$6))*(AB$3:AB$6>$AK$3:$AK$6))+ISBLANK(AB$3:AB$6)) -> 0 | AD14: =SUMPRODUCT((NOT(ISBLANK(AD$3:AD$6))*(AD$3:AD$6>$AL$3:$AL$6))+ISBLANK(AD$3:AD$6)) -> 0 | AE14: =SUMPRODUCT((NOT(ISBLANK(AE$3:AE$6))*(AE$3:AE$6>$AM$3:$AM$6))+ISBLANK(AE$3:AE$6)) -> 0
A15: WORST | B15: =SUMPRODUCT((NOT(ISBLANK(B$3:B$6))*(B$3:B$6=$AN$3:$AN$6))+ISBLANK(B$3:B$6)) -> 0 | C15: =SUMPRODUCT((NOT(ISBLANK(C$3:C$6))*(C$3:C$6=$AO$3:$AO$6))+ISBLANK(C$3:C$6)) -> 0 | E15: =SUMPRODUCT((NOT(ISBLANK(E$3:E$6))*(E$3:E$6=$AP$3:$AP$6))+ISBLANK(E$3:E$6)) -> 0 | F15: =SUMPRODUCT((NOT(ISBLANK(F$3:F$6))*(F$3:F$6=$AQ$3:$AQ$6))+ISBLANK(F$3:F$6)) -> 0 | G15: =SUMPRODUCT((NOT(ISBLANK(G$3:G$6))*(G$3:G$6=$AN$3:$AN$6))+ISBLANK(G$3:G$6)) -> 0 | H15: =SUMPRODUCT((NOT(ISBLANK(H$3:H$6))*(H$3:H$6=$AO$3:$AO$6))+ISBLANK(H$3:H$6)) -> 0 | J15: =SUMPRODUCT((NOT(ISBLANK(J$3:J$6))*(J$3:J$6=$AP$3:$AP$6))+ISBLANK(J$3:J$6)) -> 0 | K15: =SUMPRODUCT((NOT(ISBLANK(K$3:K$6))*(K$3:K$6=$AQ$3:$AQ$6))+ISBLANK(K$3:K$6)) -> 0 | L15: =SUMPRODUCT((NOT(ISBLANK(L$3:L$6))*(L$3:L$6=$AN$3:$AN$6))+ISBLANK(L$3:L$6)) -> 0 | M15: =SUMPRODUCT((NOT(ISBLANK(M$3:M$6))*(M$3:M$6=$AO$3:$AO$6))+ISBLANK(M$3:M$6)) -> 0 | O15: =SUMPRODUCT((NOT(ISBLANK(O$3:O$6))*(O$3:O$6=$AP$3:$AP$6))+ISBLANK(O$3:O$6)) -> 0 | P15: =SUMPRODUCT((NOT(ISBLANK(P$3:P$6))*(P$3:P$6=$AQ$3:$AQ$6))+ISBLANK(P$3:P$6)) -> 0 | Q15: =SUMPRODUCT((NOT(ISBLANK(Q$3:Q$6))*(Q$3:Q$6=$AN$3:$AN$6))+ISBLANK(Q$3:Q$6)) -> 0 | R15: =SUMPRODUCT((NOT(ISBLANK(R$3:R$6))*(R$3:R$6=$AO$3:$AO$6))+ISBLANK(R$3:R$6)) -> 0 | T15: =SUMPRODUCT((NOT(ISBLANK(T$3:T$6))*(T$3:T$6=$AP$3:$AP$6))+ISBLANK(T$3:T$6)) -> 0 | U15: =SUMPRODUCT((NOT(ISBLANK(U$3:U$6))*(U$3:U$6=$AQ$3:$AQ$6))+ISBLANK(U$3:U$6)) -> 0 | V15: =SUMPRODUCT((NOT(ISBLANK(V$3:V$6))*(V$3:V$6=$AN$3:$AN$6))+ISBLANK(V$3:V$6)) -> 0 | W15: =SUMPRODUCT((NOT(ISBLANK(W$3:W$6))*(W$3:W$6=$AO$3:$AO$6))+ISBLANK(W$3:W$6)) -> 0 | Y15: =SUMPRODUCT((NOT(ISBLANK(Y$3:Y$6))*(Y$3:Y$6=$AP$3:$AP$6))+ISBLANK(Y$3:Y$6)) -> 0 | Z15: =SUMPRODUCT((NOT(ISBLANK(Z$3:Z$6))*(Z$3:Z$6=$AQ$3:$AQ$6))+ISBLANK(Z$3:Z$6)) -> 0 | AA15: =SUMPRODUCT((NOT(ISBLANK(AA$3:AA$6))*(AA$3:AA$6=$AN$3:$AN$6))+ISBLANK(AA$3:AA$6)) -> 0 | AB15: =SUMPRODUCT((NOT(ISBLANK(AB$3:AB$6))*(AB$3:AB$6=$AO$3:$AO$6))+ISBLANK(AB$3:AB$6)) -> 0 | AD15: =SUMPRODUCT((NOT(ISBLANK(AD$3:AD$6))*(AD$3:AD$6=$AP$3:$AP$6))+ISBLANK(AD$3:AD$6)) -> 0 | AE15: =SUMPRODUCT((NOT(ISBLANK(AE$3:AE$6))*(AE$3:AE$6=$AQ$3:$AQ$6))+ISBLANK(AE$3:AE$6)) -> 0

Sheet Merged Runs
A1: Merge criteria: | B1: memelingo-1/simple_mlp-lpnmr-ht | G1: memelingo-1/simple_mlp-lpnmr-htc | L1: memelingo-1/simple_mlp-lpnmr-htcdl | Q1: memelingo-1/simple_mlp-tplp-ht | V1: memelingo-1/simple_mlp-tplp-htc | AA1: memelingo-1/simple_mlp-tplp-htcdl | AF1: min | AJ1: median | AN1: max
A2: median | B2: time | C2: stime | D2: status | E2: rules | F2: ctime | G2: time | H2: stime | I2: status | J2: rules | K2: ctime | L2: time | M2: stime | N2: status | O2: rules | P2: ctime | Q2: time | R2: stime | S2: status | T2: rules | U2: ctime | V2: time | W2: stime | X2: status | Y2: rules | Z2: ctime | AA2: time | AB2: stime | AC2: status | AD2: rules | AE2: ctime | AF2: time | AG2: stime | AH2: rules | AI2: ctime | AJ2: time | AK2: stime | AL2: rules | AM2: ctime | AN2: time | AO2: stime | AP2: rules | AQ2: ctime
A3: instances/size-1 | B3: {=_xlfn.SWITCH($A$2,"average", AVERAGE(Instances!B3:Instances!B3),"median", MEDIAN(Instances!B3:Instances!B3),"min", MIN(Instances!B3:Instances!B3),"max", MAX(Instances!B3:Instances!B3),"diff", MAX(Instances!B3:Instances!B3)-MIN(Instances!B3:Instances!B3))} -> 0 | C3: {=_xlfn.SWITCH($A$2,"average", AVERAGE(Instances!C3:Instances!C3),"median", MEDIAN(Instances!C3:Instances!C3),"min", MIN(Instances!C3:Instances!C3),"max", MAX(Instances!C3:Instances!C3),"diff", MAX(Instances!C3:Instances!C3)-MIN(Instances!C3:Instances!C3))} -> 0 | E3: {=_xlfn.SWITCH($A$2,"average", AVERAGE(Instances!E3:Instances!E3),"median", MEDIAN(Instances!E3:Instances!E3),"min", MIN(Instances!E3:Instances!E3),"max", MAX(Instances!E3:Instances!E3),"diff", MAX(Instances!E3:Instances!E3)-MIN(Instances!E3:Instances!E3))} -> 0 | F3: {=_xlfn.SWITCH($A$2,"average", AVERAGE(Instances!F3:Instances!F3),"median", MEDIAN(Instances!F3:Instances!F3),"min", MIN(Instances!F3:Instances!F3),"max", MAX(Instances!F3:Instances!F3),"diff", MAX(Instances!F3:Instances!F3)-MIN(Instances!F3:Instances!F3))} -> 0 | G3: {=_xlfn.SWITCH($A$2,"average", AVERAGE(Instances!G3:Instances!G3),"median", MEDIAN(Instances!G3:Instances!G3),"min", MIN(Instances!G3:Instances!G3),"max", MAX(Instances!G3:Instances!G3),"diff", MAX(Instances!G3:Instances!G3)-MIN(Instances!G3:Instances!G3))} -> 0 | H3: {=_xlfn.SWITCH($A$2,"average", AVERAGE(Instances!H3:Instances!H3),"median", MEDIAN(Instances!H3:Instances!H3),"min", MIN(Instances!H3:Instances!H3),"max", MAX(Instances!H3:Instances!H3),"diff", MAX(Instances!H3:Instances!H3)-MIN(Instances!H3:Instances!H3))} -> 0 | J3: {=_xlfn.SWITCH($A$2,"average", AVERAGE(Instances!J3:Instances!J3),"median", MEDIAN(Instances!J3:Instances!J3),"min", MIN(Instances!J3:Instances!J3),"max", MAX(Instances!J3:Instances!J3),"diff", MAX(Instances!J3:Instances!J3)-MIN(Instances!J3:Instances!J3))} -> 0 | K3: {=_xlfn.SWITCH($A$2,"average", AVERAGE(Instances!K3:Instances!K3),"median", MEDIAN(Instances!K3:Instances!K3),"min", MIN(Instances!K3:Instances!K3),"max", MAX(Instances!K3:Instances!K3),"diff", MAX(Instances!K3:Instances!K3)-MIN(Instances!K3:Instances!K3))} -> 0 | L3: {=_xlfn.SWITCH($A$2,"average", AVERAGE(Instances!L3:Instances!L3),"median", MEDIAN(Instances!L3:Instances!L3),"min", MIN(Instances!L3:Instances!L3),"max", MAX(Instances!L3:Instances!L3),"diff", MAX(Instances!L3:Instances!L3)-MIN(Instances!L3:Instances!L3))} -> 0 | M3: {=_xlfn.SWITCH($A$2,"average", AVERAGE(Instances!M3:Instances!M3),"median", MEDIAN(Instances!M3:Instances!M3),"min", MIN(Instances!M3:Instances!M3),"max", MAX(Instances!M3:Instances!M3),"diff", MAX(Instances!M3:Instances!M3)-MIN(Instances!M3:Instances!M3))} -> 0 | O3: {=_xlfn.SWITCH($A$2,"average", AVERAGE(Instances!O3:Instances!O3),"median", MEDIAN(Instances!O3:Instances!O3),"min", MIN(Instances!O3:Instances!O3),"max", MAX(Instances!O3:Instances!O3),"diff", MAX(Instances!O3:Instances!O3)-MIN(Instances!O3:Instances!O3))} -> 0 | P3: {=_xlfn.SWITCH($A$2,"average", AVERAGE(Instances!P3:Instances!P3),"median", MEDIAN(Instances!P3:Instances!P3),"min", MIN(Instances!P3:Instances!P3),"max", MAX(Instances!P3:Instances!P3),"diff", MAX(Instances!P3:Instances!P3)-MIN(Instances!P3:Instances!P3))} -> 0 | Q3: {=_xlfn.SWITCH($A$2,"average", AVERAGE(Instances!Q3:Instances!Q3),"median", MEDIAN(Instances!Q3:Instances!Q3),"min", MIN(Instances!Q3:Instances!Q3),"max", MAX(Instances!Q3:Instances!Q3),"diff", MAX(Instances!Q3:Instances!Q3)-MIN(Instances!Q3:Instances!Q3))} -> 0 | R3: {=_xlfn.SWITCH($A$2,"average", AVERAGE(Instances!R3:Instances!R3),"median", MEDIAN(Instances!R3:Instances!R3),"min", MIN(Instances!R3:Instances!R3),"max", MAX(Instances!R3:Instances!R3),"diff", MAX(Instances!R3:Instances!R3)-MIN(Instances!R3:Instances!R3))} -> 0 | T3: {=_xlfn.SWITCH($A$2,"average", AVERAGE(Instances!T3:Instances!T3),"median", MEDIAN(Instances!T3:Instances!T3),"min", MIN(Instances!T3:Instances!T3),"max", MAX(Instances!T3:Instances!T3),"diff", MAX(Instances!T3:Instances!T3)-MIN(Instances!T3:Instances!T3))} -> 0 | U3: {=_xlfn.SWITCH($A$2,"average", AVERAGE(Instances!U3:Instances!U3),"median", MEDIAN(Instances!U3:Instances!U3),"min", MIN(Instances!U3:Instances!U3),"max", MAX(Instances!U3:Instances!U3),"diff", MAX(Instances!U3:Instances!U3)-MIN(Instances!U3:Instances!U3))} -> 0 | V3: {=_xlfn.SWITCH($A$2,"average", AVERAGE(Instances!V3:Instances!V3),"median", MEDIAN(Instances!V3:Instances!V3),"min", MIN(Instances!V3:Instances!V3),"max", MAX(Instances!V3:Instances!V3),"diff", MAX(Instances!V3:Instances!V3)-MIN(Instances!V3:Instances!V3))} -> 0 | W3: {=_xlfn.SWITCH($A$2,"average", AVERAGE(Instances!W3:Instances!W3),"median", MEDIAN(Instances!W3:Instances!W3),"min", MIN(Instances!W3:Instances!W3),"max", MAX(Instances!W3:Instances!W3),"diff", MAX(Instances!W3:Instances!W3)-MIN(Instances!W3:Instances!W3))} -> 0 | Y3: {=_xlfn.SWITCH($A$2,"average", AVERAGE(Instances!Y3:Instances!Y3),"median", MEDIAN(Instances!Y3:Instances!Y3),"min", MIN(Instances!Y3:Instances!Y3),"max", MAX(Instances!Y3:Instances!Y3),"diff", MAX(Instances!Y3:Instances!Y3)-MIN(Instances!Y3:Instances!Y3))} -> 0 | Z3: {=_xlfn.SWITCH($A$2,"average", AVERAGE(Instances!Z3:Instances!Z3),"median", MEDIAN(Instances!Z3:Instances!Z3),"min", MIN(Instances!Z3:Instances!Z3),"max", MAX(Instances!Z3:Instances!Z3),"diff", MAX(Instances!Z3:Instances!Z3)-MIN(Instances!Z3:Instances!Z3))} -> 0 | AA3: {=_xlfn.SWITCH($A$2,"average", AVERAGE(Instances!AA3:Instances!AA3),"median", MEDIAN(Instances!AA3:Instances!AA3),"min", MIN(Instances!AA3:Instances!AA3),"max", MAX(Instances!AA3:Instances!AA3),"diff", MAX(Instances!AA3:Instances!AA3)-MIN(Instances!AA3:Instances!AA3))} -> 0 | AB3: {=_xlfn.SWITCH($A$2,"average", AVERAGE(Instances!AB3:Instances!AB3),"median", MEDIAN(Instances!AB3:Instances!AB3),"min", MIN(Instances!AB3:Instances!AB3),"max", MAX(Instances!AB3:Instances!AB3),"diff", MAX(Instances!AB3:Instances!AB3)-MIN(Instances!AB3:Instances!AB3))} -> 0 | AD3: {=_xlfn.SWITCH($A$2,"average", AVERAGE(Instances!AD3:Instances!AD3),"median", MEDIAN(Instances!AD3:Instances!AD3),"min", MIN(Instances!AD3:Instances!AD3),"max", MAX(Instances!AD3:Instances!AD3),"diff", MAX(Instances!AD3:Instances!AD3)-MIN(Instances!AD3:Instances!AD3))} -> 0 | AE3: {=_xlfn.SWITCH($A$2,"average", AVERAGE(Instances!AE3:Instances!AE3),"median", MEDIAN(Instances!AE3:Instances!AE3),"min", MIN(Instances!AE3:Instances!AE3),"max", MAX(Instances!AE3:Instances!AE3),"diff", MAX(Instances!AE3:Instances!AE3)-MIN(Instances!AE3:Instances!AE3))} -> 0 | AF3: =MIN($B3,$G3,$L3,$Q3,$V3,$AA3) -> 0 | AG3: =MIN($C3,$H3,$M3,$R3,$W3,$AB3) -> 0 | AH3: =MIN($E3,$J3,$O3,$T3,$Y3,$AD3) -> 0 | AI3: =MIN($F3,$K3,$P3,$U3,$Z3,$AE3) -> 0 | AJ3: =MEDIAN($B3,$G3,$L3,$Q3,$V3,$AA3) -> 0 | AK3: =MEDIAN($C3,$H3,$M3,$R3,$W3,$AB3) -> 0 | AL3: =MEDIAN($E3,$J3,$O3,$T3,$Y3,$AD3) -> 0 | AM3: =MEDIAN($F3,$K3,$P3,$U3,$Z3,$AE3) -> 0 | AN3: =MAX($B3,$G3,$L3,$Q3,$V3,$AA3) -> 0 | AO3: =MAX($C3,$H3,$M3,$R3,$W3,$AB3) -> 0 | AP3: =MAX($E3,$J3,$O3,$T3,$Y3,$AD3) -> 0 | AQ3: =MAX($F3,$K3,$P3,$U3,$Z3,$AE3) -> 0
A4: instances/size-10 | B4: {=_xlfn.SWITCH($A$2,"average", AVERAGE(Instances!B4:Instances!B4),"median", MEDIAN(Instances!B4:Instances!B4),"min", MIN(Instances!B4:Instances!B4),"max", MAX(Instances!B4:Instances!B4),"diff", MAX(Instances!B4:Instances!B4)-MIN(Instances!B4:Instances!B4))} -> 0 | C4: {=_xlfn.SWITCH($A$2,"average", AVERAGE(Instances!C4:Instances!C4),"median", MEDIAN(Instances!C4:Instances!C4),"min", MIN(Instances!C4:Instances!C4),"max", MAX(Instances!C4:Instances!C4),"diff", MAX(Instances!C4:Instances!C4)-MIN(Instances!C4:Instances!C4))} -> 0 | E4: {=_xlfn.SWITCH($A$2,"average", AVERAGE(Instances!E4:Instances!E4),"median", MEDIAN(Instances!E4:Instances!E4),"min", MIN(Instances!E4:Instances!E4),"max", MAX(Instances!E4:Instances!E4),"diff", MAX(Instances!E4:Instances!E4)-MIN(Instances!E4:Instances!E4))} -> 0 | F4: {=_xlfn.SWITCH($A$2,"average", AVERAGE(Instances!F4:Instances!F4),"median", MEDIAN(Instances!F4:Instances!F4),"min", MIN(Instances!F4:Instances!F4),"max", MAX(Instances!F4:Instances!F4),"diff", MAX(Instances!F4:Instances!F4)-MIN(Instances!F4:Instances!F4))} -> 0 | G4: {=_xlfn.SWITCH($A$2,"average", AVERAGE(Instances!G4:Instances!G4),"median", MEDIAN(Instances!G4:Instances!G4),"min", MIN(Instances!G4:Instances!G4),"max", MAX(Instances!G4:Instances!G4),"diff", MAX(Instances!G4:Instances!G4)-MIN(Instances!G4:Instances!G4))} -> 0 | H4: {=_xlfn.SWITCH($A$2,"average", AVERAGE(Instances!H4:Instances!H4),"median", MEDIAN(Instances!H4:Instances!H4),"min", MIN(Instances!H4:Instances!H4),"max", MAX(Instances!H4:Instances!H4),"diff", MAX(Instances!H4:Instances!H4)-MIN(Instances!H4:Instances!H4))} -> 0 | J4: {=_xlfn.SWITCH($A$2,"average", AVERAGE(Instances!J4:Instances!J4),"median", MEDIAN(Instances!J4:Instances!J4),"min", MIN(Instances!J4:Instances!J4),"max", MAX(Instances!J4:Instances!J4),"diff", MAX(Instances!J4:Instances!J4)-MIN(Instances!J4:Instances!J4))} -> 0 | K4: {=_xlfn.SWITCH($A$2,"average", AVERAGE(Instances!K4:Instances!K4),"median", MEDIAN(Instances!K4:Instances!K4),"min", MIN(Instances!K4:Instances!K4),"max", MAX(Instances!K4:Instances!K4),"diff", MAX(Instances!K4:Instances!K4)-MIN(Instances!K4:Instances!K4))} -> 0 | L4: {=_xlfn.SWITCH($A$2,"average", AVERAGE(Instances!L4:Instances!L4),"median", MEDIAN(Instances!L4:Instances!L4),"min", MIN(Instances!L4:Instances!L4),"max", MAX(Instances!L4:Instances!L4),"diff", MAX(Instances!L4:Instances!L4)-MIN(Instances!L4:Instances!L4))} -> 0 | M4: {=_xlfn.SWITCH($A$2,"average", AVERAGE(Instances!M4:Instances!M4),"median", MEDIAN(Instances!M4:Instances!M4),"min", MIN(Instances!M4:Instances!M4),"max", MAX(Instances!M4:Instances!M4),"diff", MAX(Instances!M4:Instances!M4)-MIN(Instances!M4:Instances!M4))} -> 0 | O4: {=_xlfn.SWITCH($A$2,"average", AVERAGE(Instances!O4:Instances!O4),"median", MEDIAN(Instances!O4:Instances!O4),"min", MIN(Instances!O4:Instances!O4),"max", MAX(Instances!O4:Instances!O4),"diff", MAX(Instances!O4:Instances!O4)-MIN(Instances!O4:Instances!O4))} -> 0 | P4: {=_xlfn.SWITCH($A$2,"average", AVERAGE(Instances!P4:Instances!P4),"median", MEDIAN(Instances!P4:Instances!P4),"min", MIN(Instances!P4:Instances!P4),"max", MAX(Instances!P4:Instances!P4),"diff", MAX(Instances!P4:Instances!P4)-MIN(Instances!P4:Instances!P4))} -> 0 | Q4: {=_xlfn.SWITCH($A$2,"average", AVERAGE(Instances!Q4:Instances!Q4),"median", MEDIAN(Instances!Q4:Instances!Q4),"min", MIN(Instances!Q4:Instances!Q4),"max", MAX(Instances!Q4:Instances!Q4),"diff", MAX(Instances!Q4:Instances!Q4)-MIN(Instances!Q4:Instances!Q4))} -> 0 | R4: {=_xlfn.SWITCH($A$2,"average", AVERAGE(Instances!R4:Instances!R4),"median", MEDIAN(Instances!R4:Instances!R4),"min", MIN(Instances!R4:Instances!R4),"max", MAX(Instances!R4:Instances!R4),"diff", MAX(Instances!R4:Instances!R4)-MIN(Instances!R4:Instances!R4))} -> 0 | T4: {=_xlfn.SWITCH($A$2,"average", AVERAGE(Instances!T4:Instances!T4),"median", MEDIAN(Instances!T4:Instances!T4),"min", MIN(Instances!T4:Instances!T4),"max", MAX(Instances!T4:Instances!T4),"diff", MAX(Instances!T4:Instances!T4)-MIN(Instances!T4:Instances!T4))} -> 0 | U4: {=_xlfn.SWITCH($A$2,"average", AVERAGE(Instances!U4:Instances!U4),"median", MEDIAN(Instances!U4:Instances!U4),"min", MIN(Instances!U4:Instances!U4),"max", MAX(Instances!U4:Instances!U4),"diff", MAX(Instances!U4:Instances!U4)-MIN(Instances!U4:Instances!U4))} -> 0 | V4: {=_xlfn.SWITCH($A$2,"average", AVERAGE(Instances!V4:Instances!V4),"median", MEDIAN(Instances!V4:Instances!V4),"min", MIN(Instances!V4:Instances!V4),"max", MAX(Instances!V4:Instances!V4),"diff", MAX(Instances!V4:Instances!V4)-MIN(Instances!V4:Instances!V4))} -> 0 | W4: {=_xlfn.SWITCH($A$2,"average", AVERAGE(Instances!W4:Instances!W4),"median", MEDIAN(Instances!W4:Instances!W4),"min", MIN(Instances!W4:Instances!W4),"max", MAX(Instances!W4:Instances!W4),"diff", MAX(Instances!W4:Instances!W4)-MIN(Instances!W4:Instances!W4))} -> 0 | Y4: {=_xlfn.SWITCH($A$2,"average", AVERAGE(Instances!Y4:Instances!Y4),"median", MEDIAN(Instances!Y4:Instances!Y4),"min", MIN(Instances!Y4:Instances!Y4),"max", MAX(Instances!Y4:Instances!Y4),"diff", MAX(Instances!Y4:Instances!Y4)-MIN(Instances!Y4:Instances!Y4))} -> 0 | Z4: {=_xlfn.SWITCH($A$2,"average", AVERAGE(Instances!Z4:Instances!Z4),"median", MEDIAN(Instances!Z4:Instances!Z4),"min", MIN(Instances!Z4:Instances!Z4),"max", MAX(Instances!Z4:Instances!Z4),"diff", MAX(Instances!Z4:Instances!Z4)-MIN(Instances!Z4:Instances!Z4))} -> 0 | AA4: {=_xlfn.SWITCH($A$2,"average", AVERAGE(Instances!AA4:Instances!AA4),"median", MEDIAN(Instances!AA4:Instances!AA4),"min", MIN(Instances!AA4:Instances!AA4),"max", MAX(Instances!AA4:Instances!AA4),"diff", MAX(Instances!AA4:Instances!AA4)-MIN(Instances!AA4:Instances!AA4))} -> 0 | AB4: {=_xlfn.SWITCH($A$2,"average", AVERAGE(Instances!AB4:Instances!AB4),"median", MEDIAN(Instances!AB4:Instances!AB4),"min", MIN(Instances!AB4:Instances!AB4),"max", MAX(Instances!AB4:Instances!AB4),"diff", MAX(Instances!AB4:Instances!AB4)-MIN(Instances!AB4:Instances!AB4))} -> 0 | AD4: {=_xlfn.SWITCH($A$2,"average", AVERAGE(Instances!AD4:Instances!AD4),"median", MEDIAN(Instances!AD4:Instances!AD4),"min", MIN(Instances!AD4:Instances!AD4),"max", MAX(Instances!AD4:Instances!AD4),"diff", MAX(Instances!AD4:Instances!AD4)-MIN(Instances!AD4:Instances!AD4))} -> 0 | AE4: {=_xlfn.SWITCH($A$2,"average", AVERAGE(Instances!AE4:Instances!AE4),"median", MEDIAN(Instances!AE4:Instances!AE4),"min", MIN(Instances!AE4:Instances!AE4),"max", MAX(Instances!AE4:Instances!AE4),"diff", MAX(Instances!AE4:Instances!AE4)-MIN(Instances!AE4:Instances!AE4))} -> 0 | AF4: =MIN($B4,$G4,$L4,$Q4,$V4,$AA4) -> 0 | AG4: =MIN($C4,$H4,$M4,$R4,$W4,$AB4) -> 0 | AH4: =MIN($E4,$J4,$O4,$T4,$Y4,$AD4) -> 0 | AI4: =MIN($F4,$K4,$P4,$U4,$Z4,$AE4) -> 0 | AJ4: =MEDIAN($B4,$G4,$L4,$Q4,$V4,$AA4) -> 0 | AK4: =MEDIAN($C4,$H4,$M4,$R4,$W4,$AB4) -> 0 | AL4: =MEDIAN($E4,$J4,$O4,$T4,$Y4,$AD4) -> 0 | AM4: =MEDIAN($F4,$K4,$P4,$U4,$Z4,$AE4) -> 0 | AN4: =MAX($B4,$G4,$L4,$Q4,$V4,$AA4) -> 0 | AO4: =MAX($C4,$H4,$M4,$R4,$W4,$AB4) -> 0 | AP4: =MAX($E4,$J4,$O4,$T4,$Y4,$AD4) -> 0 | AQ4: =MAX($F4,$K4,$P4,$U4,$Z4,$AE4) -> 0
A5: instances/size-5 | B5: {=_xlfn.SWITCH($A$2,"average", AVERAGE(Instances!B5:Instances!B5),"median", MEDIAN(Instances!B5:Instances!B5),"min", MIN(Instances!B5:Instances!B5),"max", MAX(Instances!B5:Instances!B5),"diff", MAX(Instances!B5:Instances!B5)-MIN(Instances!B5:Instances!B5))} -> 0 | C5: {=_xlfn.SWITCH($A$2,"average", AVERAGE(Instances!C5:Instances!C5),"median", MEDIAN(Instances!C5:Instances!C5),"min", MIN(Instances!C5:Instances!C5),"max", MAX(Instances!C5:Instances!C5),"diff", MAX(Instances!C5:Instances!C5)-MIN(Instances!C5:Instances!C5))} -> 0 | E5: {=_xlfn.SWITCH($A$2,"average", AVERAGE(Instances!E5:Instances!E5),"median", MEDIAN(Instances!E5:Instances!E5),"min", MIN(Instances!E5:Instances!E5),"max", MAX(Instances!E5:Instances!E5),"diff", MAX(Instances!E5:Instances!E5)-MIN(Instances!E5:Instances!E5))} -> 0 | F5: {=_xlfn.SWITCH($A$2,"average", AVERAGE(Instances!F5:Instances!F5),"median", MEDIAN(Instances!F5:Instances!F5),"min", MIN(Instances!F5:Instances!F5),"max", MAX(Instances!F5:Instances!F5),"diff", MAX(Instances!F5:Instances!F5)-MIN(Instances!F5:Instances!F5))} -> 0 | G5: {=_xlfn.SWITCH($A$2,"average", AVERAGE(Instances!G5:Instances!G5),"median", MEDIAN(Instances!G5:Instances!G5),"min", MIN(Instances!G5:Instances!G5),"max", MAX(Instances!G5:Instances!G5),"diff", MAX(Instances!G5:Instances!G5)-MIN(Instances!G5:Instances!G5))} -> 0 | H5: {=_xlfn.SWITCH($A$2,"average", AVERAGE(Instances!H5:Instances!H5),"median", MEDIAN(Instances!H5:Instances!H5),"min", MIN(Instances!H5:Instances!H5),"max", MAX(Instances!H5:Instances!H5),"diff", MAX(Instances!H5:Instances!H5)-MIN(Instances!H5:Instances!H5))} -> 0 | J5: {=_xlfn.SWITCH($A$2,"average", AVERAGE(Instances!J5:Instances!J5),"median", MEDIAN(Instances!J5:Instances!J5),"min", MIN(Instances!J5:Instances!J5),"max", MAX(Instances!J5:Instances!J5),"diff", MAX(Instances!J5:Instances!J5)-MIN(Instances!J5:Instances!J5))} -> 0 | K5: {=_xlfn.SWITCH($A$2,"average", AVERAGE(Instances!K5:Instances!K5),"median", MEDIAN(Instances!K5:Instances!K5),"min", MIN(Instances!K5:Instances!K5),"max", MAX(Instances!K5:Instances!K5),"diff", MAX(Instances!K5:Instances!K5)-MIN(Instances!K5:Instances!K5))} -> 0 | L5: {=_xlfn.SWITCH($A$2,"average", AVERAGE(Instances!L5:Instances!L5),"median", MEDIAN(Instances!L5:Instances!L5),"min", MIN(Instances!L5:Instances!L5),"max", MAX(Instances!L5:Instances!L5),"diff", MAX(Instances!L5:Instances!L5)-MIN(Instances!L5:Instances!L5))} -> 0 | M5: {=_xlfn.SWITCH($A$2,"average", AVERAGE(Instances!M5:Instances!M5),"median", MEDIAN(Instances!M5:Instances!M5),"min", MIN(Instances!M5:Instances!M5),"max", MAX(Instances!M5:Instances!M5),"diff", MAX(Instances!M5:Instances!M5)-MIN(Instances!M5:Instances!M5))} -> 0 | O5: {=_xlfn.SWITCH($A$2,"average", AVERAGE(Instances!O5:Instances!O5),"median", MEDIAN(Instances!O5:Instances!O5),"min", MIN(Instances!O5:Instances!O5),"max", MAX(Instances!O5:Instances!O5),"diff", MAX(Instances!O5:Instances!O5)-MIN(Instances!O5:Instances!O5))} -> 0 | P5: {=_xlfn.SWITCH($A$2,"average", AVERAGE(Instances!P5:Instances!P5),"median", MEDIAN(Instances!P5:Instances!P5),"min", MIN(Instances!P5:Instances!P5),"max", MAX(Instances!P5:Instances!P5),"diff", MAX(Instances!P5:Instances!P5)-MIN(Instances!P5:Instances!P5))} -> 0 | Q5: {=_xlfn.SWITCH($A$2,"average", AVERAGE(Instances!Q5:Instances!Q5),"median", MEDIAN(Instances!Q5:Instances!Q5),"min", MIN(Instances!Q5:Instances!Q5),"max", MAX(Instances!Q5:Instances!Q5),"diff", MAX(Instances!Q5:Instances!Q5)-MIN(Instances!Q5:Instances!Q5))} -> 0 | R5: {=_xlfn.SWITCH($A$2,"average", AVERAGE(Instances!R5:Instances!R5),"median", MEDIAN(Instances!R5:Instances!R5),"min", MIN(Instances!R5:Instances!R5),"max", MAX(Instances!R5:Instances!R5),"diff", MAX(Instances!R5:Instances!R5)-MIN(Instances!R5:Instances!R5))} -> 0 | T5: {=_xlfn.SWITCH($A$2,"average", AVERAGE(Instances!T5:Instances!T5),"median", MEDIAN(Instances!T5:Instances!T5),"min", MIN(Instances!T5:Instances!T5),"max", MAX(Instances!T5:Instances!T5),"diff", MAX(Instances!T5:Instances!T5)-MIN(Instances!T5:Instances!T5))} -> 0 | U5: {=_xlfn.SWITCH($A$2,"average", AVERAGE(Instances!U5:Instances!U5),"median", MEDIAN(Instances!U5:Instances!U5),"min", MIN(Instances!U5:Instances!U5),"max", MAX(Instances!U5:Instances!U5),"diff", MAX(Instances!U5:Instances!U5)-MIN(Instances!U5:Instances!U5))} -> 0 | V5: {=_xlfn.SWITCH($A$2,"average", AVERAGE(Instances!V5:Instances!V5),"median", MEDIAN(Instances!V5:Instances!V5),"min", MIN(Instances!V5:Instances!V5),"max", MAX(Instances!V5:Instances!V5),"diff", MAX(Instances!V5:Instances!V5)-MIN(Instances!V5:Instances!V5))} -> 0 | W5: {=_xlfn.SWITCH($A$2,"average", AVERAGE(Instances!W5:Instances!W5),"median", MEDIAN(Instances!W5:Instances!W5),"min", MIN(Instances!W5:Instances!W5),"max", MAX(Instances!W5:Instances!W5),"diff", MAX(Instances!W5:Instances!W5)-MIN(Instances!W5:Instances!W5))} -> 0 | Y5: {=_xlfn.SWITCH($A$2,"average", AVERAGE(Instances!Y5:Instances!Y5),"median", MEDIAN(Instances!Y5:Instances!Y5),"min", MIN(Instances!Y5:Instances!Y5),"max", MAX(Instances!Y5:Instances!Y5),"diff", MAX(Instances!Y5:Instances!Y5)-MIN(Instances!Y5:Instances!Y5))} -> 0 | Z5: {=_xlfn.SWITCH($A$2,"average", AVERAGE(Instances!Z5:Instances!Z5),"median", MEDIAN(Instances!Z5:Instances!Z5),"min", MIN(Instances!Z5:Instances!Z5),"max", MAX(Instances!Z5:Instances!Z5),"diff", MAX(Instances!Z5:Instances!Z5)-MIN(Instances!Z5:Instances!Z5))} -> 0 | AA5: {=_xlfn.SWITCH($A$2,"average", AVERAGE(Instances!AA5:Instances!AA5),"median", MEDIAN(Instances!AA5:Instances!AA5),"min", MIN(Instances!AA5:Instances!AA5),"max", MAX(Instances!AA5:Instances!AA5),"diff", MAX(Instances!AA5:Instances!AA5)-MIN(Instances!AA5:Instances!AA5))} -> 0 | AB5: {=_xlfn.SWITCH($A$2,"average", AVERAGE(Instances!AB5:Instances!AB5),"median", MEDIAN(Instances!AB5:Instances!AB5),"min", MIN(Instances!AB5:Instances!AB5),"max", MAX(Instances!AB5:Instances!AB5),"diff", MAX(Instances!AB5:Instances!AB5)-MIN(Instances!AB5:Instances!AB5))} -> 0 | AD5: {=_xlfn.SWITCH($A$2,"average", AVERAGE(Instances!AD5:Instances!AD5),"median", MEDIAN(Instances!AD5:Instances!AD5),"min", MIN(Instances!AD5:Instances!AD5),"max", MAX(Instances!AD5:Instances!AD5),"diff", MAX(Instances!AD5:Instances!AD5)-MIN(Instances!AD5:Instances!AD5))} -> 0 | AE5: {=_xlfn.SWITCH($A$2,"average", AVERAGE(Instances!AE5:Instances!AE5),"median", MEDIAN(Instances!AE5:Instances!AE5),"min", MIN(Instances!AE5:Instances!AE5),"max", MAX(Instances!AE5:Instances!AE5),"diff", MAX(Instances!AE5:Instances!AE5)-MIN(Instances!AE5:Instances!AE5))} -> 0 | AF5: =MIN($B5,$G5,$L5,$Q5,$V5,$AA5) -> 0 | AG5: =MIN($C5,$H5,$M5,$R5,$W5,$AB5) -> 0 | AH5: =MIN($E5,$J5,$O5,$T5,$Y5,$AD5) -> 0 | AI5: =MIN($F5,$K5,$P5,$U5,$Z5,$AE5) -> 0 | AJ5: =MEDIAN($B5,$G5,$L5,$Q5,$V5,$AA5) -> 0 | AK5: =MEDIAN($C5,$H5,$M5,$R5,$W5,$AB5) -> 0 | AL5: =MEDIAN($E5,$J5,$O5,$T5,$Y5,$AD5) -> 0 | AM5: =MEDIAN($F5,$K5,$P5,$U5,$Z5,$AE5) -> 0 | AN5: =MAX($B5,$G5,$L5,$Q5,$V5,$AA5) -> 0 | AO5: =MAX($C5,$H5,$M5,$R5,$W5,$AB5) -> 0 | AP5: =MAX($E5,$J5,$O5,$T5,$Y5,$AD5) -> 0 | AQ5: =MAX($F5,$K5,$P5,$U5,$Z5,$AE5) -> 0
A6: instances/size-7 | B6: {=_xlfn.SWITCH($A$2,"average", AVERAGE(Instances!B6:Instances!B6),"median", MEDIAN(Instances!B6:Instances!B6),"min", MIN(Instances!B6:Instances!B6),"max", MAX(Instances!B6:Instances!B6),"diff", MAX(Instances!B6:Instances!B6)-MIN(Instances!B6:Instances!B6))} -> 0 | C6: {=_xlfn.SWITCH($A$2,"average", AVERAGE(Instances!C6:Instances!C6),"median", MEDIAN(Instances!C6:Instances!C6),"min", MIN(Instances!C6:Instances!C6),"max", MAX(Instances!C6:Instances!C6),"diff", MAX(Instances!C6:Instances!C6)-MIN(Instances!C6:Instances!C6))} -> 0 | E6: {=_xlfn.SWITCH($A$2,"average", AVERAGE(Instances!E6:Instances!E6),"median", MEDIAN(Instances!E6:Instances!E6),"min", MIN(Instances!E6:Instances!E6),"max", MAX(Instances!E6:Instances!E6),"diff", MAX(Instances!E6:Instances!E6)-MIN(Instances!E6:Instances!E6))} -> 0 | F6: {=_xlfn.SWITCH($A$2,"average", AVERAGE(Instances!F6:Instances!F6),"median", MEDIAN(Instances!F6:Instances!F6),"min", MIN(Instances!F6:Instances!F6),"max", MAX(Instances!F6:Instances!F6),"diff", MAX(Instances!F6:Instances!F6)-MIN(Instances!F6:Instances!F6))} -> 0 | G6: {=_xlfn.SWITCH($A$2,"average", AVERAGE(Instances!G6:Instances!G6),"median", MEDIAN(Instances!G6:Instances!G6),"min", MIN(Instances!G6:Instances!G6),"max", MAX(Instances!G6:Instances!G6),"diff", MAX(Instances!G6:Instances!G6)-MIN(Instances!G6:Instances!G6))} -> 0 | H6: {=_xlfn.SWITCH($A$2,"average", AVERAGE(Instances!H6:Instances!H6),"median", MEDIAN(Instances!H6:Instances!H6),"min", MIN(Instances!H6:Instances!H6),"max", MAX(Instances!H6:Instances!H6),"diff", MAX(Instances!H6:Instances!H6)-MIN(Instances!H6:Instances!H6))} -> 0 | J6: {=_xlfn.SWITCH($A$2,"average", AVERAGE(Instances!J6:Instances!J6),"median", MEDIAN(Instances!J6:Instances!J6),"min", MIN(Instances!J6:Instances!J6),"max", MAX(Instances!J6:Instances!J6),"diff", MAX(Instances!J6:Instances!J6)-MIN(Instances!J6:Instances!J6))} -> 0 | K6: {=_xlfn.SWITCH($A$2,"average", AVERAGE(Instances!K6:Instances!K6),"median", MEDIAN(Instances!K6:Instances!K6),"min", MIN(Instances!K6:Instances!K6),"max", MAX(Instances!K6:Instances!K6),"diff", MAX(Instances!K6:Instances!K6)-MIN(Instances!K6:Instances!K6))} -> 0 | L6: {=_xlfn.SWITCH($A$2,"average", AVERAGE(Instances!L6:Instances!L6),"median", MEDIAN(Instances!L6:Instances!L6),"min", MIN(Instances!L6:Instances!L6),"max", MAX(Instances!L6:Instances!L6),"diff", MAX(Instances!L6:Instances!L6)-MIN(Instances!L6:Instances!L6))} -> 0 | M6: {=_xlfn.SWITCH($A$2,"average", AVERAGE(Instances!M6:Instances!M6),"median", MEDIAN(Instances!M6:Instances!M6),"min", MIN(Instances!M6:Instances!M6),"max", MAX(Instances!M6:Instances!M6),"diff", MAX(Instances!M6:Instances!M6)-MIN(Instances!M6:Instances!M6))} -> 0 | O6: {=_xlfn.SWITCH($A$2,"average", AVERAGE(Instances!O6:Instances!O6),"median", MEDIAN(Instances!O6:Instances!O6),"min", MIN(Instances!O6:Instances!O6),"max", MAX(Instances!O6:Instances!O6),"diff", MAX(Instances!O6:Instances!O6)-MIN(Instances!O6:Instances!O6))} -> 0 | P6: {=_xlfn.SWITCH($A$2,"average", AVERAGE(Instances!P6:Instances!P6),"median", MEDIAN(Instances!P6:Instances!P6),"min", MIN(Instances!P6:Instances!P6),"max", MAX(Instances!P6:Instances!P6),"diff", MAX(Instances!P6:Instances!P6)-MIN(Instances!P6:Instances!P6))} -> 0 | Q6: {=_xlfn.SWITCH($A$2,"average", AVERAGE(Instances!Q6:Instances!Q6),"median", MEDIAN(Instances!Q6:Instances!Q6),"min", MIN(Instances!Q6:Instances!Q6),"max", MAX(Instances!Q6:Instances!Q6),"diff", MAX(Instances!Q6:Instances!Q6)-MIN(Instances!Q6:Instances!Q6))} -> 0 | R6: {=_xlfn.SWITCH($A$2,"average", AVERAGE(Instances!R6:Instances!R6),"median", MEDIAN(Instances!R6:Instances!R6),"min", MIN(Instances!R6:Instances!R6),"max", MAX(Instances!R6:Instances!R6),"diff", MAX(Instances!R6:Instances!R6)-MIN(Instances!R6:Instances!R6))} -> 0 | T6: {=_xlfn.SWITCH($A$2,"average", AVERAGE(Instances!T6:Instances!T6),"median", MEDIAN(Instances!T6:Instances!T6),"min", MIN(Instances!T6:Instances!T6),"max", MAX(Instances!T6:Instances!T6),"diff", MAX(Instances!T6:Instances!T6)-MIN(Instances!T6:Instances!T6))} -> 0 | U6: {=_xlfn.SWITCH($A$2,"average", AVERAGE(Instances!U6:Instances!U6),"median", MEDIAN(Instances!U6:Instances!U6),"min", MIN(Instances!U6:Instances!U6),"max", MAX(Instances!U6:Instances!U6),"diff", MAX(Instances!U6:Instances!U6)-MIN(Instances!U6:Instances!U6))} -> 0 | V6: {=_xlfn.SWITCH($A$2,"average", AVERAGE(Instances!V6:Instances!V6),"median", MEDIAN(Instances!V6:Instances!V6),"min", MIN(Instances!V6:Instances!V6),"max", MAX(Instances!V6:Instances!V6),"diff", MAX(Instances!V6:Instances!V6)-MIN(Instances!V6:Instances!V6))} -> 0 | W6: {=_xlfn.SWITCH($A$2,"average", AVERAGE(Instances!W6:Instances!W6),"median", MEDIAN(Instances!W6:Instances!W6),"min", MIN(Instances!W6:Instances!W6),"max", MAX(Instances!W6:Instances!W6),"diff", MAX(Instances!W6:Instances!W6)-MIN(Instances!W6:Instances!W6))} -> 0 | Y6: {=_xlfn.SWITCH($A$2,"average", AVERAGE(Instances!Y6:Instances!Y6),"median", MEDIAN(Instances!Y6:Instances!Y6),"min", MIN(Instances!Y6:Instances!Y6),"max", MAX(Instances!Y6:Instances!Y6),"diff", MAX(Instances!Y6:Instances!Y6)-MIN(Instances!Y6:Instances!Y6))} -> 0 | Z6: {=_xlfn.SWITCH($A$2,"average", AVERAGE(Instances!Z6:Instances!Z6),"median", MEDIAN(Instances!Z6:Instances!Z6),"min", MIN(Instances!Z6:Instances!Z6),"max", MAX(Instances!Z6:Instances!Z6),"diff", MAX(Instances!Z6:Instances!Z6)-MIN(Instances!Z6:Instances!Z6))} -> 0 | AA6: {=_xlfn.SWITCH($A$2,"average", AVERAGE(Instances!AA6:Instances!AA6),"median", MEDIAN(Instances!AA6:Instances!AA6),"min", MIN(Instances!AA6:Instances!AA6),"max", MAX(Instances!AA6:Instances!AA6),"diff", MAX(Instances!AA6:Instances!AA6)-MIN(Instances!AA6:Instances!AA6))} -> 0 | AB6: {=_xlfn.SWITCH($A$2,"average", AVERAGE(Instances!AB6:Instances!AB6),"median", MEDIAN(Instances!AB6:Instances!AB6),"min", MIN(Instances!AB6:Instances!AB6),"max", MAX(Instances!AB6:Instances!AB6),"diff", MAX(Instances!AB6:Instances!AB6)-MIN(Instances!AB6:Instances!AB6))} -> 0 | AD6: {=_xlfn.SWITCH($A$2,"average", AVERAGE(Instances!AD6:Instances!AD6),"median", MEDIAN(Instances!AD6:Instances!AD6),"min", MIN(Instances!AD6:Instances!AD6),"max", MAX(Instances!AD6:Instances!AD6),"diff", MAX(Instances!AD6:Instances!AD6)-MIN(Instances!AD6:Instances!AD6))} -> 0 | AE6: {=_xlfn.SWITCH($A$2,"average", AVERAGE(Instances!AE6:Instances!AE6),"median", MEDIAN(Instances!AE6:Instances!AE6),"min", MIN(Instances!AE6:Instances!AE6),"max", MAX(Instances!AE6:Instances!AE6),"diff", MAX(Instances!AE6:Instances!AE6)-MIN(Instances!AE6:Instances!AE6))} -> 0 | AF6: =MIN($B6,$G6,$L6,$Q6,$V6,$AA6) -> 0 | AG6: =MIN($C6,$H6,$M6,$R6,$W6,$AB6) -> 0 | AH6: =MIN($E6,$J6,$O6,$T6,$Y6,$AD6) -> 0 | AI6: =MIN($F6,$K6,$P6,$U6,$Z6,$AE6) -> 0 | AJ6: =MEDIAN($B6,$G6,$L6,$Q6,$V6,$AA6) -> 0 | AK6: =MEDIAN($C6,$H6,$M6,$R6,$W6,$AB6) -> 0 | AL6: =MEDIAN($E6,$J6,$O6,$T6,$Y6,$AD6) -> 0 | AM6: =MEDIAN($F6,$K6,$P6,$U6,$Z6,$AE6) -> 0 | AN6: =MAX($B6,$G6,$L6,$Q6,$V6,$AA6) -> 0 | AO6: =MAX($C6,$H6,$M6,$R6,$W6,$AB6) -> 0 | AP6: =MAX($E6,$J6,$O6,$T6,$Y6,$AD6) -> 0 | AQ6: =MAX($F6,$K6,$P6,$U6,$Z6,$AE6) -> 0
A8: SUM | B8: =SUM(B$3:B$6) -> 0 | C8: =SUM(C$3:C$6) -> 0 | E8: =SUM(E$3:E$6) -> 0 | F8: =SUM(F$3:F$6) -> 0 | G8: =SUM(G$3:G$6) -> 0 | H8: =SUM(H$3:H$6) -> 0 | J8: =SUM(J$3:J$6) -> 0 | K8: =SUM(K$3:K$6) -> 0 | L8: =SUM(L$3:L$6) -> 0 | M8: =SUM(M$3:M$6) -> 0 | O8: =SUM(O$3:O$6) -> 0 | P8: =SUM(P$3:P$6) -> 0 | Q8: =SUM(Q$3:Q$6) -> 0 | R8: =SUM(R$3:R$6) -> 0 | T8: =SUM(T$3:T$6) -> 0 | U8: =SUM(U$3:U$6) -> 0 | V8: =SUM(V$3:V$6) -> 0 | W8: =SUM(W$3:W$6) -> 0 | Y8: =SUM(Y$3:Y$6) -> 0 | Z8: =SUM(Z$3:Z$6) -> 0 | AA8: =SUM(AA$3:AA$6) -> 0 | AB8: =SUM(AB$3:AB$6) -> 0 | AD8: =SUM(AD$3:AD$6) -> 0 | AE8: =SUM(AE$3:AE$6) -> 0 | AF8: =SUM(AF$3:AF$6) -> 0 | AG8: =SUM(AG$3:AG$6) -> 0 | AH8: =SUM(AH$3:AH$6) -> 0 | AI8: =SUM(AI$3:AI$6) -> 0 | AJ8: =SUM(AJ$3:AJ$6) -> 0 | AK8: =SUM(AK$3:AK$6) -> 0 | ... AQ8: =SUM(AQ$3:AQ$6) -> 0
A9: AVG | B9: =AVERAGE(B$3:B$6) -> 0 | C9: =AVERAGE(C$3:C$6) -> 0 | E9: =AVERAGE(E$3:E$6) -> 0 | F9: =AVERAGE(F$3:F$6) -> 0 | G9: =AVERAGE(G$3:G$6) -> 0 | H9: =AVERAGE(H$3:H$6) -> 0 | J9: =AVERAGE(J$3:J$6) -> 0 | K9: =AVERAGE(K$3:K$6) -> 0 | L9: =AVERAGE(L$3:L$6) -> 0 | M9: =AVERAGE(M$3:M$6) -> 0 | O9: =AVERAGE(O$3:O$6) -> 0 | P9: =AVERAGE(P$3:P$6) -> 0 | Q9: =AVERAGE(Q$3:Q$6) -> 0 | R9: =AVERAGE(R$3:R$6) -> 0 | T9: =AVERAGE(T$3:T$6) -> 0 | U9: =AVERAGE(U$3:U$6) -> 0 | V9: =AVERAGE(V$3:V$6) -> 0 | W9: =AVERAGE(W$3:W$6) -> 0 | Y9: =AVERAGE(Y$3:Y$6) -> 0 | Z9: =AVERAGE(Z$3:Z$6) -> 0 | AA9: =AVERAGE(AA$3:AA$6) -> 0 | AB9: =AVERAGE(AB$3:AB$6) -> 0 | AD9: =AVERAGE(AD$3:AD$6) -> 0 | AE9: =AVERAGE(AE$3:AE$6) -> 0 | AF9: =AVERAGE(AF$3:AF$6) -> 0 | AG9: =AVERAGE(AG$3:AG$6) -> 0 | AH9: =AVERAGE(AH$3:AH$6) -> 0 | AI9: =AVERAGE(AI$3:AI$6) -> 0 | AJ9: =AVERAGE(AJ$3:AJ$6) -> 0 | AK9: =AVERAGE(AK$3:AK$6) -> 0 | ... AQ9: =AVERAGE(AQ$3:AQ$6) -> 0
A10: DEV | B10: =STDEV(B$3:B$6) -> 0 | C10: =STDEV(C$3:C$6) -> 0 | E10: =STDEV(E$3:E$6) -> 0 | F10: =STDEV(F$3:F$6) -> 0 | G10: =STDEV(G$3:G$6) -> 0 | H10: =STDEV(H$3:H$6) -> 0 | J10: =STDEV(J$3:J$6) -> 0 | K10: =STDEV(K$3:K$6) -> 0 | L10: =STDEV(L$3:L$6) -> 0 | M10: =STDEV(M$3:M$6) -> 0 | O10: =STDEV(O$3:O$6) -> 0 | P10: =STDEV(P$3:P$6) -> 0 | Q10: =STDEV(Q$3:Q$6) -> 0 | R10: =STDEV(R$3:R$6) -> 0 | T10: =STDEV(T$3:T$6) -> 0 | U10: =STDEV(U$3:U$6) -> 0 | V10: =STDEV(V$3:V$6) -> 0 | W10: =STDEV(W$3:W$6) -> 0 | Y10: =STDEV(Y$3:Y$6) -> 0 | Z10: =STDEV(Z$3:Z$6) -> 0 | AA10: =STDEV(AA$3:AA$6) -> 0 | AB10: =STDEV(AB$3:AB$6) -> 0 | AD10: =STDEV(AD$3:AD$6) -> 0 | AE10: =STDEV(AE$3:AE$6) -> 0 | AF10: =STDEV(AF$3:AF$6) -> 0 | AG10: =STDEV(AG$3:AG$6) -> 0 | AH10: =STDEV(AH$3:AH$6) -> 0 | AI10: =STDEV(AI$3:AI$6) -> 0 | AJ10: =STDEV(AJ$3:AJ$6) -> 0 | AK10: =STDEV(AK$3:AK$6) -> 0 | ... AQ10: =STDEV(AQ$3:AQ$6) -> 0
A11: DST | B11: =SUMPRODUCT(--(B$3:B$6-$AF$3:$AF$6)^2)^0.5 -> 0 | C11: =SUMPRODUCT(--(C$3:C$6-$AG$3:$AG$6)^2)^0.5 -> 0 | E11: =SUMPRODUCT(--(E$3:E$6-$AH$3:$AH$6)^2)^0.5 -> 0 | F11: =SUMPRODUCT(--(F$3:F$6-$AI$3:$AI$6)^2)^0.5 -> 0 | G11: =SUMPRODUCT(--(G$3:G$6-$AF$3:$AF$6)^2)^0.5 -> 0 | H11: =SUMPRODUCT(--(H$3:H$6-$AG$3:$AG$6)^2)^0.5 -> 0 | J11: =SUMPRODUCT(--(J$3:J$6-$AH$3:$AH$6)^2)^0.5 -> 0 | K11: =SUMPRODUCT(--(K$3:K$6-$AI$3:$AI$6)^2)^0.5 -> 0 | L11: =SUMPRODUCT(--(L$3:L$6-$AF$3:$AF$6)^2)^0.5 -> 0 | M11: =SUMPRODUCT(--(M$3:M$6-$AG$3:$AG$6)^2)^0.5 -> 0 | O11: =SUMPRODUCT(--(O$3:O$6-$AH$3:$AH$6)^2)^0.5 -> 0 | P11: =SUMPRODUCT(--(P$3:P$6-$AI$3:$AI$6)^2)^0.5 -> 0 | Q11: =SUMPRODUCT(--(Q$3:Q$6-$AF$3:$AF$6)^2)^0.5 -> 0 | R11: =SUMPRODUCT(--(R$3:R$6-$AG$3:$AG$6)^2)^0.5 -> 0 | T11: =SUMPRODUCT(--(T$3:T$6-$AH$3:$AH$6)^2)^0.5 -> 0 | U11: =SUMPRODUCT(--(U$3:U$6-$AI$3:$AI$6)^2)^0.5 -> 0 | V11: =SUMPRODUCT(--(V$3:V$6-$AF$3:$AF$6)^2)^0.5 -> 0 | W11: =SUMPRODUCT(--(W$3:W$6-$AG$3:$AG$6)^2)^0.5 -> 0 | Y11: =SUMPRODUCT(--(Y$3:Y$6-$AH$3:$AH$6)^2)^0.5 -> 0 | Z11: =SUMPRODUCT(--(Z$3:Z$6-$AI$3:$AI$6)^2)^0.5 -> 0 | AA11: =SUMPRODUCT(--(AA$3:AA$6-$AF$3:$AF$6)^2)^0.5 -> 0 | AB11: =SUMPRODUCT(--(AB$3:AB$6-$AG$3:$AG$6)^2)^0.5 -> 0 | AD11: =SUMPRODUCT(--(AD$3:AD$6-$AH$3:$AH$6)^2)^0.5 -> 0 | AE11: =SUMPRODUCT(--(AE$3:AE$6-$AI$3:$AI$6)^2)^0.5 -> 0
A12: BEST | B12: =SUMPRODUCT(NOT(ISBLANK(B$3:B$6))*(B$3:B$6=$AF$3:$AF$6)) -> 0 | C12: =SUMPRODUCT(NOT(ISBLANK(C$3:C$6))*(C$3:C$6=$AG$3:$AG$6)) -> 0 | E12: =SUMPRODUCT(NOT(ISBLANK(E$3:E$6))*(E$3:E$6=$AH$3:$AH$6)) -> 0 | F12: =SUMPRODUCT(NOT(ISBLANK(F$3:F$6))*(F$3:F$6=$AI$3:$AI$6)) -> 0 | G12: =SUMPRODUCT(NOT(ISBLANK(G$3:G$6))*(G$3:G$6=$AF$3:$AF$6)) -> 0 | H12: =SUMPRODUCT(NOT(ISBLANK(H$3:H$6))*(H$3:H$6=$AG$3:$AG$6)) -> 0 | J12: =SUMPRODUCT(NOT(ISBLANK(J$3:J$6))*(J$3:J$6=$AH$3:$AH$6)) -> 0 | K12: =SUMPRODUCT(NOT(ISBLANK(K$3:K$6))*(K$3:K$6=$AI$3:$AI$6)) -> 0 | L12: =SUMPRODUCT(NOT(ISBLANK(L$3:L$6))*(L$3:L$6=$AF$3:$AF$6)) -> 0 | M12: =SUMPRODUCT(NOT(ISBLANK(M$3:M$6))*(M$3:M$6=$AG$3:$AG$6)) -> 0 | O12: =SUMPRODUCT(NOT(ISBLANK(O$3:O$6))*(O$3:O$6=$AH$3:$AH$6)) -> 0 | P12: =SUMPRODUCT(NOT(ISBLANK(P$3:P$6))*(P$3:P$6=$AI$3:$AI$6)) -> 0 | Q12: =SUMPRODUCT(NOT(ISBLANK(Q$3:Q$6))*(Q$3:Q$6=$AF$3:$AF$6)) -> 0 | R12: =SUMPRODUCT(NOT(ISBLANK(R$3:R$6))*(R$3:R$6=$AG$3:$AG$6)) -> 0 | T12: =SUMPRODUCT(NOT(ISBLANK(T$3:T$6))*(T$3:T$6=$AH$3:$AH$6)) -> 0 | U12: =SUMPRODUCT(NOT(ISBLANK(U$3:U$6))*(U$3:U$6=$AI$3:$AI$6)) -> 0 | V12: =SUMPRODUCT(NOT(ISBLANK(V$3:V$6))*(V$3:V$6=$AF$3:$AF$6)) -> 0 | W12: =SUMPRODUCT(NOT(ISBLANK(W$3:W$6))*(W$3:W$6=$AG$3:$AG$6)) -> 0 | Y12: =SUMPRODUCT(NOT(ISBLANK(Y$3:Y$6))*(Y$3:Y$6=$AH$3:$AH$6)) -> 0 | Z12: =SUMPRODUCT(NOT(ISBLANK(Z$3:Z$6))*(Z$3:Z$6=$AI$3:$AI$6)) -> 0 | AA12: =SUMPRODUCT(NOT(ISBLANK(AA$3:AA$6))*(AA$3:AA$6=$AF$3:$AF$6)) -> 0 | AB12: =SUMPRODUCT(NOT(ISBLANK(AB$3:AB$6))*(AB$3:AB$6=$AG$3:$AG$6)) -> 0 | AD12: =SUMPRODUCT(NOT(ISBLANK(AD$3:AD$6))*(AD$3:AD$6=$AH$3:$AH$6)) -> 0 | AE12: =SUMPRODUCT(NOT(ISBLANK(AE$3:AE$6))*(AE$3:AE$6=$AI$3:$AI$6)) -> 0
A13: BETTER | B13: =SUMPRODUCT(NOT(ISBLANK(B$3:B$6))*(B$3:B$6<$AJ$3:$AJ$6)) -> 0 | C13: =SUMPRODUCT(NOT(ISBLANK(C$3:C$6))*(C$3:C$6<$AK$3:$AK$6)) -> 0 | E13: =SUMPRODUCT(NOT(ISBLANK(E$3:E$6))*(E$3:E$6<$AL$3:$AL$6)) -> 0 | F13: =SUMPRODUCT(NOT(ISBLANK(F$3:F$6))*(F$3:F$6<$AM$3:$AM$6)) -> 0 | G13: =SUMPRODUCT(NOT(ISBLANK(G$3:G$6))*(G$3:G$6<$AJ$3:$AJ$6)) -> 0 | H13: =SUMPRODUCT(NOT(ISBLANK(H$3:H$6))*(H$3:H$6<$AK$3:$AK$6)) -> 0 | J13: =SUMPRODUCT(NOT(ISBLANK(J$3:J$6))*(J$3:J$6<$AL$3:$AL$6)) -> 0 | K13: =SUMPRODUCT(NOT(ISBLANK(K$3:K$6))*(K$3:K$6<$AM$3:$AM$6)) -> 0 | L13: =SUMPRODUCT(NOT(ISBLANK(L$3:L$6))*(L$3:L$6<$AJ$3:$AJ$6)) -> 0 | M13: =SUMPRODUCT(NOT(ISBLANK(M$3:M$6))*(M$3:M$6<$AK$3:$AK$6)) -> 0 | O13: =SUMPRODUCT(NOT(ISBLANK(O$3:O$6))*(O$3:O$6<$AL$3:$AL$6)) -> 0 | P13: =SUMPRODUCT(NOT(ISBLANK(P$3:P$6))*(P$3:P$6<$AM$3:$AM$6)) -> 0 | Q13: =SUMPRODUCT(NOT(ISBLANK(Q$3:Q$6))*(Q$3:Q$6<$AJ$3:$AJ$6)) -> 0 | R13: =SUMPRODUCT(NOT(ISBLANK(R$3:R$6))*(R$3:R$6<$AK$3:$AK$6)) -> 0 | T13: =SUMPRODUCT(NOT(ISBLANK(T$3:T$6))*(T$3:T$6<$AL$3:$AL$6)) -> 0 | U13: =SUMPRODUCT(NOT(ISBLANK(U$3:U$6))*(U$3:U$6<$AM$3:$AM$6)) -> 0 | V13: =SUMPRODUCT(NOT(ISBLANK(V$3:V$6))*(V$3:V$6<$AJ$3:$AJ$6)) -> 0 | W13: =SUMPRODUCT(NOT(ISBLANK(W$3:W$6))*(W$3:W$6<$AK$3:$AK$6)) -> 0 | Y13: =SUMPRODUCT(NOT(ISBLANK(Y$3:Y$6))*(Y$3:Y$6<$AL$3:$AL$6)) -> 0 | Z13: =SUMPRODUCT(NOT(ISBLANK(Z$3:Z$6))*(Z$3:Z$6<$AM$3:$AM$6)) -> 0 | AA13: =SUMPRODUCT(NOT(ISBLANK(AA$3:AA$6))*(AA$3:AA$6<$AJ$3:$AJ$6)) -> 0 | AB13: =SUMPRODUCT(NOT(ISBLANK(AB$3:AB$6))*(AB$3:AB$6<$AK$3:$AK$6)) -> 0 | AD13: =SUMPRODUCT(NOT(ISBLANK(AD$3:AD$6))*(AD$3:AD$6<$AL$3:$AL$6)) -> 0 | AE13: =SUMPRODUCT(NOT(ISBLANK(AE$3:AE$6))*(AE$3:AE$6<$AM$3:$AM$6)) -> 0
A14: WORSE | B14: =SUMPRODUCT((NOT(ISBLANK(B$3:B$6))*(B$3:B$6>$AJ$3:$AJ$6))+ISBLANK(B$3:B$6)) -> 0 | C14: =SUMPRODUCT((NOT(ISBLANK(C$3:C$6))*(C$3:C$6>$AK$3:$AK$6))+ISBLANK(C$3:C$6)) -> 0 | E14: =SUMPRODUCT((NOT(ISBLANK(E$3:E$6))*(E$3:E$6>$AL$3:$AL$6))+ISBLANK(E$3:E$6)) -> 0 | F14: =SUMPRODUCT((NOT(ISBLANK(F$3:F$6))*(F$3:F$6>$AM$3:$AM$6))+ISBLANK(F$3:F$6)) -> 0 | G14: =SUMPRODUCT((NOT(ISBLANK(G$3:G$6))*(G$3:G$6>$AJ$3:$AJ$6))+ISBLANK(G$3:G$6)) -> 0 | H14: =SUMPRODUCT((NOT(ISBLANK(H$3:H$6))*(H$3:H$6>$AK$3:$AK$6))+ISBLANK(H$3:H$6)) -> 0 | J14: =SUMPRODUCT((NOT(ISBLANK(J$3:J$6))*(J$3:J$6>$AL$3:$AL$6))+ISBLANK(J$3:J$6)) -> 0 | K14: =SUMPRODUCT((NOT(ISBLANK(K$3:K$6))*(K$3:K$6>$AM$3:$AM$6))+ISBLANK(K$3:K$6)) -> 0 | L14: =SUMPRODUCT((NOT(ISBLANK(L$3:L$6))*(L$3:L$6>$AJ$3:$AJ$6))+ISBLANK(L$3:L$6)) -> 0 | M14: =SUMPRODUCT((NOT(ISBLANK(M$3:M$6))*(M$3:M$6>$AK$3:$AK$6))+ISBLANK(M$3:M$6)) -> 0 | O14: =SUMPRODUCT((NOT(ISBLANK(O$3:O$6))*(O$3:O$6>$AL$3:$AL$6))+ISBLANK(O$3:O$6)) -> 0 | P14: =SUMPRODUCT((NOT(ISBLANK(P$3:P$6))*(P$3:P$6>$AM$3:$AM$6))+ISBLANK(P$3:P$6)) -> 0 | Q14: =SUMPRODUCT((NOT(ISBLANK(Q$3:Q$6))*(Q$3:Q$6>$AJ$3:$AJ$6))+ISBLANK(Q$3:Q$6)) -> 0 | R14: =SUMPRODUCT((NOT(ISBLANK(R$3:R$6))*(R$3:R$6>$AK$3:$AK$6))+ISBLANK(R$3:R$6)) -> 0 | T14: =SUMPRODUCT((NOT(ISBLANK(T$3:T$6))*(T$3:T$6>$AL$3:$AL$6))+ISBLANK(T$3:T$6)) -> 0 | U14: =SUMPRODUCT((NOT(ISBLANK(U$3:U$6))*(U$3:U$6>$AM$3:$AM$6))+ISBLANK(U$3:U$6)) -> 0 | V14: =SUMPRODUCT((NOT(ISBLANK(V$3:V$6))*(V$3:V$6>$AJ$3:$AJ$6))+ISBLANK(V$3:V$6)) -> 0 | W14: =SUMPRODUCT((NOT(ISBLANK(W$3:W$6))*(W$3:W$6>$AK$3:$AK$6))+ISBLANK(W$3:W$6)) -> 0 | Y14: =SUMPRODUCT((NOT(ISBLANK(Y$3:Y$6))*(Y$3:Y$6>$AL$3:$AL$6))+ISBLANK(Y$3:Y$6)) -> 0 | Z14: =SUMPRODUCT((NOT(ISBLANK(Z$3:Z$6))*(Z$3:Z$6>$AM$3:$AM$6))+ISBLANK(Z$3:Z$6)) -> 0 | AA14: =SUMPRODUCT((NOT(ISBLANK(AA$3:AA$6))*(AA$3:AA$6>$AJ$3:$AJ$6))+ISBLANK(AA$3:AA$6)) -> 0 | AB14: =SUMPRODUCT((NOT(ISBLANK(AB$3:AB$6))*(AB$3:AB$6>$AK$3:$AK$6))+ISBLANK(AB$3:AB$6)) -> 0 | AD14: =SUMPRODUCT((NOT(ISBLANK(AD$3:AD$6))*(AD$3:AD$6>$AL$3:$AL$6))+ISBLANK(AD$3:AD$6)) -> 0 | AE14: =SUMPRODUCT((NOT(ISBLANK(AE$3:AE$6))*(AE$3:AE$6>$AM$3:$AM$6))+ISBLANK(AE$3:AE$6)) -> 0
A15: WORST | B15: =SUMPRODUCT((NOT(ISBLANK(B$3:B$6))*(B$3:B$6=$AN$3:$AN$6))+ISBLANK(B$3:B$6)) -> 0 | C15: =SUMPRODUCT((NOT(ISBLANK(C$3:C$6))*(C$3:C$6=$AO$3:$AO$6))+ISBLANK(C$3:C$6)) -> 0 | E15: =SUMPRODUCT((NOT(ISBLANK(E$3:E$6))*(E$3:E$6=$AP$3:$AP$6))+ISBLANK(E$3:E$6)) -> 0 | F15: =SUMPRODUCT((NOT(ISBLANK(F$3:F$6))*(F$3:F$6=$AQ$3:$AQ$6))+ISBLANK(F$3:F$6)) -> 0 | G15: =SUMPRODUCT((NOT(ISBLANK(G$3:G$6))*(G$3:G$6=$AN$3:$AN$6))+ISBLANK(G$3:G$6)) -> 0 | H15: =SUMPRODUCT((NOT(ISBLANK(H$3:H$6))*(H$3:H$6=$AO$3:$AO$6))+ISBLANK(H$3:H$6)) -> 0 | J15: =SUMPRODUCT((NOT(ISBLANK(J$3:J$6))*(J$3:J$6=$AP$3:$AP$6))+ISBLANK(J$3:J$6)) -> 0 | K15: =SUMPRODUCT((NOT(ISBLANK(K$3:K$6))*(K$3:K$6=$AQ$3:$AQ$6))+ISBLANK(K$3:K$6)) -> 0 | L15: =SUMPRODUCT((NOT(ISBLANK(L$3:L$6))*(L$3:L$6=$AN$3:$AN$6))+ISBLANK(L$3:L$6)) -> 0 | M15: =SUMPRODUCT((NOT(ISBLANK(M$3:M$6))*(M$3:M$6=$AO$3:$AO$6))+ISBLANK(M$3:M$6)) -> 0 | O15: =SUMPRODUCT((NOT(ISBLANK(O$3:O$6))*(O$3:O$6=$AP$3:$AP$6))+ISBLANK(O$3:O$6)) -> 0 | P15: =SUMPRODUCT((NOT(ISBLANK(P$3:P$6))*(P$3:P$6=$AQ$3:$AQ$6))+ISBLANK(P$3:P$6)) -> 0 | Q15: =SUMPRODUCT((NOT(ISBLANK(Q$3:Q$6))*(Q$3:Q$6=$AN$3:$AN$6))+ISBLANK(Q$3:Q$6)) -> 0 | R15: =SUMPRODUCT((NOT(ISBLANK(R$3:R$6))*(R$3:R$6=$AO$3:$AO$6))+ISBLANK(R$3:R$6)) -> 0 | T15: =SUMPRODUCT((NOT(ISBLANK(T$3:T$6))*(T$3:T$6=$AP$3:$AP$6))+ISBLANK(T$3:T$6)) -> 0 | U15: =SUMPRODUCT((NOT(ISBLANK(U$3:U$6))*(U$3:U$6=$AQ$3:$AQ$6))+ISBLANK(U$3:U$6)) -> 0 | V15: =SUMPRODUCT((NOT(ISBLANK(V$3:V$6))*(V$3:V$6=$AN$3:$AN$6))+ISBLANK(V$3:V$6)) -> 0 | W15: =SUMPRODUCT((NOT(ISBLANK(W$3:W$6))*(W$3:W$6=$AO$3:$AO$6))+ISBLANK(W$3:W$6)) -> 0 | Y15: =SUMPRODUCT((NOT(ISBLANK(Y$3:Y$6))*(Y$3:Y$6=$AP$3:$AP$6))+ISBLANK(Y$3:Y$6)) -> 0 | Z15: =SUMPRODUCT((NOT(ISBLANK(Z$3:Z$6))*(Z$3:Z$6=$AQ$3:$AQ$6))+ISBLANK(Z$3:Z$6)) -> 0 | AA15: =SUMPRODUCT((NOT(ISBLANK(AA$3:AA$6))*(AA$3:AA$6=$AN$3:$AN$6))+ISBLANK(AA$3:AA$6)) -> 0 | AB15: =SUMPRODUCT((NOT(ISBLANK(AB$3:AB$6))*(AB$3:AB$6=$AO$3:$AO$6))+ISBLANK(AB$3:AB$6)) -> 0 | AD15: =SUMPRODUCT((NOT(ISBLANK(AD$3:AD$6))*(AD$3:AD$6=$AP$3:$AP$6))+ISBLANK(AD$3:AD$6)) -> 0 | AE15: =SUMPRODUCT((NOT(ISBLANK(AE$3:AE$6))*(AE$3:AE$6=$AQ$3:$AQ$6))+ISBLANK(AE$3:AE$6)) -> 0

Sheet Classes
B1: memelingo-1/simple_mlp-lpnmr-ht | G1: memelingo-1/simple_mlp-lpnmr-htc | L1: memelingo-1/simple_mlp-lpnmr-htcdl | Q1: memelingo-1/simple_mlp-tplp-ht | V1: memelingo-1/simple_mlp-tplp-htc | AA1: memelingo-1/simple_mlp-tplp-htcdl | AF1: min | AJ1: median | AN1: max
B2: time | C2: stime | D2: status | E2: rules | F2: ctime | G2: time | H2: stime | I2: status | J2: rules | K2: ctime | L2: time | M2: stime | N2: status | O2: rules | P2: ctime | Q2: time | R2: stime | S2: status | T2: rules | U2: ctime | V2: time | W2: stime | X2: status | Y2: rules | Z2: ctime | AA2: time | AB2: stime | AC2: status | AD2: rules | AE2: ctime | AF2: time | AG2: stime | AH2: rules | AI2: ctime | AJ2: time | AK2: stime | AL2: rules | AM2: ctime | AN2: time | AO2: stime | AP2: rules | AQ2: ctime
A3: instances | B3: =AVERAGE(Instances!B3:Instances!B6) -> 0 | C3: =AVERAGE(Instances!C3:Instances!C6) -> 0 | E3: =AVERAGE(Instances!E3:Instances!E6) -> 0 | F3: =AVERAGE(Instances!F3:Instances!F6) -> 0 | G3: =AVERAGE(Instances!G3:Instances!G6) -> 0 | H3: =AVERAGE(Instances!H3:Instances!H6) -> 0 | J3: =AVERAGE(Instances!J3:Instances!J6) -> 0 | K3: =AVERAGE(Instances!K3:Instances!K6) -> 0 | L3: =AVERAGE(Instances!L3:Instances!L6) -> 0 | M3: =AVERAGE(Instances!M3:Instances!M6) -> 0 | O3: =AVERAGE(Instances!O3:Instances!O6) -> 0 | P3: =AVERAGE(Instances!P3:Instances!P6) -> 0 | Q3: =AVERAGE(Instances!Q3:Instances!Q6) -> 0 | R3: =AVERAGE(Instances!R3:Instances!R6) -> 0 | T3: =AVERAGE(Instances!T3:Instances!T6) -> 0 | U3: =AVERAGE(Instances!U3:Instances!U6) -> 0 | V3: =AVERAGE(Instances!V3:Instances!V6) -> 0 | W3: =AVERAGE(Instances!W3:Instances!W6) -> 0 | Y3: =AVERAGE(Instances!Y3:Instances!Y6) -> 0 | Z3: =AVERAGE(Instances!Z3:Instances!Z6) -> 0 | AA3: =AVERAGE(Instances!AA3:Instances!AA6) -> 0 | AB3: =AVERAGE(Instances!AB3:Instances!AB6) -> 0 | AD3: =AVERAGE(Instances!AD3:Instances!AD6) -> 0 | AE3: =AVERAGE(Instances!AE3:Instances!AE6) -> 0 | AF3: =MIN($B3,$G3,$L3,$Q3,$V3,$AA3) -> 0 | AG3: =MIN($C3,$H3,$M3,$R3,$W3,$AB3) -> 0 | AH3: =MIN($E3,$J3,$O3,$T3,$Y3,$AD3) -> 0 | AI3: =MIN($F3,$K3,$P3,$U3,$Z3,$AE3) -> 0 | AJ3: =MEDIAN($B3,$G3,$L3,$Q3,$V3,$AA3) -> 0 | AK3: =MEDIAN($C3,$H3,$M3,$R3,$W3,$AB3) -> 0 | AL3: =MEDIAN($E3,$J3,$O3,$T3,$Y3,$AD3) -> 0 | AM3: =MEDIAN($F3,$K3,$P3,$U3,$Z3,$AE3) -> 0 | AN3: =MAX($B3,$G3,$L3,$Q3,$V3,$AA3) -> 0 | AO3: =MAX($C3,$H3,$M3,$R3,$W3,$AB3) -> 0 | AP3: =MAX($E3,$J3,$O3,$T3,$Y3,$AD3) -> 0 | AQ3: =MAX($F3,$K3,$P3,$U3,$Z3,$AE3) -> 0
