Workbook

Sheet Instances
B1: memelingo-1/lambda-small_10_mlp-tplp-ht | G1: memelingo-1/lambda-small_10_mlp-tplp-htc | L1: memelingo-1/lambda-small_10_mlp-tplp-htcdl | Q1: memelingo-1/lambda-small_12_mlp-tplp-ht | V1: memelingo-1/lambda-small_12_mlp-tplp-htc | AA1: memelingo-1/lambda-small_12_mlp-tplp-htcdl | AF1: memelingo-1/lambda-small_14_mlp-tplp-ht | AK1: memelingo-1/lambda-small_14_mlp-tplp-htc | AP1: memelingo-1/lambda-small_14_mlp-tplp-htcdl | AU1: memelingo-1/lambda-small_16_mlp-tplp-ht | AZ1: memelingo-1/lambda-small_16_mlp-tplp-htc | BE1: memelingo-1/lambda-small_16_mlp-tplp-htcdl | BJ1: memelingo-1/lambda-small_18_mlp-tplp-ht | BO1: memelingo-1/lambda-small_18_mlp-tplp-htc | BT1: memelingo-1/lambda-small_18_mlp-tplp-htcdl | BY1: memelingo-1/lambda-small_20_mlp-tplp-ht | CD1: memelingo-1/lambda-small_20_mlp-tplp-htc | CI1: memelingo-1/lambda-small_20_mlp-tplp-htcdl | CN1: memelingo-1/lambda-small_22_mlp-tplp-ht | CS1: memelingo-1/lambda-small_22_mlp-tplp-htc | CX1: memelingo-1/lambda-small_22_mlp-tplp-htcdl | DC1: memelingo-1/lambda-small_24_mlp-tplp-ht | DH1: memelingo-1/lambda-small_24_mlp-tplp-htc | DM1: memelingo-1/lambda-small_24_mlp-tplp-htcdl | DR1: memelingo-1/lambda-small_26_mlp-tplp-ht | DW1: memelingo-1/lambda-small_26_mlp-tplp-htc | EB1: memelingo-1/lambda-small_26_mlp-tplp-htcdl | EG1: memelingo-1/lambda-small_28_mlp-tplp-ht | EL1: memelingo-1/lambda-small_28_mlp-tplp-htc | EQ1: memelingo-1/lambda-small_28_mlp-tplp-htcdl | EV1: memelingo-1/lambda-small_30_mlp-tplp-ht | FA1: memelingo-1/lambda-small_30_mlp-tplp-htc | FF1: memelingo-1/lambda-small_30_mlp-tplp-htcdl | FK1: min | FO1: median | FS1: max
B2: time | C2: stime | D2: status | E2: rules | F2: ctime | G2: time | H2: stime | I2: status | J2: rules | K2: ctime | L2: time | M2: stime | N2: status | O2: rules | P2: ctime | Q2: time | R2: stime | S2: status | T2: rules | U2: ctime | V2: time | W2: stime | X2: status | Y2: rules | Z2: ctime | AA2: time | AB2: stime | AC2: status | AD2: rules | AE2: ctime | AF2: time | AG2: stime | AH2: status | AI2: rules | AJ2: ctime | AK2: time | AL2: stime | AM2: status | AN2: rules | AO2: ctime | AP2: time | AQ2: stime | AR2: status | AS2: rules | AT2: ctime | AU2: time | AV2: stime | AW2: status | AX2: rules | AY2: ctime | AZ2: time | BA2: stime | BB2: status | BC2: rules | BD2: ctime | BE2: time | BF2: stime | BG2: status | BH2: rules | BI2: ctime | BJ2: time | BK2: stime | BL2: status | BM2: rules | BN2: ctime | BO2: time | BP2: stime | BQ2: status | BR2: rules | BS2: ctime | BT2: time | BU2: stime | BV2: status | BW2: rules | BX2: ctime | BY2: time | BZ2: stime | CA2: status | CB2: rules | CC2: ctime | CD2: time | CE2: stime | CF2: status | CG2: rules | CH2: ctime | CI2: time | CJ2: stime | CK2: status | CL2: rules | CM2: ctime | CN2: time | CO2: stime | CP2: status | CQ2: rules | CR2: ctime | CS2: time | CT2: stime | CU2: status | CV2: rules | CW2: ctime | CX2: time | CY2: stime | CZ2: status | DA2: rules | DB2: ctime | DC2: time | DD2: stime | DE2: status | DF2: rules | DG2: ctime | DH2: time | DI2: stime | DJ2: status | DK2: rules | DL2: ctime | DM2: time | DN2: stime | DO2: status | DP2: rules | DQ2: ctime | DR2: time | DS2: stime | DT2: status | DU2: rules | DV2: ctime | DW2: time | DX2: stime | DY2: status | DZ2: rules | EA2: ctime | EB2: time | EC2: stime | ED2: status | EE2: rules | EF2: ctime | EG2: time | EH2: stime | EI2: status | EJ2: rules | EK2: ctime | EL2: time | EM2: stime | EN2: status | EO2: rules | EP2: ctime | EQ2: time | ER2: stime | ES2: status | ET2: rules | EU2: ctime | EV2: time | EW2: stime | EX2: status | EY2: rules | EZ2: ctime | FA2: time | FB2: stime | FC2: status | FD2: rules | FE2: ctime | FF2: time | FG2: stime | FH2: status | FI2: rules | FJ2: ctime | FK2: time | FL2: stime | FM2: rules | FN2: ctime | FO2: time | FP2: stime | FQ2: rules | FR2: ctime | FS2: time | FT2: stime | FU2: rules | FV2: ctime
A3: instances/ft06 | B3: 307.1 | C3: 293 | D3: UNSATISFIABLE | E3: 1706310 | F3: 301.11 | G3: 10.62 | H3: 3.65 | I3: UNSATISFIABLE | J3: 77413 | K3: 4.553 | L3: 10.16 | M3: 2.88 | N3: UNSATISFIABLE | O3: 77413 | P3: 3.763 | Q3: 182.12 | R3: 161.86 | S3: SATISFIABLE | T3: 2382386 | U3: 175.427 | V3: 12.43 | W3: 5.13 | X3: SATISFIABLE | Y3: 99539 | Z3: 6.266 | AA3: 13.28 | AB3: 5.79 | AC3: SATISFIABLE | AD3: 99539 | AE3: 6.907 | AF3: 318.19 | AG3: 294.22 | AH3: SATISFIABLE | AI3: 3130019 | AJ3: 311.956 | AK3: 20.93 | AL3: 13.38 | AM3: SATISFIABLE | AN3: 124081 | AO3: 14.787 | AP3: 18.14 | AQ3: 10.61 | AR3: SATISFIABLE | AS3: 124081 | AT3: 11.967 | AU3: 342.72 | AV3: 314.06 | AW3: SATISFIABLE | AX3: 3933885 | AY3: 335.856 | AZ3: 11.88 | BA3: 4.47 | BB3: SATISFIABLE | BC3: 151039 | BD3: 5.747 | BE3: 24.31 | BF3: 16.57 | BG3: SATISFIABLE | BH3: 151039 | BI3: 17.862 | BJ3: 127.19 | BK3: 95.38 | BL3: SATISFIABLE | BM3: 4779572 | BN3: 120.156 | BO3: 11.73 | BP3: 3.62 | BQ3: SATISFIABLE | BR3: 180413 | BS3: 5.597 | BT3: 38.61 | BU3: 30.66 | BV3: SATISFIABLE | BW3: 180413 | BX3: 32.542 | BY3: 71.1 | BZ3: 31.77 | CA3: SATISFIABLE | CB3: 5653580 | CC3: 63.829 | CD3: 13.68 | CE3: 4.85 | CF3: SATISFIABLE | CG3: 212203 | CH3: 7.237 | CI3: 57.99 | CJ3: 49.41 | CK3: SATISFIABLE | CL3: 212203 | CM3: 51.719 | CN3: 111.77 | CO3: 65.85 | CP3: SATISFIABLE | CQ3: 6543321 | CR3: 104.757 | CS3: 14.95 | CT3: 5.94 | CU3: SATISFIABLE | CV3: 246409 | CW3: 8.716 | CX3: 75.99 | CY3: 67.24 | CZ3: SATISFIABLE | DA3: 246409 | DB3: 69.837 | DC3: 101.55 | DD3: 51.96 | DE3: SATISFIABLE | DF3: 7437119 | DG3: 94.264 | DH3: 11.36 | DI3: 1.6 | DJ3: SATISFIABLE | DK3: 283031 | DL3: 4.855 | DM3: 102.16 | DN3: 92.81 | DO3: SATISFIABLE | DP3: 283031 | DQ3: 95.8 | DR3: 92.5 | DS3: 37.36 | DT3: SATISFIABLE | DU3: 8324210 | DV3: 85.034 | DW3: 18.5 | DX3: 8.06 | DY3: SATISFIABLE | DZ3: 322069 | EA3: 11.812 | EB3: 148.18 | EC3: 138.04 | ED3: SATISFIABLE | EE3: 322069 | EF3: 141.545 | EG3: 110.54 | EH3: 46.96 | EI3: SATISFIABLE | EJ3: 9194742 | EK3: 103.231 | EL3: 13.62 | EM3: 2.78 | EN3: SATISFIABLE | EO3: 363523 | EP3: 7.007 | EQ3: 199.64 | ER3: 189.43 | ES3: SATISFIABLE | ET3: 363523 | EU3: 193.344 | EV3: 88.19 | EW3: 23.84 | EX3: SATISFIABLE | EY3: 10039775 | EZ3: 80.723 | FA3: 19.76 | FB3: 8.5 | FC3: SATISFIABLE | FD3: 407393 | FE3: 13.123 | FF3: 249.82 | FG3: 239.2 | FH3: SATISFIABLE | FI3: 407393 | FJ3: 243.563 | FK3: =MIN($B3,$G3,$L3,$Q3,$V3,$AA3,$AF3,$AK3,$AP3,$AU3,$AZ3,$BE3,$BJ3,$BO3,$BT3,$BY3,$CD3,$CI3,$CN3,$CS3,$CX3,$DC3,$DH3,$DM3,$DR3,$DW3,$EB3,$EG3,$EL3,$EQ3,$EV3,$FA3,$FF3) -> 0 | FL3: =MIN($C3,$H3,$M3,$R3,$W3,$AB3,$AG3,$AL3,$AQ3,$AV3,$BA3,$BF3,$BK3,$BP3,$BU3,$BZ3,$CE3,$CJ3,$CO3,$CT3,$CY3,$DD3,$DI3,$DN3,$DS3,$DX3,$EC3,$EH3,$EM3,$ER3,$EW3,$FB3,$FG3) -> 0 | FM3: =MIN($E3,$J3,$O3,$T3,$Y3,$AD3,$AI3,$AN3,$AS3,$AX3,$BC3,$BH3,$BM3,$BR3,$BW3,$CB3,$CG3,$CL3,$CQ3,$CV3,$DA3,$DF3,$DK3,$DP3,$DU3,$DZ3,$EE3,$EJ3,$EO3,$ET3,$EY3,$FD3,$FI3) -> 0 | FN3: =MIN($F3,$K3,$P3,$U3,$Z3,$AE3,$AJ3,$AO3,$AT3,$AY3,$BD3,$BI3,$BN3,$BS3,$BX3,$CC3,$CH3,$CM3,$CR3,$CW3,$DB3,$DG3,$DL3,$DQ3,$DV3,$EA3,$EF3,$EK3,$EP3,$EU3,$EZ3,$FE3,$FJ3) -> 0 | FO3: =MEDIAN($B3,$G3,$L3,$Q3,$V3,$AA3,$AF3,$AK3,$AP3,$AU3,$AZ3,$BE3,$BJ3,$BO3,$BT3,$BY3,$CD3,$CI3,$CN3,$CS3,$CX3,$DC3,$DH3,$DM3,$DR3,$DW3,$EB3,$EG3,$EL3,$EQ3,$EV3,$FA3,$FF3) -> 0 | FP3: =MEDIAN($C3,$H3,$M3,$R3,$W3,$AB3,$AG3,$AL3,$AQ3,$AV3,$BA3,$BF3,$BK3,$BP3,$BU3,$BZ3,$CE3,$CJ3,$CO3,$CT3,$CY3,$DD3,$DI3,$DN3,$DS3,$DX3,$EC3,$EH3,$EM3,$ER3,$EW3,$FB3,$FG3) -> 0 | FQ3: =MEDIAN($E3,$J3,$O3,$T3,$Y3,$AD3,$AI3,$AN3,$AS3,$AX3,$BC3,$BH3,$BM3,$BR3,$BW3,$CB3,$CG3,$CL3,$CQ3,$CV3,$DA3,$DF3,$DK3,$DP3,$DU3,$DZ3,$EE3,$EJ3,$EO3,$ET3,$EY3,$FD3,$FI3) -> 0 | FR3: =MEDIAN($F3,$K3,$P3,$U3,$Z3,$AE3,$AJ3,$AO3,$AT3,$AY3,$BD3,$BI3,$BN3,$BS3,$BX3,$CC3,$CH3,$CM3,$CR3,$CW3,$DB3,$DG3,$DL3,$DQ3,$DV3,$EA3,$EF3,$EK3,$EP3,$EU3,$EZ3,$FE3,$FJ3) -> 0 | FS3: =MAX($B3,$G3,$L3,$Q3,$V3,$AA3,$AF3,$AK3,$AP3,$AU3,$AZ3,$BE3,$BJ3,$BO3,$BT3,$BY3,$CD3,$CI3,$CN3,$CS3,$CX3,$DC3,$DH3,$DM3,$DR3,$DW3,$EB3,$EG3,$EL3,$EQ3,$EV3,$FA3,$FF3) -> 0 | FT3: =MAX($C3,$H3,$M3,$R3,$W3,$AB3,$AG3,$AL3,$AQ3,$AV3,$BA3,$BF3,$BK3,$BP3,$BU3,$BZ3,$CE3,$CJ3,$CO3,$CT3,$CY3,$DD3,$DI3,$DN3,$DS3,$DX3,$EC3,$EH3,$EM3,$ER3,$EW3,$FB3,$FG3) -> 0 | FU3: =MAX($E3,$J3,$O3,$T3,$Y3,$AD3,$AI3,$AN3,$AS3,$AX3,$BC3,$BH3,$BM3,$BR3,$BW3,$CB3,$CG3,$CL3,$CQ3,$CV3,$DA3,$DF3,$DK3,$DP3,$DU3,$DZ3,$EE3,$EJ3,$EO3,$ET3,$EY3,$FD3,$FI3) -> 0 | FV3: =MAX($F3,$K3,$P3,$U3,$Z3,$AE3,$AJ3,$AO3,$AT3,$AY3,$BD3,$BI3,$BN3,$BS3,$BX3,$CC3,$CH3,$CM3,$CR3,$CW3,$DB3,$DG3,$DL3,$DQ3,$DV3,$EA3,$EF3,$EK3,$EP3,$EU3,$EZ3,$FE3,$FJ3) -> 0
A5: SUM | B5: =SUM(B$3:B$3) -> 0 | C5: =SUM(C$3:C$3) -> 0 | E5: =SUM(E$3:E$3) -> 0 | F5: =SUM(F$3:F$3) -> 0 | G5: =SUM(G$3:G$3) -> 0 | H5: =SUM(H$3:H$3) -> 0 | J5: =SUM(J$3:J$3) -> 0 | K5: =SUM(K$3:K$3) -> 0 | L5: =SUM(L$3:L$3) -> 0 | M5: =SUM(M$3:M$3) -> 0 | O5: =SUM(O$3:O$3) -> 0 | P5: =SUM(P$3:P$3) -> 0 | Q5: =SUM(Q$3:Q$3) -> 0 | R5: =SUM(R$3:R$3) -> 0 | T5: =SUM(T$3:T$3) -> 0 | U5: =SUM(U$3:U$3) -> 0 | V5: =SUM(V$3:V$3) -> 0 | W5: =SUM(W$3:W$3) -> 0 | Y5: =SUM(Y$3:Y$3) -> 0 | Z5: =SUM(Z$3:Z$3) -> 0 | AA5: =SUM(AA$3:AA$3) -> 0 | AB5: =SUM(AB$3:AB$3) -> 0 | AD5: =SUM(AD$3:AD$3) -> 0 | AE5: =SUM(AE$3:AE$3) -> 0 | AF5: =SUM(AF$3:AF$3) -> 0 | AG5: =SUM(AG$3:AG$3) -> 0 | AI5: =SUM(AI$3:AI$3) -> 0 | AJ5: =SUM(AJ$3:AJ$3) -> 0 | AK5: =SUM(AK$3:AK$3) -> 0 | AL5: =SUM(AL$3:AL$3) -> 0 | AN5: =SUM(AN$3:AN$3) -> 0 | AO5: =SUM(AO$3:AO$3) -> 0 | AP5: =SUM(AP$3:AP$3) -> 0 | AQ5: =SUM(AQ$3:AQ$3) -> 0 | AS5: =SUM(AS$3:AS$3) -> 0 | AT5: =SUM(AT$3:AT$3) -> 0 | AU5: =SUM(AU$3:AU$3) -> 0 | AV5: =SUM(AV$3:AV$3) -> 0 | AX5: =SUM(AX$3:AX$3) -> 0 | AY5: =SUM(AY$3:AY$3) -> 0 | AZ5: =SUM(AZ$3:AZ$3) -> 0 | BA5: =SUM(BA$3:BA$3) -> 0 | BC5: =SUM(BC$3:BC$3) -> 0 | BD5: =SUM(BD$3:BD$3) -> 0 | BE5: =SUM(BE$3:BE$3) -> 0 | BF5: =SUM(BF$3:BF$3) -> 0 | BH5: =SUM(BH$3:BH$3) -> 0 | BI5: =SUM(BI$3:BI$3) -> 0 | BJ5: =SUM(BJ$3:BJ$3) -> 0 | BK5: =SUM(BK$3:BK$3) -> 0 | BM5: =SUM(BM$3:BM$3) -> 0 | BN5: =SUM(BN$3:BN$3) -> 0 | BO5: =SUM(BO$3:BO$3) -> 0 | BP5: =SUM(BP$3:BP$3) -> 0 | BR5: =SUM(BR$3:BR$3) -> 0 | BS5: =SUM(BS$3:BS$3) -> 0 | BT5: =SUM(BT$3:BT$3) -> 0 | BU5: =SUM(BU$3:BU$3) -> 0 | BW5: =SUM(BW$3:BW$3) -> 0 | BX5: =SUM(BX$3:BX$3) -> 0 | BY5: =SUM(BY$3:BY$3) -> 0 | BZ5: =SUM(BZ$3:BZ$3) -> 0 | CB5: =SUM(CB$3:CB$3) -> 0 | CC5: =SUM(CC$3:CC$3) -> 0 | CD5: =SUM(CD$3:CD$3) -> 0 | CE5: =SUM(CE$3:CE$3) -> 0 | CG5: =SUM(CG$3:CG$3) -> 0 | CH5: =SUM(CH$3:CH$3) -> 0 | CI5: =SUM(CI$3:CI$3) -> 0 | CJ5: =SUM(CJ$3:CJ$3) -> 0 | CL5: =SUM(CL$3:CL$3) -> 0 | CM5: =SUM(CM$3:CM$3) -> 0 | CN5: =SUM(CN$3:CN$3) -> 0 | CO5: =SUM(CO$3:CO$3) -> 0 | CQ5: =SUM(CQ$3:CQ$3) -> 0 | CR5: =SUM(CR$3:CR$3) -> 0 | CS5: =SUM(CS$3:CS$3) -> 0 | CT5: =SUM(CT$3:CT$3) -> 0 | CV5: =SUM(CV$3:CV$3) -> 0 | CW5: =SUM(CW$3:CW$3) -> 0 | CX5: =SUM(CX$3:CX$3) -> 0 | CY5: =SUM(CY$3:CY$3) -> 0 | DA5: =SUM(DA$3:DA$3) -> 0 | DB5: =SUM(DB$3:DB$3) -> 0 | DC5: =SUM(DC$3:DC$3) -> 0 | DD5: =SUM(DD$3:DD$3) -> 0 | DF5: =SUM(DF$3:DF$3) -> 0 | DG5: =SUM(DG$3:DG$3) -> 0 | DH5: =SUM(DH$3:DH$3) -> 0 | DI5: =SUM(DI$3:DI$3) -> 0 | DK5: =SUM(DK$3:DK$3) -> 0 | DL5: =SUM(DL$3:DL$3) -> 0 | DM5: =SUM(DM$3:DM$3) -> 0 | DN5: =SUM(DN$3:DN$3) -> 0 | DP5: =SUM(DP$3:DP$3) -> 0 | DQ5: =SUM(DQ$3:DQ$3) -> 0 | DR5: =SUM(DR$3:DR$3) -> 0 | DS5: =SUM(DS$3:DS$3) -> 0 | DU5: =SUM(DU$3:DU$3) -> 0 | DV5: =SUM(DV$3:DV$3) -> 0 | DW5: =SUM(DW$3:DW$3) -> 0 | DX5: =SUM(DX$3:DX$3) -> 0 | DZ5: =SUM(DZ$3:DZ$3) -> 0 | EA5: =SUM(EA$3:EA$3) -> 0 | EB5: =SUM(EB$3:EB$3) -> 0 | EC5: =SUM(EC$3:EC$3) -> 0 | EE5: =SUM(EE$3:EE$3) -> 0 | EF5: =SUM(EF$3:EF$3) -> 0 | EG5: =SUM(EG$3:EG$3) -> 0 | EH5: =SUM(EH$3:EH$3) -> 0 | EJ5: =SUM(EJ$3:EJ$3) -> 0 | EK5: =SUM(EK$3:EK$3) -> 0 | EL5: =SUM(EL$3:EL$3) -> 0 | EM5: =SUM(EM$3:EM$3) -> 0 | EO5: =SUM(EO$3:EO$3) -> 0 | EP5: =SUM(EP$3:EP$3) -> 0 | EQ5: =SUM(EQ$3:EQ$3) -> 0 | ER5: =SUM(ER$3:ER$3) -> 0 | ET5: =SUM(ET$3:ET$3) -> 0 | EU5: =SUM(EU$3:EU$3) -> 0 | EV5: =SUM(EV$3:EV$3) -> 0 | EW5: =SUM(EW$3:EW$3) -> 0 | EY5: =SUM(EY$3:EY$3) -> 0 | EZ5: =SUM(EZ$3:EZ$3) -> 0 | FA5: =SUM(FA$3:FA$3) -> 0 | FB5: =SUM(FB$3:FB$3) -> 0 | FD5: =SUM(FD$3:FD$3) -> 0 | FE5: =SUM(FE$3:FE$3) -> 0 | FF5: =SUM(FF$3:FF$3) -> 0 | FG5: =SUM(FG$3:FG$3) -> 0 | FI5: =SUM(FI$3:FI$3) -> 0 | FJ5: =SUM(FJ$3:FJ$3) -> 0 | FK5: =SUM(FK$3:FK$3) -> 0 | FL5: =SUM(FL$3:FL$3) -> 0 | FM5: =SUM(FM$3:FM$3) -> 0 | FN5: =SUM(FN$3:FN$3) -> 0 | FO5: =SUM(FO$3:FO$3) -> 0 | FP5: =SUM(FP$3:FP$3) -> 0 | ... FV5: =SUM(FV$3:FV$3) -> 0
A6: AVG | B6: =AVERAGE(B$3:B$3) -> 0 | C6: =AVERAGE(C$3:C$3) -> 0 | E6: =AVERAGE(E$3:E$3) -> 0 | F6: =AVERAGE(F$3:F$3) -> 0 | G6: =AVERAGE(G$3:G$3) -> 0 | H6: =AVERAGE(H$3:H$3) -> 0 | J6: =AVERAGE(J$3:J$3) -> 0 | K6: =AVERAGE(K$3:K$3) -> 0 | L6: =AVERAGE(L$3:L$3) -> 0 | M6: =AVERAGE(M$3:M$3) -> 0 | O6: =AVERAGE(O$3:O$3) -> 0 | P6: =AVERAGE(P$3:P$3) -> 0 | Q6: =AVERAGE(Q$3:Q$3) -> 0 | R6: =AVERAGE(R$3:R$3) -> 0 | T6: =AVERAGE(T$3:T$3) -> 0 | U6: =AVERAGE(U$3:U$3) -> 0 | V6: =AVERAGE(V$3:V$3) -> 0 | W6: =AVERAGE(W$3:W$3) -> 0 | Y6: =AVERAGE(Y$3:Y$3) -> 0 | Z6: =AVERAGE(Z$3:Z$3) -> 0 | AA6: =AVERAGE(AA$3:AA$3) -> 0 | AB6: =AVERAGE(AB$3:AB$3) -> 0 | AD6: =AVERAGE(AD$3:AD$3) -> 0 | AE6: =AVERAGE(AE$3:AE$3) -> 0 | AF6: =AVERAGE(AF$3:AF$3) -> 0 | AG6: =AVERAGE(AG$3:AG$3) -> 0 | AI6: =AVERAGE(AI$3:AI$3) -> 0 | AJ6: =AVERAGE(AJ$3:AJ$3) -> 0 | AK6: =AVERAGE(AK$3:AK$3) -> 0 | AL6: =AVERAGE(AL$3:AL$3) -> 0 | AN6: =AVERAGE(AN$3:AN$3) -> 0 | AO6: =AVERAGE(AO$3:AO$3) -> 0 | AP6: =AVERAGE(AP$3:AP$3) -> 0 | AQ6: =AVERAGE(AQ$3:AQ$3) -> 0 | AS6: =AVERAGE(AS$3:AS$3) -> 0 | AT6: =AVERAGE(AT$3:AT$3) -> 0 | AU6: =AVERAGE(AU$3:AU$3) -> 0 | AV6: =AVERAGE(AV$3:AV$3) -> 0 | AX6: =AVERAGE(AX$3:AX$3) -> 0 | AY6: =AVERAGE(AY$3:AY$3) -> 0 | AZ6: =AVERAGE(AZ$3:AZ$3) -> 0 | BA6: =AVERAGE(BA$3:BA$3) -> 0 | BC6: =AVERAGE(BC$3:BC$3) -> 0 | BD6: =AVERAGE(BD$3:BD$3) -> 0 | BE6: =AVERAGE(BE$3:BE$3) -> 0 | BF6: =AVERAGE(BF$3:BF$3) -> 0 | BH6: =AVERAGE(BH$3:BH$3) -> 0 | BI6: =AVERAGE(BI$3:BI$3) -> 0 | BJ6: =AVERAGE(BJ$3:BJ$3) -> 0 | BK6: =AVERAGE(BK$3:BK$3) -> 0 | BM6: =AVERAGE(BM$3:BM$3) -> 0 | BN6: =AVERAGE(BN$3:BN$3) -> 0 | BO6: =AVERAGE(BO$3:BO$3) -> 0 | BP6: =AVERAGE(BP$3:BP$3) -> 0 | BR6: =AVERAGE(BR$3:BR$3) -> 0 | BS6: =AVERAGE(BS$3:BS$3) -> 0 | BT6: =AVERAGE(BT$3:BT$3) -> 0 | BU6: =AVERAGE(BU$3:BU$3) -> 0 | BW6: =AVERAGE(BW$3:BW$3) -> 0 | BX6: =AVERAGE(BX$3:BX$3) -> 0 | BY6: =AVERAGE(BY$3:BY$3) -> 0 | BZ6: =AVERAGE(BZ$3:BZ$3) -> 0 | CB6: =AVERAGE(CB$3:CB$3) -> 0 | CC6: =AVERAGE(CC$3:CC$3) -> 0 | CD6: =AVERAGE(CD$3:CD$3) -> 0 | CE6: =AVERAGE(CE$3:CE$3) -> 0 | CG6: =AVERAGE(CG$3:CG$3) -> 0 | CH6: =AVERAGE(CH$3:CH$3) -> 0 | CI6: =AVERAGE(CI$3:CI$3) -> 0 | CJ6: =AVERAGE(CJ$3:CJ$3) -> 0 | CL6: =AVERAGE(CL$3:CL$3) -> 0 | CM6: =AVERAGE(CM$3:CM$3) -> 0 | CN6: =AVERAGE(CN$3:CN$3) -> 0 | CO6: =AVERAGE(CO$3:CO$3) -> 0 | CQ6: =AVERAGE(CQ$3:CQ$3) -> 0 | CR6: =AVERAGE(CR$3:CR$3) -> 0 | CS6: =AVERAGE(CS$3:CS$3) -> 0 | CT6: =AVERAGE(CT$3:CT$3) -> 0 | CV6: =AVERAGE(CV$3:CV$3) -> 0 | CW6: =AVERAGE(CW$3:CW$3) -> 0 | CX6: =AVERAGE(CX$3:CX$3) -> 0 | CY6: =AVERAGE(CY$3:CY$3) -> 0 | DA6: =AVERAGE(DA$3:DA$3) -> 0 | DB6: =AVERAGE(DB$3:DB$3) -> 0 | DC6: =AVERAGE(DC$3:DC$3) -> 0 | DD6: =AVERAGE(DD$3:DD$3) -> 0 | DF6: =AVERAGE(DF$3:DF$3) -> 0 | DG6: =AVERAGE(DG$3:DG$3) -> 0 | DH6: =AVERAGE(DH$3:DH$3) -> 0 | DI6: =AVERAGE(DI$3:DI$3) -> 0 | DK6: =AVERAGE(DK$3:DK$3) -> 0 | DL6: =AVERAGE(DL$3:DL$3) -> 0 | DM6: =AVERAGE(DM$3:DM$3) -> 0 | DN6: =AVERAGE(DN$3:DN$3) -> 0 | DP6: =AVERAGE(DP$3:DP$3) -> 0 | DQ6: =AVERAGE(DQ$3:DQ$3) -> 0 | DR6: =AVERAGE(DR$3:DR$3) -> 0 | DS6: =AVERAGE(DS$3:DS$3) -> 0 | DU6: =AVERAGE(DU$3:DU$3) -> 0 | DV6: =AVERAGE(DV$3:DV$3) -> 0 | DW6: =AVERAGE(DW$3:DW$3) -> 0 | DX6: =AVERAGE(DX$3:DX$3) -> 0 | DZ6: =AVERAGE(DZ$3:DZ$3) -> 0 | EA6: =AVERAGE(EA$3:EA$3) -> 0 | EB6: =AVERAGE(EB$3:EB$3) -> 0 | EC6: =AVERAGE(EC$3:EC$3) -> 0 | EE6: =AVERAGE(EE$3:EE$3) -> 0 | EF6: =AVERAGE(EF$3:EF$3) -> 0 | EG6: =AVERAGE(EG$3:EG$3) -> 0 | EH6: =AVERAGE(EH$3:EH$3) -> 0 | EJ6: =AVERAGE(EJ$3:EJ$3) -> 0 | EK6: =AVERAGE(EK$3:EK$3) -> 0 | EL6: =AVERAGE(EL$3:EL$3) -> 0 | EM6: =AVERAGE(EM$3:EM$3) -> 0 | EO6: =AVERAGE(EO$3:EO$3) -> 0 | EP6: =AVERAGE(EP$3:EP$3) -> 0 | EQ6: =AVERAGE(EQ$3:EQ$3) -> 0 | ER6: =AVERAGE(ER$3:ER$3) -> 0 | ET6: =AVERAGE(ET$3:ET$3) -> 0 | EU6: =AVERAGE(EU$3:EU$3) -> 0 | EV6: =AVERAGE(EV$3:EV$3) -> 0 | EW6: =AVERAGE(EW$3:EW$3) -> 0 | EY6: =AVERAGE(EY$3:EY$3) -> 0 | EZ6: =AVERAGE(EZ$3:EZ$3) -> 0 | FA6: =AVERAGE(FA$3:FA$3) -> 0 | FB6: =AVERAGE(FB$3:FB$3) -> 0 | FD6: =AVERAGE(FD$3:FD$3) -> 0 | FE6: =AVERAGE(FE$3:FE$3) -> 0 | FF6: =AVERAGE(FF$3:FF$3) -> 0 | FG6: =AVERAGE(FG$3:FG$3) -> 0 | FI6: =AVERAGE(FI$3:FI$3) -> 0 | FJ6: =AVERAGE(FJ$3:FJ$3) -> 0 | FK6: =AVERAGE(FK$3:FK$3) -> 0 | FL6: =AVERAGE(FL$3:FL$3) -> 0 | FM6: =AVERAGE(FM$3:FM$3) -> 0 | FN6: =AVERAGE(FN$3:FN$3) -> 0 | FO6: =AVERAGE(FO$3:FO$3) -> 0 | FP6: =AVERAGE(FP$3:FP$3) -> 0 | ... FV6: =AVERAGE(FV$3:FV$3) -> 0
A7: DEV | B7: =STDEV(B$3:B$3) -> 0 | C7: =STDEV(C$3:C$3) -> 0 | E7: =STDEV(E$3:E$3) -> 0 | F7: =STDEV(F$3:F$3) -> 0 | G7: =STDEV(G$3:G$3) -> 0 | H7: =STDEV(H$3:H$3) -> 0 | J7: =STDEV(J$3:J$3) -> 0 | K7: =STDEV(K$3:K$3) -> 0 | L7: =STDEV(L$3:L$3) -> 0 | M7: =STDEV(M$3:M$3) -> 0 | O7: =STDEV(O$3:O$3) -> 0 | P7: =STDEV(P$3:P$3) -> 0 | Q7: =STDEV(Q$3:Q$3) -> 0 | R7: =STDEV(R$3:R$3) -> 0 | T7: =STDEV(T$3:T$3) -> 0 | U7: =STDEV(U$3:U$3) -> 0 | V7: =STDEV(V$3:V$3) -> 0 | W7: =STDEV(W$3:W$3) -> 0 | Y7: =STDEV(Y$3:Y$3) -> 0 | Z7: =STDEV(Z$3:Z$3) -> 0 | AA7: =STDEV(AA$3:AA$3) -> 0 | AB7: =STDEV(AB$3:AB$3) -> 0 | AD7: =STDEV(AD$3:AD$3) -> 0 | AE7: =STDEV(AE$3:AE$3) -> 0 | AF7: =STDEV(AF$3:AF$3) -> 0 | AG7: =STDEV(AG$3:AG$3) -> 0 | AI7: =STDEV(AI$3:AI$3) -> 0 | AJ7: =STDEV(AJ$3:AJ$3) -> 0 | AK7: =STDEV(AK$3:AK$3) -> 0 | AL7: =STDEV(AL$3:AL$3) -> 0 | AN7: =STDEV(AN$3:AN$3) -> 0 | AO7: =STDEV(AO$3:AO$3) -> 0 | AP7: =STDEV(AP$3:AP$3) -> 0 | AQ7: =STDEV(AQ$3:AQ$3) -> 0 | AS7: =STDEV(AS$3:AS$3) -> 0 | AT7: =STDEV(AT$3:AT$3) -> 0 | AU7: =STDEV(AU$3:AU$3) -> 0 | AV7: =STDEV(AV$3:AV$3) -> 0 | AX7: =STDEV(AX$3:AX$3) -> 0 | AY7: =STDEV(AY$3:AY$3) -> 0 | AZ7: =STDEV(AZ$3:AZ$3) -> 0 | BA7: =STDEV(BA$3:BA$3) -> 0 | BC7: =STDEV(BC$3:BC$3) -> 0 | BD7: =STDEV(BD$3:BD$3) -> 0 | BE7: =STDEV(BE$3:BE$3) -> 0 | BF7: =STDEV(BF$3:BF$3) -> 0 | BH7: =STDEV(BH$3:BH$3) -> 0 | BI7: =STDEV(BI$3:BI$3) -> 0 | BJ7: =STDEV(BJ$3:BJ$3) -> 0 | BK7: =STDEV(BK$3:BK$3) -> 0 | BM7: =STDEV(BM$3:BM$3) -> 0 | BN7: =STDEV(BN$3:BN$3) -> 0 | BO7: =STDEV(BO$3:BO$3) -> 0 | BP7: =STDEV(BP$3:BP$3) -> 0 | BR7: =STDEV(BR$3:BR$3) -> 0 | BS7: =STDEV(BS$3:BS$3) -> 0 | BT7: =STDEV(BT$3:BT$3) -> 0 | BU7: =STDEV(BU$3:BU$3) -> 0 | BW7: =STDEV(BW$3:BW$3) -> 0 | BX7: =STDEV(BX$3:BX$3) -> 0 | BY7: =STDEV(BY$3:BY$3) -> 0 | BZ7: =STDEV(BZ$3:BZ$3) -> 0 | CB7: =STDEV(CB$3:CB$3) -> 0 | CC7: =STDEV(CC$3:CC$3) -> 0 | CD7: =STDEV(CD$3:CD$3) -> 0 | CE7: =STDEV(CE$3:CE$3) -> 0 | CG7: =STDEV(CG$3:CG$3) -> 0 | CH7: =STDEV(CH$3:CH$3) -> 0 | CI7: =STDEV(CI$3:CI$3) -> 0 | CJ7: =STDEV(CJ$3:CJ$3) -> 0 | CL7: =STDEV(CL$3:CL$3) -> 0 | CM7: =STDEV(CM$3:CM$3) -> 0 | CN7: =STDEV(CN$3:CN$3) -> 0 | CO7: =STDEV(CO$3:CO$3) -> 0 | CQ7: =STDEV(CQ$3:CQ$3) -> 0 | CR7: =STDEV(CR$3:CR$3) -> 0 | CS7: =STDEV(CS$3:CS$3) -> 0 | CT7: =STDEV(CT$3:CT$3) -> 0 | CV7: =STDEV(CV$3:CV$3) -> 0 | CW7: =STDEV(CW$3:CW$3) -> 0 | CX7: =STDEV(CX$3:CX$3) -> 0 | CY7: =STDEV(CY$3:CY$3) -> 0 | DA7: =STDEV(DA$3:DA$3) -> 0 | DB7: =STDEV(DB$3:DB$3) -> 0 | DC7: =STDEV(DC$3:DC$3) -> 0 | DD7: =STDEV(DD$3:DD$3) -> 0 | DF7: =STDEV(DF$3:DF$3) -> 0 | DG7: =STDEV(DG$3:DG$3) -> 0 | DH7: =STDEV(DH$3:DH$3) -> 0 | DI7: =STDEV(DI$3:DI$3) -> 0 | DK7: =STDEV(DK$3:DK$3) -> 0 | DL7: =STDEV(DL$3:DL$3) -> 0 | DM7: =STDEV(DM$3:DM$3) -> 0 | DN7: =STDEV(DN$3:DN$3) -> 0 | DP7: =STDEV(DP$3:DP$3) -> 0 | DQ7: =STDEV(DQ$3:DQ$3) -> 0 | DR7: =STDEV(DR$3:DR$3) -> 0 | DS7: =STDEV(DS$3:DS$3) -> 0 | DU7: =STDEV(DU$3:DU$3) -> 0 | DV7: =STDEV(DV$3:DV$3) -> 0 | DW7: =STDEV(DW$3:DW$3) -> 0 | DX7: =STDEV(DX$3:DX$3) -> 0 | DZ7: =STDEV(DZ$3:DZ$3) -> 0 | EA7: =STDEV(EA$3:EA$3) -> 0 | EB7: =STDEV(EB$3:EB$3) -> 0 | EC7: =STDEV(EC$3:EC$3) -> 0 | EE7: =STDEV(EE$3:EE$3) -> 0 | EF7: =STDEV(EF$3:EF$3) -> 0 | EG7: =STDEV(EG$3:EG$3) -> 0 | EH7: =STDEV(EH$3:EH$3) -> 0 | EJ7: =STDEV(EJ$3:EJ$3) -> 0 | EK7: =STDEV(EK$3:EK$3) -> 0 | EL7: =STDEV(EL$3:EL$3) -> 0 | EM7: =STDEV(EM$3:EM$3) -> 0 | EO7: =STDEV(EO$3:EO$3) -> 0 | EP7: =STDEV(EP$3:EP$3) -> 0 | EQ7: =STDEV(EQ$3:EQ$3) -> 0 | ER7: =STDEV(ER$3:ER$3) -> 0 | ET7: =STDEV(ET$3:ET$3) -> 0 | EU7: =STDEV(EU$3:EU$3) -> 0 | EV7: =STDEV(EV$3:EV$3) -> 0 | EW7: =STDEV(EW$3:EW$3) -> 0 | EY7: =STDEV(EY$3:EY$3) -> 0 | EZ7: =STDEV(EZ$3:EZ$3) -> 0 | FA7: =STDEV(FA$3:FA$3) -> 0 | FB7: =STDEV(FB$3:FB$3) -> 0 | FD7: =STDEV(FD$3:FD$3) -> 0 | FE7: =STDEV(FE$3:FE$3) -> 0 | FF7: =STDEV(FF$3:FF$3) -> 0 | FG7: =STDEV(FG$3:FG$3) -> 0 | FI7: =STDEV(FI$3:FI$3) -> 0 | FJ7: =STDEV(FJ$3:FJ$3) -> 0 | FK7: =STDEV(FK$3:FK$3) -> 0 | FL7: =STDEV(FL$3:FL$3) -> 0 | FM7: =STDEV(FM$3:FM$3) -> 0 | FN7: =STDEV(FN$3:FN$3) -> 0 | FO7: =STDEV(FO$3:FO$3) -> 0 | FP7: =STDEV(FP$3:FP$3) -> 0 | ... FV7: =STDEV(FV$3:FV$3) -> 0
A8: DST | B8: =SUMPRODUCT(--(B$3:B$3-$FK$3:$FK$3)^2)^0.5 -> 0 | C8: =SUMPRODUCT(--(C$3:C$3-$FL$3:$FL$3)^2)^0.5 -> 0 | E8: =SUMPRODUCT(--(E$3:E$3-$FM$3:$FM$3)^2)^0.5 -> 0 | F8: =SUMPRODUCT(--(F$3:F$3-$FN$3:$FN$3)^2)^0.5 -> 0 | G8: =SUMPRODUCT(--(G$3:G$3-$FK$3:$FK$3)^2)^0.5 -> 0 | H8: =SUMPRODUCT(--(H$3:H$3-$FL$3:$FL$3)^2)^0.5 -> 0 | J8: =SUMPRODUCT(--(J$3:J$3-$FM$3:$FM$3)^2)^0.5 -> 0 | K8: =SUMPRODUCT(--(K$3:K$3-$FN$3:$FN$3)^2)^0.5 -> 0 | L8: =SUMPRODUCT(--(L$3:L$3-$FK$3:$FK$3)^2)^0.5 -> 0 | M8: =SUMPRODUCT(--(M$3:M$3-$FL$3:$FL$3)^2)^0.5 -> 0 | O8: =SUMPRODUCT(--(O$3:O$3-$FM$3:$FM$3)^2)^0.5 -> 0 | P8: =SUMPRODUCT(--(P$3:P$3-$FN$3:$FN$3)^2)^0.5 -> 0 | Q8: =SUMPRODUCT(--(Q$3:Q$3-$FK$3:$FK$3)^2)^0.5 -> 0 | R8: =SUMPRODUCT(--(R$3:R$3-$FL$3:$FL$3)^2)^0.5 -> 0 | T8: =SUMPRODUCT(--(T$3:T$3-$FM$3:$FM$3)^2)^0.5 -> 0 | U8: =SUMPRODUCT(--(U$3:U$3-$FN$3:$FN$3)^2)^0.5 -> 0 | V8: =SUMPRODUCT(--(V$3:V$3-$FK$3:$FK$3)^2)^0.5 -> 0 | W8: =SUMPRODUCT(--(W$3:W$3-$FL$3:$FL$3)^2)^0.5 -> 0 | Y8: =SUMPRODUCT(--(Y$3:Y$3-$FM$3:$FM$3)^2)^0.5 -> 0 | Z8: =SUMPRODUCT(--(Z$3:Z$3-$FN$3:$FN$3)^2)^0.5 -> 0 | AA8: =SUMPRODUCT(--(AA$3:AA$3-$FK$3:$FK$3)^2)^0.5 -> 0 | AB8: =SUMPRODUCT(--(AB$3:AB$3-$FL$3:$FL$3)^2)^0.5 -> 0 | AD8: =SUMPRODUCT(--(AD$3:AD$3-$FM$3:$FM$3)^2)^0.5 -> 0 | AE8: =SUMPRODUCT(--(AE$3:AE$3-$FN$3:$FN$3)^2)^0.5 -> 0 | AF8: =SUMPRODUCT(--(AF$3:AF$3-$FK$3:$FK$3)^2)^0.5 -> 0 | AG8: =SUMPRODUCT(--(AG$3:AG$3-$FL$3:$FL$3)^2)^0.5 -> 0 | AI8: =SUMPRODUCT(--(AI$3:AI$3-$FM$3:$FM$3)^2)^0.5 -> 0 | AJ8: =SUMPRODUCT(--(AJ$3:AJ$3-$FN$3:$FN$3)^2)^0.5 -> 0 | AK8: =SUMPRODUCT(--(AK$3:AK$3-$FK$3:$FK$3)^2)^0.5 -> 0 | AL8: =SUMPRODUCT(--(AL$3:AL$3-$FL$3:$FL$3)^2)^0.5 -> 0 | AN8: =SUMPRODUCT(--(AN$3:AN$3-$FM$3:$FM$3)^2)^0.5 -> 0 | AO8: =SUMPRODUCT(--(AO$3:AO$3-$FN$3:$FN$3)^2)^0.5 -> 0 | AP8: =SUMPRODUCT(--(AP$3:AP$3-$FK$3:$FK$3)^2)^0.5 -> 0 | AQ8: =SUMPRODUCT(--(AQ$3:AQ$3-$FL$3:$FL$3)^2)^0.5 -> 0 | AS8: =SUMPRODUCT(--(AS$3:AS$3-$FM$3:$FM$3)^2)^0.5 -> 0 | AT8: =SUMPRODUCT(--(AT$3:AT$3-$FN$3:$FN$3)^2)^0.5 -> 0 | AU8: =SUMPRODUCT(--(AU$3:AU$3-$FK$3:$FK$3)^2)^0.5 -> 0 | AV8: =SUMPRODUCT(--(AV$3:AV$3-$FL$3:$FL$3)^2)^0.5 -> 0 | AX8: =SUMPRODUCT(--(AX$3:AX$3-$FM$3:$FM$3)^2)^0.5 -> 0 | AY8: =SUMPRODUCT(--(AY$3:AY$3-$FN$3:$FN$3)^2)^0.5 -> 0 | AZ8: =SUMPRODUCT(--(AZ$3:AZ$3-$FK$3:$FK$3)^2)^0.5 -> 0 | BA8: =SUMPRODUCT(--(BA$3:BA$3-$FL$3:$FL$3)^2)^0.5 -> 0 | BC8: =SUMPRODUCT(--(BC$3:BC$3-$FM$3:$FM$3)^2)^0.5 -> 0 | BD8: =SUMPRODUCT(--(BD$3:BD$3-$FN$3:$FN$3)^2)^0.5 -> 0 | BE8: =SUMPRODUCT(--(BE$3:BE$3-$FK$3:$FK$3)^2)^0.5 -> 0 | BF8: =SUMPRODUCT(--(BF$3:BF$3-$FL$3:$FL$3)^2)^0.5 -> 0 | BH8: =SUMPRODUCT(--(BH$3:BH$3-$FM$3:$FM$3)^2)^0.5 -> 0 | BI8: =SUMPRODUCT(--(BI$3:BI$3-$FN$3:$FN$3)^2)^0.5 -> 0 | BJ8: =SUMPRODUCT(--(BJ$3:BJ$3-$FK$3:$FK$3)^2)^0.5 -> 0 | BK8: =SUMPRODUCT(--(BK$3:BK$3-$FL$3:$FL$3)^2)^0.5 -> 0 | BM8: =SUMPRODUCT(--(BM$3:BM$3-$FM$3:$FM$3)^2)^0.5 -> 0 | BN8: =SUMPRODUCT(--(BN$3:BN$3-$FN$3:$FN$3)^2)^0.5 -> 0 | BO8: =SUMPRODUCT(--(BO$3:BO$3-$FK$3:$FK$3)^2)^0.5 -> 0 | BP8: =SUMPRODUCT(--(BP$3:BP$3-$FL$3:$FL$3)^2)^0.5 -> 0 | BR8: =SUMPRODUCT(--(BR$3:BR$3-$FM$3:$FM$3)^2)^0.5 -> 0 | BS8: =SUMPRODUCT(--(BS$3:BS$3-$FN$3:$FN$3)^2)^0.5 -> 0 | BT8: =SUMPRODUCT(--(BT$3:BT$3-$FK$3:$FK$3)^2)^0.5 -> 0 | BU8: =SUMPRODUCT(--(BU$3:BU$3-$FL$3:$FL$3)^2)^0.5 -> 0 | BW8: =SUMPRODUCT(--(BW$3:BW$3-$FM$3:$FM$3)^2)^0.5 -> 0 | BX8: =SUMPRODUCT(--(BX$3:BX$3-$FN$3:$FN$3)^2)^0.5 -> 0 | BY8: =SUMPRODUCT(--(BY$3:BY$3-$FK$3:$FK$3)^2)^0.5 -> 0 | BZ8: =SUMPRODUCT(--(BZ$3:BZ$3-$FL$3:$FL$3)^2)^0.5 -> 0 | CB8: =SUMPRODUCT(--(CB$3:CB$3-$FM$3:$FM$3)^2)^0.5 -> 0 | CC8: =SUMPRODUCT(--(CC$3:CC$3-$FN$3:$FN$3)^2)^0.5 -> 0 | CD8: =SUMPRODUCT(--(CD$3:CD$3-$FK$3:$FK$3)^2)^0.5 -> 0 | CE8: =SUMPRODUCT(--(CE$3:CE$3-$FL$3:$FL$3)^2)^0.5 -> 0 | CG8: =SUMPRODUCT(--(CG$3:CG$3-$FM$3:$FM$3)^2)^0.5 -> 0 | CH8: =SUMPRODUCT(--(CH$3:CH$3-$FN$3:$FN$3)^2)^0.5 -> 0 | CI8: =SUMPRODUCT(--(CI$3:CI$3-$FK$3:$FK$3)^2)^0.5 -> 0 | CJ8: =SUMPRODUCT(--(CJ$3:CJ$3-$FL$3:$FL$3)^2)^0.5 -> 0 | CL8: =SUMPRODUCT(--(CL$3:CL$3-$FM$3:$FM$3)^2)^0.5 -> 0 | CM8: =SUMPRODUCT(--(CM$3:CM$3-$FN$3:$FN$3)^2)^0.5 -> 0 | CN8: =SUMPRODUCT(--(CN$3:CN$3-$FK$3:$FK$3)^2)^0.5 -> 0 | CO8: =SUMPRODUCT(--(CO$3:CO$3-$FL$3:$FL$3)^2)^0.5 -> 0 | CQ8: =SUMPRODUCT(--(CQ$3:CQ$3-$FM$3:$FM$3)^2)^0.5 -> 0 | CR8: =SUMPRODUCT(--(CR$3:CR$3-$FN$3:$FN$3)^2)^0.5 -> 0 | CS8: =SUMPRODUCT(--(CS$3:CS$3-$FK$3:$FK$3)^2)^0.5 -> 0 | CT8: =SUMPRODUCT(--(CT$3:CT$3-$FL$3:$FL$3)^2)^0.5 -> 0 | CV8: =SUMPRODUCT(--(CV$3:CV$3-$FM$3:$FM$3)^2)^0.5 -> 0 | CW8: =SUMPRODUCT(--(CW$3:CW$3-$FN$3:$FN$3)^2)^0.5 -> 0 | CX8: =SUMPRODUCT(--(CX$3:CX$3-$FK$3:$FK$3)^2)^0.5 -> 0 | CY8: =SUMPRODUCT(--(CY$3:CY$3-$FL$3:$FL$3)^2)^0.5 -> 0 | DA8: =SUMPRODUCT(--(DA$3:DA$3-$FM$3:$FM$3)^2)^0.5 -> 0 | DB8: =SUMPRODUCT(--(DB$3:DB$3-$FN$3:$FN$3)^2)^0.5 -> 0 | DC8: =SUMPRODUCT(--(DC$3:DC$3-$FK$3:$FK$3)^2)^0.5 -> 0 | DD8: =SUMPRODUCT(--(DD$3:DD$3-$FL$3:$FL$3)^2)^0.5 -> 0 | DF8: =SUMPRODUCT(--(DF$3:DF$3-$FM$3:$FM$3)^2)^0.5 -> 0 | DG8: =SUMPRODUCT(--(DG$3:DG$3-$FN$3:$FN$3)^2)^0.5 -> 0 | DH8: =SUMPRODUCT(--(DH$3:DH$3-$FK$3:$FK$3)^2)^0.5 -> 0 | DI8: =SUMPRODUCT(--(DI$3:DI$3-$FL$3:$FL$3)^2)^0.5 -> 0 | DK8: =SUMPRODUCT(--(DK$3:DK$3-$FM$3:$FM$3)^2)^0.5 -> 0 | DL8: =SUMPRODUCT(--(DL$3:DL$3-$FN$3:$FN$3)^2)^0.5 -> 0 | DM8: =SUMPRODUCT(--(DM$3:DM$3-$FK$3:$FK$3)^2)^0.5 -> 0 | DN8: =SUMPRODUCT(--(DN$3:DN$3-$FL$3:$FL$3)^2)^0.5 -> 0 | DP8: =SUMPRODUCT(--(DP$3:DP$3-$FM$3:$FM$3)^2)^0.5 -> 0 | DQ8: =SUMPRODUCT(--(DQ$3:DQ$3-$FN$3:$FN$3)^2)^0.5 -> 0 | DR8: =SUMPRODUCT(--(DR$3:DR$3-$FK$3:$FK$3)^2)^0.5 -> 0 | DS8: =SUMPRODUCT(--(DS$3:DS$3-$FL$3:$FL$3)^2)^0.5 -> 0 | DU8: =SUMPRODUCT(--(DU$3:DU$3-$FM$3:$FM$3)^2)^0.5 -> 0 | DV8: =SUMPRODUCT(--(DV$3:DV$3-$FN$3:$FN$3)^2)^0.5 -> 0 | DW8: =SUMPRODUCT(--(DW$3:DW$3-$FK$3:$FK$3)^2)^0.5 -> 0 | DX8: =SUMPRODUCT(--(DX$3:DX$3-$FL$3:$FL$3)^2)^0.5 -> 0 | DZ8: =SUMPRODUCT(--(DZ$3:DZ$3-$FM$3:$FM$3)^2)^0.5 -> 0 | EA8: =SUMPRODUCT(--(EA$3:EA$3-$FN$3:$FN$3)^2)^0.5 -> 0 | EB8: =SUMPRODUCT(--(EB$3:EB$3-$FK$3:$FK$3)^2)^0.5 -> 0 | EC8: =SUMPRODUCT(--(EC$3:EC$3-$FL$3:$FL$3)^2)^0.5 -> 0 | EE8: =SUMPRODUCT(--(EE$3:EE$3-$FM$3:$FM$3)^2)^0.5 -> 0 | EF8: =SUMPRODUCT(--(EF$3:EF$3-$FN$3:$FN$3)^2)^0.5 -> 0 | EG8: =SUMPRODUCT(--(EG$3:EG$3-$FK$3:$FK$3)^2)^0.5 -> 0 | EH8: =SUMPRODUCT(--(EH$3:EH$3-$FL$3:$FL$3)^2)^0.5 -> 0 | EJ8: =SUMPRODUCT(--(EJ$3:EJ$3-$FM$3:$FM$3)^2)^0.5 -> 0 | EK8: =SUMPRODUCT(--(EK$3:EK$3-$FN$3:$FN$3)^2)^0.5 -> 0 | EL8: =SUMPRODUCT(--(EL$3:EL$3-$FK$3:$FK$3)^2)^0.5 -> 0 | EM8: =SUMPRODUCT(--(EM$3:EM$3-$FL$3:$FL$3)^2)^0.5 -> 0 | EO8: =SUMPRODUCT(--(EO$3:EO$3-$FM$3:$FM$3)^2)^0.5 -> 0 | EP8: =SUMPRODUCT(--(EP$3:EP$3-$FN$3:$FN$3)^2)^0.5 -> 0 | EQ8: =SUMPRODUCT(--(EQ$3:EQ$3-$FK$3:$FK$3)^2)^0.5 -> 0 | ER8: =SUMPRODUCT(--(ER$3:ER$3-$FL$3:$FL$3)^2)^0.5 -> 0 | ET8: =SUMPRODUCT(--(ET$3:ET$3-$FM$3:$FM$3)^2)^0.5 -> 0 | EU8: =SUMPRODUCT(--(EU$3:EU$3-$FN$3:$FN$3)^2)^0.5 -> 0 | EV8: =SUMPRODUCT(--(EV$3:EV$3-$FK$3:$FK$3)^2)^0.5 -> 0 | EW8: =SUMPRODUCT(--(EW$3:EW$3-$FL$3:$FL$3)^2)^0.5 -> 0 | EY8: =SUMPRODUCT(--(EY$3:EY$3-$FM$3:$FM$3)^2)^0.5 -> 0 | EZ8: =SUMPRODUCT(--(EZ$3:EZ$3-$FN$3:$FN$3)^2)^0.5 -> 0 | FA8: =SUMPRODUCT(--(FA$3:FA$3-$FK$3:$FK$3)^2)^0.5 -> 0 | FB8: =SUMPRODUCT(--(FB$3:FB$3-$FL$3:$FL$3)^2)^0.5 -> 0 | FD8: =SUMPRODUCT(--(FD$3:FD$3-$FM$3:$FM$3)^2)^0.5 -> 0 | FE8: =SUMPRODUCT(--(FE$3:FE$3-$FN$3:$FN$3)^2)^0.5 -> 0 | FF8: =SUMPRODUCT(--(FF$3:FF$3-$FK$3:$FK$3)^2)^0.5 -> 0 | FG8: =SUMPRODUCT(--(FG$3:FG$3-$FL$3:$FL$3)^2)^0.5 -> 0 | FI8: =SUMPRODUCT(--(FI$3:FI$3-$FM$3:$FM$3)^2)^0.5 -> 0 | FJ8: =SUMPRODUCT(--(FJ$3:FJ$3-$FN$3:$FN$3)^2)^0.5 -> 0
A9: BEST | B9: =SUMPRODUCT(NOT(ISBLANK(B$3:B$3))*(B$3:B$3=$FK$3:$FK$3)) -> 0 | C9: =SUMPRODUCT(NOT(ISBLANK(C$3:C$3))*(C$3:C$3=$FL$3:$FL$3)) -> 0 | E9: =SUMPRODUCT(NOT(ISBLANK(E$3:E$3))*(E$3:E$3=$FM$3:$FM$3)) -> 0 | F9: =SUMPRODUCT(NOT(ISBLANK(F$3:F$3))*(F$3:F$3=$FN$3:$FN$3)) -> 0 | G9: =SUMPRODUCT(NOT(ISBLANK(G$3:G$3))*(G$3:G$3=$FK$3:$FK$3)) -> 0 | H9: =SUMPRODUCT(NOT(ISBLANK(H$3:H$3))*(H$3:H$3=$FL$3:$FL$3)) -> 0 | J9: =SUMPRODUCT(NOT(ISBLANK(J$3:J$3))*(J$3:J$3=$FM$3:$FM$3)) -> 0 | K9: =SUMPRODUCT(NOT(ISBLANK(K$3:K$3))*(K$3:K$3=$FN$3:$FN$3)) -> 0 | L9: =SUMPRODUCT(NOT(ISBLANK(L$3:L$3))*(L$3:L$3=$FK$3:$FK$3)) -> 0 | M9: =SUMPRODUCT(NOT(ISBLANK(M$3:M$3))*(M$3:M$3=$FL$3:$FL$3)) -> 0 | O9: =SUMPRODUCT(NOT(ISBLANK(O$3:O$3))*(O$3:O$3=$FM$3:$FM$3)) -> 0 | P9: =SUMPRODUCT(NOT(ISBLANK(P$3:P$3))*(P$3:P$3=$FN$3:$FN$3)) -> 0 | Q9: =SUMPRODUCT(NOT(ISBLANK(Q$3:Q$3))*(Q$3:Q$3=$FK$3:$FK$3)) -> 0 | R9: =SUMPRODUCT(NOT(ISBLANK(R$3:R$3))*(R$3:R$3=$FL$3:$FL$3)) -> 0 | T9: =SUMPRODUCT(NOT(ISBLANK(T$3:T$3))*(T$3:T$3=$FM$3:$FM$3)) -> 0 | U9: =SUMPRODUCT(NOT(ISBLANK(U$3:U$3))*(U$3:U$3=$FN$3:$FN$3)) -> 0 | V9: =SUMPRODUCT(NOT(ISBLANK(V$3:V$3))*(V$3:V$3=$FK$3:$FK$3)) -> 0 | W9: =SUMPRODUCT(NOT(ISBLANK(W$3:W$3))*(W$3:W$3=$FL$3:$FL$3)) -> 0 | Y9: =SUMPRODUCT(NOT(ISBLANK(Y$3:Y$3))*(Y$3:Y$3=$FM$3:$FM$3)) -> 0 | Z9: =SUMPRODUCT(NOT(ISBLANK(Z$3:Z$3))*(Z$3:Z$3=$FN$3:$FN$3)) -> 0 | AA9: =SUMPRODUCT(NOT(ISBLANK(AA$3:AA$3))*(AA$3:AA$3=$FK$3:$FK$3)) -> 0 | AB9: =SUMPRODUCT(NOT(ISBLANK(AB$3:AB$3))*(AB$3:AB$3=$FL$3:$FL$3)) -> 0 | AD9: =SUMPRODUCT(NOT(ISBLANK(AD$3:AD$3))*(AD$3:AD$3=$FM$3:$FM$3)) -> 0 | AE9: =SUMPRODUCT(NOT(ISBLANK(AE$3:AE$3))*(AE$3:AE$3=$FN$3:$FN$3)) -> 0 | AF9: =SUMPRODUCT(NOT(ISBLANK(AF$3:AF$3))*(AF$3:AF$3=$FK$3:$FK$3)) -> 0 | AG9: =SUMPRODUCT(NOT(ISBLANK(AG$3:AG$3))*(AG$3:AG$3=$FL$3:$FL$3)) -> 0 | AI9: =SUMPRODUCT(NOT(ISBLANK(AI$3:AI$3))*(AI$3:AI$3=$FM$3:$FM$3)) -> 0 | AJ9: =SUMPRODUCT(NOT(ISBLANK(AJ$3:AJ$3))*(AJ$3:AJ$3=$FN$3:$FN$3)) -> 0 | AK9: =SUMPRODUCT(NOT(ISBLANK(AK$3:AK$3))*(AK$3:AK$3=$FK$3:$FK$3)) -> 0 | AL9: =SUMPRODUCT(NOT(ISBLANK(AL$3:AL$3))*(AL$3:AL$3=$FL$3:$FL$3)) -> 0 | AN9: =SUMPRODUCT(NOT(ISBLANK(AN$3:AN$3))*(AN$3:AN$3=$FM$3:$FM$3)) -> 0 | AO9: =SUMPRODUCT(NOT(ISBLANK(AO$3:AO$3))*(AO$3:AO$3=$FN$3:$FN$3)) -> 0 | AP9: =SUMPRODUCT(NOT(ISBLANK(AP$3:AP$3))*(AP$3:AP$3=$FK$3:$FK$3)) -> 0 | AQ9: =SUMPRODUCT(NOT(ISBLANK(AQ$3:AQ$3))*(AQ$3:AQ$3=$FL$3:$FL$3)) -> 0 | AS9: =SUMPRODUCT(NOT(ISBLANK(AS$3:AS$3))*(AS$3:AS$3=$FM$3:$FM$3)) -> 0 | AT9: =SUMPRODUCT(NOT(ISBLANK(AT$3:AT$3))*(AT$3:AT$3=$FN$3:$FN$3)) -> 0 | AU9: =SUMPRODUCT(NOT(ISBLANK(AU$3:AU$3))*(AU$3:AU$3=$FK$3:$FK$3)) -> 0 | AV9: =SUMPRODUCT(NOT(ISBLANK(AV$3:AV$3))*(AV$3:AV$3=$FL$3:$FL$3)) -> 0 | AX9: =SUMPRODUCT(NOT(ISBLANK(AX$3:AX$3))*(AX$3:AX$3=$FM$3:$FM$3)) -> 0 | AY9: =SUMPRODUCT(NOT(ISBLANK(AY$3:AY$3))*(AY$3:AY$3=$FN$3:$FN$3)) -> 0 | AZ9: =SUMPRODUCT(NOT(ISBLANK(AZ$3:AZ$3))*(AZ$3:AZ$3=$FK$3:$FK$3)) -> 0 | BA9: =SUMPRODUCT(NOT(ISBLANK(BA$3:BA$3))*(BA$3:BA$3=$FL$3:$FL$3)) -> 0 | BC9: =SUMPRODUCT(NOT(ISBLANK(BC$3:BC$3))*(BC$3:BC$3=$FM$3:$FM$3)) -> 0 | BD9: =SUMPRODUCT(NOT(ISBLANK(BD$3:BD$3))*(BD$3:BD$3=$FN$3:$FN$3)) -> 0 | BE9: =SUMPRODUCT(NOT(ISBLANK(BE$3:BE$3))*(BE$3:BE$3=$FK$3:$FK$3)) -> 0 | BF9: =SUMPRODUCT(NOT(ISBLANK(BF$3:BF$3))*(BF$3:BF$3=$FL$3:$FL$3)) -> 0 | BH9: =SUMPRODUCT(NOT(ISBLANK(BH$3:BH$3))*(BH$3:BH$3=$FM$3:$FM$3)) -> 0 | BI9: =SUMPRODUCT(NOT(ISBLANK(BI$3:BI$3))*(BI$3:BI$3=$FN$3:$FN$3)) -> 0 | BJ9: =SUMPRODUCT(NOT(ISBLANK(BJ$3:BJ$3))*(BJ$3:BJ$3=$FK$3:$FK$3)) -> 0 | BK9: =SUMPRODUCT(NOT(ISBLANK(BK$3:BK$3))*(BK$3:BK$3=$FL$3:$FL$3)) -> 0 | BM9: =SUMPRODUCT(NOT(ISBLANK(BM$3:BM$3))*(BM$3:BM$3=$FM$3:$FM$3)) -> 0 | BN9: =SUMPRODUCT(NOT(ISBLANK(BN$3:BN$3))*(BN$3:BN$3=$FN$3:$FN$3)) -> 0 | BO9: =SUMPRODUCT(NOT(ISBLANK(BO$3:BO$3))*(BO$3:BO$3=$FK$3:$FK$3)) -> 0 | BP9: =SUMPRODUCT(NOT(ISBLANK(BP$3:BP$3))*(BP$3:BP$3=$FL$3:$FL$3)) -> 0 | BR9: =SUMPRODUCT(NOT(ISBLANK(BR$3:BR$3))*(BR$3:BR$3=$FM$3:$FM$3)) -> 0 | BS9: =SUMPRODUCT(NOT(ISBLANK(BS$3:BS$3))*(BS$3:BS$3=$FN$3:$FN$3)) -> 0 | BT9: =SUMPRODUCT(NOT(ISBLANK(BT$3:BT$3))*(BT$3:BT$3=$FK$3:$FK$3)) -> 0 | BU9: =SUMPRODUCT(NOT(ISBLANK(BU$3:BU$3))*(BU$3:BU$3=$FL$3:$FL$3)) -> 0 | BW9: =SUMPRODUCT(NOT(ISBLANK(BW$3:BW$3))*(BW$3:BW$3=$FM$3:$FM$3)) -> 0 | BX9: =SUMPRODUCT(NOT(ISBLANK(BX$3:BX$3))*(BX$3:BX$3=$FN$3:$FN$3)) -> 0 | BY9: =SUMPRODUCT(NOT(ISBLANK(BY$3:BY$3))*(BY$3:BY$3=$FK$3:$FK$3)) -> 0 | BZ9: =SUMPRODUCT(NOT(ISBLANK(BZ$3:BZ$3))*(BZ$3:BZ$3=$FL$3:$FL$3)) -> 0 | CB9: =SUMPRODUCT(NOT(ISBLANK(CB$3:CB$3))*(CB$3:CB$3=$FM$3:$FM$3)) -> 0 | CC9: =SUMPRODUCT(NOT(ISBLANK(CC$3:CC$3))*(CC$3:CC$3=$FN$3:$FN$3)) -> 0 | CD9: =SUMPRODUCT(NOT(ISBLANK(CD$3:CD$3))*(CD$3:CD$3=$FK$3:$FK$3)) -> 0 | CE9: =SUMPRODUCT(NOT(ISBLANK(CE$3:CE$3))*(CE$3:CE$3=$FL$3:$FL$3)) -> 0 | CG9: =SUMPRODUCT(NOT(ISBLANK(CG$3:CG$3))*(CG$3:CG$3=$FM$3:$FM$3)) -> 0 | CH9: =SUMPRODUCT(NOT(ISBLANK(CH$3:CH$3))*(CH$3:CH$3=$FN$3:$FN$3)) -> 0 | CI9: =SUMPRODUCT(NOT(ISBLANK(CI$3:CI$3))*(CI$3:CI$3=$FK$3:$FK$3)) -> 0 | CJ9: =SUMPRODUCT(NOT(ISBLANK(CJ$3:CJ$3))*(CJ$3:CJ$3=$FL$3:$FL$3)) -> 0 | CL9: =SUMPRODUCT(NOT(ISBLANK(CL$3:CL$3))*(CL$3:CL$3=$FM$3:$FM$3)) -> 0 | CM9: =SUMPRODUCT(NOT(ISBLANK(CM$3:CM$3))*(CM$3:CM$3=$FN$3:$FN$3)) -> 0 | CN9: =SUMPRODUCT(NOT(ISBLANK(CN$3:CN$3))*(CN$3:CN$3=$FK$3:$FK$3)) -> 0 | CO9: =SUMPRODUCT(NOT(ISBLANK(CO$3:CO$3))*(CO$3:CO$3=$FL$3:$FL$3)) -> 0 | CQ9: =SUMPRODUCT(NOT(ISBLANK(CQ$3:CQ$3))*(CQ$3:CQ$3=$FM$3:$FM$3)) -> 0 | CR9: =SUMPRODUCT(NOT(ISBLANK(CR$3:CR$3))*(CR$3:CR$3=$FN$3:$FN$3)) -> 0 | CS9: =SUMPRODUCT(NOT(ISBLANK(CS$3:CS$3))*(CS$3:CS$3=$FK$3:$FK$3)) -> 0 | CT9: =SUMPRODUCT(NOT(ISBLANK(CT$3:CT$3))*(CT$3:CT$3=$FL$3:$FL$3)) -> 0 | CV9: =SUMPRODUCT(NOT(ISBLANK(CV$3:CV$3))*(CV$3:CV$3=$FM$3:$FM$3)) -> 0 | CW9: =SUMPRODUCT(NOT(ISBLANK(CW$3:CW$3))*(CW$3:CW$3=$FN$3:$FN$3)) -> 0 | CX9: =SUMPRODUCT(NOT(ISBLANK(CX$3:CX$3))*(CX$3:CX$3=$FK$3:$FK$3)) -> 0 | CY9: =SUMPRODUCT(NOT(ISBLANK(CY$3:CY$3))*(CY$3:CY$3=$FL$3:$FL$3)) -> 0 | DA9: =SUMPRODUCT(NOT(ISBLANK(DA$3:DA$3))*(DA$3:DA$3=$FM$3:$FM$3)) -> 0 | DB9: =SUMPRODUCT(NOT(ISBLANK(DB$3:DB$3))*(DB$3:DB$3=$FN$3:$FN$3)) -> 0 | DC9: =SUMPRODUCT(NOT(ISBLANK(DC$3:DC$3))*(DC$3:DC$3=$FK$3:$FK$3)) -> 0 | DD9: =SUMPRODUCT(NOT(ISBLANK(DD$3:DD$3))*(DD$3:DD$3=$FL$3:$FL$3)) -> 0 | DF9: =SUMPRODUCT(NOT(ISBLANK(DF$3:DF$3))*(DF$3:DF$3=$FM$3:$FM$3)) -> 0 | DG9: =SUMPRODUCT(NOT(ISBLANK(DG$3:DG$3))*(DG$3:DG$3=$FN$3:$FN$3)) -> 0 | DH9: =SUMPRODUCT(NOT(ISBLANK(DH$3:DH$3))*(DH$3:DH$3=$FK$3:$FK$3)) -> 0 | DI9: =SUMPRODUCT(NOT(ISBLANK(DI$3:DI$3))*(DI$3:DI$3=$FL$3:$FL$3)) -> 0 | DK9: =SUMPRODUCT(NOT(ISBLANK(DK$3:DK$3))*(DK$3:DK$3=$FM$3:$FM$3)) -> 0 | DL9: =SUMPRODUCT(NOT(ISBLANK(DL$3:DL$3))*(DL$3:DL$3=$FN$3:$FN$3)) -> 0 | DM9: =SUMPRODUCT(NOT(ISBLANK(DM$3:DM$3))*(DM$3:DM$3=$FK$3:$FK$3)) -> 0 | DN9: =SUMPRODUCT(NOT(ISBLANK(DN$3:DN$3))*(DN$3:DN$3=$FL$3:$FL$3)) -> 0 | DP9: =SUMPRODUCT(NOT(ISBLANK(DP$3:DP$3))*(DP$3:DP$3=$FM$3:$FM$3)) -> 0 | DQ9: =SUMPRODUCT(NOT(ISBLANK(DQ$3:DQ$3))*(DQ$3:DQ$3=$FN$3:$FN$3)) -> 0 | DR9: =SUMPRODUCT(NOT(ISBLANK(DR$3:DR$3))*(DR$3:DR$3=$FK$3:$FK$3)) -> 0 | DS9: =SUMPRODUCT(NOT(ISBLANK(DS$3:DS$3))*(DS$3:DS$3=$FL$3:$FL$3)) -> 0 | DU9: =SUMPRODUCT(NOT(ISBLANK(DU$3:DU$3))*(DU$3:DU$3=$FM$3:$FM$3)) -> 0 | DV9: =SUMPRODUCT(NOT(ISBLANK(DV$3:DV$3))*(DV$3:DV$3=$FN$3:$FN$3)) -> 0 | DW9: =SUMPRODUCT(NOT(ISBLANK(DW$3:DW$3))*(DW$3:DW$3=$FK$3:$FK$3)) -> 0 | DX9: =SUMPRODUCT(NOT(ISBLANK(DX$3:DX$3))*(DX$3:DX$3=$FL$3:$FL$3)) -> 0 | DZ9: =SUMPRODUCT(NOT(ISBLANK(DZ$3:DZ$3))*(DZ$3:DZ$3=$FM$3:$FM$3)) -> 0 | EA9: =SUMPRODUCT(NOT(ISBLANK(EA$3:EA$3))*(EA$3:EA$3=$FN$3:$FN$3)) -> 0 | EB9: =SUMPRODUCT(NOT(ISBLANK(EB$3:EB$3))*(EB$3:EB$3=$FK$3:$FK$3)) -> 0 | EC9: =SUMPRODUCT(NOT(ISBLANK(EC$3:EC$3))*(EC$3:EC$3=$FL$3:$FL$3)) -> 0 | EE9: =SUMPRODUCT(NOT(ISBLANK(EE$3:EE$3))*(EE$3:EE$3=$FM$3:$FM$3)) -> 0 | EF9: =SUMPRODUCT(NOT(ISBLANK(EF$3:EF$3))*(EF$3:EF$3=$FN$3:$FN$3)) -> 0 | EG9: =SUMPRODUCT(NOT(ISBLANK(EG$3:EG$3))*(EG$3:EG$3=$FK$3:$FK$3)) -> 0 | EH9: =SUMPRODUCT(NOT(ISBLANK(EH$3:EH$3))*(EH$3:EH$3=$FL$3:$FL$3)) -> 0 | EJ9: =SUMPRODUCT(NOT(ISBLANK(EJ$3:EJ$3))*(EJ$3:EJ$3=$FM$3:$FM$3)) -> 0 | EK9: =SUMPRODUCT(NOT(ISBLANK(EK$3:EK$3))*(EK$3:EK$3=$FN$3:$FN$3)) -> 0 | EL9: =SUMPRODUCT(NOT(ISBLANK(EL$3:EL$3))*(EL$3:EL$3=$FK$3:$FK$3)) -> 0 | EM9: =SUMPRODUCT(NOT(ISBLANK(EM$3:EM$3))*(EM$3:EM$3=$FL$3:$FL$3)) -> 0 | EO9: =SUMPRODUCT(NOT(ISBLANK(EO$3:EO$3))*(EO$3:EO$3=$FM$3:$FM$3)) -> 0 | EP9: =SUMPRODUCT(NOT(ISBLANK(EP$3:EP$3))*(EP$3:EP$3=$FN$3:$FN$3)) -> 0 | EQ9: =SUMPRODUCT(NOT(ISBLANK(EQ$3:EQ$3))*(EQ$3:EQ$3=$FK$3:$FK$3)) -> 0 | ER9: =SUMPRODUCT(NOT(ISBLANK(ER$3:ER$3))*(ER$3:ER$3=$FL$3:$FL$3)) -> 0 | ET9: =SUMPRODUCT(NOT(ISBLANK(ET$3:ET$3))*(ET$3:ET$3=$FM$3:$FM$3)) -> 0 | EU9: =SUMPRODUCT(NOT(ISBLANK(EU$3:EU$3))*(EU$3:EU$3=$FN$3:$FN$3)) -> 0 | EV9: =SUMPRODUCT(NOT(ISBLANK(EV$3:EV$3))*(EV$3:EV$3=$FK$3:$FK$3)) -> 0 | EW9: =SUMPRODUCT(NOT(ISBLANK(EW$3:EW$3))*(EW$3:EW$3=$FL$3:$FL$3)) -> 0 | EY9: =SUMPRODUCT(NOT(ISBLANK(EY$3:EY$3))*(EY$3:EY$3=$FM$3:$FM$3)) -> 0 | EZ9: =SUMPRODUCT(NOT(ISBLANK(EZ$3:EZ$3))*(EZ$3:EZ$3=$FN$3:$FN$3)) -> 0 | FA9: =SUMPRODUCT(NOT(ISBLANK(FA$3:FA$3))*(FA$3:FA$3=$FK$3:$FK$3)) -> 0 | FB9: =SUMPRODUCT(NOT(ISBLANK(FB$3:FB$3))*(FB$3:FB$3=$FL$3:$FL$3)) -> 0 | FD9: =SUMPRODUCT(NOT(ISBLANK(FD$3:FD$3))*(FD$3:FD$3=$FM$3:$FM$3)) -> 0 | FE9: =SUMPRODUCT(NOT(ISBLANK(FE$3:FE$3))*(FE$3:FE$3=$FN$3:$FN$3)) -> 0 | FF9: =SUMPRODUCT(NOT(ISBLANK(FF$3:FF$3))*(FF$3:FF$3=$FK$3:$FK$3)) -> 0 | FG9: =SUMPRODUCT(NOT(ISBLANK(FG$3:FG$3))*(FG$3:FG$3=$FL$3:$FL$3)) -> 0 | FI9: =SUMPRODUCT(NOT(ISBLANK(FI$3:FI$3))*(FI$3:FI$3=$FM$3:$FM$3)) -> 0 | FJ9: =SUMPRODUCT(NOT(ISBLANK(FJ$3:FJ$3))*(FJ$3:FJ$3=$FN$3:$FN$3)) -> 0
A10: BETTER | B10: =SUMPRODUCT(NOT(ISBLANK(B$3:B$3))*(B$3:B$3<$FO$3:$FO$3)) -> 0 | C10: =SUMPRODUCT(NOT(ISBLANK(C$3:C$3))*(C$3:C$3<$FP$3:$FP$3)) -> 0 | E10: =SUMPRODUCT(NOT(ISBLANK(E$3:E$3))*(E$3:E$3<$FQ$3:$FQ$3)) -> 0 | F10: =SUMPRODUCT(NOT(ISBLANK(F$3:F$3))*(F$3:F$3<$FR$3:$FR$3)) -> 0 | G10: =SUMPRODUCT(NOT(ISBLANK(G$3:G$3))*(G$3:G$3<$FO$3:$FO$3)) -> 0 | H10: =SUMPRODUCT(NOT(ISBLANK(H$3:H$3))*(H$3:H$3<$FP$3:$FP$3)) -> 0 | J10: =SUMPRODUCT(NOT(ISBLANK(J$3:J$3))*(J$3:J$3<$FQ$3:$FQ$3)) -> 0 | K10: =SUMPRODUCT(NOT(ISBLANK(K$3:K$3))*(K$3:K$3<$FR$3:$FR$3)) -> 0 | L10: =SUMPRODUCT(NOT(ISBLANK(L$3:L$3))*(L$3:L$3<$FO$3:$FO$3)) -> 0 | M10: =SUMPRODUCT(NOT(ISBLANK(M$3:M$3))*(M$3:M$3<$FP$3:$FP$3)) -> 0 | O10: =SUMPRODUCT(NOT(ISBLANK(O$3:O$3))*(O$3:O$3<$FQ$3:$FQ$3)) -> 0 | P10: =SUMPRODUCT(NOT(ISBLANK(P$3:P$3))*(P$3:P$3<$FR$3:$FR$3)) -> 0 | Q10: =SUMPRODUCT(NOT(ISBLANK(Q$3:Q$3))*(Q$3:Q$3<$FO$3:$FO$3)) -> 0 | R10: =SUMPRODUCT(NOT(ISBLANK(R$3:R$3))*(R$3:R$3<$FP$3:$FP$3)) -> 0 | T10: =SUMPRODUCT(NOT(ISBLANK(T$3:T$3))*(T$3:T$3<$FQ$3:$FQ$3)) -> 0 | U10: =SUMPRODUCT(NOT(ISBLANK(U$3:U$3))*(U$3:U$3<$FR$3:$FR$3)) -> 0 | V10: =SUMPRODUCT(NOT(ISBLANK(V$3:V$3))*(V$3:V$3<$FO$3:$FO$3)) -> 0 | W10: =SUMPRODUCT(NOT(ISBLANK(W$3:W$3))*(W$3:W$3<$FP$3:$FP$3)) -> 0 | Y10: =SUMPRODUCT(NOT(ISBLANK(Y$3:Y$3))*(Y$3:Y$3<$FQ$3:$FQ$3)) -> 0 | Z10: =SUMPRODUCT(NOT(ISBLANK(Z$3:Z$3))*(Z$3:Z$3<$FR$3:$FR$3)) -> 0 | AA10: =SUMPRODUCT(NOT(ISBLANK(AA$3:AA$3))*(AA$3:AA$3<$FO$3:$FO$3)) -> 0 | AB10: =SUMPRODUCT(NOT(ISBLANK(AB$3:AB$3))*(AB$3:AB$3<$FP$3:$FP$3)) -> 0 | AD10: =SUMPRODUCT(NOT(ISBLANK(AD$3:AD$3))*(AD$3:AD$3<$FQ$3:$FQ$3)) -> 0 | AE10: =SUMPRODUCT(NOT(ISBLANK(AE$3:AE$3))*(AE$3:AE$3<$FR$3:$FR$3)) -> 0 | AF10: =SUMPRODUCT(NOT(ISBLANK(AF$3:AF$3))*(AF$3:AF$3<$FO$3:$FO$3)) -> 0 | AG10: =SUMPRODUCT(NOT(ISBLANK(AG$3:AG$3))*(AG$3:AG$3<$FP$3:$FP$3)) -> 0 | AI10: =SUMPRODUCT(NOT(ISBLANK(AI$3:AI$3))*(AI$3:AI$3<$FQ$3:$FQ$3)) -> 0 | AJ10: =SUMPRODUCT(NOT(ISBLANK(AJ$3:AJ$3))*(AJ$3:AJ$3<$FR$3:$FR$3)) -> 0 | AK10: =SUMPRODUCT(NOT(ISBLANK(AK$3:AK$3))*(AK$3:AK$3<$FO$3:$FO$3)) -> 0 | AL10: =SUMPRODUCT(NOT(ISBLANK(AL$3:AL$3))*(AL$3:AL$3<$FP$3:$FP$3)) -> 0 | AN10: =SUMPRODUCT(NOT(ISBLANK(AN$3:AN$3))*(AN$3:AN$3<$FQ$3:$FQ$3)) -> 0 | AO10: =SUMPRODUCT(NOT(ISBLANK(AO$3:AO$3))*(AO$3:AO$3<$FR$3:$FR$3)) -> 0 | AP10: =SUMPRODUCT(NOT(ISBLANK(AP$3:AP$3))*(AP$3:AP$3<$FO$3:$FO$3)) -> 0 | AQ10: =SUMPRODUCT(NOT(ISBLANK(AQ$3:AQ$3))*(AQ$3:AQ$3<$FP$3:$FP$3)) -> 0 | AS10: =SUMPRODUCT(NOT(ISBLANK(AS$3:AS$3))*(AS$3:AS$3<$FQ$3:$FQ$3)) -> 0 | AT10: =SUMPRODUCT(NOT(ISBLANK(AT$3:AT$3))*(AT$3:AT$3<$FR$3:$FR$3)) -> 0 | AU10: =SUMPRODUCT(NOT(ISBLANK(AU$3:AU$3))*(AU$3:AU$3<$FO$3:$FO$3)) -> 0 | AV10: =SUMPRODUCT(NOT(ISBLANK(AV$3:AV$3))*(AV$3:AV$3<$FP$3:$FP$3)) -> 0 | AX10: =SUMPRODUCT(NOT(ISBLANK(AX$3:AX$3))*(AX$3:AX$3<$FQ$3:$FQ$3)) -> 0 | AY10: =SUMPRODUCT(NOT(ISBLANK(AY$3:AY$3))*(AY$3:AY$3<$FR$3:$FR$3)) -> 0 | AZ10: =SUMPRODUCT(NOT(ISBLANK(AZ$3:AZ$3))*(AZ$3:AZ$3<$FO$3:$FO$3)) -> 0 | BA10: =SUMPRODUCT(NOT(ISBLANK(BA$3:BA$3))*(BA$3:BA$3<$FP$3:$FP$3)) -> 0 | BC10: =SUMPRODUCT(NOT(ISBLANK(BC$3:BC$3))*(BC$3:BC$3<$FQ$3:$FQ$3)) -> 0 | BD10: =SUMPRODUCT(NOT(ISBLANK(BD$3:BD$3))*(BD$3:BD$3<$FR$3:$FR$3)) -> 0 | BE10: =SUMPRODUCT(NOT(ISBLANK(BE$3:BE$3))*(BE$3:BE$3<$FO$3:$FO$3)) -> 0 | BF10: =SUMPRODUCT(NOT(ISBLANK(BF$3:BF$3))*(BF$3:BF$3<$FP$3:$FP$3)) -> 0 | BH10: =SUMPRODUCT(NOT(ISBLANK(BH$3:BH$3))*(BH$3:BH$3<$FQ$3:$FQ$3)) -> 0 | BI10: =SUMPRODUCT(NOT(ISBLANK(BI$3:BI$3))*(BI$3:BI$3<$FR$3:$FR$3)) -> 0 | BJ10: =SUMPRODUCT(NOT(ISBLANK(BJ$3:BJ$3))*(BJ$3:BJ$3<$FO$3:$FO$3)) -> 0 | BK10: =SUMPRODUCT(NOT(ISBLANK(BK$3:BK$3))*(BK$3:BK$3<$FP$3:$FP$3)) -> 0 | BM10: =SUMPRODUCT(NOT(ISBLANK(BM$3:BM$3))*(BM$3:BM$3<$FQ$3:$FQ$3)) -> 0 | BN10: =SUMPRODUCT(NOT(ISBLANK(BN$3:BN$3))*(BN$3:BN$3<$FR$3:$FR$3)) -> 0 | BO10: =SUMPRODUCT(NOT(ISBLANK(BO$3:BO$3))*(BO$3:BO$3<$FO$3:$FO$3)) -> 0 | BP10: =SUMPRODUCT(NOT(ISBLANK(BP$3:BP$3))*(BP$3:BP$3<$FP$3:$FP$3)) -> 0 | BR10: =SUMPRODUCT(NOT(ISBLANK(BR$3:BR$3))*(BR$3:BR$3<$FQ$3:$FQ$3)) -> 0 | BS10: =SUMPRODUCT(NOT(ISBLANK(BS$3:BS$3))*(BS$3:BS$3<$FR$3:$FR$3)) -> 0 | BT10: =SUMPRODUCT(NOT(ISBLANK(BT$3:BT$3))*(BT$3:BT$3<$FO$3:$FO$3)) -> 0 | BU10: =SUMPRODUCT(NOT(ISBLANK(BU$3:BU$3))*(BU$3:BU$3<$FP$3:$FP$3)) -> 0 | BW10: =SUMPRODUCT(NOT(ISBLANK(BW$3:BW$3))*(BW$3:BW$3<$FQ$3:$FQ$3)) -> 0 | BX10: =SUMPRODUCT(NOT(ISBLANK(BX$3:BX$3))*(BX$3:BX$3<$FR$3:$FR$3)) -> 0 | BY10: =SUMPRODUCT(NOT(ISBLANK(BY$3:BY$3))*(BY$3:BY$3<$FO$3:$FO$3)) -> 0 | BZ10: =SUMPRODUCT(NOT(ISBLANK(BZ$3:BZ$3))*(BZ$3:BZ$3<$FP$3:$FP$3)) -> 0 | CB10: =SUMPRODUCT(NOT(ISBLANK(CB$3:CB$3))*(CB$3:CB$3<$FQ$3:$FQ$3)) -> 0 | CC10: =SUMPRODUCT(NOT(ISBLANK(CC$3:CC$3))*(CC$3:CC$3<$FR$3:$FR$3)) -> 0 | CD10: =SUMPRODUCT(NOT(ISBLANK(CD$3:CD$3))*(CD$3:CD$3<$FO$3:$FO$3)) -> 0 | CE10: =SUMPRODUCT(NOT(ISBLANK(CE$3:CE$3))*(CE$3:CE$3<$FP$3:$FP$3)) -> 0 | CG10: =SUMPRODUCT(NOT(ISBLANK(CG$3:CG$3))*(CG$3:CG$3<$FQ$3:$FQ$3)) -> 0 | CH10: =SUMPRODUCT(NOT(ISBLANK(CH$3:CH$3))*(CH$3:CH$3<$FR$3:$FR$3)) -> 0 | CI10: =SUMPRODUCT(NOT(ISBLANK(CI$3:CI$3))*(CI$3:CI$3<$FO$3:$FO$3)) -> 0 | CJ10: =SUMPRODUCT(NOT(ISBLANK(CJ$3:CJ$3))*(CJ$3:CJ$3<$FP$3:$FP$3)) -> 0 | CL10: =SUMPRODUCT(NOT(ISBLANK(CL$3:CL$3))*(CL$3:CL$3<$FQ$3:$FQ$3)) -> 0 | CM10: =SUMPRODUCT(NOT(ISBLANK(CM$3:CM$3))*(CM$3:CM$3<$FR$3:$FR$3)) -> 0 | CN10: =SUMPRODUCT(NOT(ISBLANK(CN$3:CN$3))*(CN$3:CN$3<$FO$3:$FO$3)) -> 0 | CO10: =SUMPRODUCT(NOT(ISBLANK(CO$3:CO$3))*(CO$3:CO$3<$FP$3:$FP$3)) -> 0 | CQ10: =SUMPRODUCT(NOT(ISBLANK(CQ$3:CQ$3))*(CQ$3:CQ$3<$FQ$3:$FQ$3)) -> 0 | CR10: =SUMPRODUCT(NOT(ISBLANK(CR$3:CR$3))*(CR$3:CR$3<$FR$3:$FR$3)) -> 0 | CS10: =SUMPRODUCT(NOT(ISBLANK(CS$3:CS$3))*(CS$3:CS$3<$FO$3:$FO$3)) -> 0 | CT10: =SUMPRODUCT(NOT(ISBLANK(CT$3:CT$3))*(CT$3:CT$3<$FP$3:$FP$3)) -> 0 | CV10: =SUMPRODUCT(NOT(ISBLANK(CV$3:CV$3))*(CV$3:CV$3<$FQ$3:$FQ$3)) -> 0 | CW10: =SUMPRODUCT(NOT(ISBLANK(CW$3:CW$3))*(CW$3:CW$3<$FR$3:$FR$3)) -> 0 | CX10: =SUMPRODUCT(NOT(ISBLANK(CX$3:CX$3))*(CX$3:CX$3<$FO$3:$FO$3)) -> 0 | CY10: =SUMPRODUCT(NOT(ISBLANK(CY$3:CY$3))*(CY$3:CY$3<$FP$3:$FP$3)) -> 0 | DA10: =SUMPRODUCT(NOT(ISBLANK(DA$3:DA$3))*(DA$3:DA$3<$FQ$3:$FQ$3)) -> 0 | DB10: =SUMPRODUCT(NOT(ISBLANK(DB$3:DB$3))*(DB$3:DB$3<$FR$3:$FR$3)) -> 0 | DC10: =SUMPRODUCT(NOT(ISBLANK(DC$3:DC$3))*(DC$3:DC$3<$FO$3:$FO$3)) -> 0 | DD10: =SUMPRODUCT(NOT(ISBLANK(DD$3:DD$3))*(DD$3:DD$3<$FP$3:$FP$3)) -> 0 | DF10: =SUMPRODUCT(NOT(ISBLANK(DF$3:DF$3))*(DF$3:DF$3<$FQ$3:$FQ$3)) -> 0 | DG10: =SUMPRODUCT(NOT(ISBLANK(DG$3:DG$3))*(DG$3:DG$3<$FR$3:$FR$3)) -> 0 | DH10: =SUMPRODUCT(NOT(ISBLANK(DH$3:DH$3))*(DH$3:DH$3<$FO$3:$FO$3)) -> 0 | DI10: =SUMPRODUCT(NOT(ISBLANK(DI$3:DI$3))*(DI$3:DI$3<$FP$3:$FP$3)) -> 0 | DK10: =SUMPRODUCT(NOT(ISBLANK(DK$3:DK$3))*(DK$3:DK$3<$FQ$3:$FQ$3)) -> 0 | DL10: =SUMPRODUCT(NOT(ISBLANK(DL$3:DL$3))*(DL$3:DL$3<$FR$3:$FR$3)) -> 0 | DM10: =SUMPRODUCT(NOT(ISBLANK(DM$3:DM$3))*(DM$3:DM$3<$FO$3:$FO$3)) -> 0 | DN10: =SUMPRODUCT(NOT(ISBLANK(DN$3:DN$3))*(DN$3:DN$3<$FP$3:$FP$3)) -> 0 | DP10: =SUMPRODUCT(NOT(ISBLANK(DP$3:DP$3))*(DP$3:DP$3<$FQ$3:$FQ$3)) -> 0 | DQ10: =SUMPRODUCT(NOT(ISBLANK(DQ$3:DQ$3))*(DQ$3:DQ$3<$FR$3:$FR$3)) -> 0 | DR10: =SUMPRODUCT(NOT(ISBLANK(DR$3:DR$3))*(DR$3:DR$3<$FO$3:$FO$3)) -> 0 | DS10: =SUMPRODUCT(NOT(ISBLANK(DS$3:DS$3))*(DS$3:DS$3<$FP$3:$FP$3)) -> 0 | DU10: =SUMPRODUCT(NOT(ISBLANK(DU$3:DU$3))*(DU$3:DU$3<$FQ$3:$FQ$3)) -> 0 | DV10: =SUMPRODUCT(NOT(ISBLANK(DV$3:DV$3))*(DV$3:DV$3<$FR$3:$FR$3)) -> 0 | DW10: =SUMPRODUCT(NOT(ISBLANK(DW$3:DW$3))*(DW$3:DW$3<$FO$3:$FO$3)) -> 0 | DX10: =SUMPRODUCT(NOT(ISBLANK(DX$3:DX$3))*(DX$3:DX$3<$FP$3:$FP$3)) -> 0 | DZ10: =SUMPRODUCT(NOT(ISBLANK(DZ$3:DZ$3))*(DZ$3:DZ$3<$FQ$3:$FQ$3)) -> 0 | EA10: =SUMPRODUCT(NOT(ISBLANK(EA$3:EA$3))*(EA$3:EA$3<$FR$3:$FR$3)) -> 0 | EB10: =SUMPRODUCT(NOT(ISBLANK(EB$3:EB$3))*(EB$3:EB$3<$FO$3:$FO$3)) -> 0 | EC10: =SUMPRODUCT(NOT(ISBLANK(EC$3:EC$3))*(EC$3:EC$3<$FP$3:$FP$3)) -> 0 | EE10: =SUMPRODUCT(NOT(ISBLANK(EE$3:EE$3))*(EE$3:EE$3<$FQ$3:$FQ$3)) -> 0 | EF10: =SUMPRODUCT(NOT(ISBLANK(EF$3:EF$3))*(EF$3:EF$3<$FR$3:$FR$3)) -> 0 | EG10: =SUMPRODUCT(NOT(ISBLANK(EG$3:EG$3))*(EG$3:EG$3<$FO$3:$FO$3)) -> 0 | EH10: =SUMPRODUCT(NOT(ISBLANK(EH$3:EH$3))*(EH$3:EH$3<$FP$3:$FP$3)) -> 0 | EJ10: =SUMPRODUCT(NOT(ISBLANK(EJ$3:EJ$3))*(EJ$3:EJ$3<$FQ$3:$FQ$3)) -> 0 | EK10: =SUMPRODUCT(NOT(ISBLANK(EK$3:EK$3))*(EK$3:EK$3<$FR$3:$FR$3)) -> 0 | EL10: =SUMPRODUCT(NOT(ISBLANK(EL$3:EL$3))*(EL$3:EL$3<$FO$3:$FO$3)) -> 0 | EM10: =SUMPRODUCT(NOT(ISBLANK(EM$3:EM$3))*(EM$3:EM$3<$FP$3:$FP$3)) -> 0 | EO10: =SUMPRODUCT(NOT(ISBLANK(EO$3:EO$3))*(EO$3:EO$3<$FQ$3:$FQ$3)) -> 0 | EP10: =SUMPRODUCT(NOT(ISBLANK(EP$3:EP$3))*(EP$3:EP$3<$FR$3:$FR$3)) -> 0 | EQ10: =SUMPRODUCT(NOT(ISBLANK(EQ$3:EQ$3))*(EQ$3:EQ$3<$FO$3:$FO$3)) -> 0 | ER10: =SUMPRODUCT(NOT(ISBLANK(ER$3:ER$3))*(ER$3:ER$3<$FP$3:$FP$3)) -> 0 | ET10: =SUMPRODUCT(NOT(ISBLANK(ET$3:ET$3))*(ET$3:ET$3<$FQ$3:$FQ$3)) -> 0 | EU10: =SUMPRODUCT(NOT(ISBLANK(EU$3:EU$3))*(EU$3:EU$3<$FR$3:$FR$3)) -> 0 | EV10: =SUMPRODUCT(NOT(ISBLANK(EV$3:EV$3))*(EV$3:EV$3<$FO$3:$FO$3)) -> 0 | EW10: =SUMPRODUCT(NOT(ISBLANK(EW$3:EW$3))*(EW$3:EW$3<$FP$3:$FP$3)) -> 0 | EY10: =SUMPRODUCT(NOT(ISBLANK(EY$3:EY$3))*(EY$3:EY$3<$FQ$3:$FQ$3)) -> 0 | EZ10: =SUMPRODUCT(NOT(ISBLANK(EZ$3:EZ$3))*(EZ$3:EZ$3<$FR$3:$FR$3)) -> 0 | FA10: =SUMPRODUCT(NOT(ISBLANK(FA$3:FA$3))*(FA$3:FA$3<$FO$3:$FO$3)) -> 0 | FB10: =SUMPRODUCT(NOT(ISBLANK(FB$3:FB$3))*(FB$3:FB$3<$FP$3:$FP$3)) -> 0 | FD10: =SUMPRODUCT(NOT(ISBLANK(FD$3:FD$3))*(FD$3:FD$3<$FQ$3:$FQ$3)) -> 0 | FE10: =SUMPRODUCT(NOT(ISBLANK(FE$3:FE$3))*(FE$3:FE$3<$FR$3:$FR$3)) -> 0 | FF10: =SUMPRODUCT(NOT(ISBLANK(FF$3:FF$3))*(FF$3:FF$3<$FO$3:$FO$3)) -> 0 | FG10: =SUMPRODUCT(NOT(ISBLANK(FG$3:FG$3))*(FG$3:FG$3<$FP$3:$FP$3)) -> 0 | FI10: =SUMPRODUCT(NOT(ISBLANK(FI$3:FI$3))*(FI$3:FI$3<$FQ$3:$FQ$3)) -> 0 | FJ10: =SUMPRODUCT(NOT(ISBLANK(FJ$3:FJ$3))*(FJ$3:FJ$3<$FR$3:$FR$3)) -> 0
A11: WORSE | B11: =SUMPRODUCT((NOT(ISBLANK(B$3:B$3))*(B$3:B$3>$FO$3:$FO$3))+ISBLANK(B$3:B$3)) -> 0 | C11: =SUMPRODUCT((NOT(ISBLANK(C$3:C$3))*(C$3:C$3>$FP$3:$FP$3))+ISBLANK(C$3:C$3)) -> 0 | E11: =SUMPRODUCT((NOT(ISBLANK(E$3:E$3))*(E$3:E$3>$FQ$3:$FQ$3))+ISBLANK(E$3:E$3)) -> 0 | F11: =SUMPRODUCT((NOT(ISBLANK(F$3:F$3))*(F$3:F$3>$FR$3:$FR$3))+ISBLANK(F$3:F$3)) -> 0 | G11: =SUMPRODUCT((NOT(ISBLANK(G$3:G$3))*(G$3:G$3>$FO$3:$FO$3))+ISBLANK(G$3:G$3)) -> 0 | H11: =SUMPRODUCT((NOT(ISBLANK(H$3:H$3))*(H$3:H$3>$FP$3:$FP$3))+ISBLANK(H$3:H$3)) -> 0 | J11: =SUMPRODUCT((NOT(ISBLANK(J$3:J$3))*(J$3:J$3>$FQ$3:$FQ$3))+ISBLANK(J$3:J$3)) -> 0 | K11: =SUMPRODUCT((NOT(ISBLANK(K$3:K$3))*(K$3:K$3>$FR$3:$FR$3))+ISBLANK(K$3:K$3)) -> 0 | L11: =SUMPRODUCT((NOT(ISBLANK(L$3:L$3))*(L$3:L$3>$FO$3:$FO$3))+ISBLANK(L$3:L$3)) -> 0 | M11: =SUMPRODUCT((NOT(ISBLANK(M$3:M$3))*(M$3:M$3>$FP$3:$FP$3))+ISBLANK(M$3:M$3)) -> 0 | O11: =SUMPRODUCT((NOT(ISBLANK(O$3:O$3))*(O$3:O$3>$FQ$3:$FQ$3))+ISBLANK(O$3:O$3)) -> 0 | P11: =SUMPRODUCT((NOT(ISBLANK(P$3:P$3))*(P$3:P$3>$FR$3:$FR$3))+ISBLANK(P$3:P$3)) -> 0 | Q11: =SUMPRODUCT((NOT(ISBLANK(Q$3:Q$3))*(Q$3:Q$3>$FO$3:$FO$3))+ISBLANK(Q$3:Q$3)) -> 0 | R11: =SUMPRODUCT((NOT(ISBLANK(R$3:R$3))*(R$3:R$3>$FP$3:$FP$3))+ISBLANK(R$3:R$3)) -> 0 | T11: =SUMPRODUCT((NOT(ISBLANK(T$3:T$3))*(T$3:T$3>$FQ$3:$FQ$3))+ISBLANK(T$3:T$3)) -> 0 | U11: =SUMPRODUCT((NOT(ISBLANK(U$3:U$3))*(U$3:U$3>$FR$3:$FR$3))+ISBLANK(U$3:U$3)) -> 0 | V11: =SUMPRODUCT((NOT(ISBLANK(V$3:V$3))*(V$3:V$3>$FO$3:$FO$3))+ISBLANK(V$3:V$3)) -> 0 | W11: =SUMPRODUCT((NOT(ISBLANK(W$3:W$3))*(W$3:W$3>$FP$3:$FP$3))+ISBLANK(W$3:W$3)) -> 0 | Y11: =SUMPRODUCT((NOT(ISBLANK(Y$3:Y$3))*(Y$3:Y$3>$FQ$3:$FQ$3))+ISBLANK(Y$3:Y$3)) -> 0 | Z11: =SUMPRODUCT((NOT(ISBLANK(Z$3:Z$3))*(Z$3:Z$3>$FR$3:$FR$3))+ISBLANK(Z$3:Z$3)) -> 0 | AA11: =SUMPRODUCT((NOT(ISBLANK(AA$3:AA$3))*(AA$3:AA$3>$FO$3:$FO$3))+ISBLANK(AA$3:AA$3)) -> 0 | AB11: =SUMPRODUCT((NOT(ISBLANK(AB$3:AB$3))*(AB$3:AB$3>$FP$3:$FP$3))+ISBLANK(AB$3:AB$3)) -> 0 | AD11: =SUMPRODUCT((NOT(ISBLANK(AD$3:AD$3))*(AD$3:AD$3>$FQ$3:$FQ$3))+ISBLANK(AD$3:AD$3)) -> 0 | AE11: =SUMPRODUCT((NOT(ISBLANK(AE$3:AE$3))*(AE$3:AE$3>$FR$3:$FR$3))+ISBLANK(AE$3:AE$3)) -> 0 | AF11: =SUMPRODUCT((NOT(ISBLANK(AF$3:AF$3))*(AF$3:AF$3>$FO$3:$FO$3))+ISBLANK(AF$3:AF$3)) -> 0 | AG11: =SUMPRODUCT((NOT(ISBLANK(AG$3:AG$3))*(AG$3:AG$3>$FP$3:$FP$3))+ISBLANK(AG$3:AG$3)) -> 0 | AI11: =SUMPRODUCT((NOT(ISBLANK(AI$3:AI$3))*(AI$3:AI$3>$FQ$3:$FQ$3))+ISBLANK(AI$3:AI$3)) -> 0 | AJ11: =SUMPRODUCT((NOT(ISBLANK(AJ$3:AJ$3))*(AJ$3:AJ$3>$FR$3:$FR$3))+ISBLANK(AJ$3:AJ$3)) -> 0 | AK11: =SUMPRODUCT((NOT(ISBLANK(AK$3:AK$3))*(AK$3:AK$3>$FO$3:$FO$3))+ISBLANK(AK$3:AK$3)) -> 0 | AL11: =SUMPRODUCT((NOT(ISBLANK(AL$3:AL$3))*(AL$3:AL$3>$FP$3:$FP$3))+ISBLANK(AL$3:AL$3)) -> 0 | AN11: =SUMPRODUCT((NOT(ISBLANK(AN$3:AN$3))*(AN$3:AN$3>$FQ$3:$FQ$3))+ISBLANK(AN$3:AN$3)) -> 0 | AO11: =SUMPRODUCT((NOT(ISBLANK(AO$3:AO$3))*(AO$3:AO$3>$FR$3:$FR$3))+ISBLANK(AO$3:AO$3)) -> 0 | AP11: =SUMPRODUCT((NOT(ISBLANK(AP$3:AP$3))*(AP$3:AP$3>$FO$3:$FO$3))+ISBLANK(AP$3:AP$3)) -> 0 | AQ11: =SUMPRODUCT((NOT(ISBLANK(AQ$3:AQ$3))*(AQ$3:AQ$3>$FP$3:$FP$3))+ISBLANK(AQ$3:AQ$3)) -> 0 | AS11: =SUMPRODUCT((NOT(ISBLANK(AS$3:AS$3))*(AS$3:AS$3>$FQ$3:$FQ$3))+ISBLANK(AS$3:AS$3)) -> 0 | AT11: =SUMPRODUCT((NOT(ISBLANK(AT$3:AT$3))*(AT$3:AT$3>$FR$3:$FR$3))+ISBLANK(AT$3:AT$3)) -> 0 | AU11: =SUMPRODUCT((NOT(ISBLANK(AU$3:AU$3))*(AU$3:AU$3>$FO$3:$FO$3))+ISBLANK(AU$3:AU$3)) -> 0 | AV11: =SUMPRODUCT((NOT(ISBLANK(AV$3:AV$3))*(AV$3:AV$3>$FP$3:$FP$3))+ISBLANK(AV$3:AV$3)) -> 0 | AX11: =SUMPRODUCT((NOT(ISBLANK(AX$3:AX$3))*(AX$3:AX$3>$FQ$3:$FQ$3))+ISBLANK(AX$3:AX$3)) -> 0 | AY11: =SUMPRODUCT((NOT(ISBLANK(AY$3:AY$3))*(AY$3:AY$3>$FR$3:$FR$3))+ISBLANK(AY$3:AY$3)) -> 0 | AZ11: =SUMPRODUCT((NOT(ISBLANK(AZ$3:AZ$3))*(AZ$3:AZ$3>$FO$3:$FO$3))+ISBLANK(AZ$3:AZ$3)) -> 0 | BA11: =SUMPRODUCT((NOT(ISBLANK(BA$3:BA$3))*(BA$3:BA$3>$FP$3:$FP$3))+ISBLANK(BA$3:BA$3)) -> 0 | BC11: =SUMPRODUCT((NOT(ISBLANK(BC$3:BC$3))*(BC$3:BC$3>$FQ$3:$FQ$3))+ISBLANK(BC$3:BC$3)) -> 0 | BD11: =SUMPRODUCT((NOT(ISBLANK(BD$3:BD$3))*(BD$3:BD$3>$FR$3:$FR$3))+ISBLANK(BD$3:BD$3)) -> 0 | BE11: =SUMPRODUCT((NOT(ISBLANK(BE$3:BE$3))*(BE$3:BE$3>$FO$3:$FO$3))+ISBLANK(BE$3:BE$3)) -> 0 | BF11: =SUMPRODUCT((NOT(ISBLANK(BF$3:BF$3))*(BF$3:BF$3>$FP$3:$FP$3))+ISBLANK(BF$3:BF$3)) -> 0 | BH11: =SUMPRODUCT((NOT(ISBLANK(BH$3:BH$3))*(BH$3:BH$3>$FQ$3:$FQ$3))+ISBLANK(BH$3:BH$3)) -> 0 | BI11: =SUMPRODUCT((NOT(ISBLANK(BI$3:BI$3))*(BI$3:BI$3>$FR$3:$FR$3))+ISBLANK(BI$3:BI$3)) -> 0 | BJ11: =SUMPRODUCT((NOT(ISBLANK(BJ$3:BJ$3))*(BJ$3:BJ$3>$FO$3:$FO$3))+ISBLANK(BJ$3:BJ$3)) -> 0 | BK11: =SUMPRODUCT((NOT(ISBLANK(BK$3:BK$3))*(BK$3:BK$3>$FP$3:$FP$3))+ISBLANK(BK$3:BK$3)) -> 0 | BM11: =SUMPRODUCT((NOT(ISBLANK(BM$3:BM$3))*(BM$3:BM$3>$FQ$3:$FQ$3))+ISBLANK(BM$3:BM$3)) -> 0 | BN11: =SUMPRODUCT((NOT(ISBLANK(BN$3:BN$3))*(BN$3:BN$3>$FR$3:$FR$3))+ISBLANK(BN$3:BN$3)) -> 0 | BO11: =SUMPRODUCT((NOT(ISBLANK(BO$3:BO$3))*(BO$3:BO$3>$FO$3:$FO$3))+ISBLANK(BO$3:BO$3)) -> 0 | BP11: =SUMPRODUCT((NOT(ISBLANK(BP$3:BP$3))*(BP$3:BP$3>$FP$3:$FP$3))+ISBLANK(BP$3:BP$3)) -> 0 | BR11: =SUMPRODUCT((NOT(ISBLANK(BR$3:BR$3))*(BR$3:BR$3>$FQ$3:$FQ$3))+ISBLANK(BR$3:BR$3)) -> 0 | BS11: =SUMPRODUCT((NOT(ISBLANK(BS$3:BS$3))*(BS$3:BS$3>$FR$3:$FR$3))+ISBLANK(BS$3:BS$3)) -> 0 | BT11: =SUMPRODUCT((NOT(ISBLANK(BT$3:BT$3))*(BT$3:BT$3>$FO$3:$FO$3))+ISBLANK(BT$3:BT$3)) -> 0 | BU11: =SUMPRODUCT((NOT(ISBLANK(BU$3:BU$3))*(BU$3:BU$3>$FP$3:$FP$3))+ISBLANK(BU$3:BU$3)) -> 0 | BW11: =SUMPRODUCT((NOT(ISBLANK(BW$3:BW$3))*(BW$3:BW$3>$FQ$3:$FQ$3))+ISBLANK(BW$3:BW$3)) -> 0 | BX11: =SUMPRODUCT((NOT(ISBLANK(BX$3:BX$3))*(BX$3:BX$3>$FR$3:$FR$3))+ISBLANK(BX$3:BX$3)) -> 0 | BY11: =SUMPRODUCT((NOT(ISBLANK(BY$3:BY$3))*(BY$3:BY$3>$FO$3:$FO$3))+ISBLANK(BY$3:BY$3)) -> 0 | BZ11: =SUMPRODUCT((NOT(ISBLANK(BZ$3:BZ$3))*(BZ$3:BZ$3>$FP$3:$FP$3))+ISBLANK(BZ$3:BZ$3)) -> 0 | CB11: =SUMPRODUCT((NOT(ISBLANK(CB$3:CB$3))*(CB$3:CB$3>$FQ$3:$FQ$3))+ISBLANK(CB$3:CB$3)) -> 0 | CC11: =SUMPRODUCT((NOT(ISBLANK(CC$3:CC$3))*(CC$3:CC$3>$FR$3:$FR$3))+ISBLANK(CC$3:CC$3)) -> 0 | CD11: =SUMPRODUCT((NOT(ISBLANK(CD$3:CD$3))*(CD$3:CD$3>$FO$3:$FO$3))+ISBLANK(CD$3:CD$3)) -> 0 | CE11: =SUMPRODUCT((NOT(ISBLANK(CE$3:CE$3))*(CE$3:CE$3>$FP$3:$FP$3))+ISBLANK(CE$3:CE$3)) -> 0 | CG11: =SUMPRODUCT((NOT(ISBLANK(CG$3:CG$3))*(CG$3:CG$3>$FQ$3:$FQ$3))+ISBLANK(CG$3:CG$3)) -> 0 | CH11: =SUMPRODUCT((NOT(ISBLANK(CH$3:CH$3))*(CH$3:CH$3>$FR$3:$FR$3))+ISBLANK(CH$3:CH$3)) -> 0 | CI11: =SUMPRODUCT((NOT(ISBLANK(CI$3:CI$3))*(CI$3:CI$3>$FO$3:$FO$3))+ISBLANK(CI$3:CI$3)) -> 0 | CJ11: =SUMPRODUCT((NOT(ISBLANK(CJ$3:CJ$3))*(CJ$3:CJ$3>$FP$3:$FP$3))+ISBLANK(CJ$3:CJ$3)) -> 0 | CL11: =SUMPRODUCT((NOT(ISBLANK(CL$3:CL$3))*(CL$3:CL$3>$FQ$3:$FQ$3))+ISBLANK(CL$3:CL$3)) -> 0 | CM11: =SUMPRODUCT((NOT(ISBLANK(CM$3:CM$3))*(CM$3:CM$3>$FR$3:$FR$3))+ISBLANK(CM$3:CM$3)) -> 0 | CN11: =SUMPRODUCT((NOT(ISBLANK(CN$3:CN$3))*(CN$3:CN$3>$FO$3:$FO$3))+ISBLANK(CN$3:CN$3)) -> 0 | CO11: =SUMPRODUCT((NOT(ISBLANK(CO$3:CO$3))*(CO$3:CO$3>$FP$3:$FP$3))+ISBLANK(CO$3:CO$3)) -> 0 | CQ11: =SUMPRODUCT((NOT(ISBLANK(CQ$3:CQ$3))*(CQ$3:CQ$3>$FQ$3:$FQ$3))+ISBLANK(CQ$3:CQ$3)) -> 0 | CR11: =SUMPRODUCT((NOT(ISBLANK(CR$3:CR$3))*(CR$3:CR$3>$FR$3:$FR$3))+ISBLANK(CR$3:CR$3)) -> 0 | CS11: =SUMPRODUCT((NOT(ISBLANK(CS$3:CS$3))*(CS$3:CS$3>$FO$3:$FO$3))+ISBLANK(CS$3:CS$3)) -> 0 | CT11: =SUMPRODUCT((NOT(ISBLANK(CT$3:CT$3))*(CT$3:CT$3>$FP$3:$FP$3))+ISBLANK(CT$3:CT$3)) -> 0 | CV11: =SUMPRODUCT((NOT(ISBLANK(CV$3:CV$3))*(CV$3:CV$3>$FQ$3:$FQ$3))+ISBLANK(CV$3:CV$3)) -> 0 | CW11: =SUMPRODUCT((NOT(ISBLANK(CW$3:CW$3))*(CW$3:CW$3>$FR$3:$FR$3))+ISBLANK(CW$3:CW$3)) -> 0 | CX11: =SUMPRODUCT((NOT(ISBLANK(CX$3:CX$3))*(CX$3:CX$3>$FO$3:$FO$3))+ISBLANK(CX$3:CX$3)) -> 0 | CY11: =SUMPRODUCT((NOT(ISBLANK(CY$3:CY$3))*(CY$3:CY$3>$FP$3:$FP$3))+ISBLANK(CY$3:CY$3)) -> 0 | DA11: =SUMPRODUCT((NOT(ISBLANK(DA$3:DA$3))*(DA$3:DA$3>$FQ$3:$FQ$3))+ISBLANK(DA$3:DA$3)) -> 0 | DB11: =SUMPRODUCT((NOT(ISBLANK(DB$3:DB$3))*(DB$3:DB$3>$FR$3:$FR$3))+ISBLANK(DB$3:DB$3)) -> 0 | DC11: =SUMPRODUCT((NOT(ISBLANK(DC$3:DC$3))*(DC$3:DC$3>$FO$3:$FO$3))+ISBLANK(DC$3:DC$3)) -> 0 | DD11: =SUMPRODUCT((NOT(ISBLANK(DD$3:DD$3))*(DD$3:DD$3>$FP$3:$FP$3))+ISBLANK(DD$3:DD$3)) -> 0 | DF11: =SUMPRODUCT((NOT(ISBLANK(DF$3:DF$3))*(DF$3:DF$3>$FQ$3:$FQ$3))+ISBLANK(DF$3:DF$3)) -> 0 | DG11: =SUMPRODUCT((NOT(ISBLANK(DG$3:DG$3))*(DG$3:DG$3>$FR$3:$FR$3))+ISBLANK(DG$3:DG$3)) -> 0 | DH11: =SUMPRODUCT((NOT(ISBLANK(DH$3:DH$3))*(DH$3:DH$3>$FO$3:$FO$3))+ISBLANK(DH$3:DH$3)) -> 0 | DI11: =SUMPRODUCT((NOT(ISBLANK(DI$3:DI$3))*(DI$3:DI$3>$FP$3:$FP$3))+ISBLANK(DI$3:DI$3)) -> 0 | DK11: =SUMPRODUCT((NOT(ISBLANK(DK$3:DK$3))*(DK$3:DK$3>$FQ$3:$FQ$3))+ISBLANK(DK$3:DK$3)) -> 0 | DL11: =SUMPRODUCT((NOT(ISBLANK(DL$3:DL$3))*(DL$3:DL$3>$FR$3:$FR$3))+ISBLANK(DL$3:DL$3)) -> 0 | DM11: =SUMPRODUCT((NOT(ISBLANK(DM$3:DM$3))*(DM$3:DM$3>$FO$3:$FO$3))+ISBLANK(DM$3:DM$3)) -> 0 | DN11: =SUMPRODUCT((NOT(ISBLANK(DN$3:DN$3))*(DN$3:DN$3>$FP$3:$FP$3))+ISBLANK(DN$3:DN$3)) -> 0 | DP11: =SUMPRODUCT((NOT(ISBLANK(DP$3:DP$3))*(DP$3:DP$3>$FQ$3:$FQ$3))+ISBLANK(DP$3:DP$3)) -> 0 | DQ11: =SUMPRODUCT((NOT(ISBLANK(DQ$3:DQ$3))*(DQ$3:DQ$3>$FR$3:$FR$3))+ISBLANK(DQ$3:DQ$3)) -> 0 | DR11: =SUMPRODUCT((NOT(ISBLANK(DR$3:DR$3))*(DR$3:DR$3>$FO$3:$FO$3))+ISBLANK(DR$3:DR$3)) -> 0 | DS11: =SUMPRODUCT((NOT(ISBLANK(DS$3:DS$3))*(DS$3:DS$3>$FP$3:$FP$3))+ISBLANK(DS$3:DS$3)) -> 0 | DU11: =SUMPRODUCT((NOT(ISBLANK(DU$3:DU$3))*(DU$3:DU$3>$FQ$3:$FQ$3))+ISBLANK(DU$3:DU$3)) -> 0 | DV11: =SUMPRODUCT((NOT(ISBLANK(DV$3:DV$3))*(DV$3:DV$3>$FR$3:$FR$3))+ISBLANK(DV$3:DV$3)) -> 0 | DW11: =SUMPRODUCT((NOT(ISBLANK(DW$3:DW$3))*(DW$3:DW$3>$FO$3:$FO$3))+ISBLANK(DW$3:DW$3)) -> 0 | DX11: =SUMPRODUCT((NOT(ISBLANK(DX$3:DX$3))*(DX$3:DX$3>$FP$3:$FP$3))+ISBLANK(DX$3:DX$3)) -> 0 | DZ11: =SUMPRODUCT((NOT(ISBLANK(DZ$3:DZ$3))*(DZ$3:DZ$3>$FQ$3:$FQ$3))+ISBLANK(DZ$3:DZ$3)) -> 0 | EA11: =SUMPRODUCT((NOT(ISBLANK(EA$3:EA$3))*(EA$3:EA$3>$FR$3:$FR$3))+ISBLANK(EA$3:EA$3)) -> 0 | EB11: =SUMPRODUCT((NOT(ISBLANK(EB$3:EB$3))*(EB$3:EB$3>$FO$3:$FO$3))+ISBLANK(EB$3:EB$3)) -> 0 | EC11: =SUMPRODUCT((NOT(ISBLANK(EC$3:EC$3))*(EC$3:EC$3>$FP$3:$FP$3))+ISBLANK(EC$3:EC$3)) -> 0 | EE11: =SUMPRODUCT((NOT(ISBLANK(EE$3:EE$3))*(EE$3:EE$3>$FQ$3:$FQ$3))+ISBLANK(EE$3:EE$3)) -> 0 | EF11: =SUMPRODUCT((NOT(ISBLANK(EF$3:EF$3))*(EF$3:EF$3>$FR$3:$FR$3))+ISBLANK(EF$3:EF$3)) -> 0 | EG11: =SUMPRODUCT((NOT(ISBLANK(EG$3:EG$3))*(EG$3:EG$3>$FO$3:$FO$3))+ISBLANK(EG$3:EG$3)) -> 0 | EH11: =SUMPRODUCT((NOT(ISBLANK(EH$3:EH$3))*(EH$3:EH$3>$FP$3:$FP$3))+ISBLANK(EH$3:EH$3)) -> 0 | EJ11: =SUMPRODUCT((NOT(ISBLANK(EJ$3:EJ$3))*(EJ$3:EJ$3>$FQ$3:$FQ$3))+ISBLANK(EJ$3:EJ$3)) -> 0 | EK11: =SUMPRODUCT((NOT(ISBLANK(EK$3:EK$3))*(EK$3:EK$3>$FR$3:$FR$3))+ISBLANK(EK$3:EK$3)) -> 0 | EL11: =SUMPRODUCT((NOT(ISBLANK(EL$3:EL$3))*(EL$3:EL$3>$FO$3:$FO$3))+ISBLANK(EL$3:EL$3)) -> 0 | EM11: =SUMPRODUCT((NOT(ISBLANK(EM$3:EM$3))*(EM$3:EM$3>$FP$3:$FP$3))+ISBLANK(EM$3:EM$3)) -> 0 | EO11: =SUMPRODUCT((NOT(ISBLANK(EO$3:EO$3))*(EO$3:EO$3>$FQ$3:$FQ$3))+ISBLANK(EO$3:EO$3)) -> 0 | EP11: =SUMPRODUCT((NOT(ISBLANK(EP$3:EP$3))*(EP$3:EP$3>$FR$3:$FR$3))+ISBLANK(EP$3:EP$3)) -> 0 | EQ11: =SUMPRODUCT((NOT(ISBLANK(EQ$3:EQ$3))*(EQ$3:EQ$3>$FO$3:$FO$3))+ISBLANK(EQ$3:EQ$3)) -> 0 | ER11: =SUMPRODUCT((NOT(ISBLANK(ER$3:ER$3))*(ER$3:ER$3>$FP$3:$FP$3))+ISBLANK(ER$3:ER$3)) -> 0 | ET11: =SUMPRODUCT((NOT(ISBLANK(ET$3:ET$3))*(ET$3:ET$3>$FQ$3:$FQ$3))+ISBLANK(ET$3:ET$3)) -> 0 | EU11: =SUMPRODUCT((NOT(ISBLANK(EU$3:EU$3))*(EU$3:EU$3>$FR$3:$FR$3))+ISBLANK(EU$3:EU$3)) -> 0 | EV11: =SUMPRODUCT((NOT(ISBLANK(EV$3:EV$3))*(EV$3:EV$3>$FO$3:$FO$3))+ISBLANK(EV$3:EV$3)) -> 0 | EW11: =SUMPRODUCT((NOT(ISBLANK(EW$3:EW$3))*(EW$3:EW$3>$FP$3:$FP$3))+ISBLANK(EW$3:EW$3)) -> 0 | EY11: =SUMPRODUCT((NOT(ISBLANK(EY$3:EY$3))*(EY$3:EY$3>$FQ$3:$FQ$3))+ISBLANK(EY$3:EY$3)) -> 0 | EZ11: =SUMPRODUCT((NOT(ISBLANK(EZ$3:EZ$3))*(EZ$3:EZ$3>$FR$3:$FR$3))+ISBLANK(EZ$3:EZ$3)) -> 0 | FA11: =SUMPRODUCT((NOT(ISBLANK(FA$3:FA$3))*(FA$3:FA$3>$FO$3:$FO$3))+ISBLANK(FA$3:FA$3)) -> 0 | FB11: =SUMPRODUCT((NOT(ISBLANK(FB$3:FB$3))*(FB$3:FB$3>$FP$3:$FP$3))+ISBLANK(FB$3:FB$3)) -> 0 | FD11: =SUMPRODUCT((NOT(ISBLANK(FD$3:FD$3))*(FD$3:FD$3>$FQ$3:$FQ$3))+ISBLANK(FD$3:FD$3)) -> 0 | FE11: =SUMPRODUCT((NOT(ISBLANK(FE$3:FE$3))*(FE$3:FE$3>$FR$3:$FR$3))+ISBLANK(FE$3:FE$3)) -> 0 | FF11: =SUMPRODUCT((NOT(ISBLANK(FF$3:FF$3))*(FF$3:FF$3>$FO$3:$FO$3))+ISBLANK(FF$3:FF$3)) -> 0 | FG11: =SUMPRODUCT((NOT(ISBLANK(FG$3:FG$3))*(FG$3:FG$3>$FP$3:$FP$3))+ISBLANK(FG$3:FG$3)) -> 0 | FI11: =SUMPRODUCT((NOT(ISBLANK(FI$3:FI$3))*(FI$3:FI$3>$FQ$3:$FQ$3))+ISBLANK(FI$3:FI$3)) -> 0 | FJ11: =SUMPRODUCT((NOT(ISBLANK(FJ$3:FJ$3))*(FJ$3:FJ$3>$FR$3:$FR$3))+ISBLANK(FJ$3:FJ$3)) -> 0
