Workbook

Sheet Instances
B1: memelingo-1/allapproaches_mlp-tplp-ht | G1: memelingo-1/allapproaches_mlp-tplp-htc | L1: memelingo-1/allapproaches_mlp-tplp-htcdl | Q1: min | U1: median | Y1: max
B2: time | C2: stime | D2: status | E2: rules | F2: ctime | G2: time | H2: stime | I2: status | J2: rules | K2: ctime | L2: time | M2: stime | N2: status | O2: rules | P2: ctime | Q2: time | R2: stime | S2: rules | T2: ctime | U2: time | V2: stime | W2: rules | X2: ctime | Y2: time | Z2: stime | AA2: rules | AB2: ctime
A3: instances/x6_y6_a1_f1 | B3: 9.09 | C3: 0.04 | D3: SATISFIABLE | E3: 217479 | F3: 2.505 | G3: 10.97 | H3: 0.1 | I3: SATISFIABLE | J3: 173796 | K3: 2.414 | L3: 10.78 | M3: 2.11 | N3: SATISFIABLE | O3: 173796 | P3: 4.328 | Q3: =MIN($B3,$G3,$L3) -> 0 | R3: =MIN($C3,$H3,$M3) -> 0 | S3: =MIN($E3,$J3,$O3) -> 0 | T3: =MIN($F3,$K3,$P3) -> 0 | U3: =MEDIAN($B3,$G3,$L3) -> 0 | V3: =MEDIAN($C3,$H3,$M3) -> 0 | W3: =MEDIAN($E3,$J3,$O3) -> 0 | X3: =MEDIAN($F3,$K3,$P3) -> 0 | Y3: =MAX($B3,$G3,$L3) -> 0 | Z3: =MAX($C3,$H3,$M3) -> 0 | AA3: =MAX($E3,$J3,$O3) -> 0 | AB3: =MAX($F3,$K3,$P3) -> 0
A4: instances/x6_y6_a1_f10 | B4: 114.37 | C4: 50.22 | D4: SATISFIABLE | E4: 9460199 | F4: 106.964 | G4: 10.24 | H4: 1.99 | I4: SATISFIABLE | J4: 173907 | K4: 4.467 | L4: 15.27 | M4: 6.61 | N4: SATISFIABLE | O4: 173907 | P4: 8.907 | Q4: =MIN($B4,$G4,$L4) -> 0 | R4: =MIN($C4,$H4,$M4) -> 0 | S4: =MIN($E4,$J4,$O4) -> 0 | T4: =MIN($F4,$K4,$P4) -> 0 | U4: =MEDIAN($B4,$G4,$L4) -> 0 | V4: =MEDIAN($C4,$H4,$M4) -> 0 | W4: =MEDIAN($E4,$J4,$O4) -> 0 | X4: =MEDIAN($F4,$K4,$P4) -> 0 | Y4: =MAX($B4,$G4,$L4) -> 0 | Z4: =MAX($C4,$H4,$M4) -> 0 | AA4: =MAX($E4,$J4,$O4) -> 0 | AB4: =MAX($F4,$K4,$P4) -> 0
A5: instances/x6_y6_a1_f15 | B5: 440.57 | C5: 328.7 | D5: SATISFIABLE | E5: 21474749 | F5: 429.593 | G5: 10.91 | H5: 0.71 | I5: SATISFIABLE | J5: 173907 | K5: 3.409 | L5: 17.12 | M5: 6.67 | N5: SATISFIABLE | O5: 173907 | P5: 8.877 | Q5: =MIN($B5,$G5,$L5) -> 0 | R5: =MIN($C5,$H5,$M5) -> 0 | S5: =MIN($E5,$J5,$O5) -> 0 | T5: =MIN($F5,$K5,$P5) -> 0 | U5: =MEDIAN($B5,$G5,$L5) -> 0 | V5: =MEDIAN($C5,$H5,$M5) -> 0 | W5: =MEDIAN($E5,$J5,$O5) -> 0 | X5: =MEDIAN($F5,$K5,$P5) -> 0 | Y5: =MAX($B5,$G5,$L5) -> 0 | Z5: =MAX($C5,$H5,$M5) -> 0 | AA5: =MAX($E5,$J5,$O5) -> 0 | AB5: =MAX($F5,$K5,$P5) -> 0
A6: instances/x6_y6_a1_f20 | B6: 545.88 | C6: 299.63 | D6: SATISFIABLE | E6: 38405549 | F6: 534.493 | G6: 8.92 | H6: 0.75 | I6: SATISFIABLE | J6: 173907 | K6: 3.343 | L6: 15.44 | M6: 6.65 | N6: SATISFIABLE | O6: 173907 | P6: 8.932 | Q6: =MIN($B6,$G6,$L6) -> 0 | R6: =MIN($C6,$H6,$M6) -> 0 | S6: =MIN($E6,$J6,$O6) -> 0 | T6: =MIN($F6,$K6,$P6) -> 0 | U6: =MEDIAN($B6,$G6,$L6) -> 0 | V6: =MEDIAN($C6,$H6,$M6) -> 0 | W6: =MEDIAN($E6,$J6,$O6) -> 0 | X6: =MEDIAN($F6,$K6,$P6) -> 0 | Y6: =MAX($B6,$G6,$L6) -> 0 | Z6: =MAX($C6,$H6,$M6) -> 0 | AA6: =MAX($E6,$J6,$O6) -> 0 | AB6: =MAX($F6,$K6,$P6) -> 0
A7: instances/x6_y6_a1_f25 | B7: 1200 | C7: 0 | D7: UNKNOWN | E7: 0 | F7: 262.742 | G7: 12.11 | H7: 0.57 | I7: SATISFIABLE | J7: 173907 | K7: 2.981 | L7: 16.15 | M7: 7.92 | N7: SATISFIABLE | O7: 173907 | P7: 10.389 | Q7: =MIN($B7,$G7,$L7) -> 0 | R7: =MIN($C7,$H7,$M7) -> 0 | S7: =MIN($E7,$J7,$O7) -> 0 | T7: =MIN($F7,$K7,$P7) -> 0 | U7: =MEDIAN($B7,$G7,$L7) -> 0 | V7: =MEDIAN($C7,$H7,$M7) -> 0 | W7: =MEDIAN($E7,$J7,$O7) -> 0 | X7: =MEDIAN($F7,$K7,$P7) -> 0 | Y7: =MAX($B7,$G7,$L7) -> 0 | Z7: =MAX($C7,$H7,$M7) -> 0 | AA7: =MAX($E7,$J7,$O7) -> 0 | AB7: =MAX($F7,$K7,$P7) -> 0
A8: instances/x6_y6_a1_f30 | B8: 1200 | C8: 0 | D8: UNKNOWN | E8: 0 | F8: 186.394 | G8: 9.61 | H8: 0.7 | I8: SATISFIABLE | J8: 173907 | K8: 3.283 | L8: 15.96 | M8: 6.63 | N8: SATISFIABLE | O8: 173907 | P8: 8.846 | Q8: =MIN($B8,$G8,$L8) -> 0 | R8: =MIN($C8,$H8,$M8) -> 0 | S8: =MIN($E8,$J8,$O8) -> 0 | T8: =MIN($F8,$K8,$P8) -> 0 | U8: =MEDIAN($B8,$G8,$L8) -> 0 | V8: =MEDIAN($C8,$H8,$M8) -> 0 | W8: =MEDIAN($E8,$J8,$O8) -> 0 | X8: =MEDIAN($F8,$K8,$P8) -> 0 | Y8: =MAX($B8,$G8,$L8) -> 0 | Z8: =MAX($C8,$H8,$M8) -> 0 | AA8: =MAX($E8,$J8,$O8) -> 0 | AB8: =MAX($F8,$K8,$P8) -> 0
A9: instances/x6_y6_a1_f35 | B9: 1200 | C9: 0 | D9: UNKNOWN | E9: 0 | F9: 239.967 | G9: 12.18 | H9: 0.69 | I9: SATISFIABLE | J9: 173907 | K9: 3.135 | L9: 17.47 | M9: 6.63 | N9: SATISFIABLE | O9: 173907 | P9: 8.872 | Q9: =MIN($B9,$G9,$L9) -> 0 | R9: =MIN($C9,$H9,$M9) -> 0 | S9: =MIN($E9,$J9,$O9) -> 0 | T9: =MIN($F9,$K9,$P9) -> 0 | U9: =MEDIAN($B9,$G9,$L9) -> 0 | V9: =MEDIAN($C9,$H9,$M9) -> 0 | W9: =MEDIAN($E9,$J9,$O9) -> 0 | X9: =MEDIAN($F9,$K9,$P9) -> 0 | Y9: =MAX($B9,$G9,$L9) -> 0 | Z9: =MAX($C9,$H9,$M9) -> 0 | AA9: =MAX($E9,$J9,$O9) -> 0 | AB9: =MAX($F9,$K9,$P9) -> 0
A10: instances/x6_y6_a1_f40 | B10: 1200 | C10: 0 | D10: UNKNOWN | E10: 0 | F10: 224.577 | G10: 12.07 | H10: 0.89 | I10: SATISFIABLE | J10: 173907 | K10: 3.41 | L10: 18.55 | M10: 9.42 | N10: SATISFIABLE | O10: 173907 | P10: 11.994 | Q10: =MIN($B10,$G10,$L10) -> 0 | R10: =MIN($C10,$H10,$M10) -> 0 | S10: =MIN($E10,$J10,$O10) -> 0 | T10: =MIN($F10,$K10,$P10) -> 0 | U10: =MEDIAN($B10,$G10,$L10) -> 0 | V10: =MEDIAN($C10,$H10,$M10) -> 0 | W10: =MEDIAN($E10,$J10,$O10) -> 0 | X10: =MEDIAN($F10,$K10,$P10) -> 0 | Y10: =MAX($B10,$G10,$L10) -> 0 | Z10: =MAX($C10,$H10,$M10) -> 0 | AA10: =MAX($E10,$J10,$O10) -> 0 | AB10: =MAX($F10,$K10,$P10) -> 0
A11: instances/x6_y6_a1_f5 | B11: 36.1 | C11: 14.45 | D11: SATISFIABLE | E11: 2361888 | F11: 29.493 | G11: 9.33 | H11: 0.6 | I11: SATISFIABLE | J11: 173907 | K11: 3.056 | L11: 18.8 | M11: 9.13 | N11: SATISFIABLE | O11: 173907 | P11: 11.392 | Q11: =MIN($B11,$G11,$L11) -> 0 | R11: =MIN($C11,$H11,$M11) -> 0 | S11: =MIN($E11,$J11,$O11) -> 0 | T11: =MIN($F11,$K11,$P11) -> 0 | U11: =MEDIAN($B11,$G11,$L11) -> 0 | V11: =MEDIAN($C11,$H11,$M11) -> 0 | W11: =MEDIAN($E11,$J11,$O11) -> 0 | X11: =MEDIAN($F11,$K11,$P11) -> 0 | Y11: =MAX($B11,$G11,$L11) -> 0 | Z11: =MAX($C11,$H11,$M11) -> 0 | AA11: =MAX($E11,$J11,$O11) -> 0 | AB11: =MAX($F11,$K11,$P11) -> 0
A12: instances/x6_y6_a2_f1 | B12: 12.56 | C12: 0.16 | D12: SATISFIABLE | E12: 367974 | F12: 5.959 | G12: 13.72 | H12: 0.62 | I12: SATISFIABLE | J12: 326578 | K12: 4.957 | L12: 25.64 | M12: 14.4 | N12: SATISFIABLE | O12: 326578 | P12: 18.671 | Q12: =MIN($B12,$G12,$L12) -> 0 | R12: =MIN($C12,$H12,$M12) -> 0 | S12: =MIN($E12,$J12,$O12) -> 0 | T12: =MIN($F12,$K12,$P12) -> 0 | U12: =MEDIAN($B12,$G12,$L12) -> 0 | V12: =MEDIAN($C12,$H12,$M12) -> 0 | W12: =MEDIAN($E12,$J12,$O12) -> 0 | X12: =MEDIAN($F12,$K12,$P12) -> 0 | Y12: =MAX($B12,$G12,$L12) -> 0 | Z12: =MAX($C12,$H12,$M12) -> 0 | AA12: =MAX($E12,$J12,$O12) -> 0 | AB12: =MAX($F12,$K12,$P12) -> 0
A13: instances/x6_y6_a2_f10 | B13: 1200 | G13: 38.8 | H13: 25.05 | I13: SATISFIABLE | J13: 326689 | K13: 29.447 | L13: 51.85 | M13: 39.4 | N13: SATISFIABLE | O13: 326689 | P13: 43.633 | Q13: =MIN($B13,$G13,$L13) -> 0 | R13: =MIN($C13,$H13,$M13) -> 0 | S13: =MIN($E13,$J13,$O13) -> 0 | T13: =MIN($F13,$K13,$P13) -> 0 | U13: =MEDIAN($B13,$G13,$L13) -> 0 | V13: =MEDIAN($C13,$H13,$M13) -> 0 | W13: =MEDIAN($E13,$J13,$O13) -> 0 | X13: =MEDIAN($F13,$K13,$P13) -> 0 | Y13: =MAX($B13,$G13,$L13) -> 0 | Z13: =MAX($C13,$H13,$M13) -> 0 | AA13: =MAX($E13,$J13,$O13) -> 0 | AB13: =MAX($F13,$K13,$P13) -> 0
A14: instances/x6_y6_a2_f15 | B14: 1200 | G14: 40.16 | H14: 29.35 | I14: SATISFIABLE | J14: 326689 | K14: 34.035 | L14: 51.63 | M14: 39.29 | N14: SATISFIABLE | O14: 326689 | P14: 43.737 | Q14: =MIN($B14,$G14,$L14) -> 0 | R14: =MIN($C14,$H14,$M14) -> 0 | S14: =MIN($E14,$J14,$O14) -> 0 | T14: =MIN($F14,$K14,$P14) -> 0 | U14: =MEDIAN($B14,$G14,$L14) -> 0 | V14: =MEDIAN($C14,$H14,$M14) -> 0 | W14: =MEDIAN($E14,$J14,$O14) -> 0 | X14: =MEDIAN($F14,$K14,$P14) -> 0 | Y14: =MAX($B14,$G14,$L14) -> 0 | Z14: =MAX($C14,$H14,$M14) -> 0 | AA14: =MAX($E14,$J14,$O14) -> 0 | AB14: =MAX($F14,$K14,$P14) -> 0
A15: instances/x6_y6_a2_f20 | B15: 1200 | G15: 135.82 | H15: 122.25 | I15: SATISFIABLE | J15: 326689 | K15: 126.721 | L15: 53.43 | M15: 41.82 | N15: SATISFIABLE | O15: 326689 | P15: 47.03 | Q15: =MIN($B15,$G15,$L15) -> 0 | R15: =MIN($C15,$H15,$M15) -> 0 | S15: =MIN($E15,$J15,$O15) -> 0 | T15: =MIN($F15,$K15,$P15) -> 0 | U15: =MEDIAN($B15,$G15,$L15) -> 0 | V15: =MEDIAN($C15,$H15,$M15) -> 0 | W15: =MEDIAN($E15,$J15,$O15) -> 0 | X15: =MEDIAN($F15,$K15,$P15) -> 0 | Y15: =MAX($B15,$G15,$L15) -> 0 | Z15: =MAX($C15,$H15,$M15) -> 0 | AA15: =MAX($E15,$J15,$O15) -> 0 | AB15: =MAX($F15,$K15,$P15) -> 0
A16: instances/x6_y6_a2_f25 | B16: 1200 | C16: 0 | D16: UNKNOWN | E16: 0 | F16: 259.737 | G16: 48.42 | H16: 37.08 | I16: SATISFIABLE | J16: 326689 | K16: 41.793 | L16: 50.76 | M16: 39.94 | N16: SATISFIABLE | O16: 326689 | P16: 44.231 | Q16: =MIN($B16,$G16,$L16) -> 0 | R16: =MIN($C16,$H16,$M16) -> 0 | S16: =MIN($E16,$J16,$O16) -> 0 | T16: =MIN($F16,$K16,$P16) -> 0 | U16: =MEDIAN($B16,$G16,$L16) -> 0 | V16: =MEDIAN($C16,$H16,$M16) -> 0 | W16: =MEDIAN($E16,$J16,$O16) -> 0 | X16: =MEDIAN($F16,$K16,$P16) -> 0 | Y16: =MAX($B16,$G16,$L16) -> 0 | Z16: =MAX($C16,$H16,$M16) -> 0 | AA16: =MAX($E16,$J16,$O16) -> 0 | AB16: =MAX($F16,$K16,$P16) -> 0
A17: instances/x6_y6_a2_f30 | B17: 1200 | C17: 0 | D17: UNKNOWN | E17: 0 | F17: 263.801 | G17: 92.37 | H17: 79.2 | I17: SATISFIABLE | J17: 326689 | K17: 83.68 | L17: 63.72 | M17: 51.78 | N17: SATISFIABLE | O17: 326689 | P17: 57.285 | Q17: =MIN($B17,$G17,$L17) -> 0 | R17: =MIN($C17,$H17,$M17) -> 0 | S17: =MIN($E17,$J17,$O17) -> 0 | T17: =MIN($F17,$K17,$P17) -> 0 | U17: =MEDIAN($B17,$G17,$L17) -> 0 | V17: =MEDIAN($C17,$H17,$M17) -> 0 | W17: =MEDIAN($E17,$J17,$O17) -> 0 | X17: =MEDIAN($F17,$K17,$P17) -> 0 | Y17: =MAX($B17,$G17,$L17) -> 0 | Z17: =MAX($C17,$H17,$M17) -> 0 | AA17: =MAX($E17,$J17,$O17) -> 0 | AB17: =MAX($F17,$K17,$P17) -> 0
A18: instances/x6_y6_a2_f35 | B18: 1200 | C18: 0 | D18: UNKNOWN | E18: 0 | F18: 256.978 | G18: 19.59 | H18: 8.3 | I18: SATISFIABLE | J18: 326689 | K18: 13.005 | L18: 52.13 | M18: 39.09 | N18: SATISFIABLE | O18: 326689 | P18: 43.358 | Q18: =MIN($B18,$G18,$L18) -> 0 | R18: =MIN($C18,$H18,$M18) -> 0 | S18: =MIN($E18,$J18,$O18) -> 0 | T18: =MIN($F18,$K18,$P18) -> 0 | U18: =MEDIAN($B18,$G18,$L18) -> 0 | V18: =MEDIAN($C18,$H18,$M18) -> 0 | W18: =MEDIAN($E18,$J18,$O18) -> 0 | X18: =MEDIAN($F18,$K18,$P18) -> 0 | Y18: =MAX($B18,$G18,$L18) -> 0 | Z18: =MAX($C18,$H18,$M18) -> 0 | AA18: =MAX($E18,$J18,$O18) -> 0 | AB18: =MAX($F18,$K18,$P18) -> 0
A19: instances/x6_y6_a2_f40 | B19: 1200 | C19: 0 | D19: UNKNOWN | E19: 0 | F19: 214.776 | G19: 46.91 | H19: 33.01 | I19: SATISFIABLE | J19: 326689 | K19: 37.626 | L19: 50.29 | M19: 39.58 | N19: SATISFIABLE | O19: 326689 | P19: 43.841 | Q19: =MIN($B19,$G19,$L19) -> 0 | R19: =MIN($C19,$H19,$M19) -> 0 | S19: =MIN($E19,$J19,$O19) -> 0 | T19: =MIN($F19,$K19,$P19) -> 0 | U19: =MEDIAN($B19,$G19,$L19) -> 0 | V19: =MEDIAN($C19,$H19,$M19) -> 0 | W19: =MEDIAN($E19,$J19,$O19) -> 0 | X19: =MEDIAN($F19,$K19,$P19) -> 0 | Y19: =MAX($B19,$G19,$L19) -> 0 | Z19: =MAX($C19,$H19,$M19) -> 0 | AA19: =MAX($E19,$J19,$O19) -> 0 | AB19: =MAX($F19,$K19,$P19) -> 0
A20: instances/x6_y6_a2_f5 | B20: 422.24 | C20: 397.66 | D20: SATISFIABLE | E20: 2512383 | F20: 415.351 | G20: 62.27 | H20: 48.77 | I20: SATISFIABLE | J20: 326689 | K20: 53.164 | L20: 42.93 | M20: 31.79 | N20: SATISFIABLE | O20: 326689 | P20: 36.06 | Q20: =MIN($B20,$G20,$L20) -> 0 | R20: =MIN($C20,$H20,$M20) -> 0 | S20: =MIN($E20,$J20,$O20) -> 0 | T20: =MIN($F20,$K20,$P20) -> 0 | U20: =MEDIAN($B20,$G20,$L20) -> 0 | V20: =MEDIAN($C20,$H20,$M20) -> 0 | W20: =MEDIAN($E20,$J20,$O20) -> 0 | X20: =MEDIAN($F20,$K20,$P20) -> 0 | Y20: =MAX($B20,$G20,$L20) -> 0 | Z20: =MAX($C20,$H20,$M20) -> 0 | AA20: =MAX($E20,$J20,$O20) -> 0 | AB20: =MAX($F20,$K20,$P20) -> 0
A21: instances/x6_y6_a3_f1 | B21: 16.58 | C21: 1.91 | D21: SATISFIABLE | E21: 520090 | F21: 10.321 | G21: 17.25 | H21: 1.25 | I21: SATISFIABLE | J21: 480980 | K21: 7.809 | L21: 29.38 | M21: 14.26 | N21: SATISFIABLE | O21: 480980 | P21: 20.761 | Q21: =MIN($B21,$G21,$L21) -> 0 | R21: =MIN($C21,$H21,$M21) -> 0 | S21: =MIN($E21,$J21,$O21) -> 0 | T21: =MIN($F21,$K21,$P21) -> 0 | U21: =MEDIAN($B21,$G21,$L21) -> 0 | V21: =MEDIAN($C21,$H21,$M21) -> 0 | W21: =MEDIAN($E21,$J21,$O21) -> 0 | X21: =MEDIAN($F21,$K21,$P21) -> 0 | Y21: =MAX($B21,$G21,$L21) -> 0 | Z21: =MAX($C21,$H21,$M21) -> 0 | AA21: =MAX($E21,$J21,$O21) -> 0 | AB21: =MAX($F21,$K21,$P21) -> 0
A22: instances/x6_y6_a3_f10 | B22: 1200 | G22: 68.37 | H22: 52.34 | I22: SATISFIABLE | J22: 481091 | K22: 58.924 | L22: 328.34 | M22: 314.06 | N22: SATISFIABLE | O22: 481091 | P22: 321.997 | Q22: =MIN($B22,$G22,$L22) -> 0 | R22: =MIN($C22,$H22,$M22) -> 0 | S22: =MIN($E22,$J22,$O22) -> 0 | T22: =MIN($F22,$K22,$P22) -> 0 | U22: =MEDIAN($B22,$G22,$L22) -> 0 | V22: =MEDIAN($C22,$H22,$M22) -> 0 | W22: =MEDIAN($E22,$J22,$O22) -> 0 | X22: =MEDIAN($F22,$K22,$P22) -> 0 | Y22: =MAX($B22,$G22,$L22) -> 0 | Z22: =MAX($C22,$H22,$M22) -> 0 | AA22: =MAX($E22,$J22,$O22) -> 0 | AB22: =MAX($F22,$K22,$P22) -> 0
A23: instances/x6_y6_a3_f15 | B23: 1200 | G23: 296.38 | H23: 283.21 | I23: SATISFIABLE | J23: 481091 | K23: 290.57 | L23: 286.43 | M23: 271.62 | N23: SATISFIABLE | O23: 481091 | P23: 278.021 | Q23: =MIN($B23,$G23,$L23) -> 0 | R23: =MIN($C23,$H23,$M23) -> 0 | S23: =MIN($E23,$J23,$O23) -> 0 | T23: =MIN($F23,$K23,$P23) -> 0 | U23: =MEDIAN($B23,$G23,$L23) -> 0 | V23: =MEDIAN($C23,$H23,$M23) -> 0 | W23: =MEDIAN($E23,$J23,$O23) -> 0 | X23: =MEDIAN($F23,$K23,$P23) -> 0 | Y23: =MAX($B23,$G23,$L23) -> 0 | Z23: =MAX($C23,$H23,$M23) -> 0 | AA23: =MAX($E23,$J23,$O23) -> 0 | AB23: =MAX($F23,$K23,$P23) -> 0
A24: instances/x6_y6_a3_f20 | B24: 1200 | G24: 73.62 | H24: 57.53 | I24: SATISFIABLE | J24: 481091 | K24: 64.112 | L24: 271.99 | M24: 257.58 | N24: SATISFIABLE | O24: 481091 | P24: 264.049 | Q24: =MIN($B24,$G24,$L24) -> 0 | R24: =MIN($C24,$H24,$M24) -> 0 | S24: =MIN($E24,$J24,$O24) -> 0 | T24: =MIN($F24,$K24,$P24) -> 0 | U24: =MEDIAN($B24,$G24,$L24) -> 0 | V24: =MEDIAN($C24,$H24,$M24) -> 0 | W24: =MEDIAN($E24,$J24,$O24) -> 0 | X24: =MEDIAN($F24,$K24,$P24) -> 0 | Y24: =MAX($B24,$G24,$L24) -> 0 | Z24: =MAX($C24,$H24,$M24) -> 0 | AA24: =MAX($E24,$J24,$O24) -> 0 | AB24: =MAX($F24,$K24,$P24) -> 0
A25: instances/x6_y6_a3_f25 | B25: 1200 | C25: 0 | D25: UNKNOWN | E25: 0 | F25: 269.818 | G25: 131.91 | H25: 116.03 | I25: SATISFIABLE | J25: 481091 | K25: 122.644 | L25: 274.62 | M25: 260.38 | N25: SATISFIABLE | O25: 481091 | P25: 266.814 | Q25: =MIN($B25,$G25,$L25) -> 0 | R25: =MIN($C25,$H25,$M25) -> 0 | S25: =MIN($E25,$J25,$O25) -> 0 | T25: =MIN($F25,$K25,$P25) -> 0 | U25: =MEDIAN($B25,$G25,$L25) -> 0 | V25: =MEDIAN($C25,$H25,$M25) -> 0 | W25: =MEDIAN($E25,$J25,$O25) -> 0 | X25: =MEDIAN($F25,$K25,$P25) -> 0 | Y25: =MAX($B25,$G25,$L25) -> 0 | Z25: =MAX($C25,$H25,$M25) -> 0 | AA25: =MAX($E25,$J25,$O25) -> 0 | AB25: =MAX($F25,$K25,$P25) -> 0
A26: instances/x6_y6_a3_f30 | B26: 1200 | C26: 0 | D26: UNKNOWN | E26: 0 | F26: 190.12 | G26: 40.67 | H26: 26.67 | I26: SATISFIABLE | J26: 481091 | K26: 33.94 | L26: 282.52 | M26: 269.27 | N26: SATISFIABLE | O26: 481091 | P26: 275.697 | Q26: =MIN($B26,$G26,$L26) -> 0 | R26: =MIN($C26,$H26,$M26) -> 0 | S26: =MIN($E26,$J26,$O26) -> 0 | T26: =MIN($F26,$K26,$P26) -> 0 | U26: =MEDIAN($B26,$G26,$L26) -> 0 | V26: =MEDIAN($C26,$H26,$M26) -> 0 | W26: =MEDIAN($E26,$J26,$O26) -> 0 | X26: =MEDIAN($F26,$K26,$P26) -> 0 | Y26: =MAX($B26,$G26,$L26) -> 0 | Z26: =MAX($C26,$H26,$M26) -> 0 | AA26: =MAX($E26,$J26,$O26) -> 0 | AB26: =MAX($F26,$K26,$P26) -> 0
A27: instances/x6_y6_a3_f35 | B27: 1200 | C27: 0 | D27: UNKNOWN | E27: 0 | F27: 259.328 | G27: 38.28 | H27: 22.28 | I27: SATISFIABLE | J27: 481091 | K27: 28.904 | L27: 283.7 | M27: 270.72 | N27: SATISFIABLE | O27: 481091 | P27: 277.086 | Q27: =MIN($B27,$G27,$L27) -> 0 | R27: =MIN($C27,$H27,$M27) -> 0 | S27: =MIN($E27,$J27,$O27) -> 0 | T27: =MIN($F27,$K27,$P27) -> 0 | U27: =MEDIAN($B27,$G27,$L27) -> 0 | V27: =MEDIAN($C27,$H27,$M27) -> 0 | W27: =MEDIAN($E27,$J27,$O27) -> 0 | X27: =MEDIAN($F27,$K27,$P27) -> 0 | Y27: =MAX($B27,$G27,$L27) -> 0 | Z27: =MAX($C27,$H27,$M27) -> 0 | AA27: =MAX($E27,$J27,$O27) -> 0 | AB27: =MAX($F27,$K27,$P27) -> 0
A28: instances/x6_y6_a3_f40 | B28: 1200 | C28: 0 | D28: UNKNOWN | E28: 0 | F28: 181.632 | G28: 150.09 | H28: 136.14 | I28: SATISFIABLE | J28: 481091 | K28: 143.447 | L28: 283.45 | M28: 268.39 | N28: SATISFIABLE | O28: 481091 | P28: 274.89 | Q28: =MIN($B28,$G28,$L28) -> 0 | R28: =MIN($C28,$H28,$M28) -> 0 | S28: =MIN($E28,$J28,$O28) -> 0 | T28: =MIN($F28,$K28,$P28) -> 0 | U28: =MEDIAN($B28,$G28,$L28) -> 0 | V28: =MEDIAN($C28,$H28,$M28) -> 0 | W28: =MEDIAN($E28,$J28,$O28) -> 0 | X28: =MEDIAN($F28,$K28,$P28) -> 0 | Y28: =MAX($B28,$G28,$L28) -> 0 | Z28: =MAX($C28,$H28,$M28) -> 0 | AA28: =MAX($E28,$J28,$O28) -> 0 | AB28: =MAX($F28,$K28,$P28) -> 0
A29: instances/x6_y6_a3_f5 | B29: 709.53 | C29: 682.5 | D29: SATISFIABLE | E29: 2664499 | F29: 702.544 | G29: 108.42 | H29: 92.42 | I29: SATISFIABLE | J29: 481091 | K29: 99.071 | L29: 289.56 | M29: 275.19 | N29: SATISFIABLE | O29: 481091 | P29: 281.627 | Q29: =MIN($B29,$G29,$L29) -> 0 | R29: =MIN($C29,$H29,$M29) -> 0 | S29: =MIN($E29,$J29,$O29) -> 0 | T29: =MIN($F29,$K29,$P29) -> 0 | U29: =MEDIAN($B29,$G29,$L29) -> 0 | V29: =MEDIAN($C29,$H29,$M29) -> 0 | W29: =MEDIAN($E29,$J29,$O29) -> 0 | X29: =MEDIAN($F29,$K29,$P29) -> 0 | Y29: =MAX($B29,$G29,$L29) -> 0 | Z29: =MAX($C29,$H29,$M29) -> 0 | AA29: =MAX($E29,$J29,$O29) -> 0 | AB29: =MAX($F29,$K29,$P29) -> 0
A30: instances/x6_y6_a4_f1 | B30: 18 | C30: 0.4 | D30: SATISFIABLE | E30: 673826 | F30: 11.588 | G30: 16.84 | H30: 0.91 | I30: SATISFIABLE | J30: 637002 | K30: 10.264 | L30: 27.37 | M30: 10.72 | N30: SATISFIABLE | O30: 637002 | P30: 19.205 | Q30: =MIN($B30,$G30,$L30) -> 0 | R30: =MIN($C30,$H30,$M30) -> 0 | S30: =MIN($E30,$J30,$O30) -> 0 | T30: =MIN($F30,$K30,$P30) -> 0 | U30: =MEDIAN($B30,$G30,$L30) -> 0 | V30: =MEDIAN($C30,$H30,$M30) -> 0 | W30: =MEDIAN($E30,$J30,$O30) -> 0 | X30: =MEDIAN($F30,$K30,$P30) -> 0 | Y30: =MAX($B30,$G30,$L30) -> 0 | Z30: =MAX($C30,$H30,$M30) -> 0 | AA30: =MAX($E30,$J30,$O30) -> 0 | AB30: =MAX($F30,$K30,$P30) -> 0
A31: instances/x6_y6_a4_f10 | B31: 1200 | G31: 120.81 | H31: 102.87 | I31: SATISFIABLE | J31: 637113 | K31: 111.573 | L31: 1181.22 | M31: 1165.36 | N31: SATISFIABLE | O31: 637113 | P31: 1174.03 | Q31: =MIN($B31,$G31,$L31) -> 0 | R31: =MIN($C31,$H31,$M31) -> 0 | S31: =MIN($E31,$J31,$O31) -> 0 | T31: =MIN($F31,$K31,$P31) -> 0 | U31: =MEDIAN($B31,$G31,$L31) -> 0 | V31: =MEDIAN($C31,$H31,$M31) -> 0 | W31: =MEDIAN($E31,$J31,$O31) -> 0 | X31: =MEDIAN($F31,$K31,$P31) -> 0 | Y31: =MAX($B31,$G31,$L31) -> 0 | Z31: =MAX($C31,$H31,$M31) -> 0 | AA31: =MAX($E31,$J31,$O31) -> 0 | AB31: =MAX($F31,$K31,$P31) -> 0
A32: instances/x6_y6_a4_f15 | B32: 1200 | G32: 70.47 | H32: 54.11 | I32: SATISFIABLE | J32: 637113 | K32: 63.946 | L32: 1169.77 | M32: 1153.44 | N32: SATISFIABLE | O32: 637113 | P32: 1162.059 | Q32: =MIN($B32,$G32,$L32) -> 0 | R32: =MIN($C32,$H32,$M32) -> 0 | S32: =MIN($E32,$J32,$O32) -> 0 | T32: =MIN($F32,$K32,$P32) -> 0 | U32: =MEDIAN($B32,$G32,$L32) -> 0 | V32: =MEDIAN($C32,$H32,$M32) -> 0 | W32: =MEDIAN($E32,$J32,$O32) -> 0 | X32: =MEDIAN($F32,$K32,$P32) -> 0 | Y32: =MAX($B32,$G32,$L32) -> 0 | Z32: =MAX($C32,$H32,$M32) -> 0 | AA32: =MAX($E32,$J32,$O32) -> 0 | AB32: =MAX($F32,$K32,$P32) -> 0
A33: instances/x6_y6_a4_f20 | B33: 1200 | D33: UNKNOWN | G33: 50.05 | H33: 31.91 | I33: SATISFIABLE | J33: 637113 | K33: 40.685 | L33: 1182.83 | M33: 1165.82 | N33: SATISFIABLE | O33: 637113 | P33: 1174.368 | Q33: =MIN($B33,$G33,$L33) -> 0 | R33: =MIN($C33,$H33,$M33) -> 0 | S33: =MIN($E33,$J33,$O33) -> 0 | T33: =MIN($F33,$K33,$P33) -> 0 | U33: =MEDIAN($B33,$G33,$L33) -> 0 | V33: =MEDIAN($C33,$H33,$M33) -> 0 | W33: =MEDIAN($E33,$J33,$O33) -> 0 | X33: =MEDIAN($F33,$K33,$P33) -> 0 | Y33: =MAX($B33,$G33,$L33) -> 0 | Z33: =MAX($C33,$H33,$M33) -> 0 | AA33: =MAX($E33,$J33,$O33) -> 0 | AB33: =MAX($F33,$K33,$P33) -> 0
A34: instances/x6_y6_a4_f25 | B34: 1200 | C34: 0 | D34: UNKNOWN | E34: 0 | F34: 242.127 | G34: 331.06 | H34: 314.99 | I34: SATISFIABLE | J34: 637113 | K34: 324.3 | L34: 1186.01 | M34: 1170.19 | N34: SATISFIABLE | O34: 637113 | P34: 1178.792 | Q34: =MIN($B34,$G34,$L34) -> 0 | R34: =MIN($C34,$H34,$M34) -> 0 | S34: =MIN($E34,$J34,$O34) -> 0 | T34: =MIN($F34,$K34,$P34) -> 0 | U34: =MEDIAN($B34,$G34,$L34) -> 0 | V34: =MEDIAN($C34,$H34,$M34) -> 0 | W34: =MEDIAN($E34,$J34,$O34) -> 0 | X34: =MEDIAN($F34,$K34,$P34) -> 0 | Y34: =MAX($B34,$G34,$L34) -> 0 | Z34: =MAX($C34,$H34,$M34) -> 0 | AA34: =MAX($E34,$J34,$O34) -> 0 | AB34: =MAX($F34,$K34,$P34) -> 0
A35: instances/x6_y6_a4_f30 | B35: 1200 | C35: 0 | D35: UNKNOWN | E35: 0 | F35: 262.179 | G35: 156.51 | H35: 140.95 | I35: SATISFIABLE | J35: 637113 | K35: 150.329 | L35: 1172.12 | M35: 1156.34 | N35: SATISFIABLE | O35: 637113 | P35: 1164.874 | Q35: =MIN($B35,$G35,$L35) -> 0 | R35: =MIN($C35,$H35,$M35) -> 0 | S35: =MIN($E35,$J35,$O35) -> 0 | T35: =MIN($F35,$K35,$P35) -> 0 | U35: =MEDIAN($B35,$G35,$L35) -> 0 | V35: =MEDIAN($C35,$H35,$M35) -> 0 | W35: =MEDIAN($E35,$J35,$O35) -> 0 | X35: =MEDIAN($F35,$K35,$P35) -> 0 | Y35: =MAX($B35,$G35,$L35) -> 0 | Z35: =MAX($C35,$H35,$M35) -> 0 | AA35: =MAX($E35,$J35,$O35) -> 0 | AB35: =MAX($F35,$K35,$P35) -> 0
A36: instances/x6_y6_a4_f35 | B36: 1200 | C36: 0 | D36: UNKNOWN | E36: 0 | F36: 265.252 | G36: 118.5 | H36: 100.37 | I36: SATISFIABLE | J36: 637113 | K36: 109.154 | L36: 1179.62 | M36: 1162.26 | N36: SATISFIABLE | O36: 637113 | P36: 1170.83 | Q36: =MIN($B36,$G36,$L36) -> 0 | R36: =MIN($C36,$H36,$M36) -> 0 | S36: =MIN($E36,$J36,$O36) -> 0 | T36: =MIN($F36,$K36,$P36) -> 0 | U36: =MEDIAN($B36,$G36,$L36) -> 0 | V36: =MEDIAN($C36,$H36,$M36) -> 0 | W36: =MEDIAN($E36,$J36,$O36) -> 0 | X36: =MEDIAN($F36,$K36,$P36) -> 0 | Y36: =MAX($B36,$G36,$L36) -> 0 | Z36: =MAX($C36,$H36,$M36) -> 0 | AA36: =MAX($E36,$J36,$O36) -> 0 | AB36: =MAX($F36,$K36,$P36) -> 0
A37: instances/x6_y6_a4_f40 | B37: 1200 | C37: 0 | D37: UNKNOWN | E37: 0 | F37: 248.844 | G37: 30.14 | H37: 12.09 | I37: SATISFIABLE | J37: 637113 | K37: 20.859 | L37: 1188.52 | M37: 1171.39 | N37: SATISFIABLE | O37: 637113 | P37: 1182 | Q37: =MIN($B37,$G37,$L37) -> 0 | R37: =MIN($C37,$H37,$M37) -> 0 | S37: =MIN($E37,$J37,$O37) -> 0 | T37: =MIN($F37,$K37,$P37) -> 0 | U37: =MEDIAN($B37,$G37,$L37) -> 0 | V37: =MEDIAN($C37,$H37,$M37) -> 0 | W37: =MEDIAN($E37,$J37,$O37) -> 0 | X37: =MEDIAN($F37,$K37,$P37) -> 0 | Y37: =MAX($B37,$G37,$L37) -> 0 | Z37: =MAX($C37,$H37,$M37) -> 0 | AA37: =MAX($E37,$J37,$O37) -> 0 | AB37: =MAX($F37,$K37,$P37) -> 0
A38: instances/x6_y6_a4_f5 | B38: 1200 | C38: 1170.98 | D38: UNKNOWN | E38: 2818235 | F38: 1194.082 | G38: 202.02 | H38: 183.98 | I38: SATISFIABLE | J38: 637113 | K38: 192.577 | L38: 1200 | M38: 1184.69 | N38: UNKNOWN | O38: 637113 | P38: 1194.386 | Q38: =MIN($B38,$G38,$L38) -> 0 | R38: =MIN($C38,$H38,$M38) -> 0 | S38: =MIN($E38,$J38,$O38) -> 0 | T38: =MIN($F38,$K38,$P38) -> 0 | U38: =MEDIAN($B38,$G38,$L38) -> 0 | V38: =MEDIAN($C38,$H38,$M38) -> 0 | W38: =MEDIAN($E38,$J38,$O38) -> 0 | X38: =MEDIAN($F38,$K38,$P38) -> 0 | Y38: =MAX($B38,$G38,$L38) -> 0 | Z38: =MAX($C38,$H38,$M38) -> 0 | AA38: =MAX($E38,$J38,$O38) -> 0 | AB38: =MAX($F38,$K38,$P38) -> 0
A40: SUM | B40: =SUM(B$3:B$38) -> 0 | C40: =SUM(C$3:C$38) -> 0 | E40: =SUM(E$3:E$38) -> 0 | F40: =SUM(F$3:F$38) -> 0 | G40: =SUM(G$3:G$38) -> 0 | H40: =SUM(H$3:H$38) -> 0 | J40: =SUM(J$3:J$38) -> 0 | K40: =SUM(K$3:K$38) -> 0 | L40: =SUM(L$3:L$38) -> 0 | M40: =SUM(M$3:M$38) -> 0 | O40: =SUM(O$3:O$38) -> 0 | P40: =SUM(P$3:P$38) -> 0 | Q40: =SUM(Q$3:Q$38) -> 0 | R40: =SUM(R$3:R$38) -> 0 | S40: =SUM(S$3:S$38) -> 0 | T40: =SUM(T$3:T$38) -> 0 | U40: =SUM(U$3:U$38) -> 0 | V40: =SUM(V$3:V$38) -> 0 | ... AB40: =SUM(AB$3:AB$38) -> 0
A41: AVG | B41: =AVERAGE(B$3:B$38) -> 0 | C41: =AVERAGE(C$3:C$38) -> 0 | E41: =AVERAGE(E$3:E$38) -> 0 | F41: =AVERAGE(F$3:F$38) -> 0 | G41: =AVERAGE(G$3:G$38) -> 0 | H41: =AVERAGE(H$3:H$38) -> 0 | J41: =AVERAGE(J$3:J$38) -> 0 | K41: =AVERAGE(K$3:K$38) -> 0 | L41: =AVERAGE(L$3:L$38) -> 0 | M41: =AVERAGE(M$3:M$38) -> 0 | O41: =AVERAGE(O$3:O$38) -> 0 | P41: =AVERAGE(P$3:P$38) -> 0 | Q41: =AVERAGE(Q$3:Q$38) -> 0 | R41: =AVERAGE(R$3:R$38) -> 0 | S41: =AVERAGE(S$3:S$38) -> 0 | T41: =AVERAGE(T$3:T$38) -> 0 | U41: =AVERAGE(U$3:U$38) -> 0 | V41: =AVERAGE(V$3:V$38) -> 0 | ... AB41: =AVERAGE(AB$3:AB$38) -> 0
...

Sheet Merged Runs
A1: Merge criteria: | B1: memelingo-1/allapproaches_mlp-tplp-ht | G1: memelingo-1/allapproaches_mlp-tplp-htc | L1: memelingo-1/allapproaches_mlp-tplp-htcdl | Q1: min | U1: median | Y1: max
A2: median | B2: time | C2: stime | D2: status | E2: rules | F2: ctime | G2: time | H2: stime | I2: status | J2: rules | K2: ctime | L2: time | M2: stime | N2: status | O2: rules | P2: ctime | Q2: time | R2: stime | S2: rules | T2: ctime | U2: time | V2: stime | W2: rules | X2: ctime | Y2: time | Z2: stime | AA2: rules | AB2: ctime
A3: instances/x6_y6_a1_f1 | B3: {=_xlfn.SWITCH($A$2,"average", AVERAGE(Instances!B3:Instances!B3),"median", MEDIAN(Instances!B3:Instances!B3),"min", MIN(Instances!B3:Instances!B3),"max", MAX(Instances!B3:Instances!B3),"diff", MAX(Instances!B3:Instances!B3)-MIN(Instances!B3:Instances!B3))} -> 0 | C3: {=_xlfn.SWITCH($A$2,"average", AVERAGE(Instances!C3:Instances!C3),"median", MEDIAN(Instances!C3:Instances!C3),"min", MIN(Instances!C3:Instances!C3),"max", MAX(Instances!C3:Instances!C3),"diff", MAX(Instances!C3:Instances!C3)-MIN(Instances!C3:Instances!C3))} -> 0 | E3: {=_xlfn.SWITCH($A$2,"average", AVERAGE(Instances!E3:Instances!E3),"median", MEDIAN(Instances!E3:Instances!E3),"min", MIN(Instances!E3:Instances!E3),"max", MAX(Instances!E3:Instances!E3),"diff", MAX(Instances!E3:Instances!E3)-MIN(Instances!E3:Instances!E3))} -> 0 | F3: {=_xlfn.SWITCH($A$2,"average", AVERAGE(Instances!F3:Instances!F3),"median", MEDIAN(Instances!F3:Instances!F3),"min", MIN(Instances!F3:Instances!F3),"max", MAX(Instances!F3:Instances!F3),"diff", MAX(Instances!F3:Instances!F3)-MIN(Instances!F3:Instances!F3))} -> 0 | G3: {=_xlfn.SWITCH($A$2,"average", AVERAGE(Instances!G3:Instances!G3),"median", MEDIAN(Instances!G3:Instances!G3),"min", MIN(Instances!G3:Instances!G3),"max", MAX(Instances!G3:Instances!G3),"diff", MAX(Instances!G3:Instances!G3)-MIN(Instances!G3:Instances!G3))} -> 0 | H3: {=_xlfn.SWITCH($A$2,"average", AVERAGE(Instances!H3:Instances!H3),"median", MEDIAN(Instances!H3:Instances!H3),"min", MIN(Instances!H3:Instances!H3),"max", MAX(Instances!H3:Instances!H3),"diff", MAX(Instances!H3:Instances!H3)-MIN(Instances!H3:Instances!H3))} -> 0 | J3: {=_xlfn.SWITCH($A$2,"average", AVERAGE(Instances!J3:Instances!J3),"median", MEDIAN(Instances!J3:Instances!J3),"min", MIN(Instances!J3:Instances!J3),"max", MAX(Instances!J3:Instances!J3),"diff", MAX(Instances!J3:Instances!J3)-MIN(Instances!J3:Instances!J3))} -> 0 | K3: {=_xlfn.SWITCH($A$2,"average", AVERAGE(Instances!K3:Instances!K3),"median", MEDIAN(Instances!K3:Instances!K3),"min", MIN(Instances!K3:Instances!K3),"max", MAX(Instances!K3:Instances!K3),"diff", MAX(Instances!K3:Instances!K3)-MIN(Instances!K3:Instances!K3))} -> 0 | L3: {=_xlfn.SWITCH($A$2,"average", AVERAGE(Instances!L3:Instances!L3),"median", MEDIAN(Instances!L3:Instances!L3),"min", MIN(Instances!L3:Instances!L3),"max", MAX(Instances!L3:Instances!L3),"diff", MAX(Instances!L3:Instances!L3)-MIN(Instances!L3:Instances!L3))} -> 0 | M3: {=_xlfn.SWITCH($A$2,"average", AVERAGE(Instances!M3:Instances!M3),"median", MEDIAN(Instances!M3:Instances!M3),"min", MIN(Instances!M3:Instances!M3),"max", MAX(Instances!M3:Instances!M3),"diff", MAX(Instances!M3:Instances!M3)-MIN(Instances!M3:Instances!M3))} -> 0 | O3: {=_xlfn.SWITCH($A$2,"average", AVERAGE(Instances!O3:Instances!O3),"median", MEDIAN(Instances!O3:Instances!O3),"min", MIN(Instances!O3:Instances!O3),"max", MAX(Instances!O3:Instances!O3),"diff", MAX(Instances!O3:Instances!O3)-MIN(Instances!O3:Instances!O3))} -> 0 | P3: {=_xlfn.SWITCH($A$2,"average", AVERAGE(Instances!P3:Instances!P3),"median", MEDIAN(Instances!P3:Instances!P3),"min", MIN(Instances!P3:Instances!P3),"max", MAX(Instances!P3:Instances!P3),"diff", MAX(Instances!P3:Instances!P3)-MIN(Instances!P3:Instances!P3))} -> 0 | Q3: =MIN($B3,$G3,$L3) -> 0 | R3: =MIN($C3,$H3,$M3) -> 0 | S3: =MIN($E3,$J3,$O3) -> 0 | T3: =MIN($F3,$K3,$P3) -> 0 | U3: =MEDIAN($B3,$G3,$L3) -> 0 | V3: =MEDIAN($C3,$H3,$M3) -> 0 | W3: =MEDIAN($E3,$J3,$O3) -> 0 | X3: =MEDIAN($F3,$K3,$P3) -> 0 | Y3: =MAX($B3,$G3,$L3) -> 0 | Z3: =MAX($C3,$H3,$M3) -> 0 | AA3: =MAX($E3,$J3,$O3) -> 0 | AB3: =MAX($F3,$K3,$P3) -> 0
A4: instances/x6_y6_a1_f10 | B4: {=_xlfn.SWITCH($A$2,"average", AVERAGE(Instances!B4:Instances!B4),"median", MEDIAN(Instances!B4:Instances!B4),"min", MIN(Instances!B4:Instances!B4),"max", MAX(Instances!B4:Instances!B4),"diff", MAX(Instances!B4:Instances!B4)-MIN(Instances!B4:Instances!B4))} -> 0 | C4: {=_xlfn.SWITCH($A$2,"average", AVERAGE(Instances!C4:Instances!C4),"median", MEDIAN(Instances!C4:Instances!C4),"min", MIN(Instances!C4:Instances!C4),"max", MAX(Instances!C4:Instances!C4),"diff", MAX(Instances!C4:Instances!C4)-MIN(Instances!C4:Instances!C4))} -> 0 | E4: {=_xlfn.SWITCH($A$2,"average", AVERAGE(Instances!E4:Instances!E4),"median", MEDIAN(Instances!E4:Instances!E4),"min", MIN(Instances!E4:Instances!E4),"max", MAX(Instances!E4:Instances!E4),"diff", MAX(Instances!E4:Instances!E4)-MIN(Instances!E4:Instances!E4))} -> 0 | F4: {=_xlfn.SWITCH($A$2,"average", AVERAGE(Instances!F4:Instances!F4),"median", MEDIAN(Instances!F4:Instances!F4),"min", MIN(Instances!F4:Instances!F4),"max", MAX(Instances!F4:Instances!F4),"diff", MAX(Instances!F4:Instances!F4)-MIN(Instances!F4:Instances!F4))} -> 0 | G4: {=_xlfn.SWITCH($A$2,"average", AVERAGE(Instances!G4:Instances!G4),"median", MEDIAN(Instances!G4:Instances!G4),"min", MIN(Instances!G4:Instances!G4),"max", MAX(Instances!G4:Instances!G4),"diff", MAX(Instances!G4:Instances!G4)-MIN(Instances!G4:Instances!G4))} -> 0 | H4: {=_xlfn.SWITCH($A$2,"average", AVERAGE(Instances!H4:Instances!H4),"median", MEDIAN(Instances!H4:Instances!H4),"min", MIN(Instances!H4:Instances!H4),"max", MAX(Instances!H4:Instances!H4),"diff", MAX(Instances!H4:Instances!H4)-MIN(Instances!H4:Instances!H4))} -> 0 | J4: {=_xlfn.SWITCH($A$2,"average", AVERAGE(Instances!J4:Instances!J4),"median", MEDIAN(Instances!J4:Instances!J4),"min", MIN(Instances!J4:Instances!J4),"max", MAX(Instances!J4:Instances!J4),"diff", MAX(Instances!J4:Instances!J4)-MIN(Instances!J4:Instances!J4))} -> 0 | K4: {=_xlfn.SWITCH($A$2,"average", AVERAGE(Instances!K4:Instances!K4),"median", MEDIAN(Instances!K4:Instances!K4),"min", MIN(Instances!K4:Instances!K4),"max", MAX(Instances!K4:Instances!K4),"diff", MAX(Instances!K4:Instances!K4)-MIN(Instances!K4:Instances!K4))} -> 0 | L4: {=_xlfn.SWITCH($A$2,"average", AVERAGE(Instances!L4:Instances!L4),"median", MEDIAN(Instances!L4:Instances!L4),"min", MIN(Instances!L4:Instances!L4),"max", MAX(Instances!L4:Instances!L4),"diff", MAX(Instances!L4:Instances!L4)-MIN(Instances!L4:Instances!L4))} -> 0 | M4: {=_xlfn.SWITCH($A$2,"average", AVERAGE(Instances!M4:Instances!M4),"median", MEDIAN(Instances!M4:Instances!M4),"min", MIN(Instances!M4:Instances!M4),"max", MAX(Instances!M4:Instances!M4),"diff", MAX(Instances!M4:Instances!M4)-MIN(Instances!M4:Instances!M4))} -> 0 | O4: {=_xlfn.SWITCH($A$2,"average", AVERAGE(Instances!O4:Instances!O4),"median", MEDIAN(Instances!O4:Instances!O4),"min", MIN(Instances!O4:Instances!O4),"max", MAX(Instances!O4:Instances!O4),"diff", MAX(Instances!O4:Instances!O4)-MIN(Instances!O4:Instances!O4))} -> 0 | P4: {=_xlfn.SWITCH($A$2,"average", AVERAGE(Instances!P4:Instances!P4),"median", MEDIAN(Instances!P4:Instances!P4),"min", MIN(Instances!P4:Instances!P4),"max", MAX(Instances!P4:Instances!P4),"diff", MAX(Instances!P4:Instances!P4)-MIN(Instances!P4:Instances!P4))} -> 0 | Q4: =MIN($B4,$G4,$L4) -> 0 | R4: =MIN($C4,$H4,$M4) -> 0 | S4: =MIN($E4,$J4,$O4) -> 0 | T4: =MIN($F4,$K4,$P4) -> 0 | U4: =MEDIAN($B4,$G4,$L4) -> 0 | V4: =MEDIAN($C4,$H4,$M4) -> 0 | W4: =MEDIAN($E4,$J4,$O4) -> 0 | X4: =MEDIAN($F4,$K4,$P4) -> 0 | Y4: =MAX($B4,$G4,$L4) -> 0 | Z4: =MAX($C4,$H4,$M4) -> 0 | AA4: =MAX($E4,$J4,$O4) -> 0 | AB4: =MAX($F4,$K4,$P4) -> 0
A5: instances/x6_y6_a1_f15 | B5: {=_xlfn.SWITCH($A$2,"average", AVERAGE(Instances!B5:Instances!B5),"median", MEDIAN(Instances!B5:Instances!B5),"min", MIN(Instances!B5:Instances!B5),"max", MAX(Instances!B5:Instances!B5),"diff", MAX(Instances!B5:Instances!B5)-MIN(Instances!B5:Instances!B5))} -> 0 | C5: {=_xlfn.SWITCH($A$2,"average", AVERAGE(Instances!C5:Instances!C5),"median", MEDIAN(Instances!C5:Instances!C5),"min", MIN(Instances!C5:Instances!C5),"max", MAX(Instances!C5:Instances!C5),"diff", MAX(Instances!C5:Instances!C5)-MIN(Instances!C5:Instances!C5))} -> 0 | E5: {=_xlfn.SWITCH($A$2,"average", AVERAGE(Instances!E5:Instances!E5),"median", MEDIAN(Instances!E5:Instances!E5),"min", MIN(Instances!E5:Instances!E5),"max", MAX(Instances!E5:Instances!E5),"diff", MAX(Instances!E5:Instances!E5)-MIN(Instances!E5:Instances!E5))} -> 0 | F5: {=_xlfn.SWITCH($A$2,"average", AVERAGE(Instances!F5:Instances!F5),"median", MEDIAN(Instances!F5:Instances!F5),"min", MIN(Instances!F5:Instances!F5),"max", MAX(Instances!F5:Instances!F5),"diff", MAX(Instances!F5:Instances!F5)-MIN(Instances!F5:Instances!F5))} -> 0 | G5: {=_xlfn.SWITCH($A$2,"average", AVERAGE(Instances!G5:Instances!G5),"median", MEDIAN(Instances!G5:Instances!G5),"min", MIN(Instances!G5:Instances!G5),"max", MAX(Instances!G5:Instances!G5),"diff", MAX(Instances!G5:Instances!G5)-MIN(Instances!G5:Instances!G5))} -> 0 | H5: {=_xlfn.SWITCH($A$2,"average", AVERAGE(Instances!H5:Instances!H5),"median", MEDIAN(Instances!H5:Instances!H5),"min", MIN(Instances!H5:Instances!H5),"max", MAX(Instances!H5:Instances!H5),"diff", MAX(Instances!H5:Instances!H5)-MIN(Instances!H5:Instances!H5))} -> 0 | J5: {=_xlfn.SWITCH($A$2,"average", AVERAGE(Instances!J5:Instances!J5),"median", MEDIAN(Instances!J5:Instances!J5),"min", MIN(Instances!J5:Instances!J5),"max", MAX(Instances!J5:Instances!J5),"diff", MAX(Instances!J5:Instances!J5)-MIN(Instances!J5:Instances!J5))} -> 0 | K5: {=_xlfn.SWITCH($A$2,"average", AVERAGE(Instances!K5:Instances!K5),"median", MEDIAN(Instances!K5:Instances!K5),"min", MIN(Instances!K5:Instances!K5),"max", MAX(Instances!K5:Instances!K5),"diff", MAX(Instances!K5:Instances!K5)-MIN(Instances!K5:Instances!K5))} -> 0 | L5: {=_xlfn.SWITCH($A$2,"average", AVERAGE(Instances!L5:Instances!L5),"median", MEDIAN(Instances!L5:Instances!L5),"min", MIN(Instances!L5:Instances!L5),"max", MAX(Instances!L5:Instances!L5),"diff", MAX(Instances!L5:Instances!L5)-MIN(Instances!L5:Instances!L5))} -> 0 | M5: {=_xlfn.SWITCH($A$2,"average", AVERAGE(Instances!M5:Instances!M5),"median", MEDIAN(Instances!M5:Instances!M5),"min", MIN(Instances!M5:Instances!M5),"max", MAX(Instances!M5:Instances!M5),"diff", MAX(Instances!M5:Instances!M5)-MIN(Instances!M5:Instances!M5))} -> 0 | O5: {=_xlfn.SWITCH($A$2,"average", AVERAGE(Instances!O5:Instances!O5),"median", MEDIAN(Instances!O5:Instances!O5),"min", MIN(Instances!O5:Instances!O5),"max", MAX(Instances!O5:Instances!O5),"diff", MAX(Instances!O5:Instances!O5)-MIN(Instances!O5:Instances!O5))} -> 0 | P5: {=_xlfn.SWITCH($A$2,"average", AVERAGE(Instances!P5:Instances!P5),"median", MEDIAN(Instances!P5:Instances!P5),"min", MIN(Instances!P5:Instances!P5),"max", MAX(Instances!P5:Instances!P5),"diff", MAX(Instances!P5:Instances!P5)-MIN(Instances!P5:Instances!P5))} -> 0 | Q5: =MIN($B5,$G5,$L5) -> 0 | R5: =MIN($C5,$H5,$M5) -> 0 | S5: =MIN($E5,$J5,$O5) -> 0 | T5: =MIN($F5,$K5,$P5) -> 0 | U5: =MEDIAN($B5,$G5,$L5) -> 0 | V5: =MEDIAN($C5,$H5,$M5) -> 0 | W5: =MEDIAN($E5,$J5,$O5) -> 0 | X5: =MEDIAN($F5,$K5,$P5) -> 0 | Y5: =MAX($B5,$G5,$L5) -> 0 | Z5: =MAX($C5,$H5,$M5) -> 0 | AA5: =MAX($E5,$J5,$O5) -> 0 | AB5: =MAX($F5,$K5,$P5) -> 0
A6: instances/x6_y6_a1_f20 | B6: {=_xlfn.SWITCH($A$2,"average", AVERAGE(Instances!B6:Instances!B6),"median", MEDIAN(Instances!B6:Instances!B6),"min", MIN(Instances!B6:Instances!B6),"max", MAX(Instances!B6:Instances!B6),"diff", MAX(Instances!B6:Instances!B6)-MIN(Instances!B6:Instances!B6))} -> 0 | C6: {=_xlfn.SWITCH($A$2,"average", AVERAGE(Instances!C6:Instances!C6),"median", MEDIAN(Instances!C6:Instances!C6),"min", MIN(Instances!C6:Instances!C6),"max", MAX(Instances!C6:Instances!C6),"diff", MAX(Instances!C6:Instances!C6)-MIN(Instances!C6:Instances!C6))} -> 0 | E6: {=_xlfn.SWITCH($A$2,"average", AVERAGE(Instances!E6:Instances!E6),"median", MEDIAN(Instances!E6:Instances!E6),"min", MIN(Instances!E6:Instances!E6),"max", MAX(Instances!E6:Instances!E6),"diff", MAX(Instances!E6:Instances!E6)-MIN(Instances!E6:Instances!E6))} -> 0 | F6: {=_xlfn.SWITCH($A$2,"average", AVERAGE(Instances!F6:Instances!F6),"median", MEDIAN(Instances!F6:Instances!F6),"min", MIN(Instances!F6:Instances!F6),"max", MAX(Instances!F6:Instances!F6),"diff", MAX(Instances!F6:Instances!F6)-MIN(Instances!F6:Instances!F6))} -> 0 | G6: {=_xlfn.SWITCH($A$2,"average", AVERAGE(Instances!G6:Instances!G6),"median", MEDIAN(Instances!G6:Instances!G6),"min", MIN(Instances!G6:Instances!G6),"max", MAX(Instances!G6:Instances!G6),"diff", MAX(Instances!G6:Instances!G6)-MIN(Instances!G6:Instances!G6))} -> 0 | H6: {=_xlfn.SWITCH($A$2,"average", AVERAGE(Instances!H6:Instances!H6),"median", MEDIAN(Instances!H6:Instances!H6),"min", MIN(Instances!H6:Instances!H6),"max", MAX(Instances!H6:Instances!H6),"diff", MAX(Instances!H6:Instances!H6)-MIN(Instances!H6:Instances!H6))} -> 0 | J6: {=_xlfn.SWITCH($A$2,"average", AVERAGE(Instances!J6:Instances!J6),"median", MEDIAN(Instances!J6:Instances!J6),"min", MIN(Instances!J6:Instances!J6),"max", MAX(Instances!J6:Instances!J6),"diff", MAX(Instances!J6:Instances!J6)-MIN(Instances!J6:Instances!J6))} -> 0 | K6: {=_xlfn.SWITCH($A$2,"average", AVERAGE(Instances!K6:Instances!K6),"median", MEDIAN(Instances!K6:Instances!K6),"min", MIN(Instances!K6:Instances!K6),"max", MAX(Instances!K6:Instances!K6),"diff", MAX(Instances!K6:Instances!K6)-MIN(Instances!K6:Instances!K6))} -> 0 | L6: {=_xlfn.SWITCH($A$2,"average", AVERAGE(Instances!L6:Instances!L6),"median", MEDIAN(Instances!L6:Instances!L6),"min", MIN(Instances!L6:Instances!L6),"max", MAX(Instances!L6:Instances!L6),"diff", MAX(Instances!L6:Instances!L6)-MIN(Instances!L6:Instances!L6))} -> 0 | M6: {=_xlfn.SWITCH($A$2,"average", AVERAGE(Instances!M6:Instances!M6),"median", MEDIAN(Instances!M6:Instances!M6),"min", MIN(Instances!M6:Instances!M6),"max", MAX(Instances!M6:Instances!M6),"diff", MAX(Instances!M6:Instances!M6)-MIN(Instances!M6:Instances!M6))} -> 0 | O6: {=_xlfn.SWITCH($A$2,"average", AVERAGE(Instances!O6:Instances!O6),"median", MEDIAN(Instances!O6:Instances!O6),"min", MIN(Instances!O6:Instances!O6),"max", MAX(Instances!O6:Instances!O6),"diff", MAX(Instances!O6:Instances!O6)-MIN(Instances!O6:Instances!O6))} -> 0 | P6: {=_xlfn.SWITCH($A$2,"average", AVERAGE(Instances!P6:Instances!P6),"median", MEDIAN(Instances!P6:Instances!P6),"min", MIN(Instances!P6:Instances!P6),"max", MAX(Instances!P6:Instances!P6),"diff", MAX(Instances!P6:Instances!P6)-MIN(Instances!P6:Instances!P6))} -> 0 | Q6: =MIN($B6,$G6,$L6) -> 0 | R6: =MIN($C6,$H6,$M6) -> 0 | S6: =MIN($E6,$J6,$O6) -> 0 | T6: =MIN($F6,$K6,$P6) -> 0 | U6: =MEDIAN($B6,$G6,$L6) -> 0 | V6: =MEDIAN($C6,$H6,$M6) -> 0 | W6: =MEDIAN($E6,$J6,$O6) -> 0 | X6: =MEDIAN($F6,$K6,$P6) -> 0 | Y6: =MAX($B6,$G6,$L6) -> 0 | Z6: =MAX($C6,$H6,$M6) -> 0 | AA6: =MAX($E6,$J6,$O6) -> 0 | AB6: =MAX($F6,$K6,$P6) -> 0
A7: instances/x6_y6_a1_f25 | B7: {=_xlfn.SWITCH($A$2,"average", AVERAGE(Instances!B7:Instances!B7),"median", MEDIAN(Instances!B7:Instances!B7),"min", MIN(Instances!B7:Instances!B7),"max", MAX(Instances!B7:Instances!B7),"diff", MAX(Instances!B7:Instances!B7)-MIN(Instances!B7:Instances!B7))} -> 0 | C7: {=_xlfn.SWITCH($A$2,"average", AVERAGE(Instances!C7:Instances!C7),"median", MEDIAN(Instances!C7:Instances!C7),"min", MIN(Instances!C7:Instances!C7),"max", MAX(Instances!C7:Instances!C7),"diff", MAX(Instances!C7:Instances!C7)-MIN(Instances!C7:Instances!C7))} -> 0 | E7: {=_xlfn.SWITCH($A$2,"average", AVERAGE(Instances!E7:Instances!E7),"median", MEDIAN(Instances!E7:Instances!E7),"min", MIN(Instances!E7:Instances!E7),"max", MAX(Instances!E7:Instances!E7),"diff", MAX(Instances!E7:Instances!E7)-MIN(Instances!E7:Instances!E7))} -> 0 | F7: {=_xlfn.SWITCH($A$2,"average", AVERAGE(Instances!F7:Instances!F7),"median", MEDIAN(Instances!F7:Instances!F7),"min", MIN(Instances!F7:Instances!F7),"max", MAX(Instances!F7:Instances!F7),"diff", MAX(Instances!F7:Instances!F7)-MIN(Instances!F7:Instances!F7))} -> 0 | G7: {=_xlfn.SWITCH($A$2,"average", AVERAGE(Instances!G7:Instances!G7),"median", MEDIAN(Instances!G7:Instances!G7),"min", MIN(Instances!G7:Instances!G7),"max", MAX(Instances!G7:Instances!G7),"diff", MAX(Instances!G7:Instances!G7)-MIN(Instances!G7:Instances!G7))} -> 0 | H7: {=_xlfn.SWITCH($A$2,"average", AVERAGE(Instances!H7:Instances!H7),"median", MEDIAN(Instances!H7:Instances!H7),"min", MIN(Instances!H7:Instances!H7),"max", MAX(Instances!H7:Instances!H7),"diff", MAX(Instances!H7:Instances!H7)-MIN(Instances!H7:Instances!H7))} -> 0 | J7: {=_xlfn.SWITCH($A$2,"average", AVERAGE(Instances!J7:Instances!J7),"median", MEDIAN(Instances!J7:Instances!J7),"min", MIN(Instances!J7:Instances!J7),"max", MAX(Instances!J7:Instances!J7),"diff", MAX(Instances!J7:Instances!J7)-MIN(Instances!J7:Instances!J7))} -> 0 | K7: {=_xlfn.SWITCH($A$2,"average", AVERAGE(Instances!K7:Instances!K7),"median", MEDIAN(Instances!K7:Instances!K7),"min", MIN(Instances!K7:Instances!K7),"max", MAX(Instances!K7:Instances!K7),"diff", MAX(Instances!K7:Instances!K7)-MIN(Instances!K7:Instances!K7))} -> 0 | L7: {=_xlfn.SWITCH($A$2,"average", AVERAGE(Instances!L7:Instances!L7),"median", MEDIAN(Instances!L7:Instances!L7),"min", MIN(Instances!L7:Instances!L7),"max", MAX(Instances!L7:Instances!L7),"diff", MAX(Instances!L7:Instances!L7)-MIN(Instances!L7:Instances!L7))} -> 0 | M7: {=_xlfn.SWITCH($A$2,"average", AVERAGE(Instances!M7:Instances!M7),"median", MEDIAN(Instances!M7:Instances!M7),"min", MIN(Instances!M7:Instances!M7),"max", MAX(Instances!M7:Instances!M7),"diff", MAX(Instances!M7:Instances!M7)-MIN(Instances!M7:Instances!M7))} -> 0 | O7: {=_xlfn.SWITCH($A$2,"average", AVERAGE(Instances!O7:Instances!O7),"median", MEDIAN(Instances!O7:Instances!O7),"min", MIN(Instances!O7:Instances!O7),"max", MAX(Instances!O7:Instances!O7),"diff", MAX(Instances!O7:Instances!O7)-MIN(Instances!O7:Instances!O7))} -> 0 | P7: {=_xlfn.SWITCH($A$2,"average", AVERAGE(Instances!P7:Instances!P7),"median", MEDIAN(Instances!P7:Instances!P7),"min", MIN(Instances!P7:Instances!P7),"max", MAX(Instances!P7:Instances!P7),"diff", MAX(Instances!P7:Instances!P7)-MIN(Instances!P7:Instances!P7))} -> 0 | Q7: =MIN($B7,$G7,$L7) -> 0 | R7: =MIN($C7,$H7,$M7) -> 0 | S7: =MIN($E7,$J7,$O7) -> 0 | T7: =MIN($F7,$K7,$P7) -> 0 | U7: =MEDIAN($B7,$G7,$L7) -> 0 | V7: =MEDIAN($C7,$H7,$M7) -> 0 | W7: =MEDIAN($E7,$J7,$O7) -> 0 | X7: =MEDIAN($F7,$K7,$P7) -> 0 | Y7: =MAX($B7,$G7,$L7) -> 0 | Z7: =MAX($C7,$H7,$M7) -> 0 | AA7: =MAX($E7,$J7,$O7) -> 0 | AB7: =MAX($F7,$K7,$P7) -> 0
A8: instances/x6_y6_a1_f30 | B8: {=_xlfn.SWITCH($A$2,"average", AVERAGE(Instances!B8:Instances!B8),"median", MEDIAN(Instances!B8:Instances!B8),"min", MIN(Instances!B8:Instances!B8),"max", MAX(Instances!B8:Instances!B8),"diff", MAX(Instances!B8:Instances!B8)-MIN(Instances!B8:Instances!B8))} -> 0 | C8: {=_xlfn.SWITCH($A$2,"average", AVERAGE(Instances!C8:Instances!C8),"median", MEDIAN(Instances!C8:Instances!C8),"min", MIN(Instances!C8:Instances!C8),"max", MAX(Instances!C8:Instances!C8),"diff", MAX(Instances!C8:Instances!C8)-MIN(Instances!C8:Instances!C8))} -> 0 | E8: {=_xlfn.SWITCH($A$2,"average", AVERAGE(Instances!E8:Instances!E8),"median", MEDIAN(Instances!E8:Instances!E8),"min", MIN(Instances!E8:Instances!E8),"max", MAX(Instances!E8:Instances!E8),"diff", MAX(Instances!E8:Instances!E8)-MIN(Instances!E8:Instances!E8))} -> 0 | F8: {=_xlfn.SWITCH($A$2,"average", AVERAGE(Instances!F8:Instances!F8),"median", MEDIAN(Instances!F8:Instances!F8),"min", MIN(Instances!F8:Instances!F8),"max", MAX(Instances!F8:Instances!F8),"diff", MAX(Instances!F8:Instances!F8)-MIN(Instances!F8:Instances!F8))} -> 0 | G8: {=_xlfn.SWITCH($A$2,"average", AVERAGE(Instances!G8:Instances!G8),"median", MEDIAN(Instances!G8:Instances!G8),"min", MIN(Instances!G8:Instances!G8),"max", MAX(Instances!G8:Instances!G8),"diff", MAX(Instances!G8:Instances!G8)-MIN(Instances!G8:Instances!G8))} -> 0 | H8: {=_xlfn.SWITCH($A$2,"average", AVERAGE(Instances!H8:Instances!H8),"median", MEDIAN(Instances!H8:Instances!H8),"min", MIN(Instances!H8:Instances!H8),"max", MAX(Instances!H8:Instances!H8),"diff", MAX(Instances!H8:Instances!H8)-MIN(Instances!H8:Instances!H8))} -> 0 | J8: {=_xlfn.SWITCH($A$2,"average", AVERAGE(Instances!J8:Instances!J8),"median", MEDIAN(Instances!J8:Instances!J8),"min", MIN(Instances!J8:Instances!J8),"max", MAX(Instances!J8:Instances!J8),"diff", MAX(Instances!J8:Instances!J8)-MIN(Instances!J8:Instances!J8))} -> 0 | K8: {=_xlfn.SWITCH($A$2,"average", AVERAGE(Instances!K8:Instances!K8),"median", MEDIAN(Instances!K8:Instances!K8),"min", MIN(Instances!K8:Instances!K8),"max", MAX(Instances!K8:Instances!K8),"diff", MAX(Instances!K8:Instances!K8)-MIN(Instances!K8:Instances!K8))} -> 0 | L8: {=_xlfn.SWITCH($A$2,"average", AVERAGE(Instances!L8:Instances!L8),"median", MEDIAN(Instances!L8:Instances!L8),"min", MIN(Instances!L8:Instances!L8),"max", MAX(Instances!L8:Instances!L8),"diff", MAX(Instances!L8:Instances!L8)-MIN(Instances!L8:Instances!L8))} -> 0 | M8: {=_xlfn.SWITCH($A$2,"average", AVERAGE(Instances!M8:Instances!M8),"median", MEDIAN(Instances!M8:Instances!M8),"min", MIN(Instances!M8:Instances!M8),"max", MAX(Instances!M8:Instances!M8),"diff", MAX(Instances!M8:Instances!M8)-MIN(Instances!M8:Instances!M8))} -> 0 | O8: {=_xlfn.SWITCH($A$2,"average", AVERAGE(Instances!O8:Instances!O8),"median", MEDIAN(Instances!O8:Instances!O8),"min", MIN(Instances!O8:Instances!O8),"max", MAX(Instances!O8:Instances!O8),"diff", MAX(Instances!O8:Instances!O8)-MIN(Instances!O8:Instances!O8))} -> 0 | P8: {=_xlfn.SWITCH($A$2,"average", AVERAGE(Instances!P8:Instances!P8),"median", MEDIAN(Instances!P8:Instances!P8),"min", MIN(Instances!P8:Instances!P8),"max", MAX(Instances!P8:Instances!P8),"diff", MAX(Instances!P8:Instances!P8)-MIN(Instances!P8:Instances!P8))} -> 0 | Q8: =MIN($B8,$G8,$L8) -> 0 | R8: =MIN($C8,$H8,$M8) -> 0 | S8: =MIN($E8,$J8,$O8) -> 0 | T8: =MIN($F8,$K8,$P8) -> 0 | U8: =MEDIAN($B8,$G8,$L8) -> 0 | V8: =MEDIAN($C8,$H8,$M8) -> 0 | W8: =MEDIAN($E8,$J8,$O8) -> 0 | X8: =MEDIAN($F8,$K8,$P8) -> 0 | Y8: =MAX($B8,$G8,$L8) -> 0 | Z8: =MAX($C8,$H8,$M8) -> 0 | AA8: =MAX($E8,$J8,$O8) -> 0 | AB8: =MAX($F8,$K8,$P8) -> 0
A9: instances/x6_y6_a1_f35 | B9: {=_xlfn.SWITCH($A$2,"average", AVERAGE(Instances!B9:Instances!B9),"median", MEDIAN(Instances!B9:Instances!B9),"min", MIN(Instances!B9:Instances!B9),"max", MAX(Instances!B9:Instances!B9),"diff", MAX(Instances!B9:Instances!B9)-MIN(Instances!B9:Instances!B9))} -> 0 | C9: {=_xlfn.SWITCH($A$2,"average", AVERAGE(Instances!C9:Instances!C9),"median", MEDIAN(Instances!C9:Instances!C9),"min", MIN(Instances!C9:Instances!C9),"max", MAX(Instances!C9:Instances!C9),"diff", MAX(Instances!C9:Instances!C9)-MIN(Instances!C9:Instances!C9))} -> 0 | E9: {=_xlfn.SWITCH($A$2,"average", AVERAGE(Instances!E9:Instances!E9),"median", MEDIAN(Instances!E9:Instances!E9),"min", MIN(Instances!E9:Instances!E9),"max", MAX(Instances!E9:Instances!E9),"diff", MAX(Instances!E9:Instances!E9)-MIN(Instances!E9:Instances!E9))} -> 0 | F9: {=_xlfn.SWITCH($A$2,"average", AVERAGE(Instances!F9:Instances!F9),"median", MEDIAN(Instances!F9:Instances!F9),"min", MIN(Instances!F9:Instances!F9),"max", MAX(Instances!F9:Instances!F9),"diff", MAX(Instances!F9:Instances!F9)-MIN(Instances!F9:Instances!F9))} -> 0 | G9: {=_xlfn.SWITCH($A$2,"average", AVERAGE(Instances!G9:Instances!G9),"median", MEDIAN(Instances!G9:Instances!G9),"min", MIN(Instances!G9:Instances!G9),"max", MAX(Instances!G9:Instances!G9),"diff", MAX(Instances!G9:Instances!G9)-MIN(Instances!G9:Instances!G9))} -> 0 | H9: {=_xlfn.SWITCH($A$2,"average", AVERAGE(Instances!H9:Instances!H9),"median", MEDIAN(Instances!H9:Instances!H9),"min", MIN(Instances!H9:Instances!H9),"max", MAX(Instances!H9:Instances!H9),"diff", MAX(Instances!H9:Instances!H9)-MIN(Instances!H9:Instances!H9))} -> 0 | J9: {=_xlfn.SWITCH($A$2,"average", AVERAGE(Instances!J9:Instances!J9),"median", MEDIAN(Instances!J9:Instances!J9),"min", MIN(Instances!J9:Instances!J9),"max", MAX(Instances!J9:Instances!J9),"diff", MAX(Instances!J9:Instances!J9)-MIN(Instances!J9:Instances!J9))} -> 0 | K9: {=_xlfn.SWITCH($A$2,"average", AVERAGE(Instances!K9:Instances!K9),"median", MEDIAN(Instances!K9:Instances!K9),"min", MIN(Instances!K9:Instances!K9),"max", MAX(Instances!K9:Instances!K9),"diff", MAX(Instances!K9:Instances!K9)-MIN(Instances!K9:Instances!K9))} -> 0 | L9: {=_xlfn.SWITCH($A$2,"average", AVERAGE(Instances!L9:Instances!L9),"median", MEDIAN(Instances!L9:Instances!L9),"min", MIN(Instances!L9:Instances!L9),"max", MAX(Instances!L9:Instances!L9),"diff", MAX(Instances!L9:Instances!L9)-MIN(Instances!L9:Instances!L9))} -> 0 | M9: {=_xlfn.SWITCH($A$2,"average", AVERAGE(Instances!M9:Instances!M9),"median", MEDIAN(Instances!M9:Instances!M9),"min", MIN(Instances!M9:Instances!M9),"max", MAX(Instances!M9:Instances!M9),"diff", MAX(Instances!M9:Instances!M9)-MIN(Instances!M9:Instances!M9))} -> 0 | O9: {=_xlfn.SWITCH($A$2,"average", AVERAGE(Instances!O9:Instances!O9),"median", MEDIAN(Instances!O9:Instances!O9),"min", MIN(Instances!O9:Instances!O9),"max", MAX(Instances!O9:Instances!O9),"diff", MAX(Instances!O9:Instances!O9)-MIN(Instances!O9:Instances!O9))} -> 0 | P9: {=_xlfn.SWITCH($A$2,"average", AVERAGE(Instances!P9:Instances!P9),"median", MEDIAN(Instances!P9:Instances!P9),"min", MIN(Instances!P9:Instances!P9),"max", MAX(Instances!P9:Instances!P9),"diff", MAX(Instances!P9:Instances!P9)-MIN(Instances!P9:Instances!P9))} -> 0 | Q9: =MIN($B9,$G9,$L9) -> 0 | R9: =MIN($C9,$H9,$M9) -> 0 | S9: =MIN($E9,$J9,$O9) -> 0 | T9: =MIN($F9,$K9,$P9) -> 0 | U9: =MEDIAN($B9,$G9,$L9) -> 0 | V9: =MEDIAN($C9,$H9,$M9) -> 0 | W9: =MEDIAN($E9,$J9,$O9) -> 0 | X9: =MEDIAN($F9,$K9,$P9) -> 0 | Y9: =MAX($B9,$G9,$L9) -> 0 | Z9: =MAX($C9,$H9,$M9) -> 0 | AA9: =MAX($E9,$J9,$O9) -> 0 | AB9: =MAX($F9,$K9,$P9) -> 0
A10: instances/x6_y6_a1_f40 | B10: {=_xlfn.SWITCH($A$2,"average", AVERAGE(Instances!B10:Instances!B10),"median", MEDIAN(Instances!B10:Instances!B10),"min", MIN(Instances!B10:Instances!B10),"max", MAX(Instances!B10:Instances!B10),"diff", MAX(Instances!B10:Instances!B10)-MIN(Instances!B10:Instances!B10))} -> 0 | C10: {=_xlfn.SWITCH($A$2,"average", AVERAGE(Instances!C10:Instances!C10),"median", MEDIAN(Instances!C10:Instances!C10),"min", MIN(Instances!C10:Instances!C10),"max", MAX(Instances!C10:Instances!C10),"diff", MAX(Instances!C10:Instances!C10)-MIN(Instances!C10:Instances!C10))} -> 0 | E10: {=_xlfn.SWITCH($A$2,"average", AVERAGE(Instances!E10:Instances!E10),"median", MEDIAN(Instances!E10:Instances!E10),"min", MIN(Instances!E10:Instances!E10),"max", MAX(Instances!E10:Instances!E10),"diff", MAX(Instances!E10:Instances!E10)-MIN(Instances!E10:Instances!E10))} -> 0 | F10: {=_xlfn.SWITCH($A$2,"average", AVERAGE(Instances!F10:Instances!F10),"median", MEDIAN(Instances!F10:Instances!F10),"min", MIN(Instances!F10:Instances!F10),"max", MAX(Instances!F10:Instances!F10),"diff", MAX(Instances!F10:Instances!F10)-MIN(Instances!F10:Instances!F10))} -> 0 | G10: {=_xlfn.SWITCH($A$2,"average", AVERAGE(Instances!G10:Instances!G10),"median", MEDIAN(Instances!G10:Instances!G10),"min", MIN(Instances!G10:Instances!G10),"max", MAX(Instances!G10:Instances!G10),"diff", MAX(Instances!G10:Instances!G10)-MIN(Instances!G10:Instances!G10))} -> 0 | H10: {=_xlfn.SWITCH($A$2,"average", AVERAGE(Instances!H10:Instances!H10),"median", MEDIAN(Instances!H10:Instances!H10),"min", MIN(Instances!H10:Instances!H10),"max", MAX(Instances!H10:Instances!H10),"diff", MAX(Instances!H10:Instances!H10)-MIN(Instances!H10:Instances!H10))} -> 0 | J10: {=_xlfn.SWITCH($A$2,"average", AVERAGE(Instances!J10:Instances!J10),"median", MEDIAN(Instances!J10:Instances!J10),"min", MIN(Instances!J10:Instances!J10),"max", MAX(Instances!J10:Instances!J10),"diff", MAX(Instances!J10:Instances!J10)-MIN(Instances!J10:Instances!J10))} -> 0 | K10: {=_xlfn.SWITCH($A$2,"average", AVERAGE(Instances!K10:Instances!K10),"median", MEDIAN(Instances!K10:Instances!K10),"min", MIN(Instances!K10:Instances!K10),"max", MAX(Instances!K10:Instances!K10),"diff", MAX(Instances!K10:Instances!K10)-MIN(Instances!K10:Instances!K10))} -> 0 | L10: {=_xlfn.SWITCH($A$2,"average", AVERAGE(Instances!L10:Instances!L10),"median", MEDIAN(Instances!L10:Instances!L10),"min", MIN(Instances!L10:Instances!L10),"max", MAX(Instances!L10:Instances!L10),"diff", MAX(Instances!L10:Instances!L10)-MIN(Instances!L10:Instances!L10))} -> 0 | M10: {=_xlfn.SWITCH($A$2,"average", AVERAGE(Instances!M10:Instances!M10),"median", MEDIAN(Instances!M10:Instances!M10),"min", MIN(Instances!M10:Instances!M10),"max", MAX(Instances!M10:Instances!M10),"diff", MAX(Instances!M10:Instances!M10)-MIN(Instances!M10:Instances!M10))} -> 0 | O10: {=_xlfn.SWITCH($A$2,"average", AVERAGE(Instances!O10:Instances!O10),"median", MEDIAN(Instances!O10:Instances!O10),"min", MIN(Instances!O10:Instances!O10),"max", MAX(Instances!O10:Instances!O10),"diff", MAX(Instances!O10:Instances!O10)-MIN(Instances!O10:Instances!O10))} -> 0 | P10: {=_xlfn.SWITCH($A$2,"average", AVERAGE(Instances!P10:Instances!P10),"median", MEDIAN(Instances!P10:Instances!P10),"min", MIN(Instances!P10:Instances!P10),"max", MAX(Instances!P10:Instances!P10),"diff", MAX(Instances!P10:Instances!P10)-MIN(Instances!P10:Instances!P10))} -> 0 | Q10: =MIN($B10,$G10,$L10) -> 0 | R10: =MIN($C10,$H10,$M10) -> 0 | S10: =MIN($E10,$J10,$O10) -> 0 | T10: =MIN($F10,$K10,$P10) -> 0 | U10: =MEDIAN($B10,$G10,$L10) -> 0 | V10: =MEDIAN($C10,$H10,$M10) -> 0 | W10: =MEDIAN($E10,$J10,$O10) -> 0 | X10: =MEDIAN($F10,$K10,$P10) -> 0 | Y10: =MAX($B10,$G10,$L10) -> 0 | Z10: =MAX($C10,$H10,$M10) -> 0 | AA10: =MAX($E10,$J10,$O10) -> 0 | AB10: =MAX($F10,$K10,$P10) -> 0
A11: instances/x6_y6_a1_f5 | B11: {=_xlfn.SWITCH($A$2,"average", AVERAGE(Instances!B11:Instances!B11),"median", MEDIAN(Instances!B11:Instances!B11),"min", MIN(Instances!B11:Instances!B11),"max", MAX(Instances!B11:Instances!B11),"diff", MAX(Instances!B11:Instances!B11)-MIN(Instances!B11:Instances!B11))} -> 0 | C11: {=_xlfn.SWITCH($A$2,"average", AVERAGE(Instances!C11:Instances!C11),"median", MEDIAN(Instances!C11:Instances!C11),"min", MIN(Instances!C11:Instances!C11),"max", MAX(Instances!C11:Instances!C11),"diff", MAX(Instances!C11:Instances!C11)-MIN(Instances!C11:Instances!C11))} -> 0 | E11: {=_xlfn.SWITCH($A$2,"average", AVERAGE(Instances!E11:Instances!E11),"median", MEDIAN(Instances!E11:Instances!E11),"min", MIN(Instances!E11:Instances!E11),"max", MAX(Instances!E11:Instances!E11),"diff", MAX(Instances!E11:Instances!E11)-MIN(Instances!E11:Instances!E11))} -> 0 | F11: {=_xlfn.SWITCH($A$2,"average", AVERAGE(Instances!F11:Instances!F11),"median", MEDIAN(Instances!F11:Instances!F11),"min", MIN(Instances!F11:Instances!F11),"max", MAX(Instances!F11:Instances!F11),"diff", MAX(Instances!F11:Instances!F11)-MIN(Instances!F11:Instances!F11))} -> 0 | G11: {=_xlfn.SWITCH($A$2,"average", AVERAGE(Instances!G11:Instances!G11),"median", MEDIAN(Instances!G11:Instances!G11),"min", MIN(Instances!G11:Instances!G11),"max", MAX(Instances!G11:Instances!G11),"diff", MAX(Instances!G11:Instances!G11)-MIN(Instances!G11:Instances!G11))} -> 0 | H11: {=_xlfn.SWITCH($A$2,"average", AVERAGE(Instances!H11:Instances!H11),"median", MEDIAN(Instances!H11:Instances!H11),"min", MIN(Instances!H11:Instances!H11),"max", MAX(Instances!H11:Instances!H11),"diff", MAX(Instances!H11:Instances!H11)-MIN(Instances!H11:Instances!H11))} -> 0 | J11: {=_xlfn.SWITCH($A$2,"average", AVERAGE(Instances!J11:Instances!J11),"median", MEDIAN(Instances!J11:Instances!J11),"min", MIN(Instances!J11:Instances!J11),"max", MAX(Instances!J11:Instances!J11),"diff", MAX(Instances!J11:Instances!J11)-MIN(Instances!J11:Instances!J11))} -> 0 | K11: {=_xlfn.SWITCH($A$2,"average", AVERAGE(Instances!K11:Instances!K11),"median", MEDIAN(Instances!K11:Instances!K11),"min", MIN(Instances!K11:Instances!K11),"max", MAX(Instances!K11:Instances!K11),"diff", MAX(Instances!K11:Instances!K11)-MIN(Instances!K11:Instances!K11))} -> 0 | L11: {=_xlfn.SWITCH($A$2,"average", AVERAGE(Instances!L11:Instances!L11),"median", MEDIAN(Instances!L11:Instances!L11),"min", MIN(Instances!L11:Instances!L11),"max", MAX(Instances!L11:Instances!L11),"diff", MAX(Instances!L11:Instances!L11)-MIN(Instances!L11:Instances!L11))} -> 0 | M11: {=_xlfn.SWITCH($A$2,"average", AVERAGE(Instances!M11:Instances!M11),"median", MEDIAN(Instances!M11:Instances!M11),"min", MIN(Instances!M11:Instances!M11),"max", MAX(Instances!M11:Instances!M11),"diff", MAX(Instances!M11:Instances!M11)-MIN(Instances!M11:Instances!M11))} -> 0 | O11: {=_xlfn.SWITCH($A$2,"average", AVERAGE(Instances!O11:Instances!O11),"median", MEDIAN(Instances!O11:Instances!O11),"min", MIN(Instances!O11:Instances!O11),"max", MAX(Instances!O11:Instances!O11),"diff", MAX(Instances!O11:Instances!O11)-MIN(Instances!O11:Instances!O11))} -> 0 | P11: {=_xlfn.SWITCH($A$2,"average", AVERAGE(Instances!P11:Instances!P11),"median", MEDIAN(Instances!P11:Instances!P11),"min", MIN(Instances!P11:Instances!P11),"max", MAX(Instances!P11:Instances!P11),"diff", MAX(Instances!P11:Instances!P11)-MIN(Instances!P11:Instances!P11))} -> 0 | Q11: =MIN($B11,$G11,$L11) -> 0 | R11: =MIN($C11,$H11,$M11) -> 0 | S11: =MIN($E11,$J11,$O11) -> 0 | T11: =MIN($F11,$K11,$P11) -> 0 | U11: =MEDIAN($B11,$G11,$L11) -> 0 | V11: =MEDIAN($C11,$H11,$M11) -> 0 | W11: =MEDIAN($E11,$J11,$O11) -> 0 | X11: =MEDIAN($F11,$K11,$P11) -> 0 | Y11: =MAX($B11,$G11,$L11) -> 0 | Z11: =MAX($C11,$H11,$M11) -> 0 | AA11: =MAX($E11,$J11,$O11) -> 0 | AB11: =MAX($F11,$K11,$P11) -> 0
