Workbook

Sheet Instances
B1: memelingo-1/all-opts_mlp-tplp-ht_15_100 | G1: memelingo-1/all-opts_mlp-tplp-ht_15_30 | L1: memelingo-1/all-opts_mlp-tplp-ht_15_50 | Q1: memelingo-1/all-opts_mlp-tplp-ht_20_100 | V1: memelingo-1/all-opts_mlp-tplp-ht_20_30 | AA1: memelingo-1/all-opts_mlp-tplp-ht_20_50 | AF1: memelingo-1/all-opts_mlp-tplp-ht_25_100 | AK1: memelingo-1/all-opts_mlp-tplp-ht_25_30 | AP1: memelingo-1/all-opts_mlp-tplp-ht_25_50 | AU1: memelingo-1/all-opts_mlp-tplp-ht_30_100 | AZ1: memelingo-1/all-opts_mlp-tplp-ht_30_30 | BE1: memelingo-1/all-opts_mlp-tplp-ht_30_50 | BJ1: memelingo-1/all-opts_mlp-tplp-ht_35_100 | BO1: memelingo-1/all-opts_mlp-tplp-ht_35_30 | BT1: memelingo-1/all-opts_mlp-tplp-ht_35_50 | BY1: memelingo-1/all-opts_mlp-tplp-htc_15_100 | CD1: memelingo-1/all-opts_mlp-tplp-htc_15_30 | CI1: memelingo-1/all-opts_mlp-tplp-htc_15_50 | CN1: memelingo-1/all-opts_mlp-tplp-htc_20_100 | CS1: memelingo-1/all-opts_mlp-tplp-htc_20_30 | CX1: memelingo-1/all-opts_mlp-tplp-htc_20_50 | DC1: memelingo-1/all-opts_mlp-tplp-htc_25_100 | DH1: memelingo-1/all-opts_mlp-tplp-htc_25_30 | DM1: memelingo-1/all-opts_mlp-tplp-htc_25_50 | DR1: memelingo-1/all-opts_mlp-tplp-htc_30_100 | DW1: memelingo-1/all-opts_mlp-tplp-htc_30_30 | EB1: memelingo-1/all-opts_mlp-tplp-htc_30_50 | EG1: memelingo-1/all-opts_mlp-tplp-htc_35_100 | EL1: memelingo-1/all-opts_mlp-tplp-htc_35_30 | EQ1: memelingo-1/all-opts_mlp-tplp-htc_35_50 | EV1: memelingo-1/all-opts_mlp-tplp-htcdl_15_100 | FA1: memelingo-1/all-opts_mlp-tplp-htcdl_15_30 | FF1: memelingo-1/all-opts_mlp-tplp-htcdl_15_50 | FK1: memelingo-1/all-opts_mlp-tplp-htcdl_20_100 | FP1: memelingo-1/all-opts_mlp-tplp-htcdl_20_30 | FU1: memelingo-1/all-opts_mlp-tplp-htcdl_20_50 | FZ1: memelingo-1/all-opts_mlp-tplp-htcdl_25_100 | GE1: memelingo-1/all-opts_mlp-tplp-htcdl_25_30 | GJ1: memelingo-1/all-opts_mlp-tplp-htcdl_25_50 | GO1: memelingo-1/all-opts_mlp-tplp-htcdl_30_100 | GT1: memelingo-1/all-opts_mlp-tplp-htcdl_30_30 | GY1: memelingo-1/all-opts_mlp-tplp-htcdl_30_50 | HD1: memelingo-1/all-opts_mlp-tplp-htcdl_35_100 | HI1: memelingo-1/all-opts_mlp-tplp-htcdl_35_30 | HN1: memelingo-1/all-opts_mlp-tplp-htcdl_35_50 | HS1: min | HW1: median | IA1: max
B2: time | C2: stime | D2: status | E2: rules | F2: ctime | G2: time | H2: stime | I2: status | J2: rules | K2: ctime | L2: time | M2: stime | N2: status | O2: rules | P2: ctime | Q2: time | R2: stime | S2: status | T2: rules | U2: ctime | V2: time | W2: stime | X2: status | Y2: rules | Z2: ctime | AA2: time | AB2: stime | AC2: status | AD2: rules | AE2: ctime | AF2: time | AG2: stime | AH2: status | AI2: rules | AJ2: ctime | AK2: time | AL2: stime | AM2: status | AN2: rules | AO2: ctime | AP2: time | AQ2: stime | AR2: status | AS2: rules | AT2: ctime | AU2: time | AV2: stime | AW2: status | AX2: rules | AY2: ctime | AZ2: time | BA2: stime | BB2: status | BC2: rules | BD2: ctime | BE2: time | BF2: stime | BG2: status | BH2: rules | BI2: ctime | BJ2: time | BK2: stime | BL2: status | BM2: rules | BN2: ctime | BO2: time | BP2: stime | BQ2: status | BR2: rules | BS2: ctime | BT2: time | BU2: stime | BV2: status | BW2: rules | BX2: ctime | BY2: time | BZ2: stime | CA2: status | CB2: rules | CC2: ctime | CD2: time | CE2: stime | CF2: status | CG2: rules | CH2: ctime | CI2: time | CJ2: stime | CK2: status | CL2: rules | CM2: ctime | CN2: time | CO2: stime | CP2: status | CQ2: rules | CR2: ctime | CS2: time | CT2: stime | CU2: status | CV2: rules | CW2: ctime | CX2: time | CY2: stime | CZ2: status | DA2: rules | DB2: ctime | DC2: time | DD2: stime | DE2: status | DF2: rules | DG2: ctime | DH2: time | DI2: stime | DJ2: status | DK2: rules | DL2: ctime | DM2: time | DN2: stime | DO2: status | DP2: rules | DQ2: ctime | DR2: time | DS2: stime | DT2: status | DU2: rules | DV2: ctime | DW2: time | DX2: stime | DY2: status | DZ2: rules | EA2: ctime | EB2: time | EC2: stime | ED2: status | EE2: rules | EF2: ctime | EG2: time | EH2: stime | EI2: status | EJ2: rules | EK2: ctime | EL2: time | EM2: stime | EN2: status | EO2: rules | EP2: ctime | EQ2: time | ER2: stime | ES2: status | ET2: rules | EU2: ctime | EV2: time | EW2: stime | EX2: status | EY2: rules | EZ2: ctime | FA2: time | FB2: stime | FC2: status | FD2: rules | FE2: ctime | FF2: time | FG2: stime | FH2: status | FI2: rules | FJ2: ctime | FK2: time | FL2: stime | FM2: status | FN2: rules | FO2: ctime | FP2: time | FQ2: stime | FR2: status | FS2: rules | FT2: ctime | FU2: time | FV2: stime | FW2: status | FX2: rules | FY2: ctime | FZ2: time | GA2: stime | GB2: status | GC2: rules | GD2: ctime | GE2: time | GF2: stime | GG2: status | GH2: rules | GI2: ctime | GJ2: time | GK2: stime | GL2: status | GM2: rules | GN2: ctime | GO2: time | GP2: stime | GQ2: status | GR2: rules | GS2: ctime | GT2: time | GU2: stime | GV2: status | GW2: rules | GX2: ctime | GY2: time | GZ2: stime | HA2: status | HB2: rules | HC2: ctime | HD2: time | HE2: stime | HF2: status | HG2: rules | HH2: ctime | HI2: time | HJ2: stime | HK2: status | HL2: rules | HM2: ctime | HN2: time | HO2: stime | HP2: status | HQ2: rules | HR2: ctime | HS2: time | HT2: stime | HU2: rules | HV2: ctime | HW2: time | HX2: stime | HY2: rules | HZ2: ctime | IA2: time | IB2: stime | IC2: rules | ID2: ctime
A3: instances/random_x8_y8_a3 | B3: 1200 | G3: 1200 | H3: 1166.49 | I3: UNKNOWN | J3: 1453453 | K3: 1194.472 | L3: 1200 | M3: 1158.88 | N3: UNKNOWN | O3: 2765333 | P3: 1194.417 | Q3: 1200 | V3: 1200 | W3: 1149.11 | X3: UNKNOWN | Y3: 2093513 | Z3: 1194.071 | AA3: 1200 | AB3: 1128.66 | AC3: UNKNOWN | AD3: 4277493 | AE3: 1193.964 | AF3: 1200 | AK3: 1200 | AL3: 1095.45 | AM3: UNKNOWN | AN3: 2743923 | AO3: 1194.035 | AP3: 1200 | AQ3: 1053.68 | AR3: UNKNOWN | AS3: 5896253 | AT3: 1194.463 | AU3: 1200 | AZ3: 1200 | BA3: 938.25 | BB3: UNKNOWN | BC3: 3379912 | BD3: 1194.182 | BE3: 1200 | BF3: 906.31 | BG3: UNKNOWN | BH3: 7524363 | BI3: 1193.938 | BJ3: 1200 | BO3: 40.47 | BP3: 0 | BQ3: UNSATISFIABLE | BR3: 7838202 | BS3: 32.823 | BT3: 1200 | BY3: 1200 | BZ3: 1174.2 | CA3: UNKNOWN | CB3: 942149 | CC3: 1193.091 | CD3: 1200 | CE3: 1174.65 | CF3: UNKNOWN | CG3: 942149 | CH3: 1193.419 | CI3: 1200 | CJ3: 1175.58 | CK3: UNKNOWN | CL3: 942149 | CM3: 1194.235 | CN3: 1200 | CO3: 1139.91 | CP3: UNKNOWN | CQ3: 1358459 | CR3: 1193.974 | CS3: 1200 | CT3: 1154.18 | CU3: UNKNOWN | CV3: 1358459 | CW3: 1192.973 | CX3: 1200 | CY3: 1140.46 | CZ3: UNKNOWN | DA3: 1358459 | DB3: 1193.741 | DC3: 559.71 | DD3: 451.83 | DE3: SATISFIABLE | DF3: 1848144 | DG3: 551.685 | DH3: 1200 | DI3: 1079.58 | DJ3: UNKNOWN | DK3: 1848144 | DL3: 1193.564 | DM3: 474.42 | DN3: 363.36 | DO3: SATISFIABLE | DP3: 1848144 | DQ3: 466.246 | DR3: 489.41 | DS3: 235.29 | DT3: SATISFIABLE | DU3: 2411204 | DV3: 481.486 | DW3: 419.45 | DX3: 165.7 | DY3: UNSATISFIABLE | DZ3: 2411204 | EA3: 410.773 | EB3: 381.56 | EC3: 144.49 | ED3: SATISFIABLE | EE3: 2411204 | EF3: 372.906 | EG3: 601.05 | EH3: 109.13 | EI3: SATISFIABLE | EJ3: 3047639 | EK3: 591.654 | EL3: 463.76 | EM3: 0 | EN3: UNSATISFIABLE | EO3: 6095278 | EP3: 454.747 | EQ3: 607.11 | ER3: 136.88 | ES3: SATISFIABLE | ET3: 3047639 | EU3: 598.195 | EV3: 1200 | EW3: 1175.25 | EX3: UNKNOWN | EY3: 942149 | EZ3: 1193.934 | FA3: 1200 | FB3: 1168.38 | FC3: UNKNOWN | FD3: 942149 | FE3: 1193.867 | FF3: 1200 | FG3: 1174.61 | FH3: UNKNOWN | FI3: 942149 | FJ3: 1193.818 | FK3: 738.75 | FL3: 686.13 | FM3: SATISFIABLE | FN3: 1358459 | FO3: 730.47 | FP3: 1200 | FQ3: 1143.4 | FR3: UNKNOWN | FS3: 1358459 | FT3: 1193.767 | FU3: 672.37 | FV3: 625.88 | FW3: SATISFIABLE | FX3: 1358459 | FY3: 665.29 | FZ3: 654.95 | GA3: 556.09 | GB3: SATISFIABLE | GC3: 1848144 | GD3: 647.173 | GE3: 1200 | GF3: 1073.56 | GG3: UNKNOWN | GH3: 1848144 | GI3: 1193.596 | GJ3: 956.01 | GK3: 850.48 | GL3: SATISFIABLE | GM3: 1848144 | GN3: 948.143 | GO3: 1131.92 | GP3: 925.95 | GQ3: SATISFIABLE | GR3: 2411204 | GS3: 1123.763 | GT3: 867.31 | GU3: 634.09 | GV3: UNSATISFIABLE | GW3: 2411204 | GX3: 859.5 | GY3: 1128.71 | GZ3: 886.38 | HA3: SATISFIABLE | HB3: 2411204 | HC3: 1121.193 | HD3: 1200 | HE3: 771.28 | HF3: UNKNOWN | HG3: 3047639 | HH3: 1194.399 | HI3: 396.75 | HJ3: 0 | HK3: UNSATISFIABLE | HL3: 3047639 | HM3: 388.275 | HN3: 1200 | HO3: 814.54 | HP3: UNKNOWN | HQ3: 3047639 | HR3: 1194.544 | HS3: =MIN($B3,$G3,$L3,$Q3,$V3,$AA3,$AF3,$AK3,$AP3,$AU3,$AZ3,$BE3,$BJ3,$BO3,$BT3,$BY3,$CD3,$CI3,$CN3,$CS3,$CX3,$DC3,$DH3,$DM3,$DR3,$DW3,$EB3,$EG3,$EL3,$EQ3,$EV3,$FA3,$FF3,$FK3,$FP3,$FU3,$FZ3,$GE3,$GJ3,$GO3,$GT3,$GY3,$HD3,$HI3,$HN3) -> 0 | HT3: =MIN($C3,$H3,$M3,$R3,$W3,$AB3,$AG3,$AL3,$AQ3,$AV3,$BA3,$BF3,$BK3,$BP3,$BU3,$BZ3,$CE3,$CJ3,$CO3,$CT3,$CY3,$DD3,$DI3,$DN3,$DS3,$DX3,$EC3,$EH3,$EM3,$ER3,$EW3,$FB3,$FG3,$FL3,$FQ3,$FV3,$GA3,$GF3,$GK3,$GP3,$GU3,$GZ3,$HE3,$HJ3,$HO3) -> 0 | HU3: =MIN($E3,$J3,$O3,$T3,$Y3,$AD3,$AI3,$AN3,$AS3,$AX3,$BC3,$BH3,$BM3,$BR3,$BW3,$CB3,$CG3,$CL3,$CQ3,$CV3,$DA3,$DF3,$DK3,$DP3,$DU3,$DZ3,$EE3,$EJ3,$EO3,$ET3,$EY3,$FD3,$FI3,$FN3,$FS3,$FX3,$GC3,$GH3,$GM3,$GR3,$GW3,$HB3,$HG3,$HL3,$HQ3) -> 0 | HV3: =MIN($F3,$K3,$P3,$U3,$Z3,$AE3,$AJ3,$AO3,$AT3,$AY3,$BD3,$BI3,$BN3,$BS3,$BX3,$CC3,$CH3,$CM3,$CR3,$CW3,$DB3,$DG3,$DL3,$DQ3,$DV3,$EA3,$EF3,$EK3,$EP3,$EU3,$EZ3,$FE3,$FJ3,$FO3,$FT3,$FY3,$GD3,$GI3,$GN3,$GS3,$GX3,$HC3,$HH3,$HM3,$HR3) -> 0 | HW3: =MEDIAN($B3,$G3,$L3,$Q3,$V3,$AA3,$AF3,$AK3,$AP3,$AU3,$AZ3,$BE3,$BJ3,$BO3,$BT3,$BY3,$CD3,$CI3,$CN3,$CS3,$CX3,$DC3,$DH3,$DM3,$DR3,$DW3,$EB3,$EG3,$EL3,$EQ3,$EV3,$FA3,$FF3,$FK3,$FP3,$FU3,$FZ3,$GE3,$GJ3,$GO3,$GT3,$GY3,$HD3,$HI3,$HN3) -> 0 | HX3: =MEDIAN($C3,$H3,$M3,$R3,$W3,$AB3,$AG3,$AL3,$AQ3,$AV3,$BA3,$BF3,$BK3,$BP3,$BU3,$BZ3,$CE3,$CJ3,$CO3,$CT3,$CY3,$DD3,$DI3,$DN3,$DS3,$DX3,$EC3,$EH3,$EM3,$ER3,$EW3,$FB3,$FG3,$FL3,$FQ3,$FV3,$GA3,$GF3,$GK3,$GP3,$GU3,$GZ3,$HE3,$HJ3,$HO3) -> 0 | HY3: =MEDIAN($E3,$J3,$O3,$T3,$Y3,$AD3,$AI3,$AN3,$AS3,$AX3,$BC3,$BH3,$BM3,$BR3,$BW3,$CB3,$CG3,$CL3,$CQ3,$CV3,$DA3,$DF3,$DK3,$DP3,$DU3,$DZ3,$EE3,$EJ3,$EO3,$ET3,$EY3,$FD3,$FI3,$FN3,$FS3,$FX3,$GC3,$GH3,$GM3,$GR3,$GW3,$HB3,$HG3,$HL3,$HQ3) -> 0 | HZ3: =MEDIAN($F3,$K3,$P3,$U3,$Z3,$AE3,$AJ3,$AO3,$AT3,$AY3,$BD3,$BI3,$BN3,$BS3,$BX3,$CC3,$CH3,$CM3,$CR3,$CW3,$DB3,$DG3,$DL3,$DQ3,$DV3,$EA3,$EF3,$EK3,$EP3,$EU3,$EZ3,$FE3,$FJ3,$FO3,$FT3,$FY3,$GD3,$GI3,$GN3,$GS3,$GX3,$HC3,$HH3,$HM3,$HR3) -> 0 | IA3: =MAX($B3,$G3,$L3,$Q3,$V3,$AA3,$AF3,$AK3,$AP3,$AU3,$AZ3,$BE3,$BJ3,$BO3,$BT3,$BY3,$CD3,$CI3,$CN3,$CS3,$CX3,$DC3,$DH3,$DM3,$DR3,$DW3,$EB3,$EG3,$EL3,$EQ3,$EV3,$FA3,$FF3,$FK3,$FP3,$FU3,$FZ3,$GE3,$GJ3,$GO3,$GT3,$GY3,$HD3,$HI3,$HN3) -> 0 | IB3: =MAX($C3,$H3,$M3,$R3,$W3,$AB3,$AG3,$AL3,$AQ3,$AV3,$BA3,$BF3,$BK3,$BP3,$BU3,$BZ3,$CE3,$CJ3,$CO3,$CT3,$CY3,$DD3,$DI3,$DN3,$DS3,$DX3,$EC3,$EH3,$EM3,$ER3,$EW3,$FB3,$FG3,$FL3,$FQ3,$FV3,$GA3,$GF3,$GK3,$GP3,$GU3,$GZ3,$HE3,$HJ3,$HO3) -> 0 | IC3: =MAX($E3,$J3,$O3,$T3,$Y3,$AD3,$AI3,$AN3,$AS3,$AX3,$BC3,$BH3,$BM3,$BR3,$BW3,$CB3,$CG3,$CL3,$CQ3,$CV3,$DA3,$DF3,$DK3,$DP3,$DU3,$DZ3,$EE3,$EJ3,$EO3,$ET3,$EY3,$FD3,$FI3,$FN3,$FS3,$FX3,$GC3,$GH3,$GM3,$GR3,$GW3,$HB3,$HG3,$HL3,$HQ3) -> 0 | ID3: =MAX($F3,$K3,$P3,$U3,$Z3,$AE3,$AJ3,$AO3,$AT3,$AY3,$BD3,$BI3,$BN3,$BS3,$BX3,$CC3,$CH3,$CM3,$CR3,$CW3,$DB3,$DG3,$DL3,$DQ3,$DV3,$EA3,$EF3,$EK3,$EP3,$EU3,$EZ3,$FE3,$FJ3,$FO3,$FT3,$FY3,$GD3,$GI3,$GN3,$GS3,$GX3,$HC3,$HH3,$HM3,$HR3) -> 0
A4: instances/room_x8_y8_a3 | B4: 196.09 | C4: 117.46 | D4: SATISFIABLE | E4: 9700871 | F4: 188.267 | G4: 37.36 | H4: 4.63 | I4: SATISFIABLE | J4: 1595291 | K4: 30.393 | L4: 58.66 | M4: 10.38 | N4: SATISFIABLE | O4: 2907171 | P4: 52.021 | Q4: 157 | R4: 11.29 | S4: SATISFIABLE | T4: 16288146 | U4: 148.164 | V4: 139.26 | W4: 53.05 | X4: SATISFIABLE | Y4: 2295216 | Z4: 113.006 | AA4: 94.7 | AB4: 4.41 | AC4: SATISFIABLE | AD4: 4479196 | AE4: 86.726 | AF4: 322.29 | AG4: 20.85 | AH4: SATISFIABLE | AI4: 24064696 | AJ4: 312.21 | AK4: 369.38 | AL4: 214.13 | AM4: SATISFIABLE | AN4: 3016291 | AO4: 362.019 | AP4: 298.11 | AQ4: 107.11 | AR4: SATISFIABLE | AS4: 6168621 | AT4: 290.109 | AU4: 574.37 | AV4: 48.02 | AW4: SATISFIABLE | AX4: 32752021 | AY4: 562.978 | AZ4: 695.99 | BA4: 338.93 | BB4: SATISFIABLE | BC4: 3733745 | BD4: 688.351 | BE4: 515.37 | BF4: 156.71 | BG4: SATISFIABLE | BH4: 7878196 | BI4: 507.252 | BJ4: 1181.36 | BK4: 326.7 | BL4: SATISFIABLE | BM4: 42090371 | BN4: 1168.438 | BO4: 45.15 | BP4: 0 | BQ4: UNSATISFIABLE | BR4: 8701448 | BS4: 37.214 | BT4: 910.25 | BU4: 245.14 | BV4: SATISFIABLE | BW4: 9529421 | BX4: 901.307 | BY4: 34.97 | BZ4: 5.21 | CA4: SATISFIABLE | CB4: 1085130 | CC4: 28.269 | CD4: 35.79 | CE4: 4.57 | CF4: SATISFIABLE | CG4: 1085130 | CH4: 27.534 | CI4: 39.13 | CJ4: 8.98 | CK4: SATISFIABLE | CL4: 1085130 | CM4: 31.967 | CN4: 81.63 | CO4: 4.31 | CP4: SATISFIABLE | CQ4: 1561305 | CR4: 73.682 | CS4: 63.78 | CT4: 4.18 | CU4: SATISFIABLE | CV4: 1561305 | CW4: 53.904 | CX4: 81.85 | CY4: 17.65 | CZ4: SATISFIABLE | DA4: 1561305 | DB4: 73.447 | DC4: 192.88 | DD4: 37.61 | DE4: SATISFIABLE | DF4: 2121655 | DG4: 184.651 | DH4: 197.35 | DI4: 29.36 | DJ4: SATISFIABLE | DK4: 2121655 | DL4: 188.633 | DM4: 195.22 | DN4: 25.14 | DO4: SATISFIABLE | DP4: 2121655 | DQ4: 186.431 | DR4: 534.8 | DS4: 170.8 | DT4: SATISFIABLE | DU4: 2766180 | DV4: 524.589 | DW4: 347.53 | DX4: 15.67 | DY4: SATISFIABLE | DZ4: 2766180 | EA4: 339.121 | EB4: 343 | EC4: 3.17 | ED4: SATISFIABLE | EE4: 2766180 | EF4: 333.909 | EG4: 674.09 | EH4: 46.81 | EI4: SATISFIABLE | EJ4: 3494880 | EK4: 664.584 | EL4: 670.18 | EM4: 0 | EN4: UNSATISFIABLE | EO4: 6989760 | EP4: 659.655 | EQ4: 1200 | ER4: 604.95 | ES4: UNKNOWN | ET4: 3494880 | EU4: 1193.082 | EV4: 119.55 | EW4: 82.65 | EX4: SATISFIABLE | EY4: 1085130 | EZ4: 112.409 | FA4: 126.99 | FB4: 87.71 | FC4: SATISFIABLE | FD4: 1085130 | FE4: 119.204 | FF4: 125.43 | FG4: 86.77 | FH4: SATISFIABLE | FI4: 1085130 | FJ4: 117.893 | FK4: 248.12 | FL4: 180.44 | FM4: SATISFIABLE | FN4: 1561305 | FO4: 240.63 | FP4: 285.52 | FQ4: 214 | FR4: SATISFIABLE | FS4: 1561305 | FT4: 277.511 | FU4: 304.1 | FV4: 225.3 | FW4: SATISFIABLE | FX4: 1561305 | FY4: 295.257 | FZ4: 487.64 | GA4: 371.15 | GB4: SATISFIABLE | GC4: 2121655 | GD4: 479.724 | GE4: 622.72 | GF4: 457.9 | GG4: SATISFIABLE | GH4: 2121655 | GI4: 614.581 | GJ4: 622.84 | GK4: 452.68 | GL4: SATISFIABLE | GM4: 2121655 | GN4: 615.255 | GO4: 1019.2 | GP4: 698.86 | GQ4: SATISFIABLE | GR4: 2766180 | GS4: 1010.769 | GT4: 909.25 | GU4: 603.36 | GV4: SATISFIABLE | GW4: 2766180 | GX4: 901.371 | GY4: 963.67 | GZ4: 647.96 | HA4: SATISFIABLE | HB4: 2766180 | HC4: 955.988 | HD4: 1200 | HE4: 616.33 | HF4: UNKNOWN | HG4: 3494880 | HH4: 1194.072 | HI4: 569.45 | HJ4: 0 | HK4: UNSATISFIABLE | HL4: 3494880 | HM4: 560.6 | HN4: 1200 | HO4: 624.46 | HP4: UNKNOWN | HQ4: 3494880 | HR4: 1194.368 | HS4: =MIN($B4,$G4,$L4,$Q4,$V4,$AA4,$AF4,$AK4,$AP4,$AU4,$AZ4,$BE4,$BJ4,$BO4,$BT4,$BY4,$CD4,$CI4,$CN4,$CS4,$CX4,$DC4,$DH4,$DM4,$DR4,$DW4,$EB4,$EG4,$EL4,$EQ4,$EV4,$FA4,$FF4,$FK4,$FP4,$FU4,$FZ4,$GE4,$GJ4,$GO4,$GT4,$GY4,$HD4,$HI4,$HN4) -> 0 | HT4: =MIN($C4,$H4,$M4,$R4,$W4,$AB4,$AG4,$AL4,$AQ4,$AV4,$BA4,$BF4,$BK4,$BP4,$BU4,$BZ4,$CE4,$CJ4,$CO4,$CT4,$CY4,$DD4,$DI4,$DN4,$DS4,$DX4,$EC4,$EH4,$EM4,$ER4,$EW4,$FB4,$FG4,$FL4,$FQ4,$FV4,$GA4,$GF4,$GK4,$GP4,$GU4,$GZ4,$HE4,$HJ4,$HO4) -> 0 | HU4: =MIN($E4,$J4,$O4,$T4,$Y4,$AD4,$AI4,$AN4,$AS4,$AX4,$BC4,$BH4,$BM4,$BR4,$BW4,$CB4,$CG4,$CL4,$CQ4,$CV4,$DA4,$DF4,$DK4,$DP4,$DU4,$DZ4,$EE4,$EJ4,$EO4,$ET4,$EY4,$FD4,$FI4,$FN4,$FS4,$FX4,$GC4,$GH4,$GM4,$GR4,$GW4,$HB4,$HG4,$HL4,$HQ4) -> 0 | HV4: =MIN($F4,$K4,$P4,$U4,$Z4,$AE4,$AJ4,$AO4,$AT4,$AY4,$BD4,$BI4,$BN4,$BS4,$BX4,$CC4,$CH4,$CM4,$CR4,$CW4,$DB4,$DG4,$DL4,$DQ4,$DV4,$EA4,$EF4,$EK4,$EP4,$EU4,$EZ4,$FE4,$FJ4,$FO4,$FT4,$FY4,$GD4,$GI4,$GN4,$GS4,$GX4,$HC4,$HH4,$HM4,$HR4) -> 0 | HW4: =MEDIAN($B4,$G4,$L4,$Q4,$V4,$AA4,$AF4,$AK4,$AP4,$AU4,$AZ4,$BE4,$BJ4,$BO4,$BT4,$BY4,$CD4,$CI4,$CN4,$CS4,$CX4,$DC4,$DH4,$DM4,$DR4,$DW4,$EB4,$EG4,$EL4,$EQ4,$EV4,$FA4,$FF4,$FK4,$FP4,$FU4,$FZ4,$GE4,$GJ4,$GO4,$GT4,$GY4,$HD4,$HI4,$HN4) -> 0 | HX4: =MEDIAN($C4,$H4,$M4,$R4,$W4,$AB4,$AG4,$AL4,$AQ4,$AV4,$BA4,$BF4,$BK4,$BP4,$BU4,$BZ4,$CE4,$CJ4,$CO4,$CT4,$CY4,$DD4,$DI4,$DN4,$DS4,$DX4,$EC4,$EH4,$EM4,$ER4,$EW4,$FB4,$FG4,$FL4,$FQ4,$FV4,$GA4,$GF4,$GK4,$GP4,$GU4,$GZ4,$HE4,$HJ4,$HO4) -> 0 | HY4: =MEDIAN($E4,$J4,$O4,$T4,$Y4,$AD4,$AI4,$AN4,$AS4,$AX4,$BC4,$BH4,$BM4,$BR4,$BW4,$CB4,$CG4,$CL4,$CQ4,$CV4,$DA4,$DF4,$DK4,$DP4,$DU4,$DZ4,$EE4,$EJ4,$EO4,$ET4,$EY4,$FD4,$FI4,$FN4,$FS4,$FX4,$GC4,$GH4,$GM4,$GR4,$GW4,$HB4,$HG4,$HL4,$HQ4) -> 0 | HZ4: =MEDIAN($F4,$K4,$P4,$U4,$Z4,$AE4,$AJ4,$AO4,$AT4,$AY4,$BD4,$BI4,$BN4,$BS4,$BX4,$CC4,$CH4,$CM4,$CR4,$CW4,$DB4,$DG4,$DL4,$DQ4,$DV4,$EA4,$EF4,$EK4,$EP4,$EU4,$EZ4,$FE4,$FJ4,$FO4,$FT4,$FY4,$GD4,$GI4,$GN4,$GS4,$GX4,$HC4,$HH4,$HM4,$HR4) -> 0 | IA4: =MAX($B4,$G4,$L4,$Q4,$V4,$AA4,$AF4,$AK4,$AP4,$AU4,$AZ4,$BE4,$BJ4,$BO4,$BT4,$BY4,$CD4,$CI4,$CN4,$CS4,$CX4,$DC4,$DH4,$DM4,$DR4,$DW4,$EB4,$EG4,$EL4,$EQ4,$EV4,$FA4,$FF4,$FK4,$FP4,$FU4,$FZ4,$GE4,$GJ4,$GO4,$GT4,$GY4,$HD4,$HI4,$HN4) -> 0 | IB4: =MAX($C4,$H4,$M4,$R4,$W4,$AB4,$AG4,$AL4,$AQ4,$AV4,$BA4,$BF4,$BK4,$BP4,$BU4,$BZ4,$CE4,$CJ4,$CO4,$CT4,$CY4,$DD4,$DI4,$DN4,$DS4,$DX4,$EC4,$EH4,$EM4,$ER4,$EW4,$FB4,$FG4,$FL4,$FQ4,$FV4,$GA4,$GF4,$GK4,$GP4,$GU4,$GZ4,$HE4,$HJ4,$HO4) -> 0 | IC4: =MAX($E4,$J4,$O4,$T4,$Y4,$AD4,$AI4,$AN4,$AS4,$AX4,$BC4,$BH4,$BM4,$BR4,$BW4,$CB4,$CG4,$CL4,$CQ4,$CV4,$DA4,$DF4,$DK4,$DP4,$DU4,$DZ4,$EE4,$EJ4,$EO4,$ET4,$EY4,$FD4,$FI4,$FN4,$FS4,$FX4,$GC4,$GH4,$GM4,$GR4,$GW4,$HB4,$HG4,$HL4,$HQ4) -> 0 | ID4: =MAX($F4,$K4,$P4,$U4,$Z4,$AE4,$AJ4,$AO4,$AT4,$AY4,$BD4,$BI4,$BN4,$BS4,$BX4,$CC4,$CH4,$CM4,$CR4,$CW4,$DB4,$DG4,$DL4,$DQ4,$DV4,$EA4,$EF4,$EK4,$EP4,$EU4,$EZ4,$FE4,$FJ4,$FO4,$FT4,$FY4,$GD4,$GI4,$GN4,$GS4,$GX4,$HC4,$HH4,$HM4,$HR4) -> 0
A5: instances/warehouse_x8_y8_a3 | B5: 1200 | G5: 753.11 | H5: 736.69 | I5: SATISFIABLE | J5: 1032226 | K5: 746.708 | L5: 1200 | M5: 1172.24 | N5: UNKNOWN | O5: 2344106 | P5: 1194.044 | Q5: 1200 | V5: 27.91 | W5: 0.95 | X5: SATISFIABLE | Y5: 1485871 | Z5: 20.988 | AA5: 123.48 | AB5: 79.2 | AC5: SATISFIABLE | AD5: 3669851 | AE5: 116.242 | AF5: 207.7 | AG5: 31.77 | AH5: SATISFIABLE | AI5: 22964971 | AJ5: 198.177 | AK5: 99.6 | AL5: 50.21 | AM5: SATISFIABLE | AN5: 1916566 | AO5: 92.649 | AP5: 81.66 | AQ5: 12.91 | AR5: SATISFIABLE | AS5: 5068896 | AT5: 74.257 | AU5: 337.32 | AV5: 75.77 | AW5: SATISFIABLE | AX5: 31317816 | AY5: 327.013 | AZ5: 87.39 | BA5: 17.06 | BB5: SATISFIABLE | BC5: 2299540 | BD5: 80.33 | BE5: 150.9 | BF5: 46.63 | BG5: SATISFIABLE | BH5: 6443991 | BI5: 143.245 | BJ5: 444.91 | BK5: 116.94 | BL5: SATISFIABLE | BM5: 40277586 | BN5: 434 | BO5: 26.62 | BP5: 0 | BQ5: UNSATISFIABLE | BR5: 5194156 | BS5: 19.785 | BT5: 170.66 | BU5: 7.01 | BV5: SATISFIABLE | BW5: 7716636 | BX5: 163.019 | BY5: 840.14 | BZ5: 824.48 | CA5: SATISFIABLE | CB5: 517184 | CC5: 832.579 | CD5: 204.92 | CE5: 190 | CF5: SATISFIABLE | CG5: 517184 | CH5: 198.111 | CI5: 512.73 | CJ5: 497.75 | CK5: SATISFIABLE | CL5: 517184 | CM5: 505.807 | CN5: 197 | CO5: 168.74 | CP5: SATISFIABLE | CQ5: 747079 | CR5: 189.7 | CS5: 75.71 | CT5: 53.15 | CU5: SATISFIABLE | CV5: 747079 | CW5: 68.361 | CX5: 31.13 | CY5: 3.76 | CZ5: SATISFIABLE | DA5: 747079 | DB5: 24.031 | DC5: 135.72 | DD5: 95.61 | DE5: SATISFIABLE | DF5: 1017049 | DG5: 128.273 | DH5: 46.77 | DI5: 2.52 | DJ5: SATISFIABLE | DK5: 1017049 | DL5: 39.415 | DM5: 68.24 | DN5: 29.81 | DO5: SATISFIABLE | DP5: 1017049 | DQ5: 61.191 | DR5: 154.8 | DS5: 77.65 | DT5: SATISFIABLE | DU5: 1327094 | DV5: 146.916 | DW5: 77.01 | DX5: 4.36 | DY5: SATISFIABLE | DZ5: 1327094 | EA5: 69.127 | EB5: 83.16 | EC5: 2.64 | ED5: SATISFIABLE | EE5: 1327094 | EF5: 59.137 | EG5: 279.02 | EH5: 148.26 | EI5: SATISFIABLE | EJ5: 1677214 | EK5: 271.282 | EL5: 131.09 | EM5: 0 | EN5: UNSATISFIABLE | EO5: 3354428 | EP5: 123.183 | EQ5: 193.87 | ER5: 95.77 | ES5: SATISFIABLE | ET5: 1677214 | EU5: 186.201 | EV5: 786.66 | EW5: 769.76 | EX5: SATISFIABLE | EY5: 517184 | EZ5: 780.286 | FA5: 285.44 | FB5: 267.58 | FC5: SATISFIABLE | FD5: 517184 | FE5: 278.304 | FF5: 745.31 | FG5: 728.02 | FH5: SATISFIABLE | FI5: 517184 | FJ5: 738.938 | FK5: 156.94 | FL5: 133.8 | FM5: SATISFIABLE | FN5: 747079 | FO5: 149.854 | FP5: 117.29 | FQ5: 91.41 | FR5: SATISFIABLE | FS5: 747079 | FT5: 109.974 | FU5: 144.34 | FV5: 119.93 | FW5: SATISFIABLE | FX5: 747079 | FY5: 137.453 | FZ5: 274.71 | GA5: 239.22 | GB5: SATISFIABLE | GC5: 1017049 | GD5: 268.169 | GE5: 247.12 | GF5: 206.59 | GG5: SATISFIABLE | GH5: 1017049 | GI5: 239.26 | GJ5: 321.35 | GK5: 285.65 | GL5: SATISFIABLE | GM5: 1017049 | GN5: 314.416 | GO5: 503.31 | GP5: 442.96 | GQ5: SATISFIABLE | GR5: 1327094 | GS5: 495.452 | GT5: 404.27 | GU5: 335.04 | GV5: SATISFIABLE | GW5: 1327094 | GX5: 396.716 | GY5: 421.47 | GZ5: 366.55 | HA5: SATISFIABLE | HB5: 1327094 | HC5: 414.906 | HD5: 811 | HE5: 721.56 | HF5: SATISFIABLE | HG5: 1677214 | HH5: 804.136 | HI5: 90.07 | HJ5: 0 | HK5: UNSATISFIABLE | HL5: 1677214 | HM5: 82.87 | HN5: 777.38 | HO5: 654.09 | HP5: SATISFIABLE | HQ5: 1677214 | HR5: 770.333 | HS5: =MIN($B5,$G5,$L5,$Q5,$V5,$AA5,$AF5,$AK5,$AP5,$AU5,$AZ5,$BE5,$BJ5,$BO5,$BT5,$BY5,$CD5,$CI5,$CN5,$CS5,$CX5,$DC5,$DH5,$DM5,$DR5,$DW5,$EB5,$EG5,$EL5,$EQ5,$EV5,$FA5,$FF5,$FK5,$FP5,$FU5,$FZ5,$GE5,$GJ5,$GO5,$GT5,$GY5,$HD5,$HI5,$HN5) -> 0 | HT5: =MIN($C5,$H5,$M5,$R5,$W5,$AB5,$AG5,$AL5,$AQ5,$AV5,$BA5,$BF5,$BK5,$BP5,$BU5,$BZ5,$CE5,$CJ5,$CO5,$CT5,$CY5,$DD5,$DI5,$DN5,$DS5,$DX5,$EC5,$EH5,$EM5,$ER5,$EW5,$FB5,$FG5,$FL5,$FQ5,$FV5,$GA5,$GF5,$GK5,$GP5,$GU5,$GZ5,$HE5,$HJ5,$HO5) -> 0 | HU5: =MIN($E5,$J5,$O5,$T5,$Y5,$AD5,$AI5,$AN5,$AS5,$AX5,$BC5,$BH5,$BM5,$BR5,$BW5,$CB5,$CG5,$CL5,$CQ5,$CV5,$DA5,$DF5,$DK5,$DP5,$DU5,$DZ5,$EE5,$EJ5,$EO5,$ET5,$EY5,$FD5,$FI5,$FN5,$FS5,$FX5,$GC5,$GH5,$GM5,$GR5,$GW5,$HB5,$HG5,$HL5,$HQ5) -> 0 | HV5: =MIN($F5,$K5,$P5,$U5,$Z5,$AE5,$AJ5,$AO5,$AT5,$AY5,$BD5,$BI5,$BN5,$BS5,$BX5,$CC5,$CH5,$CM5,$CR5,$CW5,$DB5,$DG5,$DL5,$DQ5,$DV5,$EA5,$EF5,$EK5,$EP5,$EU5,$EZ5,$FE5,$FJ5,$FO5,$FT5,$FY5,$GD5,$GI5,$GN5,$GS5,$GX5,$HC5,$HH5,$HM5,$HR5) -> 0 | HW5: =MEDIAN($B5,$G5,$L5,$Q5,$V5,$AA5,$AF5,$AK5,$AP5,$AU5,$AZ5,$BE5,$BJ5,$BO5,$BT5,$BY5,$CD5,$CI5,$CN5,$CS5,$CX5,$DC5,$DH5,$DM5,$DR5,$DW5,$EB5,$EG5,$EL5,$EQ5,$EV5,$FA5,$FF5,$FK5,$FP5,$FU5,$FZ5,$GE5,$GJ5,$GO5,$GT5,$GY5,$HD5,$HI5,$HN5) -> 0 | HX5: =MEDIAN($C5,$H5,$M5,$R5,$W5,$AB5,$AG5,$AL5,$AQ5,$AV5,$BA5,$BF5,$BK5,$BP5,$BU5,$BZ5,$CE5,$CJ5,$CO5,$CT5,$CY5,$DD5,$DI5,$DN5,$DS5,$DX5,$EC5,$EH5,$EM5,$ER5,$EW5,$FB5,$FG5,$FL5,$FQ5,$FV5,$GA5,$GF5,$GK5,$GP5,$GU5,$GZ5,$HE5,$HJ5,$HO5) -> 0 | HY5: =MEDIAN($E5,$J5,$O5,$T5,$Y5,$AD5,$AI5,$AN5,$AS5,$AX5,$BC5,$BH5,$BM5,$BR5,$BW5,$CB5,$CG5,$CL5,$CQ5,$CV5,$DA5,$DF5,$DK5,$DP5,$DU5,$DZ5,$EE5,$EJ5,$EO5,$ET5,$EY5,$FD5,$FI5,$FN5,$FS5,$FX5,$GC5,$GH5,$GM5,$GR5,$GW5,$HB5,$HG5,$HL5,$HQ5) -> 0 | HZ5: =MEDIAN($F5,$K5,$P5,$U5,$Z5,$AE5,$AJ5,$AO5,$AT5,$AY5,$BD5,$BI5,$BN5,$BS5,$BX5,$CC5,$CH5,$CM5,$CR5,$CW5,$DB5,$DG5,$DL5,$DQ5,$DV5,$EA5,$EF5,$EK5,$EP5,$EU5,$EZ5,$FE5,$FJ5,$FO5,$FT5,$FY5,$GD5,$GI5,$GN5,$GS5,$GX5,$HC5,$HH5,$HM5,$HR5) -> 0 | IA5: =MAX($B5,$G5,$L5,$Q5,$V5,$AA5,$AF5,$AK5,$AP5,$AU5,$AZ5,$BE5,$BJ5,$BO5,$BT5,$BY5,$CD5,$CI5,$CN5,$CS5,$CX5,$DC5,$DH5,$DM5,$DR5,$DW5,$EB5,$EG5,$EL5,$EQ5,$EV5,$FA5,$FF5,$FK5,$FP5,$FU5,$FZ5,$GE5,$GJ5,$GO5,$GT5,$GY5,$HD5,$HI5,$HN5) -> 0 | IB5: =MAX($C5,$H5,$M5,$R5,$W5,$AB5,$AG5,$AL5,$AQ5,$AV5,$BA5,$BF5,$BK5,$BP5,$BU5,$BZ5,$CE5,$CJ5,$CO5,$CT5,$CY5,$DD5,$DI5,$DN5,$DS5,$DX5,$EC5,$EH5,$EM5,$ER5,$EW5,$FB5,$FG5,$FL5,$FQ5,$FV5,$GA5,$GF5,$GK5,$GP5,$GU5,$GZ5,$HE5,$HJ5,$HO5) -> 0 | IC5: =MAX($E5,$J5,$O5,$T5,$Y5,$AD5,$AI5,$AN5,$AS5,$AX5,$BC5,$BH5,$BM5,$BR5,$BW5,$CB5,$CG5,$CL5,$CQ5,$CV5,$DA5,$DF5,$DK5,$DP5,$DU5,$DZ5,$EE5,$EJ5,$EO5,$ET5,$EY5,$FD5,$FI5,$FN5,$FS5,$FX5,$GC5,$GH5,$GM5,$GR5,$GW5,$HB5,$HG5,$HL5,$HQ5) -> 0 | ID5: =MAX($F5,$K5,$P5,$U5,$Z5,$AE5,$AJ5,$AO5,$AT5,$AY5,$BD5,$BI5,$BN5,$BS5,$BX5,$CC5,$CH5,$CM5,$CR5,$CW5,$DB5,$DG5,$DL5,$DQ5,$DV5,$EA5,$EF5,$EK5,$EP5,$EU5,$EZ5,$FE5,$FJ5,$FO5,$FT5,$FY5,$GD5,$GI5,$GN5,$GS5,$GX5,$HC5,$HH5,$HM5,$HR5) -> 0
A7: SUM | B7: =SUM(B$3:B$5) -> 0 | C7: =SUM(C$3:C$5) -> 0 | E7: =SUM(E$3:E$5) -> 0 | F7: =SUM(F$3:F$5) -> 0 | G7: =SUM(G$3:G$5) -> 0 | H7: =SUM(H$3:H$5) -> 0 | J7: =SUM(J$3:J$5) -> 0 | K7: =SUM(K$3:K$5) -> 0 | L7: =SUM(L$3:L$5) -> 0 | M7: =SUM(M$3:M$5) -> 0 | O7: =SUM(O$3:O$5) -> 0 | P7: =SUM(P$3:P$5) -> 0 | Q7: =SUM(Q$3:Q$5) -> 0 | R7: =SUM(R$3:R$5) -> 0 | T7: =SUM(T$3:T$5) -> 0 | U7: =SUM(U$3:U$5) -> 0 | V7: =SUM(V$3:V$5) -> 0 | W7: =SUM(W$3:W$5) -> 0 | Y7: =SUM(Y$3:Y$5) -> 0 | Z7: =SUM(Z$3:Z$5) -> 0 | AA7: =SUM(AA$3:AA$5) -> 0 | AB7: =SUM(AB$3:AB$5) -> 0 | AD7: =SUM(AD$3:AD$5) -> 0 | AE7: =SUM(AE$3:AE$5) -> 0 | AF7: =SUM(AF$3:AF$5) -> 0 | AG7: =SUM(AG$3:AG$5) -> 0 | AI7: =SUM(AI$3:AI$5) -> 0 | AJ7: =SUM(AJ$3:AJ$5) -> 0 | AK7: =SUM(AK$3:AK$5) -> 0 | AL7: =SUM(AL$3:AL$5) -> 0 | AN7: =SUM(AN$3:AN$5) -> 0 | AO7: =SUM(AO$3:AO$5) -> 0 | AP7: =SUM(AP$3:AP$5) -> 0 | AQ7: =SUM(AQ$3:AQ$5) -> 0 | AS7: =SUM(AS$3:AS$5) -> 0 | AT7: =SUM(AT$3:AT$5) -> 0 | AU7: =SUM(AU$3:AU$5) -> 0 | AV7: =SUM(AV$3:AV$5) -> 0 | AX7: =SUM(AX$3:AX$5) -> 0 | AY7: =SUM(AY$3:AY$5) -> 0 | AZ7: =SUM(AZ$3:AZ$5) -> 0 | BA7: =SUM(BA$3:BA$5) -> 0 | BC7: =SUM(BC$3:BC$5) -> 0 | BD7: =SUM(BD$3:BD$5) -> 0 | BE7: =SUM(BE$3:BE$5) -> 0 | BF7: =SUM(BF$3:BF$5) -> 0 | BH7: =SUM(BH$3:BH$5) -> 0 | BI7: =SUM(BI$3:BI$5) -> 0 | BJ7: =SUM(BJ$3:BJ$5) -> 0 | BK7: =SUM(BK$3:BK$5) -> 0 | BM7: =SUM(BM$3:BM$5) -> 0 | BN7: =SUM(BN$3:BN$5) -> 0 | BO7: =SUM(BO$3:BO$5) -> 0 | BP7: =SUM(BP$3:BP$5) -> 0 | BR7: =SUM(BR$3:BR$5) -> 0 | BS7: =SUM(BS$3:BS$5) -> 0 | BT7: =SUM(BT$3:BT$5) -> 0 | BU7: =SUM(BU$3:BU$5) -> 0 | BW7: =SUM(BW$3:BW$5) -> 0 | BX7: =SUM(BX$3:BX$5) -> 0 | BY7: =SUM(BY$3:BY$5) -> 0 | BZ7: =SUM(BZ$3:BZ$5) -> 0 | CB7: =SUM(CB$3:CB$5) -> 0 | CC7: =SUM(CC$3:CC$5) -> 0 | CD7: =SUM(CD$3:CD$5) -> 0 | CE7: =SUM(CE$3:CE$5) -> 0 | CG7: =SUM(CG$3:CG$5) -> 0 | CH7: =SUM(CH$3:CH$5) -> 0 | CI7: =SUM(CI$3:CI$5) -> 0 | CJ7: =SUM(CJ$3:CJ$5) -> 0 | CL7: =SUM(CL$3:CL$5) -> 0 | CM7: =SUM(CM$3:CM$5) -> 0 | CN7: =SUM(CN$3:CN$5) -> 0 | CO7: =SUM(CO$3:CO$5) -> 0 | CQ7: =SUM(CQ$3:CQ$5) -> 0 | CR7: =SUM(CR$3:CR$5) -> 0 | CS7: =SUM(CS$3:CS$5) -> 0 | CT7: =SUM(CT$3:CT$5) -> 0 | CV7: =SUM(CV$3:CV$5) -> 0 | CW7: =SUM(CW$3:CW$5) -> 0 | CX7: =SUM(CX$3:CX$5) -> 0 | CY7: =SUM(CY$3:CY$5) -> 0 | DA7: =SUM(DA$3:DA$5) -> 0 | DB7: =SUM(DB$3:DB$5) -> 0 | DC7: =SUM(DC$3:DC$5) -> 0 | DD7: =SUM(DD$3:DD$5) -> 0 | DF7: =SUM(DF$3:DF$5) -> 0 | DG7: =SUM(DG$3:DG$5) -> 0 | DH7: =SUM(DH$3:DH$5) -> 0 | DI7: =SUM(DI$3:DI$5) -> 0 | DK7: =SUM(DK$3:DK$5) -> 0 | DL7: =SUM(DL$3:DL$5) -> 0 | DM7: =SUM(DM$3:DM$5) -> 0 | DN7: =SUM(DN$3:DN$5) -> 0 | DP7: =SUM(DP$3:DP$5) -> 0 | DQ7: =SUM(DQ$3:DQ$5) -> 0 | DR7: =SUM(DR$3:DR$5) -> 0 | DS7: =SUM(DS$3:DS$5) -> 0 | DU7: =SUM(DU$3:DU$5) -> 0 | DV7: =SUM(DV$3:DV$5) -> 0 | DW7: =SUM(DW$3:DW$5) -> 0 | DX7: =SUM(DX$3:DX$5) -> 0 | DZ7: =SUM(DZ$3:DZ$5) -> 0 | EA7: =SUM(EA$3:EA$5) -> 0 | EB7: =SUM(EB$3:EB$5) -> 0 | EC7: =SUM(EC$3:EC$5) -> 0 | EE7: =SUM(EE$3:EE$5) -> 0 | EF7: =SUM(EF$3:EF$5) -> 0 | EG7: =SUM(EG$3:EG$5) -> 0 | EH7: =SUM(EH$3:EH$5) -> 0 | EJ7: =SUM(EJ$3:EJ$5) -> 0 | EK7: =SUM(EK$3:EK$5) -> 0 | EL7: =SUM(EL$3:EL$5) -> 0 | EM7: =SUM(EM$3:EM$5) -> 0 | EO7: =SUM(EO$3:EO$5) -> 0 | EP7: =SUM(EP$3:EP$5) -> 0 | EQ7: =SUM(EQ$3:EQ$5) -> 0 | ER7: =SUM(ER$3:ER$5) -> 0 | ET7: =SUM(ET$3:ET$5) -> 0 | EU7: =SUM(EU$3:EU$5) -> 0 | EV7: =SUM(EV$3:EV$5) -> 0 | EW7: =SUM(EW$3:EW$5) -> 0 | EY7: =SUM(EY$3:EY$5) -> 0 | EZ7: =SUM(EZ$3:EZ$5) -> 0 | FA7: =SUM(FA$3:FA$5) -> 0 | FB7: =SUM(FB$3:FB$5) -> 0 | FD7: =SUM(FD$3:FD$5) -> 0 | FE7: =SUM(FE$3:FE$5) -> 0 | FF7: =SUM(FF$3:FF$5) -> 0 | FG7: =SUM(FG$3:FG$5) -> 0 | FI7: =SUM(FI$3:FI$5) -> 0 | FJ7: =SUM(FJ$3:FJ$5) -> 0 | FK7: =SUM(FK$3:FK$5) -> 0 | FL7: =SUM(FL$3:FL$5) -> 0 | FN7: =SUM(FN$3:FN$5) -> 0 | FO7: =SUM(FO$3:FO$5) -> 0 | FP7: =SUM(FP$3:FP$5) -> 0 | FQ7: =SUM(FQ$3:FQ$5) -> 0 | FS7: =SUM(FS$3:FS$5) -> 0 | FT7: =SUM(FT$3:FT$5) -> 0 | FU7: =SUM(FU$3:FU$5) -> 0 | FV7: =SUM(FV$3:FV$5) -> 0 | FX7: =SUM(FX$3:FX$5) -> 0 | FY7: =SUM(FY$3:FY$5) -> 0 | FZ7: =SUM(FZ$3:FZ$5) -> 0 | GA7: =SUM(GA$3:GA$5) -> 0 | GC7: =SUM(GC$3:GC$5) -> 0 | GD7: =SUM(GD$3:GD$5) -> 0 | GE7: =SUM(GE$3:GE$5) -> 0 | GF7: =SUM(GF$3:GF$5) -> 0 | GH7: =SUM(GH$3:GH$5) -> 0 | GI7: =SUM(GI$3:GI$5) -> 0 | GJ7: =SUM(GJ$3:GJ$5) -> 0 | GK7: =SUM(GK$3:GK$5) -> 0 | GM7: =SUM(GM$3:GM$5) -> 0 | GN7: =SUM(GN$3:GN$5) -> 0 | GO7: =SUM(GO$3:GO$5) -> 0 | GP7: =SUM(GP$3:GP$5) -> 0 | GR7: =SUM(GR$3:GR$5) -> 0 | GS7: =SUM(GS$3:GS$5) -> 0 | GT7: =SUM(GT$3:GT$5) -> 0 | GU7: =SUM(GU$3:GU$5) -> 0 | GW7: =SUM(GW$3:GW$5) -> 0 | GX7: =SUM(GX$3:GX$5) -> 0 | GY7: =SUM(GY$3:GY$5) -> 0 | GZ7: =SUM(GZ$3:GZ$5) -> 0 | HB7: =SUM(HB$3:HB$5) -> 0 | HC7: =SUM(HC$3:HC$5) -> 0 | HD7: =SUM(HD$3:HD$5) -> 0 | HE7: =SUM(HE$3:HE$5) -> 0 | HG7: =SUM(HG$3:HG$5) -> 0 | HH7: =SUM(HH$3:HH$5) -> 0 | HI7: =SUM(HI$3:HI$5) -> 0 | HJ7: =SUM(HJ$3:HJ$5) -> 0 | HL7: =SUM(HL$3:HL$5) -> 0 | HM7: =SUM(HM$3:HM$5) -> 0 | HN7: =SUM(HN$3:HN$5) -> 0 | HO7: =SUM(HO$3:HO$5) -> 0 | HQ7: =SUM(HQ$3:HQ$5) -> 0 | HR7: =SUM(HR$3:HR$5) -> 0 | HS7: =SUM(HS$3:HS$5) -> 0 | HT7: =SUM(HT$3:HT$5) -> 0 | HU7: =SUM(HU$3:HU$5) -> 0 | HV7: =SUM(HV$3:HV$5) -> 0 | HW7: =SUM(HW$3:HW$5) -> 0 | HX7: =SUM(HX$3:HX$5) -> 0 | ... ID7: =SUM(ID$3:ID$5) -> 0
A8: AVG | B8: =AVERAGE(B$3:B$5) -> 0 | C8: =AVERAGE(C$3:C$5) -> 0 | E8: =AVERAGE(E$3:E$5) -> 0 | F8: =AVERAGE(F$3:F$5) -> 0 | G8: =AVERAGE(G$3:G$5) -> 0 | H8: =AVERAGE(H$3:H$5) -> 0 | J8: =AVERAGE(J$3:J$5) -> 0 | K8: =AVERAGE(K$3:K$5) -> 0 | L8: =AVERAGE(L$3:L$5) -> 0 | M8: =AVERAGE(M$3:M$5) -> 0 | O8: =AVERAGE(O$3:O$5) -> 0 | P8: =AVERAGE(P$3:P$5) -> 0 | Q8: =AVERAGE(Q$3:Q$5) -> 0 | R8: =AVERAGE(R$3:R$5) -> 0 | T8: =AVERAGE(T$3:T$5) -> 0 | U8: =AVERAGE(U$3:U$5) -> 0 | V8: =AVERAGE(V$3:V$5) -> 0 | W8: =AVERAGE(W$3:W$5) -> 0 | Y8: =AVERAGE(Y$3:Y$5) -> 0 | Z8: =AVERAGE(Z$3:Z$5) -> 0 | AA8: =AVERAGE(AA$3:AA$5) -> 0 | AB8: =AVERAGE(AB$3:AB$5) -> 0 | AD8: =AVERAGE(AD$3:AD$5) -> 0 | AE8: =AVERAGE(AE$3:AE$5) -> 0 | AF8: =AVERAGE(AF$3:AF$5) -> 0 | AG8: =AVERAGE(AG$3:AG$5) -> 0 | AI8: =AVERAGE(AI$3:AI$5) -> 0 | AJ8: =AVERAGE(AJ$3:AJ$5) -> 0 | AK8: =AVERAGE(AK$3:AK$5) -> 0 | AL8: =AVERAGE(AL$3:AL$5) -> 0 | AN8: =AVERAGE(AN$3:AN$5) -> 0 | AO8: =AVERAGE(AO$3:AO$5) -> 0 | AP8: =AVERAGE(AP$3:AP$5) -> 0 | AQ8: =AVERAGE(AQ$3:AQ$5) -> 0 | AS8: =AVERAGE(AS$3:AS$5) -> 0 | AT8: =AVERAGE(AT$3:AT$5) -> 0 | AU8: =AVERAGE(AU$3:AU$5) -> 0 | AV8: =AVERAGE(AV$3:AV$5) -> 0 | AX8: =AVERAGE(AX$3:AX$5) -> 0 | AY8: =AVERAGE(AY$3:AY$5) -> 0 | AZ8: =AVERAGE(AZ$3:AZ$5) -> 0 | BA8: =AVERAGE(BA$3:BA$5) -> 0 | BC8: =AVERAGE(BC$3:BC$5) -> 0 | BD8: =AVERAGE(BD$3:BD$5) -> 0 | BE8: =AVERAGE(BE$3:BE$5) -> 0 | BF8: =AVERAGE(BF$3:BF$5) -> 0 | BH8: =AVERAGE(BH$3:BH$5) -> 0 | BI8: =AVERAGE(BI$3:BI$5) -> 0 | BJ8: =AVERAGE(BJ$3:BJ$5) -> 0 | BK8: =AVERAGE(BK$3:BK$5) -> 0 | BM8: =AVERAGE(BM$3:BM$5) -> 0 | BN8: =AVERAGE(BN$3:BN$5) -> 0 | BO8: =AVERAGE(BO$3:BO$5) -> 0 | BP8: =AVERAGE(BP$3:BP$5) -> 0 | BR8: =AVERAGE(BR$3:BR$5) -> 0 | BS8: =AVERAGE(BS$3:BS$5) -> 0 | BT8: =AVERAGE(BT$3:BT$5) -> 0 | BU8: =AVERAGE(BU$3:BU$5) -> 0 | BW8: =AVERAGE(BW$3:BW$5) -> 0 | BX8: =AVERAGE(BX$3:BX$5) -> 0 | BY8: =AVERAGE(BY$3:BY$5) -> 0 | BZ8: =AVERAGE(BZ$3:BZ$5) -> 0 | CB8: =AVERAGE(CB$3:CB$5) -> 0 | CC8: =AVERAGE(CC$3:CC$5) -> 0 | CD8: =AVERAGE(CD$3:CD$5) -> 0 | CE8: =AVERAGE(CE$3:CE$5) -> 0 | CG8: =AVERAGE(CG$3:CG$5) -> 0 | CH8: =AVERAGE(CH$3:CH$5) -> 0 | CI8: =AVERAGE(CI$3:CI$5) -> 0 | CJ8: =AVERAGE(CJ$3:CJ$5) -> 0 | CL8: =AVERAGE(CL$3:CL$5) -> 0 | CM8: =AVERAGE(CM$3:CM$5) -> 0 | CN8: =AVERAGE(CN$3:CN$5) -> 0 | CO8: =AVERAGE(CO$3:CO$5) -> 0 | CQ8: =AVERAGE(CQ$3:CQ$5) -> 0 | CR8: =AVERAGE(CR$3:CR$5) -> 0 | CS8: =AVERAGE(CS$3:CS$5) -> 0 | CT8: =AVERAGE(CT$3:CT$5) -> 0 | CV8: =AVERAGE(CV$3:CV$5) -> 0 | CW8: =AVERAGE(CW$3:CW$5) -> 0 | CX8: =AVERAGE(CX$3:CX$5) -> 0 | CY8: =AVERAGE(CY$3:CY$5) -> 0 | DA8: =AVERAGE(DA$3:DA$5) -> 0 | DB8: =AVERAGE(DB$3:DB$5) -> 0 | DC8: =AVERAGE(DC$3:DC$5) -> 0 | DD8: =AVERAGE(DD$3:DD$5) -> 0 | DF8: =AVERAGE(DF$3:DF$5) -> 0 | DG8: =AVERAGE(DG$3:DG$5) -> 0 | DH8: =AVERAGE(DH$3:DH$5) -> 0 | DI8: =AVERAGE(DI$3:DI$5) -> 0 | DK8: =AVERAGE(DK$3:DK$5) -> 0 | DL8: =AVERAGE(DL$3:DL$5) -> 0 | DM8: =AVERAGE(DM$3:DM$5) -> 0 | DN8: =AVERAGE(DN$3:DN$5) -> 0 | DP8: =AVERAGE(DP$3:DP$5) -> 0 | DQ8: =AVERAGE(DQ$3:DQ$5) -> 0 | DR8: =AVERAGE(DR$3:DR$5) -> 0 | DS8: =AVERAGE(DS$3:DS$5) -> 0 | DU8: =AVERAGE(DU$3:DU$5) -> 0 | DV8: =AVERAGE(DV$3:DV$5) -> 0 | DW8: =AVERAGE(DW$3:DW$5) -> 0 | DX8: =AVERAGE(DX$3:DX$5) -> 0 | DZ8: =AVERAGE(DZ$3:DZ$5) -> 0 | EA8: =AVERAGE(EA$3:EA$5) -> 0 | EB8: =AVERAGE(EB$3:EB$5) -> 0 | EC8: =AVERAGE(EC$3:EC$5) -> 0 | EE8: =AVERAGE(EE$3:EE$5) -> 0 | EF8: =AVERAGE(EF$3:EF$5) -> 0 | EG8: =AVERAGE(EG$3:EG$5) -> 0 | EH8: =AVERAGE(EH$3:EH$5) -> 0 | EJ8: =AVERAGE(EJ$3:EJ$5) -> 0 | EK8: =AVERAGE(EK$3:EK$5) -> 0 | EL8: =AVERAGE(EL$3:EL$5) -> 0 | EM8: =AVERAGE(EM$3:EM$5) -> 0 | EO8: =AVERAGE(EO$3:EO$5) -> 0 | EP8: =AVERAGE(EP$3:EP$5) -> 0 | EQ8: =AVERAGE(EQ$3:EQ$5) -> 0 | ER8: =AVERAGE(ER$3:ER$5) -> 0 | ET8: =AVERAGE(ET$3:ET$5) -> 0 | EU8: =AVERAGE(EU$3:EU$5) -> 0 | EV8: =AVERAGE(EV$3:EV$5) -> 0 | EW8: =AVERAGE(EW$3:EW$5) -> 0 | EY8: =AVERAGE(EY$3:EY$5) -> 0 | EZ8: =AVERAGE(EZ$3:EZ$5) -> 0 | FA8: =AVERAGE(FA$3:FA$5) -> 0 | FB8: =AVERAGE(FB$3:FB$5) -> 0 | FD8: =AVERAGE(FD$3:FD$5) -> 0 | FE8: =AVERAGE(FE$3:FE$5) -> 0 | FF8: =AVERAGE(FF$3:FF$5) -> 0 | FG8: =AVERAGE(FG$3:FG$5) -> 0 | FI8: =AVERAGE(FI$3:FI$5) -> 0 | FJ8: =AVERAGE(FJ$3:FJ$5) -> 0 | FK8: =AVERAGE(FK$3:FK$5) -> 0 | FL8: =AVERAGE(FL$3:FL$5) -> 0 | FN8: =AVERAGE(FN$3:FN$5) -> 0 | FO8: =AVERAGE(FO$3:FO$5) -> 0 | FP8: =AVERAGE(FP$3:FP$5) -> 0 | FQ8: =AVERAGE(FQ$3:FQ$5) -> 0 | FS8: =AVERAGE(FS$3:FS$5) -> 0 | FT8: =AVERAGE(FT$3:FT$5) -> 0 | FU8: =AVERAGE(FU$3:FU$5) -> 0 | FV8: =AVERAGE(FV$3:FV$5) -> 0 | FX8: =AVERAGE(FX$3:FX$5) -> 0 | FY8: =AVERAGE(FY$3:FY$5) -> 0 | FZ8: =AVERAGE(FZ$3:FZ$5) -> 0 | GA8: =AVERAGE(GA$3:GA$5) -> 0 | GC8: =AVERAGE(GC$3:GC$5) -> 0 | GD8: =AVERAGE(GD$3:GD$5) -> 0 | GE8: =AVERAGE(GE$3:GE$5) -> 0 | GF8: =AVERAGE(GF$3:GF$5) -> 0 | GH8: =AVERAGE(GH$3:GH$5) -> 0 | GI8: =AVERAGE(GI$3:GI$5) -> 0 | GJ8: =AVERAGE(GJ$3:GJ$5) -> 0 | GK8: =AVERAGE(GK$3:GK$5) -> 0 | GM8: =AVERAGE(GM$3:GM$5) -> 0 | GN8: =AVERAGE(GN$3:GN$5) -> 0 | GO8: =AVERAGE(GO$3:GO$5) -> 0 | GP8: =AVERAGE(GP$3:GP$5) -> 0 | GR8: =AVERAGE(GR$3:GR$5) -> 0 | GS8: =AVERAGE(GS$3:GS$5) -> 0 | GT8: =AVERAGE(GT$3:GT$5) -> 0 | GU8: =AVERAGE(GU$3:GU$5) -> 0 | GW8: =AVERAGE(GW$3:GW$5) -> 0 | GX8: =AVERAGE(GX$3:GX$5) -> 0 | GY8: =AVERAGE(GY$3:GY$5) -> 0 | GZ8: =AVERAGE(GZ$3:GZ$5) -> 0 | HB8: =AVERAGE(HB$3:HB$5) -> 0 | HC8: =AVERAGE(HC$3:HC$5) -> 0 | HD8: =AVERAGE(HD$3:HD$5) -> 0 | HE8: =AVERAGE(HE$3:HE$5) -> 0 | HG8: =AVERAGE(HG$3:HG$5) -> 0 | HH8: =AVERAGE(HH$3:HH$5) -> 0 | HI8: =AVERAGE(HI$3:HI$5) -> 0 | HJ8: =AVERAGE(HJ$3:HJ$5) -> 0 | HL8: =AVERAGE(HL$3:HL$5) -> 0 | HM8: =AVERAGE(HM$3:HM$5) -> 0 | HN8: =AVERAGE(HN$3:HN$5) -> 0 | HO8: =AVERAGE(HO$3:HO$5) -> 0 | HQ8: =AVERAGE(HQ$3:HQ$5) -> 0 | HR8: =AVERAGE(HR$3:HR$5) -> 0 | HS8: =AVERAGE(HS$3:HS$5) -> 0 | HT8: =AVERAGE(HT$3:HT$5) -> 0 | HU8: =AVERAGE(HU$3:HU$5) -> 0 | HV8: =AVERAGE(HV$3:HV$5) -> 0 | HW8: =AVERAGE(HW$3:HW$5) -> 0 | HX8: =AVERAGE(HX$3:HX$5) -> 0 | ... ID8: =AVERAGE(ID$3:ID$5) -> 0
A9: DEV | B9: =STDEV(B$3:B$5) -> 0 | C9: =STDEV(C$3:C$5) -> 0 | E9: =STDEV(E$3:E$5) -> 0 | F9: =STDEV(F$3:F$5) -> 0 | G9: =STDEV(G$3:G$5) -> 0 | H9: =STDEV(H$3:H$5) -> 0 | J9: =STDEV(J$3:J$5) -> 0 | K9: =STDEV(K$3:K$5) -> 0 | L9: =STDEV(L$3:L$5) -> 0 | M9: =STDEV(M$3:M$5) -> 0 | O9: =STDEV(O$3:O$5) -> 0 | P9: =STDEV(P$3:P$5) -> 0 | Q9: =STDEV(Q$3:Q$5) -> 0 | R9: =STDEV(R$3:R$5) -> 0 | T9: =STDEV(T$3:T$5) -> 0 | U9: =STDEV(U$3:U$5) -> 0 | V9: =STDEV(V$3:V$5) -> 0 | W9: =STDEV(W$3:W$5) -> 0 | Y9: =STDEV(Y$3:Y$5) -> 0 | Z9: =STDEV(Z$3:Z$5) -> 0 | AA9: =STDEV(AA$3:AA$5) -> 0 | AB9: =STDEV(AB$3:AB$5) -> 0 | AD9: =STDEV(AD$3:AD$5) -> 0 | AE9: =STDEV(AE$3:AE$5) -> 0 | AF9: =STDEV(AF$3:AF$5) -> 0 | AG9: =STDEV(AG$3:AG$5) -> 0 | AI9: =STDEV(AI$3:AI$5) -> 0 | AJ9: =STDEV(AJ$3:AJ$5) -> 0 | AK9: =STDEV(AK$3:AK$5) -> 0 | AL9: =STDEV(AL$3:AL$5) -> 0 | AN9: =STDEV(AN$3:AN$5) -> 0 | AO9: =STDEV(AO$3:AO$5) -> 0 | AP9: =STDEV(AP$3:AP$5) -> 0 | AQ9: =STDEV(AQ$3:AQ$5) -> 0 | AS9: =STDEV(AS$3:AS$5) -> 0 | AT9: =STDEV(AT$3:AT$5) -> 0 | AU9: =STDEV(AU$3:AU$5) -> 0 | AV9: =STDEV(AV$3:AV$5) -> 0 | AX9: =STDEV(AX$3:AX$5) -> 0 | AY9: =STDEV(AY$3:AY$5) -> 0 | AZ9: =STDEV(AZ$3:AZ$5) -> 0 | BA9: =STDEV(BA$3:BA$5) -> 0 | BC9: =STDEV(BC$3:BC$5) -> 0 | BD9: =STDEV(BD$3:BD$5) -> 0 | BE9: =STDEV(BE$3:BE$5) -> 0 | BF9: =STDEV(BF$3:BF$5) -> 0 | BH9: =STDEV(BH$3:BH$5) -> 0 | BI9: =STDEV(BI$3:BI$5) -> 0 | BJ9: =STDEV(BJ$3:BJ$5) -> 0 | BK9: =STDEV(BK$3:BK$5) -> 0 | BM9: =STDEV(BM$3:BM$5) -> 0 | BN9: =STDEV(BN$3:BN$5) -> 0 | BO9: =STDEV(BO$3:BO$5) -> 0 | BP9: =STDEV(BP$3:BP$5) -> 0 | BR9: =STDEV(BR$3:BR$5) -> 0 | BS9: =STDEV(BS$3:BS$5) -> 0 | BT9: =STDEV(BT$3:BT$5) -> 0 | BU9: =STDEV(BU$3:BU$5) -> 0 | BW9: =STDEV(BW$3:BW$5) -> 0 | BX9: =STDEV(BX$3:BX$5) -> 0 | BY9: =STDEV(BY$3:BY$5) -> 0 | BZ9: =STDEV(BZ$3:BZ$5) -> 0 | CB9: =STDEV(CB$3:CB$5) -> 0 | CC9: =STDEV(CC$3:CC$5) -> 0 | CD9: =STDEV(CD$3:CD$5) -> 0 | CE9: =STDEV(CE$3:CE$5) -> 0 | CG9: =STDEV(CG$3:CG$5) -> 0 | CH9: =STDEV(CH$3:CH$5) -> 0 | CI9: =STDEV(CI$3:CI$5) -> 0 | CJ9: =STDEV(CJ$3:CJ$5) -> 0 | CL9: =STDEV(CL$3:CL$5) -> 0 | CM9: =STDEV(CM$3:CM$5) -> 0 | CN9: =STDEV(CN$3:CN$5) -> 0 | CO9: =STDEV(CO$3:CO$5) -> 0 | CQ9: =STDEV(CQ$3:CQ$5) -> 0 | CR9: =STDEV(CR$3:CR$5) -> 0 | CS9: =STDEV(CS$3:CS$5) -> 0 | CT9: =STDEV(CT$3:CT$5) -> 0 | CV9: =STDEV(CV$3:CV$5) -> 0 | CW9: =STDEV(CW$3:CW$5) -> 0 | CX9: =STDEV(CX$3:CX$5) -> 0 | CY9: =STDEV(CY$3:CY$5) -> 0 | DA9: =STDEV(DA$3:DA$5) -> 0 | DB9: =STDEV(DB$3:DB$5) -> 0 | DC9: =STDEV(DC$3:DC$5) -> 0 | DD9: =STDEV(DD$3:DD$5) -> 0 | DF9: =STDEV(DF$3:DF$5) -> 0 | DG9: =STDEV(DG$3:DG$5) -> 0 | DH9: =STDEV(DH$3:DH$5) -> 0 | DI9: =STDEV(DI$3:DI$5) -> 0 | DK9: =STDEV(DK$3:DK$5) -> 0 | DL9: =STDEV(DL$3:DL$5) -> 0 | DM9: =STDEV(DM$3:DM$5) -> 0 | DN9: =STDEV(DN$3:DN$5) -> 0 | DP9: =STDEV(DP$3:DP$5) -> 0 | DQ9: =STDEV(DQ$3:DQ$5) -> 0 | DR9: =STDEV(DR$3:DR$5) -> 0 | DS9: =STDEV(DS$3:DS$5) -> 0 | DU9: =STDEV(DU$3:DU$5) -> 0 | DV9: =STDEV(DV$3:DV$5) -> 0 | DW9: =STDEV(DW$3:DW$5) -> 0 | DX9: =STDEV(DX$3:DX$5) -> 0 | DZ9: =STDEV(DZ$3:DZ$5) -> 0 | EA9: =STDEV(EA$3:EA$5) -> 0 | EB9: =STDEV(EB$3:EB$5) -> 0 | EC9: =STDEV(EC$3:EC$5) -> 0 | EE9: =STDEV(EE$3:EE$5) -> 0 | EF9: =STDEV(EF$3:EF$5) -> 0 | EG9: =STDEV(EG$3:EG$5) -> 0 | EH9: =STDEV(EH$3:EH$5) -> 0 | EJ9: =STDEV(EJ$3:EJ$5) -> 0 | EK9: =STDEV(EK$3:EK$5) -> 0 | EL9: =STDEV(EL$3:EL$5) -> 0 | EM9: =STDEV(EM$3:EM$5) -> 0 | EO9: =STDEV(EO$3:EO$5) -> 0 | EP9: =STDEV(EP$3:EP$5) -> 0 | EQ9: =STDEV(EQ$3:EQ$5) -> 0 | ER9: =STDEV(ER$3:ER$5) -> 0 | ET9: =STDEV(ET$3:ET$5) -> 0 | EU9: =STDEV(EU$3:EU$5) -> 0 | EV9: =STDEV(EV$3:EV$5) -> 0 | EW9: =STDEV(EW$3:EW$5) -> 0 | EY9: =STDEV(EY$3:EY$5) -> 0 | EZ9: =STDEV(EZ$3:EZ$5) -> 0 | FA9: =STDEV(FA$3:FA$5) -> 0 | FB9: =STDEV(FB$3:FB$5) -> 0 | FD9: =STDEV(FD$3:FD$5) -> 0 | FE9: =STDEV(FE$3:FE$5) -> 0 | FF9: =STDEV(FF$3:FF$5) -> 0 | FG9: =STDEV(FG$3:FG$5) -> 0 | FI9: =STDEV(FI$3:FI$5) -> 0 | FJ9: =STDEV(FJ$3:FJ$5) -> 0 | FK9: =STDEV(FK$3:FK$5) -> 0 | FL9: =STDEV(FL$3:FL$5) -> 0 | FN9: =STDEV(FN$3:FN$5) -> 0 | FO9: =STDEV(FO$3:FO$5) -> 0 | FP9: =STDEV(FP$3:FP$5) -> 0 | FQ9: =STDEV(FQ$3:FQ$5) -> 0 | FS9: =STDEV(FS$3:FS$5) -> 0 | FT9: =STDEV(FT$3:FT$5) -> 0 | FU9: =STDEV(FU$3:FU$5) -> 0 | FV9: =STDEV(FV$3:FV$5) -> 0 | FX9: =STDEV(FX$3:FX$5) -> 0 | FY9: =STDEV(FY$3:FY$5) -> 0 | FZ9: =STDEV(FZ$3:FZ$5) -> 0 | GA9: =STDEV(GA$3:GA$5) -> 0 | GC9: =STDEV(GC$3:GC$5) -> 0 | GD9: =STDEV(GD$3:GD$5) -> 0 | GE9: =STDEV(GE$3:GE$5) -> 0 | GF9: =STDEV(GF$3:GF$5) -> 0 | GH9: =STDEV(GH$3:GH$5) -> 0 | GI9: =STDEV(GI$3:GI$5) -> 0 | GJ9: =STDEV(GJ$3:GJ$5) -> 0 | GK9: =STDEV(GK$3:GK$5) -> 0 | GM9: =STDEV(GM$3:GM$5) -> 0 | GN9: =STDEV(GN$3:GN$5) -> 0 | GO9: =STDEV(GO$3:GO$5) -> 0 | GP9: =STDEV(GP$3:GP$5) -> 0 | GR9: =STDEV(GR$3:GR$5) -> 0 | GS9: =STDEV(GS$3:GS$5) -> 0 | GT9: =STDEV(GT$3:GT$5) -> 0 | GU9: =STDEV(GU$3:GU$5) -> 0 | GW9: =STDEV(GW$3:GW$5) -> 0 | GX9: =STDEV(GX$3:GX$5) -> 0 | GY9: =STDEV(GY$3:GY$5) -> 0 | GZ9: =STDEV(GZ$3:GZ$5) -> 0 | HB9: =STDEV(HB$3:HB$5) -> 0 | HC9: =STDEV(HC$3:HC$5) -> 0 | HD9: =STDEV(HD$3:HD$5) -> 0 | HE9: =STDEV(HE$3:HE$5) -> 0 | HG9: =STDEV(HG$3:HG$5) -> 0 | HH9: =STDEV(HH$3:HH$5) -> 0 | HI9: =STDEV(HI$3:HI$5) -> 0 | HJ9: =STDEV(HJ$3:HJ$5) -> 0 | HL9: =STDEV(HL$3:HL$5) -> 0 | HM9: =STDEV(HM$3:HM$5) -> 0 | HN9: =STDEV(HN$3:HN$5) -> 0 | HO9: =STDEV(HO$3:HO$5) -> 0 | HQ9: =STDEV(HQ$3:HQ$5) -> 0 | HR9: =STDEV(HR$3:HR$5) -> 0 | HS9: =STDEV(HS$3:HS$5) -> 0 | HT9: =STDEV(HT$3:HT$5) -> 0 | HU9: =STDEV(HU$3:HU$5) -> 0 | HV9: =STDEV(HV$3:HV$5) -> 0 | HW9: =STDEV(HW$3:HW$5) -> 0 | HX9: =STDEV(HX$3:HX$5) -> 0 | ... ID9: =STDEV(ID$3:ID$5) -> 0
A10: DST | B10: =SUMPRODUCT(--(B$3:B$5-$HS$3:$HS$5)^2)^0.5 -> 0 | C10: =SUMPRODUCT(--(C$3:C$5-$HT$3:$HT$5)^2)^0.5 -> 0 | E10: =SUMPRODUCT(--(E$3:E$5-$HU$3:$HU$5)^2)^0.5 -> 0 | F10: =SUMPRODUCT(--(F$3:F$5-$HV$3:$HV$5)^2)^0.5 -> 0 | G10: =SUMPRODUCT(--(G$3:G$5-$HS$3:$HS$5)^2)^0.5 -> 0 | H10: =SUMPRODUCT(--(H$3:H$5-$HT$3:$HT$5)^2)^0.5 -> 0 | J10: =SUMPRODUCT(--(J$3:J$5-$HU$3:$HU$5)^2)^0.5 -> 0 | K10: =SUMPRODUCT(--(K$3:K$5-$HV$3:$HV$5)^2)^0.5 -> 0 | L10: =SUMPRODUCT(--(L$3:L$5-$HS$3:$HS$5)^2)^0.5 -> 0 | M10: =SUMPRODUCT(--(M$3:M$5-$HT$3:$HT$5)^2)^0.5 -> 0 | O10: =SUMPRODUCT(--(O$3:O$5-$HU$3:$HU$5)^2)^0.5 -> 0 | P10: =SUMPRODUCT(--(P$3:P$5-$HV$3:$HV$5)^2)^0.5 -> 0 | Q10: =SUMPRODUCT(--(Q$3:Q$5-$HS$3:$HS$5)^2)^0.5 -> 0 | R10: =SUMPRODUCT(--(R$3:R$5-$HT$3:$HT$5)^2)^0.5 -> 0 | T10: =SUMPRODUCT(--(T$3:T$5-$HU$3:$HU$5)^2)^0.5 -> 0 | U10: =SUMPRODUCT(--(U$3:U$5-$HV$3:$HV$5)^2)^0.5 -> 0 | V10: =SUMPRODUCT(--(V$3:V$5-$HS$3:$HS$5)^2)^0.5 -> 0 | W10: =SUMPRODUCT(--(W$3:W$5-$HT$3:$HT$5)^2)^0.5 -> 0 | Y10: =SUMPRODUCT(--(Y$3:Y$5-$HU$3:$HU$5)^2)^0.5 -> 0 | Z10: =SUMPRODUCT(--(Z$3:Z$5-$HV$3:$HV$5)^2)^0.5 -> 0 | AA10: =SUMPRODUCT(--(AA$3:AA$5-$HS$3:$HS$5)^2)^0.5 -> 0 | AB10: =SUMPRODUCT(--(AB$3:AB$5-$HT$3:$HT$5)^2)^0.5 -> 0 | AD10: =SUMPRODUCT(--(AD$3:AD$5-$HU$3:$HU$5)^2)^0.5 -> 0 | AE10: =SUMPRODUCT(--(AE$3:AE$5-$HV$3:$HV$5)^2)^0.5 -> 0 | AF10: =SUMPRODUCT(--(AF$3:AF$5-$HS$3:$HS$5)^2)^0.5 -> 0 | AG10: =SUMPRODUCT(--(AG$3:AG$5-$HT$3:$HT$5)^2)^0.5 -> 0 | AI10: =SUMPRODUCT(--(AI$3:AI$5-$HU$3:$HU$5)^2)^0.5 -> 0 | AJ10: =SUMPRODUCT(--(AJ$3:AJ$5-$HV$3:$HV$5)^2)^0.5 -> 0 | AK10: =SUMPRODUCT(--(AK$3:AK$5-$HS$3:$HS$5)^2)^0.5 -> 0 | AL10: =SUMPRODUCT(--(AL$3:AL$5-$HT$3:$HT$5)^2)^0.5 -> 0 | AN10: =SUMPRODUCT(--(AN$3:AN$5-$HU$3:$HU$5)^2)^0.5 -> 0 | AO10: =SUMPRODUCT(--(AO$3:AO$5-$HV$3:$HV$5)^2)^0.5 -> 0 | AP10: =SUMPRODUCT(--(AP$3:AP$5-$HS$3:$HS$5)^2)^0.5 -> 0 | AQ10: =SUMPRODUCT(--(AQ$3:AQ$5-$HT$3:$HT$5)^2)^0.5 -> 0 | AS10: =SUMPRODUCT(--(AS$3:AS$5-$HU$3:$HU$5)^2)^0.5 -> 0 | AT10: =SUMPRODUCT(--(AT$3:AT$5-$HV$3:$HV$5)^2)^0.5 -> 0 | AU10: =SUMPRODUCT(--(AU$3:AU$5-$HS$3:$HS$5)^2)^0.5 -> 0 | AV10: =SUMPRODUCT(--(AV$3:AV$5-$HT$3:$HT$5)^2)^0.5 -> 0 | AX10: =SUMPRODUCT(--(AX$3:AX$5-$HU$3:$HU$5)^2)^0.5 -> 0 | AY10: =SUMPRODUCT(--(AY$3:AY$5-$HV$3:$HV$5)^2)^0.5 -> 0 | AZ10: =SUMPRODUCT(--(AZ$3:AZ$5-$HS$3:$HS$5)^2)^0.5 -> 0 | BA10: =SUMPRODUCT(--(BA$3:BA$5-$HT$3:$HT$5)^2)^0.5 -> 0 | BC10: =SUMPRODUCT(--(BC$3:BC$5-$HU$3:$HU$5)^2)^0.5 -> 0 | BD10: =SUMPRODUCT(--(BD$3:BD$5-$HV$3:$HV$5)^2)^0.5 -> 0 | BE10: =SUMPRODUCT(--(BE$3:BE$5-$HS$3:$HS$5)^2)^0.5 -> 0 | BF10: =SUMPRODUCT(--(BF$3:BF$5-$HT$3:$HT$5)^2)^0.5 -> 0 | BH10: =SUMPRODUCT(--(BH$3:BH$5-$HU$3:$HU$5)^2)^0.5 -> 0 | BI10: =SUMPRODUCT(--(BI$3:BI$5-$HV$3:$HV$5)^2)^0.5 -> 0 | BJ10: =SUMPRODUCT(--(BJ$3:BJ$5-$HS$3:$HS$5)^2)^0.5 -> 0 | BK10: =SUMPRODUCT(--(BK$3:BK$5-$HT$3:$HT$5)^2)^0.5 -> 0 | BM10: =SUMPRODUCT(--(BM$3:BM$5-$HU$3:$HU$5)^2)^0.5 -> 0 | BN10: =SUMPRODUCT(--(BN$3:BN$5-$HV$3:$HV$5)^2)^0.5 -> 0 | BO10: =SUMPRODUCT(--(BO$3:BO$5-$HS$3:$HS$5)^2)^0.5 -> 0 | BP10: =SUMPRODUCT(--(BP$3:BP$5-$HT$3:$HT$5)^2)^0.5 -> 0 | BR10: =SUMPRODUCT(--(BR$3:BR$5-$HU$3:$HU$5)^2)^0.5 -> 0 | BS10: =SUMPRODUCT(--(BS$3:BS$5-$HV$3:$HV$5)^2)^0.5 -> 0 | BT10: =SUMPRODUCT(--(BT$3:BT$5-$HS$3:$HS$5)^2)^0.5 -> 0 | BU10: =SUMPRODUCT(--(BU$3:BU$5-$HT$3:$HT$5)^2)^0.5 -> 0 | BW10: =SUMPRODUCT(--(BW$3:BW$5-$HU$3:$HU$5)^2)^0.5 -> 0 | BX10: =SUMPRODUCT(--(BX$3:BX$5-$HV$3:$HV$5)^2)^0.5 -> 0 | BY10: =SUMPRODUCT(--(BY$3:BY$5-$HS$3:$HS$5)^2)^0.5 -> 0 | BZ10: =SUMPRODUCT(--(BZ$3:BZ$5-$HT$3:$HT$5)^2)^0.5 -> 0 | CB10: =SUMPRODUCT(--(CB$3:CB$5-$HU$3:$HU$5)^2)^0.5 -> 0 | CC10: =SUMPRODUCT(--(CC$3:CC$5-$HV$3:$HV$5)^2)^0.5 -> 0 | CD10: =SUMPRODUCT(--(CD$3:CD$5-$HS$3:$HS$5)^2)^0.5 -> 0 | CE10: =SUMPRODUCT(--(CE$3:CE$5-$HT$3:$HT$5)^2)^0.5 -> 0 | CG10: =SUMPRODUCT(--(CG$3:CG$5-$HU$3:$HU$5)^2)^0.5 -> 0 | CH10: =SUMPRODUCT(--(CH$3:CH$5-$HV$3:$HV$5)^2)^0.5 -> 0 | CI10: =SUMPRODUCT(--(CI$3:CI$5-$HS$3:$HS$5)^2)^0.5 -> 0 | CJ10: =SUMPRODUCT(--(CJ$3:CJ$5-$HT$3:$HT$5)^2)^0.5 -> 0 | CL10: =SUMPRODUCT(--(CL$3:CL$5-$HU$3:$HU$5)^2)^0.5 -> 0 | CM10: =SUMPRODUCT(--(CM$3:CM$5-$HV$3:$HV$5)^2)^0.5 -> 0 | CN10: =SUMPRODUCT(--(CN$3:CN$5-$HS$3:$HS$5)^2)^0.5 -> 0 | CO10: =SUMPRODUCT(--(CO$3:CO$5-$HT$3:$HT$5)^2)^0.5 -> 0 | CQ10: =SUMPRODUCT(--(CQ$3:CQ$5-$HU$3:$HU$5)^2)^0.5 -> 0 | CR10: =SUMPRODUCT(--(CR$3:CR$5-$HV$3:$HV$5)^2)^0.5 -> 0 | CS10: =SUMPRODUCT(--(CS$3:CS$5-$HS$3:$HS$5)^2)^0.5 -> 0 | CT10: =SUMPRODUCT(--(CT$3:CT$5-$HT$3:$HT$5)^2)^0.5 -> 0 | CV10: =SUMPRODUCT(--(CV$3:CV$5-$HU$3:$HU$5)^2)^0.5 -> 0 | CW10: =SUMPRODUCT(--(CW$3:CW$5-$HV$3:$HV$5)^2)^0.5 -> 0 | CX10: =SUMPRODUCT(--(CX$3:CX$5-$HS$3:$HS$5)^2)^0.5 -> 0 | CY10: =SUMPRODUCT(--(CY$3:CY$5-$HT$3:$HT$5)^2)^0.5 -> 0 | DA10: =SUMPRODUCT(--(DA$3:DA$5-$HU$3:$HU$5)^2)^0.5 -> 0 | DB10: =SUMPRODUCT(--(DB$3:DB$5-$HV$3:$HV$5)^2)^0.5 -> 0 | DC10: =SUMPRODUCT(--(DC$3:DC$5-$HS$3:$HS$5)^2)^0.5 -> 0 | DD10: =SUMPRODUCT(--(DD$3:DD$5-$HT$3:$HT$5)^2)^0.5 -> 0 | DF10: =SUMPRODUCT(--(DF$3:DF$5-$HU$3:$HU$5)^2)^0.5 -> 0 | DG10: =SUMPRODUCT(--(DG$3:DG$5-$HV$3:$HV$5)^2)^0.5 -> 0 | DH10: =SUMPRODUCT(--(DH$3:DH$5-$HS$3:$HS$5)^2)^0.5 -> 0 | DI10: =SUMPRODUCT(--(DI$3:DI$5-$HT$3:$HT$5)^2)^0.5 -> 0 | DK10: =SUMPRODUCT(--(DK$3:DK$5-$HU$3:$HU$5)^2)^0.5 -> 0 | DL10: =SUMPRODUCT(--(DL$3:DL$5-$HV$3:$HV$5)^2)^0.5 -> 0 | DM10: =SUMPRODUCT(--(DM$3:DM$5-$HS$3:$HS$5)^2)^0.5 -> 0 | DN10: =SUMPRODUCT(--(DN$3:DN$5-$HT$3:$HT$5)^2)^0.5 -> 0 | DP10: =SUMPRODUCT(--(DP$3:DP$5-$HU$3:$HU$5)^2)^0.5 -> 0 | DQ10: =SUMPRODUCT(--(DQ$3:DQ$5-$HV$3:$HV$5)^2)^0.5 -> 0 | DR10: =SUMPRODUCT(--(DR$3:DR$5-$HS$3:$HS$5)^2)^0.5 -> 0 | DS10: =SUMPRODUCT(--(DS$3:DS$5-$HT$3:$HT$5)^2)^0.5 -> 0 | DU10: =SUMPRODUCT(--(DU$3:DU$5-$HU$3:$HU$5)^2)^0.5 -> 0 | DV10: =SUMPRODUCT(--(DV$3:DV$5-$HV$3:$HV$5)^2)^0.5 -> 0 | DW10: =SUMPRODUCT(--(DW$3:DW$5-$HS$3:$HS$5)^2)^0.5 -> 0 | DX10: =SUMPRODUCT(--(DX$3:DX$5-$HT$3:$HT$5)^2)^0.5 -> 0 | DZ10: =SUMPRODUCT(--(DZ$3:DZ$5-$HU$3:$HU$5)^2)^0.5 -> 0 | EA10: =SUMPRODUCT(--(EA$3:EA$5-$HV$3:$HV$5)^2)^0.5 -> 0 | EB10: =SUMPRODUCT(--(EB$3:EB$5-$HS$3:$HS$5)^2)^0.5 -> 0 | EC10: =SUMPRODUCT(--(EC$3:EC$5-$HT$3:$HT$5)^2)^0.5 -> 0 | EE10: =SUMPRODUCT(--(EE$3:EE$5-$HU$3:$HU$5)^2)^0.5 -> 0 | EF10: =SUMPRODUCT(--(EF$3:EF$5-$HV$3:$HV$5)^2)^0.5 -> 0 | EG10: =SUMPRODUCT(--(EG$3:EG$5-$HS$3:$HS$5)^2)^0.5 -> 0 | EH10: =SUMPRODUCT(--(EH$3:EH$5-$HT$3:$HT$5)^2)^0.5 -> 0 | EJ10: =SUMPRODUCT(--(EJ$3:EJ$5-$HU$3:$HU$5)^2)^0.5 -> 0 | EK10: =SUMPRODUCT(--(EK$3:EK$5-$HV$3:$HV$5)^2)^0.5 -> 0 | EL10: =SUMPRODUCT(--(EL$3:EL$5-$HS$3:$HS$5)^2)^0.5 -> 0 | EM10: =SUMPRODUCT(--(EM$3:EM$5-$HT$3:$HT$5)^2)^0.5 -> 0 | EO10: =SUMPRODUCT(--(EO$3:EO$5-$HU$3:$HU$5)^2)^0.5 -> 0 | EP10: =SUMPRODUCT(--(EP$3:EP$5-$HV$3:$HV$5)^2)^0.5 -> 0 | EQ10: =SUMPRODUCT(--(EQ$3:EQ$5-$HS$3:$HS$5)^2)^0.5 -> 0 | ER10: =SUMPRODUCT(--(ER$3:ER$5-$HT$3:$HT$5)^2)^0.5 -> 0 | ET10: =SUMPRODUCT(--(ET$3:ET$5-$HU$3:$HU$5)^2)^0.5 -> 0 | EU10: =SUMPRODUCT(--(EU$3:EU$5-$HV$3:$HV$5)^2)^0.5 -> 0 | EV10: =SUMPRODUCT(--(EV$3:EV$5-$HS$3:$HS$5)^2)^0.5 -> 0 | EW10: =SUMPRODUCT(--(EW$3:EW$5-$HT$3:$HT$5)^2)^0.5 -> 0 | EY10: =SUMPRODUCT(--(EY$3:EY$5-$HU$3:$HU$5)^2)^0.5 -> 0 | EZ10: =SUMPRODUCT(--(EZ$3:EZ$5-$HV$3:$HV$5)^2)^0.5 -> 0 | FA10: =SUMPRODUCT(--(FA$3:FA$5-$HS$3:$HS$5)^2)^0.5 -> 0 | FB10: =SUMPRODUCT(--(FB$3:FB$5-$HT$3:$HT$5)^2)^0.5 -> 0 | FD10: =SUMPRODUCT(--(FD$3:FD$5-$HU$3:$HU$5)^2)^0.5 -> 0 | FE10: =SUMPRODUCT(--(FE$3:FE$5-$HV$3:$HV$5)^2)^0.5 -> 0 | FF10: =SUMPRODUCT(--(FF$3:FF$5-$HS$3:$HS$5)^2)^0.5 -> 0 | FG10: =SUMPRODUCT(--(FG$3:FG$5-$HT$3:$HT$5)^2)^0.5 -> 0 | FI10: =SUMPRODUCT(--(FI$3:FI$5-$HU$3:$HU$5)^2)^0.5 -> 0 | FJ10: =SUMPRODUCT(--(FJ$3:FJ$5-$HV$3:$HV$5)^2)^0.5 -> 0 | FK10: =SUMPRODUCT(--(FK$3:FK$5-$HS$3:$HS$5)^2)^0.5 -> 0 | FL10: =SUMPRODUCT(--(FL$3:FL$5-$HT$3:$HT$5)^2)^0.5 -> 0 | FN10: =SUMPRODUCT(--(FN$3:FN$5-$HU$3:$HU$5)^2)^0.5 -> 0 | FO10: =SUMPRODUCT(--(FO$3:FO$5-$HV$3:$HV$5)^2)^0.5 -> 0 | FP10: =SUMPRODUCT(--(FP$3:FP$5-$HS$3:$HS$5)^2)^0.5 -> 0 | FQ10: =SUMPRODUCT(--(FQ$3:FQ$5-$HT$3:$HT$5)^2)^0.5 -> 0 | FS10: =SUMPRODUCT(--(FS$3:FS$5-$HU$3:$HU$5)^2)^0.5 -> 0 | FT10: =SUMPRODUCT(--(FT$3:FT$5-$HV$3:$HV$5)^2)^0.5 -> 0 | FU10: =SUMPRODUCT(--(FU$3:FU$5-$HS$3:$HS$5)^2)^0.5 -> 0 | FV10: =SUMPRODUCT(--(FV$3:FV$5-$HT$3:$HT$5)^2)^0.5 -> 0 | FX10: =SUMPRODUCT(--(FX$3:FX$5-$HU$3:$HU$5)^2)^0.5 -> 0 | FY10: =SUMPRODUCT(--(FY$3:FY$5-$HV$3:$HV$5)^2)^0.5 -> 0 | FZ10: =SUMPRODUCT(--(FZ$3:FZ$5-$HS$3:$HS$5)^2)^0.5 -> 0 | GA10: =SUMPRODUCT(--(GA$3:GA$5-$HT$3:$HT$5)^2)^0.5 -> 0 | GC10: =SUMPRODUCT(--(GC$3:GC$5-$HU$3:$HU$5)^2)^0.5 -> 0 | GD10: =SUMPRODUCT(--(GD$3:GD$5-$HV$3:$HV$5)^2)^0.5 -> 0 | GE10: =SUMPRODUCT(--(GE$3:GE$5-$HS$3:$HS$5)^2)^0.5 -> 0 | GF10: =SUMPRODUCT(--(GF$3:GF$5-$HT$3:$HT$5)^2)^0.5 -> 0 | GH10: =SUMPRODUCT(--(GH$3:GH$5-$HU$3:$HU$5)^2)^0.5 -> 0 | GI10: =SUMPRODUCT(--(GI$3:GI$5-$HV$3:$HV$5)^2)^0.5 -> 0 | GJ10: =SUMPRODUCT(--(GJ$3:GJ$5-$HS$3:$HS$5)^2)^0.5 -> 0 | GK10: =SUMPRODUCT(--(GK$3:GK$5-$HT$3:$HT$5)^2)^0.5 -> 0 | GM10: =SUMPRODUCT(--(GM$3:GM$5-$HU$3:$HU$5)^2)^0.5 -> 0 | GN10: =SUMPRODUCT(--(GN$3:GN$5-$HV$3:$HV$5)^2)^0.5 -> 0 | GO10: =SUMPRODUCT(--(GO$3:GO$5-$HS$3:$HS$5)^2)^0.5 -> 0 | GP10: =SUMPRODUCT(--(GP$3:GP$5-$HT$3:$HT$5)^2)^0.5 -> 0 | GR10: =SUMPRODUCT(--(GR$3:GR$5-$HU$3:$HU$5)^2)^0.5 -> 0 | GS10: =SUMPRODUCT(--(GS$3:GS$5-$HV$3:$HV$5)^2)^0.5 -> 0 | GT10: =SUMPRODUCT(--(GT$3:GT$5-$HS$3:$HS$5)^2)^0.5 -> 0 | GU10: =SUMPRODUCT(--(GU$3:GU$5-$HT$3:$HT$5)^2)^0.5 -> 0 | GW10: =SUMPRODUCT(--(GW$3:GW$5-$HU$3:$HU$5)^2)^0.5 -> 0 | GX10: =SUMPRODUCT(--(GX$3:GX$5-$HV$3:$HV$5)^2)^0.5 -> 0 | GY10: =SUMPRODUCT(--(GY$3:GY$5-$HS$3:$HS$5)^2)^0.5 -> 0 | GZ10: =SUMPRODUCT(--(GZ$3:GZ$5-$HT$3:$HT$5)^2)^0.5 -> 0 | HB10: =SUMPRODUCT(--(HB$3:HB$5-$HU$3:$HU$5)^2)^0.5 -> 0 | HC10: =SUMPRODUCT(--(HC$3:HC$5-$HV$3:$HV$5)^2)^0.5 -> 0 | HD10: =SUMPRODUCT(--(HD$3:HD$5-$HS$3:$HS$5)^2)^0.5 -> 0 | HE10: =SUMPRODUCT(--(HE$3:HE$5-$HT$3:$HT$5)^2)^0.5 -> 0 | HG10: =SUMPRODUCT(--(HG$3:HG$5-$HU$3:$HU$5)^2)^0.5 -> 0 | HH10: =SUMPRODUCT(--(HH$3:HH$5-$HV$3:$HV$5)^2)^0.5 -> 0 | HI10: =SUMPRODUCT(--(HI$3:HI$5-$HS$3:$HS$5)^2)^0.5 -> 0 | HJ10: =SUMPRODUCT(--(HJ$3:HJ$5-$HT$3:$HT$5)^2)^0.5 -> 0 | HL10: =SUMPRODUCT(--(HL$3:HL$5-$HU$3:$HU$5)^2)^0.5 -> 0 | HM10: =SUMPRODUCT(--(HM$3:HM$5-$HV$3:$HV$5)^2)^0.5 -> 0 | HN10: =SUMPRODUCT(--(HN$3:HN$5-$HS$3:$HS$5)^2)^0.5 -> 0 | HO10: =SUMPRODUCT(--(HO$3:HO$5-$HT$3:$HT$5)^2)^0.5 -> 0 | HQ10: =SUMPRODUCT(--(HQ$3:HQ$5-$HU$3:$HU$5)^2)^0.5 -> 0 | HR10: =SUMPRODUCT(--(HR$3:HR$5-$HV$3:$HV$5)^2)^0.5 -> 0
