Workbook

Sheet Instances
B1: memelingo-1/goal_mlp-tplp-ht | I1: memelingo-1/goal_mlp-tplp-htc | P1: memelingo-1/goal_mlp-tplp-htcdl | W1: min | AC1: median | AI1: max
B2: time | C2: stime | D2: status | E2: rules | F2: ctime | G2: fmtime | H2: memout | I2: time | J2: stime | K2: status | L2: rules | M2: ctime | N2: fmtime | O2: memout | P2: time | Q2: stime | R2: status | S2: rules | T2: ctime | U2: fmtime | V2: memout | W2: time | X2: stime | Y2: rules | Z2: ctime | AA2: fmtime | AB2: memout | AC2: time | AD2: stime | AE2: rules | AF2: ctime | AG2: fmtime | AH2: memout | AI2: time | AJ2: stime | AK2: rules | AL2: ctime | AM2: fmtime | AN2: memout
A3: instances/size-1 | B3: 1.62 | C3: 0.1 | D3: SATISFIABLE | E3: 376977 | F3: 0.755 | G3: 0.02 | H3: 0 | I3: 0.97 | J3: 0 | K3: SATISFIABLE | L3: 2407 | M3: 0.104 | N3: 0 | O3: 0 | P3: 1.01 | Q3: 0 | R3: SATISFIABLE | S3: 2407 | T3: 0.095 | U3: 0 | V3: 0 | W3: =MIN($B3,$I3,$P3) -> 0 | X3: =MIN($C3,$J3,$Q3) -> 0 | Y3: =MIN($E3,$L3,$S3) -> 0 | Z3: =MIN($F3,$M3,$T3) -> 0 | AA3: =MIN($G3,$N3,$U3) -> 0 | AB3: =MIN($H3,$O3,$V3) -> 0 | AC3: =MEDIAN($B3,$I3,$P3) -> 0 | AD3: =MEDIAN($C3,$J3,$Q3) -> 0 | AE3: =MEDIAN($E3,$L3,$S3) -> 0 | AF3: =MEDIAN($F3,$M3,$T3) -> 0 | AG3: =MEDIAN($G3,$N3,$U3) -> 0 | AH3: =MEDIAN($H3,$O3,$V3) -> 0 | AI3: =MAX($B3,$I3,$P3) -> 0 | AJ3: =MAX($C3,$J3,$Q3) -> 0 | AK3: =MAX($E3,$L3,$S3) -> 0 | AL3: =MAX($F3,$M3,$T3) -> 0 | AM3: =MAX($G3,$N3,$U3) -> 0 | AN3: =MAX($H3,$O3,$V3) -> 0
A4: instances/size-10 | B4: 1200 | H4: 0 | I4: 1.03 | J4: 0.01 | K4: SATISFIABLE | L4: 2407 | M4: 0.114 | N4: 0 | O4: 0 | P4: 1.02 | Q4: 0 | R4: SATISFIABLE | S4: 2407 | T4: 0.104 | U4: 0 | V4: 0 | W4: =MIN($B4,$I4,$P4) -> 0 | X4: =MIN($C4,$J4,$Q4) -> 0 | Y4: =MIN($E4,$L4,$S4) -> 0 | Z4: =MIN($F4,$M4,$T4) -> 0 | AA4: =MIN($G4,$N4,$U4) -> 0 | AB4: =MIN($H4,$O4,$V4) -> 0 | AC4: =MEDIAN($B4,$I4,$P4) -> 0 | AD4: =MEDIAN($C4,$J4,$Q4) -> 0 | AE4: =MEDIAN($E4,$L4,$S4) -> 0 | AF4: =MEDIAN($F4,$M4,$T4) -> 0 | AG4: =MEDIAN($G4,$N4,$U4) -> 0 | AH4: =MEDIAN($H4,$O4,$V4) -> 0 | AI4: =MAX($B4,$I4,$P4) -> 0 | AJ4: =MAX($C4,$J4,$Q4) -> 0 | AK4: =MAX($E4,$L4,$S4) -> 0 | AL4: =MAX($F4,$M4,$T4) -> 0 | AM4: =MAX($G4,$N4,$U4) -> 0 | AN4: =MAX($H4,$O4,$V4) -> 0
A5: instances/size-2 | B5: 13.43 | C5: 9.37 | D5: SATISFIABLE | E5: 1516817 | F5: 12.53 | G5: 0.26 | H5: 0 | I5: 1.01 | J5: 0 | K5: SATISFIABLE | L5: 2407 | M5: 0.111 | N5: 0 | O5: 0 | P5: 1.04 | Q5: 0 | R5: SATISFIABLE | S5: 2407 | T5: 0.091 | U5: 0 | V5: 0 | W5: =MIN($B5,$I5,$P5) -> 0 | X5: =MIN($C5,$J5,$Q5) -> 0 | Y5: =MIN($E5,$L5,$S5) -> 0 | Z5: =MIN($F5,$M5,$T5) -> 0 | AA5: =MIN($G5,$N5,$U5) -> 0 | AB5: =MIN($H5,$O5,$V5) -> 0 | AC5: =MEDIAN($B5,$I5,$P5) -> 0 | AD5: =MEDIAN($C5,$J5,$Q5) -> 0 | AE5: =MEDIAN($E5,$L5,$S5) -> 0 | AF5: =MEDIAN($F5,$M5,$T5) -> 0 | AG5: =MEDIAN($G5,$N5,$U5) -> 0 | AH5: =MEDIAN($H5,$O5,$V5) -> 0 | AI5: =MAX($B5,$I5,$P5) -> 0 | AJ5: =MAX($C5,$J5,$Q5) -> 0 | AK5: =MAX($E5,$L5,$S5) -> 0 | AL5: =MAX($F5,$M5,$T5) -> 0 | AM5: =MAX($G5,$N5,$U5) -> 0 | AN5: =MAX($H5,$O5,$V5) -> 0
A6: instances/size-3 | B6: 39.91 | C6: 30.87 | D6: SATISFIABLE | E6: 3421857 | F6: 38.964 | G6: 0.79 | H6: 0 | I6: 0.9 | J6: 0 | K6: SATISFIABLE | L6: 2407 | M6: 0.106 | N6: 0 | O6: 0 | P6: 0.98 | Q6: 0 | R6: SATISFIABLE | S6: 2407 | T6: 0.091 | U6: 0 | V6: 0 | W6: =MIN($B6,$I6,$P6) -> 0 | X6: =MIN($C6,$J6,$Q6) -> 0 | Y6: =MIN($E6,$L6,$S6) -> 0 | Z6: =MIN($F6,$M6,$T6) -> 0 | AA6: =MIN($G6,$N6,$U6) -> 0 | AB6: =MIN($H6,$O6,$V6) -> 0 | AC6: =MEDIAN($B6,$I6,$P6) -> 0 | AD6: =MEDIAN($C6,$J6,$Q6) -> 0 | AE6: =MEDIAN($E6,$L6,$S6) -> 0 | AF6: =MEDIAN($F6,$M6,$T6) -> 0 | AG6: =MEDIAN($G6,$N6,$U6) -> 0 | AH6: =MEDIAN($H6,$O6,$V6) -> 0 | AI6: =MAX($B6,$I6,$P6) -> 0 | AJ6: =MAX($C6,$J6,$Q6) -> 0 | AK6: =MAX($E6,$L6,$S6) -> 0 | AL6: =MAX($F6,$M6,$T6) -> 0 | AM6: =MAX($G6,$N6,$U6) -> 0 | AN6: =MAX($H6,$O6,$V6) -> 0
A7: instances/size-4 | B7: 42.24 | C7: 25.35 | D7: SATISFIABLE | E7: 6092097 | F7: 41.066 | G7: 1.9 | H7: 0 | I7: 0.98 | J7: 0 | K7: SATISFIABLE | L7: 2407 | M7: 0.102 | N7: 0 | O7: 0 | P7: 0.99 | Q7: 0 | R7: SATISFIABLE | S7: 2407 | T7: 0.092 | U7: 0 | V7: 0 | W7: =MIN($B7,$I7,$P7) -> 0 | X7: =MIN($C7,$J7,$Q7) -> 0 | Y7: =MIN($E7,$L7,$S7) -> 0 | Z7: =MIN($F7,$M7,$T7) -> 0 | AA7: =MIN($G7,$N7,$U7) -> 0 | AB7: =MIN($H7,$O7,$V7) -> 0 | AC7: =MEDIAN($B7,$I7,$P7) -> 0 | AD7: =MEDIAN($C7,$J7,$Q7) -> 0 | AE7: =MEDIAN($E7,$L7,$S7) -> 0 | AF7: =MEDIAN($F7,$M7,$T7) -> 0 | AG7: =MEDIAN($G7,$N7,$U7) -> 0 | AH7: =MEDIAN($H7,$O7,$V7) -> 0 | AI7: =MAX($B7,$I7,$P7) -> 0 | AJ7: =MAX($C7,$J7,$Q7) -> 0 | AK7: =MAX($E7,$L7,$S7) -> 0 | AL7: =MAX($F7,$M7,$T7) -> 0 | AM7: =MAX($G7,$N7,$U7) -> 0 | AN7: =MAX($H7,$O7,$V7) -> 0
A8: instances/size-5 | B8: 37.35 | C8: 5.26 | D8: SATISFIABLE | E8: 9527537 | F8: 36.175 | G8: 3.03 | H8: 0 | I8: 0.97 | J8: 0.01 | K8: SATISFIABLE | L8: 2407 | M8: 0.096 | N8: 0 | O8: 0 | P8: 0.96 | Q8: 0 | R8: SATISFIABLE | S8: 2407 | T8: 0.098 | U8: 0 | V8: 0 | W8: =MIN($B8,$I8,$P8) -> 0 | X8: =MIN($C8,$J8,$Q8) -> 0 | Y8: =MIN($E8,$L8,$S8) -> 0 | Z8: =MIN($F8,$M8,$T8) -> 0 | AA8: =MIN($G8,$N8,$U8) -> 0 | AB8: =MIN($H8,$O8,$V8) -> 0 | AC8: =MEDIAN($B8,$I8,$P8) -> 0 | AD8: =MEDIAN($C8,$J8,$Q8) -> 0 | AE8: =MEDIAN($E8,$L8,$S8) -> 0 | AF8: =MEDIAN($F8,$M8,$T8) -> 0 | AG8: =MEDIAN($G8,$N8,$U8) -> 0 | AH8: =MEDIAN($H8,$O8,$V8) -> 0 | AI8: =MAX($B8,$I8,$P8) -> 0 | AJ8: =MAX($C8,$J8,$Q8) -> 0 | AK8: =MAX($E8,$L8,$S8) -> 0 | AL8: =MAX($F8,$M8,$T8) -> 0 | AM8: =MAX($G8,$N8,$U8) -> 0 | AN8: =MAX($H8,$O8,$V8) -> 0
A9: instances/size-6 | B9: 96.8 | C9: 43.07 | D9: SATISFIABLE | E9: 13728177 | F9: 95.458 | G9: 6.77 | H9: 0 | I9: 1.03 | J9: 0.01 | K9: SATISFIABLE | L9: 2407 | M9: 0.11 | N9: 0 | O9: 0 | P9: 0.99 | Q9: 0 | R9: SATISFIABLE | S9: 2407 | T9: 0.101 | U9: 0 | V9: 0 | W9: =MIN($B9,$I9,$P9) -> 0 | X9: =MIN($C9,$J9,$Q9) -> 0 | Y9: =MIN($E9,$L9,$S9) -> 0 | Z9: =MIN($F9,$M9,$T9) -> 0 | AA9: =MIN($G9,$N9,$U9) -> 0 | AB9: =MIN($H9,$O9,$V9) -> 0 | AC9: =MEDIAN($B9,$I9,$P9) -> 0 | AD9: =MEDIAN($C9,$J9,$Q9) -> 0 | AE9: =MEDIAN($E9,$L9,$S9) -> 0 | AF9: =MEDIAN($F9,$M9,$T9) -> 0 | AG9: =MEDIAN($G9,$N9,$U9) -> 0 | AH9: =MEDIAN($H9,$O9,$V9) -> 0 | AI9: =MAX($B9,$I9,$P9) -> 0 | AJ9: =MAX($C9,$J9,$Q9) -> 0 | AK9: =MAX($E9,$L9,$S9) -> 0 | AL9: =MAX($F9,$M9,$T9) -> 0 | AM9: =MAX($G9,$N9,$U9) -> 0 | AN9: =MAX($H9,$O9,$V9) -> 0
A10: instances/size-7 | B10: 97.04 | C10: 17.82 | D10: SATISFIABLE | E10: 18694017 | F10: 95.495 | G10: 17.32 | H10: 0 | I10: 0.98 | J10: 0.01 | K10: SATISFIABLE | L10: 2407 | M10: 0.116 | N10: 0 | O10: 0 | P10: 1 | Q10: 0 | R10: SATISFIABLE | S10: 2407 | T10: 0.1 | U10: 0 | V10: 0 | W10: =MIN($B10,$I10,$P10) -> 0 | X10: =MIN($C10,$J10,$Q10) -> 0 | Y10: =MIN($E10,$L10,$S10) -> 0 | Z10: =MIN($F10,$M10,$T10) -> 0 | AA10: =MIN($G10,$N10,$U10) -> 0 | AB10: =MIN($H10,$O10,$V10) -> 0 | AC10: =MEDIAN($B10,$I10,$P10) -> 0 | AD10: =MEDIAN($C10,$J10,$Q10) -> 0 | AE10: =MEDIAN($E10,$L10,$S10) -> 0 | AF10: =MEDIAN($F10,$M10,$T10) -> 0 | AG10: =MEDIAN($G10,$N10,$U10) -> 0 | AH10: =MEDIAN($H10,$O10,$V10) -> 0 | AI10: =MAX($B10,$I10,$P10) -> 0 | AJ10: =MAX($C10,$J10,$Q10) -> 0 | AK10: =MAX($E10,$L10,$S10) -> 0 | AL10: =MAX($F10,$M10,$T10) -> 0 | AM10: =MAX($G10,$N10,$U10) -> 0 | AN10: =MAX($H10,$O10,$V10) -> 0
A11: instances/size-8 | B11: 294.66 | C11: 165.22 | D11: SATISFIABLE | E11: 24425057 | F11: 292.427 | G11: 18.1 | H11: 0 | I11: 1.03 | J11: 0.01 | K11: SATISFIABLE | L11: 2407 | M11: 0.124 | N11: 0 | O11: 0 | P11: 1.01 | Q11: 0 | R11: SATISFIABLE | S11: 2407 | T11: 0.095 | U11: 0 | V11: 0 | W11: =MIN($B11,$I11,$P11) -> 0 | X11: =MIN($C11,$J11,$Q11) -> 0 | Y11: =MIN($E11,$L11,$S11) -> 0 | Z11: =MIN($F11,$M11,$T11) -> 0 | AA11: =MIN($G11,$N11,$U11) -> 0 | AB11: =MIN($H11,$O11,$V11) -> 0 | AC11: =MEDIAN($B11,$I11,$P11) -> 0 | AD11: =MEDIAN($C11,$J11,$Q11) -> 0 | AE11: =MEDIAN($E11,$L11,$S11) -> 0 | AF11: =MEDIAN($F11,$M11,$T11) -> 0 | AG11: =MEDIAN($G11,$N11,$U11) -> 0 | AH11: =MEDIAN($H11,$O11,$V11) -> 0 | AI11: =MAX($B11,$I11,$P11) -> 0 | AJ11: =MAX($C11,$J11,$Q11) -> 0 | AK11: =MAX($E11,$L11,$S11) -> 0 | AL11: =MAX($F11,$M11,$T11) -> 0 | AM11: =MAX($G11,$N11,$U11) -> 0 | AN11: =MAX($H11,$O11,$V11) -> 0
A12: instances/size-9 | B12: 349.51 | C12: 187.98 | D12: SATISFIABLE | E12: 30921297 | F12: 347.342 | G12: 33.92 | H12: 0 | I12: 1.02 | J12: 0.01 | K12: SATISFIABLE | L12: 2407 | M12: 0.119 | N12: 0 | O12: 0 | P12: 1.01 | Q12: 0 | R12: SATISFIABLE | S12: 2407 | T12: 0.097 | U12: 0 | V12: 0 | W12: =MIN($B12,$I12,$P12) -> 0 | X12: =MIN($C12,$J12,$Q12) -> 0 | Y12: =MIN($E12,$L12,$S12) -> 0 | Z12: =MIN($F12,$M12,$T12) -> 0 | AA12: =MIN($G12,$N12,$U12) -> 0 | AB12: =MIN($H12,$O12,$V12) -> 0 | AC12: =MEDIAN($B12,$I12,$P12) -> 0 | AD12: =MEDIAN($C12,$J12,$Q12) -> 0 | AE12: =MEDIAN($E12,$L12,$S12) -> 0 | AF12: =MEDIAN($F12,$M12,$T12) -> 0 | AG12: =MEDIAN($G12,$N12,$U12) -> 0 | AH12: =MEDIAN($H12,$O12,$V12) -> 0 | AI12: =MAX($B12,$I12,$P12) -> 0 | AJ12: =MAX($C12,$J12,$Q12) -> 0 | AK12: =MAX($E12,$L12,$S12) -> 0 | AL12: =MAX($F12,$M12,$T12) -> 0 | AM12: =MAX($G12,$N12,$U12) -> 0 | AN12: =MAX($H12,$O12,$V12) -> 0
A14: SUM | B14: =SUM(B$3:B$12) -> 0 | C14: =SUM(C$3:C$12) -> 0 | E14: =SUM(E$3:E$12) -> 0 | F14: =SUM(F$3:F$12) -> 0 | G14: =SUM(G$3:G$12) -> 0 | H14: =SUM(H$3:H$12) -> 0 | I14: =SUM(I$3:I$12) -> 0 | J14: =SUM(J$3:J$12) -> 0 | L14: =SUM(L$3:L$12) -> 0 | M14: =SUM(M$3:M$12) -> 0 | N14: =SUM(N$3:N$12) -> 0 | O14: =SUM(O$3:O$12) -> 0 | P14: =SUM(P$3:P$12) -> 0 | Q14: =SUM(Q$3:Q$12) -> 0 | S14: =SUM(S$3:S$12) -> 0 | T14: =SUM(T$3:T$12) -> 0 | U14: =SUM(U$3:U$12) -> 0 | V14: =SUM(V$3:V$12) -> 0 | W14: =SUM(W$3:W$12) -> 0 | X14: =SUM(X$3:X$12) -> 0 | Y14: =SUM(Y$3:Y$12) -> 0 | Z14: =SUM(Z$3:Z$12) -> 0 | ... AN14: =SUM(AN$3:AN$12) -> 0
A15: AVG | B15: =AVERAGE(B$3:B$12) -> 0 | C15: =AVERAGE(C$3:C$12) -> 0 | E15: =AVERAGE(E$3:E$12) -> 0 | F15: =AVERAGE(F$3:F$12) -> 0 | G15: =AVERAGE(G$3:G$12) -> 0 | H15: =AVERAGE(H$3:H$12) -> 0 | I15: =AVERAGE(I$3:I$12) -> 0 | J15: =AVERAGE(J$3:J$12) -> 0 | L15: =AVERAGE(L$3:L$12) -> 0 | M15: =AVERAGE(M$3:M$12) -> 0 | N15: =AVERAGE(N$3:N$12) -> 0 | O15: =AVERAGE(O$3:O$12) -> 0 | P15: =AVERAGE(P$3:P$12) -> 0 | Q15: =AVERAGE(Q$3:Q$12) -> 0 | S15: =AVERAGE(S$3:S$12) -> 0 | T15: =AVERAGE(T$3:T$12) -> 0 | U15: =AVERAGE(U$3:U$12) -> 0 | V15: =AVERAGE(V$3:V$12) -> 0 | W15: =AVERAGE(W$3:W$12) -> 0 | X15: =AVERAGE(X$3:X$12) -> 0 | Y15: =AVERAGE(Y$3:Y$12) -> 0 | Z15: =AVERAGE(Z$3:Z$12) -> 0 | ... AN15: =AVERAGE(AN$3:AN$12) -> 0
A16: DEV | B16: =STDEV(B$3:B$12) -> 0 | C16: =STDEV(C$3:C$12) -> 0 | E16: =STDEV(E$3:E$12) -> 0 | F16: =STDEV(F$3:F$12) -> 0 | G16: =STDEV(G$3:G$12) -> 0 | H16: =STDEV(H$3:H$12) -> 0 | I16: =STDEV(I$3:I$12) -> 0 | J16: =STDEV(J$3:J$12) -> 0 | L16: =STDEV(L$3:L$12) -> 0 | M16: =STDEV(M$3:M$12) -> 0 | N16: =STDEV(N$3:N$12) -> 0 | O16: =STDEV(O$3:O$12) -> 0 | P16: =STDEV(P$3:P$12) -> 0 | Q16: =STDEV(Q$3:Q$12) -> 0 | S16: =STDEV(S$3:S$12) -> 0 | T16: =STDEV(T$3:T$12) -> 0 | U16: =STDEV(U$3:U$12) -> 0 | V16: =STDEV(V$3:V$12) -> 0 | W16: =STDEV(W$3:W$12) -> 0 | X16: =STDEV(X$3:X$12) -> 0 | Y16: =STDEV(Y$3:Y$12) -> 0 | Z16: =STDEV(Z$3:Z$12) -> 0 | ... AN16: =STDEV(AN$3:AN$12) -> 0
A17: DST | B17: =SUMPRODUCT(--(B$3:B$12-$W$3:$W$12)^2)^0.5 -> 0 | C17: =SUMPRODUCT(--(C$3:C$12-$X$3:$X$12)^2)^0.5 -> 0 | E17: =SUMPRODUCT(--(E$3:E$12-$Y$3:$Y$12)^2)^0.5 -> 0 | F17: =SUMPRODUCT(--(F$3:F$12-$Z$3:$Z$12)^2)^0.5 -> 0 | G17: =SUMPRODUCT(--(G$3:G$12-$AA$3:$AA$12)^2)^0.5 -> 0 | H17: =SUMPRODUCT(--(H$3:H$12-$AB$3:$AB$12)^2)^0.5 -> 0 | I17: =SUMPRODUCT(--(I$3:I$12-$W$3:$W$12)^2)^0.5 -> 0 | J17: =SUMPRODUCT(--(J$3:J$12-$X$3:$X$12)^2)^0.5 -> 0 | L17: =SUMPRODUCT(--(L$3:L$12-$Y$3:$Y$12)^2)^0.5 -> 0 | M17: =SUMPRODUCT(--(M$3:M$12-$Z$3:$Z$12)^2)^0.5 -> 0 | N17: =SUMPRODUCT(--(N$3:N$12-$AA$3:$AA$12)^2)^0.5 -> 0 | O17: =SUMPRODUCT(--(O$3:O$12-$AB$3:$AB$12)^2)^0.5 -> 0 | P17: =SUMPRODUCT(--(P$3:P$12-$W$3:$W$12)^2)^0.5 -> 0 | Q17: =SUMPRODUCT(--(Q$3:Q$12-$X$3:$X$12)^2)^0.5 -> 0 | S17: =SUMPRODUCT(--(S$3:S$12-$Y$3:$Y$12)^2)^0.5 -> 0 | T17: =SUMPRODUCT(--(T$3:T$12-$Z$3:$Z$12)^2)^0.5 -> 0 | U17: =SUMPRODUCT(--(U$3:U$12-$AA$3:$AA$12)^2)^0.5 -> 0 | V17: =SUMPRODUCT(--(V$3:V$12-$AB$3:$AB$12)^2)^0.5 -> 0
A18: BEST | B18: =SUMPRODUCT(NOT(ISBLANK(B$3:B$12))*(B$3:B$12=$W$3:$W$12)) -> 0 | C18: =SUMPRODUCT(NOT(ISBLANK(C$3:C$12))*(C$3:C$12=$X$3:$X$12)) -> 0 | E18: =SUMPRODUCT(NOT(ISBLANK(E$3:E$12))*(E$3:E$12=$Y$3:$Y$12)) -> 0 | F18: =SUMPRODUCT(NOT(ISBLANK(F$3:F$12))*(F$3:F$12=$Z$3:$Z$12)) -> 0 | G18: =SUMPRODUCT(NOT(ISBLANK(G$3:G$12))*(G$3:G$12=$AA$3:$AA$12)) -> 0 | H18: =SUMPRODUCT(NOT(ISBLANK(H$3:H$12))*(H$3:H$12=$AB$3:$AB$12)) -> 0 | I18: =SUMPRODUCT(NOT(ISBLANK(I$3:I$12))*(I$3:I$12=$W$3:$W$12)) -> 0 | J18: =SUMPRODUCT(NOT(ISBLANK(J$3:J$12))*(J$3:J$12=$X$3:$X$12)) -> 0 | L18: =SUMPRODUCT(NOT(ISBLANK(L$3:L$12))*(L$3:L$12=$Y$3:$Y$12)) -> 0 | M18: =SUMPRODUCT(NOT(ISBLANK(M$3:M$12))*(M$3:M$12=$Z$3:$Z$12)) -> 0 | N18: =SUMPRODUCT(NOT(ISBLANK(N$3:N$12))*(N$3:N$12=$AA$3:$AA$12)) -> 0 | O18: =SUMPRODUCT(NOT(ISBLANK(O$3:O$12))*(O$3:O$12=$AB$3:$AB$12)) -> 0 | P18: =SUMPRODUCT(NOT(ISBLANK(P$3:P$12))*(P$3:P$12=$W$3:$W$12)) -> 0 | Q18: =SUMPRODUCT(NOT(ISBLANK(Q$3:Q$12))*(Q$3:Q$12=$X$3:$X$12)) -> 0 | S18: =SUMPRODUCT(NOT(ISBLANK(S$3:S$12))*(S$3:S$12=$Y$3:$Y$12)) -> 0 | T18: =SUMPRODUCT(NOT(ISBLANK(T$3:T$12))*(T$3:T$12=$Z$3:$Z$12)) -> 0 | U18: =SUMPRODUCT(NOT(ISBLANK(U$3:U$12))*(U$3:U$12=$AA$3:$AA$12)) -> 0 | V18: =SUMPRODUCT(NOT(ISBLANK(V$3:V$12))*(V$3:V$12=$AB$3:$AB$12)) -> 0
A19: BETTER | B19: =SUMPRODUCT(NOT(ISBLANK(B$3:B$12))*(B$3:B$12<$AC$3:$AC$12)) -> 0 | C19: =SUMPRODUCT(NOT(ISBLANK(C$3:C$12))*(C$3:C$12<$AD$3:$AD$12)) -> 0 | E19: =SUMPRODUCT(NOT(ISBLANK(E$3:E$12))*(E$3:E$12<$AE$3:$AE$12)) -> 0 | F19: =SUMPRODUCT(NOT(ISBLANK(F$3:F$12))*(F$3:F$12<$AF$3:$AF$12)) -> 0 | G19: =SUMPRODUCT(NOT(ISBLANK(G$3:G$12))*(G$3:G$12<$AG$3:$AG$12)) -> 0 | H19: =SUMPRODUCT(NOT(ISBLANK(H$3:H$12))*(H$3:H$12<$AH$3:$AH$12)) -> 0 | I19: =SUMPRODUCT(NOT(ISBLANK(I$3:I$12))*(I$3:I$12<$AC$3:$AC$12)) -> 0 | J19: =SUMPRODUCT(NOT(ISBLANK(J$3:J$12))*(J$3:J$12<$AD$3:$AD$12)) -> 0 | L19: =SUMPRODUCT(NOT(ISBLANK(L$3:L$12))*(L$3:L$12<$AE$3:$AE$12)) -> 0 | M19: =SUMPRODUCT(NOT(ISBLANK(M$3:M$12))*(M$3:M$12<$AF$3:$AF$12)) -> 0 | N19: =SUMPRODUCT(NOT(ISBLANK(N$3:N$12))*(N$3:N$12<$AG$3:$AG$12)) -> 0 | O19: =SUMPRODUCT(NOT(ISBLANK(O$3:O$12))*(O$3:O$12<$AH$3:$AH$12)) -> 0 | P19: =SUMPRODUCT(NOT(ISBLANK(P$3:P$12))*(P$3:P$12<$AC$3:$AC$12)) -> 0 | Q19: =SUMPRODUCT(NOT(ISBLANK(Q$3:Q$12))*(Q$3:Q$12<$AD$3:$AD$12)) -> 0 | S19: =SUMPRODUCT(NOT(ISBLANK(S$3:S$12))*(S$3:S$12<$AE$3:$AE$12)) -> 0 | T19: =SUMPRODUCT(NOT(ISBLANK(T$3:T$12))*(T$3:T$12<$AF$3:$AF$12)) -> 0 | U19: =SUMPRODUCT(NOT(ISBLANK(U$3:U$12))*(U$3:U$12<$AG$3:$AG$12)) -> 0 | V19: =SUMPRODUCT(NOT(ISBLANK(V$3:V$12))*(V$3:V$12<$AH$3:$AH$12)) -> 0
A20: WORSE | B20: =SUMPRODUCT((NOT(ISBLANK(B$3:B$12))*(B$3:B$12>$AC$3:$AC$12))+ISBLANK(B$3:B$12)) -> 0 | C20: =SUMPRODUCT((NOT(ISBLANK(C$3:C$12))*(C$3:C$12>$AD$3:$AD$12))+ISBLANK(C$3:C$12)) -> 0 | E20: =SUMPRODUCT((NOT(ISBLANK(E$3:E$12))*(E$3:E$12>$AE$3:$AE$12))+ISBLANK(E$3:E$12)) -> 0 | F20: =SUMPRODUCT((NOT(ISBLANK(F$3:F$12))*(F$3:F$12>$AF$3:$AF$12))+ISBLANK(F$3:F$12)) -> 0 | G20: =SUMPRODUCT((NOT(ISBLANK(G$3:G$12))*(G$3:G$12>$AG$3:$AG$12))+ISBLANK(G$3:G$12)) -> 0 | H20: =SUMPRODUCT((NOT(ISBLANK(H$3:H$12))*(H$3:H$12>$AH$3:$AH$12))+ISBLANK(H$3:H$12)) -> 0 | I20: =SUMPRODUCT((NOT(ISBLANK(I$3:I$12))*(I$3:I$12>$AC$3:$AC$12))+ISBLANK(I$3:I$12)) -> 0 | J20: =SUMPRODUCT((NOT(ISBLANK(J$3:J$12))*(J$3:J$12>$AD$3:$AD$12))+ISBLANK(J$3:J$12)) -> 0 | L20: =SUMPRODUCT((NOT(ISBLANK(L$3:L$12))*(L$3:L$12>$AE$3:$AE$12))+ISBLANK(L$3:L$12)) -> 0 | M20: =SUMPRODUCT((NOT(ISBLANK(M$3:M$12))*(M$3:M$12>$AF$3:$AF$12))+ISBLANK(M$3:M$12)) -> 0 | N20: =SUMPRODUCT((NOT(ISBLANK(N$3:N$12))*(N$3:N$12>$AG$3:$AG$12))+ISBLANK(N$3:N$12)) -> 0 | O20: =SUMPRODUCT((NOT(ISBLANK(O$3:O$12))*(O$3:O$12>$AH$3:$AH$12))+ISBLANK(O$3:O$12)) -> 0 | P20: =SUMPRODUCT((NOT(ISBLANK(P$3:P$12))*(P$3:P$12>$AC$3:$AC$12))+ISBLANK(P$3:P$12)) -> 0 | Q20: =SUMPRODUCT((NOT(ISBLANK(Q$3:Q$12))*(Q$3:Q$12>$AD$3:$AD$12))+ISBLANK(Q$3:Q$12)) -> 0 | S20: =SUMPRODUCT((NOT(ISBLANK(S$3:S$12))*(S$3:S$12>$AE$3:$AE$12))+ISBLANK(S$3:S$12)) -> 0 | T20: =SUMPRODUCT((NOT(ISBLANK(T$3:T$12))*(T$3:T$12>$AF$3:$AF$12))+ISBLANK(T$3:T$12)) -> 0 | U20: =SUMPRODUCT((NOT(ISBLANK(U$3:U$12))*(U$3:U$12>$AG$3:$AG$12))+ISBLANK(U$3:U$12)) -> 0 | V20: =SUMPRODUCT((NOT(ISBLANK(V$3:V$12))*(V$3:V$12>$AH$3:$AH$12))+ISBLANK(V$3:V$12)) -> 0
A21: WORST | B21: =SUMPRODUCT((NOT(ISBLANK(B$3:B$12))*(B$3:B$12=$AI$3:$AI$12))+ISBLANK(B$3:B$12)) -> 0 | C21: =SUMPRODUCT((NOT(ISBLANK(C$3:C$12))*(C$3:C$12=$AJ$3:$AJ$12))+ISBLANK(C$3:C$12)) -> 0 | E21: =SUMPRODUCT((NOT(ISBLANK(E$3:E$12))*(E$3:E$12=$AK$3:$AK$12))+ISBLANK(E$3:E$12)) -> 0 | F21: =SUMPRODUCT((NOT(ISBLANK(F$3:F$12))*(F$3:F$12=$AL$3:$AL$12))+ISBLANK(F$3:F$12)) -> 0 | G21: =SUMPRODUCT((NOT(ISBLANK(G$3:G$12))*(G$3:G$12=$AM$3:$AM$12))+ISBLANK(G$3:G$12)) -> 0 | H21: =SUMPRODUCT((NOT(ISBLANK(H$3:H$12))*(H$3:H$12=$AN$3:$AN$12))+ISBLANK(H$3:H$12)) -> 0 | I21: =SUMPRODUCT((NOT(ISBLANK(I$3:I$12))*(I$3:I$12=$AI$3:$AI$12))+ISBLANK(I$3:I$12)) -> 0 | J21: =SUMPRODUCT((NOT(ISBLANK(J$3:J$12))*(J$3:J$12=$AJ$3:$AJ$12))+ISBLANK(J$3:J$12)) -> 0 | L21: =SUMPRODUCT((NOT(ISBLANK(L$3:L$12))*(L$3:L$12=$AK$3:$AK$12))+ISBLANK(L$3:L$12)) -> 0 | M21: =SUMPRODUCT((NOT(ISBLANK(M$3:M$12))*(M$3:M$12=$AL$3:$AL$12))+ISBLANK(M$3:M$12)) -> 0 | N21: =SUMPRODUCT((NOT(ISBLANK(N$3:N$12))*(N$3:N$12=$AM$3:$AM$12))+ISBLANK(N$3:N$12)) -> 0 | O21: =SUMPRODUCT((NOT(ISBLANK(O$3:O$12))*(O$3:O$12=$AN$3:$AN$12))+ISBLANK(O$3:O$12)) -> 0 | P21: =SUMPRODUCT((NOT(ISBLANK(P$3:P$12))*(P$3:P$12=$AI$3:$AI$12))+ISBLANK(P$3:P$12)) -> 0 | Q21: =SUMPRODUCT((NOT(ISBLANK(Q$3:Q$12))*(Q$3:Q$12=$AJ$3:$AJ$12))+ISBLANK(Q$3:Q$12)) -> 0 | S21: =SUMPRODUCT((NOT(ISBLANK(S$3:S$12))*(S$3:S$12=$AK$3:$AK$12))+ISBLANK(S$3:S$12)) -> 0 | T21: =SUMPRODUCT((NOT(ISBLANK(T$3:T$12))*(T$3:T$12=$AL$3:$AL$12))+ISBLANK(T$3:T$12)) -> 0 | U21: =SUMPRODUCT((NOT(ISBLANK(U$3:U$12))*(U$3:U$12=$AM$3:$AM$12))+ISBLANK(U$3:U$12)) -> 0 | V21: =SUMPRODUCT((NOT(ISBLANK(V$3:V$12))*(V$3:V$12=$AN$3:$AN$12))+ISBLANK(V$3:V$12)) -> 0

Sheet Merged Runs
A1: Merge criteria: | B1: memelingo-1/goal_mlp-tplp-ht | I1: memelingo-1/goal_mlp-tplp-htc | P1: memelingo-1/goal_mlp-tplp-htcdl | W1: min | AC1: median | AI1: max
A2: median | B2: time | C2: stime | D2: status | E2: rules | F2: ctime | G2: fmtime | H2: memout | I2: time | J2: stime | K2: status | L2: rules | M2: ctime | N2: fmtime | O2: memout | P2: time | Q2: stime | R2: status | S2: rules | T2: ctime | U2: fmtime | V2: memout | W2: time | X2: stime | Y2: rules | Z2: ctime | AA2: fmtime | AB2: memout | AC2: time | AD2: stime | AE2: rules | AF2: ctime | AG2: fmtime | AH2: memout | AI2: time | AJ2: stime | AK2: rules | AL2: ctime | AM2: fmtime | AN2: memout
A3: instances/size-1 | B3: {=_xlfn.SWITCH($A$2,"average", AVERAGE(Instances!B3:Instances!B3),"median", MEDIAN(Instances!B3:Instances!B3),"min", MIN(Instances!B3:Instances!B3),"max", MAX(Instances!B3:Instances!B3),"diff", MAX(Instances!B3:Instances!B3)-MIN(Instances!B3:Instances!B3))} -> 0 | C3: {=_xlfn.SWITCH($A$2,"average", AVERAGE(Instances!C3:Instances!C3),"median", MEDIAN(Instances!C3:Instances!C3),"min", MIN(Instances!C3:Instances!C3),"max", MAX(Instances!C3:Instances!C3),"diff", MAX(Instances!C3:Instances!C3)-MIN(Instances!C3:Instances!C3))} -> 0 | E3: {=_xlfn.SWITCH($A$2,"average", AVERAGE(Instances!E3:Instances!E3),"median", MEDIAN(Instances!E3:Instances!E3),"min", MIN(Instances!E3:Instances!E3),"max", MAX(Instances!E3:Instances!E3),"diff", MAX(Instances!E3:Instances!E3)-MIN(Instances!E3:Instances!E3))} -> 0 | F3: {=_xlfn.SWITCH($A$2,"average", AVERAGE(Instances!F3:Instances!F3),"median", MEDIAN(Instances!F3:Instances!F3),"min", MIN(Instances!F3:Instances!F3),"max", MAX(Instances!F3:Instances!F3),"diff", MAX(Instances!F3:Instances!F3)-MIN(Instances!F3:Instances!F3))} -> 0 | G3: {=_xlfn.SWITCH($A$2,"average", AVERAGE(Instances!G3:Instances!G3),"median", MEDIAN(Instances!G3:Instances!G3),"min", MIN(Instances!G3:Instances!G3),"max", MAX(Instances!G3:Instances!G3),"diff", MAX(Instances!G3:Instances!G3)-MIN(Instances!G3:Instances!G3))} -> 0 | H3: {=_xlfn.SWITCH($A$2,"average", AVERAGE(Instances!H3:Instances!H3),"median", MEDIAN(Instances!H3:Instances!H3),"min", MIN(Instances!H3:Instances!H3),"max", MAX(Instances!H3:Instances!H3),"diff", MAX(Instances!H3:Instances!H3)-MIN(Instances!H3:Instances!H3))} -> 0 | I3: {=_xlfn.SWITCH($A$2,"average", AVERAGE(Instances!I3:Instances!I3),"median", MEDIAN(Instances!I3:Instances!I3),"min", MIN(Instances!I3:Instances!I3),"max", MAX(Instances!I3:Instances!I3),"diff", MAX(Instances!I3:Instances!I3)-MIN(Instances!I3:Instances!I3))} -> 0 | J3: {=_xlfn.SWITCH($A$2,"average", AVERAGE(Instances!J3:Instances!J3),"median", MEDIAN(Instances!J3:Instances!J3),"min", MIN(Instances!J3:Instances!J3),"max", MAX(Instances!J3:Instances!J3),"diff", MAX(Instances!J3:Instances!J3)-MIN(Instances!J3:Instances!J3))} -> 0 | L3: {=_xlfn.SWITCH($A$2,"average", AVERAGE(Instances!L3:Instances!L3),"median", MEDIAN(Instances!L3:Instances!L3),"min", MIN(Instances!L3:Instances!L3),"max", MAX(Instances!L3:Instances!L3),"diff", MAX(Instances!L3:Instances!L3)-MIN(Instances!L3:Instances!L3))} -> 0 | M3: {=_xlfn.SWITCH($A$2,"average", AVERAGE(Instances!M3:Instances!M3),"median", MEDIAN(Instances!M3:Instances!M3),"min", MIN(Instances!M3:Instances!M3),"max", MAX(Instances!M3:Instances!M3),"diff", MAX(Instances!M3:Instances!M3)-MIN(Instances!M3:Instances!M3))} -> 0 | N3: {=_xlfn.SWITCH($A$2,"average", AVERAGE(Instances!N3:Instances!N3),"median", MEDIAN(Instances!N3:Instances!N3),"min", MIN(Instances!N3:Instances!N3),"max", MAX(Instances!N3:Instances!N3),"diff", MAX(Instances!N3:Instances!N3)-MIN(Instances!N3:Instances!N3))} -> 0 | O3: {=_xlfn.SWITCH($A$2,"average", AVERAGE(Instances!O3:Instances!O3),"median", MEDIAN(Instances!O3:Instances!O3),"min", MIN(Instances!O3:Instances!O3),"max", MAX(Instances!O3:Instances!O3),"diff", MAX(Instances!O3:Instances!O3)-MIN(Instances!O3:Instances!O3))} -> 0 | P3: {=_xlfn.SWITCH($A$2,"average", AVERAGE(Instances!P3:Instances!P3),"median", MEDIAN(Instances!P3:Instances!P3),"min", MIN(Instances!P3:Instances!P3),"max", MAX(Instances!P3:Instances!P3),"diff", MAX(Instances!P3:Instances!P3)-MIN(Instances!P3:Instances!P3))} -> 0 | Q3: {=_xlfn.SWITCH($A$2,"average", AVERAGE(Instances!Q3:Instances!Q3),"median", MEDIAN(Instances!Q3:Instances!Q3),"min", MIN(Instances!Q3:Instances!Q3),"max", MAX(Instances!Q3:Instances!Q3),"diff", MAX(Instances!Q3:Instances!Q3)-MIN(Instances!Q3:Instances!Q3))} -> 0 | S3: {=_xlfn.SWITCH($A$2,"average", AVERAGE(Instances!S3:Instances!S3),"median", MEDIAN(Instances!S3:Instances!S3),"min", MIN(Instances!S3:Instances!S3),"max", MAX(Instances!S3:Instances!S3),"diff", MAX(Instances!S3:Instances!S3)-MIN(Instances!S3:Instances!S3))} -> 0 | T3: {=_xlfn.SWITCH($A$2,"average", AVERAGE(Instances!T3:Instances!T3),"median", MEDIAN(Instances!T3:Instances!T3),"min", MIN(Instances!T3:Instances!T3),"max", MAX(Instances!T3:Instances!T3),"diff", MAX(Instances!T3:Instances!T3)-MIN(Instances!T3:Instances!T3))} -> 0 | U3: {=_xlfn.SWITCH($A$2,"average", AVERAGE(Instances!U3:Instances!U3),"median", MEDIAN(Instances!U3:Instances!U3),"min", MIN(Instances!U3:Instances!U3),"max", MAX(Instances!U3:Instances!U3),"diff", MAX(Instances!U3:Instances!U3)-MIN(Instances!U3:Instances!U3))} -> 0 | V3: {=_xlfn.SWITCH($A$2,"average", AVERAGE(Instances!V3:Instances!V3),"median", MEDIAN(Instances!V3:Instances!V3),"min", MIN(Instances!V3:Instances!V3),"max", MAX(Instances!V3:Instances!V3),"diff", MAX(Instances!V3:Instances!V3)-MIN(Instances!V3:Instances!V3))} -> 0 | W3: =MIN($B3,$I3,$P3) -> 0 | X3: =MIN($C3,$J3,$Q3) -> 0 | Y3: =MIN($E3,$L3,$S3) -> 0 | Z3: =MIN($F3,$M3,$T3) -> 0 | AA3: =MIN($G3,$N3,$U3) -> 0 | AB3: =MIN($H3,$O3,$V3) -> 0 | AC3: =MEDIAN($B3,$I3,$P3) -> 0 | AD3: =MEDIAN($C3,$J3,$Q3) -> 0 | AE3: =MEDIAN($E3,$L3,$S3) -> 0 | AF3: =MEDIAN($F3,$M3,$T3) -> 0 | AG3: =MEDIAN($G3,$N3,$U3) -> 0 | AH3: =MEDIAN($H3,$O3,$V3) -> 0 | AI3: =MAX($B3,$I3,$P3) -> 0 | AJ3: =MAX($C3,$J3,$Q3) -> 0 | AK3: =MAX($E3,$L3,$S3) -> 0 | AL3: =MAX($F3,$M3,$T3) -> 0 | AM3: =MAX($G3,$N3,$U3) -> 0 | AN3: =MAX($H3,$O3,$V3) -> 0
A4: instances/size-10 | B4: {=_xlfn.SWITCH($A$2,"average", AVERAGE(Instances!B4:Instances!B4),"median", MEDIAN(Instances!B4:Instances!B4),"min", MIN(Instances!B4:Instances!B4),"max", MAX(Instances!B4:Instances!B4),"diff", MAX(Instances!B4:Instances!B4)-MIN(Instances!B4:Instances!B4))} -> 0 | H4: {=_xlfn.SWITCH($A$2,"average", AVERAGE(Instances!H4:Instances!H4),"median", MEDIAN(Instances!H4:Instances!H4),"min", MIN(Instances!H4:Instances!H4),"max", MAX(Instances!H4:Instances!H4),"diff", MAX(Instances!H4:Instances!H4)-MIN(Instances!H4:Instances!H4))} -> 0 | I4: {=_xlfn.SWITCH($A$2,"average", AVERAGE(Instances!I4:Instances!I4),"median", MEDIAN(Instances!I4:Instances!I4),"min", MIN(Instances!I4:Instances!I4),"max", MAX(Instances!I4:Instances!I4),"diff", MAX(Instances!I4:Instances!I4)-MIN(Instances!I4:Instances!I4))} -> 0 | J4: {=_xlfn.SWITCH($A$2,"average", AVERAGE(Instances!J4:Instances!J4),"median", MEDIAN(Instances!J4:Instances!J4),"min", MIN(Instances!J4:Instances!J4),"max", MAX(Instances!J4:Instances!J4),"diff", MAX(Instances!J4:Instances!J4)-MIN(Instances!J4:Instances!J4))} -> 0 | L4: {=_xlfn.SWITCH($A$2,"average", AVERAGE(Instances!L4:Instances!L4),"median", MEDIAN(Instances!L4:Instances!L4),"min", MIN(Instances!L4:Instances!L4),"max", MAX(Instances!L4:Instances!L4),"diff", MAX(Instances!L4:Instances!L4)-MIN(Instances!L4:Instances!L4))} -> 0 | M4: {=_xlfn.SWITCH($A$2,"average", AVERAGE(Instances!M4:Instances!M4),"median", MEDIAN(Instances!M4:Instances!M4),"min", MIN(Instances!M4:Instances!M4),"max", MAX(Instances!M4:Instances!M4),"diff", MAX(Instances!M4:Instances!M4)-MIN(Instances!M4:Instances!M4))} -> 0 | N4: {=_xlfn.SWITCH($A$2,"average", AVERAGE(Instances!N4:Instances!N4),"median", MEDIAN(Instances!N4:Instances!N4),"min", MIN(Instances!N4:Instances!N4),"max", MAX(Instances!N4:Instances!N4),"diff", MAX(Instances!N4:Instances!N4)-MIN(Instances!N4:Instances!N4))} -> 0 | O4: {=_xlfn.SWITCH($A$2,"average", AVERAGE(Instances!O4:Instances!O4),"median", MEDIAN(Instances!O4:Instances!O4),"min", MIN(Instances!O4:Instances!O4),"max", MAX(Instances!O4:Instances!O4),"diff", MAX(Instances!O4:Instances!O4)-MIN(Instances!O4:Instances!O4))} -> 0 | P4: {=_xlfn.SWITCH($A$2,"average", AVERAGE(Instances!P4:Instances!P4),"median", MEDIAN(Instances!P4:Instances!P4),"min", MIN(Instances!P4:Instances!P4),"max", MAX(Instances!P4:Instances!P4),"diff", MAX(Instances!P4:Instances!P4)-MIN(Instances!P4:Instances!P4))} -> 0 | Q4: {=_xlfn.SWITCH($A$2,"average", AVERAGE(Instances!Q4:Instances!Q4),"median", MEDIAN(Instances!Q4:Instances!Q4),"min", MIN(Instances!Q4:Instances!Q4),"max", MAX(Instances!Q4:Instances!Q4),"diff", MAX(Instances!Q4:Instances!Q4)-MIN(Instances!Q4:Instances!Q4))} -> 0 | S4: {=_xlfn.SWITCH($A$2,"average", AVERAGE(Instances!S4:Instances!S4),"median", MEDIAN(Instances!S4:Instances!S4),"min", MIN(Instances!S4:Instances!S4),"max", MAX(Instances!S4:Instances!S4),"diff", MAX(Instances!S4:Instances!S4)-MIN(Instances!S4:Instances!S4))} -> 0 | T4: {=_xlfn.SWITCH($A$2,"average", AVERAGE(Instances!T4:Instances!T4),"median", MEDIAN(Instances!T4:Instances!T4),"min", MIN(Instances!T4:Instances!T4),"max", MAX(Instances!T4:Instances!T4),"diff", MAX(Instances!T4:Instances!T4)-MIN(Instances!T4:Instances!T4))} -> 0 | U4: {=_xlfn.SWITCH($A$2,"average", AVERAGE(Instances!U4:Instances!U4),"median", MEDIAN(Instances!U4:Instances!U4),"min", MIN(Instances!U4:Instances!U4),"max", MAX(Instances!U4:Instances!U4),"diff", MAX(Instances!U4:Instances!U4)-MIN(Instances!U4:Instances!U4))} -> 0 | V4: {=_xlfn.SWITCH($A$2,"average", AVERAGE(Instances!V4:Instances!V4),"median", MEDIAN(Instances!V4:Instances!V4),"min", MIN(Instances!V4:Instances!V4),"max", MAX(Instances!V4:Instances!V4),"diff", MAX(Instances!V4:Instances!V4)-MIN(Instances!V4:Instances!V4))} -> 0 | W4: =MIN($B4,$I4,$P4) -> 0 | X4: =MIN($C4,$J4,$Q4) -> 0 | Y4: =MIN($E4,$L4,$S4) -> 0 | Z4: =MIN($F4,$M4,$T4) -> 0 | AA4: =MIN($G4,$N4,$U4) -> 0 | AB4: =MIN($H4,$O4,$V4) -> 0 | AC4: =MEDIAN($B4,$I4,$P4) -> 0 | AD4: =MEDIAN($C4,$J4,$Q4) -> 0 | AE4: =MEDIAN($E4,$L4,$S4) -> 0 | AF4: =MEDIAN($F4,$M4,$T4) -> 0 | AG4: =MEDIAN($G4,$N4,$U4) -> 0 | AH4: =MEDIAN($H4,$O4,$V4) -> 0 | AI4: =MAX($B4,$I4,$P4) -> 0 | AJ4: =MAX($C4,$J4,$Q4) -> 0 | AK4: =MAX($E4,$L4,$S4) -> 0 | AL4: =MAX($F4,$M4,$T4) -> 0 | AM4: =MAX($G4,$N4,$U4) -> 0 | AN4: =MAX($H4,$O4,$V4) -> 0
A5: instances/size-2 | B5: {=_xlfn.SWITCH($A$2,"average", AVERAGE(Instances!B5:Instances!B5),"median", MEDIAN(Instances!B5:Instances!B5),"min", MIN(Instances!B5:Instances!B5),"max", MAX(Instances!B5:Instances!B5),"diff", MAX(Instances!B5:Instances!B5)-MIN(Instances!B5:Instances!B5))} -> 0 | C5: {=_xlfn.SWITCH($A$2,"average", AVERAGE(Instances!C5:Instances!C5),"median", MEDIAN(Instances!C5:Instances!C5),"min", MIN(Instances!C5:Instances!C5),"max", MAX(Instances!C5:Instances!C5),"diff", MAX(Instances!C5:Instances!C5)-MIN(Instances!C5:Instances!C5))} -> 0 | E5: {=_xlfn.SWITCH($A$2,"average", AVERAGE(Instances!E5:Instances!E5),"median", MEDIAN(Instances!E5:Instances!E5),"min", MIN(Instances!E5:Instances!E5),"max", MAX(Instances!E5:Instances!E5),"diff", MAX(Instances!E5:Instances!E5)-MIN(Instances!E5:Instances!E5))} -> 0 | F5: {=_xlfn.SWITCH($A$2,"average", AVERAGE(Instances!F5:Instances!F5),"median", MEDIAN(Instances!F5:Instances!F5),"min", MIN(Instances!F5:Instances!F5),"max", MAX(Instances!F5:Instances!F5),"diff", MAX(Instances!F5:Instances!F5)-MIN(Instances!F5:Instances!F5))} -> 0 | G5: {=_xlfn.SWITCH($A$2,"average", AVERAGE(Instances!G5:Instances!G5),"median", MEDIAN(Instances!G5:Instances!G5),"min", MIN(Instances!G5:Instances!G5),"max", MAX(Instances!G5:Instances!G5),"diff", MAX(Instances!G5:Instances!G5)-MIN(Instances!G5:Instances!G5))} -> 0 | H5: {=_xlfn.SWITCH($A$2,"average", AVERAGE(Instances!H5:Instances!H5),"median", MEDIAN(Instances!H5:Instances!H5),"min", MIN(Instances!H5:Instances!H5),"max", MAX(Instances!H5:Instances!H5),"diff", MAX(Instances!H5:Instances!H5)-MIN(Instances!H5:Instances!H5))} -> 0 | I5: {=_xlfn.SWITCH($A$2,"average", AVERAGE(Instances!I5:Instances!I5),"median", MEDIAN(Instances!I5:Instances!I5),"min", MIN(Instances!I5:Instances!I5),"max", MAX(Instances!I5:Instances!I5),"diff", MAX(Instances!I5:Instances!I5)-MIN(Instances!I5:Instances!I5))} -> 0 | J5: {=_xlfn.SWITCH($A$2,"average", AVERAGE(Instances!J5:Instances!J5),"median", MEDIAN(Instances!J5:Instances!J5),"min", MIN(Instances!J5:Instances!J5),"max", MAX(Instances!J5:Instances!J5),"diff", MAX(Instances!J5:Instances!J5)-MIN(Instances!J5:Instances!J5))} -> 0 | L5: {=_xlfn.SWITCH($A$2,"average", AVERAGE(Instances!L5:Instances!L5),"median", MEDIAN(Instances!L5:Instances!L5),"min", MIN(Instances!L5:Instances!L5),"max", MAX(Instances!L5:Instances!L5),"diff", MAX(Instances!L5:Instances!L5)-MIN(Instances!L5:Instances!L5))} -> 0 | M5: {=_xlfn.SWITCH($A$2,"average", AVERAGE(Instances!M5:Instances!M5),"median", MEDIAN(Instances!M5:Instances!M5),"min", MIN(Instances!M5:Instances!M5),"max", MAX(Instances!M5:Instances!M5),"diff", MAX(Instances!M5:Instances!M5)-MIN(Instances!M5:Instances!M5))} -> 0 | N5: {=_xlfn.SWITCH($A$2,"average", AVERAGE(Instances!N5:Instances!N5),"median", MEDIAN(Instances!N5:Instances!N5),"min", MIN(Instances!N5:Instances!N5),"max", MAX(Instances!N5:Instances!N5),"diff", MAX(Instances!N5:Instances!N5)-MIN(Instances!N5:Instances!N5))} -> 0 | O5: {=_xlfn.SWITCH($A$2,"average", AVERAGE(Instances!O5:Instances!O5),"median", MEDIAN(Instances!O5:Instances!O5),"min", MIN(Instances!O5:Instances!O5),"max", MAX(Instances!O5:Instances!O5),"diff", MAX(Instances!O5:Instances!O5)-MIN(Instances!O5:Instances!O5))} -> 0 | P5: {=_xlfn.SWITCH($A$2,"average", AVERAGE(Instances!P5:Instances!P5),"median", MEDIAN(Instances!P5:Instances!P5),"min", MIN(Instances!P5:Instances!P5),"max", MAX(Instances!P5:Instances!P5),"diff", MAX(Instances!P5:Instances!P5)-MIN(Instances!P5:Instances!P5))} -> 0 | Q5: {=_xlfn.SWITCH($A$2,"average", AVERAGE(Instances!Q5:Instances!Q5),"median", MEDIAN(Instances!Q5:Instances!Q5),"min", MIN(Instances!Q5:Instances!Q5),"max", MAX(Instances!Q5:Instances!Q5),"diff", MAX(Instances!Q5:Instances!Q5)-MIN(Instances!Q5:Instances!Q5))} -> 0 | S5: {=_xlfn.SWITCH($A$2,"average", AVERAGE(Instances!S5:Instances!S5),"median", MEDIAN(Instances!S5:Instances!S5),"min", MIN(Instances!S5:Instances!S5),"max", MAX(Instances!S5:Instances!S5),"diff", MAX(Instances!S5:Instances!S5)-MIN(Instances!S5:Instances!S5))} -> 0 | T5: {=_xlfn.SWITCH($A$2,"average", AVERAGE(Instances!T5:Instances!T5),"median", MEDIAN(Instances!T5:Instances!T5),"min", MIN(Instances!T5:Instances!T5),"max", MAX(Instances!T5:Instances!T5),"diff", MAX(Instances!T5:Instances!T5)-MIN(Instances!T5:Instances!T5))} -> 0 | U5: {=_xlfn.SWITCH($A$2,"average", AVERAGE(Instances!U5:Instances!U5),"median", MEDIAN(Instances!U5:Instances!U5),"min", MIN(Instances!U5:Instances!U5),"max", MAX(Instances!U5:Instances!U5),"diff", MAX(Instances!U5:Instances!U5)-MIN(Instances!U5:Instances!U5))} -> 0 | V5: {=_xlfn.SWITCH($A$2,"average", AVERAGE(Instances!V5:Instances!V5),"median", MEDIAN(Instances!V5:Instances!V5),"min", MIN(Instances!V5:Instances!V5),"max", MAX(Instances!V5:Instances!V5),"diff", MAX(Instances!V5:Instances!V5)-MIN(Instances!V5:Instances!V5))} -> 0 | W5: =MIN($B5,$I5,$P5) -> 0 | X5: =MIN($C5,$J5,$Q5) -> 0 | Y5: =MIN($E5,$L5,$S5) -> 0 | Z5: =MIN($F5,$M5,$T5) -> 0 | AA5: =MIN($G5,$N5,$U5) -> 0 | AB5: =MIN($H5,$O5,$V5) -> 0 | AC5: =MEDIAN($B5,$I5,$P5) -> 0 | AD5: =MEDIAN($C5,$J5,$Q5) -> 0 | AE5: =MEDIAN($E5,$L5,$S5) -> 0 | AF5: =MEDIAN($F5,$M5,$T5) -> 0 | AG5: =MEDIAN($G5,$N5,$U5) -> 0 | AH5: =MEDIAN($H5,$O5,$V5) -> 0 | AI5: =MAX($B5,$I5,$P5) -> 0 | AJ5: =MAX($C5,$J5,$Q5) -> 0 | AK5: =MAX($E5,$L5,$S5) -> 0 | AL5: =MAX($F5,$M5,$T5) -> 0 | AM5: =MAX($G5,$N5,$U5) -> 0 | AN5: =MAX($H5,$O5,$V5) -> 0
A6: instances/size-3 | B6: {=_xlfn.SWITCH($A$2,"average", AVERAGE(Instances!B6:Instances!B6),"median", MEDIAN(Instances!B6:Instances!B6),"min", MIN(Instances!B6:Instances!B6),"max", MAX(Instances!B6:Instances!B6),"diff", MAX(Instances!B6:Instances!B6)-MIN(Instances!B6:Instances!B6))} -> 0 | C6: {=_xlfn.SWITCH($A$2,"average", AVERAGE(Instances!C6:Instances!C6),"median", MEDIAN(Instances!C6:Instances!C6),"min", MIN(Instances!C6:Instances!C6),"max", MAX(Instances!C6:Instances!C6),"diff", MAX(Instances!C6:Instances!C6)-MIN(Instances!C6:Instances!C6))} -> 0 | E6: {=_xlfn.SWITCH($A$2,"average", AVERAGE(Instances!E6:Instances!E6),"median", MEDIAN(Instances!E6:Instances!E6),"min", MIN(Instances!E6:Instances!E6),"max", MAX(Instances!E6:Instances!E6),"diff", MAX(Instances!E6:Instances!E6)-MIN(Instances!E6:Instances!E6))} -> 0 | F6: {=_xlfn.SWITCH($A$2,"average", AVERAGE(Instances!F6:Instances!F6),"median", MEDIAN(Instances!F6:Instances!F6),"min", MIN(Instances!F6:Instances!F6),"max", MAX(Instances!F6:Instances!F6),"diff", MAX(Instances!F6:Instances!F6)-MIN(Instances!F6:Instances!F6))} -> 0 | G6: {=_xlfn.SWITCH($A$2,"average", AVERAGE(Instances!G6:Instances!G6),"median", MEDIAN(Instances!G6:Instances!G6),"min", MIN(Instances!G6:Instances!G6),"max", MAX(Instances!G6:Instances!G6),"diff", MAX(Instances!G6:Instances!G6)-MIN(Instances!G6:Instances!G6))} -> 0 | H6: {=_xlfn.SWITCH($A$2,"average", AVERAGE(Instances!H6:Instances!H6),"median", MEDIAN(Instances!H6:Instances!H6),"min", MIN(Instances!H6:Instances!H6),"max", MAX(Instances!H6:Instances!H6),"diff", MAX(Instances!H6:Instances!H6)-MIN(Instances!H6:Instances!H6))} -> 0 | I6: {=_xlfn.SWITCH($A$2,"average", AVERAGE(Instances!I6:Instances!I6),"median", MEDIAN(Instances!I6:Instances!I6),"min", MIN(Instances!I6:Instances!I6),"max", MAX(Instances!I6:Instances!I6),"diff", MAX(Instances!I6:Instances!I6)-MIN(Instances!I6:Instances!I6))} -> 0 | J6: {=_xlfn.SWITCH($A$2,"average", AVERAGE(Instances!J6:Instances!J6),"median", MEDIAN(Instances!J6:Instances!J6),"min", MIN(Instances!J6:Instances!J6),"max", MAX(Instances!J6:Instances!J6),"diff", MAX(Instances!J6:Instances!J6)-MIN(Instances!J6:Instances!J6))} -> 0 | L6: {=_xlfn.SWITCH($A$2,"average", AVERAGE(Instances!L6:Instances!L6),"median", MEDIAN(Instances!L6:Instances!L6),"min", MIN(Instances!L6:Instances!L6),"max", MAX(Instances!L6:Instances!L6),"diff", MAX(Instances!L6:Instances!L6)-MIN(Instances!L6:Instances!L6))} -> 0 | M6: {=_xlfn.SWITCH($A$2,"average", AVERAGE(Instances!M6:Instances!M6),"median", MEDIAN(Instances!M6:Instances!M6),"min", MIN(Instances!M6:Instances!M6),"max", MAX(Instances!M6:Instances!M6),"diff", MAX(Instances!M6:Instances!M6)-MIN(Instances!M6:Instances!M6))} -> 0 | N6: {=_xlfn.SWITCH($A$2,"average", AVERAGE(Instances!N6:Instances!N6),"median", MEDIAN(Instances!N6:Instances!N6),"min", MIN(Instances!N6:Instances!N6),"max", MAX(Instances!N6:Instances!N6),"diff", MAX(Instances!N6:Instances!N6)-MIN(Instances!N6:Instances!N6))} -> 0 | O6: {=_xlfn.SWITCH($A$2,"average", AVERAGE(Instances!O6:Instances!O6),"median", MEDIAN(Instances!O6:Instances!O6),"min", MIN(Instances!O6:Instances!O6),"max", MAX(Instances!O6:Instances!O6),"diff", MAX(Instances!O6:Instances!O6)-MIN(Instances!O6:Instances!O6))} -> 0 | P6: {=_xlfn.SWITCH($A$2,"average", AVERAGE(Instances!P6:Instances!P6),"median", MEDIAN(Instances!P6:Instances!P6),"min", MIN(Instances!P6:Instances!P6),"max", MAX(Instances!P6:Instances!P6),"diff", MAX(Instances!P6:Instances!P6)-MIN(Instances!P6:Instances!P6))} -> 0 | Q6: {=_xlfn.SWITCH($A$2,"average", AVERAGE(Instances!Q6:Instances!Q6),"median", MEDIAN(Instances!Q6:Instances!Q6),"min", MIN(Instances!Q6:Instances!Q6),"max", MAX(Instances!Q6:Instances!Q6),"diff", MAX(Instances!Q6:Instances!Q6)-MIN(Instances!Q6:Instances!Q6))} -> 0 | S6: {=_xlfn.SWITCH($A$2,"average", AVERAGE(Instances!S6:Instances!S6),"median", MEDIAN(Instances!S6:Instances!S6),"min", MIN(Instances!S6:Instances!S6),"max", MAX(Instances!S6:Instances!S6),"diff", MAX(Instances!S6:Instances!S6)-MIN(Instances!S6:Instances!S6))} -> 0 | T6: {=_xlfn.SWITCH($A$2,"average", AVERAGE(Instances!T6:Instances!T6),"median", MEDIAN(Instances!T6:Instances!T6),"min", MIN(Instances!T6:Instances!T6),"max", MAX(Instances!T6:Instances!T6),"diff", MAX(Instances!T6:Instances!T6)-MIN(Instances!T6:Instances!T6))} -> 0 | U6: {=_xlfn.SWITCH($A$2,"average", AVERAGE(Instances!U6:Instances!U6),"median", MEDIAN(Instances!U6:Instances!U6),"min", MIN(Instances!U6:Instances!U6),"max", MAX(Instances!U6:Instances!U6),"diff", MAX(Instances!U6:Instances!U6)-MIN(Instances!U6:Instances!U6))} -> 0 | V6: {=_xlfn.SWITCH($A$2,"average", AVERAGE(Instances!V6:Instances!V6),"median", MEDIAN(Instances!V6:Instances!V6),"min", MIN(Instances!V6:Instances!V6),"max", MAX(Instances!V6:Instances!V6),"diff", MAX(Instances!V6:Instances!V6)-MIN(Instances!V6:Instances!V6))} -> 0 | W6: =MIN($B6,$I6,$P6) -> 0 | X6: =MIN($C6,$J6,$Q6) -> 0 | Y6: =MIN($E6,$L6,$S6) -> 0 | Z6: =MIN($F6,$M6,$T6) -> 0 | AA6: =MIN($G6,$N6,$U6) -> 0 | AB6: =MIN($H6,$O6,$V6) -> 0 | AC6: =MEDIAN($B6,$I6,$P6) -> 0 | AD6: =MEDIAN($C6,$J6,$Q6) -> 0 | AE6: =MEDIAN($E6,$L6,$S6) -> 0 | AF6: =MEDIAN($F6,$M6,$T6) -> 0 | AG6: =MEDIAN($G6,$N6,$U6) -> 0 | AH6: =MEDIAN($H6,$O6,$V6) -> 0 | AI6: =MAX($B6,$I6,$P6) -> 0 | AJ6: =MAX($C6,$J6,$Q6) -> 0 | AK6: =MAX($E6,$L6,$S6) -> 0 | AL6: =MAX($F6,$M6,$T6) -> 0 | AM6: =MAX($G6,$N6,$U6) -> 0 | AN6: =MAX($H6,$O6,$V6) -> 0
A7: instances/size-4 | B7: {=_xlfn.SWITCH($A$2,"average", AVERAGE(Instances!B7:Instances!B7),"median", MEDIAN(Instances!B7:Instances!B7),"min", MIN(Instances!B7:Instances!B7),"max", MAX(Instances!B7:Instances!B7),"diff", MAX(Instances!B7:Instances!B7)-MIN(Instances!B7:Instances!B7))} -> 0 | C7: {=_xlfn.SWITCH($A$2,"average", AVERAGE(Instances!C7:Instances!C7),"median", MEDIAN(Instances!C7:Instances!C7),"min", MIN(Instances!C7:Instances!C7),"max", MAX(Instances!C7:Instances!C7),"diff", MAX(Instances!C7:Instances!C7)-MIN(Instances!C7:Instances!C7))} -> 0 | E7: {=_xlfn.SWITCH($A$2,"average", AVERAGE(Instances!E7:Instances!E7),"median", MEDIAN(Instances!E7:Instances!E7),"min", MIN(Instances!E7:Instances!E7),"max", MAX(Instances!E7:Instances!E7),"diff", MAX(Instances!E7:Instances!E7)-MIN(Instances!E7:Instances!E7))} -> 0 | F7: {=_xlfn.SWITCH($A$2,"average", AVERAGE(Instances!F7:Instances!F7),"median", MEDIAN(Instances!F7:Instances!F7),"min", MIN(Instances!F7:Instances!F7),"max", MAX(Instances!F7:Instances!F7),"diff", MAX(Instances!F7:Instances!F7)-MIN(Instances!F7:Instances!F7))} -> 0 | G7: {=_xlfn.SWITCH($A$2,"average", AVERAGE(Instances!G7:Instances!G7),"median", MEDIAN(Instances!G7:Instances!G7),"min", MIN(Instances!G7:Instances!G7),"max", MAX(Instances!G7:Instances!G7),"diff", MAX(Instances!G7:Instances!G7)-MIN(Instances!G7:Instances!G7))} -> 0 | H7: {=_xlfn.SWITCH($A$2,"average", AVERAGE(Instances!H7:Instances!H7),"median", MEDIAN(Instances!H7:Instances!H7),"min", MIN(Instances!H7:Instances!H7),"max", MAX(Instances!H7:Instances!H7),"diff", MAX(Instances!H7:Instances!H7)-MIN(Instances!H7:Instances!H7))} -> 0 | I7: {=_xlfn.SWITCH($A$2,"average", AVERAGE(Instances!I7:Instances!I7),"median", MEDIAN(Instances!I7:Instances!I7),"min", MIN(Instances!I7:Instances!I7),"max", MAX(Instances!I7:Instances!I7),"diff", MAX(Instances!I7:Instances!I7)-MIN(Instances!I7:Instances!I7))} -> 0 | J7: {=_xlfn.SWITCH($A$2,"average", AVERAGE(Instances!J7:Instances!J7),"median", MEDIAN(Instances!J7:Instances!J7),"min", MIN(Instances!J7:Instances!J7),"max", MAX(Instances!J7:Instances!J7),"diff", MAX(Instances!J7:Instances!J7)-MIN(Instances!J7:Instances!J7))} -> 0 | L7: {=_xlfn.SWITCH($A$2,"average", AVERAGE(Instances!L7:Instances!L7),"median", MEDIAN(Instances!L7:Instances!L7),"min", MIN(Instances!L7:Instances!L7),"max", MAX(Instances!L7:Instances!L7),"diff", MAX(Instances!L7:Instances!L7)-MIN(Instances!L7:Instances!L7))} -> 0 | M7: {=_xlfn.SWITCH($A$2,"average", AVERAGE(Instances!M7:Instances!M7),"median", MEDIAN(Instances!M7:Instances!M7),"min", MIN(Instances!M7:Instances!M7),"max", MAX(Instances!M7:Instances!M7),"diff", MAX(Instances!M7:Instances!M7)-MIN(Instances!M7:Instances!M7))} -> 0 | N7: {=_xlfn.SWITCH($A$2,"average", AVERAGE(Instances!N7:Instances!N7),"median", MEDIAN(Instances!N7:Instances!N7),"min", MIN(Instances!N7:Instances!N7),"max", MAX(Instances!N7:Instances!N7),"diff", MAX(Instances!N7:Instances!N7)-MIN(Instances!N7:Instances!N7))} -> 0 | O7: {=_xlfn.SWITCH($A$2,"average", AVERAGE(Instances!O7:Instances!O7),"median", MEDIAN(Instances!O7:Instances!O7),"min", MIN(Instances!O7:Instances!O7),"max", MAX(Instances!O7:Instances!O7),"diff", MAX(Instances!O7:Instances!O7)-MIN(Instances!O7:Instances!O7))} -> 0 | P7: {=_xlfn.SWITCH($A$2,"average", AVERAGE(Instances!P7:Instances!P7),"median", MEDIAN(Instances!P7:Instances!P7),"min", MIN(Instances!P7:Instances!P7),"max", MAX(Instances!P7:Instances!P7),"diff", MAX(Instances!P7:Instances!P7)-MIN(Instances!P7:Instances!P7))} -> 0 | Q7: {=_xlfn.SWITCH($A$2,"average", AVERAGE(Instances!Q7:Instances!Q7),"median", MEDIAN(Instances!Q7:Instances!Q7),"min", MIN(Instances!Q7:Instances!Q7),"max", MAX(Instances!Q7:Instances!Q7),"diff", MAX(Instances!Q7:Instances!Q7)-MIN(Instances!Q7:Instances!Q7))} -> 0 | S7: {=_xlfn.SWITCH($A$2,"average", AVERAGE(Instances!S7:Instances!S7),"median", MEDIAN(Instances!S7:Instances!S7),"min", MIN(Instances!S7:Instances!S7),"max", MAX(Instances!S7:Instances!S7),"diff", MAX(Instances!S7:Instances!S7)-MIN(Instances!S7:Instances!S7))} -> 0 | T7: {=_xlfn.SWITCH($A$2,"average", AVERAGE(Instances!T7:Instances!T7),"median", MEDIAN(Instances!T7:Instances!T7),"min", MIN(Instances!T7:Instances!T7),"max", MAX(Instances!T7:Instances!T7),"diff", MAX(Instances!T7:Instances!T7)-MIN(Instances!T7:Instances!T7))} -> 0 | U7: {=_xlfn.SWITCH($A$2,"average", AVERAGE(Instances!U7:Instances!U7),"median", MEDIAN(Instances!U7:Instances!U7),"min", MIN(Instances!U7:Instances!U7),"max", MAX(Instances!U7:Instances!U7),"diff", MAX(Instances!U7:Instances!U7)-MIN(Instances!U7:Instances!U7))} -> 0 | V7: {=_xlfn.SWITCH($A$2,"average", AVERAGE(Instances!V7:Instances!V7),"median", MEDIAN(Instances!V7:Instances!V7),"min", MIN(Instances!V7:Instances!V7),"max", MAX(Instances!V7:Instances!V7),"diff", MAX(Instances!V7:Instances!V7)-MIN(Instances!V7:Instances!V7))} -> 0 | W7: =MIN($B7,$I7,$P7) -> 0 | X7: =MIN($C7,$J7,$Q7) -> 0 | Y7: =MIN($E7,$L7,$S7) -> 0 | Z7: =MIN($F7,$M7,$T7) -> 0 | AA7: =MIN($G7,$N7,$U7) -> 0 | AB7: =MIN($H7,$O7,$V7) -> 0 | AC7: =MEDIAN($B7,$I7,$P7) -> 0 | AD7: =MEDIAN($C7,$J7,$Q7) -> 0 | AE7: =MEDIAN($E7,$L7,$S7) -> 0 | AF7: =MEDIAN($F7,$M7,$T7) -> 0 | AG7: =MEDIAN($G7,$N7,$U7) -> 0 | AH7: =MEDIAN($H7,$O7,$V7) -> 0 | AI7: =MAX($B7,$I7,$P7) -> 0 | AJ7: =MAX($C7,$J7,$Q7) -> 0 | AK7: =MAX($E7,$L7,$S7) -> 0 | AL7: =MAX($F7,$M7,$T7) -> 0 | AM7: =MAX($G7,$N7,$U7) -> 0 | AN7: =MAX($H7,$O7,$V7) -> 0
A8: instances/size-5 | B8: {=_xlfn.SWITCH($A$2,"average", AVERAGE(Instances!B8:Instances!B8),"median", MEDIAN(Instances!B8:Instances!B8),"min", MIN(Instances!B8:Instances!B8),"max", MAX(Instances!B8:Instances!B8),"diff", MAX(Instances!B8:Instances!B8)-MIN(Instances!B8:Instances!B8))} -> 0 | C8: {=_xlfn.SWITCH($A$2,"average", AVERAGE(Instances!C8:Instances!C8),"median", MEDIAN(Instances!C8:Instances!C8),"min", MIN(Instances!C8:Instances!C8),"max", MAX(Instances!C8:Instances!C8),"diff", MAX(Instances!C8:Instances!C8)-MIN(Instances!C8:Instances!C8))} -> 0 | E8: {=_xlfn.SWITCH($A$2,"average", AVERAGE(Instances!E8:Instances!E8),"median", MEDIAN(Instances!E8:Instances!E8),"min", MIN(Instances!E8:Instances!E8),"max", MAX(Instances!E8:Instances!E8),"diff", MAX(Instances!E8:Instances!E8)-MIN(Instances!E8:Instances!E8))} -> 0 | F8: {=_xlfn.SWITCH($A$2,"average", AVERAGE(Instances!F8:Instances!F8),"median", MEDIAN(Instances!F8:Instances!F8),"min", MIN(Instances!F8:Instances!F8),"max", MAX(Instances!F8:Instances!F8),"diff", MAX(Instances!F8:Instances!F8)-MIN(Instances!F8:Instances!F8))} -> 0 | G8: {=_xlfn.SWITCH($A$2,"average", AVERAGE(Instances!G8:Instances!G8),"median", MEDIAN(Instances!G8:Instances!G8),"min", MIN(Instances!G8:Instances!G8),"max", MAX(Instances!G8:Instances!G8),"diff", MAX(Instances!G8:Instances!G8)-MIN(Instances!G8:Instances!G8))} -> 0 | H8: {=_xlfn.SWITCH($A$2,"average", AVERAGE(Instances!H8:Instances!H8),"median", MEDIAN(Instances!H8:Instances!H8),"min", MIN(Instances!H8:Instances!H8),"max", MAX(Instances!H8:Instances!H8),"diff", MAX(Instances!H8:Instances!H8)-MIN(Instances!H8:Instances!H8))} -> 0 | I8: {=_xlfn.SWITCH($A$2,"average", AVERAGE(Instances!I8:Instances!I8),"median", MEDIAN(Instances!I8:Instances!I8),"min", MIN(Instances!I8:Instances!I8),"max", MAX(Instances!I8:Instances!I8),"diff", MAX(Instances!I8:Instances!I8)-MIN(Instances!I8:Instances!I8))} -> 0 | J8: {=_xlfn.SWITCH($A$2,"average", AVERAGE(Instances!J8:Instances!J8),"median", MEDIAN(Instances!J8:Instances!J8),"min", MIN(Instances!J8:Instances!J8),"max", MAX(Instances!J8:Instances!J8),"diff", MAX(Instances!J8:Instances!J8)-MIN(Instances!J8:Instances!J8))} -> 0 | L8: {=_xlfn.SWITCH($A$2,"average", AVERAGE(Instances!L8:Instances!L8),"median", MEDIAN(Instances!L8:Instances!L8),"min", MIN(Instances!L8:Instances!L8),"max", MAX(Instances!L8:Instances!L8),"diff", MAX(Instances!L8:Instances!L8)-MIN(Instances!L8:Instances!L8))} -> 0 | M8: {=_xlfn.SWITCH($A$2,"average", AVERAGE(Instances!M8:Instances!M8),"median", MEDIAN(Instances!M8:Instances!M8),"min", MIN(Instances!M8:Instances!M8),"max", MAX(Instances!M8:Instances!M8),"diff", MAX(Instances!M8:Instances!M8)-MIN(Instances!M8:Instances!M8))} -> 0 | N8: {=_xlfn.SWITCH($A$2,"average", AVERAGE(Instances!N8:Instances!N8),"median", MEDIAN(Instances!N8:Instances!N8),"min", MIN(Instances!N8:Instances!N8),"max", MAX(Instances!N8:Instances!N8),"diff", MAX(Instances!N8:Instances!N8)-MIN(Instances!N8:Instances!N8))} -> 0 | O8: {=_xlfn.SWITCH($A$2,"average", AVERAGE(Instances!O8:Instances!O8),"median", MEDIAN(Instances!O8:Instances!O8),"min", MIN(Instances!O8:Instances!O8),"max", MAX(Instances!O8:Instances!O8),"diff", MAX(Instances!O8:Instances!O8)-MIN(Instances!O8:Instances!O8))} -> 0 | P8: {=_xlfn.SWITCH($A$2,"average", AVERAGE(Instances!P8:Instances!P8),"median", MEDIAN(Instances!P8:Instances!P8),"min", MIN(Instances!P8:Instances!P8),"max", MAX(Instances!P8:Instances!P8),"diff", MAX(Instances!P8:Instances!P8)-MIN(Instances!P8:Instances!P8))} -> 0 | Q8: {=_xlfn.SWITCH($A$2,"average", AVERAGE(Instances!Q8:Instances!Q8),"median", MEDIAN(Instances!Q8:Instances!Q8),"min", MIN(Instances!Q8:Instances!Q8),"max", MAX(Instances!Q8:Instances!Q8),"diff", MAX(Instances!Q8:Instances!Q8)-MIN(Instances!Q8:Instances!Q8))} -> 0 | S8: {=_xlfn.SWITCH($A$2,"average", AVERAGE(Instances!S8:Instances!S8),"median", MEDIAN(Instances!S8:Instances!S8),"min", MIN(Instances!S8:Instances!S8),"max", MAX(Instances!S8:Instances!S8),"diff", MAX(Instances!S8:Instances!S8)-MIN(Instances!S8:Instances!S8))} -> 0 | T8: {=_xlfn.SWITCH($A$2,"average", AVERAGE(Instances!T8:Instances!T8),"median", MEDIAN(Instances!T8:Instances!T8),"min", MIN(Instances!T8:Instances!T8),"max", MAX(Instances!T8:Instances!T8),"diff", MAX(Instances!T8:Instances!T8)-MIN(Instances!T8:Instances!T8))} -> 0 | U8: {=_xlfn.SWITCH($A$2,"average", AVERAGE(Instances!U8:Instances!U8),"median", MEDIAN(Instances!U8:Instances!U8),"min", MIN(Instances!U8:Instances!U8),"max", MAX(Instances!U8:Instances!U8),"diff", MAX(Instances!U8:Instances!U8)-MIN(Instances!U8:Instances!U8))} -> 0 | V8: {=_xlfn.SWITCH($A$2,"average", AVERAGE(Instances!V8:Instances!V8),"median", MEDIAN(Instances!V8:Instances!V8),"min", MIN(Instances!V8:Instances!V8),"max", MAX(Instances!V8:Instances!V8),"diff", MAX(Instances!V8:Instances!V8)-MIN(Instances!V8:Instances!V8))} -> 0 | W8: =MIN($B8,$I8,$P8) -> 0 | X8: =MIN($C8,$J8,$Q8) -> 0 | Y8: =MIN($E8,$L8,$S8) -> 0 | Z8: =MIN($F8,$M8,$T8) -> 0 | AA8: =MIN($G8,$N8,$U8) -> 0 | AB8: =MIN($H8,$O8,$V8) -> 0 | AC8: =MEDIAN($B8,$I8,$P8) -> 0 | AD8: =MEDIAN($C8,$J8,$Q8) -> 0 | AE8: =MEDIAN($E8,$L8,$S8) -> 0 | AF8: =MEDIAN($F8,$M8,$T8) -> 0 | AG8: =MEDIAN($G8,$N8,$U8) -> 0 | AH8: =MEDIAN($H8,$O8,$V8) -> 0 | AI8: =MAX($B8,$I8,$P8) -> 0 | AJ8: =MAX($C8,$J8,$Q8) -> 0 | AK8: =MAX($E8,$L8,$S8) -> 0 | AL8: =MAX($F8,$M8,$T8) -> 0 | AM8: =MAX($G8,$N8,$U8) -> 0 | AN8: =MAX($H8,$O8,$V8) -> 0
A9: instances/size-6 | B9: {=_xlfn.SWITCH($A$2,"average", AVERAGE(Instances!B9:Instances!B9),"median", MEDIAN(Instances!B9:Instances!B9),"min", MIN(Instances!B9:Instances!B9),"max", MAX(Instances!B9:Instances!B9),"diff", MAX(Instances!B9:Instances!B9)-MIN(Instances!B9:Instances!B9))} -> 0 | C9: {=_xlfn.SWITCH($A$2,"average", AVERAGE(Instances!C9:Instances!C9),"median", MEDIAN(Instances!C9:Instances!C9),"min", MIN(Instances!C9:Instances!C9),"max", MAX(Instances!C9:Instances!C9),"diff", MAX(Instances!C9:Instances!C9)-MIN(Instances!C9:Instances!C9))} -> 0 | E9: {=_xlfn.SWITCH($A$2,"average", AVERAGE(Instances!E9:Instances!E9),"median", MEDIAN(Instances!E9:Instances!E9),"min", MIN(Instances!E9:Instances!E9),"max", MAX(Instances!E9:Instances!E9),"diff", MAX(Instances!E9:Instances!E9)-MIN(Instances!E9:Instances!E9))} -> 0 | F9: {=_xlfn.SWITCH($A$2,"average", AVERAGE(Instances!F9:Instances!F9),"median", MEDIAN(Instances!F9:Instances!F9),"min", MIN(Instances!F9:Instances!F9),"max", MAX(Instances!F9:Instances!F9),"diff", MAX(Instances!F9:Instances!F9)-MIN(Instances!F9:Instances!F9))} -> 0 | G9: {=_xlfn.SWITCH($A$2,"average", AVERAGE(Instances!G9:Instances!G9),"median", MEDIAN(Instances!G9:Instances!G9),"min", MIN(Instances!G9:Instances!G9),"max", MAX(Instances!G9:Instances!G9),"diff", MAX(Instances!G9:Instances!G9)-MIN(Instances!G9:Instances!G9))} -> 0 | H9: {=_xlfn.SWITCH($A$2,"average", AVERAGE(Instances!H9:Instances!H9),"median", MEDIAN(Instances!H9:Instances!H9),"min", MIN(Instances!H9:Instances!H9),"max", MAX(Instances!H9:Instances!H9),"diff", MAX(Instances!H9:Instances!H9)-MIN(Instances!H9:Instances!H9))} -> 0 | I9: {=_xlfn.SWITCH($A$2,"average", AVERAGE(Instances!I9:Instances!I9),"median", MEDIAN(Instances!I9:Instances!I9),"min", MIN(Instances!I9:Instances!I9),"max", MAX(Instances!I9:Instances!I9),"diff", MAX(Instances!I9:Instances!I9)-MIN(Instances!I9:Instances!I9))} -> 0 | J9: {=_xlfn.SWITCH($A$2,"average", AVERAGE(Instances!J9:Instances!J9),"median", MEDIAN(Instances!J9:Instances!J9),"min", MIN(Instances!J9:Instances!J9),"max", MAX(Instances!J9:Instances!J9),"diff", MAX(Instances!J9:Instances!J9)-MIN(Instances!J9:Instances!J9))} -> 0 | L9: {=_xlfn.SWITCH($A$2,"average", AVERAGE(Instances!L9:Instances!L9),"median", MEDIAN(Instances!L9:Instances!L9),"min", MIN(Instances!L9:Instances!L9),"max", MAX(Instances!L9:Instances!L9),"diff", MAX(Instances!L9:Instances!L9)-MIN(Instances!L9:Instances!L9))} -> 0 | M9: {=_xlfn.SWITCH($A$2,"average", AVERAGE(Instances!M9:Instances!M9),"median", MEDIAN(Instances!M9:Instances!M9),"min", MIN(Instances!M9:Instances!M9),"max", MAX(Instances!M9:Instances!M9),"diff", MAX(Instances!M9:Instances!M9)-MIN(Instances!M9:Instances!M9))} -> 0 | N9: {=_xlfn.SWITCH($A$2,"average", AVERAGE(Instances!N9:Instances!N9),"median", MEDIAN(Instances!N9:Instances!N9),"min", MIN(Instances!N9:Instances!N9),"max", MAX(Instances!N9:Instances!N9),"diff", MAX(Instances!N9:Instances!N9)-MIN(Instances!N9:Instances!N9))} -> 0 | O9: {=_xlfn.SWITCH($A$2,"average", AVERAGE(Instances!O9:Instances!O9),"median", MEDIAN(Instances!O9:Instances!O9),"min", MIN(Instances!O9:Instances!O9),"max", MAX(Instances!O9:Instances!O9),"diff", MAX(Instances!O9:Instances!O9)-MIN(Instances!O9:Instances!O9))} -> 0 | P9: {=_xlfn.SWITCH($A$2,"average", AVERAGE(Instances!P9:Instances!P9),"median", MEDIAN(Instances!P9:Instances!P9),"min", MIN(Instances!P9:Instances!P9),"max", MAX(Instances!P9:Instances!P9),"diff", MAX(Instances!P9:Instances!P9)-MIN(Instances!P9:Instances!P9))} -> 0 | Q9: {=_xlfn.SWITCH($A$2,"average", AVERAGE(Instances!Q9:Instances!Q9),"median", MEDIAN(Instances!Q9:Instances!Q9),"min", MIN(Instances!Q9:Instances!Q9),"max", MAX(Instances!Q9:Instances!Q9),"diff", MAX(Instances!Q9:Instances!Q9)-MIN(Instances!Q9:Instances!Q9))} -> 0 | S9: {=_xlfn.SWITCH($A$2,"average", AVERAGE(Instances!S9:Instances!S9),"median", MEDIAN(Instances!S9:Instances!S9),"min", MIN(Instances!S9:Instances!S9),"max", MAX(Instances!S9:Instances!S9),"diff", MAX(Instances!S9:Instances!S9)-MIN(Instances!S9:Instances!S9))} -> 0 | T9: {=_xlfn.SWITCH($A$2,"average", AVERAGE(Instances!T9:Instances!T9),"median", MEDIAN(Instances!T9:Instances!T9),"min", MIN(Instances!T9:Instances!T9),"max", MAX(Instances!T9:Instances!T9),"diff", MAX(Instances!T9:Instances!T9)-MIN(Instances!T9:Instances!T9))} -> 0 | U9: {=_xlfn.SWITCH($A$2,"average", AVERAGE(Instances!U9:Instances!U9),"median", MEDIAN(Instances!U9:Instances!U9),"min", MIN(Instances!U9:Instances!U9),"max", MAX(Instances!U9:Instances!U9),"diff", MAX(Instances!U9:Instances!U9)-MIN(Instances!U9:Instances!U9))} -> 0 | V9: {=_xlfn.SWITCH($A$2,"average", AVERAGE(Instances!V9:Instances!V9),"median", MEDIAN(Instances!V9:Instances!V9),"min", MIN(Instances!V9:Instances!V9),"max", MAX(Instances!V9:Instances!V9),"diff", MAX(Instances!V9:Instances!V9)-MIN(Instances!V9:Instances!V9))} -> 0 | W9: =MIN($B9,$I9,$P9) -> 0 | X9: =MIN($C9,$J9,$Q9) -> 0 | Y9: =MIN($E9,$L9,$S9) -> 0 | Z9: =MIN($F9,$M9,$T9) -> 0 | AA9: =MIN($G9,$N9,$U9) -> 0 | AB9: =MIN($H9,$O9,$V9) -> 0 | AC9: =MEDIAN($B9,$I9,$P9) -> 0 | AD9: =MEDIAN($C9,$J9,$Q9) -> 0 | AE9: =MEDIAN($E9,$L9,$S9) -> 0 | AF9: =MEDIAN($F9,$M9,$T9) -> 0 | AG9: =MEDIAN($G9,$N9,$U9) -> 0 | AH9: =MEDIAN($H9,$O9,$V9) -> 0 | AI9: =MAX($B9,$I9,$P9) -> 0 | AJ9: =MAX($C9,$J9,$Q9) -> 0 | AK9: =MAX($E9,$L9,$S9) -> 0 | AL9: =MAX($F9,$M9,$T9) -> 0 | AM9: =MAX($G9,$N9,$U9) -> 0 | AN9: =MAX($H9,$O9,$V9) -> 0
