Workbook

Sheet Instances
B1: memelingo-1/lambda-large_100_mlp-tplp-htc | I1: memelingo-1/lambda-large_100_mlp-tplp-htcdl | P1: memelingo-1/lambda-large_50_mlp-tplp-htc | W1: memelingo-1/lambda-large_50_mlp-tplp-htcdl | AD1: memelingo-1/lambda-large_60_mlp-tplp-htc | AK1: memelingo-1/lambda-large_60_mlp-tplp-htcdl | AR1: memelingo-1/lambda-large_70_mlp-tplp-htc | AY1: memelingo-1/lambda-large_70_mlp-tplp-htcdl | BF1: memelingo-1/lambda-large_80_mlp-tplp-htc | BM1: memelingo-1/lambda-large_80_mlp-tplp-htcdl | BT1: memelingo-1/lambda-large_90_mlp-tplp-htc | CA1: memelingo-1/lambda-large_90_mlp-tplp-htcdl | CH1: memelingo-1/lambda-small_10_mlp-tplp-ht | CO1: memelingo-1/lambda-small_10_mlp-tplp-htc | CV1: memelingo-1/lambda-small_10_mlp-tplp-htcdl | DC1: memelingo-1/lambda-small_12_mlp-tplp-ht | DJ1: memelingo-1/lambda-small_12_mlp-tplp-htc | DQ1: memelingo-1/lambda-small_12_mlp-tplp-htcdl | DX1: memelingo-1/lambda-small_14_mlp-tplp-ht | EE1: memelingo-1/lambda-small_14_mlp-tplp-htc | EL1: memelingo-1/lambda-small_14_mlp-tplp-htcdl | ES1: memelingo-1/lambda-small_16_mlp-tplp-ht | EZ1: memelingo-1/lambda-small_16_mlp-tplp-htc | FG1: memelingo-1/lambda-small_16_mlp-tplp-htcdl | FN1: memelingo-1/lambda-small_18_mlp-tplp-ht | FU1: memelingo-1/lambda-small_18_mlp-tplp-htc | GB1: memelingo-1/lambda-small_18_mlp-tplp-htcdl | GI1: memelingo-1/lambda-small_20_mlp-tplp-ht | GP1: memelingo-1/lambda-small_20_mlp-tplp-htc | GW1: memelingo-1/lambda-small_20_mlp-tplp-htcdl | HD1: memelingo-1/lambda-small_22_mlp-tplp-ht | HK1: memelingo-1/lambda-small_22_mlp-tplp-htc | HR1: memelingo-1/lambda-small_22_mlp-tplp-htcdl | HY1: memelingo-1/lambda-small_24_mlp-tplp-ht | IF1: memelingo-1/lambda-small_24_mlp-tplp-htc | IM1: memelingo-1/lambda-small_24_mlp-tplp-htcdl | IT1: memelingo-1/lambda-small_26_mlp-tplp-ht | JA1: memelingo-1/lambda-small_26_mlp-tplp-htc | JH1: memelingo-1/lambda-small_26_mlp-tplp-htcdl | JO1: memelingo-1/lambda-small_28_mlp-tplp-ht | JV1: memelingo-1/lambda-small_28_mlp-tplp-htc | KC1: memelingo-1/lambda-small_28_mlp-tplp-htcdl | KJ1: memelingo-1/lambda-small_30_mlp-tplp-ht | KQ1: memelingo-1/lambda-small_30_mlp-tplp-htc | KX1: memelingo-1/lambda-small_30_mlp-tplp-htcdl | LE1: min | LK1: median | LQ1: max
B2: time | C2: stime | D2: status | E2: rules | F2: ctime | G2: fmtime | H2: memout | I2: time | J2: stime | K2: status | L2: rules | M2: ctime | N2: fmtime | O2: memout | P2: time | Q2: stime | R2: status | S2: rules | T2: ctime | U2: fmtime | V2: memout | W2: time | X2: stime | Y2: status | Z2: rules | AA2: ctime | AB2: fmtime | AC2: memout | AD2: time | AE2: stime | AF2: status | AG2: rules | AH2: ctime | AI2: fmtime | AJ2: memout | AK2: time | AL2: stime | AM2: status | AN2: rules | AO2: ctime | AP2: fmtime | AQ2: memout | AR2: time | AS2: stime | AT2: status | AU2: rules | AV2: ctime | AW2: fmtime | AX2: memout | AY2: time | AZ2: stime | BA2: status | BB2: rules | BC2: ctime | BD2: fmtime | BE2: memout | BF2: time | BG2: stime | BH2: status | BI2: rules | BJ2: ctime | BK2: fmtime | BL2: memout | BM2: time | BN2: stime | BO2: status | BP2: rules | BQ2: ctime | BR2: fmtime | BS2: memout | BT2: time | BU2: stime | BV2: status | BW2: rules | BX2: ctime | BY2: fmtime | BZ2: memout | CA2: time | CB2: stime | CC2: status | CD2: rules | CE2: ctime | CF2: fmtime | CG2: memout | CH2: time | CI2: stime | CJ2: status | CK2: rules | CL2: ctime | CM2: fmtime | CN2: memout | CO2: time | CP2: stime | CQ2: status | CR2: rules | CS2: ctime | CT2: fmtime | CU2: memout | CV2: time | CW2: stime | CX2: status | CY2: rules | CZ2: ctime | DA2: fmtime | DB2: memout | DC2: time | DD2: stime | DE2: status | DF2: rules | DG2: ctime | DH2: fmtime | DI2: memout | DJ2: time | DK2: stime | DL2: status | DM2: rules | DN2: ctime | DO2: fmtime | DP2: memout | DQ2: time | DR2: stime | DS2: status | DT2: rules | DU2: ctime | DV2: fmtime | DW2: memout | DX2: time | DY2: stime | DZ2: status | EA2: rules | EB2: ctime | EC2: fmtime | ED2: memout | EE2: time | EF2: stime | EG2: status | EH2: rules | EI2: ctime | EJ2: fmtime | EK2: memout | EL2: time | EM2: stime | EN2: status | EO2: rules | EP2: ctime | EQ2: fmtime | ER2: memout | ES2: time | ET2: stime | EU2: status | EV2: rules | EW2: ctime | EX2: fmtime | EY2: memout | EZ2: time | FA2: stime | FB2: status | FC2: rules | FD2: ctime | FE2: fmtime | FF2: memout | FG2: time | FH2: stime | FI2: status | FJ2: rules | FK2: ctime | FL2: fmtime | FM2: memout | FN2: time | FO2: stime | FP2: status | FQ2: rules | FR2: ctime | FS2: fmtime | FT2: memout | FU2: time | FV2: stime | FW2: status | FX2: rules | FY2: ctime | FZ2: fmtime | GA2: memout | GB2: time | GC2: stime | GD2: status | GE2: rules | GF2: ctime | GG2: fmtime | GH2: memout | GI2: time | GJ2: stime | GK2: status | GL2: rules | GM2: ctime | GN2: fmtime | GO2: memout | GP2: time | GQ2: stime | GR2: status | GS2: rules | GT2: ctime | GU2: fmtime | GV2: memout | GW2: time | GX2: stime | GY2: status | GZ2: rules | HA2: ctime | HB2: fmtime | HC2: memout | HD2: time | HE2: stime | HF2: status | HG2: rules | HH2: ctime | HI2: fmtime | HJ2: memout | HK2: time | HL2: stime | HM2: status | HN2: rules | HO2: ctime | HP2: fmtime | HQ2: memout | HR2: time | HS2: stime | HT2: status | HU2: rules | HV2: ctime | HW2: fmtime | HX2: memout | HY2: time | HZ2: stime | IA2: status | IB2: rules | IC2: ctime | ID2: fmtime | IE2: memout | IF2: time | IG2: stime | IH2: status | II2: rules | IJ2: ctime | IK2: fmtime | IL2: memout | IM2: time | IN2: stime | IO2: status | IP2: rules | IQ2: ctime | IR2: fmtime | IS2: memout | IT2: time | IU2: stime | IV2: status | IW2: rules | IX2: ctime | IY2: fmtime | IZ2: memout | JA2: time | JB2: stime | JC2: status | JD2: rules | JE2: ctime | JF2: fmtime | JG2: memout | JH2: time | JI2: stime | JJ2: status | JK2: rules | JL2: ctime | JM2: fmtime | JN2: memout | JO2: time | JP2: stime | JQ2: status | JR2: rules | JS2: ctime | JT2: fmtime | JU2: memout | JV2: time | JW2: stime | JX2: status | JY2: rules | JZ2: ctime | KA2: fmtime | KB2: memout | KC2: time | KD2: stime | KE2: status | KF2: rules | KG2: ctime | KH2: fmtime | KI2: memout | KJ2: time | KK2: stime | KL2: status | KM2: rules | KN2: ctime | KO2: fmtime | KP2: memout | KQ2: time | KR2: stime | KS2: status | KT2: rules | KU2: ctime | KV2: fmtime | KW2: memout | KX2: time | KY2: stime | KZ2: status | LA2: rules | LB2: ctime | LC2: fmtime | LD2: memout | LE2: time | LF2: stime | LG2: rules | LH2: ctime | LI2: fmtime | LJ2: memout | LK2: time | LL2: stime | LM2: rules | LN2: ctime | LO2: fmtime | LP2: memout | LQ2: time | LR2: stime | LS2: rules | LT2: ctime | LU2: fmtime | LV2: memout
A3: instances/ft06 | CH3: 305.24 | CI3: 301.99 | CJ3: UNSATISFIABLE | CK3: 1706309 | CL3: 304.195 | CM3: 0 | CN3: 0 | CO3: 5.15 | CP3: 3.72 | CQ3: UNSATISFIABLE | CR3: 77412 | CS3: 4.245 | CT3: 0 | CU3: 0 | CV3: 2.79 | CW3: 1.36 | CX3: UNSATISFIABLE | CY3: 77412 | CZ3: 1.853 | DA3: 0 | DB3: 0 | DC3: 187.05 | DD3: 181.83 | DE3: SATISFIABLE | DF3: 2382385 | DG3: 186.087 | DH3: 181.82 | DI3: 0 | DJ3: 6.83 | DK3: 5.2 | DL3: SATISFIABLE | DM3: 99538 | DN3: 5.874 | DO3: 5.2 | DP3: 0 | DQ3: 3.66 | DR3: 2.05 | DS3: SATISFIABLE | DT3: 99538 | DU3: 2.669 | DV3: 2.05 | DW3: 0 | DX3: 297.9 | DY3: 291.33 | DZ3: SATISFIABLE | EA3: 3130018 | EB3: 297.001 | EC3: 291.33 | ED3: 0 | EE3: 14.75 | EF3: 13.12 | EG3: SATISFIABLE | EH3: 124080 | EI3: 13.879 | EJ3: 13.12 | EK3: 0 | EL3: 5.38 | EM3: 3.74 | EN3: SATISFIABLE | EO3: 124080 | EP3: 4.485 | EQ3: 3.74 | ER3: 0 | ES3: 325.45 | ET3: 317.76 | EU3: SATISFIABLE | EV3: 3933884 | EW3: 324.541 | EX3: 317.76 | EY3: 0 | EZ3: 7.11 | FA3: 5.18 | FB3: SATISFIABLE | FC3: 151038 | FD3: 6.163 | FE3: 5.18 | FF3: 0 | FG3: 3.82 | FH3: 2.21 | FI3: SATISFIABLE | FJ3: 151038 | FK3: 2.874 | FL3: 2.21 | FM3: 0 | FN3: 103.57 | FO3: 94.35 | FP3: SATISFIABLE | FQ3: 4779571 | FR3: 102.614 | FS3: 94.34 | FT3: 0 | FU3: 5.78 | FV3: 3.64 | FW3: SATISFIABLE | FX3: 180412 | FY3: 4.797 | FZ3: 3.63 | GA3: 0 | GB3: 3.57 | GC3: 1.46 | GD3: SATISFIABLE | GE3: 180412 | GF3: 2.548 | GG3: 1.45 | GH3: 0 | GI3: 42.65 | GJ3: 31.36 | GK3: SATISFIABLE | GL3: 5653579 | GM3: 41.585 | GN3: 31.35 | GO3: 0 | GP3: 6.68 | GQ3: 4.29 | GR3: SATISFIABLE | GS3: 212202 | GT3: 5.701 | GU3: 4.28 | GV3: 0 | GW3: 7.42 | GX3: 5.36 | GY3: SATISFIABLE | GZ3: 212202 | HA3: 6.466 | HB3: 5.36 | HC3: 0 | HD3: 74.62 | HE3: 61.78 | HF3: SATISFIABLE | HG3: 6543320 | HH3: 73.575 | HI3: 61.77 | HJ3: 0 | HK3: 8.42 | HL3: 5.76 | HM3: SATISFIABLE | HN3: 246408 | HO3: 7.396 | HP3: 5.75 | HQ3: 0 | HR3: 6.07 | HS3: 3.53 | HT3: SATISFIABLE | HU3: 246408 | HV3: 5.051 | HW3: 3.53 | HX3: 0 | HY3: 62.97 | HZ3: 48.14 | IA3: SATISFIABLE | IB3: 7437118 | IC3: 61.895 | ID3: 48.13 | IE3: 0 | IF3: 3.77 | IG3: 1.18 | IH3: SATISFIABLE | II3: 283030 | IJ3: 2.777 | IK3: 1.18 | IL3: 0 | IM3: 8.76 | IN3: 6.41 | IO3: SATISFIABLE | IP3: 283030 | IQ3: 7.83 | IR3: 6.41 | IS3: 0 | IT3: 51.74 | IU3: 36.04 | IV3: SATISFIABLE | IW3: 8324209 | IX3: 50.647 | IY3: 36.03 | IZ3: 0 | JA3: 10.71 | JB3: 7.56 | JC3: SATISFIABLE | JD3: 322068 | JE3: 9.666 | JF3: 7.55 | JG3: 0 | JH3: 11.4 | JI3: 8.5 | JJ3: SATISFIABLE | JK3: 322068 | JL3: 10.409 | JM3: 8.49 | JN3: 0 | JO3: 62.61 | JP3: 44.6 | JQ3: SATISFIABLE | JR3: 9194741 | JS3: 61.455 | JT3: 44.6 | JU3: 0 | JV3: 5.2 | JW3: 2.09 | JX3: SATISFIABLE | JY3: 363522 | JZ3: 4.116 | KA3: 2.08 | KB3: 0 | KC3: 12.75 | KD3: 9.41 | KE3: SATISFIABLE | KF3: 363522 | KG3: 11.683 | KH3: 9.4 | KI3: 0 | KJ3: 44.13 | KK3: 24.26 | KL3: SATISFIABLE | KM3: 10039774 | KN3: 42.875 | KO3: 24.25 | KP3: 0 | KQ3: 12.47 | KR3: 8.5 | KS3: SATISFIABLE | KT3: 407392 | KU3: 11.372 | KV3: 8.49 | KW3: 0 | KX3: 10.12 | KY3: 6.4 | KZ3: SATISFIABLE | LA3: 407392 | LB3: 9.019 | LC3: 6.39 | LD3: 0 | LE3: =MIN($B3,$I3,$P3,$W3,$AD3,$AK3,$AR3,$AY3,$BF3,$BM3,$BT3,$CA3,$CH3,$CO3,$CV3,$DC3,$DJ3,$DQ3,$DX3,$EE3,$EL3,$ES3,$EZ3,$FG3,$FN3,$FU3,$GB3,$GI3,$GP3,$GW3,$HD3,$HK3,$HR3,$HY3,$IF3,$IM3,$IT3,$JA3,$JH3,$JO3,$JV3,$KC3,$KJ3,$KQ3,$KX3) -> 0 | LF3: =MIN($C3,$J3,$Q3,$X3,$AE3,$AL3,$AS3,$AZ3,$BG3,$BN3,$BU3,$CB3,$CI3,$CP3,$CW3,$DD3,$DK3,$DR3,$DY3,$EF3,$EM3,$ET3,$FA3,$FH3,$FO3,$FV3,$GC3,$GJ3,$GQ3,$GX3,$HE3,$HL3,$HS3,$HZ3,$IG3,$IN3,$IU3,$JB3,$JI3,$JP3,$JW3,$KD3,$KK3,$KR3,$KY3) -> 0 | LG3: =MIN($E3,$L3,$S3,$Z3,$AG3,$AN3,$AU3,$BB3,$BI3,$BP3,$BW3,$CD3,$CK3,$CR3,$CY3,$DF3,$DM3,$DT3,$EA3,$EH3,$EO3,$EV3,$FC3,$FJ3,$FQ3,$FX3,$GE3,$GL3,$GS3,$GZ3,$HG3,$HN3,$HU3,$IB3,$II3,$IP3,$IW3,$JD3,$JK3,$JR3,$JY3,$KF3,$KM3,$KT3,$LA3) -> 0 | LH3: =MIN($F3,$M3,$T3,$AA3,$AH3,$AO3,$AV3,$BC3,$BJ3,$BQ3,$BX3,$CE3,$CL3,$CS3,$CZ3,$DG3,$DN3,$DU3,$EB3,$EI3,$EP3,$EW3,$FD3,$FK3,$FR3,$FY3,$GF3,$GM3,$GT3,$HA3,$HH3,$HO3,$HV3,$IC3,$IJ3,$IQ3,$IX3,$JE3,$JL3,$JS3,$JZ3,$KG3,$KN3,$KU3,$LB3) -> 0 | LI3: =MIN($G3,$N3,$U3,$AB3,$AI3,$AP3,$AW3,$BD3,$BK3,$BR3,$BY3,$CF3,$CM3,$CT3,$DA3,$DH3,$DO3,$DV3,$EC3,$EJ3,$EQ3,$EX3,$FE3,$FL3,$FS3,$FZ3,$GG3,$GN3,$GU3,$HB3,$HI3,$HP3,$HW3,$ID3,$IK3,$IR3,$IY3,$JF3,$JM3,$JT3,$KA3,$KH3,$KO3,$KV3,$LC3) -> 0 | LJ3: =MIN($H3,$O3,$V3,$AC3,$AJ3,$AQ3,$AX3,$BE3,$BL3,$BS3,$BZ3,$CG3,$CN3,$CU3,$DB3,$DI3,$DP3,$DW3,$ED3,$EK3,$ER3,$EY3,$FF3,$FM3,$FT3,$GA3,$GH3,$GO3,$GV3,$HC3,$HJ3,$HQ3,$HX3,$IE3,$IL3,$IS3,$IZ3,$JG3,$JN3,$JU3,$KB3,$KI3,$KP3,$KW3,$LD3) -> 0 | LK3: =MEDIAN($B3,$I3,$P3,$W3,$AD3,$AK3,$AR3,$AY3,$BF3,$BM3,$BT3,$CA3,$CH3,$CO3,$CV3,$DC3,$DJ3,$DQ3,$DX3,$EE3,$EL3,$ES3,$EZ3,$FG3,$FN3,$FU3,$GB3,$GI3,$GP3,$GW3,$HD3,$HK3,$HR3,$HY3,$IF3,$IM3,$IT3,$JA3,$JH3,$JO3,$JV3,$KC3,$KJ3,$KQ3,$KX3) -> 0 | LL3: =MEDIAN($C3,$J3,$Q3,$X3,$AE3,$AL3,$AS3,$AZ3,$BG3,$BN3,$BU3,$CB3,$CI3,$CP3,$CW3,$DD3,$DK3,$DR3,$DY3,$EF3,$EM3,$ET3,$FA3,$FH3,$FO3,$FV3,$GC3,$GJ3,$GQ3,$GX3,$HE3,$HL3,$HS3,$HZ3,$IG3,$IN3,$IU3,$JB3,$JI3,$JP3,$JW3,$KD3,$KK3,$KR3,$KY3) -> 0 | LM3: =MEDIAN($E3,$L3,$S3,$Z3,$AG3,$AN3,$AU3,$BB3,$BI3,$BP3,$BW3,$CD3,$CK3,$CR3,$CY3,$DF3,$DM3,$DT3,$EA3,$EH3,$EO3,$EV3,$FC3,$FJ3,$FQ3,$FX3,$GE3,$GL3,$GS3,$GZ3,$HG3,$HN3,$HU3,$IB3,$II3,$IP3,$IW3,$JD3,$JK3,$JR3,$JY3,$KF3,$KM3,$KT3,$LA3) -> 0 | LN3: =MEDIAN($F3,$M3,$T3,$AA3,$AH3,$AO3,$AV3,$BC3,$BJ3,$BQ3,$BX3,$CE3,$CL3,$CS3,$CZ3,$DG3,$DN3,$DU3,$EB3,$EI3,$EP3,$EW3,$FD3,$FK3,$FR3,$FY3,$GF3,$GM3,$GT3,$HA3,$HH3,$HO3,$HV3,$IC3,$IJ3,$IQ3,$IX3,$JE3,$JL3,$JS3,$JZ3,$KG3,$KN3,$KU3,$LB3) -> 0 | LO3: =MEDIAN($G3,$N3,$U3,$AB3,$AI3,$AP3,$AW3,$BD3,$BK3,$BR3,$BY3,$CF3,$CM3,$CT3,$DA3,$DH3,$DO3,$DV3,$EC3,$EJ3,$EQ3,$EX3,$FE3,$FL3,$FS3,$FZ3,$GG3,$GN3,$GU3,$HB3,$HI3,$HP3,$HW3,$ID3,$IK3,$IR3,$IY3,$JF3,$JM3,$JT3,$KA3,$KH3,$KO3,$KV3,$LC3) -> 0 | LP3: =MEDIAN($H3,$O3,$V3,$AC3,$AJ3,$AQ3,$AX3,$BE3,$BL3,$BS3,$BZ3,$CG3,$CN3,$CU3,$DB3,$DI3,$DP3,$DW3,$ED3,$EK3,$ER3,$EY3,$FF3,$FM3,$FT3,$GA3,$GH3,$GO3,$GV3,$HC3,$HJ3,$HQ3,$HX3,$IE3,$IL3,$IS3,$IZ3,$JG3,$JN3,$JU3,$KB3,$KI3,$KP3,$KW3,$LD3) -> 0 | LQ3: =MAX($B3,$I3,$P3,$W3,$AD3,$AK3,$AR3,$AY3,$BF3,$BM3,$BT3,$CA3,$CH3,$CO3,$CV3,$DC3,$DJ3,$DQ3,$DX3,$EE3,$EL3,$ES3,$EZ3,$FG3,$FN3,$FU3,$GB3,$GI3,$GP3,$GW3,$HD3,$HK3,$HR3,$HY3,$IF3,$IM3,$IT3,$JA3,$JH3,$JO3,$JV3,$KC3,$KJ3,$KQ3,$KX3) -> 0 | LR3: =MAX($C3,$J3,$Q3,$X3,$AE3,$AL3,$AS3,$AZ3,$BG3,$BN3,$BU3,$CB3,$CI3,$CP3,$CW3,$DD3,$DK3,$DR3,$DY3,$EF3,$EM3,$ET3,$FA3,$FH3,$FO3,$FV3,$GC3,$GJ3,$GQ3,$GX3,$HE3,$HL3,$HS3,$HZ3,$IG3,$IN3,$IU3,$JB3,$JI3,$JP3,$JW3,$KD3,$KK3,$KR3,$KY3) -> 0 | LS3: =MAX($E3,$L3,$S3,$Z3,$AG3,$AN3,$AU3,$BB3,$BI3,$BP3,$BW3,$CD3,$CK3,$CR3,$CY3,$DF3,$DM3,$DT3,$EA3,$EH3,$EO3,$EV3,$FC3,$FJ3,$FQ3,$FX3,$GE3,$GL3,$GS3,$GZ3,$HG3,$HN3,$HU3,$IB3,$II3,$IP3,$IW3,$JD3,$JK3,$JR3,$JY3,$KF3,$KM3,$KT3,$LA3) -> 0 | LT3: =MAX($F3,$M3,$T3,$AA3,$AH3,$AO3,$AV3,$BC3,$BJ3,$BQ3,$BX3,$CE3,$CL3,$CS3,$CZ3,$DG3,$DN3,$DU3,$EB3,$EI3,$EP3,$EW3,$FD3,$FK3,$FR3,$FY3,$GF3,$GM3,$GT3,$HA3,$HH3,$HO3,$HV3,$IC3,$IJ3,$IQ3,$IX3,$JE3,$JL3,$JS3,$JZ3,$KG3,$KN3,$KU3,$LB3) -> 0 | LU3: =MAX($G3,$N3,$U3,$AB3,$AI3,$AP3,$AW3,$BD3,$BK3,$BR3,$BY3,$CF3,$CM3,$CT3,$DA3,$DH3,$DO3,$DV3,$EC3,$EJ3,$EQ3,$EX3,$FE3,$FL3,$FS3,$FZ3,$GG3,$GN3,$GU3,$HB3,$HI3,$HP3,$HW3,$ID3,$IK3,$IR3,$IY3,$JF3,$JM3,$JT3,$KA3,$KH3,$KO3,$KV3,$LC3) -> 0 | LV3: =MAX($H3,$O3,$V3,$AC3,$AJ3,$AQ3,$AX3,$BE3,$BL3,$BS3,$BZ3,$CG3,$CN3,$CU3,$DB3,$DI3,$DP3,$DW3,$ED3,$EK3,$ER3,$EY3,$FF3,$FM3,$FT3,$GA3,$GH3,$GO3,$GV3,$HC3,$HJ3,$HQ3,$HX3,$IE3,$IL3,$IS3,$IZ3,$JG3,$JN3,$JU3,$KB3,$KI3,$KP3,$KW3,$LD3) -> 0
A4: instances/ft10 | B4: 1200 | H4: 0 | I4: 1200 | O4: 0 | P4: 1200 | V4: 0 | W4: 1200 | AC4: 0 | AD4: 1200 | AJ4: 0 | AK4: 1200 | AQ4: 0 | AR4: 1200 | AX4: 0 | AY4: 1200 | BE4: 0 | BF4: 1200 | BL4: 0 | BM4: 1200 | BS4: 0 | BT4: 1200 | BZ4: 0 | CA4: 1200 | CG4: 0 | LE4: =MIN($B4,$I4,$P4,$W4,$AD4,$AK4,$AR4,$AY4,$BF4,$BM4,$BT4,$CA4,$CH4,$CO4,$CV4,$DC4,$DJ4,$DQ4,$DX4,$EE4,$EL4,$ES4,$EZ4,$FG4,$FN4,$FU4,$GB4,$GI4,$GP4,$GW4,$HD4,$HK4,$HR4,$HY4,$IF4,$IM4,$IT4,$JA4,$JH4,$JO4,$JV4,$KC4,$KJ4,$KQ4,$KX4) -> 0 | LJ4: =MIN($H4,$O4,$V4,$AC4,$AJ4,$AQ4,$AX4,$BE4,$BL4,$BS4,$BZ4,$CG4,$CN4,$CU4,$DB4,$DI4,$DP4,$DW4,$ED4,$EK4,$ER4,$EY4,$FF4,$FM4,$FT4,$GA4,$GH4,$GO4,$GV4,$HC4,$HJ4,$HQ4,$HX4,$IE4,$IL4,$IS4,$IZ4,$JG4,$JN4,$JU4,$KB4,$KI4,$KP4,$KW4,$LD4) -> 0 | LK4: =MEDIAN($B4,$I4,$P4,$W4,$AD4,$AK4,$AR4,$AY4,$BF4,$BM4,$BT4,$CA4,$CH4,$CO4,$CV4,$DC4,$DJ4,$DQ4,$DX4,$EE4,$EL4,$ES4,$EZ4,$FG4,$FN4,$FU4,$GB4,$GI4,$GP4,$GW4,$HD4,$HK4,$HR4,$HY4,$IF4,$IM4,$IT4,$JA4,$JH4,$JO4,$JV4,$KC4,$KJ4,$KQ4,$KX4) -> 0 | LP4: =MEDIAN($H4,$O4,$V4,$AC4,$AJ4,$AQ4,$AX4,$BE4,$BL4,$BS4,$BZ4,$CG4,$CN4,$CU4,$DB4,$DI4,$DP4,$DW4,$ED4,$EK4,$ER4,$EY4,$FF4,$FM4,$FT4,$GA4,$GH4,$GO4,$GV4,$HC4,$HJ4,$HQ4,$HX4,$IE4,$IL4,$IS4,$IZ4,$JG4,$JN4,$JU4,$KB4,$KI4,$KP4,$KW4,$LD4) -> 0 | LQ4: =MAX($B4,$I4,$P4,$W4,$AD4,$AK4,$AR4,$AY4,$BF4,$BM4,$BT4,$CA4,$CH4,$CO4,$CV4,$DC4,$DJ4,$DQ4,$DX4,$EE4,$EL4,$ES4,$EZ4,$FG4,$FN4,$FU4,$GB4,$GI4,$GP4,$GW4,$HD4,$HK4,$HR4,$HY4,$IF4,$IM4,$IT4,$JA4,$JH4,$JO4,$JV4,$KC4,$KJ4,$KQ4,$KX4) -> 0 | LV4: =MAX($H4,$O4,$V4,$AC4,$AJ4,$AQ4,$AX4,$BE4,$BL4,$BS4,$BZ4,$CG4,$CN4,$CU4,$DB4,$DI4,$DP4,$DW4,$ED4,$EK4,$ER4,$EY4,$FF4,$FM4,$FT4,$GA4,$GH4,$GO4,$GV4,$HC4,$HJ4,$HQ4,$HX4,$IE4,$IL4,$IS4,$IZ4,$JG4,$JN4,$JU4,$KB4,$KI4,$KP4,$KW4,$LD4) -> 0
A6: SUM | B6: =SUM(B$3:B$4) -> 0 | H6: =SUM(H$3:H$4) -> 0 | I6: =SUM(I$3:I$4) -> 0 | O6: =SUM(O$3:O$4) -> 0 | P6: =SUM(P$3:P$4) -> 0 | V6: =SUM(V$3:V$4) -> 0 | W6: =SUM(W$3:W$4) -> 0 | AC6: =SUM(AC$3:AC$4) -> 0 | AD6: =SUM(AD$3:AD$4) -> 0 | AJ6: =SUM(AJ$3:AJ$4) -> 0 | AK6: =SUM(AK$3:AK$4) -> 0 | AQ6: =SUM(AQ$3:AQ$4) -> 0 | AR6: =SUM(AR$3:AR$4) -> 0 | AX6: =SUM(AX$3:AX$4) -> 0 | AY6: =SUM(AY$3:AY$4) -> 0 | BE6: =SUM(BE$3:BE$4) -> 0 | BF6: =SUM(BF$3:BF$4) -> 0 | BL6: =SUM(BL$3:BL$4) -> 0 | BM6: =SUM(BM$3:BM$4) -> 0 | BS6: =SUM(BS$3:BS$4) -> 0 | BT6: =SUM(BT$3:BT$4) -> 0 | BZ6: =SUM(BZ$3:BZ$4) -> 0 | CA6: =SUM(CA$3:CA$4) -> 0 | CG6: =SUM(CG$3:CG$4) -> 0 | CH6: =SUM(CH$3:CH$4) -> 0 | CI6: =SUM(CI$3:CI$4) -> 0 | CK6: =SUM(CK$3:CK$4) -> 0 | CL6: =SUM(CL$3:CL$4) -> 0 | CM6: =SUM(CM$3:CM$4) -> 0 | CN6: =SUM(CN$3:CN$4) -> 0 | CO6: =SUM(CO$3:CO$4) -> 0 | CP6: =SUM(CP$3:CP$4) -> 0 | CR6: =SUM(CR$3:CR$4) -> 0 | CS6: =SUM(CS$3:CS$4) -> 0 | CT6: =SUM(CT$3:CT$4) -> 0 | CU6: =SUM(CU$3:CU$4) -> 0 | CV6: =SUM(CV$3:CV$4) -> 0 | CW6: =SUM(CW$3:CW$4) -> 0 | CY6: =SUM(CY$3:CY$4) -> 0 | CZ6: =SUM(CZ$3:CZ$4) -> 0 | DA6: =SUM(DA$3:DA$4) -> 0 | DB6: =SUM(DB$3:DB$4) -> 0 | DC6: =SUM(DC$3:DC$4) -> 0 | DD6: =SUM(DD$3:DD$4) -> 0 | DF6: =SUM(DF$3:DF$4) -> 0 | DG6: =SUM(DG$3:DG$4) -> 0 | DH6: =SUM(DH$3:DH$4) -> 0 | DI6: =SUM(DI$3:DI$4) -> 0 | DJ6: =SUM(DJ$3:DJ$4) -> 0 | DK6: =SUM(DK$3:DK$4) -> 0 | DM6: =SUM(DM$3:DM$4) -> 0 | DN6: =SUM(DN$3:DN$4) -> 0 | DO6: =SUM(DO$3:DO$4) -> 0 | DP6: =SUM(DP$3:DP$4) -> 0 | DQ6: =SUM(DQ$3:DQ$4) -> 0 | DR6: =SUM(DR$3:DR$4) -> 0 | DT6: =SUM(DT$3:DT$4) -> 0 | DU6: =SUM(DU$3:DU$4) -> 0 | DV6: =SUM(DV$3:DV$4) -> 0 | DW6: =SUM(DW$3:DW$4) -> 0 | DX6: =SUM(DX$3:DX$4) -> 0 | DY6: =SUM(DY$3:DY$4) -> 0 | EA6: =SUM(EA$3:EA$4) -> 0 | EB6: =SUM(EB$3:EB$4) -> 0 | EC6: =SUM(EC$3:EC$4) -> 0 | ED6: =SUM(ED$3:ED$4) -> 0 | EE6: =SUM(EE$3:EE$4) -> 0 | EF6: =SUM(EF$3:EF$4) -> 0 | EH6: =SUM(EH$3:EH$4) -> 0 | EI6: =SUM(EI$3:EI$4) -> 0 | EJ6: =SUM(EJ$3:EJ$4) -> 0 | EK6: =SUM(EK$3:EK$4) -> 0 | EL6: =SUM(EL$3:EL$4) -> 0 | EM6: =SUM(EM$3:EM$4) -> 0 | EO6: =SUM(EO$3:EO$4) -> 0 | EP6: =SUM(EP$3:EP$4) -> 0 | EQ6: =SUM(EQ$3:EQ$4) -> 0 | ER6: =SUM(ER$3:ER$4) -> 0 | ES6: =SUM(ES$3:ES$4) -> 0 | ET6: =SUM(ET$3:ET$4) -> 0 | EV6: =SUM(EV$3:EV$4) -> 0 | EW6: =SUM(EW$3:EW$4) -> 0 | EX6: =SUM(EX$3:EX$4) -> 0 | EY6: =SUM(EY$3:EY$4) -> 0 | EZ6: =SUM(EZ$3:EZ$4) -> 0 | FA6: =SUM(FA$3:FA$4) -> 0 | FC6: =SUM(FC$3:FC$4) -> 0 | FD6: =SUM(FD$3:FD$4) -> 0 | FE6: =SUM(FE$3:FE$4) -> 0 | FF6: =SUM(FF$3:FF$4) -> 0 | FG6: =SUM(FG$3:FG$4) -> 0 | FH6: =SUM(FH$3:FH$4) -> 0 | FJ6: =SUM(FJ$3:FJ$4) -> 0 | FK6: =SUM(FK$3:FK$4) -> 0 | FL6: =SUM(FL$3:FL$4) -> 0 | FM6: =SUM(FM$3:FM$4) -> 0 | FN6: =SUM(FN$3:FN$4) -> 0 | FO6: =SUM(FO$3:FO$4) -> 0 | FQ6: =SUM(FQ$3:FQ$4) -> 0 | FR6: =SUM(FR$3:FR$4) -> 0 | FS6: =SUM(FS$3:FS$4) -> 0 | FT6: =SUM(FT$3:FT$4) -> 0 | FU6: =SUM(FU$3:FU$4) -> 0 | FV6: =SUM(FV$3:FV$4) -> 0 | FX6: =SUM(FX$3:FX$4) -> 0 | FY6: =SUM(FY$3:FY$4) -> 0 | FZ6: =SUM(FZ$3:FZ$4) -> 0 | GA6: =SUM(GA$3:GA$4) -> 0 | GB6: =SUM(GB$3:GB$4) -> 0 | GC6: =SUM(GC$3:GC$4) -> 0 | GE6: =SUM(GE$3:GE$4) -> 0 | GF6: =SUM(GF$3:GF$4) -> 0 | GG6: =SUM(GG$3:GG$4) -> 0 | GH6: =SUM(GH$3:GH$4) -> 0 | GI6: =SUM(GI$3:GI$4) -> 0 | GJ6: =SUM(GJ$3:GJ$4) -> 0 | GL6: =SUM(GL$3:GL$4) -> 0 | GM6: =SUM(GM$3:GM$4) -> 0 | GN6: =SUM(GN$3:GN$4) -> 0 | GO6: =SUM(GO$3:GO$4) -> 0 | GP6: =SUM(GP$3:GP$4) -> 0 | GQ6: =SUM(GQ$3:GQ$4) -> 0 | GS6: =SUM(GS$3:GS$4) -> 0 | GT6: =SUM(GT$3:GT$4) -> 0 | GU6: =SUM(GU$3:GU$4) -> 0 | GV6: =SUM(GV$3:GV$4) -> 0 | GW6: =SUM(GW$3:GW$4) -> 0 | GX6: =SUM(GX$3:GX$4) -> 0 | GZ6: =SUM(GZ$3:GZ$4) -> 0 | HA6: =SUM(HA$3:HA$4) -> 0 | HB6: =SUM(HB$3:HB$4) -> 0 | HC6: =SUM(HC$3:HC$4) -> 0 | HD6: =SUM(HD$3:HD$4) -> 0 | HE6: =SUM(HE$3:HE$4) -> 0 | HG6: =SUM(HG$3:HG$4) -> 0 | HH6: =SUM(HH$3:HH$4) -> 0 | HI6: =SUM(HI$3:HI$4) -> 0 | HJ6: =SUM(HJ$3:HJ$4) -> 0 | HK6: =SUM(HK$3:HK$4) -> 0 | HL6: =SUM(HL$3:HL$4) -> 0 | HN6: =SUM(HN$3:HN$4) -> 0 | HO6: =SUM(HO$3:HO$4) -> 0 | HP6: =SUM(HP$3:HP$4) -> 0 | HQ6: =SUM(HQ$3:HQ$4) -> 0 | HR6: =SUM(HR$3:HR$4) -> 0 | HS6: =SUM(HS$3:HS$4) -> 0 | HU6: =SUM(HU$3:HU$4) -> 0 | HV6: =SUM(HV$3:HV$4) -> 0 | HW6: =SUM(HW$3:HW$4) -> 0 | HX6: =SUM(HX$3:HX$4) -> 0 | HY6: =SUM(HY$3:HY$4) -> 0 | HZ6: =SUM(HZ$3:HZ$4) -> 0 | IB6: =SUM(IB$3:IB$4) -> 0 | IC6: =SUM(IC$3:IC$4) -> 0 | ID6: =SUM(ID$3:ID$4) -> 0 | IE6: =SUM(IE$3:IE$4) -> 0 | IF6: =SUM(IF$3:IF$4) -> 0 | IG6: =SUM(IG$3:IG$4) -> 0 | II6: =SUM(II$3:II$4) -> 0 | IJ6: =SUM(IJ$3:IJ$4) -> 0 | IK6: =SUM(IK$3:IK$4) -> 0 | IL6: =SUM(IL$3:IL$4) -> 0 | IM6: =SUM(IM$3:IM$4) -> 0 | IN6: =SUM(IN$3:IN$4) -> 0 | IP6: =SUM(IP$3:IP$4) -> 0 | IQ6: =SUM(IQ$3:IQ$4) -> 0 | IR6: =SUM(IR$3:IR$4) -> 0 | IS6: =SUM(IS$3:IS$4) -> 0 | IT6: =SUM(IT$3:IT$4) -> 0 | IU6: =SUM(IU$3:IU$4) -> 0 | IW6: =SUM(IW$3:IW$4) -> 0 | IX6: =SUM(IX$3:IX$4) -> 0 | IY6: =SUM(IY$3:IY$4) -> 0 | IZ6: =SUM(IZ$3:IZ$4) -> 0 | JA6: =SUM(JA$3:JA$4) -> 0 | JB6: =SUM(JB$3:JB$4) -> 0 | JD6: =SUM(JD$3:JD$4) -> 0 | JE6: =SUM(JE$3:JE$4) -> 0 | JF6: =SUM(JF$3:JF$4) -> 0 | JG6: =SUM(JG$3:JG$4) -> 0 | JH6: =SUM(JH$3:JH$4) -> 0 | JI6: =SUM(JI$3:JI$4) -> 0 | JK6: =SUM(JK$3:JK$4) -> 0 | JL6: =SUM(JL$3:JL$4) -> 0 | JM6: =SUM(JM$3:JM$4) -> 0 | JN6: =SUM(JN$3:JN$4) -> 0 | JO6: =SUM(JO$3:JO$4) -> 0 | JP6: =SUM(JP$3:JP$4) -> 0 | JR6: =SUM(JR$3:JR$4) -> 0 | JS6: =SUM(JS$3:JS$4) -> 0 | JT6: =SUM(JT$3:JT$4) -> 0 | JU6: =SUM(JU$3:JU$4) -> 0 | JV6: =SUM(JV$3:JV$4) -> 0 | JW6: =SUM(JW$3:JW$4) -> 0 | JY6: =SUM(JY$3:JY$4) -> 0 | JZ6: =SUM(JZ$3:JZ$4) -> 0 | KA6: =SUM(KA$3:KA$4) -> 0 | KB6: =SUM(KB$3:KB$4) -> 0 | KC6: =SUM(KC$3:KC$4) -> 0 | KD6: =SUM(KD$3:KD$4) -> 0 | KF6: =SUM(KF$3:KF$4) -> 0 | KG6: =SUM(KG$3:KG$4) -> 0 | KH6: =SUM(KH$3:KH$4) -> 0 | KI6: =SUM(KI$3:KI$4) -> 0 | KJ6: =SUM(KJ$3:KJ$4) -> 0 | KK6: =SUM(KK$3:KK$4) -> 0 | KM6: =SUM(KM$3:KM$4) -> 0 | KN6: =SUM(KN$3:KN$4) -> 0 | KO6: =SUM(KO$3:KO$4) -> 0 | KP6: =SUM(KP$3:KP$4) -> 0 | KQ6: =SUM(KQ$3:KQ$4) -> 0 | KR6: =SUM(KR$3:KR$4) -> 0 | KT6: =SUM(KT$3:KT$4) -> 0 | KU6: =SUM(KU$3:KU$4) -> 0 | KV6: =SUM(KV$3:KV$4) -> 0 | KW6: =SUM(KW$3:KW$4) -> 0 | KX6: =SUM(KX$3:KX$4) -> 0 | KY6: =SUM(KY$3:KY$4) -> 0 | LA6: =SUM(LA$3:LA$4) -> 0 | LB6: =SUM(LB$3:LB$4) -> 0 | LC6: =SUM(LC$3:LC$4) -> 0 | LD6: =SUM(LD$3:LD$4) -> 0 | LE6: =SUM(LE$3:LE$4) -> 0 | LF6: =SUM(LF$3:LF$4) -> 0 | LG6: =SUM(LG$3:LG$4) -> 0 | LH6: =SUM(LH$3:LH$4) -> 0 | ... LV6: =SUM(LV$3:LV$4) -> 0
A7: AVG | B7: =AVERAGE(B$3:B$4) -> 0 | H7: =AVERAGE(H$3:H$4) -> 0 | I7: =AVERAGE(I$3:I$4) -> 0 | O7: =AVERAGE(O$3:O$4) -> 0 | P7: =AVERAGE(P$3:P$4) -> 0 | V7: =AVERAGE(V$3:V$4) -> 0 | W7: =AVERAGE(W$3:W$4) -> 0 | AC7: =AVERAGE(AC$3:AC$4) -> 0 | AD7: =AVERAGE(AD$3:AD$4) -> 0 | AJ7: =AVERAGE(AJ$3:AJ$4) -> 0 | AK7: =AVERAGE(AK$3:AK$4) -> 0 | AQ7: =AVERAGE(AQ$3:AQ$4) -> 0 | AR7: =AVERAGE(AR$3:AR$4) -> 0 | AX7: =AVERAGE(AX$3:AX$4) -> 0 | AY7: =AVERAGE(AY$3:AY$4) -> 0 | BE7: =AVERAGE(BE$3:BE$4) -> 0 | BF7: =AVERAGE(BF$3:BF$4) -> 0 | BL7: =AVERAGE(BL$3:BL$4) -> 0 | BM7: =AVERAGE(BM$3:BM$4) -> 0 | BS7: =AVERAGE(BS$3:BS$4) -> 0 | BT7: =AVERAGE(BT$3:BT$4) -> 0 | BZ7: =AVERAGE(BZ$3:BZ$4) -> 0 | CA7: =AVERAGE(CA$3:CA$4) -> 0 | CG7: =AVERAGE(CG$3:CG$4) -> 0 | CH7: =AVERAGE(CH$3:CH$4) -> 0 | CI7: =AVERAGE(CI$3:CI$4) -> 0 | CK7: =AVERAGE(CK$3:CK$4) -> 0 | CL7: =AVERAGE(CL$3:CL$4) -> 0 | CM7: =AVERAGE(CM$3:CM$4) -> 0 | CN7: =AVERAGE(CN$3:CN$4) -> 0 | CO7: =AVERAGE(CO$3:CO$4) -> 0 | CP7: =AVERAGE(CP$3:CP$4) -> 0 | CR7: =AVERAGE(CR$3:CR$4) -> 0 | CS7: =AVERAGE(CS$3:CS$4) -> 0 | CT7: =AVERAGE(CT$3:CT$4) -> 0 | CU7: =AVERAGE(CU$3:CU$4) -> 0 | CV7: =AVERAGE(CV$3:CV$4) -> 0 | CW7: =AVERAGE(CW$3:CW$4) -> 0 | CY7: =AVERAGE(CY$3:CY$4) -> 0 | CZ7: =AVERAGE(CZ$3:CZ$4) -> 0 | DA7: =AVERAGE(DA$3:DA$4) -> 0 | DB7: =AVERAGE(DB$3:DB$4) -> 0 | DC7: =AVERAGE(DC$3:DC$4) -> 0 | DD7: =AVERAGE(DD$3:DD$4) -> 0 | DF7: =AVERAGE(DF$3:DF$4) -> 0 | DG7: =AVERAGE(DG$3:DG$4) -> 0 | DH7: =AVERAGE(DH$3:DH$4) -> 0 | DI7: =AVERAGE(DI$3:DI$4) -> 0 | DJ7: =AVERAGE(DJ$3:DJ$4) -> 0 | DK7: =AVERAGE(DK$3:DK$4) -> 0 | DM7: =AVERAGE(DM$3:DM$4) -> 0 | DN7: =AVERAGE(DN$3:DN$4) -> 0 | DO7: =AVERAGE(DO$3:DO$4) -> 0 | DP7: =AVERAGE(DP$3:DP$4) -> 0 | DQ7: =AVERAGE(DQ$3:DQ$4) -> 0 | DR7: =AVERAGE(DR$3:DR$4) -> 0 | DT7: =AVERAGE(DT$3:DT$4) -> 0 | DU7: =AVERAGE(DU$3:DU$4) -> 0 | DV7: =AVERAGE(DV$3:DV$4) -> 0 | DW7: =AVERAGE(DW$3:DW$4) -> 0 | DX7: =AVERAGE(DX$3:DX$4) -> 0 | DY7: =AVERAGE(DY$3:DY$4) -> 0 | EA7: =AVERAGE(EA$3:EA$4) -> 0 | EB7: =AVERAGE(EB$3:EB$4) -> 0 | EC7: =AVERAGE(EC$3:EC$4) -> 0 | ED7: =AVERAGE(ED$3:ED$4) -> 0 | EE7: =AVERAGE(EE$3:EE$4) -> 0 | EF7: =AVERAGE(EF$3:EF$4) -> 0 | EH7: =AVERAGE(EH$3:EH$4) -> 0 | EI7: =AVERAGE(EI$3:EI$4) -> 0 | EJ7: =AVERAGE(EJ$3:EJ$4) -> 0 | EK7: =AVERAGE(EK$3:EK$4) -> 0 | EL7: =AVERAGE(EL$3:EL$4) -> 0 | EM7: =AVERAGE(EM$3:EM$4) -> 0 | EO7: =AVERAGE(EO$3:EO$4) -> 0 | EP7: =AVERAGE(EP$3:EP$4) -> 0 | EQ7: =AVERAGE(EQ$3:EQ$4) -> 0 | ER7: =AVERAGE(ER$3:ER$4) -> 0 | ES7: =AVERAGE(ES$3:ES$4) -> 0 | ET7: =AVERAGE(ET$3:ET$4) -> 0 | EV7: =AVERAGE(EV$3:EV$4) -> 0 | EW7: =AVERAGE(EW$3:EW$4) -> 0 | EX7: =AVERAGE(EX$3:EX$4) -> 0 | EY7: =AVERAGE(EY$3:EY$4) -> 0 | EZ7: =AVERAGE(EZ$3:EZ$4) -> 0 | FA7: =AVERAGE(FA$3:FA$4) -> 0 | FC7: =AVERAGE(FC$3:FC$4) -> 0 | FD7: =AVERAGE(FD$3:FD$4) -> 0 | FE7: =AVERAGE(FE$3:FE$4) -> 0 | FF7: =AVERAGE(FF$3:FF$4) -> 0 | FG7: =AVERAGE(FG$3:FG$4) -> 0 | FH7: =AVERAGE(FH$3:FH$4) -> 0 | FJ7: =AVERAGE(FJ$3:FJ$4) -> 0 | FK7: =AVERAGE(FK$3:FK$4) -> 0 | FL7: =AVERAGE(FL$3:FL$4) -> 0 | FM7: =AVERAGE(FM$3:FM$4) -> 0 | FN7: =AVERAGE(FN$3:FN$4) -> 0 | FO7: =AVERAGE(FO$3:FO$4) -> 0 | FQ7: =AVERAGE(FQ$3:FQ$4) -> 0 | FR7: =AVERAGE(FR$3:FR$4) -> 0 | FS7: =AVERAGE(FS$3:FS$4) -> 0 | FT7: =AVERAGE(FT$3:FT$4) -> 0 | FU7: =AVERAGE(FU$3:FU$4) -> 0 | FV7: =AVERAGE(FV$3:FV$4) -> 0 | FX7: =AVERAGE(FX$3:FX$4) -> 0 | FY7: =AVERAGE(FY$3:FY$4) -> 0 | FZ7: =AVERAGE(FZ$3:FZ$4) -> 0 | GA7: =AVERAGE(GA$3:GA$4) -> 0 | GB7: =AVERAGE(GB$3:GB$4) -> 0 | GC7: =AVERAGE(GC$3:GC$4) -> 0 | GE7: =AVERAGE(GE$3:GE$4) -> 0 | GF7: =AVERAGE(GF$3:GF$4) -> 0 | GG7: =AVERAGE(GG$3:GG$4) -> 0 | GH7: =AVERAGE(GH$3:GH$4) -> 0 | GI7: =AVERAGE(GI$3:GI$4) -> 0 | GJ7: =AVERAGE(GJ$3:GJ$4) -> 0 | GL7: =AVERAGE(GL$3:GL$4) -> 0 | GM7: =AVERAGE(GM$3:GM$4) -> 0 | GN7: =AVERAGE(GN$3:GN$4) -> 0 | GO7: =AVERAGE(GO$3:GO$4) -> 0 | GP7: =AVERAGE(GP$3:GP$4) -> 0 | GQ7: =AVERAGE(GQ$3:GQ$4) -> 0 | GS7: =AVERAGE(GS$3:GS$4) -> 0 | GT7: =AVERAGE(GT$3:GT$4) -> 0 | GU7: =AVERAGE(GU$3:GU$4) -> 0 | GV7: =AVERAGE(GV$3:GV$4) -> 0 | GW7: =AVERAGE(GW$3:GW$4) -> 0 | GX7: =AVERAGE(GX$3:GX$4) -> 0 | GZ7: =AVERAGE(GZ$3:GZ$4) -> 0 | HA7: =AVERAGE(HA$3:HA$4) -> 0 | HB7: =AVERAGE(HB$3:HB$4) -> 0 | HC7: =AVERAGE(HC$3:HC$4) -> 0 | HD7: =AVERAGE(HD$3:HD$4) -> 0 | HE7: =AVERAGE(HE$3:HE$4) -> 0 | HG7: =AVERAGE(HG$3:HG$4) -> 0 | HH7: =AVERAGE(HH$3:HH$4) -> 0 | HI7: =AVERAGE(HI$3:HI$4) -> 0 | HJ7: =AVERAGE(HJ$3:HJ$4) -> 0 | HK7: =AVERAGE(HK$3:HK$4) -> 0 | HL7: =AVERAGE(HL$3:HL$4) -> 0 | HN7: =AVERAGE(HN$3:HN$4) -> 0 | HO7: =AVERAGE(HO$3:HO$4) -> 0 | HP7: =AVERAGE(HP$3:HP$4) -> 0 | HQ7: =AVERAGE(HQ$3:HQ$4) -> 0 | HR7: =AVERAGE(HR$3:HR$4) -> 0 | HS7: =AVERAGE(HS$3:HS$4) -> 0 | HU7: =AVERAGE(HU$3:HU$4) -> 0 | HV7: =AVERAGE(HV$3:HV$4) -> 0 | HW7: =AVERAGE(HW$3:HW$4) -> 0 | HX7: =AVERAGE(HX$3:HX$4) -> 0 | HY7: =AVERAGE(HY$3:HY$4) -> 0 | HZ7: =AVERAGE(HZ$3:HZ$4) -> 0 | IB7: =AVERAGE(IB$3:IB$4) -> 0 | IC7: =AVERAGE(IC$3:IC$4) -> 0 | ID7: =AVERAGE(ID$3:ID$4) -> 0 | IE7: =AVERAGE(IE$3:IE$4) -> 0 | IF7: =AVERAGE(IF$3:IF$4) -> 0 | IG7: =AVERAGE(IG$3:IG$4) -> 0 | II7: =AVERAGE(II$3:II$4) -> 0 | IJ7: =AVERAGE(IJ$3:IJ$4) -> 0 | IK7: =AVERAGE(IK$3:IK$4) -> 0 | IL7: =AVERAGE(IL$3:IL$4) -> 0 | IM7: =AVERAGE(IM$3:IM$4) -> 0 | IN7: =AVERAGE(IN$3:IN$4) -> 0 | IP7: =AVERAGE(IP$3:IP$4) -> 0 | IQ7: =AVERAGE(IQ$3:IQ$4) -> 0 | IR7: =AVERAGE(IR$3:IR$4) -> 0 | IS7: =AVERAGE(IS$3:IS$4) -> 0 | IT7: =AVERAGE(IT$3:IT$4) -> 0 | IU7: =AVERAGE(IU$3:IU$4) -> 0 | IW7: =AVERAGE(IW$3:IW$4) -> 0 | IX7: =AVERAGE(IX$3:IX$4) -> 0 | IY7: =AVERAGE(IY$3:IY$4) -> 0 | IZ7: =AVERAGE(IZ$3:IZ$4) -> 0 | JA7: =AVERAGE(JA$3:JA$4) -> 0 | JB7: =AVERAGE(JB$3:JB$4) -> 0 | JD7: =AVERAGE(JD$3:JD$4) -> 0 | JE7: =AVERAGE(JE$3:JE$4) -> 0 | JF7: =AVERAGE(JF$3:JF$4) -> 0 | JG7: =AVERAGE(JG$3:JG$4) -> 0 | JH7: =AVERAGE(JH$3:JH$4) -> 0 | JI7: =AVERAGE(JI$3:JI$4) -> 0 | JK7: =AVERAGE(JK$3:JK$4) -> 0 | JL7: =AVERAGE(JL$3:JL$4) -> 0 | JM7: =AVERAGE(JM$3:JM$4) -> 0 | JN7: =AVERAGE(JN$3:JN$4) -> 0 | JO7: =AVERAGE(JO$3:JO$4) -> 0 | JP7: =AVERAGE(JP$3:JP$4) -> 0 | JR7: =AVERAGE(JR$3:JR$4) -> 0 | JS7: =AVERAGE(JS$3:JS$4) -> 0 | JT7: =AVERAGE(JT$3:JT$4) -> 0 | JU7: =AVERAGE(JU$3:JU$4) -> 0 | JV7: =AVERAGE(JV$3:JV$4) -> 0 | JW7: =AVERAGE(JW$3:JW$4) -> 0 | JY7: =AVERAGE(JY$3:JY$4) -> 0 | JZ7: =AVERAGE(JZ$3:JZ$4) -> 0 | KA7: =AVERAGE(KA$3:KA$4) -> 0 | KB7: =AVERAGE(KB$3:KB$4) -> 0 | KC7: =AVERAGE(KC$3:KC$4) -> 0 | KD7: =AVERAGE(KD$3:KD$4) -> 0 | KF7: =AVERAGE(KF$3:KF$4) -> 0 | KG7: =AVERAGE(KG$3:KG$4) -> 0 | KH7: =AVERAGE(KH$3:KH$4) -> 0 | KI7: =AVERAGE(KI$3:KI$4) -> 0 | KJ7: =AVERAGE(KJ$3:KJ$4) -> 0 | KK7: =AVERAGE(KK$3:KK$4) -> 0 | KM7: =AVERAGE(KM$3:KM$4) -> 0 | KN7: =AVERAGE(KN$3:KN$4) -> 0 | KO7: =AVERAGE(KO$3:KO$4) -> 0 | KP7: =AVERAGE(KP$3:KP$4) -> 0 | KQ7: =AVERAGE(KQ$3:KQ$4) -> 0 | KR7: =AVERAGE(KR$3:KR$4) -> 0 | KT7: =AVERAGE(KT$3:KT$4) -> 0 | KU7: =AVERAGE(KU$3:KU$4) -> 0 | KV7: =AVERAGE(KV$3:KV$4) -> 0 | KW7: =AVERAGE(KW$3:KW$4) -> 0 | KX7: =AVERAGE(KX$3:KX$4) -> 0 | KY7: =AVERAGE(KY$3:KY$4) -> 0 | LA7: =AVERAGE(LA$3:LA$4) -> 0 | LB7: =AVERAGE(LB$3:LB$4) -> 0 | LC7: =AVERAGE(LC$3:LC$4) -> 0 | LD7: =AVERAGE(LD$3:LD$4) -> 0 | LE7: =AVERAGE(LE$3:LE$4) -> 0 | LF7: =AVERAGE(LF$3:LF$4) -> 0 | LG7: =AVERAGE(LG$3:LG$4) -> 0 | LH7: =AVERAGE(LH$3:LH$4) -> 0 | ... LV7: =AVERAGE(LV$3:LV$4) -> 0
A8: DEV | B8: =STDEV(B$3:B$4) -> 0 | H8: =STDEV(H$3:H$4) -> 0 | I8: =STDEV(I$3:I$4) -> 0 | O8: =STDEV(O$3:O$4) -> 0 | P8: =STDEV(P$3:P$4) -> 0 | V8: =STDEV(V$3:V$4) -> 0 | W8: =STDEV(W$3:W$4) -> 0 | AC8: =STDEV(AC$3:AC$4) -> 0 | AD8: =STDEV(AD$3:AD$4) -> 0 | AJ8: =STDEV(AJ$3:AJ$4) -> 0 | AK8: =STDEV(AK$3:AK$4) -> 0 | AQ8: =STDEV(AQ$3:AQ$4) -> 0 | AR8: =STDEV(AR$3:AR$4) -> 0 | AX8: =STDEV(AX$3:AX$4) -> 0 | AY8: =STDEV(AY$3:AY$4) -> 0 | BE8: =STDEV(BE$3:BE$4) -> 0 | BF8: =STDEV(BF$3:BF$4) -> 0 | BL8: =STDEV(BL$3:BL$4) -> 0 | BM8: =STDEV(BM$3:BM$4) -> 0 | BS8: =STDEV(BS$3:BS$4) -> 0 | BT8: =STDEV(BT$3:BT$4) -> 0 | BZ8: =STDEV(BZ$3:BZ$4) -> 0 | CA8: =STDEV(CA$3:CA$4) -> 0 | CG8: =STDEV(CG$3:CG$4) -> 0 | CH8: =STDEV(CH$3:CH$4) -> 0 | CI8: =STDEV(CI$3:CI$4) -> 0 | CK8: =STDEV(CK$3:CK$4) -> 0 | CL8: =STDEV(CL$3:CL$4) -> 0 | CM8: =STDEV(CM$3:CM$4) -> 0 | CN8: =STDEV(CN$3:CN$4) -> 0 | CO8: =STDEV(CO$3:CO$4) -> 0 | CP8: =STDEV(CP$3:CP$4) -> 0 | CR8: =STDEV(CR$3:CR$4) -> 0 | CS8: =STDEV(CS$3:CS$4) -> 0 | CT8: =STDEV(CT$3:CT$4) -> 0 | CU8: =STDEV(CU$3:CU$4) -> 0 | CV8: =STDEV(CV$3:CV$4) -> 0 | CW8: =STDEV(CW$3:CW$4) -> 0 | CY8: =STDEV(CY$3:CY$4) -> 0 | CZ8: =STDEV(CZ$3:CZ$4) -> 0 | DA8: =STDEV(DA$3:DA$4) -> 0 | DB8: =STDEV(DB$3:DB$4) -> 0 | DC8: =STDEV(DC$3:DC$4) -> 0 | DD8: =STDEV(DD$3:DD$4) -> 0 | DF8: =STDEV(DF$3:DF$4) -> 0 | DG8: =STDEV(DG$3:DG$4) -> 0 | DH8: =STDEV(DH$3:DH$4) -> 0 | DI8: =STDEV(DI$3:DI$4) -> 0 | DJ8: =STDEV(DJ$3:DJ$4) -> 0 | DK8: =STDEV(DK$3:DK$4) -> 0 | DM8: =STDEV(DM$3:DM$4) -> 0 | DN8: =STDEV(DN$3:DN$4) -> 0 | DO8: =STDEV(DO$3:DO$4) -> 0 | DP8: =STDEV(DP$3:DP$4) -> 0 | DQ8: =STDEV(DQ$3:DQ$4) -> 0 | DR8: =STDEV(DR$3:DR$4) -> 0 | DT8: =STDEV(DT$3:DT$4) -> 0 | DU8: =STDEV(DU$3:DU$4) -> 0 | DV8: =STDEV(DV$3:DV$4) -> 0 | DW8: =STDEV(DW$3:DW$4) -> 0 | DX8: =STDEV(DX$3:DX$4) -> 0 | DY8: =STDEV(DY$3:DY$4) -> 0 | EA8: =STDEV(EA$3:EA$4) -> 0 | EB8: =STDEV(EB$3:EB$4) -> 0 | EC8: =STDEV(EC$3:EC$4) -> 0 | ED8: =STDEV(ED$3:ED$4) -> 0 | EE8: =STDEV(EE$3:EE$4) -> 0 | EF8: =STDEV(EF$3:EF$4) -> 0 | EH8: =STDEV(EH$3:EH$4) -> 0 | EI8: =STDEV(EI$3:EI$4) -> 0 | EJ8: =STDEV(EJ$3:EJ$4) -> 0 | EK8: =STDEV(EK$3:EK$4) -> 0 | EL8: =STDEV(EL$3:EL$4) -> 0 | EM8: =STDEV(EM$3:EM$4) -> 0 | EO8: =STDEV(EO$3:EO$4) -> 0 | EP8: =STDEV(EP$3:EP$4) -> 0 | EQ8: =STDEV(EQ$3:EQ$4) -> 0 | ER8: =STDEV(ER$3:ER$4) -> 0 | ES8: =STDEV(ES$3:ES$4) -> 0 | ET8: =STDEV(ET$3:ET$4) -> 0 | EV8: =STDEV(EV$3:EV$4) -> 0 | EW8: =STDEV(EW$3:EW$4) -> 0 | EX8: =STDEV(EX$3:EX$4) -> 0 | EY8: =STDEV(EY$3:EY$4) -> 0 | EZ8: =STDEV(EZ$3:EZ$4) -> 0 | FA8: =STDEV(FA$3:FA$4) -> 0 | FC8: =STDEV(FC$3:FC$4) -> 0 | FD8: =STDEV(FD$3:FD$4) -> 0 | FE8: =STDEV(FE$3:FE$4) -> 0 | FF8: =STDEV(FF$3:FF$4) -> 0 | FG8: =STDEV(FG$3:FG$4) -> 0 | FH8: =STDEV(FH$3:FH$4) -> 0 | FJ8: =STDEV(FJ$3:FJ$4) -> 0 | FK8: =STDEV(FK$3:FK$4) -> 0 | FL8: =STDEV(FL$3:FL$4) -> 0 | FM8: =STDEV(FM$3:FM$4) -> 0 | FN8: =STDEV(FN$3:FN$4) -> 0 | FO8: =STDEV(FO$3:FO$4) -> 0 | FQ8: =STDEV(FQ$3:FQ$4) -> 0 | FR8: =STDEV(FR$3:FR$4) -> 0 | FS8: =STDEV(FS$3:FS$4) -> 0 | FT8: =STDEV(FT$3:FT$4) -> 0 | FU8: =STDEV(FU$3:FU$4) -> 0 | FV8: =STDEV(FV$3:FV$4) -> 0 | FX8: =STDEV(FX$3:FX$4) -> 0 | FY8: =STDEV(FY$3:FY$4) -> 0 | FZ8: =STDEV(FZ$3:FZ$4) -> 0 | GA8: =STDEV(GA$3:GA$4) -> 0 | GB8: =STDEV(GB$3:GB$4) -> 0 | GC8: =STDEV(GC$3:GC$4) -> 0 | GE8: =STDEV(GE$3:GE$4) -> 0 | GF8: =STDEV(GF$3:GF$4) -> 0 | GG8: =STDEV(GG$3:GG$4) -> 0 | GH8: =STDEV(GH$3:GH$4) -> 0 | GI8: =STDEV(GI$3:GI$4) -> 0 | GJ8: =STDEV(GJ$3:GJ$4) -> 0 | GL8: =STDEV(GL$3:GL$4) -> 0 | GM8: =STDEV(GM$3:GM$4) -> 0 | GN8: =STDEV(GN$3:GN$4) -> 0 | GO8: =STDEV(GO$3:GO$4) -> 0 | GP8: =STDEV(GP$3:GP$4) -> 0 | GQ8: =STDEV(GQ$3:GQ$4) -> 0 | GS8: =STDEV(GS$3:GS$4) -> 0 | GT8: =STDEV(GT$3:GT$4) -> 0 | GU8: =STDEV(GU$3:GU$4) -> 0 | GV8: =STDEV(GV$3:GV$4) -> 0 | GW8: =STDEV(GW$3:GW$4) -> 0 | GX8: =STDEV(GX$3:GX$4) -> 0 | GZ8: =STDEV(GZ$3:GZ$4) -> 0 | HA8: =STDEV(HA$3:HA$4) -> 0 | HB8: =STDEV(HB$3:HB$4) -> 0 | HC8: =STDEV(HC$3:HC$4) -> 0 | HD8: =STDEV(HD$3:HD$4) -> 0 | HE8: =STDEV(HE$3:HE$4) -> 0 | HG8: =STDEV(HG$3:HG$4) -> 0 | HH8: =STDEV(HH$3:HH$4) -> 0 | HI8: =STDEV(HI$3:HI$4) -> 0 | HJ8: =STDEV(HJ$3:HJ$4) -> 0 | HK8: =STDEV(HK$3:HK$4) -> 0 | HL8: =STDEV(HL$3:HL$4) -> 0 | HN8: =STDEV(HN$3:HN$4) -> 0 | HO8: =STDEV(HO$3:HO$4) -> 0 | HP8: =STDEV(HP$3:HP$4) -> 0 | HQ8: =STDEV(HQ$3:HQ$4) -> 0 | HR8: =STDEV(HR$3:HR$4) -> 0 | HS8: =STDEV(HS$3:HS$4) -> 0 | HU8: =STDEV(HU$3:HU$4) -> 0 | HV8: =STDEV(HV$3:HV$4) -> 0 | HW8: =STDEV(HW$3:HW$4) -> 0 | HX8: =STDEV(HX$3:HX$4) -> 0 | HY8: =STDEV(HY$3:HY$4) -> 0 | HZ8: =STDEV(HZ$3:HZ$4) -> 0 | IB8: =STDEV(IB$3:IB$4) -> 0 | IC8: =STDEV(IC$3:IC$4) -> 0 | ID8: =STDEV(ID$3:ID$4) -> 0 | IE8: =STDEV(IE$3:IE$4) -> 0 | IF8: =STDEV(IF$3:IF$4) -> 0 | IG8: =STDEV(IG$3:IG$4) -> 0 | II8: =STDEV(II$3:II$4) -> 0 | IJ8: =STDEV(IJ$3:IJ$4) -> 0 | IK8: =STDEV(IK$3:IK$4) -> 0 | IL8: =STDEV(IL$3:IL$4) -> 0 | IM8: =STDEV(IM$3:IM$4) -> 0 | IN8: =STDEV(IN$3:IN$4) -> 0 | IP8: =STDEV(IP$3:IP$4) -> 0 | IQ8: =STDEV(IQ$3:IQ$4) -> 0 | IR8: =STDEV(IR$3:IR$4) -> 0 | IS8: =STDEV(IS$3:IS$4) -> 0 | IT8: =STDEV(IT$3:IT$4) -> 0 | IU8: =STDEV(IU$3:IU$4) -> 0 | IW8: =STDEV(IW$3:IW$4) -> 0 | IX8: =STDEV(IX$3:IX$4) -> 0 | IY8: =STDEV(IY$3:IY$4) -> 0 | IZ8: =STDEV(IZ$3:IZ$4) -> 0 | JA8: =STDEV(JA$3:JA$4) -> 0 | JB8: =STDEV(JB$3:JB$4) -> 0 | JD8: =STDEV(JD$3:JD$4) -> 0 | JE8: =STDEV(JE$3:JE$4) -> 0 | JF8: =STDEV(JF$3:JF$4) -> 0 | JG8: =STDEV(JG$3:JG$4) -> 0 | JH8: =STDEV(JH$3:JH$4) -> 0 | JI8: =STDEV(JI$3:JI$4) -> 0 | JK8: =STDEV(JK$3:JK$4) -> 0 | JL8: =STDEV(JL$3:JL$4) -> 0 | JM8: =STDEV(JM$3:JM$4) -> 0 | JN8: =STDEV(JN$3:JN$4) -> 0 | JO8: =STDEV(JO$3:JO$4) -> 0 | JP8: =STDEV(JP$3:JP$4) -> 0 | JR8: =STDEV(JR$3:JR$4) -> 0 | JS8: =STDEV(JS$3:JS$4) -> 0 | JT8: =STDEV(JT$3:JT$4) -> 0 | JU8: =STDEV(JU$3:JU$4) -> 0 | JV8: =STDEV(JV$3:JV$4) -> 0 | JW8: =STDEV(JW$3:JW$4) -> 0 | JY8: =STDEV(JY$3:JY$4) -> 0 | JZ8: =STDEV(JZ$3:JZ$4) -> 0 | KA8: =STDEV(KA$3:KA$4) -> 0 | KB8: =STDEV(KB$3:KB$4) -> 0 | KC8: =STDEV(KC$3:KC$4) -> 0 | KD8: =STDEV(KD$3:KD$4) -> 0 | KF8: =STDEV(KF$3:KF$4) -> 0 | KG8: =STDEV(KG$3:KG$4) -> 0 | KH8: =STDEV(KH$3:KH$4) -> 0 | KI8: =STDEV(KI$3:KI$4) -> 0 | KJ8: =STDEV(KJ$3:KJ$4) -> 0 | KK8: =STDEV(KK$3:KK$4) -> 0 | KM8: =STDEV(KM$3:KM$4) -> 0 | KN8: =STDEV(KN$3:KN$4) -> 0 | KO8: =STDEV(KO$3:KO$4) -> 0 | KP8: =STDEV(KP$3:KP$4) -> 0 | KQ8: =STDEV(KQ$3:KQ$4) -> 0 | KR8: =STDEV(KR$3:KR$4) -> 0 | KT8: =STDEV(KT$3:KT$4) -> 0 | KU8: =STDEV(KU$3:KU$4) -> 0 | KV8: =STDEV(KV$3:KV$4) -> 0 | KW8: =STDEV(KW$3:KW$4) -> 0 | KX8: =STDEV(KX$3:KX$4) -> 0 | KY8: =STDEV(KY$3:KY$4) -> 0 | LA8: =STDEV(LA$3:LA$4) -> 0 | LB8: =STDEV(LB$3:LB$4) -> 0 | LC8: =STDEV(LC$3:LC$4) -> 0 | LD8: =STDEV(LD$3:LD$4) -> 0 | LE8: =STDEV(LE$3:LE$4) -> 0 | LF8: =STDEV(LF$3:LF$4) -> 0 | LG8: =STDEV(LG$3:LG$4) -> 0 | LH8: =STDEV(LH$3:LH$4) -> 0 | ... LV8: =STDEV(LV$3:LV$4) -> 0
A9: DST | B9: =SUMPRODUCT(--(B$3:B$4-$LE$3:$LE$4)^2)^0.5 -> 0 | H9: =SUMPRODUCT(--(H$3:H$4-$LJ$3:$LJ$4)^2)^0.5 -> 0 | I9: =SUMPRODUCT(--(I$3:I$4-$LE$3:$LE$4)^2)^0.5 -> 0 | O9: =SUMPRODUCT(--(O$3:O$4-$LJ$3:$LJ$4)^2)^0.5 -> 0 | P9: =SUMPRODUCT(--(P$3:P$4-$LE$3:$LE$4)^2)^0.5 -> 0 | V9: =SUMPRODUCT(--(V$3:V$4-$LJ$3:$LJ$4)^2)^0.5 -> 0 | W9: =SUMPRODUCT(--(W$3:W$4-$LE$3:$LE$4)^2)^0.5 -> 0 | AC9: =SUMPRODUCT(--(AC$3:AC$4-$LJ$3:$LJ$4)^2)^0.5 -> 0 | AD9: =SUMPRODUCT(--(AD$3:AD$4-$LE$3:$LE$4)^2)^0.5 -> 0 | AJ9: =SUMPRODUCT(--(AJ$3:AJ$4-$LJ$3:$LJ$4)^2)^0.5 -> 0 | AK9: =SUMPRODUCT(--(AK$3:AK$4-$LE$3:$LE$4)^2)^0.5 -> 0 | AQ9: =SUMPRODUCT(--(AQ$3:AQ$4-$LJ$3:$LJ$4)^2)^0.5 -> 0 | AR9: =SUMPRODUCT(--(AR$3:AR$4-$LE$3:$LE$4)^2)^0.5 -> 0 | AX9: =SUMPRODUCT(--(AX$3:AX$4-$LJ$3:$LJ$4)^2)^0.5 -> 0 | AY9: =SUMPRODUCT(--(AY$3:AY$4-$LE$3:$LE$4)^2)^0.5 -> 0 | BE9: =SUMPRODUCT(--(BE$3:BE$4-$LJ$3:$LJ$4)^2)^0.5 -> 0 | BF9: =SUMPRODUCT(--(BF$3:BF$4-$LE$3:$LE$4)^2)^0.5 -> 0 | BL9: =SUMPRODUCT(--(BL$3:BL$4-$LJ$3:$LJ$4)^2)^0.5 -> 0 | BM9: =SUMPRODUCT(--(BM$3:BM$4-$LE$3:$LE$4)^2)^0.5 -> 0 | BS9: =SUMPRODUCT(--(BS$3:BS$4-$LJ$3:$LJ$4)^2)^0.5 -> 0 | BT9: =SUMPRODUCT(--(BT$3:BT$4-$LE$3:$LE$4)^2)^0.5 -> 0 | BZ9: =SUMPRODUCT(--(BZ$3:BZ$4-$LJ$3:$LJ$4)^2)^0.5 -> 0 | CA9: =SUMPRODUCT(--(CA$3:CA$4-$LE$3:$LE$4)^2)^0.5 -> 0 | CG9: =SUMPRODUCT(--(CG$3:CG$4-$LJ$3:$LJ$4)^2)^0.5 -> 0 | CH9: =SUMPRODUCT(--(CH$3:CH$4-$LE$3:$LE$4)^2)^0.5 -> 0 | CI9: =SUMPRODUCT(--(CI$3:CI$4-$LF$3:$LF$4)^2)^0.5 -> 0 | CK9: =SUMPRODUCT(--(CK$3:CK$4-$LG$3:$LG$4)^2)^0.5 -> 0 | CL9: =SUMPRODUCT(--(CL$3:CL$4-$LH$3:$LH$4)^2)^0.5 -> 0 | CM9: =SUMPRODUCT(--(CM$3:CM$4-$LI$3:$LI$4)^2)^0.5 -> 0 | CN9: =SUMPRODUCT(--(CN$3:CN$4-$LJ$3:$LJ$4)^2)^0.5 -> 0 | CO9: =SUMPRODUCT(--(CO$3:CO$4-$LE$3:$LE$4)^2)^0.5 -> 0 | CP9: =SUMPRODUCT(--(CP$3:CP$4-$LF$3:$LF$4)^2)^0.5 -> 0 | CR9: =SUMPRODUCT(--(CR$3:CR$4-$LG$3:$LG$4)^2)^0.5 -> 0 | CS9: =SUMPRODUCT(--(CS$3:CS$4-$LH$3:$LH$4)^2)^0.5 -> 0 | CT9: =SUMPRODUCT(--(CT$3:CT$4-$LI$3:$LI$4)^2)^0.5 -> 0 | CU9: =SUMPRODUCT(--(CU$3:CU$4-$LJ$3:$LJ$4)^2)^0.5 -> 0 | CV9: =SUMPRODUCT(--(CV$3:CV$4-$LE$3:$LE$4)^2)^0.5 -> 0 | CW9: =SUMPRODUCT(--(CW$3:CW$4-$LF$3:$LF$4)^2)^0.5 -> 0 | CY9: =SUMPRODUCT(--(CY$3:CY$4-$LG$3:$LG$4)^2)^0.5 -> 0 | CZ9: =SUMPRODUCT(--(CZ$3:CZ$4-$LH$3:$LH$4)^2)^0.5 -> 0 | DA9: =SUMPRODUCT(--(DA$3:DA$4-$LI$3:$LI$4)^2)^0.5 -> 0 | DB9: =SUMPRODUCT(--(DB$3:DB$4-$LJ$3:$LJ$4)^2)^0.5 -> 0 | DC9: =SUMPRODUCT(--(DC$3:DC$4-$LE$3:$LE$4)^2)^0.5 -> 0 | DD9: =SUMPRODUCT(--(DD$3:DD$4-$LF$3:$LF$4)^2)^0.5 -> 0 | DF9: =SUMPRODUCT(--(DF$3:DF$4-$LG$3:$LG$4)^2)^0.5 -> 0 | DG9: =SUMPRODUCT(--(DG$3:DG$4-$LH$3:$LH$4)^2)^0.5 -> 0 | DH9: =SUMPRODUCT(--(DH$3:DH$4-$LI$3:$LI$4)^2)^0.5 -> 0 | DI9: =SUMPRODUCT(--(DI$3:DI$4-$LJ$3:$LJ$4)^2)^0.5 -> 0 | DJ9: =SUMPRODUCT(--(DJ$3:DJ$4-$LE$3:$LE$4)^2)^0.5 -> 0 | DK9: =SUMPRODUCT(--(DK$3:DK$4-$LF$3:$LF$4)^2)^0.5 -> 0 | DM9: =SUMPRODUCT(--(DM$3:DM$4-$LG$3:$LG$4)^2)^0.5 -> 0 | DN9: =SUMPRODUCT(--(DN$3:DN$4-$LH$3:$LH$4)^2)^0.5 -> 0 | DO9: =SUMPRODUCT(--(DO$3:DO$4-$LI$3:$LI$4)^2)^0.5 -> 0 | DP9: =SUMPRODUCT(--(DP$3:DP$4-$LJ$3:$LJ$4)^2)^0.5 -> 0 | DQ9: =SUMPRODUCT(--(DQ$3:DQ$4-$LE$3:$LE$4)^2)^0.5 -> 0 | DR9: =SUMPRODUCT(--(DR$3:DR$4-$LF$3:$LF$4)^2)^0.5 -> 0 | DT9: =SUMPRODUCT(--(DT$3:DT$4-$LG$3:$LG$4)^2)^0.5 -> 0 | DU9: =SUMPRODUCT(--(DU$3:DU$4-$LH$3:$LH$4)^2)^0.5 -> 0 | DV9: =SUMPRODUCT(--(DV$3:DV$4-$LI$3:$LI$4)^2)^0.5 -> 0 | DW9: =SUMPRODUCT(--(DW$3:DW$4-$LJ$3:$LJ$4)^2)^0.5 -> 0 | DX9: =SUMPRODUCT(--(DX$3:DX$4-$LE$3:$LE$4)^2)^0.5 -> 0 | DY9: =SUMPRODUCT(--(DY$3:DY$4-$LF$3:$LF$4)^2)^0.5 -> 0 | EA9: =SUMPRODUCT(--(EA$3:EA$4-$LG$3:$LG$4)^2)^0.5 -> 0 | EB9: =SUMPRODUCT(--(EB$3:EB$4-$LH$3:$LH$4)^2)^0.5 -> 0 | EC9: =SUMPRODUCT(--(EC$3:EC$4-$LI$3:$LI$4)^2)^0.5 -> 0 | ED9: =SUMPRODUCT(--(ED$3:ED$4-$LJ$3:$LJ$4)^2)^0.5 -> 0 | EE9: =SUMPRODUCT(--(EE$3:EE$4-$LE$3:$LE$4)^2)^0.5 -> 0 | EF9: =SUMPRODUCT(--(EF$3:EF$4-$LF$3:$LF$4)^2)^0.5 -> 0 | EH9: =SUMPRODUCT(--(EH$3:EH$4-$LG$3:$LG$4)^2)^0.5 -> 0 | EI9: =SUMPRODUCT(--(EI$3:EI$4-$LH$3:$LH$4)^2)^0.5 -> 0 | EJ9: =SUMPRODUCT(--(EJ$3:EJ$4-$LI$3:$LI$4)^2)^0.5 -> 0 | EK9: =SUMPRODUCT(--(EK$3:EK$4-$LJ$3:$LJ$4)^2)^0.5 -> 0 | EL9: =SUMPRODUCT(--(EL$3:EL$4-$LE$3:$LE$4)^2)^0.5 -> 0 | EM9: =SUMPRODUCT(--(EM$3:EM$4-$LF$3:$LF$4)^2)^0.5 -> 0 | EO9: =SUMPRODUCT(--(EO$3:EO$4-$LG$3:$LG$4)^2)^0.5 -> 0 | EP9: =SUMPRODUCT(--(EP$3:EP$4-$LH$3:$LH$4)^2)^0.5 -> 0 | EQ9: =SUMPRODUCT(--(EQ$3:EQ$4-$LI$3:$LI$4)^2)^0.5 -> 0 | ER9: =SUMPRODUCT(--(ER$3:ER$4-$LJ$3:$LJ$4)^2)^0.5 -> 0 | ES9: =SUMPRODUCT(--(ES$3:ES$4-$LE$3:$LE$4)^2)^0.5 -> 0 | ET9: =SUMPRODUCT(--(ET$3:ET$4-$LF$3:$LF$4)^2)^0.5 -> 0 | EV9: =SUMPRODUCT(--(EV$3:EV$4-$LG$3:$LG$4)^2)^0.5 -> 0 | EW9: =SUMPRODUCT(--(EW$3:EW$4-$LH$3:$LH$4)^2)^0.5 -> 0 | EX9: =SUMPRODUCT(--(EX$3:EX$4-$LI$3:$LI$4)^2)^0.5 -> 0 | EY9: =SUMPRODUCT(--(EY$3:EY$4-$LJ$3:$LJ$4)^2)^0.5 -> 0 | EZ9: =SUMPRODUCT(--(EZ$3:EZ$4-$LE$3:$LE$4)^2)^0.5 -> 0 | FA9: =SUMPRODUCT(--(FA$3:FA$4-$LF$3:$LF$4)^2)^0.5 -> 0 | FC9: =SUMPRODUCT(--(FC$3:FC$4-$LG$3:$LG$4)^2)^0.5 -> 0 | FD9: =SUMPRODUCT(--(FD$3:FD$4-$LH$3:$LH$4)^2)^0.5 -> 0 | FE9: =SUMPRODUCT(--(FE$3:FE$4-$LI$3:$LI$4)^2)^0.5 -> 0 | FF9: =SUMPRODUCT(--(FF$3:FF$4-$LJ$3:$LJ$4)^2)^0.5 -> 0 | FG9: =SUMPRODUCT(--(FG$3:FG$4-$LE$3:$LE$4)^2)^0.5 -> 0 | FH9: =SUMPRODUCT(--(FH$3:FH$4-$LF$3:$LF$4)^2)^0.5 -> 0 | FJ9: =SUMPRODUCT(--(FJ$3:FJ$4-$LG$3:$LG$4)^2)^0.5 -> 0 | FK9: =SUMPRODUCT(--(FK$3:FK$4-$LH$3:$LH$4)^2)^0.5 -> 0 | FL9: =SUMPRODUCT(--(FL$3:FL$4-$LI$3:$LI$4)^2)^0.5 -> 0 | FM9: =SUMPRODUCT(--(FM$3:FM$4-$LJ$3:$LJ$4)^2)^0.5 -> 0 | FN9: =SUMPRODUCT(--(FN$3:FN$4-$LE$3:$LE$4)^2)^0.5 -> 0 | FO9: =SUMPRODUCT(--(FO$3:FO$4-$LF$3:$LF$4)^2)^0.5 -> 0 | FQ9: =SUMPRODUCT(--(FQ$3:FQ$4-$LG$3:$LG$4)^2)^0.5 -> 0 | FR9: =SUMPRODUCT(--(FR$3:FR$4-$LH$3:$LH$4)^2)^0.5 -> 0 | FS9: =SUMPRODUCT(--(FS$3:FS$4-$LI$3:$LI$4)^2)^0.5 -> 0 | FT9: =SUMPRODUCT(--(FT$3:FT$4-$LJ$3:$LJ$4)^2)^0.5 -> 0 | FU9: =SUMPRODUCT(--(FU$3:FU$4-$LE$3:$LE$4)^2)^0.5 -> 0 | FV9: =SUMPRODUCT(--(FV$3:FV$4-$LF$3:$LF$4)^2)^0.5 -> 0 | FX9: =SUMPRODUCT(--(FX$3:FX$4-$LG$3:$LG$4)^2)^0.5 -> 0 | FY9: =SUMPRODUCT(--(FY$3:FY$4-$LH$3:$LH$4)^2)^0.5 -> 0 | FZ9: =SUMPRODUCT(--(FZ$3:FZ$4-$LI$3:$LI$4)^2)^0.5 -> 0 | GA9: =SUMPRODUCT(--(GA$3:GA$4-$LJ$3:$LJ$4)^2)^0.5 -> 0 | GB9: =SUMPRODUCT(--(GB$3:GB$4-$LE$3:$LE$4)^2)^0.5 -> 0 | GC9: =SUMPRODUCT(--(GC$3:GC$4-$LF$3:$LF$4)^2)^0.5 -> 0 | GE9: =SUMPRODUCT(--(GE$3:GE$4-$LG$3:$LG$4)^2)^0.5 -> 0 | GF9: =SUMPRODUCT(--(GF$3:GF$4-$LH$3:$LH$4)^2)^0.5 -> 0 | GG9: =SUMPRODUCT(--(GG$3:GG$4-$LI$3:$LI$4)^2)^0.5 -> 0 | GH9: =SUMPRODUCT(--(GH$3:GH$4-$LJ$3:$LJ$4)^2)^0.5 -> 0 | GI9: =SUMPRODUCT(--(GI$3:GI$4-$LE$3:$LE$4)^2)^0.5 -> 0 | GJ9: =SUMPRODUCT(--(GJ$3:GJ$4-$LF$3:$LF$4)^2)^0.5 -> 0 | GL9: =SUMPRODUCT(--(GL$3:GL$4-$LG$3:$LG$4)^2)^0.5 -> 0 | GM9: =SUMPRODUCT(--(GM$3:GM$4-$LH$3:$LH$4)^2)^0.5 -> 0 | GN9: =SUMPRODUCT(--(GN$3:GN$4-$LI$3:$LI$4)^2)^0.5 -> 0 | GO9: =SUMPRODUCT(--(GO$3:GO$4-$LJ$3:$LJ$4)^2)^0.5 -> 0 | GP9: =SUMPRODUCT(--(GP$3:GP$4-$LE$3:$LE$4)^2)^0.5 -> 0 | GQ9: =SUMPRODUCT(--(GQ$3:GQ$4-$LF$3:$LF$4)^2)^0.5 -> 0 | GS9: =SUMPRODUCT(--(GS$3:GS$4-$LG$3:$LG$4)^2)^0.5 -> 0 | GT9: =SUMPRODUCT(--(GT$3:GT$4-$LH$3:$LH$4)^2)^0.5 -> 0 | GU9: =SUMPRODUCT(--(GU$3:GU$4-$LI$3:$LI$4)^2)^0.5 -> 0 | GV9: =SUMPRODUCT(--(GV$3:GV$4-$LJ$3:$LJ$4)^2)^0.5 -> 0 | GW9: =SUMPRODUCT(--(GW$3:GW$4-$LE$3:$LE$4)^2)^0.5 -> 0 | GX9: =SUMPRODUCT(--(GX$3:GX$4-$LF$3:$LF$4)^2)^0.5 -> 0 | GZ9: =SUMPRODUCT(--(GZ$3:GZ$4-$LG$3:$LG$4)^2)^0.5 -> 0 | HA9: =SUMPRODUCT(--(HA$3:HA$4-$LH$3:$LH$4)^2)^0.5 -> 0 | HB9: =SUMPRODUCT(--(HB$3:HB$4-$LI$3:$LI$4)^2)^0.5 -> 0 | HC9: =SUMPRODUCT(--(HC$3:HC$4-$LJ$3:$LJ$4)^2)^0.5 -> 0 | HD9: =SUMPRODUCT(--(HD$3:HD$4-$LE$3:$LE$4)^2)^0.5 -> 0 | HE9: =SUMPRODUCT(--(HE$3:HE$4-$LF$3:$LF$4)^2)^0.5 -> 0 | HG9: =SUMPRODUCT(--(HG$3:HG$4-$LG$3:$LG$4)^2)^0.5 -> 0 | HH9: =SUMPRODUCT(--(HH$3:HH$4-$LH$3:$LH$4)^2)^0.5 -> 0 | HI9: =SUMPRODUCT(--(HI$3:HI$4-$LI$3:$LI$4)^2)^0.5 -> 0 | HJ9: =SUMPRODUCT(--(HJ$3:HJ$4-$LJ$3:$LJ$4)^2)^0.5 -> 0 | HK9: =SUMPRODUCT(--(HK$3:HK$4-$LE$3:$LE$4)^2)^0.5 -> 0 | HL9: =SUMPRODUCT(--(HL$3:HL$4-$LF$3:$LF$4)^2)^0.5 -> 0 | HN9: =SUMPRODUCT(--(HN$3:HN$4-$LG$3:$LG$4)^2)^0.5 -> 0 | HO9: =SUMPRODUCT(--(HO$3:HO$4-$LH$3:$LH$4)^2)^0.5 -> 0 | HP9: =SUMPRODUCT(--(HP$3:HP$4-$LI$3:$LI$4)^2)^0.5 -> 0 | HQ9: =SUMPRODUCT(--(HQ$3:HQ$4-$LJ$3:$LJ$4)^2)^0.5 -> 0 | HR9: =SUMPRODUCT(--(HR$3:HR$4-$LE$3:$LE$4)^2)^0.5 -> 0 | HS9: =SUMPRODUCT(--(HS$3:HS$4-$LF$3:$LF$4)^2)^0.5 -> 0 | HU9: =SUMPRODUCT(--(HU$3:HU$4-$LG$3:$LG$4)^2)^0.5 -> 0 | HV9: =SUMPRODUCT(--(HV$3:HV$4-$LH$3:$LH$4)^2)^0.5 -> 0 | HW9: =SUMPRODUCT(--(HW$3:HW$4-$LI$3:$LI$4)^2)^0.5 -> 0 | HX9: =SUMPRODUCT(--(HX$3:HX$4-$LJ$3:$LJ$4)^2)^0.5 -> 0 | HY9: =SUMPRODUCT(--(HY$3:HY$4-$LE$3:$LE$4)^2)^0.5 -> 0 | HZ9: =SUMPRODUCT(--(HZ$3:HZ$4-$LF$3:$LF$4)^2)^0.5 -> 0 | IB9: =SUMPRODUCT(--(IB$3:IB$4-$LG$3:$LG$4)^2)^0.5 -> 0 | IC9: =SUMPRODUCT(--(IC$3:IC$4-$LH$3:$LH$4)^2)^0.5 -> 0 | ID9: =SUMPRODUCT(--(ID$3:ID$4-$LI$3:$LI$4)^2)^0.5 -> 0 | IE9: =SUMPRODUCT(--(IE$3:IE$4-$LJ$3:$LJ$4)^2)^0.5 -> 0 | IF9: =SUMPRODUCT(--(IF$3:IF$4-$LE$3:$LE$4)^2)^0.5 -> 0 | IG9: =SUMPRODUCT(--(IG$3:IG$4-$LF$3:$LF$4)^2)^0.5 -> 0 | II9: =SUMPRODUCT(--(II$3:II$4-$LG$3:$LG$4)^2)^0.5 -> 0 | IJ9: =SUMPRODUCT(--(IJ$3:IJ$4-$LH$3:$LH$4)^2)^0.5 -> 0 | IK9: =SUMPRODUCT(--(IK$3:IK$4-$LI$3:$LI$4)^2)^0.5 -> 0 | IL9: =SUMPRODUCT(--(IL$3:IL$4-$LJ$3:$LJ$4)^2)^0.5 -> 0 | IM9: =SUMPRODUCT(--(IM$3:IM$4-$LE$3:$LE$4)^2)^0.5 -> 0 | IN9: =SUMPRODUCT(--(IN$3:IN$4-$LF$3:$LF$4)^2)^0.5 -> 0 | IP9: =SUMPRODUCT(--(IP$3:IP$4-$LG$3:$LG$4)^2)^0.5 -> 0 | IQ9: =SUMPRODUCT(--(IQ$3:IQ$4-$LH$3:$LH$4)^2)^0.5 -> 0 | IR9: =SUMPRODUCT(--(IR$3:IR$4-$LI$3:$LI$4)^2)^0.5 -> 0 | IS9: =SUMPRODUCT(--(IS$3:IS$4-$LJ$3:$LJ$4)^2)^0.5 -> 0 | IT9: =SUMPRODUCT(--(IT$3:IT$4-$LE$3:$LE$4)^2)^0.5 -> 0 | IU9: =SUMPRODUCT(--(IU$3:IU$4-$LF$3:$LF$4)^2)^0.5 -> 0 | IW9: =SUMPRODUCT(--(IW$3:IW$4-$LG$3:$LG$4)^2)^0.5 -> 0 | IX9: =SUMPRODUCT(--(IX$3:IX$4-$LH$3:$LH$4)^2)^0.5 -> 0 | IY9: =SUMPRODUCT(--(IY$3:IY$4-$LI$3:$LI$4)^2)^0.5 -> 0 | IZ9: =SUMPRODUCT(--(IZ$3:IZ$4-$LJ$3:$LJ$4)^2)^0.5 -> 0 | JA9: =SUMPRODUCT(--(JA$3:JA$4-$LE$3:$LE$4)^2)^0.5 -> 0 | JB9: =SUMPRODUCT(--(JB$3:JB$4-$LF$3:$LF$4)^2)^0.5 -> 0 | JD9: =SUMPRODUCT(--(JD$3:JD$4-$LG$3:$LG$4)^2)^0.5 -> 0 | JE9: =SUMPRODUCT(--(JE$3:JE$4-$LH$3:$LH$4)^2)^0.5 -> 0 | JF9: =SUMPRODUCT(--(JF$3:JF$4-$LI$3:$LI$4)^2)^0.5 -> 0 | JG9: =SUMPRODUCT(--(JG$3:JG$4-$LJ$3:$LJ$4)^2)^0.5 -> 0 | JH9: =SUMPRODUCT(--(JH$3:JH$4-$LE$3:$LE$4)^2)^0.5 -> 0 | JI9: =SUMPRODUCT(--(JI$3:JI$4-$LF$3:$LF$4)^2)^0.5 -> 0 | JK9: =SUMPRODUCT(--(JK$3:JK$4-$LG$3:$LG$4)^2)^0.5 -> 0 | JL9: =SUMPRODUCT(--(JL$3:JL$4-$LH$3:$LH$4)^2)^0.5 -> 0 | JM9: =SUMPRODUCT(--(JM$3:JM$4-$LI$3:$LI$4)^2)^0.5 -> 0 | JN9: =SUMPRODUCT(--(JN$3:JN$4-$LJ$3:$LJ$4)^2)^0.5 -> 0 | JO9: =SUMPRODUCT(--(JO$3:JO$4-$LE$3:$LE$4)^2)^0.5 -> 0 | JP9: =SUMPRODUCT(--(JP$3:JP$4-$LF$3:$LF$4)^2)^0.5 -> 0 | JR9: =SUMPRODUCT(--(JR$3:JR$4-$LG$3:$LG$4)^2)^0.5 -> 0 | JS9: =SUMPRODUCT(--(JS$3:JS$4-$LH$3:$LH$4)^2)^0.5 -> 0 | JT9: =SUMPRODUCT(--(JT$3:JT$4-$LI$3:$LI$4)^2)^0.5 -> 0 | JU9: =SUMPRODUCT(--(JU$3:JU$4-$LJ$3:$LJ$4)^2)^0.5 -> 0 | JV9: =SUMPRODUCT(--(JV$3:JV$4-$LE$3:$LE$4)^2)^0.5 -> 0 | JW9: =SUMPRODUCT(--(JW$3:JW$4-$LF$3:$LF$4)^2)^0.5 -> 0 | JY9: =SUMPRODUCT(--(JY$3:JY$4-$LG$3:$LG$4)^2)^0.5 -> 0 | JZ9: =SUMPRODUCT(--(JZ$3:JZ$4-$LH$3:$LH$4)^2)^0.5 -> 0 | KA9: =SUMPRODUCT(--(KA$3:KA$4-$LI$3:$LI$4)^2)^0.5 -> 0 | KB9: =SUMPRODUCT(--(KB$3:KB$4-$LJ$3:$LJ$4)^2)^0.5 -> 0 | KC9: =SUMPRODUCT(--(KC$3:KC$4-$LE$3:$LE$4)^2)^0.5 -> 0 | KD9: =SUMPRODUCT(--(KD$3:KD$4-$LF$3:$LF$4)^2)^0.5 -> 0 | KF9: =SUMPRODUCT(--(KF$3:KF$4-$LG$3:$LG$4)^2)^0.5 -> 0 | KG9: =SUMPRODUCT(--(KG$3:KG$4-$LH$3:$LH$4)^2)^0.5 -> 0 | KH9: =SUMPRODUCT(--(KH$3:KH$4-$LI$3:$LI$4)^2)^0.5 -> 0 | KI9: =SUMPRODUCT(--(KI$3:KI$4-$LJ$3:$LJ$4)^2)^0.5 -> 0 | KJ9: =SUMPRODUCT(--(KJ$3:KJ$4-$LE$3:$LE$4)^2)^0.5 -> 0 | KK9: =SUMPRODUCT(--(KK$3:KK$4-$LF$3:$LF$4)^2)^0.5 -> 0 | KM9: =SUMPRODUCT(--(KM$3:KM$4-$LG$3:$LG$4)^2)^0.5 -> 0 | KN9: =SUMPRODUCT(--(KN$3:KN$4-$LH$3:$LH$4)^2)^0.5 -> 0 | KO9: =SUMPRODUCT(--(KO$3:KO$4-$LI$3:$LI$4)^2)^0.5 -> 0 | KP9: =SUMPRODUCT(--(KP$3:KP$4-$LJ$3:$LJ$4)^2)^0.5 -> 0 | KQ9: =SUMPRODUCT(--(KQ$3:KQ$4-$LE$3:$LE$4)^2)^0.5 -> 0 | KR9: =SUMPRODUCT(--(KR$3:KR$4-$LF$3:$LF$4)^2)^0.5 -> 0 | KT9: =SUMPRODUCT(--(KT$3:KT$4-$LG$3:$LG$4)^2)^0.5 -> 0 | KU9: =SUMPRODUCT(--(KU$3:KU$4-$LH$3:$LH$4)^2)^0.5 -> 0 | KV9: =SUMPRODUCT(--(KV$3:KV$4-$LI$3:$LI$4)^2)^0.5 -> 0 | KW9: =SUMPRODUCT(--(KW$3:KW$4-$LJ$3:$LJ$4)^2)^0.5 -> 0 | KX9: =SUMPRODUCT(--(KX$3:KX$4-$LE$3:$LE$4)^2)^0.5 -> 0 | KY9: =SUMPRODUCT(--(KY$3:KY$4-$LF$3:$LF$4)^2)^0.5 -> 0 | LA9: =SUMPRODUCT(--(LA$3:LA$4-$LG$3:$LG$4)^2)^0.5 -> 0 | LB9: =SUMPRODUCT(--(LB$3:LB$4-$LH$3:$LH$4)^2)^0.5 -> 0 | LC9: =SUMPRODUCT(--(LC$3:LC$4-$LI$3:$LI$4)^2)^0.5 -> 0 | LD9: =SUMPRODUCT(--(LD$3:LD$4-$LJ$3:$LJ$4)^2)^0.5 -> 0
