Workbook

Sheet Instances
B1: memelingo-1/simple_mlp-lpnmr-ht | I1: memelingo-1/simple_mlp-lpnmr-htc | P1: memelingo-1/simple_mlp-lpnmr-htcdl | W1: memelingo-1/simple_mlp-tplp-ht | AD1: memelingo-1/simple_mlp-tplp-htc | AK1: memelingo-1/simple_mlp-tplp-htcdl | AR1: min | AX1: median | BD1: max
B2: time | C2: stime | D2: status | E2: rules | F2: ctime | G2: fmtime | H2: memout | I2: time | J2: stime | K2: status | L2: rules | M2: ctime | N2: fmtime | O2: memout | P2: time | Q2: stime | R2: status | S2: rules | T2: ctime | U2: fmtime | V2: memout | W2: time | X2: stime | Y2: status | Z2: rules | AA2: ctime | AB2: fmtime | AC2: memout | AD2: time | AE2: stime | AF2: status | AG2: rules | AH2: ctime | AI2: fmtime | AJ2: memout | AK2: time | AL2: stime | AM2: status | AN2: rules | AO2: ctime | AP2: fmtime | AQ2: memout | AR2: time | AS2: stime | AT2: rules | AU2: ctime | AV2: fmtime | AW2: memout | AX2: time | AY2: stime | AZ2: rules | BA2: ctime | BB2: fmtime | BC2: memout | BD2: time | BE2: stime | BF2: rules | BG2: ctime | BH2: fmtime | BI2: memout
A3: instances/size-1 | B3: 7.1 | C3: 0.03 | D3: SATISFIABLE | E3: 297383 | F3: 1.213 | G3: 0.01 | H3: 0 | I3: 6.24 | J3: 0.01 | K3: SATISFIABLE | L3: 2337 | M3: 0.162 | N3: 0 | O3: 0 | P3: 5.85 | Q3: 0.01 | R3: SATISFIABLE | S3: 2337 | T3: 0.147 | U3: 0 | V3: 0 | W3: 6.78 | X3: 0.29 | Y3: SATISFIABLE | Z3: 334458 | AA3: 0.927 | AB3: 0.02 | AC3: 0 | AD3: 5.81 | AE3: 0.01 | AF3: SATISFIABLE | AG3: 2572 | AH3: 0.168 | AI3: 0 | AJ3: 0 | AK3: 5.69 | AL3: 0.01 | AM3: SATISFIABLE | AN3: 2572 | AO3: 0.153 | AP3: 0 | AQ3: 0 | AR3: =MIN($B3,$I3,$P3,$W3,$AD3,$AK3) -> 0 | AS3: =MIN($C3,$J3,$Q3,$X3,$AE3,$AL3) -> 0 | AT3: =MIN($E3,$L3,$S3,$Z3,$AG3,$AN3) -> 0 | AU3: =MIN($F3,$M3,$T3,$AA3,$AH3,$AO3) -> 0 | AV3: =MIN($G3,$N3,$U3,$AB3,$AI3,$AP3) -> 0 | AW3: =MIN($H3,$O3,$V3,$AC3,$AJ3,$AQ3) -> 0 | AX3: =MEDIAN($B3,$I3,$P3,$W3,$AD3,$AK3) -> 0 | AY3: =MEDIAN($C3,$J3,$Q3,$X3,$AE3,$AL3) -> 0 | AZ3: =MEDIAN($E3,$L3,$S3,$Z3,$AG3,$AN3) -> 0 | BA3: =MEDIAN($F3,$M3,$T3,$AA3,$AH3,$AO3) -> 0 | BB3: =MEDIAN($G3,$N3,$U3,$AB3,$AI3,$AP3) -> 0 | BC3: =MEDIAN($H3,$O3,$V3,$AC3,$AJ3,$AQ3) -> 0 | BD3: =MAX($B3,$I3,$P3,$W3,$AD3,$AK3) -> 0 | BE3: =MAX($C3,$J3,$Q3,$X3,$AE3,$AL3) -> 0 | BF3: =MAX($E3,$L3,$S3,$Z3,$AG3,$AN3) -> 0 | BG3: =MAX($F3,$M3,$T3,$AA3,$AH3,$AO3) -> 0 | BH3: =MAX($G3,$N3,$U3,$AB3,$AI3,$AP3) -> 0 | BI3: =MAX($H3,$O3,$V3,$AC3,$AJ3,$AQ3) -> 0
A4: instances/size-10 | B4: 1200 | H4: 0 | I4: 1200 | O4: 0 | P4: 1200 | V4: 0 | W4: 1200 | AC4: 0 | AD4: 1200 | AJ4: 0 | AK4: 1200 | AQ4: 0 | AR4: =MIN($B4,$I4,$P4,$W4,$AD4,$AK4) -> 0 | AW4: =MIN($H4,$O4,$V4,$AC4,$AJ4,$AQ4) -> 0 | AX4: =MEDIAN($B4,$I4,$P4,$W4,$AD4,$AK4) -> 0 | BC4: =MEDIAN($H4,$O4,$V4,$AC4,$AJ4,$AQ4) -> 0 | BD4: =MAX($B4,$I4,$P4,$W4,$AD4,$AK4) -> 0 | BI4: =MAX($H4,$O4,$V4,$AC4,$AJ4,$AQ4) -> 0
A5: instances/size-2 | B5: 1200 | H5: 0 | I5: 1200 | O5: 0 | P5: 1200 | V5: 0 | W5: 1200 | AC5: 0 | AD5: 1200 | AJ5: 0 | AK5: 1200 | AQ5: 0 | AR5: =MIN($B5,$I5,$P5,$W5,$AD5,$AK5) -> 0 | AW5: =MIN($H5,$O5,$V5,$AC5,$AJ5,$AQ5) -> 0 | AX5: =MEDIAN($B5,$I5,$P5,$W5,$AD5,$AK5) -> 0 | BC5: =MEDIAN($H5,$O5,$V5,$AC5,$AJ5,$AQ5) -> 0 | BD5: =MAX($B5,$I5,$P5,$W5,$AD5,$AK5) -> 0 | BI5: =MAX($H5,$O5,$V5,$AC5,$AJ5,$AQ5) -> 0
A6: instances/size-3 | B6: 1200 | H6: 0 | I6: 1200 | O6: 0 | P6: 1200 | V6: 0 | W6: 1200 | AC6: 0 | AD6: 1200 | AJ6: 0 | AK6: 1200 | AQ6: 0 | AR6: =MIN($B6,$I6,$P6,$W6,$AD6,$AK6) -> 0 | AW6: =MIN($H6,$O6,$V6,$AC6,$AJ6,$AQ6) -> 0 | AX6: =MEDIAN($B6,$I6,$P6,$W6,$AD6,$AK6) -> 0 | BC6: =MEDIAN($H6,$O6,$V6,$AC6,$AJ6,$AQ6) -> 0 | BD6: =MAX($B6,$I6,$P6,$W6,$AD6,$AK6) -> 0 | BI6: =MAX($H6,$O6,$V6,$AC6,$AJ6,$AQ6) -> 0
A7: instances/size-4 | B7: 1200 | H7: 0 | I7: 1200 | O7: 0 | P7: 1200 | V7: 0 | W7: 1200 | AC7: 0 | AD7: 1200 | AJ7: 0 | AK7: 1200 | AQ7: 0 | AR7: =MIN($B7,$I7,$P7,$W7,$AD7,$AK7) -> 0 | AW7: =MIN($H7,$O7,$V7,$AC7,$AJ7,$AQ7) -> 0 | AX7: =MEDIAN($B7,$I7,$P7,$W7,$AD7,$AK7) -> 0 | BC7: =MEDIAN($H7,$O7,$V7,$AC7,$AJ7,$AQ7) -> 0 | BD7: =MAX($B7,$I7,$P7,$W7,$AD7,$AK7) -> 0 | BI7: =MAX($H7,$O7,$V7,$AC7,$AJ7,$AQ7) -> 0
A8: instances/size-5 | B8: 1200 | H8: 0 | I8: 1200 | O8: 0 | P8: 1200 | V8: 0 | W8: 1200 | AC8: 0 | AD8: 1200 | AJ8: 0 | AK8: 1200 | AQ8: 0 | AR8: =MIN($B8,$I8,$P8,$W8,$AD8,$AK8) -> 0 | AW8: =MIN($H8,$O8,$V8,$AC8,$AJ8,$AQ8) -> 0 | AX8: =MEDIAN($B8,$I8,$P8,$W8,$AD8,$AK8) -> 0 | BC8: =MEDIAN($H8,$O8,$V8,$AC8,$AJ8,$AQ8) -> 0 | BD8: =MAX($B8,$I8,$P8,$W8,$AD8,$AK8) -> 0 | BI8: =MAX($H8,$O8,$V8,$AC8,$AJ8,$AQ8) -> 0
A9: instances/size-6 | B9: 1200 | H9: 0 | I9: 1200 | O9: 0 | P9: 1200 | V9: 0 | W9: 1200 | AC9: 0 | AD9: 1200 | AJ9: 0 | AK9: 1200 | AQ9: 0 | AR9: =MIN($B9,$I9,$P9,$W9,$AD9,$AK9) -> 0 | AW9: =MIN($H9,$O9,$V9,$AC9,$AJ9,$AQ9) -> 0 | AX9: =MEDIAN($B9,$I9,$P9,$W9,$AD9,$AK9) -> 0 | BC9: =MEDIAN($H9,$O9,$V9,$AC9,$AJ9,$AQ9) -> 0 | BD9: =MAX($B9,$I9,$P9,$W9,$AD9,$AK9) -> 0 | BI9: =MAX($H9,$O9,$V9,$AC9,$AJ9,$AQ9) -> 0
A10: instances/size-7 | B10: 1200 | H10: 0 | I10: 1200 | O10: 0 | P10: 1200 | V10: 0 | W10: 1200 | AC10: 0 | AD10: 1200 | AJ10: 0 | AK10: 1200 | AQ10: 0 | AR10: =MIN($B10,$I10,$P10,$W10,$AD10,$AK10) -> 0 | AW10: =MIN($H10,$O10,$V10,$AC10,$AJ10,$AQ10) -> 0 | AX10: =MEDIAN($B10,$I10,$P10,$W10,$AD10,$AK10) -> 0 | BC10: =MEDIAN($H10,$O10,$V10,$AC10,$AJ10,$AQ10) -> 0 | BD10: =MAX($B10,$I10,$P10,$W10,$AD10,$AK10) -> 0 | BI10: =MAX($H10,$O10,$V10,$AC10,$AJ10,$AQ10) -> 0
A11: instances/size-8 | B11: 1200 | H11: 0 | I11: 1200 | O11: 0 | P11: 1200 | V11: 0 | W11: 1200 | AC11: 0 | AD11: 1200 | AJ11: 0 | AK11: 1200 | AQ11: 0 | AR11: =MIN($B11,$I11,$P11,$W11,$AD11,$AK11) -> 0 | AW11: =MIN($H11,$O11,$V11,$AC11,$AJ11,$AQ11) -> 0 | AX11: =MEDIAN($B11,$I11,$P11,$W11,$AD11,$AK11) -> 0 | BC11: =MEDIAN($H11,$O11,$V11,$AC11,$AJ11,$AQ11) -> 0 | BD11: =MAX($B11,$I11,$P11,$W11,$AD11,$AK11) -> 0 | BI11: =MAX($H11,$O11,$V11,$AC11,$AJ11,$AQ11) -> 0
A12: instances/size-9 | B12: 1200 | H12: 0 | I12: 1200 | O12: 0 | P12: 1200 | V12: 0 | W12: 1200 | AC12: 0 | AD12: 1200 | AJ12: 0 | AK12: 1200 | AQ12: 0 | AR12: =MIN($B12,$I12,$P12,$W12,$AD12,$AK12) -> 0 | AW12: =MIN($H12,$O12,$V12,$AC12,$AJ12,$AQ12) -> 0 | AX12: =MEDIAN($B12,$I12,$P12,$W12,$AD12,$AK12) -> 0 | BC12: =MEDIAN($H12,$O12,$V12,$AC12,$AJ12,$AQ12) -> 0 | BD12: =MAX($B12,$I12,$P12,$W12,$AD12,$AK12) -> 0 | BI12: =MAX($H12,$O12,$V12,$AC12,$AJ12,$AQ12) -> 0
A14: SUM | B14: =SUM(B$3:B$12) -> 0 | C14: =SUM(C$3:C$12) -> 0 | E14: =SUM(E$3:E$12) -> 0 | F14: =SUM(F$3:F$12) -> 0 | G14: =SUM(G$3:G$12) -> 0 | H14: =SUM(H$3:H$12) -> 0 | I14: =SUM(I$3:I$12) -> 0 | J14: =SUM(J$3:J$12) -> 0 | L14: =SUM(L$3:L$12) -> 0 | M14: =SUM(M$3:M$12) -> 0 | N14: =SUM(N$3:N$12) -> 0 | O14: =SUM(O$3:O$12) -> 0 | P14: =SUM(P$3:P$12) -> 0 | Q14: =SUM(Q$3:Q$12) -> 0 | S14: =SUM(S$3:S$12) -> 0 | T14: =SUM(T$3:T$12) -> 0 | U14: =SUM(U$3:U$12) -> 0 | V14: =SUM(V$3:V$12) -> 0 | W14: =SUM(W$3:W$12) -> 0 | X14: =SUM(X$3:X$12) -> 0 | Z14: =SUM(Z$3:Z$12) -> 0 | AA14: =SUM(AA$3:AA$12) -> 0 | AB14: =SUM(AB$3:AB$12) -> 0 | AC14: =SUM(AC$3:AC$12) -> 0 | AD14: =SUM(AD$3:AD$12) -> 0 | AE14: =SUM(AE$3:AE$12) -> 0 | AG14: =SUM(AG$3:AG$12) -> 0 | AH14: =SUM(AH$3:AH$12) -> 0 | AI14: =SUM(AI$3:AI$12) -> 0 | AJ14: =SUM(AJ$3:AJ$12) -> 0 | AK14: =SUM(AK$3:AK$12) -> 0 | AL14: =SUM(AL$3:AL$12) -> 0 | AN14: =SUM(AN$3:AN$12) -> 0 | AO14: =SUM(AO$3:AO$12) -> 0 | AP14: =SUM(AP$3:AP$12) -> 0 | AQ14: =SUM(AQ$3:AQ$12) -> 0 | AR14: =SUM(AR$3:AR$12) -> 0 | AS14: =SUM(AS$3:AS$12) -> 0 | AT14: =SUM(AT$3:AT$12) -> 0 | AU14: =SUM(AU$3:AU$12) -> 0 | ... BI14: =SUM(BI$3:BI$12) -> 0
A15: AVG | B15: =AVERAGE(B$3:B$12) -> 0 | C15: =AVERAGE(C$3:C$12) -> 0 | E15: =AVERAGE(E$3:E$12) -> 0 | F15: =AVERAGE(F$3:F$12) -> 0 | G15: =AVERAGE(G$3:G$12) -> 0 | H15: =AVERAGE(H$3:H$12) -> 0 | I15: =AVERAGE(I$3:I$12) -> 0 | J15: =AVERAGE(J$3:J$12) -> 0 | L15: =AVERAGE(L$3:L$12) -> 0 | M15: =AVERAGE(M$3:M$12) -> 0 | N15: =AVERAGE(N$3:N$12) -> 0 | O15: =AVERAGE(O$3:O$12) -> 0 | P15: =AVERAGE(P$3:P$12) -> 0 | Q15: =AVERAGE(Q$3:Q$12) -> 0 | S15: =AVERAGE(S$3:S$12) -> 0 | T15: =AVERAGE(T$3:T$12) -> 0 | U15: =AVERAGE(U$3:U$12) -> 0 | V15: =AVERAGE(V$3:V$12) -> 0 | W15: =AVERAGE(W$3:W$12) -> 0 | X15: =AVERAGE(X$3:X$12) -> 0 | Z15: =AVERAGE(Z$3:Z$12) -> 0 | AA15: =AVERAGE(AA$3:AA$12) -> 0 | AB15: =AVERAGE(AB$3:AB$12) -> 0 | AC15: =AVERAGE(AC$3:AC$12) -> 0 | AD15: =AVERAGE(AD$3:AD$12) -> 0 | AE15: =AVERAGE(AE$3:AE$12) -> 0 | AG15: =AVERAGE(AG$3:AG$12) -> 0 | AH15: =AVERAGE(AH$3:AH$12) -> 0 | AI15: =AVERAGE(AI$3:AI$12) -> 0 | AJ15: =AVERAGE(AJ$3:AJ$12) -> 0 | AK15: =AVERAGE(AK$3:AK$12) -> 0 | AL15: =AVERAGE(AL$3:AL$12) -> 0 | AN15: =AVERAGE(AN$3:AN$12) -> 0 | AO15: =AVERAGE(AO$3:AO$12) -> 0 | AP15: =AVERAGE(AP$3:AP$12) -> 0 | AQ15: =AVERAGE(AQ$3:AQ$12) -> 0 | AR15: =AVERAGE(AR$3:AR$12) -> 0 | AS15: =AVERAGE(AS$3:AS$12) -> 0 | AT15: =AVERAGE(AT$3:AT$12) -> 0 | AU15: =AVERAGE(AU$3:AU$12) -> 0 | ... BI15: =AVERAGE(BI$3:BI$12) -> 0
A16: DEV | B16: =STDEV(B$3:B$12) -> 0 | C16: =STDEV(C$3:C$12) -> 0 | E16: =STDEV(E$3:E$12) -> 0 | F16: =STDEV(F$3:F$12) -> 0 | G16: =STDEV(G$3:G$12) -> 0 | H16: =STDEV(H$3:H$12) -> 0 | I16: =STDEV(I$3:I$12) -> 0 | J16: =STDEV(J$3:J$12) -> 0 | L16: =STDEV(L$3:L$12) -> 0 | M16: =STDEV(M$3:M$12) -> 0 | N16: =STDEV(N$3:N$12) -> 0 | O16: =STDEV(O$3:O$12) -> 0 | P16: =STDEV(P$3:P$12) -> 0 | Q16: =STDEV(Q$3:Q$12) -> 0 | S16: =STDEV(S$3:S$12) -> 0 | T16: =STDEV(T$3:T$12) -> 0 | U16: =STDEV(U$3:U$12) -> 0 | V16: =STDEV(V$3:V$12) -> 0 | W16: =STDEV(W$3:W$12) -> 0 | X16: =STDEV(X$3:X$12) -> 0 | Z16: =STDEV(Z$3:Z$12) -> 0 | AA16: =STDEV(AA$3:AA$12) -> 0 | AB16: =STDEV(AB$3:AB$12) -> 0 | AC16: =STDEV(AC$3:AC$12) -> 0 | AD16: =STDEV(AD$3:AD$12) -> 0 | AE16: =STDEV(AE$3:AE$12) -> 0 | AG16: =STDEV(AG$3:AG$12) -> 0 | AH16: =STDEV(AH$3:AH$12) -> 0 | AI16: =STDEV(AI$3:AI$12) -> 0 | AJ16: =STDEV(AJ$3:AJ$12) -> 0 | AK16: =STDEV(AK$3:AK$12) -> 0 | AL16: =STDEV(AL$3:AL$12) -> 0 | AN16: =STDEV(AN$3:AN$12) -> 0 | AO16: =STDEV(AO$3:AO$12) -> 0 | AP16: =STDEV(AP$3:AP$12) -> 0 | AQ16: =STDEV(AQ$3:AQ$12) -> 0 | AR16: =STDEV(AR$3:AR$12) -> 0 | AS16: =STDEV(AS$3:AS$12) -> 0 | AT16: =STDEV(AT$3:AT$12) -> 0 | AU16: =STDEV(AU$3:AU$12) -> 0 | ... BI16: =STDEV(BI$3:BI$12) -> 0
A17: DST | B17: =SUMPRODUCT(--(B$3:B$12-$AR$3:$AR$12)^2)^0.5 -> 0 | C17: =SUMPRODUCT(--(C$3:C$12-$AS$3:$AS$12)^2)^0.5 -> 0 | E17: =SUMPRODUCT(--(E$3:E$12-$AT$3:$AT$12)^2)^0.5 -> 0 | F17: =SUMPRODUCT(--(F$3:F$12-$AU$3:$AU$12)^2)^0.5 -> 0 | G17: =SUMPRODUCT(--(G$3:G$12-$AV$3:$AV$12)^2)^0.5 -> 0 | H17: =SUMPRODUCT(--(H$3:H$12-$AW$3:$AW$12)^2)^0.5 -> 0 | I17: =SUMPRODUCT(--(I$3:I$12-$AR$3:$AR$12)^2)^0.5 -> 0 | J17: =SUMPRODUCT(--(J$3:J$12-$AS$3:$AS$12)^2)^0.5 -> 0 | L17: =SUMPRODUCT(--(L$3:L$12-$AT$3:$AT$12)^2)^0.5 -> 0 | M17: =SUMPRODUCT(--(M$3:M$12-$AU$3:$AU$12)^2)^0.5 -> 0 | N17: =SUMPRODUCT(--(N$3:N$12-$AV$3:$AV$12)^2)^0.5 -> 0 | O17: =SUMPRODUCT(--(O$3:O$12-$AW$3:$AW$12)^2)^0.5 -> 0 | P17: =SUMPRODUCT(--(P$3:P$12-$AR$3:$AR$12)^2)^0.5 -> 0 | Q17: =SUMPRODUCT(--(Q$3:Q$12-$AS$3:$AS$12)^2)^0.5 -> 0 | S17: =SUMPRODUCT(--(S$3:S$12-$AT$3:$AT$12)^2)^0.5 -> 0 | T17: =SUMPRODUCT(--(T$3:T$12-$AU$3:$AU$12)^2)^0.5 -> 0 | U17: =SUMPRODUCT(--(U$3:U$12-$AV$3:$AV$12)^2)^0.5 -> 0 | V17: =SUMPRODUCT(--(V$3:V$12-$AW$3:$AW$12)^2)^0.5 -> 0 | W17: =SUMPRODUCT(--(W$3:W$12-$AR$3:$AR$12)^2)^0.5 -> 0 | X17: =SUMPRODUCT(--(X$3:X$12-$AS$3:$AS$12)^2)^0.5 -> 0 | Z17: =SUMPRODUCT(--(Z$3:Z$12-$AT$3:$AT$12)^2)^0.5 -> 0 | AA17: =SUMPRODUCT(--(AA$3:AA$12-$AU$3:$AU$12)^2)^0.5 -> 0 | AB17: =SUMPRODUCT(--(AB$3:AB$12-$AV$3:$AV$12)^2)^0.5 -> 0 | AC17: =SUMPRODUCT(--(AC$3:AC$12-$AW$3:$AW$12)^2)^0.5 -> 0 | AD17: =SUMPRODUCT(--(AD$3:AD$12-$AR$3:$AR$12)^2)^0.5 -> 0 | AE17: =SUMPRODUCT(--(AE$3:AE$12-$AS$3:$AS$12)^2)^0.5 -> 0 | AG17: =SUMPRODUCT(--(AG$3:AG$12-$AT$3:$AT$12)^2)^0.5 -> 0 | AH17: =SUMPRODUCT(--(AH$3:AH$12-$AU$3:$AU$12)^2)^0.5 -> 0 | AI17: =SUMPRODUCT(--(AI$3:AI$12-$AV$3:$AV$12)^2)^0.5 -> 0 | AJ17: =SUMPRODUCT(--(AJ$3:AJ$12-$AW$3:$AW$12)^2)^0.5 -> 0 | AK17: =SUMPRODUCT(--(AK$3:AK$12-$AR$3:$AR$12)^2)^0.5 -> 0 | AL17: =SUMPRODUCT(--(AL$3:AL$12-$AS$3:$AS$12)^2)^0.5 -> 0 | AN17: =SUMPRODUCT(--(AN$3:AN$12-$AT$3:$AT$12)^2)^0.5 -> 0 | AO17: =SUMPRODUCT(--(AO$3:AO$12-$AU$3:$AU$12)^2)^0.5 -> 0 | AP17: =SUMPRODUCT(--(AP$3:AP$12-$AV$3:$AV$12)^2)^0.5 -> 0 | AQ17: =SUMPRODUCT(--(AQ$3:AQ$12-$AW$3:$AW$12)^2)^0.5 -> 0
A18: BEST | B18: =SUMPRODUCT(NOT(ISBLANK(B$3:B$12))*(B$3:B$12=$AR$3:$AR$12)) -> 0 | C18: =SUMPRODUCT(NOT(ISBLANK(C$3:C$12))*(C$3:C$12=$AS$3:$AS$12)) -> 0 | E18: =SUMPRODUCT(NOT(ISBLANK(E$3:E$12))*(E$3:E$12=$AT$3:$AT$12)) -> 0 | F18: =SUMPRODUCT(NOT(ISBLANK(F$3:F$12))*(F$3:F$12=$AU$3:$AU$12)) -> 0 | G18: =SUMPRODUCT(NOT(ISBLANK(G$3:G$12))*(G$3:G$12=$AV$3:$AV$12)) -> 0 | H18: =SUMPRODUCT(NOT(ISBLANK(H$3:H$12))*(H$3:H$12=$AW$3:$AW$12)) -> 0 | I18: =SUMPRODUCT(NOT(ISBLANK(I$3:I$12))*(I$3:I$12=$AR$3:$AR$12)) -> 0 | J18: =SUMPRODUCT(NOT(ISBLANK(J$3:J$12))*(J$3:J$12=$AS$3:$AS$12)) -> 0 | L18: =SUMPRODUCT(NOT(ISBLANK(L$3:L$12))*(L$3:L$12=$AT$3:$AT$12)) -> 0 | M18: =SUMPRODUCT(NOT(ISBLANK(M$3:M$12))*(M$3:M$12=$AU$3:$AU$12)) -> 0 | N18: =SUMPRODUCT(NOT(ISBLANK(N$3:N$12))*(N$3:N$12=$AV$3:$AV$12)) -> 0 | O18: =SUMPRODUCT(NOT(ISBLANK(O$3:O$12))*(O$3:O$12=$AW$3:$AW$12)) -> 0 | P18: =SUMPRODUCT(NOT(ISBLANK(P$3:P$12))*(P$3:P$12=$AR$3:$AR$12)) -> 0 | Q18: =SUMPRODUCT(NOT(ISBLANK(Q$3:Q$12))*(Q$3:Q$12=$AS$3:$AS$12)) -> 0 | S18: =SUMPRODUCT(NOT(ISBLANK(S$3:S$12))*(S$3:S$12=$AT$3:$AT$12)) -> 0 | T18: =SUMPRODUCT(NOT(ISBLANK(T$3:T$12))*(T$3:T$12=$AU$3:$AU$12)) -> 0 | U18: =SUMPRODUCT(NOT(ISBLANK(U$3:U$12))*(U$3:U$12=$AV$3:$AV$12)) -> 0 | V18: =SUMPRODUCT(NOT(ISBLANK(V$3:V$12))*(V$3:V$12=$AW$3:$AW$12)) -> 0 | W18: =SUMPRODUCT(NOT(ISBLANK(W$3:W$12))*(W$3:W$12=$AR$3:$AR$12)) -> 0 | X18: =SUMPRODUCT(NOT(ISBLANK(X$3:X$12))*(X$3:X$12=$AS$3:$AS$12)) -> 0 | Z18: =SUMPRODUCT(NOT(ISBLANK(Z$3:Z$12))*(Z$3:Z$12=$AT$3:$AT$12)) -> 0 | AA18: =SUMPRODUCT(NOT(ISBLANK(AA$3:AA$12))*(AA$3:AA$12=$AU$3:$AU$12)) -> 0 | AB18: =SUMPRODUCT(NOT(ISBLANK(AB$3:AB$12))*(AB$3:AB$12=$AV$3:$AV$12)) -> 0 | AC18: =SUMPRODUCT(NOT(ISBLANK(AC$3:AC$12))*(AC$3:AC$12=$AW$3:$AW$12)) -> 0 | AD18: =SUMPRODUCT(NOT(ISBLANK(AD$3:AD$12))*(AD$3:AD$12=$AR$3:$AR$12)) -> 0 | AE18: =SUMPRODUCT(NOT(ISBLANK(AE$3:AE$12))*(AE$3:AE$12=$AS$3:$AS$12)) -> 0 | AG18: =SUMPRODUCT(NOT(ISBLANK(AG$3:AG$12))*(AG$3:AG$12=$AT$3:$AT$12)) -> 0 | AH18: =SUMPRODUCT(NOT(ISBLANK(AH$3:AH$12))*(AH$3:AH$12=$AU$3:$AU$12)) -> 0 | AI18: =SUMPRODUCT(NOT(ISBLANK(AI$3:AI$12))*(AI$3:AI$12=$AV$3:$AV$12)) -> 0 | AJ18: =SUMPRODUCT(NOT(ISBLANK(AJ$3:AJ$12))*(AJ$3:AJ$12=$AW$3:$AW$12)) -> 0 | AK18: =SUMPRODUCT(NOT(ISBLANK(AK$3:AK$12))*(AK$3:AK$12=$AR$3:$AR$12)) -> 0 | AL18: =SUMPRODUCT(NOT(ISBLANK(AL$3:AL$12))*(AL$3:AL$12=$AS$3:$AS$12)) -> 0 | AN18: =SUMPRODUCT(NOT(ISBLANK(AN$3:AN$12))*(AN$3:AN$12=$AT$3:$AT$12)) -> 0 | AO18: =SUMPRODUCT(NOT(ISBLANK(AO$3:AO$12))*(AO$3:AO$12=$AU$3:$AU$12)) -> 0 | AP18: =SUMPRODUCT(NOT(ISBLANK(AP$3:AP$12))*(AP$3:AP$12=$AV$3:$AV$12)) -> 0 | AQ18: =SUMPRODUCT(NOT(ISBLANK(AQ$3:AQ$12))*(AQ$3:AQ$12=$AW$3:$AW$12)) -> 0
A19: BETTER | B19: =SUMPRODUCT(NOT(ISBLANK(B$3:B$12))*(B$3:B$12<$AX$3:$AX$12)) -> 0 | C19: =SUMPRODUCT(NOT(ISBLANK(C$3:C$12))*(C$3:C$12<$AY$3:$AY$12)) -> 0 | E19: =SUMPRODUCT(NOT(ISBLANK(E$3:E$12))*(E$3:E$12<$AZ$3:$AZ$12)) -> 0 | F19: =SUMPRODUCT(NOT(ISBLANK(F$3:F$12))*(F$3:F$12<$BA$3:$BA$12)) -> 0 | G19: =SUMPRODUCT(NOT(ISBLANK(G$3:G$12))*(G$3:G$12<$BB$3:$BB$12)) -> 0 | H19: =SUMPRODUCT(NOT(ISBLANK(H$3:H$12))*(H$3:H$12<$BC$3:$BC$12)) -> 0 | I19: =SUMPRODUCT(NOT(ISBLANK(I$3:I$12))*(I$3:I$12<$AX$3:$AX$12)) -> 0 | J19: =SUMPRODUCT(NOT(ISBLANK(J$3:J$12))*(J$3:J$12<$AY$3:$AY$12)) -> 0 | L19: =SUMPRODUCT(NOT(ISBLANK(L$3:L$12))*(L$3:L$12<$AZ$3:$AZ$12)) -> 0 | M19: =SUMPRODUCT(NOT(ISBLANK(M$3:M$12))*(M$3:M$12<$BA$3:$BA$12)) -> 0 | N19: =SUMPRODUCT(NOT(ISBLANK(N$3:N$12))*(N$3:N$12<$BB$3:$BB$12)) -> 0 | O19: =SUMPRODUCT(NOT(ISBLANK(O$3:O$12))*(O$3:O$12<$BC$3:$BC$12)) -> 0 | P19: =SUMPRODUCT(NOT(ISBLANK(P$3:P$12))*(P$3:P$12<$AX$3:$AX$12)) -> 0 | Q19: =SUMPRODUCT(NOT(ISBLANK(Q$3:Q$12))*(Q$3:Q$12<$AY$3:$AY$12)) -> 0 | S19: =SUMPRODUCT(NOT(ISBLANK(S$3:S$12))*(S$3:S$12<$AZ$3:$AZ$12)) -> 0 | T19: =SUMPRODUCT(NOT(ISBLANK(T$3:T$12))*(T$3:T$12<$BA$3:$BA$12)) -> 0 | U19: =SUMPRODUCT(NOT(ISBLANK(U$3:U$12))*(U$3:U$12<$BB$3:$BB$12)) -> 0 | V19: =SUMPRODUCT(NOT(ISBLANK(V$3:V$12))*(V$3:V$12<$BC$3:$BC$12)) -> 0 | W19: =SUMPRODUCT(NOT(ISBLANK(W$3:W$12))*(W$3:W$12<$AX$3:$AX$12)) -> 0 | X19: =SUMPRODUCT(NOT(ISBLANK(X$3:X$12))*(X$3:X$12<$AY$3:$AY$12)) -> 0 | Z19: =SUMPRODUCT(NOT(ISBLANK(Z$3:Z$12))*(Z$3:Z$12<$AZ$3:$AZ$12)) -> 0 | AA19: =SUMPRODUCT(NOT(ISBLANK(AA$3:AA$12))*(AA$3:AA$12<$BA$3:$BA$12)) -> 0 | AB19: =SUMPRODUCT(NOT(ISBLANK(AB$3:AB$12))*(AB$3:AB$12<$BB$3:$BB$12)) -> 0 | AC19: =SUMPRODUCT(NOT(ISBLANK(AC$3:AC$12))*(AC$3:AC$12<$BC$3:$BC$12)) -> 0 | AD19: =SUMPRODUCT(NOT(ISBLANK(AD$3:AD$12))*(AD$3:AD$12<$AX$3:$AX$12)) -> 0 | AE19: =SUMPRODUCT(NOT(ISBLANK(AE$3:AE$12))*(AE$3:AE$12<$AY$3:$AY$12)) -> 0 | AG19: =SUMPRODUCT(NOT(ISBLANK(AG$3:AG$12))*(AG$3:AG$12<$AZ$3:$AZ$12)) -> 0 | AH19: =SUMPRODUCT(NOT(ISBLANK(AH$3:AH$12))*(AH$3:AH$12<$BA$3:$BA$12)) -> 0 | AI19: =SUMPRODUCT(NOT(ISBLANK(AI$3:AI$12))*(AI$3:AI$12<$BB$3:$BB$12)) -> 0 | AJ19: =SUMPRODUCT(NOT(ISBLANK(AJ$3:AJ$12))*(AJ$3:AJ$12<$BC$3:$BC$12)) -> 0 | AK19: =SUMPRODUCT(NOT(ISBLANK(AK$3:AK$12))*(AK$3:AK$12<$AX$3:$AX$12)) -> 0 | AL19: =SUMPRODUCT(NOT(ISBLANK(AL$3:AL$12))*(AL$3:AL$12<$AY$3:$AY$12)) -> 0 | AN19: =SUMPRODUCT(NOT(ISBLANK(AN$3:AN$12))*(AN$3:AN$12<$AZ$3:$AZ$12)) -> 0 | AO19: =SUMPRODUCT(NOT(ISBLANK(AO$3:AO$12))*(AO$3:AO$12<$BA$3:$BA$12)) -> 0 | AP19: =SUMPRODUCT(NOT(ISBLANK(AP$3:AP$12))*(AP$3:AP$12<$BB$3:$BB$12)) -> 0 | AQ19: =SUMPRODUCT(NOT(ISBLANK(AQ$3:AQ$12))*(AQ$3:AQ$12<$BC$3:$BC$12)) -> 0
A20: WORSE | B20: =SUMPRODUCT((NOT(ISBLANK(B$3:B$12))*(B$3:B$12>$AX$3:$AX$12))+ISBLANK(B$3:B$12)) -> 0 | C20: =SUMPRODUCT((NOT(ISBLANK(C$3:C$12))*(C$3:C$12>$AY$3:$AY$12))+ISBLANK(C$3:C$12)) -> 0 | E20: =SUMPRODUCT((NOT(ISBLANK(E$3:E$12))*(E$3:E$12>$AZ$3:$AZ$12))+ISBLANK(E$3:E$12)) -> 0 | F20: =SUMPRODUCT((NOT(ISBLANK(F$3:F$12))*(F$3:F$12>$BA$3:$BA$12))+ISBLANK(F$3:F$12)) -> 0 | G20: =SUMPRODUCT((NOT(ISBLANK(G$3:G$12))*(G$3:G$12>$BB$3:$BB$12))+ISBLANK(G$3:G$12)) -> 0 | H20: =SUMPRODUCT((NOT(ISBLANK(H$3:H$12))*(H$3:H$12>$BC$3:$BC$12))+ISBLANK(H$3:H$12)) -> 0 | I20: =SUMPRODUCT((NOT(ISBLANK(I$3:I$12))*(I$3:I$12>$AX$3:$AX$12))+ISBLANK(I$3:I$12)) -> 0 | J20: =SUMPRODUCT((NOT(ISBLANK(J$3:J$12))*(J$3:J$12>$AY$3:$AY$12))+ISBLANK(J$3:J$12)) -> 0 | L20: =SUMPRODUCT((NOT(ISBLANK(L$3:L$12))*(L$3:L$12>$AZ$3:$AZ$12))+ISBLANK(L$3:L$12)) -> 0 | M20: =SUMPRODUCT((NOT(ISBLANK(M$3:M$12))*(M$3:M$12>$BA$3:$BA$12))+ISBLANK(M$3:M$12)) -> 0 | N20: =SUMPRODUCT((NOT(ISBLANK(N$3:N$12))*(N$3:N$12>$BB$3:$BB$12))+ISBLANK(N$3:N$12)) -> 0 | O20: =SUMPRODUCT((NOT(ISBLANK(O$3:O$12))*(O$3:O$12>$BC$3:$BC$12))+ISBLANK(O$3:O$12)) -> 0 | P20: =SUMPRODUCT((NOT(ISBLANK(P$3:P$12))*(P$3:P$12>$AX$3:$AX$12))+ISBLANK(P$3:P$12)) -> 0 | Q20: =SUMPRODUCT((NOT(ISBLANK(Q$3:Q$12))*(Q$3:Q$12>$AY$3:$AY$12))+ISBLANK(Q$3:Q$12)) -> 0 | S20: =SUMPRODUCT((NOT(ISBLANK(S$3:S$12))*(S$3:S$12>$AZ$3:$AZ$12))+ISBLANK(S$3:S$12)) -> 0 | T20: =SUMPRODUCT((NOT(ISBLANK(T$3:T$12))*(T$3:T$12>$BA$3:$BA$12))+ISBLANK(T$3:T$12)) -> 0 | U20: =SUMPRODUCT((NOT(ISBLANK(U$3:U$12))*(U$3:U$12>$BB$3:$BB$12))+ISBLANK(U$3:U$12)) -> 0 | V20: =SUMPRODUCT((NOT(ISBLANK(V$3:V$12))*(V$3:V$12>$BC$3:$BC$12))+ISBLANK(V$3:V$12)) -> 0 | W20: =SUMPRODUCT((NOT(ISBLANK(W$3:W$12))*(W$3:W$12>$AX$3:$AX$12))+ISBLANK(W$3:W$12)) -> 0 | X20: =SUMPRODUCT((NOT(ISBLANK(X$3:X$12))*(X$3:X$12>$AY$3:$AY$12))+ISBLANK(X$3:X$12)) -> 0 | Z20: =SUMPRODUCT((NOT(ISBLANK(Z$3:Z$12))*(Z$3:Z$12>$AZ$3:$AZ$12))+ISBLANK(Z$3:Z$12)) -> 0 | AA20: =SUMPRODUCT((NOT(ISBLANK(AA$3:AA$12))*(AA$3:AA$12>$BA$3:$BA$12))+ISBLANK(AA$3:AA$12)) -> 0 | AB20: =SUMPRODUCT((NOT(ISBLANK(AB$3:AB$12))*(AB$3:AB$12>$BB$3:$BB$12))+ISBLANK(AB$3:AB$12)) -> 0 | AC20: =SUMPRODUCT((NOT(ISBLANK(AC$3:AC$12))*(AC$3:AC$12>$BC$3:$BC$12))+ISBLANK(AC$3:AC$12)) -> 0 | AD20: =SUMPRODUCT((NOT(ISBLANK(AD$3:AD$12))*(AD$3:AD$12>$AX$3:$AX$12))+ISBLANK(AD$3:AD$12)) -> 0 | AE20: =SUMPRODUCT((NOT(ISBLANK(AE$3:AE$12))*(AE$3:AE$12>$AY$3:$AY$12))+ISBLANK(AE$3:AE$12)) -> 0 | AG20: =SUMPRODUCT((NOT(ISBLANK(AG$3:AG$12))*(AG$3:AG$12>$AZ$3:$AZ$12))+ISBLANK(AG$3:AG$12)) -> 0 | AH20: =SUMPRODUCT((NOT(ISBLANK(AH$3:AH$12))*(AH$3:AH$12>$BA$3:$BA$12))+ISBLANK(AH$3:AH$12)) -> 0 | AI20: =SUMPRODUCT((NOT(ISBLANK(AI$3:AI$12))*(AI$3:AI$12>$BB$3:$BB$12))+ISBLANK(AI$3:AI$12)) -> 0 | AJ20: =SUMPRODUCT((NOT(ISBLANK(AJ$3:AJ$12))*(AJ$3:AJ$12>$BC$3:$BC$12))+ISBLANK(AJ$3:AJ$12)) -> 0 | AK20: =SUMPRODUCT((NOT(ISBLANK(AK$3:AK$12))*(AK$3:AK$12>$AX$3:$AX$12))+ISBLANK(AK$3:AK$12)) -> 0 | AL20: =SUMPRODUCT((NOT(ISBLANK(AL$3:AL$12))*(AL$3:AL$12>$AY$3:$AY$12))+ISBLANK(AL$3:AL$12)) -> 0 | AN20: =SUMPRODUCT((NOT(ISBLANK(AN$3:AN$12))*(AN$3:AN$12>$AZ$3:$AZ$12))+ISBLANK(AN$3:AN$12)) -> 0 | AO20: =SUMPRODUCT((NOT(ISBLANK(AO$3:AO$12))*(AO$3:AO$12>$BA$3:$BA$12))+ISBLANK(AO$3:AO$12)) -> 0 | AP20: =SUMPRODUCT((NOT(ISBLANK(AP$3:AP$12))*(AP$3:AP$12>$BB$3:$BB$12))+ISBLANK(AP$3:AP$12)) -> 0 | AQ20: =SUMPRODUCT((NOT(ISBLANK(AQ$3:AQ$12))*(AQ$3:AQ$12>$BC$3:$BC$12))+ISBLANK(AQ$3:AQ$12)) -> 0
A21: WORST | B21: =SUMPRODUCT((NOT(ISBLANK(B$3:B$12))*(B$3:B$12=$BD$3:$BD$12))+ISBLANK(B$3:B$12)) -> 0 | C21: =SUMPRODUCT((NOT(ISBLANK(C$3:C$12))*(C$3:C$12=$BE$3:$BE$12))+ISBLANK(C$3:C$12)) -> 0 | E21: =SUMPRODUCT((NOT(ISBLANK(E$3:E$12))*(E$3:E$12=$BF$3:$BF$12))+ISBLANK(E$3:E$12)) -> 0 | F21: =SUMPRODUCT((NOT(ISBLANK(F$3:F$12))*(F$3:F$12=$BG$3:$BG$12))+ISBLANK(F$3:F$12)) -> 0 | G21: =SUMPRODUCT((NOT(ISBLANK(G$3:G$12))*(G$3:G$12=$BH$3:$BH$12))+ISBLANK(G$3:G$12)) -> 0 | H21: =SUMPRODUCT((NOT(ISBLANK(H$3:H$12))*(H$3:H$12=$BI$3:$BI$12))+ISBLANK(H$3:H$12)) -> 0 | I21: =SUMPRODUCT((NOT(ISBLANK(I$3:I$12))*(I$3:I$12=$BD$3:$BD$12))+ISBLANK(I$3:I$12)) -> 0 | J21: =SUMPRODUCT((NOT(ISBLANK(J$3:J$12))*(J$3:J$12=$BE$3:$BE$12))+ISBLANK(J$3:J$12)) -> 0 | L21: =SUMPRODUCT((NOT(ISBLANK(L$3:L$12))*(L$3:L$12=$BF$3:$BF$12))+ISBLANK(L$3:L$12)) -> 0 | M21: =SUMPRODUCT((NOT(ISBLANK(M$3:M$12))*(M$3:M$12=$BG$3:$BG$12))+ISBLANK(M$3:M$12)) -> 0 | N21: =SUMPRODUCT((NOT(ISBLANK(N$3:N$12))*(N$3:N$12=$BH$3:$BH$12))+ISBLANK(N$3:N$12)) -> 0 | O21: =SUMPRODUCT((NOT(ISBLANK(O$3:O$12))*(O$3:O$12=$BI$3:$BI$12))+ISBLANK(O$3:O$12)) -> 0 | P21: =SUMPRODUCT((NOT(ISBLANK(P$3:P$12))*(P$3:P$12=$BD$3:$BD$12))+ISBLANK(P$3:P$12)) -> 0 | Q21: =SUMPRODUCT((NOT(ISBLANK(Q$3:Q$12))*(Q$3:Q$12=$BE$3:$BE$12))+ISBLANK(Q$3:Q$12)) -> 0 | S21: =SUMPRODUCT((NOT(ISBLANK(S$3:S$12))*(S$3:S$12=$BF$3:$BF$12))+ISBLANK(S$3:S$12)) -> 0 | T21: =SUMPRODUCT((NOT(ISBLANK(T$3:T$12))*(T$3:T$12=$BG$3:$BG$12))+ISBLANK(T$3:T$12)) -> 0 | U21: =SUMPRODUCT((NOT(ISBLANK(U$3:U$12))*(U$3:U$12=$BH$3:$BH$12))+ISBLANK(U$3:U$12)) -> 0 | V21: =SUMPRODUCT((NOT(ISBLANK(V$3:V$12))*(V$3:V$12=$BI$3:$BI$12))+ISBLANK(V$3:V$12)) -> 0 | W21: =SUMPRODUCT((NOT(ISBLANK(W$3:W$12))*(W$3:W$12=$BD$3:$BD$12))+ISBLANK(W$3:W$12)) -> 0 | X21: =SUMPRODUCT((NOT(ISBLANK(X$3:X$12))*(X$3:X$12=$BE$3:$BE$12))+ISBLANK(X$3:X$12)) -> 0 | Z21: =SUMPRODUCT((NOT(ISBLANK(Z$3:Z$12))*(Z$3:Z$12=$BF$3:$BF$12))+ISBLANK(Z$3:Z$12)) -> 0 | AA21: =SUMPRODUCT((NOT(ISBLANK(AA$3:AA$12))*(AA$3:AA$12=$BG$3:$BG$12))+ISBLANK(AA$3:AA$12)) -> 0 | AB21: =SUMPRODUCT((NOT(ISBLANK(AB$3:AB$12))*(AB$3:AB$12=$BH$3:$BH$12))+ISBLANK(AB$3:AB$12)) -> 0 | AC21: =SUMPRODUCT((NOT(ISBLANK(AC$3:AC$12))*(AC$3:AC$12=$BI$3:$BI$12))+ISBLANK(AC$3:AC$12)) -> 0 | AD21: =SUMPRODUCT((NOT(ISBLANK(AD$3:AD$12))*(AD$3:AD$12=$BD$3:$BD$12))+ISBLANK(AD$3:AD$12)) -> 0 | AE21: =SUMPRODUCT((NOT(ISBLANK(AE$3:AE$12))*(AE$3:AE$12=$BE$3:$BE$12))+ISBLANK(AE$3:AE$12)) -> 0 | AG21: =SUMPRODUCT((NOT(ISBLANK(AG$3:AG$12))*(AG$3:AG$12=$BF$3:$BF$12))+ISBLANK(AG$3:AG$12)) -> 0 | AH21: =SUMPRODUCT((NOT(ISBLANK(AH$3:AH$12))*(AH$3:AH$12=$BG$3:$BG$12))+ISBLANK(AH$3:AH$12)) -> 0 | AI21: =SUMPRODUCT((NOT(ISBLANK(AI$3:AI$12))*(AI$3:AI$12=$BH$3:$BH$12))+ISBLANK(AI$3:AI$12)) -> 0 | AJ21: =SUMPRODUCT((NOT(ISBLANK(AJ$3:AJ$12))*(AJ$3:AJ$12=$BI$3:$BI$12))+ISBLANK(AJ$3:AJ$12)) -> 0 | AK21: =SUMPRODUCT((NOT(ISBLANK(AK$3:AK$12))*(AK$3:AK$12=$BD$3:$BD$12))+ISBLANK(AK$3:AK$12)) -> 0 | AL21: =SUMPRODUCT((NOT(ISBLANK(AL$3:AL$12))*(AL$3:AL$12=$BE$3:$BE$12))+ISBLANK(AL$3:AL$12)) -> 0 | AN21: =SUMPRODUCT((NOT(ISBLANK(AN$3:AN$12))*(AN$3:AN$12=$BF$3:$BF$12))+ISBLANK(AN$3:AN$12)) -> 0 | AO21: =SUMPRODUCT((NOT(ISBLANK(AO$3:AO$12))*(AO$3:AO$12=$BG$3:$BG$12))+ISBLANK(AO$3:AO$12)) -> 0 | AP21: =SUMPRODUCT((NOT(ISBLANK(AP$3:AP$12))*(AP$3:AP$12=$BH$3:$BH$12))+ISBLANK(AP$3:AP$12)) -> 0 | AQ21: =SUMPRODUCT((NOT(ISBLANK(AQ$3:AQ$12))*(AQ$3:AQ$12=$BI$3:$BI$12))+ISBLANK(AQ$3:AQ$12)) -> 0

Sheet Merged Runs
A1: Merge criteria: | B1: memelingo-1/simple_mlp-lpnmr-ht | I1: memelingo-1/simple_mlp-lpnmr-htc | P1: memelingo-1/simple_mlp-lpnmr-htcdl | W1: memelingo-1/simple_mlp-tplp-ht | AD1: memelingo-1/simple_mlp-tplp-htc | AK1: memelingo-1/simple_mlp-tplp-htcdl | AR1: min | AX1: median | BD1: max
A2: median | B2: time | C2: stime | D2: status | E2: rules | F2: ctime | G2: fmtime | H2: memout | I2: time | J2: stime | K2: status | L2: rules | M2: ctime | N2: fmtime | O2: memout | P2: time | Q2: stime | R2: status | S2: rules | T2: ctime | U2: fmtime | V2: memout | W2: time | X2: stime | Y2: status | Z2: rules | AA2: ctime | AB2: fmtime | AC2: memout | AD2: time | AE2: stime | AF2: status | AG2: rules | AH2: ctime | AI2: fmtime | AJ2: memout | AK2: time | AL2: stime | AM2: status | AN2: rules | AO2: ctime | AP2: fmtime | AQ2: memout | AR2: time | AS2: stime | AT2: rules | AU2: ctime | AV2: fmtime | AW2: memout | AX2: time | AY2: stime | AZ2: rules | BA2: ctime | BB2: fmtime | BC2: memout | BD2: time | BE2: stime | BF2: rules | BG2: ctime | BH2: fmtime | BI2: memout
A3: instances/size-1 | B3: {=_xlfn.SWITCH($A$2,"average", AVERAGE(Instances!B3:Instances!B3),"median", MEDIAN(Instances!B3:Instances!B3),"min", MIN(Instances!B3:Instances!B3),"max", MAX(Instances!B3:Instances!B3),"diff", MAX(Instances!B3:Instances!B3)-MIN(Instances!B3:Instances!B3))} -> 0 | C3: {=_xlfn.SWITCH($A$2,"average", AVERAGE(Instances!C3:Instances!C3),"median", MEDIAN(Instances!C3:Instances!C3),"min", MIN(Instances!C3:Instances!C3),"max", MAX(Instances!C3:Instances!C3),"diff", MAX(Instances!C3:Instances!C3)-MIN(Instances!C3:Instances!C3))} -> 0 | E3: {=_xlfn.SWITCH($A$2,"average", AVERAGE(Instances!E3:Instances!E3),"median", MEDIAN(Instances!E3:Instances!E3),"min", MIN(Instances!E3:Instances!E3),"max", MAX(Instances!E3:Instances!E3),"diff", MAX(Instances!E3:Instances!E3)-MIN(Instances!E3:Instances!E3))} -> 0 | F3: {=_xlfn.SWITCH($A$2,"average", AVERAGE(Instances!F3:Instances!F3),"median", MEDIAN(Instances!F3:Instances!F3),"min", MIN(Instances!F3:Instances!F3),"max", MAX(Instances!F3:Instances!F3),"diff", MAX(Instances!F3:Instances!F3)-MIN(Instances!F3:Instances!F3))} -> 0 | G3: {=_xlfn.SWITCH($A$2,"average", AVERAGE(Instances!G3:Instances!G3),"median", MEDIAN(Instances!G3:Instances!G3),"min", MIN(Instances!G3:Instances!G3),"max", MAX(Instances!G3:Instances!G3),"diff", MAX(Instances!G3:Instances!G3)-MIN(Instances!G3:Instances!G3))} -> 0 | H3: {=_xlfn.SWITCH($A$2,"average", AVERAGE(Instances!H3:Instances!H3),"median", MEDIAN(Instances!H3:Instances!H3),"min", MIN(Instances!H3:Instances!H3),"max", MAX(Instances!H3:Instances!H3),"diff", MAX(Instances!H3:Instances!H3)-MIN(Instances!H3:Instances!H3))} -> 0 | I3: {=_xlfn.SWITCH($A$2,"average", AVERAGE(Instances!I3:Instances!I3),"median", MEDIAN(Instances!I3:Instances!I3),"min", MIN(Instances!I3:Instances!I3),"max", MAX(Instances!I3:Instances!I3),"diff", MAX(Instances!I3:Instances!I3)-MIN(Instances!I3:Instances!I3))} -> 0 | J3: {=_xlfn.SWITCH($A$2,"average", AVERAGE(Instances!J3:Instances!J3),"median", MEDIAN(Instances!J3:Instances!J3),"min", MIN(Instances!J3:Instances!J3),"max", MAX(Instances!J3:Instances!J3),"diff", MAX(Instances!J3:Instances!J3)-MIN(Instances!J3:Instances!J3))} -> 0 | L3: {=_xlfn.SWITCH($A$2,"average", AVERAGE(Instances!L3:Instances!L3),"median", MEDIAN(Instances!L3:Instances!L3),"min", MIN(Instances!L3:Instances!L3),"max", MAX(Instances!L3:Instances!L3),"diff", MAX(Instances!L3:Instances!L3)-MIN(Instances!L3:Instances!L3))} -> 0 | M3: {=_xlfn.SWITCH($A$2,"average", AVERAGE(Instances!M3:Instances!M3),"median", MEDIAN(Instances!M3:Instances!M3),"min", MIN(Instances!M3:Instances!M3),"max", MAX(Instances!M3:Instances!M3),"diff", MAX(Instances!M3:Instances!M3)-MIN(Instances!M3:Instances!M3))} -> 0 | N3: {=_xlfn.SWITCH($A$2,"average", AVERAGE(Instances!N3:Instances!N3),"median", MEDIAN(Instances!N3:Instances!N3),"min", MIN(Instances!N3:Instances!N3),"max", MAX(Instances!N3:Instances!N3),"diff", MAX(Instances!N3:Instances!N3)-MIN(Instances!N3:Instances!N3))} -> 0 | O3: {=_xlfn.SWITCH($A$2,"average", AVERAGE(Instances!O3:Instances!O3),"median", MEDIAN(Instances!O3:Instances!O3),"min", MIN(Instances!O3:Instances!O3),"max", MAX(Instances!O3:Instances!O3),"diff", MAX(Instances!O3:Instances!O3)-MIN(Instances!O3:Instances!O3))} -> 0 | P3: {=_xlfn.SWITCH($A$2,"average", AVERAGE(Instances!P3:Instances!P3),"median", MEDIAN(Instances!P3:Instances!P3),"min", MIN(Instances!P3:Instances!P3),"max", MAX(Instances!P3:Instances!P3),"diff", MAX(Instances!P3:Instances!P3)-MIN(Instances!P3:Instances!P3))} -> 0 | Q3: {=_xlfn.SWITCH($A$2,"average", AVERAGE(Instances!Q3:Instances!Q3),"median", MEDIAN(Instances!Q3:Instances!Q3),"min", MIN(Instances!Q3:Instances!Q3),"max", MAX(Instances!Q3:Instances!Q3),"diff", MAX(Instances!Q3:Instances!Q3)-MIN(Instances!Q3:Instances!Q3))} -> 0 | S3: {=_xlfn.SWITCH($A$2,"average", AVERAGE(Instances!S3:Instances!S3),"median", MEDIAN(Instances!S3:Instances!S3),"min", MIN(Instances!S3:Instances!S3),"max", MAX(Instances!S3:Instances!S3),"diff", MAX(Instances!S3:Instances!S3)-MIN(Instances!S3:Instances!S3))} -> 0 | T3: {=_xlfn.SWITCH($A$2,"average", AVERAGE(Instances!T3:Instances!T3),"median", MEDIAN(Instances!T3:Instances!T3),"min", MIN(Instances!T3:Instances!T3),"max", MAX(Instances!T3:Instances!T3),"diff", MAX(Instances!T3:Instances!T3)-MIN(Instances!T3:Instances!T3))} -> 0 | U3: {=_xlfn.SWITCH($A$2,"average", AVERAGE(Instances!U3:Instances!U3),"median", MEDIAN(Instances!U3:Instances!U3),"min", MIN(Instances!U3:Instances!U3),"max", MAX(Instances!U3:Instances!U3),"diff", MAX(Instances!U3:Instances!U3)-MIN(Instances!U3:Instances!U3))} -> 0 | V3: {=_xlfn.SWITCH($A$2,"average", AVERAGE(Instances!V3:Instances!V3),"median", MEDIAN(Instances!V3:Instances!V3),"min", MIN(Instances!V3:Instances!V3),"max", MAX(Instances!V3:Instances!V3),"diff", MAX(Instances!V3:Instances!V3)-MIN(Instances!V3:Instances!V3))} -> 0 | W3: {=_xlfn.SWITCH($A$2,"average", AVERAGE(Instances!W3:Instances!W3),"median", MEDIAN(Instances!W3:Instances!W3),"min", MIN(Instances!W3:Instances!W3),"max", MAX(Instances!W3:Instances!W3),"diff", MAX(Instances!W3:Instances!W3)-MIN(Instances!W3:Instances!W3))} -> 0 | X3: {=_xlfn.SWITCH($A$2,"average", AVERAGE(Instances!X3:Instances!X3),"median", MEDIAN(Instances!X3:Instances!X3),"min", MIN(Instances!X3:Instances!X3),"max", MAX(Instances!X3:Instances!X3),"diff", MAX(Instances!X3:Instances!X3)-MIN(Instances!X3:Instances!X3))} -> 0 | Z3: {=_xlfn.SWITCH($A$2,"average", AVERAGE(Instances!Z3:Instances!Z3),"median", MEDIAN(Instances!Z3:Instances!Z3),"min", MIN(Instances!Z3:Instances!Z3),"max", MAX(Instances!Z3:Instances!Z3),"diff", MAX(Instances!Z3:Instances!Z3)-MIN(Instances!Z3:Instances!Z3))} -> 0 | AA3: {=_xlfn.SWITCH($A$2,"average", AVERAGE(Instances!AA3:Instances!AA3),"median", MEDIAN(Instances!AA3:Instances!AA3),"min", MIN(Instances!AA3:Instances!AA3),"max", MAX(Instances!AA3:Instances!AA3),"diff", MAX(Instances!AA3:Instances!AA3)-MIN(Instances!AA3:Instances!AA3))} -> 0 | AB3: {=_xlfn.SWITCH($A$2,"average", AVERAGE(Instances!AB3:Instances!AB3),"median", MEDIAN(Instances!AB3:Instances!AB3),"min", MIN(Instances!AB3:Instances!AB3),"max", MAX(Instances!AB3:Instances!AB3),"diff", MAX(Instances!AB3:Instances!AB3)-MIN(Instances!AB3:Instances!AB3))} -> 0 | AC3: {=_xlfn.SWITCH($A$2,"average", AVERAGE(Instances!AC3:Instances!AC3),"median", MEDIAN(Instances!AC3:Instances!AC3),"min", MIN(Instances!AC3:Instances!AC3),"max", MAX(Instances!AC3:Instances!AC3),"diff", MAX(Instances!AC3:Instances!AC3)-MIN(Instances!AC3:Instances!AC3))} -> 0 | AD3: {=_xlfn.SWITCH($A$2,"average", AVERAGE(Instances!AD3:Instances!AD3),"median", MEDIAN(Instances!AD3:Instances!AD3),"min", MIN(Instances!AD3:Instances!AD3),"max", MAX(Instances!AD3:Instances!AD3),"diff", MAX(Instances!AD3:Instances!AD3)-MIN(Instances!AD3:Instances!AD3))} -> 0 | AE3: {=_xlfn.SWITCH($A$2,"average", AVERAGE(Instances!AE3:Instances!AE3),"median", MEDIAN(Instances!AE3:Instances!AE3),"min", MIN(Instances!AE3:Instances!AE3),"max", MAX(Instances!AE3:Instances!AE3),"diff", MAX(Instances!AE3:Instances!AE3)-MIN(Instances!AE3:Instances!AE3))} -> 0 | AG3: {=_xlfn.SWITCH($A$2,"average", AVERAGE(Instances!AG3:Instances!AG3),"median", MEDIAN(Instances!AG3:Instances!AG3),"min", MIN(Instances!AG3:Instances!AG3),"max", MAX(Instances!AG3:Instances!AG3),"diff", MAX(Instances!AG3:Instances!AG3)-MIN(Instances!AG3:Instances!AG3))} -> 0 | AH3: {=_xlfn.SWITCH($A$2,"average", AVERAGE(Instances!AH3:Instances!AH3),"median", MEDIAN(Instances!AH3:Instances!AH3),"min", MIN(Instances!AH3:Instances!AH3),"max", MAX(Instances!AH3:Instances!AH3),"diff", MAX(Instances!AH3:Instances!AH3)-MIN(Instances!AH3:Instances!AH3))} -> 0 | AI3: {=_xlfn.SWITCH($A$2,"average", AVERAGE(Instances!AI3:Instances!AI3),"median", MEDIAN(Instances!AI3:Instances!AI3),"min", MIN(Instances!AI3:Instances!AI3),"max", MAX(Instances!AI3:Instances!AI3),"diff", MAX(Instances!AI3:Instances!AI3)-MIN(Instances!AI3:Instances!AI3))} -> 0 | AJ3: {=_xlfn.SWITCH($A$2,"average", AVERAGE(Instances!AJ3:Instances!AJ3),"median", MEDIAN(Instances!AJ3:Instances!AJ3),"min", MIN(Instances!AJ3:Instances!AJ3),"max", MAX(Instances!AJ3:Instances!AJ3),"diff", MAX(Instances!AJ3:Instances!AJ3)-MIN(Instances!AJ3:Instances!AJ3))} -> 0 | AK3: {=_xlfn.SWITCH($A$2,"average", AVERAGE(Instances!AK3:Instances!AK3),"median", MEDIAN(Instances!AK3:Instances!AK3),"min", MIN(Instances!AK3:Instances!AK3),"max", MAX(Instances!AK3:Instances!AK3),"diff", MAX(Instances!AK3:Instances!AK3)-MIN(Instances!AK3:Instances!AK3))} -> 0 | AL3: {=_xlfn.SWITCH($A$2,"average", AVERAGE(Instances!AL3:Instances!AL3),"median", MEDIAN(Instances!AL3:Instances!AL3),"min", MIN(Instances!AL3:Instances!AL3),"max", MAX(Instances!AL3:Instances!AL3),"diff", MAX(Instances!AL3:Instances!AL3)-MIN(Instances!AL3:Instances!AL3))} -> 0 | AN3: {=_xlfn.SWITCH($A$2,"average", AVERAGE(Instances!AN3:Instances!AN3),"median", MEDIAN(Instances!AN3:Instances!AN3),"min", MIN(Instances!AN3:Instances!AN3),"max", MAX(Instances!AN3:Instances!AN3),"diff", MAX(Instances!AN3:Instances!AN3)-MIN(Instances!AN3:Instances!AN3))} -> 0 | AO3: {=_xlfn.SWITCH($A$2,"average", AVERAGE(Instances!AO3:Instances!AO3),"median", MEDIAN(Instances!AO3:Instances!AO3),"min", MIN(Instances!AO3:Instances!AO3),"max", MAX(Instances!AO3:Instances!AO3),"diff", MAX(Instances!AO3:Instances!AO3)-MIN(Instances!AO3:Instances!AO3))} -> 0 | AP3: {=_xlfn.SWITCH($A$2,"average", AVERAGE(Instances!AP3:Instances!AP3),"median", MEDIAN(Instances!AP3:Instances!AP3),"min", MIN(Instances!AP3:Instances!AP3),"max", MAX(Instances!AP3:Instances!AP3),"diff", MAX(Instances!AP3:Instances!AP3)-MIN(Instances!AP3:Instances!AP3))} -> 0 | AQ3: {=_xlfn.SWITCH($A$2,"average", AVERAGE(Instances!AQ3:Instances!AQ3),"median", MEDIAN(Instances!AQ3:Instances!AQ3),"min", MIN(Instances!AQ3:Instances!AQ3),"max", MAX(Instances!AQ3:Instances!AQ3),"diff", MAX(Instances!AQ3:Instances!AQ3)-MIN(Instances!AQ3:Instances!AQ3))} -> 0 | AR3: =MIN($B3,$I3,$P3,$W3,$AD3,$AK3) -> 0 | AS3: =MIN($C3,$J3,$Q3,$X3,$AE3,$AL3) -> 0 | AT3: =MIN($E3,$L3,$S3,$Z3,$AG3,$AN3) -> 0 | AU3: =MIN($F3,$M3,$T3,$AA3,$AH3,$AO3) -> 0 | AV3: =MIN($G3,$N3,$U3,$AB3,$AI3,$AP3) -> 0 | AW3: =MIN($H3,$O3,$V3,$AC3,$AJ3,$AQ3) -> 0 | AX3: =MEDIAN($B3,$I3,$P3,$W3,$AD3,$AK3) -> 0 | AY3: =MEDIAN($C3,$J3,$Q3,$X3,$AE3,$AL3) -> 0 | AZ3: =MEDIAN($E3,$L3,$S3,$Z3,$AG3,$AN3) -> 0 | BA3: =MEDIAN($F3,$M3,$T3,$AA3,$AH3,$AO3) -> 0 | BB3: =MEDIAN($G3,$N3,$U3,$AB3,$AI3,$AP3) -> 0 | BC3: =MEDIAN($H3,$O3,$V3,$AC3,$AJ3,$AQ3) -> 0 | BD3: =MAX($B3,$I3,$P3,$W3,$AD3,$AK3) -> 0 | BE3: =MAX($C3,$J3,$Q3,$X3,$AE3,$AL3) -> 0 | BF3: =MAX($E3,$L3,$S3,$Z3,$AG3,$AN3) -> 0 | BG3: =MAX($F3,$M3,$T3,$AA3,$AH3,$AO3) -> 0 | BH3: =MAX($G3,$N3,$U3,$AB3,$AI3,$AP3) -> 0 | BI3: =MAX($H3,$O3,$V3,$AC3,$AJ3,$AQ3) -> 0
A4: instances/size-10 | B4: {=_xlfn.SWITCH($A$2,"average", AVERAGE(Instances!B4:Instances!B4),"median", MEDIAN(Instances!B4:Instances!B4),"min", MIN(Instances!B4:Instances!B4),"max", MAX(Instances!B4:Instances!B4),"diff", MAX(Instances!B4:Instances!B4)-MIN(Instances!B4:Instances!B4))} -> 0 | H4: {=_xlfn.SWITCH($A$2,"average", AVERAGE(Instances!H4:Instances!H4),"median", MEDIAN(Instances!H4:Instances!H4),"min", MIN(Instances!H4:Instances!H4),"max", MAX(Instances!H4:Instances!H4),"diff", MAX(Instances!H4:Instances!H4)-MIN(Instances!H4:Instances!H4))} -> 0 | I4: {=_xlfn.SWITCH($A$2,"average", AVERAGE(Instances!I4:Instances!I4),"median", MEDIAN(Instances!I4:Instances!I4),"min", MIN(Instances!I4:Instances!I4),"max", MAX(Instances!I4:Instances!I4),"diff", MAX(Instances!I4:Instances!I4)-MIN(Instances!I4:Instances!I4))} -> 0 | O4: {=_xlfn.SWITCH($A$2,"average", AVERAGE(Instances!O4:Instances!O4),"median", MEDIAN(Instances!O4:Instances!O4),"min", MIN(Instances!O4:Instances!O4),"max", MAX(Instances!O4:Instances!O4),"diff", MAX(Instances!O4:Instances!O4)-MIN(Instances!O4:Instances!O4))} -> 0 | P4: {=_xlfn.SWITCH($A$2,"average", AVERAGE(Instances!P4:Instances!P4),"median", MEDIAN(Instances!P4:Instances!P4),"min", MIN(Instances!P4:Instances!P4),"max", MAX(Instances!P4:Instances!P4),"diff", MAX(Instances!P4:Instances!P4)-MIN(Instances!P4:Instances!P4))} -> 0 | V4: {=_xlfn.SWITCH($A$2,"average", AVERAGE(Instances!V4:Instances!V4),"median", MEDIAN(Instances!V4:Instances!V4),"min", MIN(Instances!V4:Instances!V4),"max", MAX(Instances!V4:Instances!V4),"diff", MAX(Instances!V4:Instances!V4)-MIN(Instances!V4:Instances!V4))} -> 0 | W4: {=_xlfn.SWITCH($A$2,"average", AVERAGE(Instances!W4:Instances!W4),"median", MEDIAN(Instances!W4:Instances!W4),"min", MIN(Instances!W4:Instances!W4),"max", MAX(Instances!W4:Instances!W4),"diff", MAX(Instances!W4:Instances!W4)-MIN(Instances!W4:Instances!W4))} -> 0 | AC4: {=_xlfn.SWITCH($A$2,"average", AVERAGE(Instances!AC4:Instances!AC4),"median", MEDIAN(Instances!AC4:Instances!AC4),"min", MIN(Instances!AC4:Instances!AC4),"max", MAX(Instances!AC4:Instances!AC4),"diff", MAX(Instances!AC4:Instances!AC4)-MIN(Instances!AC4:Instances!AC4))} -> 0 | AD4: {=_xlfn.SWITCH($A$2,"average", AVERAGE(Instances!AD4:Instances!AD4),"median", MEDIAN(Instances!AD4:Instances!AD4),"min", MIN(Instances!AD4:Instances!AD4),"max", MAX(Instances!AD4:Instances!AD4),"diff", MAX(Instances!AD4:Instances!AD4)-MIN(Instances!AD4:Instances!AD4))} -> 0 | AJ4: {=_xlfn.SWITCH($A$2,"average", AVERAGE(Instances!AJ4:Instances!AJ4),"median", MEDIAN(Instances!AJ4:Instances!AJ4),"min", MIN(Instances!AJ4:Instances!AJ4),"max", MAX(Instances!AJ4:Instances!AJ4),"diff", MAX(Instances!AJ4:Instances!AJ4)-MIN(Instances!AJ4:Instances!AJ4))} -> 0 | AK4: {=_xlfn.SWITCH($A$2,"average", AVERAGE(Instances!AK4:Instances!AK4),"median", MEDIAN(Instances!AK4:Instances!AK4),"min", MIN(Instances!AK4:Instances!AK4),"max", MAX(Instances!AK4:Instances!AK4),"diff", MAX(Instances!AK4:Instances!AK4)-MIN(Instances!AK4:Instances!AK4))} -> 0 | AQ4: {=_xlfn.SWITCH($A$2,"average", AVERAGE(Instances!AQ4:Instances!AQ4),"median", MEDIAN(Instances!AQ4:Instances!AQ4),"min", MIN(Instances!AQ4:Instances!AQ4),"max", MAX(Instances!AQ4:Instances!AQ4),"diff", MAX(Instances!AQ4:Instances!AQ4)-MIN(Instances!AQ4:Instances!AQ4))} -> 0 | AR4: =MIN($B4,$I4,$P4,$W4,$AD4,$AK4) -> 0 | AW4: =MIN($H4,$O4,$V4,$AC4,$AJ4,$AQ4) -> 0 | AX4: =MEDIAN($B4,$I4,$P4,$W4,$AD4,$AK4) -> 0 | BC4: =MEDIAN($H4,$O4,$V4,$AC4,$AJ4,$AQ4) -> 0 | BD4: =MAX($B4,$I4,$P4,$W4,$AD4,$AK4) -> 0 | BI4: =MAX($H4,$O4,$V4,$AC4,$AJ4,$AQ4) -> 0
A5: instances/size-2 | B5: {=_xlfn.SWITCH($A$2,"average", AVERAGE(Instances!B5:Instances!B5),"median", MEDIAN(Instances!B5:Instances!B5),"min", MIN(Instances!B5:Instances!B5),"max", MAX(Instances!B5:Instances!B5),"diff", MAX(Instances!B5:Instances!B5)-MIN(Instances!B5:Instances!B5))} -> 0 | H5: {=_xlfn.SWITCH($A$2,"average", AVERAGE(Instances!H5:Instances!H5),"median", MEDIAN(Instances!H5:Instances!H5),"min", MIN(Instances!H5:Instances!H5),"max", MAX(Instances!H5:Instances!H5),"diff", MAX(Instances!H5:Instances!H5)-MIN(Instances!H5:Instances!H5))} -> 0 | I5: {=_xlfn.SWITCH($A$2,"average", AVERAGE(Instances!I5:Instances!I5),"median", MEDIAN(Instances!I5:Instances!I5),"min", MIN(Instances!I5:Instances!I5),"max", MAX(Instances!I5:Instances!I5),"diff", MAX(Instances!I5:Instances!I5)-MIN(Instances!I5:Instances!I5))} -> 0 | O5: {=_xlfn.SWITCH($A$2,"average", AVERAGE(Instances!O5:Instances!O5),"median", MEDIAN(Instances!O5:Instances!O5),"min", MIN(Instances!O5:Instances!O5),"max", MAX(Instances!O5:Instances!O5),"diff", MAX(Instances!O5:Instances!O5)-MIN(Instances!O5:Instances!O5))} -> 0 | P5: {=_xlfn.SWITCH($A$2,"average", AVERAGE(Instances!P5:Instances!P5),"median", MEDIAN(Instances!P5:Instances!P5),"min", MIN(Instances!P5:Instances!P5),"max", MAX(Instances!P5:Instances!P5),"diff", MAX(Instances!P5:Instances!P5)-MIN(Instances!P5:Instances!P5))} -> 0 | V5: {=_xlfn.SWITCH($A$2,"average", AVERAGE(Instances!V5:Instances!V5),"median", MEDIAN(Instances!V5:Instances!V5),"min", MIN(Instances!V5:Instances!V5),"max", MAX(Instances!V5:Instances!V5),"diff", MAX(Instances!V5:Instances!V5)-MIN(Instances!V5:Instances!V5))} -> 0 | W5: {=_xlfn.SWITCH($A$2,"average", AVERAGE(Instances!W5:Instances!W5),"median", MEDIAN(Instances!W5:Instances!W5),"min", MIN(Instances!W5:Instances!W5),"max", MAX(Instances!W5:Instances!W5),"diff", MAX(Instances!W5:Instances!W5)-MIN(Instances!W5:Instances!W5))} -> 0 | AC5: {=_xlfn.SWITCH($A$2,"average", AVERAGE(Instances!AC5:Instances!AC5),"median", MEDIAN(Instances!AC5:Instances!AC5),"min", MIN(Instances!AC5:Instances!AC5),"max", MAX(Instances!AC5:Instances!AC5),"diff", MAX(Instances!AC5:Instances!AC5)-MIN(Instances!AC5:Instances!AC5))} -> 0 | AD5: {=_xlfn.SWITCH($A$2,"average", AVERAGE(Instances!AD5:Instances!AD5),"median", MEDIAN(Instances!AD5:Instances!AD5),"min", MIN(Instances!AD5:Instances!AD5),"max", MAX(Instances!AD5:Instances!AD5),"diff", MAX(Instances!AD5:Instances!AD5)-MIN(Instances!AD5:Instances!AD5))} -> 0 | AJ5: {=_xlfn.SWITCH($A$2,"average", AVERAGE(Instances!AJ5:Instances!AJ5),"median", MEDIAN(Instances!AJ5:Instances!AJ5),"min", MIN(Instances!AJ5:Instances!AJ5),"max", MAX(Instances!AJ5:Instances!AJ5),"diff", MAX(Instances!AJ5:Instances!AJ5)-MIN(Instances!AJ5:Instances!AJ5))} -> 0 | AK5: {=_xlfn.SWITCH($A$2,"average", AVERAGE(Instances!AK5:Instances!AK5),"median", MEDIAN(Instances!AK5:Instances!AK5),"min", MIN(Instances!AK5:Instances!AK5),"max", MAX(Instances!AK5:Instances!AK5),"diff", MAX(Instances!AK5:Instances!AK5)-MIN(Instances!AK5:Instances!AK5))} -> 0 | AQ5: {=_xlfn.SWITCH($A$2,"average", AVERAGE(Instances!AQ5:Instances!AQ5),"median", MEDIAN(Instances!AQ5:Instances!AQ5),"min", MIN(Instances!AQ5:Instances!AQ5),"max", MAX(Instances!AQ5:Instances!AQ5),"diff", MAX(Instances!AQ5:Instances!AQ5)-MIN(Instances!AQ5:Instances!AQ5))} -> 0 | AR5: =MIN($B5,$I5,$P5,$W5,$AD5,$AK5) -> 0 | AW5: =MIN($H5,$O5,$V5,$AC5,$AJ5,$AQ5) -> 0 | AX5: =MEDIAN($B5,$I5,$P5,$W5,$AD5,$AK5) -> 0 | BC5: =MEDIAN($H5,$O5,$V5,$AC5,$AJ5,$AQ5) -> 0 | BD5: =MAX($B5,$I5,$P5,$W5,$AD5,$AK5) -> 0 | BI5: =MAX($H5,$O5,$V5,$AC5,$AJ5,$AQ5) -> 0
A6: instances/size-3 | B6: {=_xlfn.SWITCH($A$2,"average", AVERAGE(Instances!B6:Instances!B6),"median", MEDIAN(Instances!B6:Instances!B6),"min", MIN(Instances!B6:Instances!B6),"max", MAX(Instances!B6:Instances!B6),"diff", MAX(Instances!B6:Instances!B6)-MIN(Instances!B6:Instances!B6))} -> 0 | H6: {=_xlfn.SWITCH($A$2,"average", AVERAGE(Instances!H6:Instances!H6),"median", MEDIAN(Instances!H6:Instances!H6),"min", MIN(Instances!H6:Instances!H6),"max", MAX(Instances!H6:Instances!H6),"diff", MAX(Instances!H6:Instances!H6)-MIN(Instances!H6:Instances!H6))} -> 0 | I6: {=_xlfn.SWITCH($A$2,"average", AVERAGE(Instances!I6:Instances!I6),"median", MEDIAN(Instances!I6:Instances!I6),"min", MIN(Instances!I6:Instances!I6),"max", MAX(Instances!I6:Instances!I6),"diff", MAX(Instances!I6:Instances!I6)-MIN(Instances!I6:Instances!I6))} -> 0 | O6: {=_xlfn.SWITCH($A$2,"average", AVERAGE(Instances!O6:Instances!O6),"median", MEDIAN(Instances!O6:Instances!O6),"min", MIN(Instances!O6:Instances!O6),"max", MAX(Instances!O6:Instances!O6),"diff", MAX(Instances!O6:Instances!O6)-MIN(Instances!O6:Instances!O6))} -> 0 | P6: {=_xlfn.SWITCH($A$2,"average", AVERAGE(Instances!P6:Instances!P6),"median", MEDIAN(Instances!P6:Instances!P6),"min", MIN(Instances!P6:Instances!P6),"max", MAX(Instances!P6:Instances!P6),"diff", MAX(Instances!P6:Instances!P6)-MIN(Instances!P6:Instances!P6))} -> 0 | V6: {=_xlfn.SWITCH($A$2,"average", AVERAGE(Instances!V6:Instances!V6),"median", MEDIAN(Instances!V6:Instances!V6),"min", MIN(Instances!V6:Instances!V6),"max", MAX(Instances!V6:Instances!V6),"diff", MAX(Instances!V6:Instances!V6)-MIN(Instances!V6:Instances!V6))} -> 0 | W6: {=_xlfn.SWITCH($A$2,"average", AVERAGE(Instances!W6:Instances!W6),"median", MEDIAN(Instances!W6:Instances!W6),"min", MIN(Instances!W6:Instances!W6),"max", MAX(Instances!W6:Instances!W6),"diff", MAX(Instances!W6:Instances!W6)-MIN(Instances!W6:Instances!W6))} -> 0 | AC6: {=_xlfn.SWITCH($A$2,"average", AVERAGE(Instances!AC6:Instances!AC6),"median", MEDIAN(Instances!AC6:Instances!AC6),"min", MIN(Instances!AC6:Instances!AC6),"max", MAX(Instances!AC6:Instances!AC6),"diff", MAX(Instances!AC6:Instances!AC6)-MIN(Instances!AC6:Instances!AC6))} -> 0 | AD6: {=_xlfn.SWITCH($A$2,"average", AVERAGE(Instances!AD6:Instances!AD6),"median", MEDIAN(Instances!AD6:Instances!AD6),"min", MIN(Instances!AD6:Instances!AD6),"max", MAX(Instances!AD6:Instances!AD6),"diff", MAX(Instances!AD6:Instances!AD6)-MIN(Instances!AD6:Instances!AD6))} -> 0 | AJ6: {=_xlfn.SWITCH($A$2,"average", AVERAGE(Instances!AJ6:Instances!AJ6),"median", MEDIAN(Instances!AJ6:Instances!AJ6),"min", MIN(Instances!AJ6:Instances!AJ6),"max", MAX(Instances!AJ6:Instances!AJ6),"diff", MAX(Instances!AJ6:Instances!AJ6)-MIN(Instances!AJ6:Instances!AJ6))} -> 0 | AK6: {=_xlfn.SWITCH($A$2,"average", AVERAGE(Instances!AK6:Instances!AK6),"median", MEDIAN(Instances!AK6:Instances!AK6),"min", MIN(Instances!AK6:Instances!AK6),"max", MAX(Instances!AK6:Instances!AK6),"diff", MAX(Instances!AK6:Instances!AK6)-MIN(Instances!AK6:Instances!AK6))} -> 0 | AQ6: {=_xlfn.SWITCH($A$2,"average", AVERAGE(Instances!AQ6:Instances!AQ6),"median", MEDIAN(Instances!AQ6:Instances!AQ6),"min", MIN(Instances!AQ6:Instances!AQ6),"max", MAX(Instances!AQ6:Instances!AQ6),"diff", MAX(Instances!AQ6:Instances!AQ6)-MIN(Instances!AQ6:Instances!AQ6))} -> 0 | AR6: =MIN($B6,$I6,$P6,$W6,$AD6,$AK6) -> 0 | AW6: =MIN($H6,$O6,$V6,$AC6,$AJ6,$AQ6) -> 0 | AX6: =MEDIAN($B6,$I6,$P6,$W6,$AD6,$AK6) -> 0 | BC6: =MEDIAN($H6,$O6,$V6,$AC6,$AJ6,$AQ6) -> 0 | BD6: =MAX($B6,$I6,$P6,$W6,$AD6,$AK6) -> 0 | BI6: =MAX($H6,$O6,$V6,$AC6,$AJ6,$AQ6) -> 0
A7: instances/size-4 | B7: {=_xlfn.SWITCH($A$2,"average", AVERAGE(Instances!B7:Instances!B7),"median", MEDIAN(Instances!B7:Instances!B7),"min", MIN(Instances!B7:Instances!B7),"max", MAX(Instances!B7:Instances!B7),"diff", MAX(Instances!B7:Instances!B7)-MIN(Instances!B7:Instances!B7))} -> 0 | H7: {=_xlfn.SWITCH($A$2,"average", AVERAGE(Instances!H7:Instances!H7),"median", MEDIAN(Instances!H7:Instances!H7),"min", MIN(Instances!H7:Instances!H7),"max", MAX(Instances!H7:Instances!H7),"diff", MAX(Instances!H7:Instances!H7)-MIN(Instances!H7:Instances!H7))} -> 0 | I7: {=_xlfn.SWITCH($A$2,"average", AVERAGE(Instances!I7:Instances!I7),"median", MEDIAN(Instances!I7:Instances!I7),"min", MIN(Instances!I7:Instances!I7),"max", MAX(Instances!I7:Instances!I7),"diff", MAX(Instances!I7:Instances!I7)-MIN(Instances!I7:Instances!I7))} -> 0 | O7: {=_xlfn.SWITCH($A$2,"average", AVERAGE(Instances!O7:Instances!O7),"median", MEDIAN(Instances!O7:Instances!O7),"min", MIN(Instances!O7:Instances!O7),"max", MAX(Instances!O7:Instances!O7),"diff", MAX(Instances!O7:Instances!O7)-MIN(Instances!O7:Instances!O7))} -> 0 | P7: {=_xlfn.SWITCH($A$2,"average", AVERAGE(Instances!P7:Instances!P7),"median", MEDIAN(Instances!P7:Instances!P7),"min", MIN(Instances!P7:Instances!P7),"max", MAX(Instances!P7:Instances!P7),"diff", MAX(Instances!P7:Instances!P7)-MIN(Instances!P7:Instances!P7))} -> 0 | V7: {=_xlfn.SWITCH($A$2,"average", AVERAGE(Instances!V7:Instances!V7),"median", MEDIAN(Instances!V7:Instances!V7),"min", MIN(Instances!V7:Instances!V7),"max", MAX(Instances!V7:Instances!V7),"diff", MAX(Instances!V7:Instances!V7)-MIN(Instances!V7:Instances!V7))} -> 0 | W7: {=_xlfn.SWITCH($A$2,"average", AVERAGE(Instances!W7:Instances!W7),"median", MEDIAN(Instances!W7:Instances!W7),"min", MIN(Instances!W7:Instances!W7),"max", MAX(Instances!W7:Instances!W7),"diff", MAX(Instances!W7:Instances!W7)-MIN(Instances!W7:Instances!W7))} -> 0 | AC7: {=_xlfn.SWITCH($A$2,"average", AVERAGE(Instances!AC7:Instances!AC7),"median", MEDIAN(Instances!AC7:Instances!AC7),"min", MIN(Instances!AC7:Instances!AC7),"max", MAX(Instances!AC7:Instances!AC7),"diff", MAX(Instances!AC7:Instances!AC7)-MIN(Instances!AC7:Instances!AC7))} -> 0 | AD7: {=_xlfn.SWITCH($A$2,"average", AVERAGE(Instances!AD7:Instances!AD7),"median", MEDIAN(Instances!AD7:Instances!AD7),"min", MIN(Instances!AD7:Instances!AD7),"max", MAX(Instances!AD7:Instances!AD7),"diff", MAX(Instances!AD7:Instances!AD7)-MIN(Instances!AD7:Instances!AD7))} -> 0 | AJ7: {=_xlfn.SWITCH($A$2,"average", AVERAGE(Instances!AJ7:Instances!AJ7),"median", MEDIAN(Instances!AJ7:Instances!AJ7),"min", MIN(Instances!AJ7:Instances!AJ7),"max", MAX(Instances!AJ7:Instances!AJ7),"diff", MAX(Instances!AJ7:Instances!AJ7)-MIN(Instances!AJ7:Instances!AJ7))} -> 0 | AK7: {=_xlfn.SWITCH($A$2,"average", AVERAGE(Instances!AK7:Instances!AK7),"median", MEDIAN(Instances!AK7:Instances!AK7),"min", MIN(Instances!AK7:Instances!AK7),"max", MAX(Instances!AK7:Instances!AK7),"diff", MAX(Instances!AK7:Instances!AK7)-MIN(Instances!AK7:Instances!AK7))} -> 0 | AQ7: {=_xlfn.SWITCH($A$2,"average", AVERAGE(Instances!AQ7:Instances!AQ7),"median", MEDIAN(Instances!AQ7:Instances!AQ7),"min", MIN(Instances!AQ7:Instances!AQ7),"max", MAX(Instances!AQ7:Instances!AQ7),"diff", MAX(Instances!AQ7:Instances!AQ7)-MIN(Instances!AQ7:Instances!AQ7))} -> 0 | AR7: =MIN($B7,$I7,$P7,$W7,$AD7,$AK7) -> 0 | AW7: =MIN($H7,$O7,$V7,$AC7,$AJ7,$AQ7) -> 0 | AX7: =MEDIAN($B7,$I7,$P7,$W7,$AD7,$AK7) -> 0 | BC7: =MEDIAN($H7,$O7,$V7,$AC7,$AJ7,$AQ7) -> 0 | BD7: =MAX($B7,$I7,$P7,$W7,$AD7,$AK7) -> 0 | BI7: =MAX($H7,$O7,$V7,$AC7,$AJ7,$AQ7) -> 0
A8: instances/size-5 | B8: {=_xlfn.SWITCH($A$2,"average", AVERAGE(Instances!B8:Instances!B8),"median", MEDIAN(Instances!B8:Instances!B8),"min", MIN(Instances!B8:Instances!B8),"max", MAX(Instances!B8:Instances!B8),"diff", MAX(Instances!B8:Instances!B8)-MIN(Instances!B8:Instances!B8))} -> 0 | H8: {=_xlfn.SWITCH($A$2,"average", AVERAGE(Instances!H8:Instances!H8),"median", MEDIAN(Instances!H8:Instances!H8),"min", MIN(Instances!H8:Instances!H8),"max", MAX(Instances!H8:Instances!H8),"diff", MAX(Instances!H8:Instances!H8)-MIN(Instances!H8:Instances!H8))} -> 0 | I8: {=_xlfn.SWITCH($A$2,"average", AVERAGE(Instances!I8:Instances!I8),"median", MEDIAN(Instances!I8:Instances!I8),"min", MIN(Instances!I8:Instances!I8),"max", MAX(Instances!I8:Instances!I8),"diff", MAX(Instances!I8:Instances!I8)-MIN(Instances!I8:Instances!I8))} -> 0 | O8: {=_xlfn.SWITCH($A$2,"average", AVERAGE(Instances!O8:Instances!O8),"median", MEDIAN(Instances!O8:Instances!O8),"min", MIN(Instances!O8:Instances!O8),"max", MAX(Instances!O8:Instances!O8),"diff", MAX(Instances!O8:Instances!O8)-MIN(Instances!O8:Instances!O8))} -> 0 | P8: {=_xlfn.SWITCH($A$2,"average", AVERAGE(Instances!P8:Instances!P8),"median", MEDIAN(Instances!P8:Instances!P8),"min", MIN(Instances!P8:Instances!P8),"max", MAX(Instances!P8:Instances!P8),"diff", MAX(Instances!P8:Instances!P8)-MIN(Instances!P8:Instances!P8))} -> 0 | V8: {=_xlfn.SWITCH($A$2,"average", AVERAGE(Instances!V8:Instances!V8),"median", MEDIAN(Instances!V8:Instances!V8),"min", MIN(Instances!V8:Instances!V8),"max", MAX(Instances!V8:Instances!V8),"diff", MAX(Instances!V8:Instances!V8)-MIN(Instances!V8:Instances!V8))} -> 0 | W8: {=_xlfn.SWITCH($A$2,"average", AVERAGE(Instances!W8:Instances!W8),"median", MEDIAN(Instances!W8:Instances!W8),"min", MIN(Instances!W8:Instances!W8),"max", MAX(Instances!W8:Instances!W8),"diff", MAX(Instances!W8:Instances!W8)-MIN(Instances!W8:Instances!W8))} -> 0 | AC8: {=_xlfn.SWITCH($A$2,"average", AVERAGE(Instances!AC8:Instances!AC8),"median", MEDIAN(Instances!AC8:Instances!AC8),"min", MIN(Instances!AC8:Instances!AC8),"max", MAX(Instances!AC8:Instances!AC8),"diff", MAX(Instances!AC8:Instances!AC8)-MIN(Instances!AC8:Instances!AC8))} -> 0 | AD8: {=_xlfn.SWITCH($A$2,"average", AVERAGE(Instances!AD8:Instances!AD8),"median", MEDIAN(Instances!AD8:Instances!AD8),"min", MIN(Instances!AD8:Instances!AD8),"max", MAX(Instances!AD8:Instances!AD8),"diff", MAX(Instances!AD8:Instances!AD8)-MIN(Instances!AD8:Instances!AD8))} -> 0 | AJ8: {=_xlfn.SWITCH($A$2,"average", AVERAGE(Instances!AJ8:Instances!AJ8),"median", MEDIAN(Instances!AJ8:Instances!AJ8),"min", MIN(Instances!AJ8:Instances!AJ8),"max", MAX(Instances!AJ8:Instances!AJ8),"diff", MAX(Instances!AJ8:Instances!AJ8)-MIN(Instances!AJ8:Instances!AJ8))} -> 0 | AK8: {=_xlfn.SWITCH($A$2,"average", AVERAGE(Instances!AK8:Instances!AK8),"median", MEDIAN(Instances!AK8:Instances!AK8),"min", MIN(Instances!AK8:Instances!AK8),"max", MAX(Instances!AK8:Instances!AK8),"diff", MAX(Instances!AK8:Instances!AK8)-MIN(Instances!AK8:Instances!AK8))} -> 0 | AQ8: {=_xlfn.SWITCH($A$2,"average", AVERAGE(Instances!AQ8:Instances!AQ8),"median", MEDIAN(Instances!AQ8:Instances!AQ8),"min", MIN(Instances!AQ8:Instances!AQ8),"max", MAX(Instances!AQ8:Instances!AQ8),"diff", MAX(Instances!AQ8:Instances!AQ8)-MIN(Instances!AQ8:Instances!AQ8))} -> 0 | AR8: =MIN($B8,$I8,$P8,$W8,$AD8,$AK8) -> 0 | AW8: =MIN($H8,$O8,$V8,$AC8,$AJ8,$AQ8) -> 0 | AX8: =MEDIAN($B8,$I8,$P8,$W8,$AD8,$AK8) -> 0 | BC8: =MEDIAN($H8,$O8,$V8,$AC8,$AJ8,$AQ8) -> 0 | BD8: =MAX($B8,$I8,$P8,$W8,$AD8,$AK8) -> 0 | BI8: =MAX($H8,$O8,$V8,$AC8,$AJ8,$AQ8) -> 0
A9: instances/size-6 | B9: {=_xlfn.SWITCH($A$2,"average", AVERAGE(Instances!B9:Instances!B9),"median", MEDIAN(Instances!B9:Instances!B9),"min", MIN(Instances!B9:Instances!B9),"max", MAX(Instances!B9:Instances!B9),"diff", MAX(Instances!B9:Instances!B9)-MIN(Instances!B9:Instances!B9))} -> 0 | H9: {=_xlfn.SWITCH($A$2,"average", AVERAGE(Instances!H9:Instances!H9),"median", MEDIAN(Instances!H9:Instances!H9),"min", MIN(Instances!H9:Instances!H9),"max", MAX(Instances!H9:Instances!H9),"diff", MAX(Instances!H9:Instances!H9)-MIN(Instances!H9:Instances!H9))} -> 0 | I9: {=_xlfn.SWITCH($A$2,"average", AVERAGE(Instances!I9:Instances!I9),"median", MEDIAN(Instances!I9:Instances!I9),"min", MIN(Instances!I9:Instances!I9),"max", MAX(Instances!I9:Instances!I9),"diff", MAX(Instances!I9:Instances!I9)-MIN(Instances!I9:Instances!I9))} -> 0 | O9: {=_xlfn.SWITCH($A$2,"average", AVERAGE(Instances!O9:Instances!O9),"median", MEDIAN(Instances!O9:Instances!O9),"min", MIN(Instances!O9:Instances!O9),"max", MAX(Instances!O9:Instances!O9),"diff", MAX(Instances!O9:Instances!O9)-MIN(Instances!O9:Instances!O9))} -> 0 | P9: {=_xlfn.SWITCH($A$2,"average", AVERAGE(Instances!P9:Instances!P9),"median", MEDIAN(Instances!P9:Instances!P9),"min", MIN(Instances!P9:Instances!P9),"max", MAX(Instances!P9:Instances!P9),"diff", MAX(Instances!P9:Instances!P9)-MIN(Instances!P9:Instances!P9))} -> 0 | V9: {=_xlfn.SWITCH($A$2,"average", AVERAGE(Instances!V9:Instances!V9),"median", MEDIAN(Instances!V9:Instances!V9),"min", MIN(Instances!V9:Instances!V9),"max", MAX(Instances!V9:Instances!V9),"diff", MAX(Instances!V9:Instances!V9)-MIN(Instances!V9:Instances!V9))} -> 0 | W9: {=_xlfn.SWITCH($A$2,"average", AVERAGE(Instances!W9:Instances!W9),"median", MEDIAN(Instances!W9:Instances!W9),"min", MIN(Instances!W9:Instances!W9),"max", MAX(Instances!W9:Instances!W9),"diff", MAX(Instances!W9:Instances!W9)-MIN(Instances!W9:Instances!W9))} -> 0 | AC9: {=_xlfn.SWITCH($A$2,"average", AVERAGE(Instances!AC9:Instances!AC9),"median", MEDIAN(Instances!AC9:Instances!AC9),"min", MIN(Instances!AC9:Instances!AC9),"max", MAX(Instances!AC9:Instances!AC9),"diff", MAX(Instances!AC9:Instances!AC9)-MIN(Instances!AC9:Instances!AC9))} -> 0 | AD9: {=_xlfn.SWITCH($A$2,"average", AVERAGE(Instances!AD9:Instances!AD9),"median", MEDIAN(Instances!AD9:Instances!AD9),"min", MIN(Instances!AD9:Instances!AD9),"max", MAX(Instances!AD9:Instances!AD9),"diff", MAX(Instances!AD9:Instances!AD9)-MIN(Instances!AD9:Instances!AD9))} -> 0 | AJ9: {=_xlfn.SWITCH($A$2,"average", AVERAGE(Instances!AJ9:Instances!AJ9),"median", MEDIAN(Instances!AJ9:Instances!AJ9),"min", MIN(Instances!AJ9:Instances!AJ9),"max", MAX(Instances!AJ9:Instances!AJ9),"diff", MAX(Instances!AJ9:Instances!AJ9)-MIN(Instances!AJ9:Instances!AJ9))} -> 0 | AK9: {=_xlfn.SWITCH($A$2,"average", AVERAGE(Instances!AK9:Instances!AK9),"median", MEDIAN(Instances!AK9:Instances!AK9),"min", MIN(Instances!AK9:Instances!AK9),"max", MAX(Instances!AK9:Instances!AK9),"diff", MAX(Instances!AK9:Instances!AK9)-MIN(Instances!AK9:Instances!AK9))} -> 0 | AQ9: {=_xlfn.SWITCH($A$2,"average", AVERAGE(Instances!AQ9:Instances!AQ9),"median", MEDIAN(Instances!AQ9:Instances!AQ9),"min", MIN(Instances!AQ9:Instances!AQ9),"max", MAX(Instances!AQ9:Instances!AQ9),"diff", MAX(Instances!AQ9:Instances!AQ9)-MIN(Instances!AQ9:Instances!AQ9))} -> 0 | AR9: =MIN($B9,$I9,$P9,$W9,$AD9,$AK9) -> 0 | AW9: =MIN($H9,$O9,$V9,$AC9,$AJ9,$AQ9) -> 0 | AX9: =MEDIAN($B9,$I9,$P9,$W9,$AD9,$AK9) -> 0 | BC9: =MEDIAN($H9,$O9,$V9,$AC9,$AJ9,$AQ9) -> 0 | BD9: =MAX($B9,$I9,$P9,$W9,$AD9,$AK9) -> 0 | BI9: =MAX($H9,$O9,$V9,$AC9,$AJ9,$AQ9) -> 0
