Workbook

Sheet Instances
B1: memelingo-1/lambda-small_mlp-tplp-ht_10 | I1: memelingo-1/lambda-small_mlp-tplp-ht_15 | P1: memelingo-1/lambda-small_mlp-tplp-ht_20 | W1: memelingo-1/lambda-small_mlp-tplp-ht_25 | AD1: memelingo-1/lambda-small_mlp-tplp-ht_30 | AK1: memelingo-1/lambda-small_mlp-tplp-ht_35 | AR1: memelingo-1/lambda-small_mlp-tplp-ht_40 | AY1: memelingo-1/lambda-small_mlp-tplp-ht_45 | BF1: memelingo-1/lambda-small_mlp-tplp-ht_50 | BM1: memelingo-1/lambda-small_mlp-tplp-htc_10 | BT1: memelingo-1/lambda-small_mlp-tplp-htc_15 | CA1: memelingo-1/lambda-small_mlp-tplp-htc_20 | CH1: memelingo-1/lambda-small_mlp-tplp-htc_25 | CO1: memelingo-1/lambda-small_mlp-tplp-htc_30 | CV1: memelingo-1/lambda-small_mlp-tplp-htc_35 | DC1: memelingo-1/lambda-small_mlp-tplp-htc_40 | DJ1: memelingo-1/lambda-small_mlp-tplp-htc_45 | DQ1: memelingo-1/lambda-small_mlp-tplp-htc_50 | DX1: memelingo-1/lambda-small_mlp-tplp-htcdl_10 | EE1: memelingo-1/lambda-small_mlp-tplp-htcdl_15 | EL1: memelingo-1/lambda-small_mlp-tplp-htcdl_20 | ES1: memelingo-1/lambda-small_mlp-tplp-htcdl_25 | EZ1: memelingo-1/lambda-small_mlp-tplp-htcdl_30 | FG1: memelingo-1/lambda-small_mlp-tplp-htcdl_35 | FN1: memelingo-1/lambda-small_mlp-tplp-htcdl_40 | FU1: memelingo-1/lambda-small_mlp-tplp-htcdl_45 | GB1: memelingo-1/lambda-small_mlp-tplp-htcdl_50 | GI1: min | GO1: median | GU1: max
B2: time | C2: stime | D2: status | E2: rules | F2: ctime | G2: fmtime | H2: memout | I2: time | J2: stime | K2: status | L2: rules | M2: ctime | N2: fmtime | O2: memout | P2: time | Q2: stime | R2: status | S2: rules | T2: ctime | U2: fmtime | V2: memout | W2: time | X2: stime | Y2: status | Z2: rules | AA2: ctime | AB2: fmtime | AC2: memout | AD2: time | AE2: stime | AF2: status | AG2: rules | AH2: ctime | AI2: fmtime | AJ2: memout | AK2: time | AL2: stime | AM2: status | AN2: rules | AO2: ctime | AP2: fmtime | AQ2: memout | AR2: time | AS2: stime | AT2: status | AU2: rules | AV2: ctime | AW2: fmtime | AX2: memout | AY2: time | AZ2: stime | BA2: status | BB2: rules | BC2: ctime | BD2: fmtime | BE2: memout | BF2: time | BG2: stime | BH2: status | BI2: rules | BJ2: ctime | BK2: fmtime | BL2: memout | BM2: time | BN2: stime | BO2: status | BP2: rules | BQ2: ctime | BR2: fmtime | BS2: memout | BT2: time | BU2: stime | BV2: status | BW2: rules | BX2: ctime | BY2: fmtime | BZ2: memout | CA2: time | CB2: stime | CC2: status | CD2: rules | CE2: ctime | CF2: fmtime | CG2: memout | CH2: time | CI2: stime | CJ2: status | CK2: rules | CL2: ctime | CM2: fmtime | CN2: memout | CO2: time | CP2: stime | CQ2: status | CR2: rules | CS2: ctime | CT2: fmtime | CU2: memout | CV2: time | CW2: stime | CX2: status | CY2: rules | CZ2: ctime | DA2: fmtime | DB2: memout | DC2: time | DD2: stime | DE2: status | DF2: rules | DG2: ctime | DH2: fmtime | DI2: memout | DJ2: time | DK2: stime | DL2: status | DM2: rules | DN2: ctime | DO2: fmtime | DP2: memout | DQ2: time | DR2: stime | DS2: status | DT2: rules | DU2: ctime | DV2: fmtime | DW2: memout | DX2: time | DY2: stime | DZ2: status | EA2: rules | EB2: ctime | EC2: fmtime | ED2: memout | EE2: time | EF2: stime | EG2: status | EH2: rules | EI2: ctime | EJ2: fmtime | EK2: memout | EL2: time | EM2: stime | EN2: status | EO2: rules | EP2: ctime | EQ2: fmtime | ER2: memout | ES2: time | ET2: stime | EU2: status | EV2: rules | EW2: ctime | EX2: fmtime | EY2: memout | EZ2: time | FA2: stime | FB2: status | FC2: rules | FD2: ctime | FE2: fmtime | FF2: memout | FG2: time | FH2: stime | FI2: status | FJ2: rules | FK2: ctime | FL2: fmtime | FM2: memout | FN2: time | FO2: stime | FP2: status | FQ2: rules | FR2: ctime | FS2: fmtime | FT2: memout | FU2: time | FV2: stime | FW2: status | FX2: rules | FY2: ctime | FZ2: fmtime | GA2: memout | GB2: time | GC2: stime | GD2: status | GE2: rules | GF2: ctime | GG2: fmtime | GH2: memout | GI2: time | GJ2: stime | GK2: rules | GL2: ctime | GM2: fmtime | GN2: memout | GO2: time | GP2: stime | GQ2: rules | GR2: ctime | GS2: fmtime | GT2: memout | GU2: time | GV2: stime | GW2: rules | GX2: ctime | GY2: fmtime | GZ2: memout
A3: instances/ft06 | B3: 147.02 | C3: 135.79 | D3: UNSATISFIABLE | E3: 1680929 | F3: 137.942 | G3: 0 | H3: 0 | I3: 1200 | J3: 1185.83 | K3: UNKNOWN | L3: 3477919 | M3: 1190.466 | N3: 0 | O3: 0 | P3: 1200 | Q3: 1183.08 | R3: UNKNOWN | S3: 5585084 | T3: 1190.661 | U3: 0 | V3: 0 | W3: 1200 | X3: 1179.61 | Y3: UNKNOWN | Z3: 7799174 | AA3: 1190.178 | AB3: 0 | AC3: 0 | AD3: 1200 | AE3: 1176.55 | AF3: UNKNOWN | AG3: 9950689 | AH3: 1190.181 | AI3: 0 | AJ3: 0 | AK3: 1200 | AL3: 1175.11 | AM3: UNKNOWN | AN3: 11903879 | AO3: 1191.026 | AP3: 0 | AQ3: 0 | AR3: 652.67 | AS3: 623.81 | AT3: SATISFIABLE | AU3: 13556744 | AV3: 641.971 | AW3: 623.8 | AX3: 0 | AY3: 205.35 | AZ3: 175.98 | BA3: SATISFIABLE | BB3: 14841034 | BC3: 195.319 | BD3: 175.98 | BE3: 0 | BF3: 45.43 | BG3: 15.41 | BH3: SATISFIABLE | BI3: 15722249 | BJ3: 36.038 | BK3: 15.4 | BL3: 0 | BM3: 12.66 | BN3: 1.89 | BO3: UNSATISFIABLE | BP3: 62428 | BQ3: 2.412 | BR3: 0 | BS3: 0 | BT3: 223.74 | BU3: 213.58 | BV3: UNSATISFIABLE | BW3: 103743 | BX3: 214.306 | BY3: 0 | BZ3: 0 | CA3: 20.69 | CB3: 8.93 | CC3: SATISFIABLE | CD3: 152933 | CE3: 9.846 | CF3: 8.92 | CG3: 0 | CH3: 979.26 | CI3: 967.76 | CJ3: SATISFIABLE | CK3: 209998 | CL3: 968.955 | CM3: 967.76 | CN3: 0 | CO3: 86.39 | CP3: 74.6 | CQ3: SATISFIABLE | CR3: 274938 | CS3: 76.111 | CT3: 74.6 | CU3: 0 | CV3: 209.23 | CW3: 197.58 | CX3: SATISFIABLE | CY3: 347753 | CZ3: 199.473 | DA3: 197.58 | DB3: 0 | DC3: 41.71 | DD3: 28.53 | DE3: SATISFIABLE | DF3: 428443 | DG3: 30.886 | DH3: 28.53 | DI3: 0 | DJ3: 31.93 | DK3: 19.47 | DL3: SATISFIABLE | DM3: 517008 | DN3: 22.271 | DO3: 19.46 | DP3: 0 | DQ3: 56.52 | DR3: 42.63 | DS3: SATISFIABLE | DT3: 613448 | DU3: 45.604 | DV3: 42.62 | DW3: 0 | DX3: 11.02 | DY3: 0.42 | DZ3: UNSATISFIABLE | EA3: 62428 | EB3: 0.906 | EC3: 0 | ED3: 0 | EE3: 415.17 | EF3: 404.82 | EG3: UNSATISFIABLE | EH3: 103743 | EI3: 405.423 | EJ3: 0 | EK3: 0 | EL3: 818.71 | EM3: 807.07 | EN3: SATISFIABLE | EO3: 152933 | EP3: 807.93 | EQ3: 807.07 | ER3: 0 | ES3: 1200 | ET3: 1188.5 | EU3: UNKNOWN | EV3: 209998 | EW3: 1189.592 | EX3: 0 | EY3: 0 | EZ3: 212.65 | FA3: 200.69 | FB3: SATISFIABLE | FC3: 274938 | FD3: 201.991 | FE3: 200.69 | FF3: 0 | FG3: 315.74 | FH3: 304.87 | FI3: SATISFIABLE | FJ3: 347753 | FK3: 306.476 | FL3: 304.86 | FM3: 0 | FN3: 88.85 | FO3: 76.27 | FP3: SATISFIABLE | FQ3: 428443 | FR3: 78.294 | FS3: 76.27 | FT3: 0 | FU3: 87.23 | FV3: 74.44 | FW3: SATISFIABLE | FX3: 517008 | FY3: 76.745 | FZ3: 74.44 | GA3: 0 | GB3: 35.09 | GC3: 22.16 | GD3: SATISFIABLE | GE3: 613448 | GF3: 24.82 | GG3: 22.15 | GH3: 0 | GI3: =MIN($B3,$I3,$P3,$W3,$AD3,$AK3,$AR3,$AY3,$BF3,$BM3,$BT3,$CA3,$CH3,$CO3,$CV3,$DC3,$DJ3,$DQ3,$DX3,$EE3,$EL3,$ES3,$EZ3,$FG3,$FN3,$FU3,$GB3) -> 0 | GJ3: =MIN($C3,$J3,$Q3,$X3,$AE3,$AL3,$AS3,$AZ3,$BG3,$BN3,$BU3,$CB3,$CI3,$CP3,$CW3,$DD3,$DK3,$DR3,$DY3,$EF3,$EM3,$ET3,$FA3,$FH3,$FO3,$FV3,$GC3) -> 0 | GK3: =MIN($E3,$L3,$S3,$Z3,$AG3,$AN3,$AU3,$BB3,$BI3,$BP3,$BW3,$CD3,$CK3,$CR3,$CY3,$DF3,$DM3,$DT3,$EA3,$EH3,$EO3,$EV3,$FC3,$FJ3,$FQ3,$FX3,$GE3) -> 0 | GL3: =MIN($F3,$M3,$T3,$AA3,$AH3,$AO3,$AV3,$BC3,$BJ3,$BQ3,$BX3,$CE3,$CL3,$CS3,$CZ3,$DG3,$DN3,$DU3,$EB3,$EI3,$EP3,$EW3,$FD3,$FK3,$FR3,$FY3,$GF3) -> 0 | GM3: =MIN($G3,$N3,$U3,$AB3,$AI3,$AP3,$AW3,$BD3,$BK3,$BR3,$BY3,$CF3,$CM3,$CT3,$DA3,$DH3,$DO3,$DV3,$EC3,$EJ3,$EQ3,$EX3,$FE3,$FL3,$FS3,$FZ3,$GG3) -> 0 | GN3: =MIN($H3,$O3,$V3,$AC3,$AJ3,$AQ3,$AX3,$BE3,$BL3,$BS3,$BZ3,$CG3,$CN3,$CU3,$DB3,$DI3,$DP3,$DW3,$ED3,$EK3,$ER3,$EY3,$FF3,$FM3,$FT3,$GA3,$GH3) -> 0 | GO3: =MEDIAN($B3,$I3,$P3,$W3,$AD3,$AK3,$AR3,$AY3,$BF3,$BM3,$BT3,$CA3,$CH3,$CO3,$CV3,$DC3,$DJ3,$DQ3,$DX3,$EE3,$EL3,$ES3,$EZ3,$FG3,$FN3,$FU3,$GB3) -> 0 | GP3: =MEDIAN($C3,$J3,$Q3,$X3,$AE3,$AL3,$AS3,$AZ3,$BG3,$BN3,$BU3,$CB3,$CI3,$CP3,$CW3,$DD3,$DK3,$DR3,$DY3,$EF3,$EM3,$ET3,$FA3,$FH3,$FO3,$FV3,$GC3) -> 0 | GQ3: =MEDIAN($E3,$L3,$S3,$Z3,$AG3,$AN3,$AU3,$BB3,$BI3,$BP3,$BW3,$CD3,$CK3,$CR3,$CY3,$DF3,$DM3,$DT3,$EA3,$EH3,$EO3,$EV3,$FC3,$FJ3,$FQ3,$FX3,$GE3) -> 0 | GR3: =MEDIAN($F3,$M3,$T3,$AA3,$AH3,$AO3,$AV3,$BC3,$BJ3,$BQ3,$BX3,$CE3,$CL3,$CS3,$CZ3,$DG3,$DN3,$DU3,$EB3,$EI3,$EP3,$EW3,$FD3,$FK3,$FR3,$FY3,$GF3) -> 0 | GS3: =MEDIAN($G3,$N3,$U3,$AB3,$AI3,$AP3,$AW3,$BD3,$BK3,$BR3,$BY3,$CF3,$CM3,$CT3,$DA3,$DH3,$DO3,$DV3,$EC3,$EJ3,$EQ3,$EX3,$FE3,$FL3,$FS3,$FZ3,$GG3) -> 0 | GT3: =MEDIAN($H3,$O3,$V3,$AC3,$AJ3,$AQ3,$AX3,$BE3,$BL3,$BS3,$BZ3,$CG3,$CN3,$CU3,$DB3,$DI3,$DP3,$DW3,$ED3,$EK3,$ER3,$EY3,$FF3,$FM3,$FT3,$GA3,$GH3) -> 0 | GU3: =MAX($B3,$I3,$P3,$W3,$AD3,$AK3,$AR3,$AY3,$BF3,$BM3,$BT3,$CA3,$CH3,$CO3,$CV3,$DC3,$DJ3,$DQ3,$DX3,$EE3,$EL3,$ES3,$EZ3,$FG3,$FN3,$FU3,$GB3) -> 0 | GV3: =MAX($C3,$J3,$Q3,$X3,$AE3,$AL3,$AS3,$AZ3,$BG3,$BN3,$BU3,$CB3,$CI3,$CP3,$CW3,$DD3,$DK3,$DR3,$DY3,$EF3,$EM3,$ET3,$FA3,$FH3,$FO3,$FV3,$GC3) -> 0 | GW3: =MAX($E3,$L3,$S3,$Z3,$AG3,$AN3,$AU3,$BB3,$BI3,$BP3,$BW3,$CD3,$CK3,$CR3,$CY3,$DF3,$DM3,$DT3,$EA3,$EH3,$EO3,$EV3,$FC3,$FJ3,$FQ3,$FX3,$GE3) -> 0 | GX3: =MAX($F3,$M3,$T3,$AA3,$AH3,$AO3,$AV3,$BC3,$BJ3,$BQ3,$BX3,$CE3,$CL3,$CS3,$CZ3,$DG3,$DN3,$DU3,$EB3,$EI3,$EP3,$EW3,$FD3,$FK3,$FR3,$FY3,$GF3) -> 0 | GY3: =MAX($G3,$N3,$U3,$AB3,$AI3,$AP3,$AW3,$BD3,$BK3,$BR3,$BY3,$CF3,$CM3,$CT3,$DA3,$DH3,$DO3,$DV3,$EC3,$EJ3,$EQ3,$EX3,$FE3,$FL3,$FS3,$FZ3,$GG3) -> 0 | GZ3: =MAX($H3,$O3,$V3,$AC3,$AJ3,$AQ3,$AX3,$BE3,$BL3,$BS3,$BZ3,$CG3,$CN3,$CU3,$DB3,$DI3,$DP3,$DW3,$ED3,$EK3,$ER3,$EY3,$FF3,$FM3,$FT3,$GA3,$GH3) -> 0
A5: SUM | B5: =SUM(B$3:B$3) -> 0 | C5: =SUM(C$3:C$3) -> 0 | E5: =SUM(E$3:E$3) -> 0 | F5: =SUM(F$3:F$3) -> 0 | G5: =SUM(G$3:G$3) -> 0 | H5: =SUM(H$3:H$3) -> 0 | I5: =SUM(I$3:I$3) -> 0 | J5: =SUM(J$3:J$3) -> 0 | L5: =SUM(L$3:L$3) -> 0 | M5: =SUM(M$3:M$3) -> 0 | N5: =SUM(N$3:N$3) -> 0 | O5: =SUM(O$3:O$3) -> 0 | P5: =SUM(P$3:P$3) -> 0 | Q5: =SUM(Q$3:Q$3) -> 0 | S5: =SUM(S$3:S$3) -> 0 | T5: =SUM(T$3:T$3) -> 0 | U5: =SUM(U$3:U$3) -> 0 | V5: =SUM(V$3:V$3) -> 0 | W5: =SUM(W$3:W$3) -> 0 | X5: =SUM(X$3:X$3) -> 0 | Z5: =SUM(Z$3:Z$3) -> 0 | AA5: =SUM(AA$3:AA$3) -> 0 | AB5: =SUM(AB$3:AB$3) -> 0 | AC5: =SUM(AC$3:AC$3) -> 0 | AD5: =SUM(AD$3:AD$3) -> 0 | AE5: =SUM(AE$3:AE$3) -> 0 | AG5: =SUM(AG$3:AG$3) -> 0 | AH5: =SUM(AH$3:AH$3) -> 0 | AI5: =SUM(AI$3:AI$3) -> 0 | AJ5: =SUM(AJ$3:AJ$3) -> 0 | AK5: =SUM(AK$3:AK$3) -> 0 | AL5: =SUM(AL$3:AL$3) -> 0 | AN5: =SUM(AN$3:AN$3) -> 0 | AO5: =SUM(AO$3:AO$3) -> 0 | AP5: =SUM(AP$3:AP$3) -> 0 | AQ5: =SUM(AQ$3:AQ$3) -> 0 | AR5: =SUM(AR$3:AR$3) -> 0 | AS5: =SUM(AS$3:AS$3) -> 0 | AU5: =SUM(AU$3:AU$3) -> 0 | AV5: =SUM(AV$3:AV$3) -> 0 | AW5: =SUM(AW$3:AW$3) -> 0 | AX5: =SUM(AX$3:AX$3) -> 0 | AY5: =SUM(AY$3:AY$3) -> 0 | AZ5: =SUM(AZ$3:AZ$3) -> 0 | BB5: =SUM(BB$3:BB$3) -> 0 | BC5: =SUM(BC$3:BC$3) -> 0 | BD5: =SUM(BD$3:BD$3) -> 0 | BE5: =SUM(BE$3:BE$3) -> 0 | BF5: =SUM(BF$3:BF$3) -> 0 | BG5: =SUM(BG$3:BG$3) -> 0 | BI5: =SUM(BI$3:BI$3) -> 0 | BJ5: =SUM(BJ$3:BJ$3) -> 0 | BK5: =SUM(BK$3:BK$3) -> 0 | BL5: =SUM(BL$3:BL$3) -> 0 | BM5: =SUM(BM$3:BM$3) -> 0 | BN5: =SUM(BN$3:BN$3) -> 0 | BP5: =SUM(BP$3:BP$3) -> 0 | BQ5: =SUM(BQ$3:BQ$3) -> 0 | BR5: =SUM(BR$3:BR$3) -> 0 | BS5: =SUM(BS$3:BS$3) -> 0 | BT5: =SUM(BT$3:BT$3) -> 0 | BU5: =SUM(BU$3:BU$3) -> 0 | BW5: =SUM(BW$3:BW$3) -> 0 | BX5: =SUM(BX$3:BX$3) -> 0 | BY5: =SUM(BY$3:BY$3) -> 0 | BZ5: =SUM(BZ$3:BZ$3) -> 0 | CA5: =SUM(CA$3:CA$3) -> 0 | CB5: =SUM(CB$3:CB$3) -> 0 | CD5: =SUM(CD$3:CD$3) -> 0 | CE5: =SUM(CE$3:CE$3) -> 0 | CF5: =SUM(CF$3:CF$3) -> 0 | CG5: =SUM(CG$3:CG$3) -> 0 | CH5: =SUM(CH$3:CH$3) -> 0 | CI5: =SUM(CI$3:CI$3) -> 0 | CK5: =SUM(CK$3:CK$3) -> 0 | CL5: =SUM(CL$3:CL$3) -> 0 | CM5: =SUM(CM$3:CM$3) -> 0 | CN5: =SUM(CN$3:CN$3) -> 0 | CO5: =SUM(CO$3:CO$3) -> 0 | CP5: =SUM(CP$3:CP$3) -> 0 | CR5: =SUM(CR$3:CR$3) -> 0 | CS5: =SUM(CS$3:CS$3) -> 0 | CT5: =SUM(CT$3:CT$3) -> 0 | CU5: =SUM(CU$3:CU$3) -> 0 | CV5: =SUM(CV$3:CV$3) -> 0 | CW5: =SUM(CW$3:CW$3) -> 0 | CY5: =SUM(CY$3:CY$3) -> 0 | CZ5: =SUM(CZ$3:CZ$3) -> 0 | DA5: =SUM(DA$3:DA$3) -> 0 | DB5: =SUM(DB$3:DB$3) -> 0 | DC5: =SUM(DC$3:DC$3) -> 0 | DD5: =SUM(DD$3:DD$3) -> 0 | DF5: =SUM(DF$3:DF$3) -> 0 | DG5: =SUM(DG$3:DG$3) -> 0 | DH5: =SUM(DH$3:DH$3) -> 0 | DI5: =SUM(DI$3:DI$3) -> 0 | DJ5: =SUM(DJ$3:DJ$3) -> 0 | DK5: =SUM(DK$3:DK$3) -> 0 | DM5: =SUM(DM$3:DM$3) -> 0 | DN5: =SUM(DN$3:DN$3) -> 0 | DO5: =SUM(DO$3:DO$3) -> 0 | DP5: =SUM(DP$3:DP$3) -> 0 | DQ5: =SUM(DQ$3:DQ$3) -> 0 | DR5: =SUM(DR$3:DR$3) -> 0 | DT5: =SUM(DT$3:DT$3) -> 0 | DU5: =SUM(DU$3:DU$3) -> 0 | DV5: =SUM(DV$3:DV$3) -> 0 | DW5: =SUM(DW$3:DW$3) -> 0 | DX5: =SUM(DX$3:DX$3) -> 0 | DY5: =SUM(DY$3:DY$3) -> 0 | EA5: =SUM(EA$3:EA$3) -> 0 | EB5: =SUM(EB$3:EB$3) -> 0 | EC5: =SUM(EC$3:EC$3) -> 0 | ED5: =SUM(ED$3:ED$3) -> 0 | EE5: =SUM(EE$3:EE$3) -> 0 | EF5: =SUM(EF$3:EF$3) -> 0 | EH5: =SUM(EH$3:EH$3) -> 0 | EI5: =SUM(EI$3:EI$3) -> 0 | EJ5: =SUM(EJ$3:EJ$3) -> 0 | EK5: =SUM(EK$3:EK$3) -> 0 | EL5: =SUM(EL$3:EL$3) -> 0 | EM5: =SUM(EM$3:EM$3) -> 0 | EO5: =SUM(EO$3:EO$3) -> 0 | EP5: =SUM(EP$3:EP$3) -> 0 | EQ5: =SUM(EQ$3:EQ$3) -> 0 | ER5: =SUM(ER$3:ER$3) -> 0 | ES5: =SUM(ES$3:ES$3) -> 0 | ET5: =SUM(ET$3:ET$3) -> 0 | EV5: =SUM(EV$3:EV$3) -> 0 | EW5: =SUM(EW$3:EW$3) -> 0 | EX5: =SUM(EX$3:EX$3) -> 0 | EY5: =SUM(EY$3:EY$3) -> 0 | EZ5: =SUM(EZ$3:EZ$3) -> 0 | FA5: =SUM(FA$3:FA$3) -> 0 | FC5: =SUM(FC$3:FC$3) -> 0 | FD5: =SUM(FD$3:FD$3) -> 0 | FE5: =SUM(FE$3:FE$3) -> 0 | FF5: =SUM(FF$3:FF$3) -> 0 | FG5: =SUM(FG$3:FG$3) -> 0 | FH5: =SUM(FH$3:FH$3) -> 0 | FJ5: =SUM(FJ$3:FJ$3) -> 0 | FK5: =SUM(FK$3:FK$3) -> 0 | FL5: =SUM(FL$3:FL$3) -> 0 | FM5: =SUM(FM$3:FM$3) -> 0 | FN5: =SUM(FN$3:FN$3) -> 0 | FO5: =SUM(FO$3:FO$3) -> 0 | FQ5: =SUM(FQ$3:FQ$3) -> 0 | FR5: =SUM(FR$3:FR$3) -> 0 | FS5: =SUM(FS$3:FS$3) -> 0 | FT5: =SUM(FT$3:FT$3) -> 0 | FU5: =SUM(FU$3:FU$3) -> 0 | FV5: =SUM(FV$3:FV$3) -> 0 | FX5: =SUM(FX$3:FX$3) -> 0 | FY5: =SUM(FY$3:FY$3) -> 0 | FZ5: =SUM(FZ$3:FZ$3) -> 0 | GA5: =SUM(GA$3:GA$3) -> 0 | GB5: =SUM(GB$3:GB$3) -> 0 | GC5: =SUM(GC$3:GC$3) -> 0 | GE5: =SUM(GE$3:GE$3) -> 0 | GF5: =SUM(GF$3:GF$3) -> 0 | GG5: =SUM(GG$3:GG$3) -> 0 | GH5: =SUM(GH$3:GH$3) -> 0 | GI5: =SUM(GI$3:GI$3) -> 0 | GJ5: =SUM(GJ$3:GJ$3) -> 0 | GK5: =SUM(GK$3:GK$3) -> 0 | GL5: =SUM(GL$3:GL$3) -> 0 | ... GZ5: =SUM(GZ$3:GZ$3) -> 0
A6: AVG | B6: =AVERAGE(B$3:B$3) -> 0 | C6: =AVERAGE(C$3:C$3) -> 0 | E6: =AVERAGE(E$3:E$3) -> 0 | F6: =AVERAGE(F$3:F$3) -> 0 | G6: =AVERAGE(G$3:G$3) -> 0 | H6: =AVERAGE(H$3:H$3) -> 0 | I6: =AVERAGE(I$3:I$3) -> 0 | J6: =AVERAGE(J$3:J$3) -> 0 | L6: =AVERAGE(L$3:L$3) -> 0 | M6: =AVERAGE(M$3:M$3) -> 0 | N6: =AVERAGE(N$3:N$3) -> 0 | O6: =AVERAGE(O$3:O$3) -> 0 | P6: =AVERAGE(P$3:P$3) -> 0 | Q6: =AVERAGE(Q$3:Q$3) -> 0 | S6: =AVERAGE(S$3:S$3) -> 0 | T6: =AVERAGE(T$3:T$3) -> 0 | U6: =AVERAGE(U$3:U$3) -> 0 | V6: =AVERAGE(V$3:V$3) -> 0 | W6: =AVERAGE(W$3:W$3) -> 0 | X6: =AVERAGE(X$3:X$3) -> 0 | Z6: =AVERAGE(Z$3:Z$3) -> 0 | AA6: =AVERAGE(AA$3:AA$3) -> 0 | AB6: =AVERAGE(AB$3:AB$3) -> 0 | AC6: =AVERAGE(AC$3:AC$3) -> 0 | AD6: =AVERAGE(AD$3:AD$3) -> 0 | AE6: =AVERAGE(AE$3:AE$3) -> 0 | AG6: =AVERAGE(AG$3:AG$3) -> 0 | AH6: =AVERAGE(AH$3:AH$3) -> 0 | AI6: =AVERAGE(AI$3:AI$3) -> 0 | AJ6: =AVERAGE(AJ$3:AJ$3) -> 0 | AK6: =AVERAGE(AK$3:AK$3) -> 0 | AL6: =AVERAGE(AL$3:AL$3) -> 0 | AN6: =AVERAGE(AN$3:AN$3) -> 0 | AO6: =AVERAGE(AO$3:AO$3) -> 0 | AP6: =AVERAGE(AP$3:AP$3) -> 0 | AQ6: =AVERAGE(AQ$3:AQ$3) -> 0 | AR6: =AVERAGE(AR$3:AR$3) -> 0 | AS6: =AVERAGE(AS$3:AS$3) -> 0 | AU6: =AVERAGE(AU$3:AU$3) -> 0 | AV6: =AVERAGE(AV$3:AV$3) -> 0 | AW6: =AVERAGE(AW$3:AW$3) -> 0 | AX6: =AVERAGE(AX$3:AX$3) -> 0 | AY6: =AVERAGE(AY$3:AY$3) -> 0 | AZ6: =AVERAGE(AZ$3:AZ$3) -> 0 | BB6: =AVERAGE(BB$3:BB$3) -> 0 | BC6: =AVERAGE(BC$3:BC$3) -> 0 | BD6: =AVERAGE(BD$3:BD$3) -> 0 | BE6: =AVERAGE(BE$3:BE$3) -> 0 | BF6: =AVERAGE(BF$3:BF$3) -> 0 | BG6: =AVERAGE(BG$3:BG$3) -> 0 | BI6: =AVERAGE(BI$3:BI$3) -> 0 | BJ6: =AVERAGE(BJ$3:BJ$3) -> 0 | BK6: =AVERAGE(BK$3:BK$3) -> 0 | BL6: =AVERAGE(BL$3:BL$3) -> 0 | BM6: =AVERAGE(BM$3:BM$3) -> 0 | BN6: =AVERAGE(BN$3:BN$3) -> 0 | BP6: =AVERAGE(BP$3:BP$3) -> 0 | BQ6: =AVERAGE(BQ$3:BQ$3) -> 0 | BR6: =AVERAGE(BR$3:BR$3) -> 0 | BS6: =AVERAGE(BS$3:BS$3) -> 0 | BT6: =AVERAGE(BT$3:BT$3) -> 0 | BU6: =AVERAGE(BU$3:BU$3) -> 0 | BW6: =AVERAGE(BW$3:BW$3) -> 0 | BX6: =AVERAGE(BX$3:BX$3) -> 0 | BY6: =AVERAGE(BY$3:BY$3) -> 0 | BZ6: =AVERAGE(BZ$3:BZ$3) -> 0 | CA6: =AVERAGE(CA$3:CA$3) -> 0 | CB6: =AVERAGE(CB$3:CB$3) -> 0 | CD6: =AVERAGE(CD$3:CD$3) -> 0 | CE6: =AVERAGE(CE$3:CE$3) -> 0 | CF6: =AVERAGE(CF$3:CF$3) -> 0 | CG6: =AVERAGE(CG$3:CG$3) -> 0 | CH6: =AVERAGE(CH$3:CH$3) -> 0 | CI6: =AVERAGE(CI$3:CI$3) -> 0 | CK6: =AVERAGE(CK$3:CK$3) -> 0 | CL6: =AVERAGE(CL$3:CL$3) -> 0 | CM6: =AVERAGE(CM$3:CM$3) -> 0 | CN6: =AVERAGE(CN$3:CN$3) -> 0 | CO6: =AVERAGE(CO$3:CO$3) -> 0 | CP6: =AVERAGE(CP$3:CP$3) -> 0 | CR6: =AVERAGE(CR$3:CR$3) -> 0 | CS6: =AVERAGE(CS$3:CS$3) -> 0 | CT6: =AVERAGE(CT$3:CT$3) -> 0 | CU6: =AVERAGE(CU$3:CU$3) -> 0 | CV6: =AVERAGE(CV$3:CV$3) -> 0 | CW6: =AVERAGE(CW$3:CW$3) -> 0 | CY6: =AVERAGE(CY$3:CY$3) -> 0 | CZ6: =AVERAGE(CZ$3:CZ$3) -> 0 | DA6: =AVERAGE(DA$3:DA$3) -> 0 | DB6: =AVERAGE(DB$3:DB$3) -> 0 | DC6: =AVERAGE(DC$3:DC$3) -> 0 | DD6: =AVERAGE(DD$3:DD$3) -> 0 | DF6: =AVERAGE(DF$3:DF$3) -> 0 | DG6: =AVERAGE(DG$3:DG$3) -> 0 | DH6: =AVERAGE(DH$3:DH$3) -> 0 | DI6: =AVERAGE(DI$3:DI$3) -> 0 | DJ6: =AVERAGE(DJ$3:DJ$3) -> 0 | DK6: =AVERAGE(DK$3:DK$3) -> 0 | DM6: =AVERAGE(DM$3:DM$3) -> 0 | DN6: =AVERAGE(DN$3:DN$3) -> 0 | DO6: =AVERAGE(DO$3:DO$3) -> 0 | DP6: =AVERAGE(DP$3:DP$3) -> 0 | DQ6: =AVERAGE(DQ$3:DQ$3) -> 0 | DR6: =AVERAGE(DR$3:DR$3) -> 0 | DT6: =AVERAGE(DT$3:DT$3) -> 0 | DU6: =AVERAGE(DU$3:DU$3) -> 0 | DV6: =AVERAGE(DV$3:DV$3) -> 0 | DW6: =AVERAGE(DW$3:DW$3) -> 0 | DX6: =AVERAGE(DX$3:DX$3) -> 0 | DY6: =AVERAGE(DY$3:DY$3) -> 0 | EA6: =AVERAGE(EA$3:EA$3) -> 0 | EB6: =AVERAGE(EB$3:EB$3) -> 0 | EC6: =AVERAGE(EC$3:EC$3) -> 0 | ED6: =AVERAGE(ED$3:ED$3) -> 0 | EE6: =AVERAGE(EE$3:EE$3) -> 0 | EF6: =AVERAGE(EF$3:EF$3) -> 0 | EH6: =AVERAGE(EH$3:EH$3) -> 0 | EI6: =AVERAGE(EI$3:EI$3) -> 0 | EJ6: =AVERAGE(EJ$3:EJ$3) -> 0 | EK6: =AVERAGE(EK$3:EK$3) -> 0 | EL6: =AVERAGE(EL$3:EL$3) -> 0 | EM6: =AVERAGE(EM$3:EM$3) -> 0 | EO6: =AVERAGE(EO$3:EO$3) -> 0 | EP6: =AVERAGE(EP$3:EP$3) -> 0 | EQ6: =AVERAGE(EQ$3:EQ$3) -> 0 | ER6: =AVERAGE(ER$3:ER$3) -> 0 | ES6: =AVERAGE(ES$3:ES$3) -> 0 | ET6: =AVERAGE(ET$3:ET$3) -> 0 | EV6: =AVERAGE(EV$3:EV$3) -> 0 | EW6: =AVERAGE(EW$3:EW$3) -> 0 | EX6: =AVERAGE(EX$3:EX$3) -> 0 | EY6: =AVERAGE(EY$3:EY$3) -> 0 | EZ6: =AVERAGE(EZ$3:EZ$3) -> 0 | FA6: =AVERAGE(FA$3:FA$3) -> 0 | FC6: =AVERAGE(FC$3:FC$3) -> 0 | FD6: =AVERAGE(FD$3:FD$3) -> 0 | FE6: =AVERAGE(FE$3:FE$3) -> 0 | FF6: =AVERAGE(FF$3:FF$3) -> 0 | FG6: =AVERAGE(FG$3:FG$3) -> 0 | FH6: =AVERAGE(FH$3:FH$3) -> 0 | FJ6: =AVERAGE(FJ$3:FJ$3) -> 0 | FK6: =AVERAGE(FK$3:FK$3) -> 0 | FL6: =AVERAGE(FL$3:FL$3) -> 0 | FM6: =AVERAGE(FM$3:FM$3) -> 0 | FN6: =AVERAGE(FN$3:FN$3) -> 0 | FO6: =AVERAGE(FO$3:FO$3) -> 0 | FQ6: =AVERAGE(FQ$3:FQ$3) -> 0 | FR6: =AVERAGE(FR$3:FR$3) -> 0 | FS6: =AVERAGE(FS$3:FS$3) -> 0 | FT6: =AVERAGE(FT$3:FT$3) -> 0 | FU6: =AVERAGE(FU$3:FU$3) -> 0 | FV6: =AVERAGE(FV$3:FV$3) -> 0 | FX6: =AVERAGE(FX$3:FX$3) -> 0 | FY6: =AVERAGE(FY$3:FY$3) -> 0 | FZ6: =AVERAGE(FZ$3:FZ$3) -> 0 | GA6: =AVERAGE(GA$3:GA$3) -> 0 | GB6: =AVERAGE(GB$3:GB$3) -> 0 | GC6: =AVERAGE(GC$3:GC$3) -> 0 | GE6: =AVERAGE(GE$3:GE$3) -> 0 | GF6: =AVERAGE(GF$3:GF$3) -> 0 | GG6: =AVERAGE(GG$3:GG$3) -> 0 | GH6: =AVERAGE(GH$3:GH$3) -> 0 | GI6: =AVERAGE(GI$3:GI$3) -> 0 | GJ6: =AVERAGE(GJ$3:GJ$3) -> 0 | GK6: =AVERAGE(GK$3:GK$3) -> 0 | GL6: =AVERAGE(GL$3:GL$3) -> 0 | ... GZ6: =AVERAGE(GZ$3:GZ$3) -> 0
A7: DEV | B7: =STDEV(B$3:B$3) -> 0 | C7: =STDEV(C$3:C$3) -> 0 | E7: =STDEV(E$3:E$3) -> 0 | F7: =STDEV(F$3:F$3) -> 0 | G7: =STDEV(G$3:G$3) -> 0 | H7: =STDEV(H$3:H$3) -> 0 | I7: =STDEV(I$3:I$3) -> 0 | J7: =STDEV(J$3:J$3) -> 0 | L7: =STDEV(L$3:L$3) -> 0 | M7: =STDEV(M$3:M$3) -> 0 | N7: =STDEV(N$3:N$3) -> 0 | O7: =STDEV(O$3:O$3) -> 0 | P7: =STDEV(P$3:P$3) -> 0 | Q7: =STDEV(Q$3:Q$3) -> 0 | S7: =STDEV(S$3:S$3) -> 0 | T7: =STDEV(T$3:T$3) -> 0 | U7: =STDEV(U$3:U$3) -> 0 | V7: =STDEV(V$3:V$3) -> 0 | W7: =STDEV(W$3:W$3) -> 0 | X7: =STDEV(X$3:X$3) -> 0 | Z7: =STDEV(Z$3:Z$3) -> 0 | AA7: =STDEV(AA$3:AA$3) -> 0 | AB7: =STDEV(AB$3:AB$3) -> 0 | AC7: =STDEV(AC$3:AC$3) -> 0 | AD7: =STDEV(AD$3:AD$3) -> 0 | AE7: =STDEV(AE$3:AE$3) -> 0 | AG7: =STDEV(AG$3:AG$3) -> 0 | AH7: =STDEV(AH$3:AH$3) -> 0 | AI7: =STDEV(AI$3:AI$3) -> 0 | AJ7: =STDEV(AJ$3:AJ$3) -> 0 | AK7: =STDEV(AK$3:AK$3) -> 0 | AL7: =STDEV(AL$3:AL$3) -> 0 | AN7: =STDEV(AN$3:AN$3) -> 0 | AO7: =STDEV(AO$3:AO$3) -> 0 | AP7: =STDEV(AP$3:AP$3) -> 0 | AQ7: =STDEV(AQ$3:AQ$3) -> 0 | AR7: =STDEV(AR$3:AR$3) -> 0 | AS7: =STDEV(AS$3:AS$3) -> 0 | AU7: =STDEV(AU$3:AU$3) -> 0 | AV7: =STDEV(AV$3:AV$3) -> 0 | AW7: =STDEV(AW$3:AW$3) -> 0 | AX7: =STDEV(AX$3:AX$3) -> 0 | AY7: =STDEV(AY$3:AY$3) -> 0 | AZ7: =STDEV(AZ$3:AZ$3) -> 0 | BB7: =STDEV(BB$3:BB$3) -> 0 | BC7: =STDEV(BC$3:BC$3) -> 0 | BD7: =STDEV(BD$3:BD$3) -> 0 | BE7: =STDEV(BE$3:BE$3) -> 0 | BF7: =STDEV(BF$3:BF$3) -> 0 | BG7: =STDEV(BG$3:BG$3) -> 0 | BI7: =STDEV(BI$3:BI$3) -> 0 | BJ7: =STDEV(BJ$3:BJ$3) -> 0 | BK7: =STDEV(BK$3:BK$3) -> 0 | BL7: =STDEV(BL$3:BL$3) -> 0 | BM7: =STDEV(BM$3:BM$3) -> 0 | BN7: =STDEV(BN$3:BN$3) -> 0 | BP7: =STDEV(BP$3:BP$3) -> 0 | BQ7: =STDEV(BQ$3:BQ$3) -> 0 | BR7: =STDEV(BR$3:BR$3) -> 0 | BS7: =STDEV(BS$3:BS$3) -> 0 | BT7: =STDEV(BT$3:BT$3) -> 0 | BU7: =STDEV(BU$3:BU$3) -> 0 | BW7: =STDEV(BW$3:BW$3) -> 0 | BX7: =STDEV(BX$3:BX$3) -> 0 | BY7: =STDEV(BY$3:BY$3) -> 0 | BZ7: =STDEV(BZ$3:BZ$3) -> 0 | CA7: =STDEV(CA$3:CA$3) -> 0 | CB7: =STDEV(CB$3:CB$3) -> 0 | CD7: =STDEV(CD$3:CD$3) -> 0 | CE7: =STDEV(CE$3:CE$3) -> 0 | CF7: =STDEV(CF$3:CF$3) -> 0 | CG7: =STDEV(CG$3:CG$3) -> 0 | CH7: =STDEV(CH$3:CH$3) -> 0 | CI7: =STDEV(CI$3:CI$3) -> 0 | CK7: =STDEV(CK$3:CK$3) -> 0 | CL7: =STDEV(CL$3:CL$3) -> 0 | CM7: =STDEV(CM$3:CM$3) -> 0 | CN7: =STDEV(CN$3:CN$3) -> 0 | CO7: =STDEV(CO$3:CO$3) -> 0 | CP7: =STDEV(CP$3:CP$3) -> 0 | CR7: =STDEV(CR$3:CR$3) -> 0 | CS7: =STDEV(CS$3:CS$3) -> 0 | CT7: =STDEV(CT$3:CT$3) -> 0 | CU7: =STDEV(CU$3:CU$3) -> 0 | CV7: =STDEV(CV$3:CV$3) -> 0 | CW7: =STDEV(CW$3:CW$3) -> 0 | CY7: =STDEV(CY$3:CY$3) -> 0 | CZ7: =STDEV(CZ$3:CZ$3) -> 0 | DA7: =STDEV(DA$3:DA$3) -> 0 | DB7: =STDEV(DB$3:DB$3) -> 0 | DC7: =STDEV(DC$3:DC$3) -> 0 | DD7: =STDEV(DD$3:DD$3) -> 0 | DF7: =STDEV(DF$3:DF$3) -> 0 | DG7: =STDEV(DG$3:DG$3) -> 0 | DH7: =STDEV(DH$3:DH$3) -> 0 | DI7: =STDEV(DI$3:DI$3) -> 0 | DJ7: =STDEV(DJ$3:DJ$3) -> 0 | DK7: =STDEV(DK$3:DK$3) -> 0 | DM7: =STDEV(DM$3:DM$3) -> 0 | DN7: =STDEV(DN$3:DN$3) -> 0 | DO7: =STDEV(DO$3:DO$3) -> 0 | DP7: =STDEV(DP$3:DP$3) -> 0 | DQ7: =STDEV(DQ$3:DQ$3) -> 0 | DR7: =STDEV(DR$3:DR$3) -> 0 | DT7: =STDEV(DT$3:DT$3) -> 0 | DU7: =STDEV(DU$3:DU$3) -> 0 | DV7: =STDEV(DV$3:DV$3) -> 0 | DW7: =STDEV(DW$3:DW$3) -> 0 | DX7: =STDEV(DX$3:DX$3) -> 0 | DY7: =STDEV(DY$3:DY$3) -> 0 | EA7: =STDEV(EA$3:EA$3) -> 0 | EB7: =STDEV(EB$3:EB$3) -> 0 | EC7: =STDEV(EC$3:EC$3) -> 0 | ED7: =STDEV(ED$3:ED$3) -> 0 | EE7: =STDEV(EE$3:EE$3) -> 0 | EF7: =STDEV(EF$3:EF$3) -> 0 | EH7: =STDEV(EH$3:EH$3) -> 0 | EI7: =STDEV(EI$3:EI$3) -> 0 | EJ7: =STDEV(EJ$3:EJ$3) -> 0 | EK7: =STDEV(EK$3:EK$3) -> 0 | EL7: =STDEV(EL$3:EL$3) -> 0 | EM7: =STDEV(EM$3:EM$3) -> 0 | EO7: =STDEV(EO$3:EO$3) -> 0 | EP7: =STDEV(EP$3:EP$3) -> 0 | EQ7: =STDEV(EQ$3:EQ$3) -> 0 | ER7: =STDEV(ER$3:ER$3) -> 0 | ES7: =STDEV(ES$3:ES$3) -> 0 | ET7: =STDEV(ET$3:ET$3) -> 0 | EV7: =STDEV(EV$3:EV$3) -> 0 | EW7: =STDEV(EW$3:EW$3) -> 0 | EX7: =STDEV(EX$3:EX$3) -> 0 | EY7: =STDEV(EY$3:EY$3) -> 0 | EZ7: =STDEV(EZ$3:EZ$3) -> 0 | FA7: =STDEV(FA$3:FA$3) -> 0 | FC7: =STDEV(FC$3:FC$3) -> 0 | FD7: =STDEV(FD$3:FD$3) -> 0 | FE7: =STDEV(FE$3:FE$3) -> 0 | FF7: =STDEV(FF$3:FF$3) -> 0 | FG7: =STDEV(FG$3:FG$3) -> 0 | FH7: =STDEV(FH$3:FH$3) -> 0 | FJ7: =STDEV(FJ$3:FJ$3) -> 0 | FK7: =STDEV(FK$3:FK$3) -> 0 | FL7: =STDEV(FL$3:FL$3) -> 0 | FM7: =STDEV(FM$3:FM$3) -> 0 | FN7: =STDEV(FN$3:FN$3) -> 0 | FO7: =STDEV(FO$3:FO$3) -> 0 | FQ7: =STDEV(FQ$3:FQ$3) -> 0 | FR7: =STDEV(FR$3:FR$3) -> 0 | FS7: =STDEV(FS$3:FS$3) -> 0 | FT7: =STDEV(FT$3:FT$3) -> 0 | FU7: =STDEV(FU$3:FU$3) -> 0 | FV7: =STDEV(FV$3:FV$3) -> 0 | FX7: =STDEV(FX$3:FX$3) -> 0 | FY7: =STDEV(FY$3:FY$3) -> 0 | FZ7: =STDEV(FZ$3:FZ$3) -> 0 | GA7: =STDEV(GA$3:GA$3) -> 0 | GB7: =STDEV(GB$3:GB$3) -> 0 | GC7: =STDEV(GC$3:GC$3) -> 0 | GE7: =STDEV(GE$3:GE$3) -> 0 | GF7: =STDEV(GF$3:GF$3) -> 0 | GG7: =STDEV(GG$3:GG$3) -> 0 | GH7: =STDEV(GH$3:GH$3) -> 0 | GI7: =STDEV(GI$3:GI$3) -> 0 | GJ7: =STDEV(GJ$3:GJ$3) -> 0 | GK7: =STDEV(GK$3:GK$3) -> 0 | GL7: =STDEV(GL$3:GL$3) -> 0 | ... GZ7: =STDEV(GZ$3:GZ$3) -> 0
A8: DST | B8: =SUMPRODUCT(--(B$3:B$3-$GI$3:$GI$3)^2)^0.5 -> 0 | C8: =SUMPRODUCT(--(C$3:C$3-$GJ$3:$GJ$3)^2)^0.5 -> 0 | E8: =SUMPRODUCT(--(E$3:E$3-$GK$3:$GK$3)^2)^0.5 -> 0 | F8: =SUMPRODUCT(--(F$3:F$3-$GL$3:$GL$3)^2)^0.5 -> 0 | G8: =SUMPRODUCT(--(G$3:G$3-$GM$3:$GM$3)^2)^0.5 -> 0 | H8: =SUMPRODUCT(--(H$3:H$3-$GN$3:$GN$3)^2)^0.5 -> 0 | I8: =SUMPRODUCT(--(I$3:I$3-$GI$3:$GI$3)^2)^0.5 -> 0 | J8: =SUMPRODUCT(--(J$3:J$3-$GJ$3:$GJ$3)^2)^0.5 -> 0 | L8: =SUMPRODUCT(--(L$3:L$3-$GK$3:$GK$3)^2)^0.5 -> 0 | M8: =SUMPRODUCT(--(M$3:M$3-$GL$3:$GL$3)^2)^0.5 -> 0 | N8: =SUMPRODUCT(--(N$3:N$3-$GM$3:$GM$3)^2)^0.5 -> 0 | O8: =SUMPRODUCT(--(O$3:O$3-$GN$3:$GN$3)^2)^0.5 -> 0 | P8: =SUMPRODUCT(--(P$3:P$3-$GI$3:$GI$3)^2)^0.5 -> 0 | Q8: =SUMPRODUCT(--(Q$3:Q$3-$GJ$3:$GJ$3)^2)^0.5 -> 0 | S8: =SUMPRODUCT(--(S$3:S$3-$GK$3:$GK$3)^2)^0.5 -> 0 | T8: =SUMPRODUCT(--(T$3:T$3-$GL$3:$GL$3)^2)^0.5 -> 0 | U8: =SUMPRODUCT(--(U$3:U$3-$GM$3:$GM$3)^2)^0.5 -> 0 | V8: =SUMPRODUCT(--(V$3:V$3-$GN$3:$GN$3)^2)^0.5 -> 0 | W8: =SUMPRODUCT(--(W$3:W$3-$GI$3:$GI$3)^2)^0.5 -> 0 | X8: =SUMPRODUCT(--(X$3:X$3-$GJ$3:$GJ$3)^2)^0.5 -> 0 | Z8: =SUMPRODUCT(--(Z$3:Z$3-$GK$3:$GK$3)^2)^0.5 -> 0 | AA8: =SUMPRODUCT(--(AA$3:AA$3-$GL$3:$GL$3)^2)^0.5 -> 0 | AB8: =SUMPRODUCT(--(AB$3:AB$3-$GM$3:$GM$3)^2)^0.5 -> 0 | AC8: =SUMPRODUCT(--(AC$3:AC$3-$GN$3:$GN$3)^2)^0.5 -> 0 | AD8: =SUMPRODUCT(--(AD$3:AD$3-$GI$3:$GI$3)^2)^0.5 -> 0 | AE8: =SUMPRODUCT(--(AE$3:AE$3-$GJ$3:$GJ$3)^2)^0.5 -> 0 | AG8: =SUMPRODUCT(--(AG$3:AG$3-$GK$3:$GK$3)^2)^0.5 -> 0 | AH8: =SUMPRODUCT(--(AH$3:AH$3-$GL$3:$GL$3)^2)^0.5 -> 0 | AI8: =SUMPRODUCT(--(AI$3:AI$3-$GM$3:$GM$3)^2)^0.5 -> 0 | AJ8: =SUMPRODUCT(--(AJ$3:AJ$3-$GN$3:$GN$3)^2)^0.5 -> 0 | AK8: =SUMPRODUCT(--(AK$3:AK$3-$GI$3:$GI$3)^2)^0.5 -> 0 | AL8: =SUMPRODUCT(--(AL$3:AL$3-$GJ$3:$GJ$3)^2)^0.5 -> 0 | AN8: =SUMPRODUCT(--(AN$3:AN$3-$GK$3:$GK$3)^2)^0.5 -> 0 | AO8: =SUMPRODUCT(--(AO$3:AO$3-$GL$3:$GL$3)^2)^0.5 -> 0 | AP8: =SUMPRODUCT(--(AP$3:AP$3-$GM$3:$GM$3)^2)^0.5 -> 0 | AQ8: =SUMPRODUCT(--(AQ$3:AQ$3-$GN$3:$GN$3)^2)^0.5 -> 0 | AR8: =SUMPRODUCT(--(AR$3:AR$3-$GI$3:$GI$3)^2)^0.5 -> 0 | AS8: =SUMPRODUCT(--(AS$3:AS$3-$GJ$3:$GJ$3)^2)^0.5 -> 0 | AU8: =SUMPRODUCT(--(AU$3:AU$3-$GK$3:$GK$3)^2)^0.5 -> 0 | AV8: =SUMPRODUCT(--(AV$3:AV$3-$GL$3:$GL$3)^2)^0.5 -> 0 | AW8: =SUMPRODUCT(--(AW$3:AW$3-$GM$3:$GM$3)^2)^0.5 -> 0 | AX8: =SUMPRODUCT(--(AX$3:AX$3-$GN$3:$GN$3)^2)^0.5 -> 0 | AY8: =SUMPRODUCT(--(AY$3:AY$3-$GI$3:$GI$3)^2)^0.5 -> 0 | AZ8: =SUMPRODUCT(--(AZ$3:AZ$3-$GJ$3:$GJ$3)^2)^0.5 -> 0 | BB8: =SUMPRODUCT(--(BB$3:BB$3-$GK$3:$GK$3)^2)^0.5 -> 0 | BC8: =SUMPRODUCT(--(BC$3:BC$3-$GL$3:$GL$3)^2)^0.5 -> 0 | BD8: =SUMPRODUCT(--(BD$3:BD$3-$GM$3:$GM$3)^2)^0.5 -> 0 | BE8: =SUMPRODUCT(--(BE$3:BE$3-$GN$3:$GN$3)^2)^0.5 -> 0 | BF8: =SUMPRODUCT(--(BF$3:BF$3-$GI$3:$GI$3)^2)^0.5 -> 0 | BG8: =SUMPRODUCT(--(BG$3:BG$3-$GJ$3:$GJ$3)^2)^0.5 -> 0 | BI8: =SUMPRODUCT(--(BI$3:BI$3-$GK$3:$GK$3)^2)^0.5 -> 0 | BJ8: =SUMPRODUCT(--(BJ$3:BJ$3-$GL$3:$GL$3)^2)^0.5 -> 0 | BK8: =SUMPRODUCT(--(BK$3:BK$3-$GM$3:$GM$3)^2)^0.5 -> 0 | BL8: =SUMPRODUCT(--(BL$3:BL$3-$GN$3:$GN$3)^2)^0.5 -> 0 | BM8: =SUMPRODUCT(--(BM$3:BM$3-$GI$3:$GI$3)^2)^0.5 -> 0 | BN8: =SUMPRODUCT(--(BN$3:BN$3-$GJ$3:$GJ$3)^2)^0.5 -> 0 | BP8: =SUMPRODUCT(--(BP$3:BP$3-$GK$3:$GK$3)^2)^0.5 -> 0 | BQ8: =SUMPRODUCT(--(BQ$3:BQ$3-$GL$3:$GL$3)^2)^0.5 -> 0 | BR8: =SUMPRODUCT(--(BR$3:BR$3-$GM$3:$GM$3)^2)^0.5 -> 0 | BS8: =SUMPRODUCT(--(BS$3:BS$3-$GN$3:$GN$3)^2)^0.5 -> 0 | BT8: =SUMPRODUCT(--(BT$3:BT$3-$GI$3:$GI$3)^2)^0.5 -> 0 | BU8: =SUMPRODUCT(--(BU$3:BU$3-$GJ$3:$GJ$3)^2)^0.5 -> 0 | BW8: =SUMPRODUCT(--(BW$3:BW$3-$GK$3:$GK$3)^2)^0.5 -> 0 | BX8: =SUMPRODUCT(--(BX$3:BX$3-$GL$3:$GL$3)^2)^0.5 -> 0 | BY8: =SUMPRODUCT(--(BY$3:BY$3-$GM$3:$GM$3)^2)^0.5 -> 0 | BZ8: =SUMPRODUCT(--(BZ$3:BZ$3-$GN$3:$GN$3)^2)^0.5 -> 0 | CA8: =SUMPRODUCT(--(CA$3:CA$3-$GI$3:$GI$3)^2)^0.5 -> 0 | CB8: =SUMPRODUCT(--(CB$3:CB$3-$GJ$3:$GJ$3)^2)^0.5 -> 0 | CD8: =SUMPRODUCT(--(CD$3:CD$3-$GK$3:$GK$3)^2)^0.5 -> 0 | CE8: =SUMPRODUCT(--(CE$3:CE$3-$GL$3:$GL$3)^2)^0.5 -> 0 | CF8: =SUMPRODUCT(--(CF$3:CF$3-$GM$3:$GM$3)^2)^0.5 -> 0 | CG8: =SUMPRODUCT(--(CG$3:CG$3-$GN$3:$GN$3)^2)^0.5 -> 0 | CH8: =SUMPRODUCT(--(CH$3:CH$3-$GI$3:$GI$3)^2)^0.5 -> 0 | CI8: =SUMPRODUCT(--(CI$3:CI$3-$GJ$3:$GJ$3)^2)^0.5 -> 0 | CK8: =SUMPRODUCT(--(CK$3:CK$3-$GK$3:$GK$3)^2)^0.5 -> 0 | CL8: =SUMPRODUCT(--(CL$3:CL$3-$GL$3:$GL$3)^2)^0.5 -> 0 | CM8: =SUMPRODUCT(--(CM$3:CM$3-$GM$3:$GM$3)^2)^0.5 -> 0 | CN8: =SUMPRODUCT(--(CN$3:CN$3-$GN$3:$GN$3)^2)^0.5 -> 0 | CO8: =SUMPRODUCT(--(CO$3:CO$3-$GI$3:$GI$3)^2)^0.5 -> 0 | CP8: =SUMPRODUCT(--(CP$3:CP$3-$GJ$3:$GJ$3)^2)^0.5 -> 0 | CR8: =SUMPRODUCT(--(CR$3:CR$3-$GK$3:$GK$3)^2)^0.5 -> 0 | CS8: =SUMPRODUCT(--(CS$3:CS$3-$GL$3:$GL$3)^2)^0.5 -> 0 | CT8: =SUMPRODUCT(--(CT$3:CT$3-$GM$3:$GM$3)^2)^0.5 -> 0 | CU8: =SUMPRODUCT(--(CU$3:CU$3-$GN$3:$GN$3)^2)^0.5 -> 0 | CV8: =SUMPRODUCT(--(CV$3:CV$3-$GI$3:$GI$3)^2)^0.5 -> 0 | CW8: =SUMPRODUCT(--(CW$3:CW$3-$GJ$3:$GJ$3)^2)^0.5 -> 0 | CY8: =SUMPRODUCT(--(CY$3:CY$3-$GK$3:$GK$3)^2)^0.5 -> 0 | CZ8: =SUMPRODUCT(--(CZ$3:CZ$3-$GL$3:$GL$3)^2)^0.5 -> 0 | DA8: =SUMPRODUCT(--(DA$3:DA$3-$GM$3:$GM$3)^2)^0.5 -> 0 | DB8: =SUMPRODUCT(--(DB$3:DB$3-$GN$3:$GN$3)^2)^0.5 -> 0 | DC8: =SUMPRODUCT(--(DC$3:DC$3-$GI$3:$GI$3)^2)^0.5 -> 0 | DD8: =SUMPRODUCT(--(DD$3:DD$3-$GJ$3:$GJ$3)^2)^0.5 -> 0 | DF8: =SUMPRODUCT(--(DF$3:DF$3-$GK$3:$GK$3)^2)^0.5 -> 0 | DG8: =SUMPRODUCT(--(DG$3:DG$3-$GL$3:$GL$3)^2)^0.5 -> 0 | DH8: =SUMPRODUCT(--(DH$3:DH$3-$GM$3:$GM$3)^2)^0.5 -> 0 | DI8: =SUMPRODUCT(--(DI$3:DI$3-$GN$3:$GN$3)^2)^0.5 -> 0 | DJ8: =SUMPRODUCT(--(DJ$3:DJ$3-$GI$3:$GI$3)^2)^0.5 -> 0 | DK8: =SUMPRODUCT(--(DK$3:DK$3-$GJ$3:$GJ$3)^2)^0.5 -> 0 | DM8: =SUMPRODUCT(--(DM$3:DM$3-$GK$3:$GK$3)^2)^0.5 -> 0 | DN8: =SUMPRODUCT(--(DN$3:DN$3-$GL$3:$GL$3)^2)^0.5 -> 0 | DO8: =SUMPRODUCT(--(DO$3:DO$3-$GM$3:$GM$3)^2)^0.5 -> 0 | DP8: =SUMPRODUCT(--(DP$3:DP$3-$GN$3:$GN$3)^2)^0.5 -> 0 | DQ8: =SUMPRODUCT(--(DQ$3:DQ$3-$GI$3:$GI$3)^2)^0.5 -> 0 | DR8: =SUMPRODUCT(--(DR$3:DR$3-$GJ$3:$GJ$3)^2)^0.5 -> 0 | DT8: =SUMPRODUCT(--(DT$3:DT$3-$GK$3:$GK$3)^2)^0.5 -> 0 | DU8: =SUMPRODUCT(--(DU$3:DU$3-$GL$3:$GL$3)^2)^0.5 -> 0 | DV8: =SUMPRODUCT(--(DV$3:DV$3-$GM$3:$GM$3)^2)^0.5 -> 0 | DW8: =SUMPRODUCT(--(DW$3:DW$3-$GN$3:$GN$3)^2)^0.5 -> 0 | DX8: =SUMPRODUCT(--(DX$3:DX$3-$GI$3:$GI$3)^2)^0.5 -> 0 | DY8: =SUMPRODUCT(--(DY$3:DY$3-$GJ$3:$GJ$3)^2)^0.5 -> 0 | EA8: =SUMPRODUCT(--(EA$3:EA$3-$GK$3:$GK$3)^2)^0.5 -> 0 | EB8: =SUMPRODUCT(--(EB$3:EB$3-$GL$3:$GL$3)^2)^0.5 -> 0 | EC8: =SUMPRODUCT(--(EC$3:EC$3-$GM$3:$GM$3)^2)^0.5 -> 0 | ED8: =SUMPRODUCT(--(ED$3:ED$3-$GN$3:$GN$3)^2)^0.5 -> 0 | EE8: =SUMPRODUCT(--(EE$3:EE$3-$GI$3:$GI$3)^2)^0.5 -> 0 | EF8: =SUMPRODUCT(--(EF$3:EF$3-$GJ$3:$GJ$3)^2)^0.5 -> 0 | EH8: =SUMPRODUCT(--(EH$3:EH$3-$GK$3:$GK$3)^2)^0.5 -> 0 | EI8: =SUMPRODUCT(--(EI$3:EI$3-$GL$3:$GL$3)^2)^0.5 -> 0 | EJ8: =SUMPRODUCT(--(EJ$3:EJ$3-$GM$3:$GM$3)^2)^0.5 -> 0 | EK8: =SUMPRODUCT(--(EK$3:EK$3-$GN$3:$GN$3)^2)^0.5 -> 0 | EL8: =SUMPRODUCT(--(EL$3:EL$3-$GI$3:$GI$3)^2)^0.5 -> 0 | EM8: =SUMPRODUCT(--(EM$3:EM$3-$GJ$3:$GJ$3)^2)^0.5 -> 0 | EO8: =SUMPRODUCT(--(EO$3:EO$3-$GK$3:$GK$3)^2)^0.5 -> 0 | EP8: =SUMPRODUCT(--(EP$3:EP$3-$GL$3:$GL$3)^2)^0.5 -> 0 | EQ8: =SUMPRODUCT(--(EQ$3:EQ$3-$GM$3:$GM$3)^2)^0.5 -> 0 | ER8: =SUMPRODUCT(--(ER$3:ER$3-$GN$3:$GN$3)^2)^0.5 -> 0 | ES8: =SUMPRODUCT(--(ES$3:ES$3-$GI$3:$GI$3)^2)^0.5 -> 0 | ET8: =SUMPRODUCT(--(ET$3:ET$3-$GJ$3:$GJ$3)^2)^0.5 -> 0 | EV8: =SUMPRODUCT(--(EV$3:EV$3-$GK$3:$GK$3)^2)^0.5 -> 0 | EW8: =SUMPRODUCT(--(EW$3:EW$3-$GL$3:$GL$3)^2)^0.5 -> 0 | EX8: =SUMPRODUCT(--(EX$3:EX$3-$GM$3:$GM$3)^2)^0.5 -> 0 | EY8: =SUMPRODUCT(--(EY$3:EY$3-$GN$3:$GN$3)^2)^0.5 -> 0 | EZ8: =SUMPRODUCT(--(EZ$3:EZ$3-$GI$3:$GI$3)^2)^0.5 -> 0 | FA8: =SUMPRODUCT(--(FA$3:FA$3-$GJ$3:$GJ$3)^2)^0.5 -> 0 | FC8: =SUMPRODUCT(--(FC$3:FC$3-$GK$3:$GK$3)^2)^0.5 -> 0 | FD8: =SUMPRODUCT(--(FD$3:FD$3-$GL$3:$GL$3)^2)^0.5 -> 0 | FE8: =SUMPRODUCT(--(FE$3:FE$3-$GM$3:$GM$3)^2)^0.5 -> 0 | FF8: =SUMPRODUCT(--(FF$3:FF$3-$GN$3:$GN$3)^2)^0.5 -> 0 | FG8: =SUMPRODUCT(--(FG$3:FG$3-$GI$3:$GI$3)^2)^0.5 -> 0 | FH8: =SUMPRODUCT(--(FH$3:FH$3-$GJ$3:$GJ$3)^2)^0.5 -> 0 | FJ8: =SUMPRODUCT(--(FJ$3:FJ$3-$GK$3:$GK$3)^2)^0.5 -> 0 | FK8: =SUMPRODUCT(--(FK$3:FK$3-$GL$3:$GL$3)^2)^0.5 -> 0 | FL8: =SUMPRODUCT(--(FL$3:FL$3-$GM$3:$GM$3)^2)^0.5 -> 0 | FM8: =SUMPRODUCT(--(FM$3:FM$3-$GN$3:$GN$3)^2)^0.5 -> 0 | FN8: =SUMPRODUCT(--(FN$3:FN$3-$GI$3:$GI$3)^2)^0.5 -> 0 | FO8: =SUMPRODUCT(--(FO$3:FO$3-$GJ$3:$GJ$3)^2)^0.5 -> 0 | FQ8: =SUMPRODUCT(--(FQ$3:FQ$3-$GK$3:$GK$3)^2)^0.5 -> 0 | FR8: =SUMPRODUCT(--(FR$3:FR$3-$GL$3:$GL$3)^2)^0.5 -> 0 | FS8: =SUMPRODUCT(--(FS$3:FS$3-$GM$3:$GM$3)^2)^0.5 -> 0 | FT8: =SUMPRODUCT(--(FT$3:FT$3-$GN$3:$GN$3)^2)^0.5 -> 0 | FU8: =SUMPRODUCT(--(FU$3:FU$3-$GI$3:$GI$3)^2)^0.5 -> 0 | FV8: =SUMPRODUCT(--(FV$3:FV$3-$GJ$3:$GJ$3)^2)^0.5 -> 0 | FX8: =SUMPRODUCT(--(FX$3:FX$3-$GK$3:$GK$3)^2)^0.5 -> 0 | FY8: =SUMPRODUCT(--(FY$3:FY$3-$GL$3:$GL$3)^2)^0.5 -> 0 | FZ8: =SUMPRODUCT(--(FZ$3:FZ$3-$GM$3:$GM$3)^2)^0.5 -> 0 | GA8: =SUMPRODUCT(--(GA$3:GA$3-$GN$3:$GN$3)^2)^0.5 -> 0 | GB8: =SUMPRODUCT(--(GB$3:GB$3-$GI$3:$GI$3)^2)^0.5 -> 0 | GC8: =SUMPRODUCT(--(GC$3:GC$3-$GJ$3:$GJ$3)^2)^0.5 -> 0 | GE8: =SUMPRODUCT(--(GE$3:GE$3-$GK$3:$GK$3)^2)^0.5 -> 0 | GF8: =SUMPRODUCT(--(GF$3:GF$3-$GL$3:$GL$3)^2)^0.5 -> 0 | GG8: =SUMPRODUCT(--(GG$3:GG$3-$GM$3:$GM$3)^2)^0.5 -> 0 | GH8: =SUMPRODUCT(--(GH$3:GH$3-$GN$3:$GN$3)^2)^0.5 -> 0
A9: BEST | B9: =SUMPRODUCT(NOT(ISBLANK(B$3:B$3))*(B$3:B$3=$GI$3:$GI$3)) -> 0 | C9: =SUMPRODUCT(NOT(ISBLANK(C$3:C$3))*(C$3:C$3=$GJ$3:$GJ$3)) -> 0 | E9: =SUMPRODUCT(NOT(ISBLANK(E$3:E$3))*(E$3:E$3=$GK$3:$GK$3)) -> 0 | F9: =SUMPRODUCT(NOT(ISBLANK(F$3:F$3))*(F$3:F$3=$GL$3:$GL$3)) -> 0 | G9: =SUMPRODUCT(NOT(ISBLANK(G$3:G$3))*(G$3:G$3=$GM$3:$GM$3)) -> 0 | H9: =SUMPRODUCT(NOT(ISBLANK(H$3:H$3))*(H$3:H$3=$GN$3:$GN$3)) -> 0 | I9: =SUMPRODUCT(NOT(ISBLANK(I$3:I$3))*(I$3:I$3=$GI$3:$GI$3)) -> 0 | J9: =SUMPRODUCT(NOT(ISBLANK(J$3:J$3))*(J$3:J$3=$GJ$3:$GJ$3)) -> 0 | L9: =SUMPRODUCT(NOT(ISBLANK(L$3:L$3))*(L$3:L$3=$GK$3:$GK$3)) -> 0 | M9: =SUMPRODUCT(NOT(ISBLANK(M$3:M$3))*(M$3:M$3=$GL$3:$GL$3)) -> 0 | N9: =SUMPRODUCT(NOT(ISBLANK(N$3:N$3))*(N$3:N$3=$GM$3:$GM$3)) -> 0 | O9: =SUMPRODUCT(NOT(ISBLANK(O$3:O$3))*(O$3:O$3=$GN$3:$GN$3)) -> 0 | P9: =SUMPRODUCT(NOT(ISBLANK(P$3:P$3))*(P$3:P$3=$GI$3:$GI$3)) -> 0 | Q9: =SUMPRODUCT(NOT(ISBLANK(Q$3:Q$3))*(Q$3:Q$3=$GJ$3:$GJ$3)) -> 0 | S9: =SUMPRODUCT(NOT(ISBLANK(S$3:S$3))*(S$3:S$3=$GK$3:$GK$3)) -> 0 | T9: =SUMPRODUCT(NOT(ISBLANK(T$3:T$3))*(T$3:T$3=$GL$3:$GL$3)) -> 0 | U9: =SUMPRODUCT(NOT(ISBLANK(U$3:U$3))*(U$3:U$3=$GM$3:$GM$3)) -> 0 | V9: =SUMPRODUCT(NOT(ISBLANK(V$3:V$3))*(V$3:V$3=$GN$3:$GN$3)) -> 0 | W9: =SUMPRODUCT(NOT(ISBLANK(W$3:W$3))*(W$3:W$3=$GI$3:$GI$3)) -> 0 | X9: =SUMPRODUCT(NOT(ISBLANK(X$3:X$3))*(X$3:X$3=$GJ$3:$GJ$3)) -> 0 | Z9: =SUMPRODUCT(NOT(ISBLANK(Z$3:Z$3))*(Z$3:Z$3=$GK$3:$GK$3)) -> 0 | AA9: =SUMPRODUCT(NOT(ISBLANK(AA$3:AA$3))*(AA$3:AA$3=$GL$3:$GL$3)) -> 0 | AB9: =SUMPRODUCT(NOT(ISBLANK(AB$3:AB$3))*(AB$3:AB$3=$GM$3:$GM$3)) -> 0 | AC9: =SUMPRODUCT(NOT(ISBLANK(AC$3:AC$3))*(AC$3:AC$3=$GN$3:$GN$3)) -> 0 | AD9: =SUMPRODUCT(NOT(ISBLANK(AD$3:AD$3))*(AD$3:AD$3=$GI$3:$GI$3)) -> 0 | AE9: =SUMPRODUCT(NOT(ISBLANK(AE$3:AE$3))*(AE$3:AE$3=$GJ$3:$GJ$3)) -> 0 | AG9: =SUMPRODUCT(NOT(ISBLANK(AG$3:AG$3))*(AG$3:AG$3=$GK$3:$GK$3)) -> 0 | AH9: =SUMPRODUCT(NOT(ISBLANK(AH$3:AH$3))*(AH$3:AH$3=$GL$3:$GL$3)) -> 0 | AI9: =SUMPRODUCT(NOT(ISBLANK(AI$3:AI$3))*(AI$3:AI$3=$GM$3:$GM$3)) -> 0 | AJ9: =SUMPRODUCT(NOT(ISBLANK(AJ$3:AJ$3))*(AJ$3:AJ$3=$GN$3:$GN$3)) -> 0 | AK9: =SUMPRODUCT(NOT(ISBLANK(AK$3:AK$3))*(AK$3:AK$3=$GI$3:$GI$3)) -> 0 | AL9: =SUMPRODUCT(NOT(ISBLANK(AL$3:AL$3))*(AL$3:AL$3=$GJ$3:$GJ$3)) -> 0 | AN9: =SUMPRODUCT(NOT(ISBLANK(AN$3:AN$3))*(AN$3:AN$3=$GK$3:$GK$3)) -> 0 | AO9: =SUMPRODUCT(NOT(ISBLANK(AO$3:AO$3))*(AO$3:AO$3=$GL$3:$GL$3)) -> 0 | AP9: =SUMPRODUCT(NOT(ISBLANK(AP$3:AP$3))*(AP$3:AP$3=$GM$3:$GM$3)) -> 0 | AQ9: =SUMPRODUCT(NOT(ISBLANK(AQ$3:AQ$3))*(AQ$3:AQ$3=$GN$3:$GN$3)) -> 0 | AR9: =SUMPRODUCT(NOT(ISBLANK(AR$3:AR$3))*(AR$3:AR$3=$GI$3:$GI$3)) -> 0 | AS9: =SUMPRODUCT(NOT(ISBLANK(AS$3:AS$3))*(AS$3:AS$3=$GJ$3:$GJ$3)) -> 0 | AU9: =SUMPRODUCT(NOT(ISBLANK(AU$3:AU$3))*(AU$3:AU$3=$GK$3:$GK$3)) -> 0 | AV9: =SUMPRODUCT(NOT(ISBLANK(AV$3:AV$3))*(AV$3:AV$3=$GL$3:$GL$3)) -> 0 | AW9: =SUMPRODUCT(NOT(ISBLANK(AW$3:AW$3))*(AW$3:AW$3=$GM$3:$GM$3)) -> 0 | AX9: =SUMPRODUCT(NOT(ISBLANK(AX$3:AX$3))*(AX$3:AX$3=$GN$3:$GN$3)) -> 0 | AY9: =SUMPRODUCT(NOT(ISBLANK(AY$3:AY$3))*(AY$3:AY$3=$GI$3:$GI$3)) -> 0 | AZ9: =SUMPRODUCT(NOT(ISBLANK(AZ$3:AZ$3))*(AZ$3:AZ$3=$GJ$3:$GJ$3)) -> 0 | BB9: =SUMPRODUCT(NOT(ISBLANK(BB$3:BB$3))*(BB$3:BB$3=$GK$3:$GK$3)) -> 0 | BC9: =SUMPRODUCT(NOT(ISBLANK(BC$3:BC$3))*(BC$3:BC$3=$GL$3:$GL$3)) -> 0 | BD9: =SUMPRODUCT(NOT(ISBLANK(BD$3:BD$3))*(BD$3:BD$3=$GM$3:$GM$3)) -> 0 | BE9: =SUMPRODUCT(NOT(ISBLANK(BE$3:BE$3))*(BE$3:BE$3=$GN$3:$GN$3)) -> 0 | BF9: =SUMPRODUCT(NOT(ISBLANK(BF$3:BF$3))*(BF$3:BF$3=$GI$3:$GI$3)) -> 0 | BG9: =SUMPRODUCT(NOT(ISBLANK(BG$3:BG$3))*(BG$3:BG$3=$GJ$3:$GJ$3)) -> 0 | BI9: =SUMPRODUCT(NOT(ISBLANK(BI$3:BI$3))*(BI$3:BI$3=$GK$3:$GK$3)) -> 0 | BJ9: =SUMPRODUCT(NOT(ISBLANK(BJ$3:BJ$3))*(BJ$3:BJ$3=$GL$3:$GL$3)) -> 0 | BK9: =SUMPRODUCT(NOT(ISBLANK(BK$3:BK$3))*(BK$3:BK$3=$GM$3:$GM$3)) -> 0 | BL9: =SUMPRODUCT(NOT(ISBLANK(BL$3:BL$3))*(BL$3:BL$3=$GN$3:$GN$3)) -> 0 | BM9: =SUMPRODUCT(NOT(ISBLANK(BM$3:BM$3))*(BM$3:BM$3=$GI$3:$GI$3)) -> 0 | BN9: =SUMPRODUCT(NOT(ISBLANK(BN$3:BN$3))*(BN$3:BN$3=$GJ$3:$GJ$3)) -> 0 | BP9: =SUMPRODUCT(NOT(ISBLANK(BP$3:BP$3))*(BP$3:BP$3=$GK$3:$GK$3)) -> 0 | BQ9: =SUMPRODUCT(NOT(ISBLANK(BQ$3:BQ$3))*(BQ$3:BQ$3=$GL$3:$GL$3)) -> 0 | BR9: =SUMPRODUCT(NOT(ISBLANK(BR$3:BR$3))*(BR$3:BR$3=$GM$3:$GM$3)) -> 0 | BS9: =SUMPRODUCT(NOT(ISBLANK(BS$3:BS$3))*(BS$3:BS$3=$GN$3:$GN$3)) -> 0 | BT9: =SUMPRODUCT(NOT(ISBLANK(BT$3:BT$3))*(BT$3:BT$3=$GI$3:$GI$3)) -> 0 | BU9: =SUMPRODUCT(NOT(ISBLANK(BU$3:BU$3))*(BU$3:BU$3=$GJ$3:$GJ$3)) -> 0 | BW9: =SUMPRODUCT(NOT(ISBLANK(BW$3:BW$3))*(BW$3:BW$3=$GK$3:$GK$3)) -> 0 | BX9: =SUMPRODUCT(NOT(ISBLANK(BX$3:BX$3))*(BX$3:BX$3=$GL$3:$GL$3)) -> 0 | BY9: =SUMPRODUCT(NOT(ISBLANK(BY$3:BY$3))*(BY$3:BY$3=$GM$3:$GM$3)) -> 0 | BZ9: =SUMPRODUCT(NOT(ISBLANK(BZ$3:BZ$3))*(BZ$3:BZ$3=$GN$3:$GN$3)) -> 0 | CA9: =SUMPRODUCT(NOT(ISBLANK(CA$3:CA$3))*(CA$3:CA$3=$GI$3:$GI$3)) -> 0 | CB9: =SUMPRODUCT(NOT(ISBLANK(CB$3:CB$3))*(CB$3:CB$3=$GJ$3:$GJ$3)) -> 0 | CD9: =SUMPRODUCT(NOT(ISBLANK(CD$3:CD$3))*(CD$3:CD$3=$GK$3:$GK$3)) -> 0 | CE9: =SUMPRODUCT(NOT(ISBLANK(CE$3:CE$3))*(CE$3:CE$3=$GL$3:$GL$3)) -> 0 | CF9: =SUMPRODUCT(NOT(ISBLANK(CF$3:CF$3))*(CF$3:CF$3=$GM$3:$GM$3)) -> 0 | CG9: =SUMPRODUCT(NOT(ISBLANK(CG$3:CG$3))*(CG$3:CG$3=$GN$3:$GN$3)) -> 0 | CH9: =SUMPRODUCT(NOT(ISBLANK(CH$3:CH$3))*(CH$3:CH$3=$GI$3:$GI$3)) -> 0 | CI9: =SUMPRODUCT(NOT(ISBLANK(CI$3:CI$3))*(CI$3:CI$3=$GJ$3:$GJ$3)) -> 0 | CK9: =SUMPRODUCT(NOT(ISBLANK(CK$3:CK$3))*(CK$3:CK$3=$GK$3:$GK$3)) -> 0 | CL9: =SUMPRODUCT(NOT(ISBLANK(CL$3:CL$3))*(CL$3:CL$3=$GL$3:$GL$3)) -> 0 | CM9: =SUMPRODUCT(NOT(ISBLANK(CM$3:CM$3))*(CM$3:CM$3=$GM$3:$GM$3)) -> 0 | CN9: =SUMPRODUCT(NOT(ISBLANK(CN$3:CN$3))*(CN$3:CN$3=$GN$3:$GN$3)) -> 0 | CO9: =SUMPRODUCT(NOT(ISBLANK(CO$3:CO$3))*(CO$3:CO$3=$GI$3:$GI$3)) -> 0 | CP9: =SUMPRODUCT(NOT(ISBLANK(CP$3:CP$3))*(CP$3:CP$3=$GJ$3:$GJ$3)) -> 0 | CR9: =SUMPRODUCT(NOT(ISBLANK(CR$3:CR$3))*(CR$3:CR$3=$GK$3:$GK$3)) -> 0 | CS9: =SUMPRODUCT(NOT(ISBLANK(CS$3:CS$3))*(CS$3:CS$3=$GL$3:$GL$3)) -> 0 | CT9: =SUMPRODUCT(NOT(ISBLANK(CT$3:CT$3))*(CT$3:CT$3=$GM$3:$GM$3)) -> 0 | CU9: =SUMPRODUCT(NOT(ISBLANK(CU$3:CU$3))*(CU$3:CU$3=$GN$3:$GN$3)) -> 0 | CV9: =SUMPRODUCT(NOT(ISBLANK(CV$3:CV$3))*(CV$3:CV$3=$GI$3:$GI$3)) -> 0 | CW9: =SUMPRODUCT(NOT(ISBLANK(CW$3:CW$3))*(CW$3:CW$3=$GJ$3:$GJ$3)) -> 0 | CY9: =SUMPRODUCT(NOT(ISBLANK(CY$3:CY$3))*(CY$3:CY$3=$GK$3:$GK$3)) -> 0 | CZ9: =SUMPRODUCT(NOT(ISBLANK(CZ$3:CZ$3))*(CZ$3:CZ$3=$GL$3:$GL$3)) -> 0 | DA9: =SUMPRODUCT(NOT(ISBLANK(DA$3:DA$3))*(DA$3:DA$3=$GM$3:$GM$3)) -> 0 | DB9: =SUMPRODUCT(NOT(ISBLANK(DB$3:DB$3))*(DB$3:DB$3=$GN$3:$GN$3)) -> 0 | DC9: =SUMPRODUCT(NOT(ISBLANK(DC$3:DC$3))*(DC$3:DC$3=$GI$3:$GI$3)) -> 0 | DD9: =SUMPRODUCT(NOT(ISBLANK(DD$3:DD$3))*(DD$3:DD$3=$GJ$3:$GJ$3)) -> 0 | DF9: =SUMPRODUCT(NOT(ISBLANK(DF$3:DF$3))*(DF$3:DF$3=$GK$3:$GK$3)) -> 0 | DG9: =SUMPRODUCT(NOT(ISBLANK(DG$3:DG$3))*(DG$3:DG$3=$GL$3:$GL$3)) -> 0 | DH9: =SUMPRODUCT(NOT(ISBLANK(DH$3:DH$3))*(DH$3:DH$3=$GM$3:$GM$3)) -> 0 | DI9: =SUMPRODUCT(NOT(ISBLANK(DI$3:DI$3))*(DI$3:DI$3=$GN$3:$GN$3)) -> 0 | DJ9: =SUMPRODUCT(NOT(ISBLANK(DJ$3:DJ$3))*(DJ$3:DJ$3=$GI$3:$GI$3)) -> 0 | DK9: =SUMPRODUCT(NOT(ISBLANK(DK$3:DK$3))*(DK$3:DK$3=$GJ$3:$GJ$3)) -> 0 | DM9: =SUMPRODUCT(NOT(ISBLANK(DM$3:DM$3))*(DM$3:DM$3=$GK$3:$GK$3)) -> 0 | DN9: =SUMPRODUCT(NOT(ISBLANK(DN$3:DN$3))*(DN$3:DN$3=$GL$3:$GL$3)) -> 0 | DO9: =SUMPRODUCT(NOT(ISBLANK(DO$3:DO$3))*(DO$3:DO$3=$GM$3:$GM$3)) -> 0 | DP9: =SUMPRODUCT(NOT(ISBLANK(DP$3:DP$3))*(DP$3:DP$3=$GN$3:$GN$3)) -> 0 | DQ9: =SUMPRODUCT(NOT(ISBLANK(DQ$3:DQ$3))*(DQ$3:DQ$3=$GI$3:$GI$3)) -> 0 | DR9: =SUMPRODUCT(NOT(ISBLANK(DR$3:DR$3))*(DR$3:DR$3=$GJ$3:$GJ$3)) -> 0 | DT9: =SUMPRODUCT(NOT(ISBLANK(DT$3:DT$3))*(DT$3:DT$3=$GK$3:$GK$3)) -> 0 | DU9: =SUMPRODUCT(NOT(ISBLANK(DU$3:DU$3))*(DU$3:DU$3=$GL$3:$GL$3)) -> 0 | DV9: =SUMPRODUCT(NOT(ISBLANK(DV$3:DV$3))*(DV$3:DV$3=$GM$3:$GM$3)) -> 0 | DW9: =SUMPRODUCT(NOT(ISBLANK(DW$3:DW$3))*(DW$3:DW$3=$GN$3:$GN$3)) -> 0 | DX9: =SUMPRODUCT(NOT(ISBLANK(DX$3:DX$3))*(DX$3:DX$3=$GI$3:$GI$3)) -> 0 | DY9: =SUMPRODUCT(NOT(ISBLANK(DY$3:DY$3))*(DY$3:DY$3=$GJ$3:$GJ$3)) -> 0 | EA9: =SUMPRODUCT(NOT(ISBLANK(EA$3:EA$3))*(EA$3:EA$3=$GK$3:$GK$3)) -> 0 | EB9: =SUMPRODUCT(NOT(ISBLANK(EB$3:EB$3))*(EB$3:EB$3=$GL$3:$GL$3)) -> 0 | EC9: =SUMPRODUCT(NOT(ISBLANK(EC$3:EC$3))*(EC$3:EC$3=$GM$3:$GM$3)) -> 0 | ED9: =SUMPRODUCT(NOT(ISBLANK(ED$3:ED$3))*(ED$3:ED$3=$GN$3:$GN$3)) -> 0 | EE9: =SUMPRODUCT(NOT(ISBLANK(EE$3:EE$3))*(EE$3:EE$3=$GI$3:$GI$3)) -> 0 | EF9: =SUMPRODUCT(NOT(ISBLANK(EF$3:EF$3))*(EF$3:EF$3=$GJ$3:$GJ$3)) -> 0 | EH9: =SUMPRODUCT(NOT(ISBLANK(EH$3:EH$3))*(EH$3:EH$3=$GK$3:$GK$3)) -> 0 | EI9: =SUMPRODUCT(NOT(ISBLANK(EI$3:EI$3))*(EI$3:EI$3=$GL$3:$GL$3)) -> 0 | EJ9: =SUMPRODUCT(NOT(ISBLANK(EJ$3:EJ$3))*(EJ$3:EJ$3=$GM$3:$GM$3)) -> 0 | EK9: =SUMPRODUCT(NOT(ISBLANK(EK$3:EK$3))*(EK$3:EK$3=$GN$3:$GN$3)) -> 0 | EL9: =SUMPRODUCT(NOT(ISBLANK(EL$3:EL$3))*(EL$3:EL$3=$GI$3:$GI$3)) -> 0 | EM9: =SUMPRODUCT(NOT(ISBLANK(EM$3:EM$3))*(EM$3:EM$3=$GJ$3:$GJ$3)) -> 0 | EO9: =SUMPRODUCT(NOT(ISBLANK(EO$3:EO$3))*(EO$3:EO$3=$GK$3:$GK$3)) -> 0 | EP9: =SUMPRODUCT(NOT(ISBLANK(EP$3:EP$3))*(EP$3:EP$3=$GL$3:$GL$3)) -> 0 | EQ9: =SUMPRODUCT(NOT(ISBLANK(EQ$3:EQ$3))*(EQ$3:EQ$3=$GM$3:$GM$3)) -> 0 | ER9: =SUMPRODUCT(NOT(ISBLANK(ER$3:ER$3))*(ER$3:ER$3=$GN$3:$GN$3)) -> 0 | ES9: =SUMPRODUCT(NOT(ISBLANK(ES$3:ES$3))*(ES$3:ES$3=$GI$3:$GI$3)) -> 0 | ET9: =SUMPRODUCT(NOT(ISBLANK(ET$3:ET$3))*(ET$3:ET$3=$GJ$3:$GJ$3)) -> 0 | EV9: =SUMPRODUCT(NOT(ISBLANK(EV$3:EV$3))*(EV$3:EV$3=$GK$3:$GK$3)) -> 0 | EW9: =SUMPRODUCT(NOT(ISBLANK(EW$3:EW$3))*(EW$3:EW$3=$GL$3:$GL$3)) -> 0 | EX9: =SUMPRODUCT(NOT(ISBLANK(EX$3:EX$3))*(EX$3:EX$3=$GM$3:$GM$3)) -> 0 | EY9: =SUMPRODUCT(NOT(ISBLANK(EY$3:EY$3))*(EY$3:EY$3=$GN$3:$GN$3)) -> 0 | EZ9: =SUMPRODUCT(NOT(ISBLANK(EZ$3:EZ$3))*(EZ$3:EZ$3=$GI$3:$GI$3)) -> 0 | FA9: =SUMPRODUCT(NOT(ISBLANK(FA$3:FA$3))*(FA$3:FA$3=$GJ$3:$GJ$3)) -> 0 | FC9: =SUMPRODUCT(NOT(ISBLANK(FC$3:FC$3))*(FC$3:FC$3=$GK$3:$GK$3)) -> 0 | FD9: =SUMPRODUCT(NOT(ISBLANK(FD$3:FD$3))*(FD$3:FD$3=$GL$3:$GL$3)) -> 0 | FE9: =SUMPRODUCT(NOT(ISBLANK(FE$3:FE$3))*(FE$3:FE$3=$GM$3:$GM$3)) -> 0 | FF9: =SUMPRODUCT(NOT(ISBLANK(FF$3:FF$3))*(FF$3:FF$3=$GN$3:$GN$3)) -> 0 | FG9: =SUMPRODUCT(NOT(ISBLANK(FG$3:FG$3))*(FG$3:FG$3=$GI$3:$GI$3)) -> 0 | FH9: =SUMPRODUCT(NOT(ISBLANK(FH$3:FH$3))*(FH$3:FH$3=$GJ$3:$GJ$3)) -> 0 | FJ9: =SUMPRODUCT(NOT(ISBLANK(FJ$3:FJ$3))*(FJ$3:FJ$3=$GK$3:$GK$3)) -> 0 | FK9: =SUMPRODUCT(NOT(ISBLANK(FK$3:FK$3))*(FK$3:FK$3=$GL$3:$GL$3)) -> 0 | FL9: =SUMPRODUCT(NOT(ISBLANK(FL$3:FL$3))*(FL$3:FL$3=$GM$3:$GM$3)) -> 0 | FM9: =SUMPRODUCT(NOT(ISBLANK(FM$3:FM$3))*(FM$3:FM$3=$GN$3:$GN$3)) -> 0 | FN9: =SUMPRODUCT(NOT(ISBLANK(FN$3:FN$3))*(FN$3:FN$3=$GI$3:$GI$3)) -> 0 | FO9: =SUMPRODUCT(NOT(ISBLANK(FO$3:FO$3))*(FO$3:FO$3=$GJ$3:$GJ$3)) -> 0 | FQ9: =SUMPRODUCT(NOT(ISBLANK(FQ$3:FQ$3))*(FQ$3:FQ$3=$GK$3:$GK$3)) -> 0 | FR9: =SUMPRODUCT(NOT(ISBLANK(FR$3:FR$3))*(FR$3:FR$3=$GL$3:$GL$3)) -> 0 | FS9: =SUMPRODUCT(NOT(ISBLANK(FS$3:FS$3))*(FS$3:FS$3=$GM$3:$GM$3)) -> 0 | FT9: =SUMPRODUCT(NOT(ISBLANK(FT$3:FT$3))*(FT$3:FT$3=$GN$3:$GN$3)) -> 0 | FU9: =SUMPRODUCT(NOT(ISBLANK(FU$3:FU$3))*(FU$3:FU$3=$GI$3:$GI$3)) -> 0 | FV9: =SUMPRODUCT(NOT(ISBLANK(FV$3:FV$3))*(FV$3:FV$3=$GJ$3:$GJ$3)) -> 0 | FX9: =SUMPRODUCT(NOT(ISBLANK(FX$3:FX$3))*(FX$3:FX$3=$GK$3:$GK$3)) -> 0 | FY9: =SUMPRODUCT(NOT(ISBLANK(FY$3:FY$3))*(FY$3:FY$3=$GL$3:$GL$3)) -> 0 | FZ9: =SUMPRODUCT(NOT(ISBLANK(FZ$3:FZ$3))*(FZ$3:FZ$3=$GM$3:$GM$3)) -> 0 | GA9: =SUMPRODUCT(NOT(ISBLANK(GA$3:GA$3))*(GA$3:GA$3=$GN$3:$GN$3)) -> 0 | GB9: =SUMPRODUCT(NOT(ISBLANK(GB$3:GB$3))*(GB$3:GB$3=$GI$3:$GI$3)) -> 0 | GC9: =SUMPRODUCT(NOT(ISBLANK(GC$3:GC$3))*(GC$3:GC$3=$GJ$3:$GJ$3)) -> 0 | GE9: =SUMPRODUCT(NOT(ISBLANK(GE$3:GE$3))*(GE$3:GE$3=$GK$3:$GK$3)) -> 0 | GF9: =SUMPRODUCT(NOT(ISBLANK(GF$3:GF$3))*(GF$3:GF$3=$GL$3:$GL$3)) -> 0 | GG9: =SUMPRODUCT(NOT(ISBLANK(GG$3:GG$3))*(GG$3:GG$3=$GM$3:$GM$3)) -> 0 | GH9: =SUMPRODUCT(NOT(ISBLANK(GH$3:GH$3))*(GH$3:GH$3=$GN$3:$GN$3)) -> 0
A10: BETTER | B10: =SUMPRODUCT(NOT(ISBLANK(B$3:B$3))*(B$3:B$3<$GO$3:$GO$3)) -> 0 | C10: =SUMPRODUCT(NOT(ISBLANK(C$3:C$3))*(C$3:C$3<$GP$3:$GP$3)) -> 0 | E10: =SUMPRODUCT(NOT(ISBLANK(E$3:E$3))*(E$3:E$3<$GQ$3:$GQ$3)) -> 0 | F10: =SUMPRODUCT(NOT(ISBLANK(F$3:F$3))*(F$3:F$3<$GR$3:$GR$3)) -> 0 | G10: =SUMPRODUCT(NOT(ISBLANK(G$3:G$3))*(G$3:G$3<$GS$3:$GS$3)) -> 0 | H10: =SUMPRODUCT(NOT(ISBLANK(H$3:H$3))*(H$3:H$3<$GT$3:$GT$3)) -> 0 | I10: =SUMPRODUCT(NOT(ISBLANK(I$3:I$3))*(I$3:I$3<$GO$3:$GO$3)) -> 0 | J10: =SUMPRODUCT(NOT(ISBLANK(J$3:J$3))*(J$3:J$3<$GP$3:$GP$3)) -> 0 | L10: =SUMPRODUCT(NOT(ISBLANK(L$3:L$3))*(L$3:L$3<$GQ$3:$GQ$3)) -> 0 | M10: =SUMPRODUCT(NOT(ISBLANK(M$3:M$3))*(M$3:M$3<$GR$3:$GR$3)) -> 0 | N10: =SUMPRODUCT(NOT(ISBLANK(N$3:N$3))*(N$3:N$3<$GS$3:$GS$3)) -> 0 | O10: =SUMPRODUCT(NOT(ISBLANK(O$3:O$3))*(O$3:O$3<$GT$3:$GT$3)) -> 0 | P10: =SUMPRODUCT(NOT(ISBLANK(P$3:P$3))*(P$3:P$3<$GO$3:$GO$3)) -> 0 | Q10: =SUMPRODUCT(NOT(ISBLANK(Q$3:Q$3))*(Q$3:Q$3<$GP$3:$GP$3)) -> 0 | S10: =SUMPRODUCT(NOT(ISBLANK(S$3:S$3))*(S$3:S$3<$GQ$3:$GQ$3)) -> 0 | T10: =SUMPRODUCT(NOT(ISBLANK(T$3:T$3))*(T$3:T$3<$GR$3:$GR$3)) -> 0 | U10: =SUMPRODUCT(NOT(ISBLANK(U$3:U$3))*(U$3:U$3<$GS$3:$GS$3)) -> 0 | V10: =SUMPRODUCT(NOT(ISBLANK(V$3:V$3))*(V$3:V$3<$GT$3:$GT$3)) -> 0 | W10: =SUMPRODUCT(NOT(ISBLANK(W$3:W$3))*(W$3:W$3<$GO$3:$GO$3)) -> 0 | X10: =SUMPRODUCT(NOT(ISBLANK(X$3:X$3))*(X$3:X$3<$GP$3:$GP$3)) -> 0 | Z10: =SUMPRODUCT(NOT(ISBLANK(Z$3:Z$3))*(Z$3:Z$3<$GQ$3:$GQ$3)) -> 0 | AA10: =SUMPRODUCT(NOT(ISBLANK(AA$3:AA$3))*(AA$3:AA$3<$GR$3:$GR$3)) -> 0 | AB10: =SUMPRODUCT(NOT(ISBLANK(AB$3:AB$3))*(AB$3:AB$3<$GS$3:$GS$3)) -> 0 | AC10: =SUMPRODUCT(NOT(ISBLANK(AC$3:AC$3))*(AC$3:AC$3<$GT$3:$GT$3)) -> 0 | AD10: =SUMPRODUCT(NOT(ISBLANK(AD$3:AD$3))*(AD$3:AD$3<$GO$3:$GO$3)) -> 0 | AE10: =SUMPRODUCT(NOT(ISBLANK(AE$3:AE$3))*(AE$3:AE$3<$GP$3:$GP$3)) -> 0 | AG10: =SUMPRODUCT(NOT(ISBLANK(AG$3:AG$3))*(AG$3:AG$3<$GQ$3:$GQ$3)) -> 0 | AH10: =SUMPRODUCT(NOT(ISBLANK(AH$3:AH$3))*(AH$3:AH$3<$GR$3:$GR$3)) -> 0 | AI10: =SUMPRODUCT(NOT(ISBLANK(AI$3:AI$3))*(AI$3:AI$3<$GS$3:$GS$3)) -> 0 | AJ10: =SUMPRODUCT(NOT(ISBLANK(AJ$3:AJ$3))*(AJ$3:AJ$3<$GT$3:$GT$3)) -> 0 | AK10: =SUMPRODUCT(NOT(ISBLANK(AK$3:AK$3))*(AK$3:AK$3<$GO$3:$GO$3)) -> 0 | AL10: =SUMPRODUCT(NOT(ISBLANK(AL$3:AL$3))*(AL$3:AL$3<$GP$3:$GP$3)) -> 0 | AN10: =SUMPRODUCT(NOT(ISBLANK(AN$3:AN$3))*(AN$3:AN$3<$GQ$3:$GQ$3)) -> 0 | AO10: =SUMPRODUCT(NOT(ISBLANK(AO$3:AO$3))*(AO$3:AO$3<$GR$3:$GR$3)) -> 0 | AP10: =SUMPRODUCT(NOT(ISBLANK(AP$3:AP$3))*(AP$3:AP$3<$GS$3:$GS$3)) -> 0 | AQ10: =SUMPRODUCT(NOT(ISBLANK(AQ$3:AQ$3))*(AQ$3:AQ$3<$GT$3:$GT$3)) -> 0 | AR10: =SUMPRODUCT(NOT(ISBLANK(AR$3:AR$3))*(AR$3:AR$3<$GO$3:$GO$3)) -> 0 | AS10: =SUMPRODUCT(NOT(ISBLANK(AS$3:AS$3))*(AS$3:AS$3<$GP$3:$GP$3)) -> 0 | AU10: =SUMPRODUCT(NOT(ISBLANK(AU$3:AU$3))*(AU$3:AU$3<$GQ$3:$GQ$3)) -> 0 | AV10: =SUMPRODUCT(NOT(ISBLANK(AV$3:AV$3))*(AV$3:AV$3<$GR$3:$GR$3)) -> 0 | AW10: =SUMPRODUCT(NOT(ISBLANK(AW$3:AW$3))*(AW$3:AW$3<$GS$3:$GS$3)) -> 0 | AX10: =SUMPRODUCT(NOT(ISBLANK(AX$3:AX$3))*(AX$3:AX$3<$GT$3:$GT$3)) -> 0 | AY10: =SUMPRODUCT(NOT(ISBLANK(AY$3:AY$3))*(AY$3:AY$3<$GO$3:$GO$3)) -> 0 | AZ10: =SUMPRODUCT(NOT(ISBLANK(AZ$3:AZ$3))*(AZ$3:AZ$3<$GP$3:$GP$3)) -> 0 | BB10: =SUMPRODUCT(NOT(ISBLANK(BB$3:BB$3))*(BB$3:BB$3<$GQ$3:$GQ$3)) -> 0 | BC10: =SUMPRODUCT(NOT(ISBLANK(BC$3:BC$3))*(BC$3:BC$3<$GR$3:$GR$3)) -> 0 | BD10: =SUMPRODUCT(NOT(ISBLANK(BD$3:BD$3))*(BD$3:BD$3<$GS$3:$GS$3)) -> 0 | BE10: =SUMPRODUCT(NOT(ISBLANK(BE$3:BE$3))*(BE$3:BE$3<$GT$3:$GT$3)) -> 0 | BF10: =SUMPRODUCT(NOT(ISBLANK(BF$3:BF$3))*(BF$3:BF$3<$GO$3:$GO$3)) -> 0 | BG10: =SUMPRODUCT(NOT(ISBLANK(BG$3:BG$3))*(BG$3:BG$3<$GP$3:$GP$3)) -> 0 | BI10: =SUMPRODUCT(NOT(ISBLANK(BI$3:BI$3))*(BI$3:BI$3<$GQ$3:$GQ$3)) -> 0 | BJ10: =SUMPRODUCT(NOT(ISBLANK(BJ$3:BJ$3))*(BJ$3:BJ$3<$GR$3:$GR$3)) -> 0 | BK10: =SUMPRODUCT(NOT(ISBLANK(BK$3:BK$3))*(BK$3:BK$3<$GS$3:$GS$3)) -> 0 | BL10: =SUMPRODUCT(NOT(ISBLANK(BL$3:BL$3))*(BL$3:BL$3<$GT$3:$GT$3)) -> 0 | BM10: =SUMPRODUCT(NOT(ISBLANK(BM$3:BM$3))*(BM$3:BM$3<$GO$3:$GO$3)) -> 0 | BN10: =SUMPRODUCT(NOT(ISBLANK(BN$3:BN$3))*(BN$3:BN$3<$GP$3:$GP$3)) -> 0 | BP10: =SUMPRODUCT(NOT(ISBLANK(BP$3:BP$3))*(BP$3:BP$3<$GQ$3:$GQ$3)) -> 0 | BQ10: =SUMPRODUCT(NOT(ISBLANK(BQ$3:BQ$3))*(BQ$3:BQ$3<$GR$3:$GR$3)) -> 0 | BR10: =SUMPRODUCT(NOT(ISBLANK(BR$3:BR$3))*(BR$3:BR$3<$GS$3:$GS$3)) -> 0 | BS10: =SUMPRODUCT(NOT(ISBLANK(BS$3:BS$3))*(BS$3:BS$3<$GT$3:$GT$3)) -> 0 | BT10: =SUMPRODUCT(NOT(ISBLANK(BT$3:BT$3))*(BT$3:BT$3<$GO$3:$GO$3)) -> 0 | BU10: =SUMPRODUCT(NOT(ISBLANK(BU$3:BU$3))*(BU$3:BU$3<$GP$3:$GP$3)) -> 0 | BW10: =SUMPRODUCT(NOT(ISBLANK(BW$3:BW$3))*(BW$3:BW$3<$GQ$3:$GQ$3)) -> 0 | BX10: =SUMPRODUCT(NOT(ISBLANK(BX$3:BX$3))*(BX$3:BX$3<$GR$3:$GR$3)) -> 0 | BY10: =SUMPRODUCT(NOT(ISBLANK(BY$3:BY$3))*(BY$3:BY$3<$GS$3:$GS$3)) -> 0 | BZ10: =SUMPRODUCT(NOT(ISBLANK(BZ$3:BZ$3))*(BZ$3:BZ$3<$GT$3:$GT$3)) -> 0 | CA10: =SUMPRODUCT(NOT(ISBLANK(CA$3:CA$3))*(CA$3:CA$3<$GO$3:$GO$3)) -> 0 | CB10: =SUMPRODUCT(NOT(ISBLANK(CB$3:CB$3))*(CB$3:CB$3<$GP$3:$GP$3)) -> 0 | CD10: =SUMPRODUCT(NOT(ISBLANK(CD$3:CD$3))*(CD$3:CD$3<$GQ$3:$GQ$3)) -> 0 | CE10: =SUMPRODUCT(NOT(ISBLANK(CE$3:CE$3))*(CE$3:CE$3<$GR$3:$GR$3)) -> 0 | CF10: =SUMPRODUCT(NOT(ISBLANK(CF$3:CF$3))*(CF$3:CF$3<$GS$3:$GS$3)) -> 0 | CG10: =SUMPRODUCT(NOT(ISBLANK(CG$3:CG$3))*(CG$3:CG$3<$GT$3:$GT$3)) -> 0 | CH10: =SUMPRODUCT(NOT(ISBLANK(CH$3:CH$3))*(CH$3:CH$3<$GO$3:$GO$3)) -> 0 | CI10: =SUMPRODUCT(NOT(ISBLANK(CI$3:CI$3))*(CI$3:CI$3<$GP$3:$GP$3)) -> 0 | CK10: =SUMPRODUCT(NOT(ISBLANK(CK$3:CK$3))*(CK$3:CK$3<$GQ$3:$GQ$3)) -> 0 | CL10: =SUMPRODUCT(NOT(ISBLANK(CL$3:CL$3))*(CL$3:CL$3<$GR$3:$GR$3)) -> 0 | CM10: =SUMPRODUCT(NOT(ISBLANK(CM$3:CM$3))*(CM$3:CM$3<$GS$3:$GS$3)) -> 0 | CN10: =SUMPRODUCT(NOT(ISBLANK(CN$3:CN$3))*(CN$3:CN$3<$GT$3:$GT$3)) -> 0 | CO10: =SUMPRODUCT(NOT(ISBLANK(CO$3:CO$3))*(CO$3:CO$3<$GO$3:$GO$3)) -> 0 | CP10: =SUMPRODUCT(NOT(ISBLANK(CP$3:CP$3))*(CP$3:CP$3<$GP$3:$GP$3)) -> 0 | CR10: =SUMPRODUCT(NOT(ISBLANK(CR$3:CR$3))*(CR$3:CR$3<$GQ$3:$GQ$3)) -> 0 | CS10: =SUMPRODUCT(NOT(ISBLANK(CS$3:CS$3))*(CS$3:CS$3<$GR$3:$GR$3)) -> 0 | CT10: =SUMPRODUCT(NOT(ISBLANK(CT$3:CT$3))*(CT$3:CT$3<$GS$3:$GS$3)) -> 0 | CU10: =SUMPRODUCT(NOT(ISBLANK(CU$3:CU$3))*(CU$3:CU$3<$GT$3:$GT$3)) -> 0 | CV10: =SUMPRODUCT(NOT(ISBLANK(CV$3:CV$3))*(CV$3:CV$3<$GO$3:$GO$3)) -> 0 | CW10: =SUMPRODUCT(NOT(ISBLANK(CW$3:CW$3))*(CW$3:CW$3<$GP$3:$GP$3)) -> 0 | CY10: =SUMPRODUCT(NOT(ISBLANK(CY$3:CY$3))*(CY$3:CY$3<$GQ$3:$GQ$3)) -> 0 | CZ10: =SUMPRODUCT(NOT(ISBLANK(CZ$3:CZ$3))*(CZ$3:CZ$3<$GR$3:$GR$3)) -> 0 | DA10: =SUMPRODUCT(NOT(ISBLANK(DA$3:DA$3))*(DA$3:DA$3<$GS$3:$GS$3)) -> 0 | DB10: =SUMPRODUCT(NOT(ISBLANK(DB$3:DB$3))*(DB$3:DB$3<$GT$3:$GT$3)) -> 0 | DC10: =SUMPRODUCT(NOT(ISBLANK(DC$3:DC$3))*(DC$3:DC$3<$GO$3:$GO$3)) -> 0 | DD10: =SUMPRODUCT(NOT(ISBLANK(DD$3:DD$3))*(DD$3:DD$3<$GP$3:$GP$3)) -> 0 | DF10: =SUMPRODUCT(NOT(ISBLANK(DF$3:DF$3))*(DF$3:DF$3<$GQ$3:$GQ$3)) -> 0 | DG10: =SUMPRODUCT(NOT(ISBLANK(DG$3:DG$3))*(DG$3:DG$3<$GR$3:$GR$3)) -> 0 | DH10: =SUMPRODUCT(NOT(ISBLANK(DH$3:DH$3))*(DH$3:DH$3<$GS$3:$GS$3)) -> 0 | DI10: =SUMPRODUCT(NOT(ISBLANK(DI$3:DI$3))*(DI$3:DI$3<$GT$3:$GT$3)) -> 0 | DJ10: =SUMPRODUCT(NOT(ISBLANK(DJ$3:DJ$3))*(DJ$3:DJ$3<$GO$3:$GO$3)) -> 0 | DK10: =SUMPRODUCT(NOT(ISBLANK(DK$3:DK$3))*(DK$3:DK$3<$GP$3:$GP$3)) -> 0 | DM10: =SUMPRODUCT(NOT(ISBLANK(DM$3:DM$3))*(DM$3:DM$3<$GQ$3:$GQ$3)) -> 0 | DN10: =SUMPRODUCT(NOT(ISBLANK(DN$3:DN$3))*(DN$3:DN$3<$GR$3:$GR$3)) -> 0 | DO10: =SUMPRODUCT(NOT(ISBLANK(DO$3:DO$3))*(DO$3:DO$3<$GS$3:$GS$3)) -> 0 | DP10: =SUMPRODUCT(NOT(ISBLANK(DP$3:DP$3))*(DP$3:DP$3<$GT$3:$GT$3)) -> 0 | DQ10: =SUMPRODUCT(NOT(ISBLANK(DQ$3:DQ$3))*(DQ$3:DQ$3<$GO$3:$GO$3)) -> 0 | DR10: =SUMPRODUCT(NOT(ISBLANK(DR$3:DR$3))*(DR$3:DR$3<$GP$3:$GP$3)) -> 0 | DT10: =SUMPRODUCT(NOT(ISBLANK(DT$3:DT$3))*(DT$3:DT$3<$GQ$3:$GQ$3)) -> 0 | DU10: =SUMPRODUCT(NOT(ISBLANK(DU$3:DU$3))*(DU$3:DU$3<$GR$3:$GR$3)) -> 0 | DV10: =SUMPRODUCT(NOT(ISBLANK(DV$3:DV$3))*(DV$3:DV$3<$GS$3:$GS$3)) -> 0 | DW10: =SUMPRODUCT(NOT(ISBLANK(DW$3:DW$3))*(DW$3:DW$3<$GT$3:$GT$3)) -> 0 | DX10: =SUMPRODUCT(NOT(ISBLANK(DX$3:DX$3))*(DX$3:DX$3<$GO$3:$GO$3)) -> 0 | DY10: =SUMPRODUCT(NOT(ISBLANK(DY$3:DY$3))*(DY$3:DY$3<$GP$3:$GP$3)) -> 0 | EA10: =SUMPRODUCT(NOT(ISBLANK(EA$3:EA$3))*(EA$3:EA$3<$GQ$3:$GQ$3)) -> 0 | EB10: =SUMPRODUCT(NOT(ISBLANK(EB$3:EB$3))*(EB$3:EB$3<$GR$3:$GR$3)) -> 0 | EC10: =SUMPRODUCT(NOT(ISBLANK(EC$3:EC$3))*(EC$3:EC$3<$GS$3:$GS$3)) -> 0 | ED10: =SUMPRODUCT(NOT(ISBLANK(ED$3:ED$3))*(ED$3:ED$3<$GT$3:$GT$3)) -> 0 | EE10: =SUMPRODUCT(NOT(ISBLANK(EE$3:EE$3))*(EE$3:EE$3<$GO$3:$GO$3)) -> 0 | EF10: =SUMPRODUCT(NOT(ISBLANK(EF$3:EF$3))*(EF$3:EF$3<$GP$3:$GP$3)) -> 0 | EH10: =SUMPRODUCT(NOT(ISBLANK(EH$3:EH$3))*(EH$3:EH$3<$GQ$3:$GQ$3)) -> 0 | EI10: =SUMPRODUCT(NOT(ISBLANK(EI$3:EI$3))*(EI$3:EI$3<$GR$3:$GR$3)) -> 0 | EJ10: =SUMPRODUCT(NOT(ISBLANK(EJ$3:EJ$3))*(EJ$3:EJ$3<$GS$3:$GS$3)) -> 0 | EK10: =SUMPRODUCT(NOT(ISBLANK(EK$3:EK$3))*(EK$3:EK$3<$GT$3:$GT$3)) -> 0 | EL10: =SUMPRODUCT(NOT(ISBLANK(EL$3:EL$3))*(EL$3:EL$3<$GO$3:$GO$3)) -> 0 | EM10: =SUMPRODUCT(NOT(ISBLANK(EM$3:EM$3))*(EM$3:EM$3<$GP$3:$GP$3)) -> 0 | EO10: =SUMPRODUCT(NOT(ISBLANK(EO$3:EO$3))*(EO$3:EO$3<$GQ$3:$GQ$3)) -> 0 | EP10: =SUMPRODUCT(NOT(ISBLANK(EP$3:EP$3))*(EP$3:EP$3<$GR$3:$GR$3)) -> 0 | EQ10: =SUMPRODUCT(NOT(ISBLANK(EQ$3:EQ$3))*(EQ$3:EQ$3<$GS$3:$GS$3)) -> 0 | ER10: =SUMPRODUCT(NOT(ISBLANK(ER$3:ER$3))*(ER$3:ER$3<$GT$3:$GT$3)) -> 0 | ES10: =SUMPRODUCT(NOT(ISBLANK(ES$3:ES$3))*(ES$3:ES$3<$GO$3:$GO$3)) -> 0 | ET10: =SUMPRODUCT(NOT(ISBLANK(ET$3:ET$3))*(ET$3:ET$3<$GP$3:$GP$3)) -> 0 | EV10: =SUMPRODUCT(NOT(ISBLANK(EV$3:EV$3))*(EV$3:EV$3<$GQ$3:$GQ$3)) -> 0 | EW10: =SUMPRODUCT(NOT(ISBLANK(EW$3:EW$3))*(EW$3:EW$3<$GR$3:$GR$3)) -> 0 | EX10: =SUMPRODUCT(NOT(ISBLANK(EX$3:EX$3))*(EX$3:EX$3<$GS$3:$GS$3)) -> 0 | EY10: =SUMPRODUCT(NOT(ISBLANK(EY$3:EY$3))*(EY$3:EY$3<$GT$3:$GT$3)) -> 0 | EZ10: =SUMPRODUCT(NOT(ISBLANK(EZ$3:EZ$3))*(EZ$3:EZ$3<$GO$3:$GO$3)) -> 0 | FA10: =SUMPRODUCT(NOT(ISBLANK(FA$3:FA$3))*(FA$3:FA$3<$GP$3:$GP$3)) -> 0 | FC10: =SUMPRODUCT(NOT(ISBLANK(FC$3:FC$3))*(FC$3:FC$3<$GQ$3:$GQ$3)) -> 0 | FD10: =SUMPRODUCT(NOT(ISBLANK(FD$3:FD$3))*(FD$3:FD$3<$GR$3:$GR$3)) -> 0 | FE10: =SUMPRODUCT(NOT(ISBLANK(FE$3:FE$3))*(FE$3:FE$3<$GS$3:$GS$3)) -> 0 | FF10: =SUMPRODUCT(NOT(ISBLANK(FF$3:FF$3))*(FF$3:FF$3<$GT$3:$GT$3)) -> 0 | FG10: =SUMPRODUCT(NOT(ISBLANK(FG$3:FG$3))*(FG$3:FG$3<$GO$3:$GO$3)) -> 0 | FH10: =SUMPRODUCT(NOT(ISBLANK(FH$3:FH$3))*(FH$3:FH$3<$GP$3:$GP$3)) -> 0 | FJ10: =SUMPRODUCT(NOT(ISBLANK(FJ$3:FJ$3))*(FJ$3:FJ$3<$GQ$3:$GQ$3)) -> 0 | FK10: =SUMPRODUCT(NOT(ISBLANK(FK$3:FK$3))*(FK$3:FK$3<$GR$3:$GR$3)) -> 0 | FL10: =SUMPRODUCT(NOT(ISBLANK(FL$3:FL$3))*(FL$3:FL$3<$GS$3:$GS$3)) -> 0 | FM10: =SUMPRODUCT(NOT(ISBLANK(FM$3:FM$3))*(FM$3:FM$3<$GT$3:$GT$3)) -> 0 | FN10: =SUMPRODUCT(NOT(ISBLANK(FN$3:FN$3))*(FN$3:FN$3<$GO$3:$GO$3)) -> 0 | FO10: =SUMPRODUCT(NOT(ISBLANK(FO$3:FO$3))*(FO$3:FO$3<$GP$3:$GP$3)) -> 0 | FQ10: =SUMPRODUCT(NOT(ISBLANK(FQ$3:FQ$3))*(FQ$3:FQ$3<$GQ$3:$GQ$3)) -> 0 | FR10: =SUMPRODUCT(NOT(ISBLANK(FR$3:FR$3))*(FR$3:FR$3<$GR$3:$GR$3)) -> 0 | FS10: =SUMPRODUCT(NOT(ISBLANK(FS$3:FS$3))*(FS$3:FS$3<$GS$3:$GS$3)) -> 0 | FT10: =SUMPRODUCT(NOT(ISBLANK(FT$3:FT$3))*(FT$3:FT$3<$GT$3:$GT$3)) -> 0 | FU10: =SUMPRODUCT(NOT(ISBLANK(FU$3:FU$3))*(FU$3:FU$3<$GO$3:$GO$3)) -> 0 | FV10: =SUMPRODUCT(NOT(ISBLANK(FV$3:FV$3))*(FV$3:FV$3<$GP$3:$GP$3)) -> 0 | FX10: =SUMPRODUCT(NOT(ISBLANK(FX$3:FX$3))*(FX$3:FX$3<$GQ$3:$GQ$3)) -> 0 | FY10: =SUMPRODUCT(NOT(ISBLANK(FY$3:FY$3))*(FY$3:FY$3<$GR$3:$GR$3)) -> 0 | FZ10: =SUMPRODUCT(NOT(ISBLANK(FZ$3:FZ$3))*(FZ$3:FZ$3<$GS$3:$GS$3)) -> 0 | GA10: =SUMPRODUCT(NOT(ISBLANK(GA$3:GA$3))*(GA$3:GA$3<$GT$3:$GT$3)) -> 0 | GB10: =SUMPRODUCT(NOT(ISBLANK(GB$3:GB$3))*(GB$3:GB$3<$GO$3:$GO$3)) -> 0 | GC10: =SUMPRODUCT(NOT(ISBLANK(GC$3:GC$3))*(GC$3:GC$3<$GP$3:$GP$3)) -> 0 | GE10: =SUMPRODUCT(NOT(ISBLANK(GE$3:GE$3))*(GE$3:GE$3<$GQ$3:$GQ$3)) -> 0 | GF10: =SUMPRODUCT(NOT(ISBLANK(GF$3:GF$3))*(GF$3:GF$3<$GR$3:$GR$3)) -> 0 | GG10: =SUMPRODUCT(NOT(ISBLANK(GG$3:GG$3))*(GG$3:GG$3<$GS$3:$GS$3)) -> 0 | GH10: =SUMPRODUCT(NOT(ISBLANK(GH$3:GH$3))*(GH$3:GH$3<$GT$3:$GT$3)) -> 0
