Workbook

Sheet Instances
B1: memelingo-1/lambda-large_100_mlp-tplp-htc | I1: memelingo-1/lambda-large_100_mlp-tplp-htcdl | P1: memelingo-1/lambda-large_150_mlp-tplp-htc | W1: memelingo-1/lambda-large_150_mlp-tplp-htcdl | AD1: memelingo-1/lambda-large_200_mlp-tplp-htc | AK1: memelingo-1/lambda-large_200_mlp-tplp-htcdl | AR1: memelingo-1/lambda-small_20_mlp-tplp-ht | AY1: memelingo-1/lambda-small_20_mlp-tplp-htc | BF1: memelingo-1/lambda-small_20_mlp-tplp-htcdl | BM1: memelingo-1/lambda-small_25_mlp-tplp-ht | BT1: memelingo-1/lambda-small_25_mlp-tplp-htc | CA1: memelingo-1/lambda-small_25_mlp-tplp-htcdl | CH1: memelingo-1/lambda-small_30_mlp-tplp-ht | CO1: memelingo-1/lambda-small_30_mlp-tplp-htc | CV1: memelingo-1/lambda-small_30_mlp-tplp-htcdl | DC1: memelingo-1/lambda-small_35_mlp-tplp-ht | DJ1: memelingo-1/lambda-small_35_mlp-tplp-htc | DQ1: memelingo-1/lambda-small_35_mlp-tplp-htcdl | DX1: memelingo-1/lambda-small_40_mlp-tplp-ht | EE1: memelingo-1/lambda-small_40_mlp-tplp-htc | EL1: memelingo-1/lambda-small_40_mlp-tplp-htcdl | ES1: memelingo-1/lambda-small_45_mlp-tplp-ht | EZ1: memelingo-1/lambda-small_45_mlp-tplp-htc | FG1: memelingo-1/lambda-small_45_mlp-tplp-htcdl | FN1: memelingo-1/lambda-small_50_mlp-tplp-ht | FU1: memelingo-1/lambda-small_50_mlp-tplp-htc | GB1: memelingo-1/lambda-small_50_mlp-tplp-htcdl | GI1: min | GO1: median | GU1: max
B2: time | C2: stime | D2: status | E2: rules | F2: ctime | G2: fmtime | H2: memout | I2: time | J2: stime | K2: status | L2: rules | M2: ctime | N2: fmtime | O2: memout | P2: time | Q2: stime | R2: status | S2: rules | T2: ctime | U2: fmtime | V2: memout | W2: time | X2: stime | Y2: status | Z2: rules | AA2: ctime | AB2: fmtime | AC2: memout | AD2: time | AE2: stime | AF2: status | AG2: rules | AH2: ctime | AI2: fmtime | AJ2: memout | AK2: time | AL2: stime | AM2: status | AN2: rules | AO2: ctime | AP2: fmtime | AQ2: memout | AR2: time | AS2: stime | AT2: status | AU2: rules | AV2: ctime | AW2: fmtime | AX2: memout | AY2: time | AZ2: stime | BA2: status | BB2: rules | BC2: ctime | BD2: fmtime | BE2: memout | BF2: time | BG2: stime | BH2: status | BI2: rules | BJ2: ctime | BK2: fmtime | BL2: memout | BM2: time | BN2: stime | BO2: status | BP2: rules | BQ2: ctime | BR2: fmtime | BS2: memout | BT2: time | BU2: stime | BV2: status | BW2: rules | BX2: ctime | BY2: fmtime | BZ2: memout | CA2: time | CB2: stime | CC2: status | CD2: rules | CE2: ctime | CF2: fmtime | CG2: memout | CH2: time | CI2: stime | CJ2: status | CK2: rules | CL2: ctime | CM2: fmtime | CN2: memout | CO2: time | CP2: stime | CQ2: status | CR2: rules | CS2: ctime | CT2: fmtime | CU2: memout | CV2: time | CW2: stime | CX2: status | CY2: rules | CZ2: ctime | DA2: fmtime | DB2: memout | DC2: time | DD2: stime | DE2: status | DF2: rules | DG2: ctime | DH2: fmtime | DI2: memout | DJ2: time | DK2: stime | DL2: status | DM2: rules | DN2: ctime | DO2: fmtime | DP2: memout | DQ2: time | DR2: stime | DS2: status | DT2: rules | DU2: ctime | DV2: fmtime | DW2: memout | DX2: time | DY2: stime | DZ2: status | EA2: rules | EB2: ctime | EC2: fmtime | ED2: memout | EE2: time | EF2: stime | EG2: status | EH2: rules | EI2: ctime | EJ2: fmtime | EK2: memout | EL2: time | EM2: stime | EN2: status | EO2: rules | EP2: ctime | EQ2: fmtime | ER2: memout | ES2: time | ET2: stime | EU2: status | EV2: rules | EW2: ctime | EX2: fmtime | EY2: memout | EZ2: time | FA2: stime | FB2: status | FC2: rules | FD2: ctime | FE2: fmtime | FF2: memout | FG2: time | FH2: stime | FI2: status | FJ2: rules | FK2: ctime | FL2: fmtime | FM2: memout | FN2: time | FO2: stime | FP2: status | FQ2: rules | FR2: ctime | FS2: fmtime | FT2: memout | FU2: time | FV2: stime | FW2: status | FX2: rules | FY2: ctime | FZ2: fmtime | GA2: memout | GB2: time | GC2: stime | GD2: status | GE2: rules | GF2: ctime | GG2: fmtime | GH2: memout | GI2: time | GJ2: stime | GK2: rules | GL2: ctime | GM2: fmtime | GN2: memout | GO2: time | GP2: stime | GQ2: rules | GR2: ctime | GS2: fmtime | GT2: memout | GU2: time | GV2: stime | GW2: rules | GX2: ctime | GY2: fmtime | GZ2: memout
A3: instances/ft06 | AR3: 1200 | AX3: 0 | AY3: 16.72 | AZ3: 14.83 | BA3: SATISFIABLE | BB3: 136533 | BC3: 15.712 | BD3: 14.82 | BE3: 0 | BF3: 1200 | BG3: 1499.74 | BH3: SATISFIABLE | BI3: 136533 | BJ3: 1500.461 | BK3: 1499.74 | BL3: 0 | BM3: 1200 | BN3: 22008.27 | BO3: SATISFIABLE | BP3: 7778774 | BQ3: 22030.897 | BR3: 22008.14 | BS3: 0 | BT3: 1200 | BU3: 2233.02 | BV3: SATISFIABLE | BW3: 189598 | BX3: 2234.539 | BY3: 2233.01 | BZ3: 0 | CA3: 1200 | CB3: 13427.52 | CC3: SATISFIABLE | CD3: 189598 | CE3: 13428.944 | CF3: 13427.49 | CG3: 0 | CH3: 1200 | CN3: 0 | CO3: 201.99 | CP3: 197.68 | CQ3: SATISFIABLE | CR3: 250538 | CS3: 200.466 | CT3: 197.67 | CU3: 0 | CV3: 547.21 | CW3: 543.5 | CX3: SATISFIABLE | CY3: 250538 | CZ3: 545.629 | DA3: 543.5 | DB3: 0 | DC3: 1200 | DI3: 0 | DJ3: 696.22 | DK3: 690.22 | DL3: SATISFIABLE | DM3: 319353 | DN3: 694.282 | DO3: 690.21 | DP3: 0 | DQ3: 1023.88 | DR3: 1019.01 | DS3: SATISFIABLE | DT3: 319353 | DU3: 1022.337 | DV3: 1019 | DW3: 0 | DX3: 1200 | DY3: 2043.47 | DZ3: SATISFIABLE | EA3: 13524344 | EB3: 2096.31 | EC3: 2043.46 | ED3: 0 | EE3: 113.31 | EF3: 104.75 | EG3: SATISFIABLE | EH3: 396043 | EI3: 111.798 | EJ3: 104.74 | EK3: 0 | EL3: 255.21 | EM3: 248.58 | EN3: SATISFIABLE | EO3: 396043 | EP3: 253.256 | EQ3: 248.56 | ER3: 0 | ES3: 698 | ET3: 625.86 | EU3: SATISFIABLE | EV3: 14804634 | EW3: 696.119 | EX3: 625.85 | EY3: 0 | EZ3: 68.48 | FA3: 59.33 | FB3: SATISFIABLE | FC3: 480608 | FD3: 66.564 | FE3: 59.32 | FF3: 0 | FG3: 208.15 | FH3: 201.47 | FI3: SATISFIABLE | FJ3: 480608 | FK3: 206.413 | FL3: 201.45 | FM3: 0 | FN3: 102.14 | FO3: 43.19 | FP3: SATISFIABLE | FQ3: 15681849 | FR3: 100.389 | FS3: 43.17 | FT3: 0 | FU3: 122.85 | FV3: 110.3 | FW3: SATISFIABLE | FX3: 573048 | FY3: 116.39 | FZ3: 110.29 | GA3: 0 | GB3: 68.54 | GC3: 60.91 | GD3: SATISFIABLE | GE3: 573048 | GF3: 66.962 | GG3: 60.87 | GH3: 0 | GI3: =MIN($B3,$I3,$P3,$W3,$AD3,$AK3,$AR3,$AY3,$BF3,$BM3,$BT3,$CA3,$CH3,$CO3,$CV3,$DC3,$DJ3,$DQ3,$DX3,$EE3,$EL3,$ES3,$EZ3,$FG3,$FN3,$FU3,$GB3) -> 0 | GJ3: =MIN($C3,$J3,$Q3,$X3,$AE3,$AL3,$AS3,$AZ3,$BG3,$BN3,$BU3,$CB3,$CI3,$CP3,$CW3,$DD3,$DK3,$DR3,$DY3,$EF3,$EM3,$ET3,$FA3,$FH3,$FO3,$FV3,$GC3) -> 0 | GK3: =MIN($E3,$L3,$S3,$Z3,$AG3,$AN3,$AU3,$BB3,$BI3,$BP3,$BW3,$CD3,$CK3,$CR3,$CY3,$DF3,$DM3,$DT3,$EA3,$EH3,$EO3,$EV3,$FC3,$FJ3,$FQ3,$FX3,$GE3) -> 0 | GL3: =MIN($F3,$M3,$T3,$AA3,$AH3,$AO3,$AV3,$BC3,$BJ3,$BQ3,$BX3,$CE3,$CL3,$CS3,$CZ3,$DG3,$DN3,$DU3,$EB3,$EI3,$EP3,$EW3,$FD3,$FK3,$FR3,$FY3,$GF3) -> 0 | GM3: =MIN($G3,$N3,$U3,$AB3,$AI3,$AP3,$AW3,$BD3,$BK3,$BR3,$BY3,$CF3,$CM3,$CT3,$DA3,$DH3,$DO3,$DV3,$EC3,$EJ3,$EQ3,$EX3,$FE3,$FL3,$FS3,$FZ3,$GG3) -> 0 | GN3: =MIN($H3,$O3,$V3,$AC3,$AJ3,$AQ3,$AX3,$BE3,$BL3,$BS3,$BZ3,$CG3,$CN3,$CU3,$DB3,$DI3,$DP3,$DW3,$ED3,$EK3,$ER3,$EY3,$FF3,$FM3,$FT3,$GA3,$GH3) -> 0 | GO3: =MEDIAN($B3,$I3,$P3,$W3,$AD3,$AK3,$AR3,$AY3,$BF3,$BM3,$BT3,$CA3,$CH3,$CO3,$CV3,$DC3,$DJ3,$DQ3,$DX3,$EE3,$EL3,$ES3,$EZ3,$FG3,$FN3,$FU3,$GB3) -> 0 | GP3: =MEDIAN($C3,$J3,$Q3,$X3,$AE3,$AL3,$AS3,$AZ3,$BG3,$BN3,$BU3,$CB3,$CI3,$CP3,$CW3,$DD3,$DK3,$DR3,$DY3,$EF3,$EM3,$ET3,$FA3,$FH3,$FO3,$FV3,$GC3) -> 0 | GQ3: =MEDIAN($E3,$L3,$S3,$Z3,$AG3,$AN3,$AU3,$BB3,$BI3,$BP3,$BW3,$CD3,$CK3,$CR3,$CY3,$DF3,$DM3,$DT3,$EA3,$EH3,$EO3,$EV3,$FC3,$FJ3,$FQ3,$FX3,$GE3) -> 0 | GR3: =MEDIAN($F3,$M3,$T3,$AA3,$AH3,$AO3,$AV3,$BC3,$BJ3,$BQ3,$BX3,$CE3,$CL3,$CS3,$CZ3,$DG3,$DN3,$DU3,$EB3,$EI3,$EP3,$EW3,$FD3,$FK3,$FR3,$FY3,$GF3) -> 0 | GS3: =MEDIAN($G3,$N3,$U3,$AB3,$AI3,$AP3,$AW3,$BD3,$BK3,$BR3,$BY3,$CF3,$CM3,$CT3,$DA3,$DH3,$DO3,$DV3,$EC3,$EJ3,$EQ3,$EX3,$FE3,$FL3,$FS3,$FZ3,$GG3) -> 0 | GT3: =MEDIAN($H3,$O3,$V3,$AC3,$AJ3,$AQ3,$AX3,$BE3,$BL3,$BS3,$BZ3,$CG3,$CN3,$CU3,$DB3,$DI3,$DP3,$DW3,$ED3,$EK3,$ER3,$EY3,$FF3,$FM3,$FT3,$GA3,$GH3) -> 0 | GU3: =MAX($B3,$I3,$P3,$W3,$AD3,$AK3,$AR3,$AY3,$BF3,$BM3,$BT3,$CA3,$CH3,$CO3,$CV3,$DC3,$DJ3,$DQ3,$DX3,$EE3,$EL3,$ES3,$EZ3,$FG3,$FN3,$FU3,$GB3) -> 0 | GV3: =MAX($C3,$J3,$Q3,$X3,$AE3,$AL3,$AS3,$AZ3,$BG3,$BN3,$BU3,$CB3,$CI3,$CP3,$CW3,$DD3,$DK3,$DR3,$DY3,$EF3,$EM3,$ET3,$FA3,$FH3,$FO3,$FV3,$GC3) -> 0 | GW3: =MAX($E3,$L3,$S3,$Z3,$AG3,$AN3,$AU3,$BB3,$BI3,$BP3,$BW3,$CD3,$CK3,$CR3,$CY3,$DF3,$DM3,$DT3,$EA3,$EH3,$EO3,$EV3,$FC3,$FJ3,$FQ3,$FX3,$GE3) -> 0 | GX3: =MAX($F3,$M3,$T3,$AA3,$AH3,$AO3,$AV3,$BC3,$BJ3,$BQ3,$BX3,$CE3,$CL3,$CS3,$CZ3,$DG3,$DN3,$DU3,$EB3,$EI3,$EP3,$EW3,$FD3,$FK3,$FR3,$FY3,$GF3) -> 0 | GY3: =MAX($G3,$N3,$U3,$AB3,$AI3,$AP3,$AW3,$BD3,$BK3,$BR3,$BY3,$CF3,$CM3,$CT3,$DA3,$DH3,$DO3,$DV3,$EC3,$EJ3,$EQ3,$EX3,$FE3,$FL3,$FS3,$FZ3,$GG3) -> 0 | GZ3: =MAX($H3,$O3,$V3,$AC3,$AJ3,$AQ3,$AX3,$BE3,$BL3,$BS3,$BZ3,$CG3,$CN3,$CU3,$DB3,$DI3,$DP3,$DW3,$ED3,$EK3,$ER3,$EY3,$FF3,$FM3,$FT3,$GA3,$GH3) -> 0
A4: instances/ft10 | B4: 1200 | H4: 0 | I4: 1200 | O4: 0 | P4: 1200 | V4: 0 | W4: 1200 | AC4: 0 | AD4: 1200 | AJ4: 0 | AK4: 1200 | AQ4: 0 | GI4: =MIN($B4,$I4,$P4,$W4,$AD4,$AK4,$AR4,$AY4,$BF4,$BM4,$BT4,$CA4,$CH4,$CO4,$CV4,$DC4,$DJ4,$DQ4,$DX4,$EE4,$EL4,$ES4,$EZ4,$FG4,$FN4,$FU4,$GB4) -> 0 | GN4: =MIN($H4,$O4,$V4,$AC4,$AJ4,$AQ4,$AX4,$BE4,$BL4,$BS4,$BZ4,$CG4,$CN4,$CU4,$DB4,$DI4,$DP4,$DW4,$ED4,$EK4,$ER4,$EY4,$FF4,$FM4,$FT4,$GA4,$GH4) -> 0 | GO4: =MEDIAN($B4,$I4,$P4,$W4,$AD4,$AK4,$AR4,$AY4,$BF4,$BM4,$BT4,$CA4,$CH4,$CO4,$CV4,$DC4,$DJ4,$DQ4,$DX4,$EE4,$EL4,$ES4,$EZ4,$FG4,$FN4,$FU4,$GB4) -> 0 | GT4: =MEDIAN($H4,$O4,$V4,$AC4,$AJ4,$AQ4,$AX4,$BE4,$BL4,$BS4,$BZ4,$CG4,$CN4,$CU4,$DB4,$DI4,$DP4,$DW4,$ED4,$EK4,$ER4,$EY4,$FF4,$FM4,$FT4,$GA4,$GH4) -> 0 | GU4: =MAX($B4,$I4,$P4,$W4,$AD4,$AK4,$AR4,$AY4,$BF4,$BM4,$BT4,$CA4,$CH4,$CO4,$CV4,$DC4,$DJ4,$DQ4,$DX4,$EE4,$EL4,$ES4,$EZ4,$FG4,$FN4,$FU4,$GB4) -> 0 | GZ4: =MAX($H4,$O4,$V4,$AC4,$AJ4,$AQ4,$AX4,$BE4,$BL4,$BS4,$BZ4,$CG4,$CN4,$CU4,$DB4,$DI4,$DP4,$DW4,$ED4,$EK4,$ER4,$EY4,$FF4,$FM4,$FT4,$GA4,$GH4) -> 0
A5: instances/la01 | B5: 1200 | H5: 0 | I5: 1200 | O5: 0 | P5: 1200 | V5: 0 | W5: 1200 | AC5: 0 | AD5: 1200 | AJ5: 0 | AK5: 1200 | AQ5: 0 | GI5: =MIN($B5,$I5,$P5,$W5,$AD5,$AK5,$AR5,$AY5,$BF5,$BM5,$BT5,$CA5,$CH5,$CO5,$CV5,$DC5,$DJ5,$DQ5,$DX5,$EE5,$EL5,$ES5,$EZ5,$FG5,$FN5,$FU5,$GB5) -> 0 | GN5: =MIN($H5,$O5,$V5,$AC5,$AJ5,$AQ5,$AX5,$BE5,$BL5,$BS5,$BZ5,$CG5,$CN5,$CU5,$DB5,$DI5,$DP5,$DW5,$ED5,$EK5,$ER5,$EY5,$FF5,$FM5,$FT5,$GA5,$GH5) -> 0 | GO5: =MEDIAN($B5,$I5,$P5,$W5,$AD5,$AK5,$AR5,$AY5,$BF5,$BM5,$BT5,$CA5,$CH5,$CO5,$CV5,$DC5,$DJ5,$DQ5,$DX5,$EE5,$EL5,$ES5,$EZ5,$FG5,$FN5,$FU5,$GB5) -> 0 | GT5: =MEDIAN($H5,$O5,$V5,$AC5,$AJ5,$AQ5,$AX5,$BE5,$BL5,$BS5,$BZ5,$CG5,$CN5,$CU5,$DB5,$DI5,$DP5,$DW5,$ED5,$EK5,$ER5,$EY5,$FF5,$FM5,$FT5,$GA5,$GH5) -> 0 | GU5: =MAX($B5,$I5,$P5,$W5,$AD5,$AK5,$AR5,$AY5,$BF5,$BM5,$BT5,$CA5,$CH5,$CO5,$CV5,$DC5,$DJ5,$DQ5,$DX5,$EE5,$EL5,$ES5,$EZ5,$FG5,$FN5,$FU5,$GB5) -> 0 | GZ5: =MAX($H5,$O5,$V5,$AC5,$AJ5,$AQ5,$AX5,$BE5,$BL5,$BS5,$BZ5,$CG5,$CN5,$CU5,$DB5,$DI5,$DP5,$DW5,$ED5,$EK5,$ER5,$EY5,$FF5,$FM5,$FT5,$GA5,$GH5) -> 0
A6: instances/la02 | B6: 1200 | H6: 0 | I6: 1200 | O6: 0 | P6: 1200 | V6: 0 | W6: 1200 | AC6: 0 | AD6: 1200 | AJ6: 0 | AK6: 1200 | AQ6: 0 | GI6: =MIN($B6,$I6,$P6,$W6,$AD6,$AK6,$AR6,$AY6,$BF6,$BM6,$BT6,$CA6,$CH6,$CO6,$CV6,$DC6,$DJ6,$DQ6,$DX6,$EE6,$EL6,$ES6,$EZ6,$FG6,$FN6,$FU6,$GB6) -> 0 | GN6: =MIN($H6,$O6,$V6,$AC6,$AJ6,$AQ6,$AX6,$BE6,$BL6,$BS6,$BZ6,$CG6,$CN6,$CU6,$DB6,$DI6,$DP6,$DW6,$ED6,$EK6,$ER6,$EY6,$FF6,$FM6,$FT6,$GA6,$GH6) -> 0 | GO6: =MEDIAN($B6,$I6,$P6,$W6,$AD6,$AK6,$AR6,$AY6,$BF6,$BM6,$BT6,$CA6,$CH6,$CO6,$CV6,$DC6,$DJ6,$DQ6,$DX6,$EE6,$EL6,$ES6,$EZ6,$FG6,$FN6,$FU6,$GB6) -> 0 | GT6: =MEDIAN($H6,$O6,$V6,$AC6,$AJ6,$AQ6,$AX6,$BE6,$BL6,$BS6,$BZ6,$CG6,$CN6,$CU6,$DB6,$DI6,$DP6,$DW6,$ED6,$EK6,$ER6,$EY6,$FF6,$FM6,$FT6,$GA6,$GH6) -> 0 | GU6: =MAX($B6,$I6,$P6,$W6,$AD6,$AK6,$AR6,$AY6,$BF6,$BM6,$BT6,$CA6,$CH6,$CO6,$CV6,$DC6,$DJ6,$DQ6,$DX6,$EE6,$EL6,$ES6,$EZ6,$FG6,$FN6,$FU6,$GB6) -> 0 | GZ6: =MAX($H6,$O6,$V6,$AC6,$AJ6,$AQ6,$AX6,$BE6,$BL6,$BS6,$BZ6,$CG6,$CN6,$CU6,$DB6,$DI6,$DP6,$DW6,$ED6,$EK6,$ER6,$EY6,$FF6,$FM6,$FT6,$GA6,$GH6) -> 0
A8: SUM | B8: =SUM(B$3:B$6) -> 0 | H8: =SUM(H$3:H$6) -> 0 | I8: =SUM(I$3:I$6) -> 0 | O8: =SUM(O$3:O$6) -> 0 | P8: =SUM(P$3:P$6) -> 0 | V8: =SUM(V$3:V$6) -> 0 | W8: =SUM(W$3:W$6) -> 0 | AC8: =SUM(AC$3:AC$6) -> 0 | AD8: =SUM(AD$3:AD$6) -> 0 | AJ8: =SUM(AJ$3:AJ$6) -> 0 | AK8: =SUM(AK$3:AK$6) -> 0 | AQ8: =SUM(AQ$3:AQ$6) -> 0 | AR8: =SUM(AR$3:AR$6) -> 0 | AX8: =SUM(AX$3:AX$6) -> 0 | AY8: =SUM(AY$3:AY$6) -> 0 | AZ8: =SUM(AZ$3:AZ$6) -> 0 | BB8: =SUM(BB$3:BB$6) -> 0 | BC8: =SUM(BC$3:BC$6) -> 0 | BD8: =SUM(BD$3:BD$6) -> 0 | BE8: =SUM(BE$3:BE$6) -> 0 | BF8: =SUM(BF$3:BF$6) -> 0 | BG8: =SUM(BG$3:BG$6) -> 0 | BI8: =SUM(BI$3:BI$6) -> 0 | BJ8: =SUM(BJ$3:BJ$6) -> 0 | BK8: =SUM(BK$3:BK$6) -> 0 | BL8: =SUM(BL$3:BL$6) -> 0 | BM8: =SUM(BM$3:BM$6) -> 0 | BN8: =SUM(BN$3:BN$6) -> 0 | BP8: =SUM(BP$3:BP$6) -> 0 | BQ8: =SUM(BQ$3:BQ$6) -> 0 | BR8: =SUM(BR$3:BR$6) -> 0 | BS8: =SUM(BS$3:BS$6) -> 0 | BT8: =SUM(BT$3:BT$6) -> 0 | BU8: =SUM(BU$3:BU$6) -> 0 | BW8: =SUM(BW$3:BW$6) -> 0 | BX8: =SUM(BX$3:BX$6) -> 0 | BY8: =SUM(BY$3:BY$6) -> 0 | BZ8: =SUM(BZ$3:BZ$6) -> 0 | CA8: =SUM(CA$3:CA$6) -> 0 | CB8: =SUM(CB$3:CB$6) -> 0 | CD8: =SUM(CD$3:CD$6) -> 0 | CE8: =SUM(CE$3:CE$6) -> 0 | CF8: =SUM(CF$3:CF$6) -> 0 | CG8: =SUM(CG$3:CG$6) -> 0 | CH8: =SUM(CH$3:CH$6) -> 0 | CN8: =SUM(CN$3:CN$6) -> 0 | CO8: =SUM(CO$3:CO$6) -> 0 | CP8: =SUM(CP$3:CP$6) -> 0 | CR8: =SUM(CR$3:CR$6) -> 0 | CS8: =SUM(CS$3:CS$6) -> 0 | CT8: =SUM(CT$3:CT$6) -> 0 | CU8: =SUM(CU$3:CU$6) -> 0 | CV8: =SUM(CV$3:CV$6) -> 0 | CW8: =SUM(CW$3:CW$6) -> 0 | CY8: =SUM(CY$3:CY$6) -> 0 | CZ8: =SUM(CZ$3:CZ$6) -> 0 | DA8: =SUM(DA$3:DA$6) -> 0 | DB8: =SUM(DB$3:DB$6) -> 0 | DC8: =SUM(DC$3:DC$6) -> 0 | DI8: =SUM(DI$3:DI$6) -> 0 | DJ8: =SUM(DJ$3:DJ$6) -> 0 | DK8: =SUM(DK$3:DK$6) -> 0 | DM8: =SUM(DM$3:DM$6) -> 0 | DN8: =SUM(DN$3:DN$6) -> 0 | DO8: =SUM(DO$3:DO$6) -> 0 | DP8: =SUM(DP$3:DP$6) -> 0 | DQ8: =SUM(DQ$3:DQ$6) -> 0 | DR8: =SUM(DR$3:DR$6) -> 0 | DT8: =SUM(DT$3:DT$6) -> 0 | DU8: =SUM(DU$3:DU$6) -> 0 | DV8: =SUM(DV$3:DV$6) -> 0 | DW8: =SUM(DW$3:DW$6) -> 0 | DX8: =SUM(DX$3:DX$6) -> 0 | DY8: =SUM(DY$3:DY$6) -> 0 | EA8: =SUM(EA$3:EA$6) -> 0 | EB8: =SUM(EB$3:EB$6) -> 0 | EC8: =SUM(EC$3:EC$6) -> 0 | ED8: =SUM(ED$3:ED$6) -> 0 | EE8: =SUM(EE$3:EE$6) -> 0 | EF8: =SUM(EF$3:EF$6) -> 0 | EH8: =SUM(EH$3:EH$6) -> 0 | EI8: =SUM(EI$3:EI$6) -> 0 | EJ8: =SUM(EJ$3:EJ$6) -> 0 | EK8: =SUM(EK$3:EK$6) -> 0 | EL8: =SUM(EL$3:EL$6) -> 0 | EM8: =SUM(EM$3:EM$6) -> 0 | EO8: =SUM(EO$3:EO$6) -> 0 | EP8: =SUM(EP$3:EP$6) -> 0 | EQ8: =SUM(EQ$3:EQ$6) -> 0 | ER8: =SUM(ER$3:ER$6) -> 0 | ES8: =SUM(ES$3:ES$6) -> 0 | ET8: =SUM(ET$3:ET$6) -> 0 | EV8: =SUM(EV$3:EV$6) -> 0 | EW8: =SUM(EW$3:EW$6) -> 0 | EX8: =SUM(EX$3:EX$6) -> 0 | EY8: =SUM(EY$3:EY$6) -> 0 | EZ8: =SUM(EZ$3:EZ$6) -> 0 | FA8: =SUM(FA$3:FA$6) -> 0 | FC8: =SUM(FC$3:FC$6) -> 0 | FD8: =SUM(FD$3:FD$6) -> 0 | FE8: =SUM(FE$3:FE$6) -> 0 | FF8: =SUM(FF$3:FF$6) -> 0 | FG8: =SUM(FG$3:FG$6) -> 0 | FH8: =SUM(FH$3:FH$6) -> 0 | FJ8: =SUM(FJ$3:FJ$6) -> 0 | FK8: =SUM(FK$3:FK$6) -> 0 | FL8: =SUM(FL$3:FL$6) -> 0 | FM8: =SUM(FM$3:FM$6) -> 0 | FN8: =SUM(FN$3:FN$6) -> 0 | FO8: =SUM(FO$3:FO$6) -> 0 | FQ8: =SUM(FQ$3:FQ$6) -> 0 | FR8: =SUM(FR$3:FR$6) -> 0 | FS8: =SUM(FS$3:FS$6) -> 0 | FT8: =SUM(FT$3:FT$6) -> 0 | FU8: =SUM(FU$3:FU$6) -> 0 | FV8: =SUM(FV$3:FV$6) -> 0 | FX8: =SUM(FX$3:FX$6) -> 0 | FY8: =SUM(FY$3:FY$6) -> 0 | FZ8: =SUM(FZ$3:FZ$6) -> 0 | GA8: =SUM(GA$3:GA$6) -> 0 | GB8: =SUM(GB$3:GB$6) -> 0 | GC8: =SUM(GC$3:GC$6) -> 0 | GE8: =SUM(GE$3:GE$6) -> 0 | GF8: =SUM(GF$3:GF$6) -> 0 | GG8: =SUM(GG$3:GG$6) -> 0 | GH8: =SUM(GH$3:GH$6) -> 0 | GI8: =SUM(GI$3:GI$6) -> 0 | GJ8: =SUM(GJ$3:GJ$6) -> 0 | GK8: =SUM(GK$3:GK$6) -> 0 | GL8: =SUM(GL$3:GL$6) -> 0 | ... GZ8: =SUM(GZ$3:GZ$6) -> 0
A9: AVG | B9: =AVERAGE(B$3:B$6) -> 0 | H9: =AVERAGE(H$3:H$6) -> 0 | I9: =AVERAGE(I$3:I$6) -> 0 | O9: =AVERAGE(O$3:O$6) -> 0 | P9: =AVERAGE(P$3:P$6) -> 0 | V9: =AVERAGE(V$3:V$6) -> 0 | W9: =AVERAGE(W$3:W$6) -> 0 | AC9: =AVERAGE(AC$3:AC$6) -> 0 | AD9: =AVERAGE(AD$3:AD$6) -> 0 | AJ9: =AVERAGE(AJ$3:AJ$6) -> 0 | AK9: =AVERAGE(AK$3:AK$6) -> 0 | AQ9: =AVERAGE(AQ$3:AQ$6) -> 0 | AR9: =AVERAGE(AR$3:AR$6) -> 0 | AX9: =AVERAGE(AX$3:AX$6) -> 0 | AY9: =AVERAGE(AY$3:AY$6) -> 0 | AZ9: =AVERAGE(AZ$3:AZ$6) -> 0 | BB9: =AVERAGE(BB$3:BB$6) -> 0 | BC9: =AVERAGE(BC$3:BC$6) -> 0 | BD9: =AVERAGE(BD$3:BD$6) -> 0 | BE9: =AVERAGE(BE$3:BE$6) -> 0 | BF9: =AVERAGE(BF$3:BF$6) -> 0 | BG9: =AVERAGE(BG$3:BG$6) -> 0 | BI9: =AVERAGE(BI$3:BI$6) -> 0 | BJ9: =AVERAGE(BJ$3:BJ$6) -> 0 | BK9: =AVERAGE(BK$3:BK$6) -> 0 | BL9: =AVERAGE(BL$3:BL$6) -> 0 | BM9: =AVERAGE(BM$3:BM$6) -> 0 | BN9: =AVERAGE(BN$3:BN$6) -> 0 | BP9: =AVERAGE(BP$3:BP$6) -> 0 | BQ9: =AVERAGE(BQ$3:BQ$6) -> 0 | BR9: =AVERAGE(BR$3:BR$6) -> 0 | BS9: =AVERAGE(BS$3:BS$6) -> 0 | BT9: =AVERAGE(BT$3:BT$6) -> 0 | BU9: =AVERAGE(BU$3:BU$6) -> 0 | BW9: =AVERAGE(BW$3:BW$6) -> 0 | BX9: =AVERAGE(BX$3:BX$6) -> 0 | BY9: =AVERAGE(BY$3:BY$6) -> 0 | BZ9: =AVERAGE(BZ$3:BZ$6) -> 0 | CA9: =AVERAGE(CA$3:CA$6) -> 0 | CB9: =AVERAGE(CB$3:CB$6) -> 0 | CD9: =AVERAGE(CD$3:CD$6) -> 0 | CE9: =AVERAGE(CE$3:CE$6) -> 0 | CF9: =AVERAGE(CF$3:CF$6) -> 0 | CG9: =AVERAGE(CG$3:CG$6) -> 0 | CH9: =AVERAGE(CH$3:CH$6) -> 0 | CN9: =AVERAGE(CN$3:CN$6) -> 0 | CO9: =AVERAGE(CO$3:CO$6) -> 0 | CP9: =AVERAGE(CP$3:CP$6) -> 0 | CR9: =AVERAGE(CR$3:CR$6) -> 0 | CS9: =AVERAGE(CS$3:CS$6) -> 0 | CT9: =AVERAGE(CT$3:CT$6) -> 0 | CU9: =AVERAGE(CU$3:CU$6) -> 0 | CV9: =AVERAGE(CV$3:CV$6) -> 0 | CW9: =AVERAGE(CW$3:CW$6) -> 0 | CY9: =AVERAGE(CY$3:CY$6) -> 0 | CZ9: =AVERAGE(CZ$3:CZ$6) -> 0 | DA9: =AVERAGE(DA$3:DA$6) -> 0 | DB9: =AVERAGE(DB$3:DB$6) -> 0 | DC9: =AVERAGE(DC$3:DC$6) -> 0 | DI9: =AVERAGE(DI$3:DI$6) -> 0 | DJ9: =AVERAGE(DJ$3:DJ$6) -> 0 | DK9: =AVERAGE(DK$3:DK$6) -> 0 | DM9: =AVERAGE(DM$3:DM$6) -> 0 | DN9: =AVERAGE(DN$3:DN$6) -> 0 | DO9: =AVERAGE(DO$3:DO$6) -> 0 | DP9: =AVERAGE(DP$3:DP$6) -> 0 | DQ9: =AVERAGE(DQ$3:DQ$6) -> 0 | DR9: =AVERAGE(DR$3:DR$6) -> 0 | DT9: =AVERAGE(DT$3:DT$6) -> 0 | DU9: =AVERAGE(DU$3:DU$6) -> 0 | DV9: =AVERAGE(DV$3:DV$6) -> 0 | DW9: =AVERAGE(DW$3:DW$6) -> 0 | DX9: =AVERAGE(DX$3:DX$6) -> 0 | DY9: =AVERAGE(DY$3:DY$6) -> 0 | EA9: =AVERAGE(EA$3:EA$6) -> 0 | EB9: =AVERAGE(EB$3:EB$6) -> 0 | EC9: =AVERAGE(EC$3:EC$6) -> 0 | ED9: =AVERAGE(ED$3:ED$6) -> 0 | EE9: =AVERAGE(EE$3:EE$6) -> 0 | EF9: =AVERAGE(EF$3:EF$6) -> 0 | EH9: =AVERAGE(EH$3:EH$6) -> 0 | EI9: =AVERAGE(EI$3:EI$6) -> 0 | EJ9: =AVERAGE(EJ$3:EJ$6) -> 0 | EK9: =AVERAGE(EK$3:EK$6) -> 0 | EL9: =AVERAGE(EL$3:EL$6) -> 0 | EM9: =AVERAGE(EM$3:EM$6) -> 0 | EO9: =AVERAGE(EO$3:EO$6) -> 0 | EP9: =AVERAGE(EP$3:EP$6) -> 0 | EQ9: =AVERAGE(EQ$3:EQ$6) -> 0 | ER9: =AVERAGE(ER$3:ER$6) -> 0 | ES9: =AVERAGE(ES$3:ES$6) -> 0 | ET9: =AVERAGE(ET$3:ET$6) -> 0 | EV9: =AVERAGE(EV$3:EV$6) -> 0 | EW9: =AVERAGE(EW$3:EW$6) -> 0 | EX9: =AVERAGE(EX$3:EX$6) -> 0 | EY9: =AVERAGE(EY$3:EY$6) -> 0 | EZ9: =AVERAGE(EZ$3:EZ$6) -> 0 | FA9: =AVERAGE(FA$3:FA$6) -> 0 | FC9: =AVERAGE(FC$3:FC$6) -> 0 | FD9: =AVERAGE(FD$3:FD$6) -> 0 | FE9: =AVERAGE(FE$3:FE$6) -> 0 | FF9: =AVERAGE(FF$3:FF$6) -> 0 | FG9: =AVERAGE(FG$3:FG$6) -> 0 | FH9: =AVERAGE(FH$3:FH$6) -> 0 | FJ9: =AVERAGE(FJ$3:FJ$6) -> 0 | FK9: =AVERAGE(FK$3:FK$6) -> 0 | FL9: =AVERAGE(FL$3:FL$6) -> 0 | FM9: =AVERAGE(FM$3:FM$6) -> 0 | FN9: =AVERAGE(FN$3:FN$6) -> 0 | FO9: =AVERAGE(FO$3:FO$6) -> 0 | FQ9: =AVERAGE(FQ$3:FQ$6) -> 0 | FR9: =AVERAGE(FR$3:FR$6) -> 0 | FS9: =AVERAGE(FS$3:FS$6) -> 0 | FT9: =AVERAGE(FT$3:FT$6) -> 0 | FU9: =AVERAGE(FU$3:FU$6) -> 0 | FV9: =AVERAGE(FV$3:FV$6) -> 0 | FX9: =AVERAGE(FX$3:FX$6) -> 0 | FY9: =AVERAGE(FY$3:FY$6) -> 0 | FZ9: =AVERAGE(FZ$3:FZ$6) -> 0 | GA9: =AVERAGE(GA$3:GA$6) -> 0 | GB9: =AVERAGE(GB$3:GB$6) -> 0 | GC9: =AVERAGE(GC$3:GC$6) -> 0 | GE9: =AVERAGE(GE$3:GE$6) -> 0 | GF9: =AVERAGE(GF$3:GF$6) -> 0 | GG9: =AVERAGE(GG$3:GG$6) -> 0 | GH9: =AVERAGE(GH$3:GH$6) -> 0 | GI9: =AVERAGE(GI$3:GI$6) -> 0 | GJ9: =AVERAGE(GJ$3:GJ$6) -> 0 | GK9: =AVERAGE(GK$3:GK$6) -> 0 | GL9: =AVERAGE(GL$3:GL$6) -> 0 | ... GZ9: =AVERAGE(GZ$3:GZ$6) -> 0
A10: DEV | B10: =STDEV(B$3:B$6) -> 0 | H10: =STDEV(H$3:H$6) -> 0 | I10: =STDEV(I$3:I$6) -> 0 | O10: =STDEV(O$3:O$6) -> 0 | P10: =STDEV(P$3:P$6) -> 0 | V10: =STDEV(V$3:V$6) -> 0 | W10: =STDEV(W$3:W$6) -> 0 | AC10: =STDEV(AC$3:AC$6) -> 0 | AD10: =STDEV(AD$3:AD$6) -> 0 | AJ10: =STDEV(AJ$3:AJ$6) -> 0 | AK10: =STDEV(AK$3:AK$6) -> 0 | AQ10: =STDEV(AQ$3:AQ$6) -> 0 | AR10: =STDEV(AR$3:AR$6) -> 0 | AX10: =STDEV(AX$3:AX$6) -> 0 | AY10: =STDEV(AY$3:AY$6) -> 0 | AZ10: =STDEV(AZ$3:AZ$6) -> 0 | BB10: =STDEV(BB$3:BB$6) -> 0 | BC10: =STDEV(BC$3:BC$6) -> 0 | BD10: =STDEV(BD$3:BD$6) -> 0 | BE10: =STDEV(BE$3:BE$6) -> 0 | BF10: =STDEV(BF$3:BF$6) -> 0 | BG10: =STDEV(BG$3:BG$6) -> 0 | BI10: =STDEV(BI$3:BI$6) -> 0 | BJ10: =STDEV(BJ$3:BJ$6) -> 0 | BK10: =STDEV(BK$3:BK$6) -> 0 | BL10: =STDEV(BL$3:BL$6) -> 0 | BM10: =STDEV(BM$3:BM$6) -> 0 | BN10: =STDEV(BN$3:BN$6) -> 0 | BP10: =STDEV(BP$3:BP$6) -> 0 | BQ10: =STDEV(BQ$3:BQ$6) -> 0 | BR10: =STDEV(BR$3:BR$6) -> 0 | BS10: =STDEV(BS$3:BS$6) -> 0 | BT10: =STDEV(BT$3:BT$6) -> 0 | BU10: =STDEV(BU$3:BU$6) -> 0 | BW10: =STDEV(BW$3:BW$6) -> 0 | BX10: =STDEV(BX$3:BX$6) -> 0 | BY10: =STDEV(BY$3:BY$6) -> 0 | BZ10: =STDEV(BZ$3:BZ$6) -> 0 | CA10: =STDEV(CA$3:CA$6) -> 0 | CB10: =STDEV(CB$3:CB$6) -> 0 | CD10: =STDEV(CD$3:CD$6) -> 0 | CE10: =STDEV(CE$3:CE$6) -> 0 | CF10: =STDEV(CF$3:CF$6) -> 0 | CG10: =STDEV(CG$3:CG$6) -> 0 | CH10: =STDEV(CH$3:CH$6) -> 0 | CN10: =STDEV(CN$3:CN$6) -> 0 | CO10: =STDEV(CO$3:CO$6) -> 0 | CP10: =STDEV(CP$3:CP$6) -> 0 | CR10: =STDEV(CR$3:CR$6) -> 0 | CS10: =STDEV(CS$3:CS$6) -> 0 | CT10: =STDEV(CT$3:CT$6) -> 0 | CU10: =STDEV(CU$3:CU$6) -> 0 | CV10: =STDEV(CV$3:CV$6) -> 0 | CW10: =STDEV(CW$3:CW$6) -> 0 | CY10: =STDEV(CY$3:CY$6) -> 0 | CZ10: =STDEV(CZ$3:CZ$6) -> 0 | DA10: =STDEV(DA$3:DA$6) -> 0 | DB10: =STDEV(DB$3:DB$6) -> 0 | DC10: =STDEV(DC$3:DC$6) -> 0 | DI10: =STDEV(DI$3:DI$6) -> 0 | DJ10: =STDEV(DJ$3:DJ$6) -> 0 | DK10: =STDEV(DK$3:DK$6) -> 0 | DM10: =STDEV(DM$3:DM$6) -> 0 | DN10: =STDEV(DN$3:DN$6) -> 0 | DO10: =STDEV(DO$3:DO$6) -> 0 | DP10: =STDEV(DP$3:DP$6) -> 0 | DQ10: =STDEV(DQ$3:DQ$6) -> 0 | DR10: =STDEV(DR$3:DR$6) -> 0 | DT10: =STDEV(DT$3:DT$6) -> 0 | DU10: =STDEV(DU$3:DU$6) -> 0 | DV10: =STDEV(DV$3:DV$6) -> 0 | DW10: =STDEV(DW$3:DW$6) -> 0 | DX10: =STDEV(DX$3:DX$6) -> 0 | DY10: =STDEV(DY$3:DY$6) -> 0 | EA10: =STDEV(EA$3:EA$6) -> 0 | EB10: =STDEV(EB$3:EB$6) -> 0 | EC10: =STDEV(EC$3:EC$6) -> 0 | ED10: =STDEV(ED$3:ED$6) -> 0 | EE10: =STDEV(EE$3:EE$6) -> 0 | EF10: =STDEV(EF$3:EF$6) -> 0 | EH10: =STDEV(EH$3:EH$6) -> 0 | EI10: =STDEV(EI$3:EI$6) -> 0 | EJ10: =STDEV(EJ$3:EJ$6) -> 0 | EK10: =STDEV(EK$3:EK$6) -> 0 | EL10: =STDEV(EL$3:EL$6) -> 0 | EM10: =STDEV(EM$3:EM$6) -> 0 | EO10: =STDEV(EO$3:EO$6) -> 0 | EP10: =STDEV(EP$3:EP$6) -> 0 | EQ10: =STDEV(EQ$3:EQ$6) -> 0 | ER10: =STDEV(ER$3:ER$6) -> 0 | ES10: =STDEV(ES$3:ES$6) -> 0 | ET10: =STDEV(ET$3:ET$6) -> 0 | EV10: =STDEV(EV$3:EV$6) -> 0 | EW10: =STDEV(EW$3:EW$6) -> 0 | EX10: =STDEV(EX$3:EX$6) -> 0 | EY10: =STDEV(EY$3:EY$6) -> 0 | EZ10: =STDEV(EZ$3:EZ$6) -> 0 | FA10: =STDEV(FA$3:FA$6) -> 0 | FC10: =STDEV(FC$3:FC$6) -> 0 | FD10: =STDEV(FD$3:FD$6) -> 0 | FE10: =STDEV(FE$3:FE$6) -> 0 | FF10: =STDEV(FF$3:FF$6) -> 0 | FG10: =STDEV(FG$3:FG$6) -> 0 | FH10: =STDEV(FH$3:FH$6) -> 0 | FJ10: =STDEV(FJ$3:FJ$6) -> 0 | FK10: =STDEV(FK$3:FK$6) -> 0 | FL10: =STDEV(FL$3:FL$6) -> 0 | FM10: =STDEV(FM$3:FM$6) -> 0 | FN10: =STDEV(FN$3:FN$6) -> 0 | FO10: =STDEV(FO$3:FO$6) -> 0 | FQ10: =STDEV(FQ$3:FQ$6) -> 0 | FR10: =STDEV(FR$3:FR$6) -> 0 | FS10: =STDEV(FS$3:FS$6) -> 0 | FT10: =STDEV(FT$3:FT$6) -> 0 | FU10: =STDEV(FU$3:FU$6) -> 0 | FV10: =STDEV(FV$3:FV$6) -> 0 | FX10: =STDEV(FX$3:FX$6) -> 0 | FY10: =STDEV(FY$3:FY$6) -> 0 | FZ10: =STDEV(FZ$3:FZ$6) -> 0 | GA10: =STDEV(GA$3:GA$6) -> 0 | GB10: =STDEV(GB$3:GB$6) -> 0 | GC10: =STDEV(GC$3:GC$6) -> 0 | GE10: =STDEV(GE$3:GE$6) -> 0 | GF10: =STDEV(GF$3:GF$6) -> 0 | GG10: =STDEV(GG$3:GG$6) -> 0 | GH10: =STDEV(GH$3:GH$6) -> 0 | GI10: =STDEV(GI$3:GI$6) -> 0 | GJ10: =STDEV(GJ$3:GJ$6) -> 0 | GK10: =STDEV(GK$3:GK$6) -> 0 | GL10: =STDEV(GL$3:GL$6) -> 0 | ... GZ10: =STDEV(GZ$3:GZ$6) -> 0
A11: DST | B11: =SUMPRODUCT(--(B$3:B$6-$GI$3:$GI$6)^2)^0.5 -> 0 | H11: =SUMPRODUCT(--(H$3:H$6-$GN$3:$GN$6)^2)^0.5 -> 0 | I11: =SUMPRODUCT(--(I$3:I$6-$GI$3:$GI$6)^2)^0.5 -> 0 | O11: =SUMPRODUCT(--(O$3:O$6-$GN$3:$GN$6)^2)^0.5 -> 0 | P11: =SUMPRODUCT(--(P$3:P$6-$GI$3:$GI$6)^2)^0.5 -> 0 | V11: =SUMPRODUCT(--(V$3:V$6-$GN$3:$GN$6)^2)^0.5 -> 0 | W11: =SUMPRODUCT(--(W$3:W$6-$GI$3:$GI$6)^2)^0.5 -> 0 | AC11: =SUMPRODUCT(--(AC$3:AC$6-$GN$3:$GN$6)^2)^0.5 -> 0 | AD11: =SUMPRODUCT(--(AD$3:AD$6-$GI$3:$GI$6)^2)^0.5 -> 0 | AJ11: =SUMPRODUCT(--(AJ$3:AJ$6-$GN$3:$GN$6)^2)^0.5 -> 0 | AK11: =SUMPRODUCT(--(AK$3:AK$6-$GI$3:$GI$6)^2)^0.5 -> 0 | AQ11: =SUMPRODUCT(--(AQ$3:AQ$6-$GN$3:$GN$6)^2)^0.5 -> 0 | AR11: =SUMPRODUCT(--(AR$3:AR$6-$GI$3:$GI$6)^2)^0.5 -> 0 | AX11: =SUMPRODUCT(--(AX$3:AX$6-$GN$3:$GN$6)^2)^0.5 -> 0 | AY11: =SUMPRODUCT(--(AY$3:AY$6-$GI$3:$GI$6)^2)^0.5 -> 0 | AZ11: =SUMPRODUCT(--(AZ$3:AZ$6-$GJ$3:$GJ$6)^2)^0.5 -> 0 | BB11: =SUMPRODUCT(--(BB$3:BB$6-$GK$3:$GK$6)^2)^0.5 -> 0 | BC11: =SUMPRODUCT(--(BC$3:BC$6-$GL$3:$GL$6)^2)^0.5 -> 0 | BD11: =SUMPRODUCT(--(BD$3:BD$6-$GM$3:$GM$6)^2)^0.5 -> 0 | BE11: =SUMPRODUCT(--(BE$3:BE$6-$GN$3:$GN$6)^2)^0.5 -> 0 | BF11: =SUMPRODUCT(--(BF$3:BF$6-$GI$3:$GI$6)^2)^0.5 -> 0 | BG11: =SUMPRODUCT(--(BG$3:BG$6-$GJ$3:$GJ$6)^2)^0.5 -> 0 | BI11: =SUMPRODUCT(--(BI$3:BI$6-$GK$3:$GK$6)^2)^0.5 -> 0 | BJ11: =SUMPRODUCT(--(BJ$3:BJ$6-$GL$3:$GL$6)^2)^0.5 -> 0 | BK11: =SUMPRODUCT(--(BK$3:BK$6-$GM$3:$GM$6)^2)^0.5 -> 0 | BL11: =SUMPRODUCT(--(BL$3:BL$6-$GN$3:$GN$6)^2)^0.5 -> 0 | BM11: =SUMPRODUCT(--(BM$3:BM$6-$GI$3:$GI$6)^2)^0.5 -> 0 | BN11: =SUMPRODUCT(--(BN$3:BN$6-$GJ$3:$GJ$6)^2)^0.5 -> 0 | BP11: =SUMPRODUCT(--(BP$3:BP$6-$GK$3:$GK$6)^2)^0.5 -> 0 | BQ11: =SUMPRODUCT(--(BQ$3:BQ$6-$GL$3:$GL$6)^2)^0.5 -> 0 | BR11: =SUMPRODUCT(--(BR$3:BR$6-$GM$3:$GM$6)^2)^0.5 -> 0 | BS11: =SUMPRODUCT(--(BS$3:BS$6-$GN$3:$GN$6)^2)^0.5 -> 0 | BT11: =SUMPRODUCT(--(BT$3:BT$6-$GI$3:$GI$6)^2)^0.5 -> 0 | BU11: =SUMPRODUCT(--(BU$3:BU$6-$GJ$3:$GJ$6)^2)^0.5 -> 0 | BW11: =SUMPRODUCT(--(BW$3:BW$6-$GK$3:$GK$6)^2)^0.5 -> 0 | BX11: =SUMPRODUCT(--(BX$3:BX$6-$GL$3:$GL$6)^2)^0.5 -> 0 | BY11: =SUMPRODUCT(--(BY$3:BY$6-$GM$3:$GM$6)^2)^0.5 -> 0 | BZ11: =SUMPRODUCT(--(BZ$3:BZ$6-$GN$3:$GN$6)^2)^0.5 -> 0 | CA11: =SUMPRODUCT(--(CA$3:CA$6-$GI$3:$GI$6)^2)^0.5 -> 0 | CB11: =SUMPRODUCT(--(CB$3:CB$6-$GJ$3:$GJ$6)^2)^0.5 -> 0 | CD11: =SUMPRODUCT(--(CD$3:CD$6-$GK$3:$GK$6)^2)^0.5 -> 0 | CE11: =SUMPRODUCT(--(CE$3:CE$6-$GL$3:$GL$6)^2)^0.5 -> 0 | CF11: =SUMPRODUCT(--(CF$3:CF$6-$GM$3:$GM$6)^2)^0.5 -> 0 | CG11: =SUMPRODUCT(--(CG$3:CG$6-$GN$3:$GN$6)^2)^0.5 -> 0 | CH11: =SUMPRODUCT(--(CH$3:CH$6-$GI$3:$GI$6)^2)^0.5 -> 0 | CN11: =SUMPRODUCT(--(CN$3:CN$6-$GN$3:$GN$6)^2)^0.5 -> 0 | CO11: =SUMPRODUCT(--(CO$3:CO$6-$GI$3:$GI$6)^2)^0.5 -> 0 | CP11: =SUMPRODUCT(--(CP$3:CP$6-$GJ$3:$GJ$6)^2)^0.5 -> 0 | CR11: =SUMPRODUCT(--(CR$3:CR$6-$GK$3:$GK$6)^2)^0.5 -> 0 | CS11: =SUMPRODUCT(--(CS$3:CS$6-$GL$3:$GL$6)^2)^0.5 -> 0 | CT11: =SUMPRODUCT(--(CT$3:CT$6-$GM$3:$GM$6)^2)^0.5 -> 0 | CU11: =SUMPRODUCT(--(CU$3:CU$6-$GN$3:$GN$6)^2)^0.5 -> 0 | CV11: =SUMPRODUCT(--(CV$3:CV$6-$GI$3:$GI$6)^2)^0.5 -> 0 | CW11: =SUMPRODUCT(--(CW$3:CW$6-$GJ$3:$GJ$6)^2)^0.5 -> 0 | CY11: =SUMPRODUCT(--(CY$3:CY$6-$GK$3:$GK$6)^2)^0.5 -> 0 | CZ11: =SUMPRODUCT(--(CZ$3:CZ$6-$GL$3:$GL$6)^2)^0.5 -> 0 | DA11: =SUMPRODUCT(--(DA$3:DA$6-$GM$3:$GM$6)^2)^0.5 -> 0 | DB11: =SUMPRODUCT(--(DB$3:DB$6-$GN$3:$GN$6)^2)^0.5 -> 0 | DC11: =SUMPRODUCT(--(DC$3:DC$6-$GI$3:$GI$6)^2)^0.5 -> 0 | DI11: =SUMPRODUCT(--(DI$3:DI$6-$GN$3:$GN$6)^2)^0.5 -> 0 | DJ11: =SUMPRODUCT(--(DJ$3:DJ$6-$GI$3:$GI$6)^2)^0.5 -> 0 | DK11: =SUMPRODUCT(--(DK$3:DK$6-$GJ$3:$GJ$6)^2)^0.5 -> 0 | DM11: =SUMPRODUCT(--(DM$3:DM$6-$GK$3:$GK$6)^2)^0.5 -> 0 | DN11: =SUMPRODUCT(--(DN$3:DN$6-$GL$3:$GL$6)^2)^0.5 -> 0 | DO11: =SUMPRODUCT(--(DO$3:DO$6-$GM$3:$GM$6)^2)^0.5 -> 0 | DP11: =SUMPRODUCT(--(DP$3:DP$6-$GN$3:$GN$6)^2)^0.5 -> 0 | DQ11: =SUMPRODUCT(--(DQ$3:DQ$6-$GI$3:$GI$6)^2)^0.5 -> 0 | DR11: =SUMPRODUCT(--(DR$3:DR$6-$GJ$3:$GJ$6)^2)^0.5 -> 0 | DT11: =SUMPRODUCT(--(DT$3:DT$6-$GK$3:$GK$6)^2)^0.5 -> 0 | DU11: =SUMPRODUCT(--(DU$3:DU$6-$GL$3:$GL$6)^2)^0.5 -> 0 | DV11: =SUMPRODUCT(--(DV$3:DV$6-$GM$3:$GM$6)^2)^0.5 -> 0 | DW11: =SUMPRODUCT(--(DW$3:DW$6-$GN$3:$GN$6)^2)^0.5 -> 0 | DX11: =SUMPRODUCT(--(DX$3:DX$6-$GI$3:$GI$6)^2)^0.5 -> 0 | DY11: =SUMPRODUCT(--(DY$3:DY$6-$GJ$3:$GJ$6)^2)^0.5 -> 0 | EA11: =SUMPRODUCT(--(EA$3:EA$6-$GK$3:$GK$6)^2)^0.5 -> 0 | EB11: =SUMPRODUCT(--(EB$3:EB$6-$GL$3:$GL$6)^2)^0.5 -> 0 | EC11: =SUMPRODUCT(--(EC$3:EC$6-$GM$3:$GM$6)^2)^0.5 -> 0 | ED11: =SUMPRODUCT(--(ED$3:ED$6-$GN$3:$GN$6)^2)^0.5 -> 0 | EE11: =SUMPRODUCT(--(EE$3:EE$6-$GI$3:$GI$6)^2)^0.5 -> 0 | EF11: =SUMPRODUCT(--(EF$3:EF$6-$GJ$3:$GJ$6)^2)^0.5 -> 0 | EH11: =SUMPRODUCT(--(EH$3:EH$6-$GK$3:$GK$6)^2)^0.5 -> 0 | EI11: =SUMPRODUCT(--(EI$3:EI$6-$GL$3:$GL$6)^2)^0.5 -> 0 | EJ11: =SUMPRODUCT(--(EJ$3:EJ$6-$GM$3:$GM$6)^2)^0.5 -> 0 | EK11: =SUMPRODUCT(--(EK$3:EK$6-$GN$3:$GN$6)^2)^0.5 -> 0 | EL11: =SUMPRODUCT(--(EL$3:EL$6-$GI$3:$GI$6)^2)^0.5 -> 0 | EM11: =SUMPRODUCT(--(EM$3:EM$6-$GJ$3:$GJ$6)^2)^0.5 -> 0 | EO11: =SUMPRODUCT(--(EO$3:EO$6-$GK$3:$GK$6)^2)^0.5 -> 0 | EP11: =SUMPRODUCT(--(EP$3:EP$6-$GL$3:$GL$6)^2)^0.5 -> 0 | EQ11: =SUMPRODUCT(--(EQ$3:EQ$6-$GM$3:$GM$6)^2)^0.5 -> 0 | ER11: =SUMPRODUCT(--(ER$3:ER$6-$GN$3:$GN$6)^2)^0.5 -> 0 | ES11: =SUMPRODUCT(--(ES$3:ES$6-$GI$3:$GI$6)^2)^0.5 -> 0 | ET11: =SUMPRODUCT(--(ET$3:ET$6-$GJ$3:$GJ$6)^2)^0.5 -> 0 | EV11: =SUMPRODUCT(--(EV$3:EV$6-$GK$3:$GK$6)^2)^0.5 -> 0 | EW11: =SUMPRODUCT(--(EW$3:EW$6-$GL$3:$GL$6)^2)^0.5 -> 0 | EX11: =SUMPRODUCT(--(EX$3:EX$6-$GM$3:$GM$6)^2)^0.5 -> 0 | EY11: =SUMPRODUCT(--(EY$3:EY$6-$GN$3:$GN$6)^2)^0.5 -> 0 | EZ11: =SUMPRODUCT(--(EZ$3:EZ$6-$GI$3:$GI$6)^2)^0.5 -> 0 | FA11: =SUMPRODUCT(--(FA$3:FA$6-$GJ$3:$GJ$6)^2)^0.5 -> 0 | FC11: =SUMPRODUCT(--(FC$3:FC$6-$GK$3:$GK$6)^2)^0.5 -> 0 | FD11: =SUMPRODUCT(--(FD$3:FD$6-$GL$3:$GL$6)^2)^0.5 -> 0 | FE11: =SUMPRODUCT(--(FE$3:FE$6-$GM$3:$GM$6)^2)^0.5 -> 0 | FF11: =SUMPRODUCT(--(FF$3:FF$6-$GN$3:$GN$6)^2)^0.5 -> 0 | FG11: =SUMPRODUCT(--(FG$3:FG$6-$GI$3:$GI$6)^2)^0.5 -> 0 | FH11: =SUMPRODUCT(--(FH$3:FH$6-$GJ$3:$GJ$6)^2)^0.5 -> 0 | FJ11: =SUMPRODUCT(--(FJ$3:FJ$6-$GK$3:$GK$6)^2)^0.5 -> 0 | FK11: =SUMPRODUCT(--(FK$3:FK$6-$GL$3:$GL$6)^2)^0.5 -> 0 | FL11: =SUMPRODUCT(--(FL$3:FL$6-$GM$3:$GM$6)^2)^0.5 -> 0 | FM11: =SUMPRODUCT(--(FM$3:FM$6-$GN$3:$GN$6)^2)^0.5 -> 0 | FN11: =SUMPRODUCT(--(FN$3:FN$6-$GI$3:$GI$6)^2)^0.5 -> 0 | FO11: =SUMPRODUCT(--(FO$3:FO$6-$GJ$3:$GJ$6)^2)^0.5 -> 0 | FQ11: =SUMPRODUCT(--(FQ$3:FQ$6-$GK$3:$GK$6)^2)^0.5 -> 0 | FR11: =SUMPRODUCT(--(FR$3:FR$6-$GL$3:$GL$6)^2)^0.5 -> 0 | FS11: =SUMPRODUCT(--(FS$3:FS$6-$GM$3:$GM$6)^2)^0.5 -> 0 | FT11: =SUMPRODUCT(--(FT$3:FT$6-$GN$3:$GN$6)^2)^0.5 -> 0 | FU11: =SUMPRODUCT(--(FU$3:FU$6-$GI$3:$GI$6)^2)^0.5 -> 0 | FV11: =SUMPRODUCT(--(FV$3:FV$6-$GJ$3:$GJ$6)^2)^0.5 -> 0 | FX11: =SUMPRODUCT(--(FX$3:FX$6-$GK$3:$GK$6)^2)^0.5 -> 0 | FY11: =SUMPRODUCT(--(FY$3:FY$6-$GL$3:$GL$6)^2)^0.5 -> 0 | FZ11: =SUMPRODUCT(--(FZ$3:FZ$6-$GM$3:$GM$6)^2)^0.5 -> 0 | GA11: =SUMPRODUCT(--(GA$3:GA$6-$GN$3:$GN$6)^2)^0.5 -> 0 | GB11: =SUMPRODUCT(--(GB$3:GB$6-$GI$3:$GI$6)^2)^0.5 -> 0 | GC11: =SUMPRODUCT(--(GC$3:GC$6-$GJ$3:$GJ$6)^2)^0.5 -> 0 | GE11: =SUMPRODUCT(--(GE$3:GE$6-$GK$3:$GK$6)^2)^0.5 -> 0 | GF11: =SUMPRODUCT(--(GF$3:GF$6-$GL$3:$GL$6)^2)^0.5 -> 0 | GG11: =SUMPRODUCT(--(GG$3:GG$6-$GM$3:$GM$6)^2)^0.5 -> 0 | GH11: =SUMPRODUCT(--(GH$3:GH$6-$GN$3:$GN$6)^2)^0.5 -> 0
A12: BEST | B12: =SUMPRODUCT(NOT(ISBLANK(B$3:B$6))*(B$3:B$6=$GI$3:$GI$6)) -> 0 | H12: =SUMPRODUCT(NOT(ISBLANK(H$3:H$6))*(H$3:H$6=$GN$3:$GN$6)) -> 0 | I12: =SUMPRODUCT(NOT(ISBLANK(I$3:I$6))*(I$3:I$6=$GI$3:$GI$6)) -> 0 | O12: =SUMPRODUCT(NOT(ISBLANK(O$3:O$6))*(O$3:O$6=$GN$3:$GN$6)) -> 0 | P12: =SUMPRODUCT(NOT(ISBLANK(P$3:P$6))*(P$3:P$6=$GI$3:$GI$6)) -> 0 | V12: =SUMPRODUCT(NOT(ISBLANK(V$3:V$6))*(V$3:V$6=$GN$3:$GN$6)) -> 0 | W12: =SUMPRODUCT(NOT(ISBLANK(W$3:W$6))*(W$3:W$6=$GI$3:$GI$6)) -> 0 | AC12: =SUMPRODUCT(NOT(ISBLANK(AC$3:AC$6))*(AC$3:AC$6=$GN$3:$GN$6)) -> 0 | AD12: =SUMPRODUCT(NOT(ISBLANK(AD$3:AD$6))*(AD$3:AD$6=$GI$3:$GI$6)) -> 0 | AJ12: =SUMPRODUCT(NOT(ISBLANK(AJ$3:AJ$6))*(AJ$3:AJ$6=$GN$3:$GN$6)) -> 0 | AK12: =SUMPRODUCT(NOT(ISBLANK(AK$3:AK$6))*(AK$3:AK$6=$GI$3:$GI$6)) -> 0 | AQ12: =SUMPRODUCT(NOT(ISBLANK(AQ$3:AQ$6))*(AQ$3:AQ$6=$GN$3:$GN$6)) -> 0 | AR12: =SUMPRODUCT(NOT(ISBLANK(AR$3:AR$6))*(AR$3:AR$6=$GI$3:$GI$6)) -> 0 | AX12: =SUMPRODUCT(NOT(ISBLANK(AX$3:AX$6))*(AX$3:AX$6=$GN$3:$GN$6)) -> 0 | AY12: =SUMPRODUCT(NOT(ISBLANK(AY$3:AY$6))*(AY$3:AY$6=$GI$3:$GI$6)) -> 0 | AZ12: =SUMPRODUCT(NOT(ISBLANK(AZ$3:AZ$6))*(AZ$3:AZ$6=$GJ$3:$GJ$6)) -> 0 | BB12: =SUMPRODUCT(NOT(ISBLANK(BB$3:BB$6))*(BB$3:BB$6=$GK$3:$GK$6)) -> 0 | BC12: =SUMPRODUCT(NOT(ISBLANK(BC$3:BC$6))*(BC$3:BC$6=$GL$3:$GL$6)) -> 0 | BD12: =SUMPRODUCT(NOT(ISBLANK(BD$3:BD$6))*(BD$3:BD$6=$GM$3:$GM$6)) -> 0 | BE12: =SUMPRODUCT(NOT(ISBLANK(BE$3:BE$6))*(BE$3:BE$6=$GN$3:$GN$6)) -> 0 | BF12: =SUMPRODUCT(NOT(ISBLANK(BF$3:BF$6))*(BF$3:BF$6=$GI$3:$GI$6)) -> 0 | BG12: =SUMPRODUCT(NOT(ISBLANK(BG$3:BG$6))*(BG$3:BG$6=$GJ$3:$GJ$6)) -> 0 | BI12: =SUMPRODUCT(NOT(ISBLANK(BI$3:BI$6))*(BI$3:BI$6=$GK$3:$GK$6)) -> 0 | BJ12: =SUMPRODUCT(NOT(ISBLANK(BJ$3:BJ$6))*(BJ$3:BJ$6=$GL$3:$GL$6)) -> 0 | BK12: =SUMPRODUCT(NOT(ISBLANK(BK$3:BK$6))*(BK$3:BK$6=$GM$3:$GM$6)) -> 0 | BL12: =SUMPRODUCT(NOT(ISBLANK(BL$3:BL$6))*(BL$3:BL$6=$GN$3:$GN$6)) -> 0 | BM12: =SUMPRODUCT(NOT(ISBLANK(BM$3:BM$6))*(BM$3:BM$6=$GI$3:$GI$6)) -> 0 | BN12: =SUMPRODUCT(NOT(ISBLANK(BN$3:BN$6))*(BN$3:BN$6=$GJ$3:$GJ$6)) -> 0 | BP12: =SUMPRODUCT(NOT(ISBLANK(BP$3:BP$6))*(BP$3:BP$6=$GK$3:$GK$6)) -> 0 | BQ12: =SUMPRODUCT(NOT(ISBLANK(BQ$3:BQ$6))*(BQ$3:BQ$6=$GL$3:$GL$6)) -> 0 | BR12: =SUMPRODUCT(NOT(ISBLANK(BR$3:BR$6))*(BR$3:BR$6=$GM$3:$GM$6)) -> 0 | BS12: =SUMPRODUCT(NOT(ISBLANK(BS$3:BS$6))*(BS$3:BS$6=$GN$3:$GN$6)) -> 0 | BT12: =SUMPRODUCT(NOT(ISBLANK(BT$3:BT$6))*(BT$3:BT$6=$GI$3:$GI$6)) -> 0 | BU12: =SUMPRODUCT(NOT(ISBLANK(BU$3:BU$6))*(BU$3:BU$6=$GJ$3:$GJ$6)) -> 0 | BW12: =SUMPRODUCT(NOT(ISBLANK(BW$3:BW$6))*(BW$3:BW$6=$GK$3:$GK$6)) -> 0 | BX12: =SUMPRODUCT(NOT(ISBLANK(BX$3:BX$6))*(BX$3:BX$6=$GL$3:$GL$6)) -> 0 | BY12: =SUMPRODUCT(NOT(ISBLANK(BY$3:BY$6))*(BY$3:BY$6=$GM$3:$GM$6)) -> 0 | BZ12: =SUMPRODUCT(NOT(ISBLANK(BZ$3:BZ$6))*(BZ$3:BZ$6=$GN$3:$GN$6)) -> 0 | CA12: =SUMPRODUCT(NOT(ISBLANK(CA$3:CA$6))*(CA$3:CA$6=$GI$3:$GI$6)) -> 0 | CB12: =SUMPRODUCT(NOT(ISBLANK(CB$3:CB$6))*(CB$3:CB$6=$GJ$3:$GJ$6)) -> 0 | CD12: =SUMPRODUCT(NOT(ISBLANK(CD$3:CD$6))*(CD$3:CD$6=$GK$3:$GK$6)) -> 0 | CE12: =SUMPRODUCT(NOT(ISBLANK(CE$3:CE$6))*(CE$3:CE$6=$GL$3:$GL$6)) -> 0 | CF12: =SUMPRODUCT(NOT(ISBLANK(CF$3:CF$6))*(CF$3:CF$6=$GM$3:$GM$6)) -> 0 | CG12: =SUMPRODUCT(NOT(ISBLANK(CG$3:CG$6))*(CG$3:CG$6=$GN$3:$GN$6)) -> 0 | CH12: =SUMPRODUCT(NOT(ISBLANK(CH$3:CH$6))*(CH$3:CH$6=$GI$3:$GI$6)) -> 0 | CN12: =SUMPRODUCT(NOT(ISBLANK(CN$3:CN$6))*(CN$3:CN$6=$GN$3:$GN$6)) -> 0 | CO12: =SUMPRODUCT(NOT(ISBLANK(CO$3:CO$6))*(CO$3:CO$6=$GI$3:$GI$6)) -> 0 | CP12: =SUMPRODUCT(NOT(ISBLANK(CP$3:CP$6))*(CP$3:CP$6=$GJ$3:$GJ$6)) -> 0 | CR12: =SUMPRODUCT(NOT(ISBLANK(CR$3:CR$6))*(CR$3:CR$6=$GK$3:$GK$6)) -> 0 | CS12: =SUMPRODUCT(NOT(ISBLANK(CS$3:CS$6))*(CS$3:CS$6=$GL$3:$GL$6)) -> 0 | CT12: =SUMPRODUCT(NOT(ISBLANK(CT$3:CT$6))*(CT$3:CT$6=$GM$3:$GM$6)) -> 0 | CU12: =SUMPRODUCT(NOT(ISBLANK(CU$3:CU$6))*(CU$3:CU$6=$GN$3:$GN$6)) -> 0 | CV12: =SUMPRODUCT(NOT(ISBLANK(CV$3:CV$6))*(CV$3:CV$6=$GI$3:$GI$6)) -> 0 | CW12: =SUMPRODUCT(NOT(ISBLANK(CW$3:CW$6))*(CW$3:CW$6=$GJ$3:$GJ$6)) -> 0 | CY12: =SUMPRODUCT(NOT(ISBLANK(CY$3:CY$6))*(CY$3:CY$6=$GK$3:$GK$6)) -> 0 | CZ12: =SUMPRODUCT(NOT(ISBLANK(CZ$3:CZ$6))*(CZ$3:CZ$6=$GL$3:$GL$6)) -> 0 | DA12: =SUMPRODUCT(NOT(ISBLANK(DA$3:DA$6))*(DA$3:DA$6=$GM$3:$GM$6)) -> 0 | DB12: =SUMPRODUCT(NOT(ISBLANK(DB$3:DB$6))*(DB$3:DB$6=$GN$3:$GN$6)) -> 0 | DC12: =SUMPRODUCT(NOT(ISBLANK(DC$3:DC$6))*(DC$3:DC$6=$GI$3:$GI$6)) -> 0 | DI12: =SUMPRODUCT(NOT(ISBLANK(DI$3:DI$6))*(DI$3:DI$6=$GN$3:$GN$6)) -> 0 | DJ12: =SUMPRODUCT(NOT(ISBLANK(DJ$3:DJ$6))*(DJ$3:DJ$6=$GI$3:$GI$6)) -> 0 | DK12: =SUMPRODUCT(NOT(ISBLANK(DK$3:DK$6))*(DK$3:DK$6=$GJ$3:$GJ$6)) -> 0 | DM12: =SUMPRODUCT(NOT(ISBLANK(DM$3:DM$6))*(DM$3:DM$6=$GK$3:$GK$6)) -> 0 | DN12: =SUMPRODUCT(NOT(ISBLANK(DN$3:DN$6))*(DN$3:DN$6=$GL$3:$GL$6)) -> 0 | DO12: =SUMPRODUCT(NOT(ISBLANK(DO$3:DO$6))*(DO$3:DO$6=$GM$3:$GM$6)) -> 0 | DP12: =SUMPRODUCT(NOT(ISBLANK(DP$3:DP$6))*(DP$3:DP$6=$GN$3:$GN$6)) -> 0 | DQ12: =SUMPRODUCT(NOT(ISBLANK(DQ$3:DQ$6))*(DQ$3:DQ$6=$GI$3:$GI$6)) -> 0 | DR12: =SUMPRODUCT(NOT(ISBLANK(DR$3:DR$6))*(DR$3:DR$6=$GJ$3:$GJ$6)) -> 0 | DT12: =SUMPRODUCT(NOT(ISBLANK(DT$3:DT$6))*(DT$3:DT$6=$GK$3:$GK$6)) -> 0 | DU12: =SUMPRODUCT(NOT(ISBLANK(DU$3:DU$6))*(DU$3:DU$6=$GL$3:$GL$6)) -> 0 | DV12: =SUMPRODUCT(NOT(ISBLANK(DV$3:DV$6))*(DV$3:DV$6=$GM$3:$GM$6)) -> 0 | DW12: =SUMPRODUCT(NOT(ISBLANK(DW$3:DW$6))*(DW$3:DW$6=$GN$3:$GN$6)) -> 0 | DX12: =SUMPRODUCT(NOT(ISBLANK(DX$3:DX$6))*(DX$3:DX$6=$GI$3:$GI$6)) -> 0 | DY12: =SUMPRODUCT(NOT(ISBLANK(DY$3:DY$6))*(DY$3:DY$6=$GJ$3:$GJ$6)) -> 0 | EA12: =SUMPRODUCT(NOT(ISBLANK(EA$3:EA$6))*(EA$3:EA$6=$GK$3:$GK$6)) -> 0 | EB12: =SUMPRODUCT(NOT(ISBLANK(EB$3:EB$6))*(EB$3:EB$6=$GL$3:$GL$6)) -> 0 | EC12: =SUMPRODUCT(NOT(ISBLANK(EC$3:EC$6))*(EC$3:EC$6=$GM$3:$GM$6)) -> 0 | ED12: =SUMPRODUCT(NOT(ISBLANK(ED$3:ED$6))*(ED$3:ED$6=$GN$3:$GN$6)) -> 0 | EE12: =SUMPRODUCT(NOT(ISBLANK(EE$3:EE$6))*(EE$3:EE$6=$GI$3:$GI$6)) -> 0 | EF12: =SUMPRODUCT(NOT(ISBLANK(EF$3:EF$6))*(EF$3:EF$6=$GJ$3:$GJ$6)) -> 0 | EH12: =SUMPRODUCT(NOT(ISBLANK(EH$3:EH$6))*(EH$3:EH$6=$GK$3:$GK$6)) -> 0 | EI12: =SUMPRODUCT(NOT(ISBLANK(EI$3:EI$6))*(EI$3:EI$6=$GL$3:$GL$6)) -> 0 | EJ12: =SUMPRODUCT(NOT(ISBLANK(EJ$3:EJ$6))*(EJ$3:EJ$6=$GM$3:$GM$6)) -> 0 | EK12: =SUMPRODUCT(NOT(ISBLANK(EK$3:EK$6))*(EK$3:EK$6=$GN$3:$GN$6)) -> 0 | EL12: =SUMPRODUCT(NOT(ISBLANK(EL$3:EL$6))*(EL$3:EL$6=$GI$3:$GI$6)) -> 0 | EM12: =SUMPRODUCT(NOT(ISBLANK(EM$3:EM$6))*(EM$3:EM$6=$GJ$3:$GJ$6)) -> 0 | EO12: =SUMPRODUCT(NOT(ISBLANK(EO$3:EO$6))*(EO$3:EO$6=$GK$3:$GK$6)) -> 0 | EP12: =SUMPRODUCT(NOT(ISBLANK(EP$3:EP$6))*(EP$3:EP$6=$GL$3:$GL$6)) -> 0 | EQ12: =SUMPRODUCT(NOT(ISBLANK(EQ$3:EQ$6))*(EQ$3:EQ$6=$GM$3:$GM$6)) -> 0 | ER12: =SUMPRODUCT(NOT(ISBLANK(ER$3:ER$6))*(ER$3:ER$6=$GN$3:$GN$6)) -> 0 | ES12: =SUMPRODUCT(NOT(ISBLANK(ES$3:ES$6))*(ES$3:ES$6=$GI$3:$GI$6)) -> 0 | ET12: =SUMPRODUCT(NOT(ISBLANK(ET$3:ET$6))*(ET$3:ET$6=$GJ$3:$GJ$6)) -> 0 | EV12: =SUMPRODUCT(NOT(ISBLANK(EV$3:EV$6))*(EV$3:EV$6=$GK$3:$GK$6)) -> 0 | EW12: =SUMPRODUCT(NOT(ISBLANK(EW$3:EW$6))*(EW$3:EW$6=$GL$3:$GL$6)) -> 0 | EX12: =SUMPRODUCT(NOT(ISBLANK(EX$3:EX$6))*(EX$3:EX$6=$GM$3:$GM$6)) -> 0 | EY12: =SUMPRODUCT(NOT(ISBLANK(EY$3:EY$6))*(EY$3:EY$6=$GN$3:$GN$6)) -> 0 | EZ12: =SUMPRODUCT(NOT(ISBLANK(EZ$3:EZ$6))*(EZ$3:EZ$6=$GI$3:$GI$6)) -> 0 | FA12: =SUMPRODUCT(NOT(ISBLANK(FA$3:FA$6))*(FA$3:FA$6=$GJ$3:$GJ$6)) -> 0 | FC12: =SUMPRODUCT(NOT(ISBLANK(FC$3:FC$6))*(FC$3:FC$6=$GK$3:$GK$6)) -> 0 | FD12: =SUMPRODUCT(NOT(ISBLANK(FD$3:FD$6))*(FD$3:FD$6=$GL$3:$GL$6)) -> 0 | FE12: =SUMPRODUCT(NOT(ISBLANK(FE$3:FE$6))*(FE$3:FE$6=$GM$3:$GM$6)) -> 0 | FF12: =SUMPRODUCT(NOT(ISBLANK(FF$3:FF$6))*(FF$3:FF$6=$GN$3:$GN$6)) -> 0 | FG12: =SUMPRODUCT(NOT(ISBLANK(FG$3:FG$6))*(FG$3:FG$6=$GI$3:$GI$6)) -> 0 | FH12: =SUMPRODUCT(NOT(ISBLANK(FH$3:FH$6))*(FH$3:FH$6=$GJ$3:$GJ$6)) -> 0 | FJ12: =SUMPRODUCT(NOT(ISBLANK(FJ$3:FJ$6))*(FJ$3:FJ$6=$GK$3:$GK$6)) -> 0 | FK12: =SUMPRODUCT(NOT(ISBLANK(FK$3:FK$6))*(FK$3:FK$6=$GL$3:$GL$6)) -> 0 | FL12: =SUMPRODUCT(NOT(ISBLANK(FL$3:FL$6))*(FL$3:FL$6=$GM$3:$GM$6)) -> 0 | FM12: =SUMPRODUCT(NOT(ISBLANK(FM$3:FM$6))*(FM$3:FM$6=$GN$3:$GN$6)) -> 0 | FN12: =SUMPRODUCT(NOT(ISBLANK(FN$3:FN$6))*(FN$3:FN$6=$GI$3:$GI$6)) -> 0 | FO12: =SUMPRODUCT(NOT(ISBLANK(FO$3:FO$6))*(FO$3:FO$6=$GJ$3:$GJ$6)) -> 0 | FQ12: =SUMPRODUCT(NOT(ISBLANK(FQ$3:FQ$6))*(FQ$3:FQ$6=$GK$3:$GK$6)) -> 0 | FR12: =SUMPRODUCT(NOT(ISBLANK(FR$3:FR$6))*(FR$3:FR$6=$GL$3:$GL$6)) -> 0 | FS12: =SUMPRODUCT(NOT(ISBLANK(FS$3:FS$6))*(FS$3:FS$6=$GM$3:$GM$6)) -> 0 | FT12: =SUMPRODUCT(NOT(ISBLANK(FT$3:FT$6))*(FT$3:FT$6=$GN$3:$GN$6)) -> 0 | FU12: =SUMPRODUCT(NOT(ISBLANK(FU$3:FU$6))*(FU$3:FU$6=$GI$3:$GI$6)) -> 0 | FV12: =SUMPRODUCT(NOT(ISBLANK(FV$3:FV$6))*(FV$3:FV$6=$GJ$3:$GJ$6)) -> 0 | FX12: =SUMPRODUCT(NOT(ISBLANK(FX$3:FX$6))*(FX$3:FX$6=$GK$3:$GK$6)) -> 0 | FY12: =SUMPRODUCT(NOT(ISBLANK(FY$3:FY$6))*(FY$3:FY$6=$GL$3:$GL$6)) -> 0 | FZ12: =SUMPRODUCT(NOT(ISBLANK(FZ$3:FZ$6))*(FZ$3:FZ$6=$GM$3:$GM$6)) -> 0 | GA12: =SUMPRODUCT(NOT(ISBLANK(GA$3:GA$6))*(GA$3:GA$6=$GN$3:$GN$6)) -> 0 | GB12: =SUMPRODUCT(NOT(ISBLANK(GB$3:GB$6))*(GB$3:GB$6=$GI$3:$GI$6)) -> 0 | GC12: =SUMPRODUCT(NOT(ISBLANK(GC$3:GC$6))*(GC$3:GC$6=$GJ$3:$GJ$6)) -> 0 | GE12: =SUMPRODUCT(NOT(ISBLANK(GE$3:GE$6))*(GE$3:GE$6=$GK$3:$GK$6)) -> 0 | GF12: =SUMPRODUCT(NOT(ISBLANK(GF$3:GF$6))*(GF$3:GF$6=$GL$3:$GL$6)) -> 0 | GG12: =SUMPRODUCT(NOT(ISBLANK(GG$3:GG$6))*(GG$3:GG$6=$GM$3:$GM$6)) -> 0 | GH12: =SUMPRODUCT(NOT(ISBLANK(GH$3:GH$6))*(GH$3:GH$6=$GN$3:$GN$6)) -> 0
A13: BETTER | B13: =SUMPRODUCT(NOT(ISBLANK(B$3:B$6))*(B$3:B$6<$GO$3:$GO$6)) -> 0 | H13: =SUMPRODUCT(NOT(ISBLANK(H$3:H$6))*(H$3:H$6<$GT$3:$GT$6)) -> 0 | I13: =SUMPRODUCT(NOT(ISBLANK(I$3:I$6))*(I$3:I$6<$GO$3:$GO$6)) -> 0 | O13: =SUMPRODUCT(NOT(ISBLANK(O$3:O$6))*(O$3:O$6<$GT$3:$GT$6)) -> 0 | P13: =SUMPRODUCT(NOT(ISBLANK(P$3:P$6))*(P$3:P$6<$GO$3:$GO$6)) -> 0 | V13: =SUMPRODUCT(NOT(ISBLANK(V$3:V$6))*(V$3:V$6<$GT$3:$GT$6)) -> 0 | W13: =SUMPRODUCT(NOT(ISBLANK(W$3:W$6))*(W$3:W$6<$GO$3:$GO$6)) -> 0 | AC13: =SUMPRODUCT(NOT(ISBLANK(AC$3:AC$6))*(AC$3:AC$6<$GT$3:$GT$6)) -> 0 | AD13: =SUMPRODUCT(NOT(ISBLANK(AD$3:AD$6))*(AD$3:AD$6<$GO$3:$GO$6)) -> 0 | AJ13: =SUMPRODUCT(NOT(ISBLANK(AJ$3:AJ$6))*(AJ$3:AJ$6<$GT$3:$GT$6)) -> 0 | AK13: =SUMPRODUCT(NOT(ISBLANK(AK$3:AK$6))*(AK$3:AK$6<$GO$3:$GO$6)) -> 0 | AQ13: =SUMPRODUCT(NOT(ISBLANK(AQ$3:AQ$6))*(AQ$3:AQ$6<$GT$3:$GT$6)) -> 0 | AR13: =SUMPRODUCT(NOT(ISBLANK(AR$3:AR$6))*(AR$3:AR$6<$GO$3:$GO$6)) -> 0 | AX13: =SUMPRODUCT(NOT(ISBLANK(AX$3:AX$6))*(AX$3:AX$6<$GT$3:$GT$6)) -> 0 | AY13: =SUMPRODUCT(NOT(ISBLANK(AY$3:AY$6))*(AY$3:AY$6<$GO$3:$GO$6)) -> 0 | AZ13: =SUMPRODUCT(NOT(ISBLANK(AZ$3:AZ$6))*(AZ$3:AZ$6<$GP$3:$GP$6)) -> 0 | BB13: =SUMPRODUCT(NOT(ISBLANK(BB$3:BB$6))*(BB$3:BB$6<$GQ$3:$GQ$6)) -> 0 | BC13: =SUMPRODUCT(NOT(ISBLANK(BC$3:BC$6))*(BC$3:BC$6<$GR$3:$GR$6)) -> 0 | BD13: =SUMPRODUCT(NOT(ISBLANK(BD$3:BD$6))*(BD$3:BD$6<$GS$3:$GS$6)) -> 0 | BE13: =SUMPRODUCT(NOT(ISBLANK(BE$3:BE$6))*(BE$3:BE$6<$GT$3:$GT$6)) -> 0 | BF13: =SUMPRODUCT(NOT(ISBLANK(BF$3:BF$6))*(BF$3:BF$6<$GO$3:$GO$6)) -> 0 | BG13: =SUMPRODUCT(NOT(ISBLANK(BG$3:BG$6))*(BG$3:BG$6<$GP$3:$GP$6)) -> 0 | BI13: =SUMPRODUCT(NOT(ISBLANK(BI$3:BI$6))*(BI$3:BI$6<$GQ$3:$GQ$6)) -> 0 | BJ13: =SUMPRODUCT(NOT(ISBLANK(BJ$3:BJ$6))*(BJ$3:BJ$6<$GR$3:$GR$6)) -> 0 | BK13: =SUMPRODUCT(NOT(ISBLANK(BK$3:BK$6))*(BK$3:BK$6<$GS$3:$GS$6)) -> 0 | BL13: =SUMPRODUCT(NOT(ISBLANK(BL$3:BL$6))*(BL$3:BL$6<$GT$3:$GT$6)) -> 0 | BM13: =SUMPRODUCT(NOT(ISBLANK(BM$3:BM$6))*(BM$3:BM$6<$GO$3:$GO$6)) -> 0 | BN13: =SUMPRODUCT(NOT(ISBLANK(BN$3:BN$6))*(BN$3:BN$6<$GP$3:$GP$6)) -> 0 | BP13: =SUMPRODUCT(NOT(ISBLANK(BP$3:BP$6))*(BP$3:BP$6<$GQ$3:$GQ$6)) -> 0 | BQ13: =SUMPRODUCT(NOT(ISBLANK(BQ$3:BQ$6))*(BQ$3:BQ$6<$GR$3:$GR$6)) -> 0 | BR13: =SUMPRODUCT(NOT(ISBLANK(BR$3:BR$6))*(BR$3:BR$6<$GS$3:$GS$6)) -> 0 | BS13: =SUMPRODUCT(NOT(ISBLANK(BS$3:BS$6))*(BS$3:BS$6<$GT$3:$GT$6)) -> 0 | BT13: =SUMPRODUCT(NOT(ISBLANK(BT$3:BT$6))*(BT$3:BT$6<$GO$3:$GO$6)) -> 0 | BU13: =SUMPRODUCT(NOT(ISBLANK(BU$3:BU$6))*(BU$3:BU$6<$GP$3:$GP$6)) -> 0 | BW13: =SUMPRODUCT(NOT(ISBLANK(BW$3:BW$6))*(BW$3:BW$6<$GQ$3:$GQ$6)) -> 0 | BX13: =SUMPRODUCT(NOT(ISBLANK(BX$3:BX$6))*(BX$3:BX$6<$GR$3:$GR$6)) -> 0 | BY13: =SUMPRODUCT(NOT(ISBLANK(BY$3:BY$6))*(BY$3:BY$6<$GS$3:$GS$6)) -> 0 | BZ13: =SUMPRODUCT(NOT(ISBLANK(BZ$3:BZ$6))*(BZ$3:BZ$6<$GT$3:$GT$6)) -> 0 | CA13: =SUMPRODUCT(NOT(ISBLANK(CA$3:CA$6))*(CA$3:CA$6<$GO$3:$GO$6)) -> 0 | CB13: =SUMPRODUCT(NOT(ISBLANK(CB$3:CB$6))*(CB$3:CB$6<$GP$3:$GP$6)) -> 0 | CD13: =SUMPRODUCT(NOT(ISBLANK(CD$3:CD$6))*(CD$3:CD$6<$GQ$3:$GQ$6)) -> 0 | CE13: =SUMPRODUCT(NOT(ISBLANK(CE$3:CE$6))*(CE$3:CE$6<$GR$3:$GR$6)) -> 0 | CF13: =SUMPRODUCT(NOT(ISBLANK(CF$3:CF$6))*(CF$3:CF$6<$GS$3:$GS$6)) -> 0 | CG13: =SUMPRODUCT(NOT(ISBLANK(CG$3:CG$6))*(CG$3:CG$6<$GT$3:$GT$6)) -> 0 | CH13: =SUMPRODUCT(NOT(ISBLANK(CH$3:CH$6))*(CH$3:CH$6<$GO$3:$GO$6)) -> 0 | CN13: =SUMPRODUCT(NOT(ISBLANK(CN$3:CN$6))*(CN$3:CN$6<$GT$3:$GT$6)) -> 0 | CO13: =SUMPRODUCT(NOT(ISBLANK(CO$3:CO$6))*(CO$3:CO$6<$GO$3:$GO$6)) -> 0 | CP13: =SUMPRODUCT(NOT(ISBLANK(CP$3:CP$6))*(CP$3:CP$6<$GP$3:$GP$6)) -> 0 | CR13: =SUMPRODUCT(NOT(ISBLANK(CR$3:CR$6))*(CR$3:CR$6<$GQ$3:$GQ$6)) -> 0 | CS13: =SUMPRODUCT(NOT(ISBLANK(CS$3:CS$6))*(CS$3:CS$6<$GR$3:$GR$6)) -> 0 | CT13: =SUMPRODUCT(NOT(ISBLANK(CT$3:CT$6))*(CT$3:CT$6<$GS$3:$GS$6)) -> 0 | CU13: =SUMPRODUCT(NOT(ISBLANK(CU$3:CU$6))*(CU$3:CU$6<$GT$3:$GT$6)) -> 0 | CV13: =SUMPRODUCT(NOT(ISBLANK(CV$3:CV$6))*(CV$3:CV$6<$GO$3:$GO$6)) -> 0 | CW13: =SUMPRODUCT(NOT(ISBLANK(CW$3:CW$6))*(CW$3:CW$6<$GP$3:$GP$6)) -> 0 | CY13: =SUMPRODUCT(NOT(ISBLANK(CY$3:CY$6))*(CY$3:CY$6<$GQ$3:$GQ$6)) -> 0 | CZ13: =SUMPRODUCT(NOT(ISBLANK(CZ$3:CZ$6))*(CZ$3:CZ$6<$GR$3:$GR$6)) -> 0 | DA13: =SUMPRODUCT(NOT(ISBLANK(DA$3:DA$6))*(DA$3:DA$6<$GS$3:$GS$6)) -> 0 | DB13: =SUMPRODUCT(NOT(ISBLANK(DB$3:DB$6))*(DB$3:DB$6<$GT$3:$GT$6)) -> 0 | DC13: =SUMPRODUCT(NOT(ISBLANK(DC$3:DC$6))*(DC$3:DC$6<$GO$3:$GO$6)) -> 0 | DI13: =SUMPRODUCT(NOT(ISBLANK(DI$3:DI$6))*(DI$3:DI$6<$GT$3:$GT$6)) -> 0 | DJ13: =SUMPRODUCT(NOT(ISBLANK(DJ$3:DJ$6))*(DJ$3:DJ$6<$GO$3:$GO$6)) -> 0 | DK13: =SUMPRODUCT(NOT(ISBLANK(DK$3:DK$6))*(DK$3:DK$6<$GP$3:$GP$6)) -> 0 | DM13: =SUMPRODUCT(NOT(ISBLANK(DM$3:DM$6))*(DM$3:DM$6<$GQ$3:$GQ$6)) -> 0 | DN13: =SUMPRODUCT(NOT(ISBLANK(DN$3:DN$6))*(DN$3:DN$6<$GR$3:$GR$6)) -> 0 | DO13: =SUMPRODUCT(NOT(ISBLANK(DO$3:DO$6))*(DO$3:DO$6<$GS$3:$GS$6)) -> 0 | DP13: =SUMPRODUCT(NOT(ISBLANK(DP$3:DP$6))*(DP$3:DP$6<$GT$3:$GT$6)) -> 0 | DQ13: =SUMPRODUCT(NOT(ISBLANK(DQ$3:DQ$6))*(DQ$3:DQ$6<$GO$3:$GO$6)) -> 0 | DR13: =SUMPRODUCT(NOT(ISBLANK(DR$3:DR$6))*(DR$3:DR$6<$GP$3:$GP$6)) -> 0 | DT13: =SUMPRODUCT(NOT(ISBLANK(DT$3:DT$6))*(DT$3:DT$6<$GQ$3:$GQ$6)) -> 0 | DU13: =SUMPRODUCT(NOT(ISBLANK(DU$3:DU$6))*(DU$3:DU$6<$GR$3:$GR$6)) -> 0 | DV13: =SUMPRODUCT(NOT(ISBLANK(DV$3:DV$6))*(DV$3:DV$6<$GS$3:$GS$6)) -> 0 | DW13: =SUMPRODUCT(NOT(ISBLANK(DW$3:DW$6))*(DW$3:DW$6<$GT$3:$GT$6)) -> 0 | DX13: =SUMPRODUCT(NOT(ISBLANK(DX$3:DX$6))*(DX$3:DX$6<$GO$3:$GO$6)) -> 0 | DY13: =SUMPRODUCT(NOT(ISBLANK(DY$3:DY$6))*(DY$3:DY$6<$GP$3:$GP$6)) -> 0 | EA13: =SUMPRODUCT(NOT(ISBLANK(EA$3:EA$6))*(EA$3:EA$6<$GQ$3:$GQ$6)) -> 0 | EB13: =SUMPRODUCT(NOT(ISBLANK(EB$3:EB$6))*(EB$3:EB$6<$GR$3:$GR$6)) -> 0 | EC13: =SUMPRODUCT(NOT(ISBLANK(EC$3:EC$6))*(EC$3:EC$6<$GS$3:$GS$6)) -> 0 | ED13: =SUMPRODUCT(NOT(ISBLANK(ED$3:ED$6))*(ED$3:ED$6<$GT$3:$GT$6)) -> 0 | EE13: =SUMPRODUCT(NOT(ISBLANK(EE$3:EE$6))*(EE$3:EE$6<$GO$3:$GO$6)) -> 0 | EF13: =SUMPRODUCT(NOT(ISBLANK(EF$3:EF$6))*(EF$3:EF$6<$GP$3:$GP$6)) -> 0 | EH13: =SUMPRODUCT(NOT(ISBLANK(EH$3:EH$6))*(EH$3:EH$6<$GQ$3:$GQ$6)) -> 0 | EI13: =SUMPRODUCT(NOT(ISBLANK(EI$3:EI$6))*(EI$3:EI$6<$GR$3:$GR$6)) -> 0 | EJ13: =SUMPRODUCT(NOT(ISBLANK(EJ$3:EJ$6))*(EJ$3:EJ$6<$GS$3:$GS$6)) -> 0 | EK13: =SUMPRODUCT(NOT(ISBLANK(EK$3:EK$6))*(EK$3:EK$6<$GT$3:$GT$6)) -> 0 | EL13: =SUMPRODUCT(NOT(ISBLANK(EL$3:EL$6))*(EL$3:EL$6<$GO$3:$GO$6)) -> 0 | EM13: =SUMPRODUCT(NOT(ISBLANK(EM$3:EM$6))*(EM$3:EM$6<$GP$3:$GP$6)) -> 0 | EO13: =SUMPRODUCT(NOT(ISBLANK(EO$3:EO$6))*(EO$3:EO$6<$GQ$3:$GQ$6)) -> 0 | EP13: =SUMPRODUCT(NOT(ISBLANK(EP$3:EP$6))*(EP$3:EP$6<$GR$3:$GR$6)) -> 0 | EQ13: =SUMPRODUCT(NOT(ISBLANK(EQ$3:EQ$6))*(EQ$3:EQ$6<$GS$3:$GS$6)) -> 0 | ER13: =SUMPRODUCT(NOT(ISBLANK(ER$3:ER$6))*(ER$3:ER$6<$GT$3:$GT$6)) -> 0 | ES13: =SUMPRODUCT(NOT(ISBLANK(ES$3:ES$6))*(ES$3:ES$6<$GO$3:$GO$6)) -> 0 | ET13: =SUMPRODUCT(NOT(ISBLANK(ET$3:ET$6))*(ET$3:ET$6<$GP$3:$GP$6)) -> 0 | EV13: =SUMPRODUCT(NOT(ISBLANK(EV$3:EV$6))*(EV$3:EV$6<$GQ$3:$GQ$6)) -> 0 | EW13: =SUMPRODUCT(NOT(ISBLANK(EW$3:EW$6))*(EW$3:EW$6<$GR$3:$GR$6)) -> 0 | EX13: =SUMPRODUCT(NOT(ISBLANK(EX$3:EX$6))*(EX$3:EX$6<$GS$3:$GS$6)) -> 0 | EY13: =SUMPRODUCT(NOT(ISBLANK(EY$3:EY$6))*(EY$3:EY$6<$GT$3:$GT$6)) -> 0 | EZ13: =SUMPRODUCT(NOT(ISBLANK(EZ$3:EZ$6))*(EZ$3:EZ$6<$GO$3:$GO$6)) -> 0 | FA13: =SUMPRODUCT(NOT(ISBLANK(FA$3:FA$6))*(FA$3:FA$6<$GP$3:$GP$6)) -> 0 | FC13: =SUMPRODUCT(NOT(ISBLANK(FC$3:FC$6))*(FC$3:FC$6<$GQ$3:$GQ$6)) -> 0 | FD13: =SUMPRODUCT(NOT(ISBLANK(FD$3:FD$6))*(FD$3:FD$6<$GR$3:$GR$6)) -> 0 | FE13: =SUMPRODUCT(NOT(ISBLANK(FE$3:FE$6))*(FE$3:FE$6<$GS$3:$GS$6)) -> 0 | FF13: =SUMPRODUCT(NOT(ISBLANK(FF$3:FF$6))*(FF$3:FF$6<$GT$3:$GT$6)) -> 0 | FG13: =SUMPRODUCT(NOT(ISBLANK(FG$3:FG$6))*(FG$3:FG$6<$GO$3:$GO$6)) -> 0 | FH13: =SUMPRODUCT(NOT(ISBLANK(FH$3:FH$6))*(FH$3:FH$6<$GP$3:$GP$6)) -> 0 | FJ13: =SUMPRODUCT(NOT(ISBLANK(FJ$3:FJ$6))*(FJ$3:FJ$6<$GQ$3:$GQ$6)) -> 0 | FK13: =SUMPRODUCT(NOT(ISBLANK(FK$3:FK$6))*(FK$3:FK$6<$GR$3:$GR$6)) -> 0 | FL13: =SUMPRODUCT(NOT(ISBLANK(FL$3:FL$6))*(FL$3:FL$6<$GS$3:$GS$6)) -> 0 | FM13: =SUMPRODUCT(NOT(ISBLANK(FM$3:FM$6))*(FM$3:FM$6<$GT$3:$GT$6)) -> 0 | FN13: =SUMPRODUCT(NOT(ISBLANK(FN$3:FN$6))*(FN$3:FN$6<$GO$3:$GO$6)) -> 0 | FO13: =SUMPRODUCT(NOT(ISBLANK(FO$3:FO$6))*(FO$3:FO$6<$GP$3:$GP$6)) -> 0 | FQ13: =SUMPRODUCT(NOT(ISBLANK(FQ$3:FQ$6))*(FQ$3:FQ$6<$GQ$3:$GQ$6)) -> 0 | FR13: =SUMPRODUCT(NOT(ISBLANK(FR$3:FR$6))*(FR$3:FR$6<$GR$3:$GR$6)) -> 0 | FS13: =SUMPRODUCT(NOT(ISBLANK(FS$3:FS$6))*(FS$3:FS$6<$GS$3:$GS$6)) -> 0 | FT13: =SUMPRODUCT(NOT(ISBLANK(FT$3:FT$6))*(FT$3:FT$6<$GT$3:$GT$6)) -> 0 | FU13: =SUMPRODUCT(NOT(ISBLANK(FU$3:FU$6))*(FU$3:FU$6<$GO$3:$GO$6)) -> 0 | FV13: =SUMPRODUCT(NOT(ISBLANK(FV$3:FV$6))*(FV$3:FV$6<$GP$3:$GP$6)) -> 0 | FX13: =SUMPRODUCT(NOT(ISBLANK(FX$3:FX$6))*(FX$3:FX$6<$GQ$3:$GQ$6)) -> 0 | FY13: =SUMPRODUCT(NOT(ISBLANK(FY$3:FY$6))*(FY$3:FY$6<$GR$3:$GR$6)) -> 0 | FZ13: =SUMPRODUCT(NOT(ISBLANK(FZ$3:FZ$6))*(FZ$3:FZ$6<$GS$3:$GS$6)) -> 0 | GA13: =SUMPRODUCT(NOT(ISBLANK(GA$3:GA$6))*(GA$3:GA$6<$GT$3:$GT$6)) -> 0 | GB13: =SUMPRODUCT(NOT(ISBLANK(GB$3:GB$6))*(GB$3:GB$6<$GO$3:$GO$6)) -> 0 | GC13: =SUMPRODUCT(NOT(ISBLANK(GC$3:GC$6))*(GC$3:GC$6<$GP$3:$GP$6)) -> 0 | GE13: =SUMPRODUCT(NOT(ISBLANK(GE$3:GE$6))*(GE$3:GE$6<$GQ$3:$GQ$6)) -> 0 | GF13: =SUMPRODUCT(NOT(ISBLANK(GF$3:GF$6))*(GF$3:GF$6<$GR$3:$GR$6)) -> 0 | GG13: =SUMPRODUCT(NOT(ISBLANK(GG$3:GG$6))*(GG$3:GG$6<$GS$3:$GS$6)) -> 0 | GH13: =SUMPRODUCT(NOT(ISBLANK(GH$3:GH$6))*(GH$3:GH$6<$GT$3:$GT$6)) -> 0
