Workbook

Sheet Instances
B1: memelingo-1/lambda-small_mlp-tplp-ht_20 | I1: memelingo-1/lambda-small_mlp-tplp-ht_25 | P1: memelingo-1/lambda-small_mlp-tplp-ht_30 | W1: memelingo-1/lambda-small_mlp-tplp-ht_35 | AD1: memelingo-1/lambda-small_mlp-tplp-ht_40 | AK1: memelingo-1/lambda-small_mlp-tplp-ht_45 | AR1: memelingo-1/lambda-small_mlp-tplp-ht_50 | AY1: memelingo-1/lambda-small_mlp-tplp-htc_20 | BF1: memelingo-1/lambda-small_mlp-tplp-htc_25 | BM1: memelingo-1/lambda-small_mlp-tplp-htc_30 | BT1: memelingo-1/lambda-small_mlp-tplp-htc_35 | CA1: memelingo-1/lambda-small_mlp-tplp-htc_40 | CH1: memelingo-1/lambda-small_mlp-tplp-htc_45 | CO1: memelingo-1/lambda-small_mlp-tplp-htc_50 | CV1: memelingo-1/lambda-small_mlp-tplp-htcdl_20 | DC1: memelingo-1/lambda-small_mlp-tplp-htcdl_25 | DJ1: memelingo-1/lambda-small_mlp-tplp-htcdl_30 | DQ1: memelingo-1/lambda-small_mlp-tplp-htcdl_35 | DX1: memelingo-1/lambda-small_mlp-tplp-htcdl_40 | EE1: memelingo-1/lambda-small_mlp-tplp-htcdl_45 | EL1: memelingo-1/lambda-small_mlp-tplp-htcdl_50 | ES1: min | EY1: median | FE1: max
B2: time | C2: stime | D2: status | E2: rules | F2: ctime | G2: fmtime | H2: memout | I2: time | J2: stime | K2: status | L2: rules | M2: ctime | N2: fmtime | O2: memout | P2: time | Q2: stime | R2: status | S2: rules | T2: ctime | U2: fmtime | V2: memout | W2: time | X2: stime | Y2: status | Z2: rules | AA2: ctime | AB2: fmtime | AC2: memout | AD2: time | AE2: stime | AF2: status | AG2: rules | AH2: ctime | AI2: fmtime | AJ2: memout | AK2: time | AL2: stime | AM2: status | AN2: rules | AO2: ctime | AP2: fmtime | AQ2: memout | AR2: time | AS2: stime | AT2: status | AU2: rules | AV2: ctime | AW2: fmtime | AX2: memout | AY2: time | AZ2: stime | BA2: status | BB2: rules | BC2: ctime | BD2: fmtime | BE2: memout | BF2: time | BG2: stime | BH2: status | BI2: rules | BJ2: ctime | BK2: fmtime | BL2: memout | BM2: time | BN2: stime | BO2: status | BP2: rules | BQ2: ctime | BR2: fmtime | BS2: memout | BT2: time | BU2: stime | BV2: status | BW2: rules | BX2: ctime | BY2: fmtime | BZ2: memout | CA2: time | CB2: stime | CC2: status | CD2: rules | CE2: ctime | CF2: fmtime | CG2: memout | CH2: time | CI2: stime | CJ2: status | CK2: rules | CL2: ctime | CM2: fmtime | CN2: memout | CO2: time | CP2: stime | CQ2: status | CR2: rules | CS2: ctime | CT2: fmtime | CU2: memout | CV2: time | CW2: stime | CX2: status | CY2: rules | CZ2: ctime | DA2: fmtime | DB2: memout | DC2: time | DD2: stime | DE2: status | DF2: rules | DG2: ctime | DH2: fmtime | DI2: memout | DJ2: time | DK2: stime | DL2: status | DM2: rules | DN2: ctime | DO2: fmtime | DP2: memout | DQ2: time | DR2: stime | DS2: status | DT2: rules | DU2: ctime | DV2: fmtime | DW2: memout | DX2: time | DY2: stime | DZ2: status | EA2: rules | EB2: ctime | EC2: fmtime | ED2: memout | EE2: time | EF2: stime | EG2: status | EH2: rules | EI2: ctime | EJ2: fmtime | EK2: memout | EL2: time | EM2: stime | EN2: status | EO2: rules | EP2: ctime | EQ2: fmtime | ER2: memout | ES2: time | ET2: stime | EU2: rules | EV2: ctime | EW2: fmtime | EX2: memout | EY2: time | EZ2: stime | FA2: rules | FB2: ctime | FC2: fmtime | FD2: memout | FE2: time | FF2: stime | FG2: rules | FH2: ctime | FI2: fmtime | FJ2: memout
A3: instances/ft06 | B3: 1200 | C3: 1185.65 | D3: UNKNOWN | E3: 5585084 | F3: 1193.722 | G3: 0 | H3: 0 | I3: 1200 | J3: 1180.26 | K3: UNKNOWN | L3: 7799174 | M3: 1194.043 | N3: 0 | O3: 0 | P3: 1200 | Q3: 1175.3 | R3: UNKNOWN | S3: 9950689 | T3: 1192.987 | U3: 0 | V3: 0 | W3: 1200 | X3: 1175.71 | Y3: UNKNOWN | Z3: 11903879 | AA3: 1193.455 | AB3: 0 | AC3: 0 | AD3: 641.95 | AE3: 615.35 | AF3: SATISFIABLE | AG3: 13556744 | AH3: 633.15 | AI3: 615.34 | AJ3: 0 | AK3: 196.68 | AL3: 170.99 | AM3: SATISFIABLE | AN3: 14841034 | AO3: 189.581 | AP3: 170.98 | AQ3: 0 | AR3: 45.15 | AS3: 15.02 | AT3: SATISFIABLE | AU3: 15722249 | AV3: 35.219 | AW3: 15.01 | AX3: 0 | AY3: 18.98 | AZ3: 8.75 | BA3: SATISFIABLE | BB3: 152933 | BC3: 9.633 | BD3: 8.74 | BE3: 0 | BF3: 970.7 | BG3: 961.17 | BH3: SATISFIABLE | BI3: 209998 | BJ3: 962.307 | BK3: 961.17 | BL3: 0 | BM3: 83.37 | BN3: 74.61 | BO3: SATISFIABLE | BP3: 274938 | BQ3: 76.079 | BR3: 74.6 | BS3: 0 | BT3: 208.26 | BU3: 197.96 | BV3: SATISFIABLE | BW3: 347753 | BX3: 199.734 | BY3: 197.95 | BZ3: 0 | CA3: 40.74 | CB3: 28.75 | CC3: SATISFIABLE | CD3: 428443 | CE3: 31.087 | CF3: 28.74 | CG3: 0 | CH3: 28.98 | CI3: 19.31 | CJ3: SATISFIABLE | CK3: 517008 | CL3: 22.061 | CM3: 19.31 | CN3: 0 | CO3: 52.19 | CP3: 42.4 | CQ3: SATISFIABLE | CR3: 613448 | CS3: 45.216 | CT3: 42.4 | CU3: 0 | CV3: 799.89 | CW3: 789.43 | CX3: SATISFIABLE | CY3: 152933 | CZ3: 790.238 | DA3: 789.42 | DB3: 0 | DC3: 1200 | DD3: 1192.31 | DE3: UNKNOWN | DF3: 209998 | DG3: 1193.266 | DH3: 0 | DI3: 0 | DJ3: 208.26 | DK3: 197.38 | DL3: SATISFIABLE | DM3: 274938 | DN3: 198.672 | DO3: 197.38 | DP3: 0 | DQ3: 301.19 | DR3: 293.29 | DS3: SATISFIABLE | DT3: 347753 | DU3: 294.813 | DV3: 293.29 | DW3: 0 | DX3: 86.32 | DY3: 74.77 | DZ3: SATISFIABLE | EA3: 428443 | EB3: 76.704 | EC3: 74.76 | ED3: 0 | EE3: 85.5 | EF3: 73.55 | EG3: SATISFIABLE | EH3: 517008 | EI3: 75.807 | EJ3: 73.54 | EK3: 0 | EL3: 31.13 | EM3: 21.95 | EN3: SATISFIABLE | EO3: 613448 | EP3: 24.486 | EQ3: 21.94 | ER3: 0 | ES3: =MIN($B3,$I3,$P3,$W3,$AD3,$AK3,$AR3,$AY3,$BF3,$BM3,$BT3,$CA3,$CH3,$CO3,$CV3,$DC3,$DJ3,$DQ3,$DX3,$EE3,$EL3) -> 0 | ET3: =MIN($C3,$J3,$Q3,$X3,$AE3,$AL3,$AS3,$AZ3,$BG3,$BN3,$BU3,$CB3,$CI3,$CP3,$CW3,$DD3,$DK3,$DR3,$DY3,$EF3,$EM3) -> 0 | EU3: =MIN($E3,$L3,$S3,$Z3,$AG3,$AN3,$AU3,$BB3,$BI3,$BP3,$BW3,$CD3,$CK3,$CR3,$CY3,$DF3,$DM3,$DT3,$EA3,$EH3,$EO3) -> 0 | EV3: =MIN($F3,$M3,$T3,$AA3,$AH3,$AO3,$AV3,$BC3,$BJ3,$BQ3,$BX3,$CE3,$CL3,$CS3,$CZ3,$DG3,$DN3,$DU3,$EB3,$EI3,$EP3) -> 0 | EW3: =MIN($G3,$N3,$U3,$AB3,$AI3,$AP3,$AW3,$BD3,$BK3,$BR3,$BY3,$CF3,$CM3,$CT3,$DA3,$DH3,$DO3,$DV3,$EC3,$EJ3,$EQ3) -> 0 | EX3: =MIN($H3,$O3,$V3,$AC3,$AJ3,$AQ3,$AX3,$BE3,$BL3,$BS3,$BZ3,$CG3,$CN3,$CU3,$DB3,$DI3,$DP3,$DW3,$ED3,$EK3,$ER3) -> 0 | EY3: =MEDIAN($B3,$I3,$P3,$W3,$AD3,$AK3,$AR3,$AY3,$BF3,$BM3,$BT3,$CA3,$CH3,$CO3,$CV3,$DC3,$DJ3,$DQ3,$DX3,$EE3,$EL3) -> 0 | EZ3: =MEDIAN($C3,$J3,$Q3,$X3,$AE3,$AL3,$AS3,$AZ3,$BG3,$BN3,$BU3,$CB3,$CI3,$CP3,$CW3,$DD3,$DK3,$DR3,$DY3,$EF3,$EM3) -> 0 | FA3: =MEDIAN($E3,$L3,$S3,$Z3,$AG3,$AN3,$AU3,$BB3,$BI3,$BP3,$BW3,$CD3,$CK3,$CR3,$CY3,$DF3,$DM3,$DT3,$EA3,$EH3,$EO3) -> 0 | FB3: =MEDIAN($F3,$M3,$T3,$AA3,$AH3,$AO3,$AV3,$BC3,$BJ3,$BQ3,$BX3,$CE3,$CL3,$CS3,$CZ3,$DG3,$DN3,$DU3,$EB3,$EI3,$EP3) -> 0 | FC3: =MEDIAN($G3,$N3,$U3,$AB3,$AI3,$AP3,$AW3,$BD3,$BK3,$BR3,$BY3,$CF3,$CM3,$CT3,$DA3,$DH3,$DO3,$DV3,$EC3,$EJ3,$EQ3) -> 0 | FD3: =MEDIAN($H3,$O3,$V3,$AC3,$AJ3,$AQ3,$AX3,$BE3,$BL3,$BS3,$BZ3,$CG3,$CN3,$CU3,$DB3,$DI3,$DP3,$DW3,$ED3,$EK3,$ER3) -> 0 | FE3: =MAX($B3,$I3,$P3,$W3,$AD3,$AK3,$AR3,$AY3,$BF3,$BM3,$BT3,$CA3,$CH3,$CO3,$CV3,$DC3,$DJ3,$DQ3,$DX3,$EE3,$EL3) -> 0 | FF3: =MAX($C3,$J3,$Q3,$X3,$AE3,$AL3,$AS3,$AZ3,$BG3,$BN3,$BU3,$CB3,$CI3,$CP3,$CW3,$DD3,$DK3,$DR3,$DY3,$EF3,$EM3) -> 0 | FG3: =MAX($E3,$L3,$S3,$Z3,$AG3,$AN3,$AU3,$BB3,$BI3,$BP3,$BW3,$CD3,$CK3,$CR3,$CY3,$DF3,$DM3,$DT3,$EA3,$EH3,$EO3) -> 0 | FH3: =MAX($F3,$M3,$T3,$AA3,$AH3,$AO3,$AV3,$BC3,$BJ3,$BQ3,$BX3,$CE3,$CL3,$CS3,$CZ3,$DG3,$DN3,$DU3,$EB3,$EI3,$EP3) -> 0 | FI3: =MAX($G3,$N3,$U3,$AB3,$AI3,$AP3,$AW3,$BD3,$BK3,$BR3,$BY3,$CF3,$CM3,$CT3,$DA3,$DH3,$DO3,$DV3,$EC3,$EJ3,$EQ3) -> 0 | FJ3: =MAX($H3,$O3,$V3,$AC3,$AJ3,$AQ3,$AX3,$BE3,$BL3,$BS3,$BZ3,$CG3,$CN3,$CU3,$DB3,$DI3,$DP3,$DW3,$ED3,$EK3,$ER3) -> 0
A5: SUM | B5: =SUM(B$3:B$3) -> 0 | C5: =SUM(C$3:C$3) -> 0 | E5: =SUM(E$3:E$3) -> 0 | F5: =SUM(F$3:F$3) -> 0 | G5: =SUM(G$3:G$3) -> 0 | H5: =SUM(H$3:H$3) -> 0 | I5: =SUM(I$3:I$3) -> 0 | J5: =SUM(J$3:J$3) -> 0 | L5: =SUM(L$3:L$3) -> 0 | M5: =SUM(M$3:M$3) -> 0 | N5: =SUM(N$3:N$3) -> 0 | O5: =SUM(O$3:O$3) -> 0 | P5: =SUM(P$3:P$3) -> 0 | Q5: =SUM(Q$3:Q$3) -> 0 | S5: =SUM(S$3:S$3) -> 0 | T5: =SUM(T$3:T$3) -> 0 | U5: =SUM(U$3:U$3) -> 0 | V5: =SUM(V$3:V$3) -> 0 | W5: =SUM(W$3:W$3) -> 0 | X5: =SUM(X$3:X$3) -> 0 | Z5: =SUM(Z$3:Z$3) -> 0 | AA5: =SUM(AA$3:AA$3) -> 0 | AB5: =SUM(AB$3:AB$3) -> 0 | AC5: =SUM(AC$3:AC$3) -> 0 | AD5: =SUM(AD$3:AD$3) -> 0 | AE5: =SUM(AE$3:AE$3) -> 0 | AG5: =SUM(AG$3:AG$3) -> 0 | AH5: =SUM(AH$3:AH$3) -> 0 | AI5: =SUM(AI$3:AI$3) -> 0 | AJ5: =SUM(AJ$3:AJ$3) -> 0 | AK5: =SUM(AK$3:AK$3) -> 0 | AL5: =SUM(AL$3:AL$3) -> 0 | AN5: =SUM(AN$3:AN$3) -> 0 | AO5: =SUM(AO$3:AO$3) -> 0 | AP5: =SUM(AP$3:AP$3) -> 0 | AQ5: =SUM(AQ$3:AQ$3) -> 0 | AR5: =SUM(AR$3:AR$3) -> 0 | AS5: =SUM(AS$3:AS$3) -> 0 | AU5: =SUM(AU$3:AU$3) -> 0 | AV5: =SUM(AV$3:AV$3) -> 0 | AW5: =SUM(AW$3:AW$3) -> 0 | AX5: =SUM(AX$3:AX$3) -> 0 | AY5: =SUM(AY$3:AY$3) -> 0 | AZ5: =SUM(AZ$3:AZ$3) -> 0 | BB5: =SUM(BB$3:BB$3) -> 0 | BC5: =SUM(BC$3:BC$3) -> 0 | BD5: =SUM(BD$3:BD$3) -> 0 | BE5: =SUM(BE$3:BE$3) -> 0 | BF5: =SUM(BF$3:BF$3) -> 0 | BG5: =SUM(BG$3:BG$3) -> 0 | BI5: =SUM(BI$3:BI$3) -> 0 | BJ5: =SUM(BJ$3:BJ$3) -> 0 | BK5: =SUM(BK$3:BK$3) -> 0 | BL5: =SUM(BL$3:BL$3) -> 0 | BM5: =SUM(BM$3:BM$3) -> 0 | BN5: =SUM(BN$3:BN$3) -> 0 | BP5: =SUM(BP$3:BP$3) -> 0 | BQ5: =SUM(BQ$3:BQ$3) -> 0 | BR5: =SUM(BR$3:BR$3) -> 0 | BS5: =SUM(BS$3:BS$3) -> 0 | BT5: =SUM(BT$3:BT$3) -> 0 | BU5: =SUM(BU$3:BU$3) -> 0 | BW5: =SUM(BW$3:BW$3) -> 0 | BX5: =SUM(BX$3:BX$3) -> 0 | BY5: =SUM(BY$3:BY$3) -> 0 | BZ5: =SUM(BZ$3:BZ$3) -> 0 | CA5: =SUM(CA$3:CA$3) -> 0 | CB5: =SUM(CB$3:CB$3) -> 0 | CD5: =SUM(CD$3:CD$3) -> 0 | CE5: =SUM(CE$3:CE$3) -> 0 | CF5: =SUM(CF$3:CF$3) -> 0 | CG5: =SUM(CG$3:CG$3) -> 0 | CH5: =SUM(CH$3:CH$3) -> 0 | CI5: =SUM(CI$3:CI$3) -> 0 | CK5: =SUM(CK$3:CK$3) -> 0 | CL5: =SUM(CL$3:CL$3) -> 0 | CM5: =SUM(CM$3:CM$3) -> 0 | CN5: =SUM(CN$3:CN$3) -> 0 | CO5: =SUM(CO$3:CO$3) -> 0 | CP5: =SUM(CP$3:CP$3) -> 0 | CR5: =SUM(CR$3:CR$3) -> 0 | CS5: =SUM(CS$3:CS$3) -> 0 | CT5: =SUM(CT$3:CT$3) -> 0 | CU5: =SUM(CU$3:CU$3) -> 0 | CV5: =SUM(CV$3:CV$3) -> 0 | CW5: =SUM(CW$3:CW$3) -> 0 | CY5: =SUM(CY$3:CY$3) -> 0 | CZ5: =SUM(CZ$3:CZ$3) -> 0 | DA5: =SUM(DA$3:DA$3) -> 0 | DB5: =SUM(DB$3:DB$3) -> 0 | DC5: =SUM(DC$3:DC$3) -> 0 | DD5: =SUM(DD$3:DD$3) -> 0 | DF5: =SUM(DF$3:DF$3) -> 0 | DG5: =SUM(DG$3:DG$3) -> 0 | DH5: =SUM(DH$3:DH$3) -> 0 | DI5: =SUM(DI$3:DI$3) -> 0 | DJ5: =SUM(DJ$3:DJ$3) -> 0 | DK5: =SUM(DK$3:DK$3) -> 0 | DM5: =SUM(DM$3:DM$3) -> 0 | DN5: =SUM(DN$3:DN$3) -> 0 | DO5: =SUM(DO$3:DO$3) -> 0 | DP5: =SUM(DP$3:DP$3) -> 0 | DQ5: =SUM(DQ$3:DQ$3) -> 0 | DR5: =SUM(DR$3:DR$3) -> 0 | DT5: =SUM(DT$3:DT$3) -> 0 | DU5: =SUM(DU$3:DU$3) -> 0 | DV5: =SUM(DV$3:DV$3) -> 0 | DW5: =SUM(DW$3:DW$3) -> 0 | DX5: =SUM(DX$3:DX$3) -> 0 | DY5: =SUM(DY$3:DY$3) -> 0 | EA5: =SUM(EA$3:EA$3) -> 0 | EB5: =SUM(EB$3:EB$3) -> 0 | EC5: =SUM(EC$3:EC$3) -> 0 | ED5: =SUM(ED$3:ED$3) -> 0 | EE5: =SUM(EE$3:EE$3) -> 0 | EF5: =SUM(EF$3:EF$3) -> 0 | EH5: =SUM(EH$3:EH$3) -> 0 | EI5: =SUM(EI$3:EI$3) -> 0 | EJ5: =SUM(EJ$3:EJ$3) -> 0 | EK5: =SUM(EK$3:EK$3) -> 0 | EL5: =SUM(EL$3:EL$3) -> 0 | EM5: =SUM(EM$3:EM$3) -> 0 | EO5: =SUM(EO$3:EO$3) -> 0 | EP5: =SUM(EP$3:EP$3) -> 0 | EQ5: =SUM(EQ$3:EQ$3) -> 0 | ER5: =SUM(ER$3:ER$3) -> 0 | ES5: =SUM(ES$3:ES$3) -> 0 | ET5: =SUM(ET$3:ET$3) -> 0 | EU5: =SUM(EU$3:EU$3) -> 0 | EV5: =SUM(EV$3:EV$3) -> 0 | ... FJ5: =SUM(FJ$3:FJ$3) -> 0
A6: AVG | B6: =AVERAGE(B$3:B$3) -> 0 | C6: =AVERAGE(C$3:C$3) -> 0 | E6: =AVERAGE(E$3:E$3) -> 0 | F6: =AVERAGE(F$3:F$3) -> 0 | G6: =AVERAGE(G$3:G$3) -> 0 | H6: =AVERAGE(H$3:H$3) -> 0 | I6: =AVERAGE(I$3:I$3) -> 0 | J6: =AVERAGE(J$3:J$3) -> 0 | L6: =AVERAGE(L$3:L$3) -> 0 | M6: =AVERAGE(M$3:M$3) -> 0 | N6: =AVERAGE(N$3:N$3) -> 0 | O6: =AVERAGE(O$3:O$3) -> 0 | P6: =AVERAGE(P$3:P$3) -> 0 | Q6: =AVERAGE(Q$3:Q$3) -> 0 | S6: =AVERAGE(S$3:S$3) -> 0 | T6: =AVERAGE(T$3:T$3) -> 0 | U6: =AVERAGE(U$3:U$3) -> 0 | V6: =AVERAGE(V$3:V$3) -> 0 | W6: =AVERAGE(W$3:W$3) -> 0 | X6: =AVERAGE(X$3:X$3) -> 0 | Z6: =AVERAGE(Z$3:Z$3) -> 0 | AA6: =AVERAGE(AA$3:AA$3) -> 0 | AB6: =AVERAGE(AB$3:AB$3) -> 0 | AC6: =AVERAGE(AC$3:AC$3) -> 0 | AD6: =AVERAGE(AD$3:AD$3) -> 0 | AE6: =AVERAGE(AE$3:AE$3) -> 0 | AG6: =AVERAGE(AG$3:AG$3) -> 0 | AH6: =AVERAGE(AH$3:AH$3) -> 0 | AI6: =AVERAGE(AI$3:AI$3) -> 0 | AJ6: =AVERAGE(AJ$3:AJ$3) -> 0 | AK6: =AVERAGE(AK$3:AK$3) -> 0 | AL6: =AVERAGE(AL$3:AL$3) -> 0 | AN6: =AVERAGE(AN$3:AN$3) -> 0 | AO6: =AVERAGE(AO$3:AO$3) -> 0 | AP6: =AVERAGE(AP$3:AP$3) -> 0 | AQ6: =AVERAGE(AQ$3:AQ$3) -> 0 | AR6: =AVERAGE(AR$3:AR$3) -> 0 | AS6: =AVERAGE(AS$3:AS$3) -> 0 | AU6: =AVERAGE(AU$3:AU$3) -> 0 | AV6: =AVERAGE(AV$3:AV$3) -> 0 | AW6: =AVERAGE(AW$3:AW$3) -> 0 | AX6: =AVERAGE(AX$3:AX$3) -> 0 | AY6: =AVERAGE(AY$3:AY$3) -> 0 | AZ6: =AVERAGE(AZ$3:AZ$3) -> 0 | BB6: =AVERAGE(BB$3:BB$3) -> 0 | BC6: =AVERAGE(BC$3:BC$3) -> 0 | BD6: =AVERAGE(BD$3:BD$3) -> 0 | BE6: =AVERAGE(BE$3:BE$3) -> 0 | BF6: =AVERAGE(BF$3:BF$3) -> 0 | BG6: =AVERAGE(BG$3:BG$3) -> 0 | BI6: =AVERAGE(BI$3:BI$3) -> 0 | BJ6: =AVERAGE(BJ$3:BJ$3) -> 0 | BK6: =AVERAGE(BK$3:BK$3) -> 0 | BL6: =AVERAGE(BL$3:BL$3) -> 0 | BM6: =AVERAGE(BM$3:BM$3) -> 0 | BN6: =AVERAGE(BN$3:BN$3) -> 0 | BP6: =AVERAGE(BP$3:BP$3) -> 0 | BQ6: =AVERAGE(BQ$3:BQ$3) -> 0 | BR6: =AVERAGE(BR$3:BR$3) -> 0 | BS6: =AVERAGE(BS$3:BS$3) -> 0 | BT6: =AVERAGE(BT$3:BT$3) -> 0 | BU6: =AVERAGE(BU$3:BU$3) -> 0 | BW6: =AVERAGE(BW$3:BW$3) -> 0 | BX6: =AVERAGE(BX$3:BX$3) -> 0 | BY6: =AVERAGE(BY$3:BY$3) -> 0 | BZ6: =AVERAGE(BZ$3:BZ$3) -> 0 | CA6: =AVERAGE(CA$3:CA$3) -> 0 | CB6: =AVERAGE(CB$3:CB$3) -> 0 | CD6: =AVERAGE(CD$3:CD$3) -> 0 | CE6: =AVERAGE(CE$3:CE$3) -> 0 | CF6: =AVERAGE(CF$3:CF$3) -> 0 | CG6: =AVERAGE(CG$3:CG$3) -> 0 | CH6: =AVERAGE(CH$3:CH$3) -> 0 | CI6: =AVERAGE(CI$3:CI$3) -> 0 | CK6: =AVERAGE(CK$3:CK$3) -> 0 | CL6: =AVERAGE(CL$3:CL$3) -> 0 | CM6: =AVERAGE(CM$3:CM$3) -> 0 | CN6: =AVERAGE(CN$3:CN$3) -> 0 | CO6: =AVERAGE(CO$3:CO$3) -> 0 | CP6: =AVERAGE(CP$3:CP$3) -> 0 | CR6: =AVERAGE(CR$3:CR$3) -> 0 | CS6: =AVERAGE(CS$3:CS$3) -> 0 | CT6: =AVERAGE(CT$3:CT$3) -> 0 | CU6: =AVERAGE(CU$3:CU$3) -> 0 | CV6: =AVERAGE(CV$3:CV$3) -> 0 | CW6: =AVERAGE(CW$3:CW$3) -> 0 | CY6: =AVERAGE(CY$3:CY$3) -> 0 | CZ6: =AVERAGE(CZ$3:CZ$3) -> 0 | DA6: =AVERAGE(DA$3:DA$3) -> 0 | DB6: =AVERAGE(DB$3:DB$3) -> 0 | DC6: =AVERAGE(DC$3:DC$3) -> 0 | DD6: =AVERAGE(DD$3:DD$3) -> 0 | DF6: =AVERAGE(DF$3:DF$3) -> 0 | DG6: =AVERAGE(DG$3:DG$3) -> 0 | DH6: =AVERAGE(DH$3:DH$3) -> 0 | DI6: =AVERAGE(DI$3:DI$3) -> 0 | DJ6: =AVERAGE(DJ$3:DJ$3) -> 0 | DK6: =AVERAGE(DK$3:DK$3) -> 0 | DM6: =AVERAGE(DM$3:DM$3) -> 0 | DN6: =AVERAGE(DN$3:DN$3) -> 0 | DO6: =AVERAGE(DO$3:DO$3) -> 0 | DP6: =AVERAGE(DP$3:DP$3) -> 0 | DQ6: =AVERAGE(DQ$3:DQ$3) -> 0 | DR6: =AVERAGE(DR$3:DR$3) -> 0 | DT6: =AVERAGE(DT$3:DT$3) -> 0 | DU6: =AVERAGE(DU$3:DU$3) -> 0 | DV6: =AVERAGE(DV$3:DV$3) -> 0 | DW6: =AVERAGE(DW$3:DW$3) -> 0 | DX6: =AVERAGE(DX$3:DX$3) -> 0 | DY6: =AVERAGE(DY$3:DY$3) -> 0 | EA6: =AVERAGE(EA$3:EA$3) -> 0 | EB6: =AVERAGE(EB$3:EB$3) -> 0 | EC6: =AVERAGE(EC$3:EC$3) -> 0 | ED6: =AVERAGE(ED$3:ED$3) -> 0 | EE6: =AVERAGE(EE$3:EE$3) -> 0 | EF6: =AVERAGE(EF$3:EF$3) -> 0 | EH6: =AVERAGE(EH$3:EH$3) -> 0 | EI6: =AVERAGE(EI$3:EI$3) -> 0 | EJ6: =AVERAGE(EJ$3:EJ$3) -> 0 | EK6: =AVERAGE(EK$3:EK$3) -> 0 | EL6: =AVERAGE(EL$3:EL$3) -> 0 | EM6: =AVERAGE(EM$3:EM$3) -> 0 | EO6: =AVERAGE(EO$3:EO$3) -> 0 | EP6: =AVERAGE(EP$3:EP$3) -> 0 | EQ6: =AVERAGE(EQ$3:EQ$3) -> 0 | ER6: =AVERAGE(ER$3:ER$3) -> 0 | ES6: =AVERAGE(ES$3:ES$3) -> 0 | ET6: =AVERAGE(ET$3:ET$3) -> 0 | EU6: =AVERAGE(EU$3:EU$3) -> 0 | EV6: =AVERAGE(EV$3:EV$3) -> 0 | ... FJ6: =AVERAGE(FJ$3:FJ$3) -> 0
A7: DEV | B7: =STDEV(B$3:B$3) -> 0 | C7: =STDEV(C$3:C$3) -> 0 | E7: =STDEV(E$3:E$3) -> 0 | F7: =STDEV(F$3:F$3) -> 0 | G7: =STDEV(G$3:G$3) -> 0 | H7: =STDEV(H$3:H$3) -> 0 | I7: =STDEV(I$3:I$3) -> 0 | J7: =STDEV(J$3:J$3) -> 0 | L7: =STDEV(L$3:L$3) -> 0 | M7: =STDEV(M$3:M$3) -> 0 | N7: =STDEV(N$3:N$3) -> 0 | O7: =STDEV(O$3:O$3) -> 0 | P7: =STDEV(P$3:P$3) -> 0 | Q7: =STDEV(Q$3:Q$3) -> 0 | S7: =STDEV(S$3:S$3) -> 0 | T7: =STDEV(T$3:T$3) -> 0 | U7: =STDEV(U$3:U$3) -> 0 | V7: =STDEV(V$3:V$3) -> 0 | W7: =STDEV(W$3:W$3) -> 0 | X7: =STDEV(X$3:X$3) -> 0 | Z7: =STDEV(Z$3:Z$3) -> 0 | AA7: =STDEV(AA$3:AA$3) -> 0 | AB7: =STDEV(AB$3:AB$3) -> 0 | AC7: =STDEV(AC$3:AC$3) -> 0 | AD7: =STDEV(AD$3:AD$3) -> 0 | AE7: =STDEV(AE$3:AE$3) -> 0 | AG7: =STDEV(AG$3:AG$3) -> 0 | AH7: =STDEV(AH$3:AH$3) -> 0 | AI7: =STDEV(AI$3:AI$3) -> 0 | AJ7: =STDEV(AJ$3:AJ$3) -> 0 | AK7: =STDEV(AK$3:AK$3) -> 0 | AL7: =STDEV(AL$3:AL$3) -> 0 | AN7: =STDEV(AN$3:AN$3) -> 0 | AO7: =STDEV(AO$3:AO$3) -> 0 | AP7: =STDEV(AP$3:AP$3) -> 0 | AQ7: =STDEV(AQ$3:AQ$3) -> 0 | AR7: =STDEV(AR$3:AR$3) -> 0 | AS7: =STDEV(AS$3:AS$3) -> 0 | AU7: =STDEV(AU$3:AU$3) -> 0 | AV7: =STDEV(AV$3:AV$3) -> 0 | AW7: =STDEV(AW$3:AW$3) -> 0 | AX7: =STDEV(AX$3:AX$3) -> 0 | AY7: =STDEV(AY$3:AY$3) -> 0 | AZ7: =STDEV(AZ$3:AZ$3) -> 0 | BB7: =STDEV(BB$3:BB$3) -> 0 | BC7: =STDEV(BC$3:BC$3) -> 0 | BD7: =STDEV(BD$3:BD$3) -> 0 | BE7: =STDEV(BE$3:BE$3) -> 0 | BF7: =STDEV(BF$3:BF$3) -> 0 | BG7: =STDEV(BG$3:BG$3) -> 0 | BI7: =STDEV(BI$3:BI$3) -> 0 | BJ7: =STDEV(BJ$3:BJ$3) -> 0 | BK7: =STDEV(BK$3:BK$3) -> 0 | BL7: =STDEV(BL$3:BL$3) -> 0 | BM7: =STDEV(BM$3:BM$3) -> 0 | BN7: =STDEV(BN$3:BN$3) -> 0 | BP7: =STDEV(BP$3:BP$3) -> 0 | BQ7: =STDEV(BQ$3:BQ$3) -> 0 | BR7: =STDEV(BR$3:BR$3) -> 0 | BS7: =STDEV(BS$3:BS$3) -> 0 | BT7: =STDEV(BT$3:BT$3) -> 0 | BU7: =STDEV(BU$3:BU$3) -> 0 | BW7: =STDEV(BW$3:BW$3) -> 0 | BX7: =STDEV(BX$3:BX$3) -> 0 | BY7: =STDEV(BY$3:BY$3) -> 0 | BZ7: =STDEV(BZ$3:BZ$3) -> 0 | CA7: =STDEV(CA$3:CA$3) -> 0 | CB7: =STDEV(CB$3:CB$3) -> 0 | CD7: =STDEV(CD$3:CD$3) -> 0 | CE7: =STDEV(CE$3:CE$3) -> 0 | CF7: =STDEV(CF$3:CF$3) -> 0 | CG7: =STDEV(CG$3:CG$3) -> 0 | CH7: =STDEV(CH$3:CH$3) -> 0 | CI7: =STDEV(CI$3:CI$3) -> 0 | CK7: =STDEV(CK$3:CK$3) -> 0 | CL7: =STDEV(CL$3:CL$3) -> 0 | CM7: =STDEV(CM$3:CM$3) -> 0 | CN7: =STDEV(CN$3:CN$3) -> 0 | CO7: =STDEV(CO$3:CO$3) -> 0 | CP7: =STDEV(CP$3:CP$3) -> 0 | CR7: =STDEV(CR$3:CR$3) -> 0 | CS7: =STDEV(CS$3:CS$3) -> 0 | CT7: =STDEV(CT$3:CT$3) -> 0 | CU7: =STDEV(CU$3:CU$3) -> 0 | CV7: =STDEV(CV$3:CV$3) -> 0 | CW7: =STDEV(CW$3:CW$3) -> 0 | CY7: =STDEV(CY$3:CY$3) -> 0 | CZ7: =STDEV(CZ$3:CZ$3) -> 0 | DA7: =STDEV(DA$3:DA$3) -> 0 | DB7: =STDEV(DB$3:DB$3) -> 0 | DC7: =STDEV(DC$3:DC$3) -> 0 | DD7: =STDEV(DD$3:DD$3) -> 0 | DF7: =STDEV(DF$3:DF$3) -> 0 | DG7: =STDEV(DG$3:DG$3) -> 0 | DH7: =STDEV(DH$3:DH$3) -> 0 | DI7: =STDEV(DI$3:DI$3) -> 0 | DJ7: =STDEV(DJ$3:DJ$3) -> 0 | DK7: =STDEV(DK$3:DK$3) -> 0 | DM7: =STDEV(DM$3:DM$3) -> 0 | DN7: =STDEV(DN$3:DN$3) -> 0 | DO7: =STDEV(DO$3:DO$3) -> 0 | DP7: =STDEV(DP$3:DP$3) -> 0 | DQ7: =STDEV(DQ$3:DQ$3) -> 0 | DR7: =STDEV(DR$3:DR$3) -> 0 | DT7: =STDEV(DT$3:DT$3) -> 0 | DU7: =STDEV(DU$3:DU$3) -> 0 | DV7: =STDEV(DV$3:DV$3) -> 0 | DW7: =STDEV(DW$3:DW$3) -> 0 | DX7: =STDEV(DX$3:DX$3) -> 0 | DY7: =STDEV(DY$3:DY$3) -> 0 | EA7: =STDEV(EA$3:EA$3) -> 0 | EB7: =STDEV(EB$3:EB$3) -> 0 | EC7: =STDEV(EC$3:EC$3) -> 0 | ED7: =STDEV(ED$3:ED$3) -> 0 | EE7: =STDEV(EE$3:EE$3) -> 0 | EF7: =STDEV(EF$3:EF$3) -> 0 | EH7: =STDEV(EH$3:EH$3) -> 0 | EI7: =STDEV(EI$3:EI$3) -> 0 | EJ7: =STDEV(EJ$3:EJ$3) -> 0 | EK7: =STDEV(EK$3:EK$3) -> 0 | EL7: =STDEV(EL$3:EL$3) -> 0 | EM7: =STDEV(EM$3:EM$3) -> 0 | EO7: =STDEV(EO$3:EO$3) -> 0 | EP7: =STDEV(EP$3:EP$3) -> 0 | EQ7: =STDEV(EQ$3:EQ$3) -> 0 | ER7: =STDEV(ER$3:ER$3) -> 0 | ES7: =STDEV(ES$3:ES$3) -> 0 | ET7: =STDEV(ET$3:ET$3) -> 0 | EU7: =STDEV(EU$3:EU$3) -> 0 | EV7: =STDEV(EV$3:EV$3) -> 0 | ... FJ7: =STDEV(FJ$3:FJ$3) -> 0
A8: DST | B8: =SUMPRODUCT(--(B$3:B$3-$ES$3:$ES$3)^2)^0.5 -> 0 | C8: =SUMPRODUCT(--(C$3:C$3-$ET$3:$ET$3)^2)^0.5 -> 0 | E8: =SUMPRODUCT(--(E$3:E$3-$EU$3:$EU$3)^2)^0.5 -> 0 | F8: =SUMPRODUCT(--(F$3:F$3-$EV$3:$EV$3)^2)^0.5 -> 0 | G8: =SUMPRODUCT(--(G$3:G$3-$EW$3:$EW$3)^2)^0.5 -> 0 | H8: =SUMPRODUCT(--(H$3:H$3-$EX$3:$EX$3)^2)^0.5 -> 0 | I8: =SUMPRODUCT(--(I$3:I$3-$ES$3:$ES$3)^2)^0.5 -> 0 | J8: =SUMPRODUCT(--(J$3:J$3-$ET$3:$ET$3)^2)^0.5 -> 0 | L8: =SUMPRODUCT(--(L$3:L$3-$EU$3:$EU$3)^2)^0.5 -> 0 | M8: =SUMPRODUCT(--(M$3:M$3-$EV$3:$EV$3)^2)^0.5 -> 0 | N8: =SUMPRODUCT(--(N$3:N$3-$EW$3:$EW$3)^2)^0.5 -> 0 | O8: =SUMPRODUCT(--(O$3:O$3-$EX$3:$EX$3)^2)^0.5 -> 0 | P8: =SUMPRODUCT(--(P$3:P$3-$ES$3:$ES$3)^2)^0.5 -> 0 | Q8: =SUMPRODUCT(--(Q$3:Q$3-$ET$3:$ET$3)^2)^0.5 -> 0 | S8: =SUMPRODUCT(--(S$3:S$3-$EU$3:$EU$3)^2)^0.5 -> 0 | T8: =SUMPRODUCT(--(T$3:T$3-$EV$3:$EV$3)^2)^0.5 -> 0 | U8: =SUMPRODUCT(--(U$3:U$3-$EW$3:$EW$3)^2)^0.5 -> 0 | V8: =SUMPRODUCT(--(V$3:V$3-$EX$3:$EX$3)^2)^0.5 -> 0 | W8: =SUMPRODUCT(--(W$3:W$3-$ES$3:$ES$3)^2)^0.5 -> 0 | X8: =SUMPRODUCT(--(X$3:X$3-$ET$3:$ET$3)^2)^0.5 -> 0 | Z8: =SUMPRODUCT(--(Z$3:Z$3-$EU$3:$EU$3)^2)^0.5 -> 0 | AA8: =SUMPRODUCT(--(AA$3:AA$3-$EV$3:$EV$3)^2)^0.5 -> 0 | AB8: =SUMPRODUCT(--(AB$3:AB$3-$EW$3:$EW$3)^2)^0.5 -> 0 | AC8: =SUMPRODUCT(--(AC$3:AC$3-$EX$3:$EX$3)^2)^0.5 -> 0 | AD8: =SUMPRODUCT(--(AD$3:AD$3-$ES$3:$ES$3)^2)^0.5 -> 0 | AE8: =SUMPRODUCT(--(AE$3:AE$3-$ET$3:$ET$3)^2)^0.5 -> 0 | AG8: =SUMPRODUCT(--(AG$3:AG$3-$EU$3:$EU$3)^2)^0.5 -> 0 | AH8: =SUMPRODUCT(--(AH$3:AH$3-$EV$3:$EV$3)^2)^0.5 -> 0 | AI8: =SUMPRODUCT(--(AI$3:AI$3-$EW$3:$EW$3)^2)^0.5 -> 0 | AJ8: =SUMPRODUCT(--(AJ$3:AJ$3-$EX$3:$EX$3)^2)^0.5 -> 0 | AK8: =SUMPRODUCT(--(AK$3:AK$3-$ES$3:$ES$3)^2)^0.5 -> 0 | AL8: =SUMPRODUCT(--(AL$3:AL$3-$ET$3:$ET$3)^2)^0.5 -> 0 | AN8: =SUMPRODUCT(--(AN$3:AN$3-$EU$3:$EU$3)^2)^0.5 -> 0 | AO8: =SUMPRODUCT(--(AO$3:AO$3-$EV$3:$EV$3)^2)^0.5 -> 0 | AP8: =SUMPRODUCT(--(AP$3:AP$3-$EW$3:$EW$3)^2)^0.5 -> 0 | AQ8: =SUMPRODUCT(--(AQ$3:AQ$3-$EX$3:$EX$3)^2)^0.5 -> 0 | AR8: =SUMPRODUCT(--(AR$3:AR$3-$ES$3:$ES$3)^2)^0.5 -> 0 | AS8: =SUMPRODUCT(--(AS$3:AS$3-$ET$3:$ET$3)^2)^0.5 -> 0 | AU8: =SUMPRODUCT(--(AU$3:AU$3-$EU$3:$EU$3)^2)^0.5 -> 0 | AV8: =SUMPRODUCT(--(AV$3:AV$3-$EV$3:$EV$3)^2)^0.5 -> 0 | AW8: =SUMPRODUCT(--(AW$3:AW$3-$EW$3:$EW$3)^2)^0.5 -> 0 | AX8: =SUMPRODUCT(--(AX$3:AX$3-$EX$3:$EX$3)^2)^0.5 -> 0 | AY8: =SUMPRODUCT(--(AY$3:AY$3-$ES$3:$ES$3)^2)^0.5 -> 0 | AZ8: =SUMPRODUCT(--(AZ$3:AZ$3-$ET$3:$ET$3)^2)^0.5 -> 0 | BB8: =SUMPRODUCT(--(BB$3:BB$3-$EU$3:$EU$3)^2)^0.5 -> 0 | BC8: =SUMPRODUCT(--(BC$3:BC$3-$EV$3:$EV$3)^2)^0.5 -> 0 | BD8: =SUMPRODUCT(--(BD$3:BD$3-$EW$3:$EW$3)^2)^0.5 -> 0 | BE8: =SUMPRODUCT(--(BE$3:BE$3-$EX$3:$EX$3)^2)^0.5 -> 0 | BF8: =SUMPRODUCT(--(BF$3:BF$3-$ES$3:$ES$3)^2)^0.5 -> 0 | BG8: =SUMPRODUCT(--(BG$3:BG$3-$ET$3:$ET$3)^2)^0.5 -> 0 | BI8: =SUMPRODUCT(--(BI$3:BI$3-$EU$3:$EU$3)^2)^0.5 -> 0 | BJ8: =SUMPRODUCT(--(BJ$3:BJ$3-$EV$3:$EV$3)^2)^0.5 -> 0 | BK8: =SUMPRODUCT(--(BK$3:BK$3-$EW$3:$EW$3)^2)^0.5 -> 0 | BL8: =SUMPRODUCT(--(BL$3:BL$3-$EX$3:$EX$3)^2)^0.5 -> 0 | BM8: =SUMPRODUCT(--(BM$3:BM$3-$ES$3:$ES$3)^2)^0.5 -> 0 | BN8: =SUMPRODUCT(--(BN$3:BN$3-$ET$3:$ET$3)^2)^0.5 -> 0 | BP8: =SUMPRODUCT(--(BP$3:BP$3-$EU$3:$EU$3)^2)^0.5 -> 0 | BQ8: =SUMPRODUCT(--(BQ$3:BQ$3-$EV$3:$EV$3)^2)^0.5 -> 0 | BR8: =SUMPRODUCT(--(BR$3:BR$3-$EW$3:$EW$3)^2)^0.5 -> 0 | BS8: =SUMPRODUCT(--(BS$3:BS$3-$EX$3:$EX$3)^2)^0.5 -> 0 | BT8: =SUMPRODUCT(--(BT$3:BT$3-$ES$3:$ES$3)^2)^0.5 -> 0 | BU8: =SUMPRODUCT(--(BU$3:BU$3-$ET$3:$ET$3)^2)^0.5 -> 0 | BW8: =SUMPRODUCT(--(BW$3:BW$3-$EU$3:$EU$3)^2)^0.5 -> 0 | BX8: =SUMPRODUCT(--(BX$3:BX$3-$EV$3:$EV$3)^2)^0.5 -> 0 | BY8: =SUMPRODUCT(--(BY$3:BY$3-$EW$3:$EW$3)^2)^0.5 -> 0 | BZ8: =SUMPRODUCT(--(BZ$3:BZ$3-$EX$3:$EX$3)^2)^0.5 -> 0 | CA8: =SUMPRODUCT(--(CA$3:CA$3-$ES$3:$ES$3)^2)^0.5 -> 0 | CB8: =SUMPRODUCT(--(CB$3:CB$3-$ET$3:$ET$3)^2)^0.5 -> 0 | CD8: =SUMPRODUCT(--(CD$3:CD$3-$EU$3:$EU$3)^2)^0.5 -> 0 | CE8: =SUMPRODUCT(--(CE$3:CE$3-$EV$3:$EV$3)^2)^0.5 -> 0 | CF8: =SUMPRODUCT(--(CF$3:CF$3-$EW$3:$EW$3)^2)^0.5 -> 0 | CG8: =SUMPRODUCT(--(CG$3:CG$3-$EX$3:$EX$3)^2)^0.5 -> 0 | CH8: =SUMPRODUCT(--(CH$3:CH$3-$ES$3:$ES$3)^2)^0.5 -> 0 | CI8: =SUMPRODUCT(--(CI$3:CI$3-$ET$3:$ET$3)^2)^0.5 -> 0 | CK8: =SUMPRODUCT(--(CK$3:CK$3-$EU$3:$EU$3)^2)^0.5 -> 0 | CL8: =SUMPRODUCT(--(CL$3:CL$3-$EV$3:$EV$3)^2)^0.5 -> 0 | CM8: =SUMPRODUCT(--(CM$3:CM$3-$EW$3:$EW$3)^2)^0.5 -> 0 | CN8: =SUMPRODUCT(--(CN$3:CN$3-$EX$3:$EX$3)^2)^0.5 -> 0 | CO8: =SUMPRODUCT(--(CO$3:CO$3-$ES$3:$ES$3)^2)^0.5 -> 0 | CP8: =SUMPRODUCT(--(CP$3:CP$3-$ET$3:$ET$3)^2)^0.5 -> 0 | CR8: =SUMPRODUCT(--(CR$3:CR$3-$EU$3:$EU$3)^2)^0.5 -> 0 | CS8: =SUMPRODUCT(--(CS$3:CS$3-$EV$3:$EV$3)^2)^0.5 -> 0 | CT8: =SUMPRODUCT(--(CT$3:CT$3-$EW$3:$EW$3)^2)^0.5 -> 0 | CU8: =SUMPRODUCT(--(CU$3:CU$3-$EX$3:$EX$3)^2)^0.5 -> 0 | CV8: =SUMPRODUCT(--(CV$3:CV$3-$ES$3:$ES$3)^2)^0.5 -> 0 | CW8: =SUMPRODUCT(--(CW$3:CW$3-$ET$3:$ET$3)^2)^0.5 -> 0 | CY8: =SUMPRODUCT(--(CY$3:CY$3-$EU$3:$EU$3)^2)^0.5 -> 0 | CZ8: =SUMPRODUCT(--(CZ$3:CZ$3-$EV$3:$EV$3)^2)^0.5 -> 0 | DA8: =SUMPRODUCT(--(DA$3:DA$3-$EW$3:$EW$3)^2)^0.5 -> 0 | DB8: =SUMPRODUCT(--(DB$3:DB$3-$EX$3:$EX$3)^2)^0.5 -> 0 | DC8: =SUMPRODUCT(--(DC$3:DC$3-$ES$3:$ES$3)^2)^0.5 -> 0 | DD8: =SUMPRODUCT(--(DD$3:DD$3-$ET$3:$ET$3)^2)^0.5 -> 0 | DF8: =SUMPRODUCT(--(DF$3:DF$3-$EU$3:$EU$3)^2)^0.5 -> 0 | DG8: =SUMPRODUCT(--(DG$3:DG$3-$EV$3:$EV$3)^2)^0.5 -> 0 | DH8: =SUMPRODUCT(--(DH$3:DH$3-$EW$3:$EW$3)^2)^0.5 -> 0 | DI8: =SUMPRODUCT(--(DI$3:DI$3-$EX$3:$EX$3)^2)^0.5 -> 0 | DJ8: =SUMPRODUCT(--(DJ$3:DJ$3-$ES$3:$ES$3)^2)^0.5 -> 0 | DK8: =SUMPRODUCT(--(DK$3:DK$3-$ET$3:$ET$3)^2)^0.5 -> 0 | DM8: =SUMPRODUCT(--(DM$3:DM$3-$EU$3:$EU$3)^2)^0.5 -> 0 | DN8: =SUMPRODUCT(--(DN$3:DN$3-$EV$3:$EV$3)^2)^0.5 -> 0 | DO8: =SUMPRODUCT(--(DO$3:DO$3-$EW$3:$EW$3)^2)^0.5 -> 0 | DP8: =SUMPRODUCT(--(DP$3:DP$3-$EX$3:$EX$3)^2)^0.5 -> 0 | DQ8: =SUMPRODUCT(--(DQ$3:DQ$3-$ES$3:$ES$3)^2)^0.5 -> 0 | DR8: =SUMPRODUCT(--(DR$3:DR$3-$ET$3:$ET$3)^2)^0.5 -> 0 | DT8: =SUMPRODUCT(--(DT$3:DT$3-$EU$3:$EU$3)^2)^0.5 -> 0 | DU8: =SUMPRODUCT(--(DU$3:DU$3-$EV$3:$EV$3)^2)^0.5 -> 0 | DV8: =SUMPRODUCT(--(DV$3:DV$3-$EW$3:$EW$3)^2)^0.5 -> 0 | DW8: =SUMPRODUCT(--(DW$3:DW$3-$EX$3:$EX$3)^2)^0.5 -> 0 | DX8: =SUMPRODUCT(--(DX$3:DX$3-$ES$3:$ES$3)^2)^0.5 -> 0 | DY8: =SUMPRODUCT(--(DY$3:DY$3-$ET$3:$ET$3)^2)^0.5 -> 0 | EA8: =SUMPRODUCT(--(EA$3:EA$3-$EU$3:$EU$3)^2)^0.5 -> 0 | EB8: =SUMPRODUCT(--(EB$3:EB$3-$EV$3:$EV$3)^2)^0.5 -> 0 | EC8: =SUMPRODUCT(--(EC$3:EC$3-$EW$3:$EW$3)^2)^0.5 -> 0 | ED8: =SUMPRODUCT(--(ED$3:ED$3-$EX$3:$EX$3)^2)^0.5 -> 0 | EE8: =SUMPRODUCT(--(EE$3:EE$3-$ES$3:$ES$3)^2)^0.5 -> 0 | EF8: =SUMPRODUCT(--(EF$3:EF$3-$ET$3:$ET$3)^2)^0.5 -> 0 | EH8: =SUMPRODUCT(--(EH$3:EH$3-$EU$3:$EU$3)^2)^0.5 -> 0 | EI8: =SUMPRODUCT(--(EI$3:EI$3-$EV$3:$EV$3)^2)^0.5 -> 0 | EJ8: =SUMPRODUCT(--(EJ$3:EJ$3-$EW$3:$EW$3)^2)^0.5 -> 0 | EK8: =SUMPRODUCT(--(EK$3:EK$3-$EX$3:$EX$3)^2)^0.5 -> 0 | EL8: =SUMPRODUCT(--(EL$3:EL$3-$ES$3:$ES$3)^2)^0.5 -> 0 | EM8: =SUMPRODUCT(--(EM$3:EM$3-$ET$3:$ET$3)^2)^0.5 -> 0 | EO8: =SUMPRODUCT(--(EO$3:EO$3-$EU$3:$EU$3)^2)^0.5 -> 0 | EP8: =SUMPRODUCT(--(EP$3:EP$3-$EV$3:$EV$3)^2)^0.5 -> 0 | EQ8: =SUMPRODUCT(--(EQ$3:EQ$3-$EW$3:$EW$3)^2)^0.5 -> 0 | ER8: =SUMPRODUCT(--(ER$3:ER$3-$EX$3:$EX$3)^2)^0.5 -> 0
A9: BEST | B9: =SUMPRODUCT(NOT(ISBLANK(B$3:B$3))*(B$3:B$3=$ES$3:$ES$3)) -> 0 | C9: =SUMPRODUCT(NOT(ISBLANK(C$3:C$3))*(C$3:C$3=$ET$3:$ET$3)) -> 0 | E9: =SUMPRODUCT(NOT(ISBLANK(E$3:E$3))*(E$3:E$3=$EU$3:$EU$3)) -> 0 | F9: =SUMPRODUCT(NOT(ISBLANK(F$3:F$3))*(F$3:F$3=$EV$3:$EV$3)) -> 0 | G9: =SUMPRODUCT(NOT(ISBLANK(G$3:G$3))*(G$3:G$3=$EW$3:$EW$3)) -> 0 | H9: =SUMPRODUCT(NOT(ISBLANK(H$3:H$3))*(H$3:H$3=$EX$3:$EX$3)) -> 0 | I9: =SUMPRODUCT(NOT(ISBLANK(I$3:I$3))*(I$3:I$3=$ES$3:$ES$3)) -> 0 | J9: =SUMPRODUCT(NOT(ISBLANK(J$3:J$3))*(J$3:J$3=$ET$3:$ET$3)) -> 0 | L9: =SUMPRODUCT(NOT(ISBLANK(L$3:L$3))*(L$3:L$3=$EU$3:$EU$3)) -> 0 | M9: =SUMPRODUCT(NOT(ISBLANK(M$3:M$3))*(M$3:M$3=$EV$3:$EV$3)) -> 0 | N9: =SUMPRODUCT(NOT(ISBLANK(N$3:N$3))*(N$3:N$3=$EW$3:$EW$3)) -> 0 | O9: =SUMPRODUCT(NOT(ISBLANK(O$3:O$3))*(O$3:O$3=$EX$3:$EX$3)) -> 0 | P9: =SUMPRODUCT(NOT(ISBLANK(P$3:P$3))*(P$3:P$3=$ES$3:$ES$3)) -> 0 | Q9: =SUMPRODUCT(NOT(ISBLANK(Q$3:Q$3))*(Q$3:Q$3=$ET$3:$ET$3)) -> 0 | S9: =SUMPRODUCT(NOT(ISBLANK(S$3:S$3))*(S$3:S$3=$EU$3:$EU$3)) -> 0 | T9: =SUMPRODUCT(NOT(ISBLANK(T$3:T$3))*(T$3:T$3=$EV$3:$EV$3)) -> 0 | U9: =SUMPRODUCT(NOT(ISBLANK(U$3:U$3))*(U$3:U$3=$EW$3:$EW$3)) -> 0 | V9: =SUMPRODUCT(NOT(ISBLANK(V$3:V$3))*(V$3:V$3=$EX$3:$EX$3)) -> 0 | W9: =SUMPRODUCT(NOT(ISBLANK(W$3:W$3))*(W$3:W$3=$ES$3:$ES$3)) -> 0 | X9: =SUMPRODUCT(NOT(ISBLANK(X$3:X$3))*(X$3:X$3=$ET$3:$ET$3)) -> 0 | Z9: =SUMPRODUCT(NOT(ISBLANK(Z$3:Z$3))*(Z$3:Z$3=$EU$3:$EU$3)) -> 0 | AA9: =SUMPRODUCT(NOT(ISBLANK(AA$3:AA$3))*(AA$3:AA$3=$EV$3:$EV$3)) -> 0 | AB9: =SUMPRODUCT(NOT(ISBLANK(AB$3:AB$3))*(AB$3:AB$3=$EW$3:$EW$3)) -> 0 | AC9: =SUMPRODUCT(NOT(ISBLANK(AC$3:AC$3))*(AC$3:AC$3=$EX$3:$EX$3)) -> 0 | AD9: =SUMPRODUCT(NOT(ISBLANK(AD$3:AD$3))*(AD$3:AD$3=$ES$3:$ES$3)) -> 0 | AE9: =SUMPRODUCT(NOT(ISBLANK(AE$3:AE$3))*(AE$3:AE$3=$ET$3:$ET$3)) -> 0 | AG9: =SUMPRODUCT(NOT(ISBLANK(AG$3:AG$3))*(AG$3:AG$3=$EU$3:$EU$3)) -> 0 | AH9: =SUMPRODUCT(NOT(ISBLANK(AH$3:AH$3))*(AH$3:AH$3=$EV$3:$EV$3)) -> 0 | AI9: =SUMPRODUCT(NOT(ISBLANK(AI$3:AI$3))*(AI$3:AI$3=$EW$3:$EW$3)) -> 0 | AJ9: =SUMPRODUCT(NOT(ISBLANK(AJ$3:AJ$3))*(AJ$3:AJ$3=$EX$3:$EX$3)) -> 0 | AK9: =SUMPRODUCT(NOT(ISBLANK(AK$3:AK$3))*(AK$3:AK$3=$ES$3:$ES$3)) -> 0 | AL9: =SUMPRODUCT(NOT(ISBLANK(AL$3:AL$3))*(AL$3:AL$3=$ET$3:$ET$3)) -> 0 | AN9: =SUMPRODUCT(NOT(ISBLANK(AN$3:AN$3))*(AN$3:AN$3=$EU$3:$EU$3)) -> 0 | AO9: =SUMPRODUCT(NOT(ISBLANK(AO$3:AO$3))*(AO$3:AO$3=$EV$3:$EV$3)) -> 0 | AP9: =SUMPRODUCT(NOT(ISBLANK(AP$3:AP$3))*(AP$3:AP$3=$EW$3:$EW$3)) -> 0 | AQ9: =SUMPRODUCT(NOT(ISBLANK(AQ$3:AQ$3))*(AQ$3:AQ$3=$EX$3:$EX$3)) -> 0 | AR9: =SUMPRODUCT(NOT(ISBLANK(AR$3:AR$3))*(AR$3:AR$3=$ES$3:$ES$3)) -> 0 | AS9: =SUMPRODUCT(NOT(ISBLANK(AS$3:AS$3))*(AS$3:AS$3=$ET$3:$ET$3)) -> 0 | AU9: =SUMPRODUCT(NOT(ISBLANK(AU$3:AU$3))*(AU$3:AU$3=$EU$3:$EU$3)) -> 0 | AV9: =SUMPRODUCT(NOT(ISBLANK(AV$3:AV$3))*(AV$3:AV$3=$EV$3:$EV$3)) -> 0 | AW9: =SUMPRODUCT(NOT(ISBLANK(AW$3:AW$3))*(AW$3:AW$3=$EW$3:$EW$3)) -> 0 | AX9: =SUMPRODUCT(NOT(ISBLANK(AX$3:AX$3))*(AX$3:AX$3=$EX$3:$EX$3)) -> 0 | AY9: =SUMPRODUCT(NOT(ISBLANK(AY$3:AY$3))*(AY$3:AY$3=$ES$3:$ES$3)) -> 0 | AZ9: =SUMPRODUCT(NOT(ISBLANK(AZ$3:AZ$3))*(AZ$3:AZ$3=$ET$3:$ET$3)) -> 0 | BB9: =SUMPRODUCT(NOT(ISBLANK(BB$3:BB$3))*(BB$3:BB$3=$EU$3:$EU$3)) -> 0 | BC9: =SUMPRODUCT(NOT(ISBLANK(BC$3:BC$3))*(BC$3:BC$3=$EV$3:$EV$3)) -> 0 | BD9: =SUMPRODUCT(NOT(ISBLANK(BD$3:BD$3))*(BD$3:BD$3=$EW$3:$EW$3)) -> 0 | BE9: =SUMPRODUCT(NOT(ISBLANK(BE$3:BE$3))*(BE$3:BE$3=$EX$3:$EX$3)) -> 0 | BF9: =SUMPRODUCT(NOT(ISBLANK(BF$3:BF$3))*(BF$3:BF$3=$ES$3:$ES$3)) -> 0 | BG9: =SUMPRODUCT(NOT(ISBLANK(BG$3:BG$3))*(BG$3:BG$3=$ET$3:$ET$3)) -> 0 | BI9: =SUMPRODUCT(NOT(ISBLANK(BI$3:BI$3))*(BI$3:BI$3=$EU$3:$EU$3)) -> 0 | BJ9: =SUMPRODUCT(NOT(ISBLANK(BJ$3:BJ$3))*(BJ$3:BJ$3=$EV$3:$EV$3)) -> 0 | BK9: =SUMPRODUCT(NOT(ISBLANK(BK$3:BK$3))*(BK$3:BK$3=$EW$3:$EW$3)) -> 0 | BL9: =SUMPRODUCT(NOT(ISBLANK(BL$3:BL$3))*(BL$3:BL$3=$EX$3:$EX$3)) -> 0 | BM9: =SUMPRODUCT(NOT(ISBLANK(BM$3:BM$3))*(BM$3:BM$3=$ES$3:$ES$3)) -> 0 | BN9: =SUMPRODUCT(NOT(ISBLANK(BN$3:BN$3))*(BN$3:BN$3=$ET$3:$ET$3)) -> 0 | BP9: =SUMPRODUCT(NOT(ISBLANK(BP$3:BP$3))*(BP$3:BP$3=$EU$3:$EU$3)) -> 0 | BQ9: =SUMPRODUCT(NOT(ISBLANK(BQ$3:BQ$3))*(BQ$3:BQ$3=$EV$3:$EV$3)) -> 0 | BR9: =SUMPRODUCT(NOT(ISBLANK(BR$3:BR$3))*(BR$3:BR$3=$EW$3:$EW$3)) -> 0 | BS9: =SUMPRODUCT(NOT(ISBLANK(BS$3:BS$3))*(BS$3:BS$3=$EX$3:$EX$3)) -> 0 | BT9: =SUMPRODUCT(NOT(ISBLANK(BT$3:BT$3))*(BT$3:BT$3=$ES$3:$ES$3)) -> 0 | BU9: =SUMPRODUCT(NOT(ISBLANK(BU$3:BU$3))*(BU$3:BU$3=$ET$3:$ET$3)) -> 0 | BW9: =SUMPRODUCT(NOT(ISBLANK(BW$3:BW$3))*(BW$3:BW$3=$EU$3:$EU$3)) -> 0 | BX9: =SUMPRODUCT(NOT(ISBLANK(BX$3:BX$3))*(BX$3:BX$3=$EV$3:$EV$3)) -> 0 | BY9: =SUMPRODUCT(NOT(ISBLANK(BY$3:BY$3))*(BY$3:BY$3=$EW$3:$EW$3)) -> 0 | BZ9: =SUMPRODUCT(NOT(ISBLANK(BZ$3:BZ$3))*(BZ$3:BZ$3=$EX$3:$EX$3)) -> 0 | CA9: =SUMPRODUCT(NOT(ISBLANK(CA$3:CA$3))*(CA$3:CA$3=$ES$3:$ES$3)) -> 0 | CB9: =SUMPRODUCT(NOT(ISBLANK(CB$3:CB$3))*(CB$3:CB$3=$ET$3:$ET$3)) -> 0 | CD9: =SUMPRODUCT(NOT(ISBLANK(CD$3:CD$3))*(CD$3:CD$3=$EU$3:$EU$3)) -> 0 | CE9: =SUMPRODUCT(NOT(ISBLANK(CE$3:CE$3))*(CE$3:CE$3=$EV$3:$EV$3)) -> 0 | CF9: =SUMPRODUCT(NOT(ISBLANK(CF$3:CF$3))*(CF$3:CF$3=$EW$3:$EW$3)) -> 0 | CG9: =SUMPRODUCT(NOT(ISBLANK(CG$3:CG$3))*(CG$3:CG$3=$EX$3:$EX$3)) -> 0 | CH9: =SUMPRODUCT(NOT(ISBLANK(CH$3:CH$3))*(CH$3:CH$3=$ES$3:$ES$3)) -> 0 | CI9: =SUMPRODUCT(NOT(ISBLANK(CI$3:CI$3))*(CI$3:CI$3=$ET$3:$ET$3)) -> 0 | CK9: =SUMPRODUCT(NOT(ISBLANK(CK$3:CK$3))*(CK$3:CK$3=$EU$3:$EU$3)) -> 0 | CL9: =SUMPRODUCT(NOT(ISBLANK(CL$3:CL$3))*(CL$3:CL$3=$EV$3:$EV$3)) -> 0 | CM9: =SUMPRODUCT(NOT(ISBLANK(CM$3:CM$3))*(CM$3:CM$3=$EW$3:$EW$3)) -> 0 | CN9: =SUMPRODUCT(NOT(ISBLANK(CN$3:CN$3))*(CN$3:CN$3=$EX$3:$EX$3)) -> 0 | CO9: =SUMPRODUCT(NOT(ISBLANK(CO$3:CO$3))*(CO$3:CO$3=$ES$3:$ES$3)) -> 0 | CP9: =SUMPRODUCT(NOT(ISBLANK(CP$3:CP$3))*(CP$3:CP$3=$ET$3:$ET$3)) -> 0 | CR9: =SUMPRODUCT(NOT(ISBLANK(CR$3:CR$3))*(CR$3:CR$3=$EU$3:$EU$3)) -> 0 | CS9: =SUMPRODUCT(NOT(ISBLANK(CS$3:CS$3))*(CS$3:CS$3=$EV$3:$EV$3)) -> 0 | CT9: =SUMPRODUCT(NOT(ISBLANK(CT$3:CT$3))*(CT$3:CT$3=$EW$3:$EW$3)) -> 0 | CU9: =SUMPRODUCT(NOT(ISBLANK(CU$3:CU$3))*(CU$3:CU$3=$EX$3:$EX$3)) -> 0 | CV9: =SUMPRODUCT(NOT(ISBLANK(CV$3:CV$3))*(CV$3:CV$3=$ES$3:$ES$3)) -> 0 | CW9: =SUMPRODUCT(NOT(ISBLANK(CW$3:CW$3))*(CW$3:CW$3=$ET$3:$ET$3)) -> 0 | CY9: =SUMPRODUCT(NOT(ISBLANK(CY$3:CY$3))*(CY$3:CY$3=$EU$3:$EU$3)) -> 0 | CZ9: =SUMPRODUCT(NOT(ISBLANK(CZ$3:CZ$3))*(CZ$3:CZ$3=$EV$3:$EV$3)) -> 0 | DA9: =SUMPRODUCT(NOT(ISBLANK(DA$3:DA$3))*(DA$3:DA$3=$EW$3:$EW$3)) -> 0 | DB9: =SUMPRODUCT(NOT(ISBLANK(DB$3:DB$3))*(DB$3:DB$3=$EX$3:$EX$3)) -> 0 | DC9: =SUMPRODUCT(NOT(ISBLANK(DC$3:DC$3))*(DC$3:DC$3=$ES$3:$ES$3)) -> 0 | DD9: =SUMPRODUCT(NOT(ISBLANK(DD$3:DD$3))*(DD$3:DD$3=$ET$3:$ET$3)) -> 0 | DF9: =SUMPRODUCT(NOT(ISBLANK(DF$3:DF$3))*(DF$3:DF$3=$EU$3:$EU$3)) -> 0 | DG9: =SUMPRODUCT(NOT(ISBLANK(DG$3:DG$3))*(DG$3:DG$3=$EV$3:$EV$3)) -> 0 | DH9: =SUMPRODUCT(NOT(ISBLANK(DH$3:DH$3))*(DH$3:DH$3=$EW$3:$EW$3)) -> 0 | DI9: =SUMPRODUCT(NOT(ISBLANK(DI$3:DI$3))*(DI$3:DI$3=$EX$3:$EX$3)) -> 0 | DJ9: =SUMPRODUCT(NOT(ISBLANK(DJ$3:DJ$3))*(DJ$3:DJ$3=$ES$3:$ES$3)) -> 0 | DK9: =SUMPRODUCT(NOT(ISBLANK(DK$3:DK$3))*(DK$3:DK$3=$ET$3:$ET$3)) -> 0 | DM9: =SUMPRODUCT(NOT(ISBLANK(DM$3:DM$3))*(DM$3:DM$3=$EU$3:$EU$3)) -> 0 | DN9: =SUMPRODUCT(NOT(ISBLANK(DN$3:DN$3))*(DN$3:DN$3=$EV$3:$EV$3)) -> 0 | DO9: =SUMPRODUCT(NOT(ISBLANK(DO$3:DO$3))*(DO$3:DO$3=$EW$3:$EW$3)) -> 0 | DP9: =SUMPRODUCT(NOT(ISBLANK(DP$3:DP$3))*(DP$3:DP$3=$EX$3:$EX$3)) -> 0 | DQ9: =SUMPRODUCT(NOT(ISBLANK(DQ$3:DQ$3))*(DQ$3:DQ$3=$ES$3:$ES$3)) -> 0 | DR9: =SUMPRODUCT(NOT(ISBLANK(DR$3:DR$3))*(DR$3:DR$3=$ET$3:$ET$3)) -> 0 | DT9: =SUMPRODUCT(NOT(ISBLANK(DT$3:DT$3))*(DT$3:DT$3=$EU$3:$EU$3)) -> 0 | DU9: =SUMPRODUCT(NOT(ISBLANK(DU$3:DU$3))*(DU$3:DU$3=$EV$3:$EV$3)) -> 0 | DV9: =SUMPRODUCT(NOT(ISBLANK(DV$3:DV$3))*(DV$3:DV$3=$EW$3:$EW$3)) -> 0 | DW9: =SUMPRODUCT(NOT(ISBLANK(DW$3:DW$3))*(DW$3:DW$3=$EX$3:$EX$3)) -> 0 | DX9: =SUMPRODUCT(NOT(ISBLANK(DX$3:DX$3))*(DX$3:DX$3=$ES$3:$ES$3)) -> 0 | DY9: =SUMPRODUCT(NOT(ISBLANK(DY$3:DY$3))*(DY$3:DY$3=$ET$3:$ET$3)) -> 0 | EA9: =SUMPRODUCT(NOT(ISBLANK(EA$3:EA$3))*(EA$3:EA$3=$EU$3:$EU$3)) -> 0 | EB9: =SUMPRODUCT(NOT(ISBLANK(EB$3:EB$3))*(EB$3:EB$3=$EV$3:$EV$3)) -> 0 | EC9: =SUMPRODUCT(NOT(ISBLANK(EC$3:EC$3))*(EC$3:EC$3=$EW$3:$EW$3)) -> 0 | ED9: =SUMPRODUCT(NOT(ISBLANK(ED$3:ED$3))*(ED$3:ED$3=$EX$3:$EX$3)) -> 0 | EE9: =SUMPRODUCT(NOT(ISBLANK(EE$3:EE$3))*(EE$3:EE$3=$ES$3:$ES$3)) -> 0 | EF9: =SUMPRODUCT(NOT(ISBLANK(EF$3:EF$3))*(EF$3:EF$3=$ET$3:$ET$3)) -> 0 | EH9: =SUMPRODUCT(NOT(ISBLANK(EH$3:EH$3))*(EH$3:EH$3=$EU$3:$EU$3)) -> 0 | EI9: =SUMPRODUCT(NOT(ISBLANK(EI$3:EI$3))*(EI$3:EI$3=$EV$3:$EV$3)) -> 0 | EJ9: =SUMPRODUCT(NOT(ISBLANK(EJ$3:EJ$3))*(EJ$3:EJ$3=$EW$3:$EW$3)) -> 0 | EK9: =SUMPRODUCT(NOT(ISBLANK(EK$3:EK$3))*(EK$3:EK$3=$EX$3:$EX$3)) -> 0 | EL9: =SUMPRODUCT(NOT(ISBLANK(EL$3:EL$3))*(EL$3:EL$3=$ES$3:$ES$3)) -> 0 | EM9: =SUMPRODUCT(NOT(ISBLANK(EM$3:EM$3))*(EM$3:EM$3=$ET$3:$ET$3)) -> 0 | EO9: =SUMPRODUCT(NOT(ISBLANK(EO$3:EO$3))*(EO$3:EO$3=$EU$3:$EU$3)) -> 0 | EP9: =SUMPRODUCT(NOT(ISBLANK(EP$3:EP$3))*(EP$3:EP$3=$EV$3:$EV$3)) -> 0 | EQ9: =SUMPRODUCT(NOT(ISBLANK(EQ$3:EQ$3))*(EQ$3:EQ$3=$EW$3:$EW$3)) -> 0 | ER9: =SUMPRODUCT(NOT(ISBLANK(ER$3:ER$3))*(ER$3:ER$3=$EX$3:$EX$3)) -> 0
A10: BETTER | B10: =SUMPRODUCT(NOT(ISBLANK(B$3:B$3))*(B$3:B$3<$EY$3:$EY$3)) -> 0 | C10: =SUMPRODUCT(NOT(ISBLANK(C$3:C$3))*(C$3:C$3<$EZ$3:$EZ$3)) -> 0 | E10: =SUMPRODUCT(NOT(ISBLANK(E$3:E$3))*(E$3:E$3<$FA$3:$FA$3)) -> 0 | F10: =SUMPRODUCT(NOT(ISBLANK(F$3:F$3))*(F$3:F$3<$FB$3:$FB$3)) -> 0 | G10: =SUMPRODUCT(NOT(ISBLANK(G$3:G$3))*(G$3:G$3<$FC$3:$FC$3)) -> 0 | H10: =SUMPRODUCT(NOT(ISBLANK(H$3:H$3))*(H$3:H$3<$FD$3:$FD$3)) -> 0 | I10: =SUMPRODUCT(NOT(ISBLANK(I$3:I$3))*(I$3:I$3<$EY$3:$EY$3)) -> 0 | J10: =SUMPRODUCT(NOT(ISBLANK(J$3:J$3))*(J$3:J$3<$EZ$3:$EZ$3)) -> 0 | L10: =SUMPRODUCT(NOT(ISBLANK(L$3:L$3))*(L$3:L$3<$FA$3:$FA$3)) -> 0 | M10: =SUMPRODUCT(NOT(ISBLANK(M$3:M$3))*(M$3:M$3<$FB$3:$FB$3)) -> 0 | N10: =SUMPRODUCT(NOT(ISBLANK(N$3:N$3))*(N$3:N$3<$FC$3:$FC$3)) -> 0 | O10: =SUMPRODUCT(NOT(ISBLANK(O$3:O$3))*(O$3:O$3<$FD$3:$FD$3)) -> 0 | P10: =SUMPRODUCT(NOT(ISBLANK(P$3:P$3))*(P$3:P$3<$EY$3:$EY$3)) -> 0 | Q10: =SUMPRODUCT(NOT(ISBLANK(Q$3:Q$3))*(Q$3:Q$3<$EZ$3:$EZ$3)) -> 0 | S10: =SUMPRODUCT(NOT(ISBLANK(S$3:S$3))*(S$3:S$3<$FA$3:$FA$3)) -> 0 | T10: =SUMPRODUCT(NOT(ISBLANK(T$3:T$3))*(T$3:T$3<$FB$3:$FB$3)) -> 0 | U10: =SUMPRODUCT(NOT(ISBLANK(U$3:U$3))*(U$3:U$3<$FC$3:$FC$3)) -> 0 | V10: =SUMPRODUCT(NOT(ISBLANK(V$3:V$3))*(V$3:V$3<$FD$3:$FD$3)) -> 0 | W10: =SUMPRODUCT(NOT(ISBLANK(W$3:W$3))*(W$3:W$3<$EY$3:$EY$3)) -> 0 | X10: =SUMPRODUCT(NOT(ISBLANK(X$3:X$3))*(X$3:X$3<$EZ$3:$EZ$3)) -> 0 | Z10: =SUMPRODUCT(NOT(ISBLANK(Z$3:Z$3))*(Z$3:Z$3<$FA$3:$FA$3)) -> 0 | AA10: =SUMPRODUCT(NOT(ISBLANK(AA$3:AA$3))*(AA$3:AA$3<$FB$3:$FB$3)) -> 0 | AB10: =SUMPRODUCT(NOT(ISBLANK(AB$3:AB$3))*(AB$3:AB$3<$FC$3:$FC$3)) -> 0 | AC10: =SUMPRODUCT(NOT(ISBLANK(AC$3:AC$3))*(AC$3:AC$3<$FD$3:$FD$3)) -> 0 | AD10: =SUMPRODUCT(NOT(ISBLANK(AD$3:AD$3))*(AD$3:AD$3<$EY$3:$EY$3)) -> 0 | AE10: =SUMPRODUCT(NOT(ISBLANK(AE$3:AE$3))*(AE$3:AE$3<$EZ$3:$EZ$3)) -> 0 | AG10: =SUMPRODUCT(NOT(ISBLANK(AG$3:AG$3))*(AG$3:AG$3<$FA$3:$FA$3)) -> 0 | AH10: =SUMPRODUCT(NOT(ISBLANK(AH$3:AH$3))*(AH$3:AH$3<$FB$3:$FB$3)) -> 0 | AI10: =SUMPRODUCT(NOT(ISBLANK(AI$3:AI$3))*(AI$3:AI$3<$FC$3:$FC$3)) -> 0 | AJ10: =SUMPRODUCT(NOT(ISBLANK(AJ$3:AJ$3))*(AJ$3:AJ$3<$FD$3:$FD$3)) -> 0 | AK10: =SUMPRODUCT(NOT(ISBLANK(AK$3:AK$3))*(AK$3:AK$3<$EY$3:$EY$3)) -> 0 | AL10: =SUMPRODUCT(NOT(ISBLANK(AL$3:AL$3))*(AL$3:AL$3<$EZ$3:$EZ$3)) -> 0 | AN10: =SUMPRODUCT(NOT(ISBLANK(AN$3:AN$3))*(AN$3:AN$3<$FA$3:$FA$3)) -> 0 | AO10: =SUMPRODUCT(NOT(ISBLANK(AO$3:AO$3))*(AO$3:AO$3<$FB$3:$FB$3)) -> 0 | AP10: =SUMPRODUCT(NOT(ISBLANK(AP$3:AP$3))*(AP$3:AP$3<$FC$3:$FC$3)) -> 0 | AQ10: =SUMPRODUCT(NOT(ISBLANK(AQ$3:AQ$3))*(AQ$3:AQ$3<$FD$3:$FD$3)) -> 0 | AR10: =SUMPRODUCT(NOT(ISBLANK(AR$3:AR$3))*(AR$3:AR$3<$EY$3:$EY$3)) -> 0 | AS10: =SUMPRODUCT(NOT(ISBLANK(AS$3:AS$3))*(AS$3:AS$3<$EZ$3:$EZ$3)) -> 0 | AU10: =SUMPRODUCT(NOT(ISBLANK(AU$3:AU$3))*(AU$3:AU$3<$FA$3:$FA$3)) -> 0 | AV10: =SUMPRODUCT(NOT(ISBLANK(AV$3:AV$3))*(AV$3:AV$3<$FB$3:$FB$3)) -> 0 | AW10: =SUMPRODUCT(NOT(ISBLANK(AW$3:AW$3))*(AW$3:AW$3<$FC$3:$FC$3)) -> 0 | AX10: =SUMPRODUCT(NOT(ISBLANK(AX$3:AX$3))*(AX$3:AX$3<$FD$3:$FD$3)) -> 0 | AY10: =SUMPRODUCT(NOT(ISBLANK(AY$3:AY$3))*(AY$3:AY$3<$EY$3:$EY$3)) -> 0 | AZ10: =SUMPRODUCT(NOT(ISBLANK(AZ$3:AZ$3))*(AZ$3:AZ$3<$EZ$3:$EZ$3)) -> 0 | BB10: =SUMPRODUCT(NOT(ISBLANK(BB$3:BB$3))*(BB$3:BB$3<$FA$3:$FA$3)) -> 0 | BC10: =SUMPRODUCT(NOT(ISBLANK(BC$3:BC$3))*(BC$3:BC$3<$FB$3:$FB$3)) -> 0 | BD10: =SUMPRODUCT(NOT(ISBLANK(BD$3:BD$3))*(BD$3:BD$3<$FC$3:$FC$3)) -> 0 | BE10: =SUMPRODUCT(NOT(ISBLANK(BE$3:BE$3))*(BE$3:BE$3<$FD$3:$FD$3)) -> 0 | BF10: =SUMPRODUCT(NOT(ISBLANK(BF$3:BF$3))*(BF$3:BF$3<$EY$3:$EY$3)) -> 0 | BG10: =SUMPRODUCT(NOT(ISBLANK(BG$3:BG$3))*(BG$3:BG$3<$EZ$3:$EZ$3)) -> 0 | BI10: =SUMPRODUCT(NOT(ISBLANK(BI$3:BI$3))*(BI$3:BI$3<$FA$3:$FA$3)) -> 0 | BJ10: =SUMPRODUCT(NOT(ISBLANK(BJ$3:BJ$3))*(BJ$3:BJ$3<$FB$3:$FB$3)) -> 0 | BK10: =SUMPRODUCT(NOT(ISBLANK(BK$3:BK$3))*(BK$3:BK$3<$FC$3:$FC$3)) -> 0 | BL10: =SUMPRODUCT(NOT(ISBLANK(BL$3:BL$3))*(BL$3:BL$3<$FD$3:$FD$3)) -> 0 | BM10: =SUMPRODUCT(NOT(ISBLANK(BM$3:BM$3))*(BM$3:BM$3<$EY$3:$EY$3)) -> 0 | BN10: =SUMPRODUCT(NOT(ISBLANK(BN$3:BN$3))*(BN$3:BN$3<$EZ$3:$EZ$3)) -> 0 | BP10: =SUMPRODUCT(NOT(ISBLANK(BP$3:BP$3))*(BP$3:BP$3<$FA$3:$FA$3)) -> 0 | BQ10: =SUMPRODUCT(NOT(ISBLANK(BQ$3:BQ$3))*(BQ$3:BQ$3<$FB$3:$FB$3)) -> 0 | BR10: =SUMPRODUCT(NOT(ISBLANK(BR$3:BR$3))*(BR$3:BR$3<$FC$3:$FC$3)) -> 0 | BS10: =SUMPRODUCT(NOT(ISBLANK(BS$3:BS$3))*(BS$3:BS$3<$FD$3:$FD$3)) -> 0 | BT10: =SUMPRODUCT(NOT(ISBLANK(BT$3:BT$3))*(BT$3:BT$3<$EY$3:$EY$3)) -> 0 | BU10: =SUMPRODUCT(NOT(ISBLANK(BU$3:BU$3))*(BU$3:BU$3<$EZ$3:$EZ$3)) -> 0 | BW10: =SUMPRODUCT(NOT(ISBLANK(BW$3:BW$3))*(BW$3:BW$3<$FA$3:$FA$3)) -> 0 | BX10: =SUMPRODUCT(NOT(ISBLANK(BX$3:BX$3))*(BX$3:BX$3<$FB$3:$FB$3)) -> 0 | BY10: =SUMPRODUCT(NOT(ISBLANK(BY$3:BY$3))*(BY$3:BY$3<$FC$3:$FC$3)) -> 0 | BZ10: =SUMPRODUCT(NOT(ISBLANK(BZ$3:BZ$3))*(BZ$3:BZ$3<$FD$3:$FD$3)) -> 0 | CA10: =SUMPRODUCT(NOT(ISBLANK(CA$3:CA$3))*(CA$3:CA$3<$EY$3:$EY$3)) -> 0 | CB10: =SUMPRODUCT(NOT(ISBLANK(CB$3:CB$3))*(CB$3:CB$3<$EZ$3:$EZ$3)) -> 0 | CD10: =SUMPRODUCT(NOT(ISBLANK(CD$3:CD$3))*(CD$3:CD$3<$FA$3:$FA$3)) -> 0 | CE10: =SUMPRODUCT(NOT(ISBLANK(CE$3:CE$3))*(CE$3:CE$3<$FB$3:$FB$3)) -> 0 | CF10: =SUMPRODUCT(NOT(ISBLANK(CF$3:CF$3))*(CF$3:CF$3<$FC$3:$FC$3)) -> 0 | CG10: =SUMPRODUCT(NOT(ISBLANK(CG$3:CG$3))*(CG$3:CG$3<$FD$3:$FD$3)) -> 0 | CH10: =SUMPRODUCT(NOT(ISBLANK(CH$3:CH$3))*(CH$3:CH$3<$EY$3:$EY$3)) -> 0 | CI10: =SUMPRODUCT(NOT(ISBLANK(CI$3:CI$3))*(CI$3:CI$3<$EZ$3:$EZ$3)) -> 0 | CK10: =SUMPRODUCT(NOT(ISBLANK(CK$3:CK$3))*(CK$3:CK$3<$FA$3:$FA$3)) -> 0 | CL10: =SUMPRODUCT(NOT(ISBLANK(CL$3:CL$3))*(CL$3:CL$3<$FB$3:$FB$3)) -> 0 | CM10: =SUMPRODUCT(NOT(ISBLANK(CM$3:CM$3))*(CM$3:CM$3<$FC$3:$FC$3)) -> 0 | CN10: =SUMPRODUCT(NOT(ISBLANK(CN$3:CN$3))*(CN$3:CN$3<$FD$3:$FD$3)) -> 0 | CO10: =SUMPRODUCT(NOT(ISBLANK(CO$3:CO$3))*(CO$3:CO$3<$EY$3:$EY$3)) -> 0 | CP10: =SUMPRODUCT(NOT(ISBLANK(CP$3:CP$3))*(CP$3:CP$3<$EZ$3:$EZ$3)) -> 0 | CR10: =SUMPRODUCT(NOT(ISBLANK(CR$3:CR$3))*(CR$3:CR$3<$FA$3:$FA$3)) -> 0 | CS10: =SUMPRODUCT(NOT(ISBLANK(CS$3:CS$3))*(CS$3:CS$3<$FB$3:$FB$3)) -> 0 | CT10: =SUMPRODUCT(NOT(ISBLANK(CT$3:CT$3))*(CT$3:CT$3<$FC$3:$FC$3)) -> 0 | CU10: =SUMPRODUCT(NOT(ISBLANK(CU$3:CU$3))*(CU$3:CU$3<$FD$3:$FD$3)) -> 0 | CV10: =SUMPRODUCT(NOT(ISBLANK(CV$3:CV$3))*(CV$3:CV$3<$EY$3:$EY$3)) -> 0 | CW10: =SUMPRODUCT(NOT(ISBLANK(CW$3:CW$3))*(CW$3:CW$3<$EZ$3:$EZ$3)) -> 0 | CY10: =SUMPRODUCT(NOT(ISBLANK(CY$3:CY$3))*(CY$3:CY$3<$FA$3:$FA$3)) -> 0 | CZ10: =SUMPRODUCT(NOT(ISBLANK(CZ$3:CZ$3))*(CZ$3:CZ$3<$FB$3:$FB$3)) -> 0 | DA10: =SUMPRODUCT(NOT(ISBLANK(DA$3:DA$3))*(DA$3:DA$3<$FC$3:$FC$3)) -> 0 | DB10: =SUMPRODUCT(NOT(ISBLANK(DB$3:DB$3))*(DB$3:DB$3<$FD$3:$FD$3)) -> 0 | DC10: =SUMPRODUCT(NOT(ISBLANK(DC$3:DC$3))*(DC$3:DC$3<$EY$3:$EY$3)) -> 0 | DD10: =SUMPRODUCT(NOT(ISBLANK(DD$3:DD$3))*(DD$3:DD$3<$EZ$3:$EZ$3)) -> 0 | DF10: =SUMPRODUCT(NOT(ISBLANK(DF$3:DF$3))*(DF$3:DF$3<$FA$3:$FA$3)) -> 0 | DG10: =SUMPRODUCT(NOT(ISBLANK(DG$3:DG$3))*(DG$3:DG$3<$FB$3:$FB$3)) -> 0 | DH10: =SUMPRODUCT(NOT(ISBLANK(DH$3:DH$3))*(DH$3:DH$3<$FC$3:$FC$3)) -> 0 | DI10: =SUMPRODUCT(NOT(ISBLANK(DI$3:DI$3))*(DI$3:DI$3<$FD$3:$FD$3)) -> 0 | DJ10: =SUMPRODUCT(NOT(ISBLANK(DJ$3:DJ$3))*(DJ$3:DJ$3<$EY$3:$EY$3)) -> 0 | DK10: =SUMPRODUCT(NOT(ISBLANK(DK$3:DK$3))*(DK$3:DK$3<$EZ$3:$EZ$3)) -> 0 | DM10: =SUMPRODUCT(NOT(ISBLANK(DM$3:DM$3))*(DM$3:DM$3<$FA$3:$FA$3)) -> 0 | DN10: =SUMPRODUCT(NOT(ISBLANK(DN$3:DN$3))*(DN$3:DN$3<$FB$3:$FB$3)) -> 0 | DO10: =SUMPRODUCT(NOT(ISBLANK(DO$3:DO$3))*(DO$3:DO$3<$FC$3:$FC$3)) -> 0 | DP10: =SUMPRODUCT(NOT(ISBLANK(DP$3:DP$3))*(DP$3:DP$3<$FD$3:$FD$3)) -> 0 | DQ10: =SUMPRODUCT(NOT(ISBLANK(DQ$3:DQ$3))*(DQ$3:DQ$3<$EY$3:$EY$3)) -> 0 | DR10: =SUMPRODUCT(NOT(ISBLANK(DR$3:DR$3))*(DR$3:DR$3<$EZ$3:$EZ$3)) -> 0 | DT10: =SUMPRODUCT(NOT(ISBLANK(DT$3:DT$3))*(DT$3:DT$3<$FA$3:$FA$3)) -> 0 | DU10: =SUMPRODUCT(NOT(ISBLANK(DU$3:DU$3))*(DU$3:DU$3<$FB$3:$FB$3)) -> 0 | DV10: =SUMPRODUCT(NOT(ISBLANK(DV$3:DV$3))*(DV$3:DV$3<$FC$3:$FC$3)) -> 0 | DW10: =SUMPRODUCT(NOT(ISBLANK(DW$3:DW$3))*(DW$3:DW$3<$FD$3:$FD$3)) -> 0 | DX10: =SUMPRODUCT(NOT(ISBLANK(DX$3:DX$3))*(DX$3:DX$3<$EY$3:$EY$3)) -> 0 | DY10: =SUMPRODUCT(NOT(ISBLANK(DY$3:DY$3))*(DY$3:DY$3<$EZ$3:$EZ$3)) -> 0 | EA10: =SUMPRODUCT(NOT(ISBLANK(EA$3:EA$3))*(EA$3:EA$3<$FA$3:$FA$3)) -> 0 | EB10: =SUMPRODUCT(NOT(ISBLANK(EB$3:EB$3))*(EB$3:EB$3<$FB$3:$FB$3)) -> 0 | EC10: =SUMPRODUCT(NOT(ISBLANK(EC$3:EC$3))*(EC$3:EC$3<$FC$3:$FC$3)) -> 0 | ED10: =SUMPRODUCT(NOT(ISBLANK(ED$3:ED$3))*(ED$3:ED$3<$FD$3:$FD$3)) -> 0 | EE10: =SUMPRODUCT(NOT(ISBLANK(EE$3:EE$3))*(EE$3:EE$3<$EY$3:$EY$3)) -> 0 | EF10: =SUMPRODUCT(NOT(ISBLANK(EF$3:EF$3))*(EF$3:EF$3<$EZ$3:$EZ$3)) -> 0 | EH10: =SUMPRODUCT(NOT(ISBLANK(EH$3:EH$3))*(EH$3:EH$3<$FA$3:$FA$3)) -> 0 | EI10: =SUMPRODUCT(NOT(ISBLANK(EI$3:EI$3))*(EI$3:EI$3<$FB$3:$FB$3)) -> 0 | EJ10: =SUMPRODUCT(NOT(ISBLANK(EJ$3:EJ$3))*(EJ$3:EJ$3<$FC$3:$FC$3)) -> 0 | EK10: =SUMPRODUCT(NOT(ISBLANK(EK$3:EK$3))*(EK$3:EK$3<$FD$3:$FD$3)) -> 0 | EL10: =SUMPRODUCT(NOT(ISBLANK(EL$3:EL$3))*(EL$3:EL$3<$EY$3:$EY$3)) -> 0 | EM10: =SUMPRODUCT(NOT(ISBLANK(EM$3:EM$3))*(EM$3:EM$3<$EZ$3:$EZ$3)) -> 0 | EO10: =SUMPRODUCT(NOT(ISBLANK(EO$3:EO$3))*(EO$3:EO$3<$FA$3:$FA$3)) -> 0 | EP10: =SUMPRODUCT(NOT(ISBLANK(EP$3:EP$3))*(EP$3:EP$3<$FB$3:$FB$3)) -> 0 | EQ10: =SUMPRODUCT(NOT(ISBLANK(EQ$3:EQ$3))*(EQ$3:EQ$3<$FC$3:$FC$3)) -> 0 | ER10: =SUMPRODUCT(NOT(ISBLANK(ER$3:ER$3))*(ER$3:ER$3<$FD$3:$FD$3)) -> 0
A11: WORSE | B11: =SUMPRODUCT((NOT(ISBLANK(B$3:B$3))*(B$3:B$3>$EY$3:$EY$3))+ISBLANK(B$3:B$3)) -> 0 | C11: =SUMPRODUCT((NOT(ISBLANK(C$3:C$3))*(C$3:C$3>$EZ$3:$EZ$3))+ISBLANK(C$3:C$3)) -> 0 | E11: =SUMPRODUCT((NOT(ISBLANK(E$3:E$3))*(E$3:E$3>$FA$3:$FA$3))+ISBLANK(E$3:E$3)) -> 0 | F11: =SUMPRODUCT((NOT(ISBLANK(F$3:F$3))*(F$3:F$3>$FB$3:$FB$3))+ISBLANK(F$3:F$3)) -> 0 | G11: =SUMPRODUCT((NOT(ISBLANK(G$3:G$3))*(G$3:G$3>$FC$3:$FC$3))+ISBLANK(G$3:G$3)) -> 0 | H11: =SUMPRODUCT((NOT(ISBLANK(H$3:H$3))*(H$3:H$3>$FD$3:$FD$3))+ISBLANK(H$3:H$3)) -> 0 | I11: =SUMPRODUCT((NOT(ISBLANK(I$3:I$3))*(I$3:I$3>$EY$3:$EY$3))+ISBLANK(I$3:I$3)) -> 0 | J11: =SUMPRODUCT((NOT(ISBLANK(J$3:J$3))*(J$3:J$3>$EZ$3:$EZ$3))+ISBLANK(J$3:J$3)) -> 0 | L11: =SUMPRODUCT((NOT(ISBLANK(L$3:L$3))*(L$3:L$3>$FA$3:$FA$3))+ISBLANK(L$3:L$3)) -> 0 | M11: =SUMPRODUCT((NOT(ISBLANK(M$3:M$3))*(M$3:M$3>$FB$3:$FB$3))+ISBLANK(M$3:M$3)) -> 0 | N11: =SUMPRODUCT((NOT(ISBLANK(N$3:N$3))*(N$3:N$3>$FC$3:$FC$3))+ISBLANK(N$3:N$3)) -> 0 | O11: =SUMPRODUCT((NOT(ISBLANK(O$3:O$3))*(O$3:O$3>$FD$3:$FD$3))+ISBLANK(O$3:O$3)) -> 0 | P11: =SUMPRODUCT((NOT(ISBLANK(P$3:P$3))*(P$3:P$3>$EY$3:$EY$3))+ISBLANK(P$3:P$3)) -> 0 | Q11: =SUMPRODUCT((NOT(ISBLANK(Q$3:Q$3))*(Q$3:Q$3>$EZ$3:$EZ$3))+ISBLANK(Q$3:Q$3)) -> 0 | S11: =SUMPRODUCT((NOT(ISBLANK(S$3:S$3))*(S$3:S$3>$FA$3:$FA$3))+ISBLANK(S$3:S$3)) -> 0 | T11: =SUMPRODUCT((NOT(ISBLANK(T$3:T$3))*(T$3:T$3>$FB$3:$FB$3))+ISBLANK(T$3:T$3)) -> 0 | U11: =SUMPRODUCT((NOT(ISBLANK(U$3:U$3))*(U$3:U$3>$FC$3:$FC$3))+ISBLANK(U$3:U$3)) -> 0 | V11: =SUMPRODUCT((NOT(ISBLANK(V$3:V$3))*(V$3:V$3>$FD$3:$FD$3))+ISBLANK(V$3:V$3)) -> 0 | W11: =SUMPRODUCT((NOT(ISBLANK(W$3:W$3))*(W$3:W$3>$EY$3:$EY$3))+ISBLANK(W$3:W$3)) -> 0 | X11: =SUMPRODUCT((NOT(ISBLANK(X$3:X$3))*(X$3:X$3>$EZ$3:$EZ$3))+ISBLANK(X$3:X$3)) -> 0 | Z11: =SUMPRODUCT((NOT(ISBLANK(Z$3:Z$3))*(Z$3:Z$3>$FA$3:$FA$3))+ISBLANK(Z$3:Z$3)) -> 0 | AA11: =SUMPRODUCT((NOT(ISBLANK(AA$3:AA$3))*(AA$3:AA$3>$FB$3:$FB$3))+ISBLANK(AA$3:AA$3)) -> 0 | AB11: =SUMPRODUCT((NOT(ISBLANK(AB$3:AB$3))*(AB$3:AB$3>$FC$3:$FC$3))+ISBLANK(AB$3:AB$3)) -> 0 | AC11: =SUMPRODUCT((NOT(ISBLANK(AC$3:AC$3))*(AC$3:AC$3>$FD$3:$FD$3))+ISBLANK(AC$3:AC$3)) -> 0 | AD11: =SUMPRODUCT((NOT(ISBLANK(AD$3:AD$3))*(AD$3:AD$3>$EY$3:$EY$3))+ISBLANK(AD$3:AD$3)) -> 0 | AE11: =SUMPRODUCT((NOT(ISBLANK(AE$3:AE$3))*(AE$3:AE$3>$EZ$3:$EZ$3))+ISBLANK(AE$3:AE$3)) -> 0 | AG11: =SUMPRODUCT((NOT(ISBLANK(AG$3:AG$3))*(AG$3:AG$3>$FA$3:$FA$3))+ISBLANK(AG$3:AG$3)) -> 0 | AH11: =SUMPRODUCT((NOT(ISBLANK(AH$3:AH$3))*(AH$3:AH$3>$FB$3:$FB$3))+ISBLANK(AH$3:AH$3)) -> 0 | AI11: =SUMPRODUCT((NOT(ISBLANK(AI$3:AI$3))*(AI$3:AI$3>$FC$3:$FC$3))+ISBLANK(AI$3:AI$3)) -> 0 | AJ11: =SUMPRODUCT((NOT(ISBLANK(AJ$3:AJ$3))*(AJ$3:AJ$3>$FD$3:$FD$3))+ISBLANK(AJ$3:AJ$3)) -> 0 | AK11: =SUMPRODUCT((NOT(ISBLANK(AK$3:AK$3))*(AK$3:AK$3>$EY$3:$EY$3))+ISBLANK(AK$3:AK$3)) -> 0 | AL11: =SUMPRODUCT((NOT(ISBLANK(AL$3:AL$3))*(AL$3:AL$3>$EZ$3:$EZ$3))+ISBLANK(AL$3:AL$3)) -> 0 | AN11: =SUMPRODUCT((NOT(ISBLANK(AN$3:AN$3))*(AN$3:AN$3>$FA$3:$FA$3))+ISBLANK(AN$3:AN$3)) -> 0 | AO11: =SUMPRODUCT((NOT(ISBLANK(AO$3:AO$3))*(AO$3:AO$3>$FB$3:$FB$3))+ISBLANK(AO$3:AO$3)) -> 0 | AP11: =SUMPRODUCT((NOT(ISBLANK(AP$3:AP$3))*(AP$3:AP$3>$FC$3:$FC$3))+ISBLANK(AP$3:AP$3)) -> 0 | AQ11: =SUMPRODUCT((NOT(ISBLANK(AQ$3:AQ$3))*(AQ$3:AQ$3>$FD$3:$FD$3))+ISBLANK(AQ$3:AQ$3)) -> 0 | AR11: =SUMPRODUCT((NOT(ISBLANK(AR$3:AR$3))*(AR$3:AR$3>$EY$3:$EY$3))+ISBLANK(AR$3:AR$3)) -> 0 | AS11: =SUMPRODUCT((NOT(ISBLANK(AS$3:AS$3))*(AS$3:AS$3>$EZ$3:$EZ$3))+ISBLANK(AS$3:AS$3)) -> 0 | AU11: =SUMPRODUCT((NOT(ISBLANK(AU$3:AU$3))*(AU$3:AU$3>$FA$3:$FA$3))+ISBLANK(AU$3:AU$3)) -> 0 | AV11: =SUMPRODUCT((NOT(ISBLANK(AV$3:AV$3))*(AV$3:AV$3>$FB$3:$FB$3))+ISBLANK(AV$3:AV$3)) -> 0 | AW11: =SUMPRODUCT((NOT(ISBLANK(AW$3:AW$3))*(AW$3:AW$3>$FC$3:$FC$3))+ISBLANK(AW$3:AW$3)) -> 0 | AX11: =SUMPRODUCT((NOT(ISBLANK(AX$3:AX$3))*(AX$3:AX$3>$FD$3:$FD$3))+ISBLANK(AX$3:AX$3)) -> 0 | AY11: =SUMPRODUCT((NOT(ISBLANK(AY$3:AY$3))*(AY$3:AY$3>$EY$3:$EY$3))+ISBLANK(AY$3:AY$3)) -> 0 | AZ11: =SUMPRODUCT((NOT(ISBLANK(AZ$3:AZ$3))*(AZ$3:AZ$3>$EZ$3:$EZ$3))+ISBLANK(AZ$3:AZ$3)) -> 0 | BB11: =SUMPRODUCT((NOT(ISBLANK(BB$3:BB$3))*(BB$3:BB$3>$FA$3:$FA$3))+ISBLANK(BB$3:BB$3)) -> 0 | BC11: =SUMPRODUCT((NOT(ISBLANK(BC$3:BC$3))*(BC$3:BC$3>$FB$3:$FB$3))+ISBLANK(BC$3:BC$3)) -> 0 | BD11: =SUMPRODUCT((NOT(ISBLANK(BD$3:BD$3))*(BD$3:BD$3>$FC$3:$FC$3))+ISBLANK(BD$3:BD$3)) -> 0 | BE11: =SUMPRODUCT((NOT(ISBLANK(BE$3:BE$3))*(BE$3:BE$3>$FD$3:$FD$3))+ISBLANK(BE$3:BE$3)) -> 0 | BF11: =SUMPRODUCT((NOT(ISBLANK(BF$3:BF$3))*(BF$3:BF$3>$EY$3:$EY$3))+ISBLANK(BF$3:BF$3)) -> 0 | BG11: =SUMPRODUCT((NOT(ISBLANK(BG$3:BG$3))*(BG$3:BG$3>$EZ$3:$EZ$3))+ISBLANK(BG$3:BG$3)) -> 0 | BI11: =SUMPRODUCT((NOT(ISBLANK(BI$3:BI$3))*(BI$3:BI$3>$FA$3:$FA$3))+ISBLANK(BI$3:BI$3)) -> 0 | BJ11: =SUMPRODUCT((NOT(ISBLANK(BJ$3:BJ$3))*(BJ$3:BJ$3>$FB$3:$FB$3))+ISBLANK(BJ$3:BJ$3)) -> 0 | BK11: =SUMPRODUCT((NOT(ISBLANK(BK$3:BK$3))*(BK$3:BK$3>$FC$3:$FC$3))+ISBLANK(BK$3:BK$3)) -> 0 | BL11: =SUMPRODUCT((NOT(ISBLANK(BL$3:BL$3))*(BL$3:BL$3>$FD$3:$FD$3))+ISBLANK(BL$3:BL$3)) -> 0 | BM11: =SUMPRODUCT((NOT(ISBLANK(BM$3:BM$3))*(BM$3:BM$3>$EY$3:$EY$3))+ISBLANK(BM$3:BM$3)) -> 0 | BN11: =SUMPRODUCT((NOT(ISBLANK(BN$3:BN$3))*(BN$3:BN$3>$EZ$3:$EZ$3))+ISBLANK(BN$3:BN$3)) -> 0 | BP11: =SUMPRODUCT((NOT(ISBLANK(BP$3:BP$3))*(BP$3:BP$3>$FA$3:$FA$3))+ISBLANK(BP$3:BP$3)) -> 0 | BQ11: =SUMPRODUCT((NOT(ISBLANK(BQ$3:BQ$3))*(BQ$3:BQ$3>$FB$3:$FB$3))+ISBLANK(BQ$3:BQ$3)) -> 0 | BR11: =SUMPRODUCT((NOT(ISBLANK(BR$3:BR$3))*(BR$3:BR$3>$FC$3:$FC$3))+ISBLANK(BR$3:BR$3)) -> 0 | BS11: =SUMPRODUCT((NOT(ISBLANK(BS$3:BS$3))*(BS$3:BS$3>$FD$3:$FD$3))+ISBLANK(BS$3:BS$3)) -> 0 | BT11: =SUMPRODUCT((NOT(ISBLANK(BT$3:BT$3))*(BT$3:BT$3>$EY$3:$EY$3))+ISBLANK(BT$3:BT$3)) -> 0 | BU11: =SUMPRODUCT((NOT(ISBLANK(BU$3:BU$3))*(BU$3:BU$3>$EZ$3:$EZ$3))+ISBLANK(BU$3:BU$3)) -> 0 | BW11: =SUMPRODUCT((NOT(ISBLANK(BW$3:BW$3))*(BW$3:BW$3>$FA$3:$FA$3))+ISBLANK(BW$3:BW$3)) -> 0 | BX11: =SUMPRODUCT((NOT(ISBLANK(BX$3:BX$3))*(BX$3:BX$3>$FB$3:$FB$3))+ISBLANK(BX$3:BX$3)) -> 0 | BY11: =SUMPRODUCT((NOT(ISBLANK(BY$3:BY$3))*(BY$3:BY$3>$FC$3:$FC$3))+ISBLANK(BY$3:BY$3)) -> 0 | BZ11: =SUMPRODUCT((NOT(ISBLANK(BZ$3:BZ$3))*(BZ$3:BZ$3>$FD$3:$FD$3))+ISBLANK(BZ$3:BZ$3)) -> 0 | CA11: =SUMPRODUCT((NOT(ISBLANK(CA$3:CA$3))*(CA$3:CA$3>$EY$3:$EY$3))+ISBLANK(CA$3:CA$3)) -> 0 | CB11: =SUMPRODUCT((NOT(ISBLANK(CB$3:CB$3))*(CB$3:CB$3>$EZ$3:$EZ$3))+ISBLANK(CB$3:CB$3)) -> 0 | CD11: =SUMPRODUCT((NOT(ISBLANK(CD$3:CD$3))*(CD$3:CD$3>$FA$3:$FA$3))+ISBLANK(CD$3:CD$3)) -> 0 | CE11: =SUMPRODUCT((NOT(ISBLANK(CE$3:CE$3))*(CE$3:CE$3>$FB$3:$FB$3))+ISBLANK(CE$3:CE$3)) -> 0 | CF11: =SUMPRODUCT((NOT(ISBLANK(CF$3:CF$3))*(CF$3:CF$3>$FC$3:$FC$3))+ISBLANK(CF$3:CF$3)) -> 0 | CG11: =SUMPRODUCT((NOT(ISBLANK(CG$3:CG$3))*(CG$3:CG$3>$FD$3:$FD$3))+ISBLANK(CG$3:CG$3)) -> 0 | CH11: =SUMPRODUCT((NOT(ISBLANK(CH$3:CH$3))*(CH$3:CH$3>$EY$3:$EY$3))+ISBLANK(CH$3:CH$3)) -> 0 | CI11: =SUMPRODUCT((NOT(ISBLANK(CI$3:CI$3))*(CI$3:CI$3>$EZ$3:$EZ$3))+ISBLANK(CI$3:CI$3)) -> 0 | CK11: =SUMPRODUCT((NOT(ISBLANK(CK$3:CK$3))*(CK$3:CK$3>$FA$3:$FA$3))+ISBLANK(CK$3:CK$3)) -> 0 | CL11: =SUMPRODUCT((NOT(ISBLANK(CL$3:CL$3))*(CL$3:CL$3>$FB$3:$FB$3))+ISBLANK(CL$3:CL$3)) -> 0 | CM11: =SUMPRODUCT((NOT(ISBLANK(CM$3:CM$3))*(CM$3:CM$3>$FC$3:$FC$3))+ISBLANK(CM$3:CM$3)) -> 0 | CN11: =SUMPRODUCT((NOT(ISBLANK(CN$3:CN$3))*(CN$3:CN$3>$FD$3:$FD$3))+ISBLANK(CN$3:CN$3)) -> 0 | CO11: =SUMPRODUCT((NOT(ISBLANK(CO$3:CO$3))*(CO$3:CO$3>$EY$3:$EY$3))+ISBLANK(CO$3:CO$3)) -> 0 | CP11: =SUMPRODUCT((NOT(ISBLANK(CP$3:CP$3))*(CP$3:CP$3>$EZ$3:$EZ$3))+ISBLANK(CP$3:CP$3)) -> 0 | CR11: =SUMPRODUCT((NOT(ISBLANK(CR$3:CR$3))*(CR$3:CR$3>$FA$3:$FA$3))+ISBLANK(CR$3:CR$3)) -> 0 | CS11: =SUMPRODUCT((NOT(ISBLANK(CS$3:CS$3))*(CS$3:CS$3>$FB$3:$FB$3))+ISBLANK(CS$3:CS$3)) -> 0 | CT11: =SUMPRODUCT((NOT(ISBLANK(CT$3:CT$3))*(CT$3:CT$3>$FC$3:$FC$3))+ISBLANK(CT$3:CT$3)) -> 0 | CU11: =SUMPRODUCT((NOT(ISBLANK(CU$3:CU$3))*(CU$3:CU$3>$FD$3:$FD$3))+ISBLANK(CU$3:CU$3)) -> 0 | CV11: =SUMPRODUCT((NOT(ISBLANK(CV$3:CV$3))*(CV$3:CV$3>$EY$3:$EY$3))+ISBLANK(CV$3:CV$3)) -> 0 | CW11: =SUMPRODUCT((NOT(ISBLANK(CW$3:CW$3))*(CW$3:CW$3>$EZ$3:$EZ$3))+ISBLANK(CW$3:CW$3)) -> 0 | CY11: =SUMPRODUCT((NOT(ISBLANK(CY$3:CY$3))*(CY$3:CY$3>$FA$3:$FA$3))+ISBLANK(CY$3:CY$3)) -> 0 | CZ11: =SUMPRODUCT((NOT(ISBLANK(CZ$3:CZ$3))*(CZ$3:CZ$3>$FB$3:$FB$3))+ISBLANK(CZ$3:CZ$3)) -> 0 | DA11: =SUMPRODUCT((NOT(ISBLANK(DA$3:DA$3))*(DA$3:DA$3>$FC$3:$FC$3))+ISBLANK(DA$3:DA$3)) -> 0 | DB11: =SUMPRODUCT((NOT(ISBLANK(DB$3:DB$3))*(DB$3:DB$3>$FD$3:$FD$3))+ISBLANK(DB$3:DB$3)) -> 0 | DC11: =SUMPRODUCT((NOT(ISBLANK(DC$3:DC$3))*(DC$3:DC$3>$EY$3:$EY$3))+ISBLANK(DC$3:DC$3)) -> 0 | DD11: =SUMPRODUCT((NOT(ISBLANK(DD$3:DD$3))*(DD$3:DD$3>$EZ$3:$EZ$3))+ISBLANK(DD$3:DD$3)) -> 0 | DF11: =SUMPRODUCT((NOT(ISBLANK(DF$3:DF$3))*(DF$3:DF$3>$FA$3:$FA$3))+ISBLANK(DF$3:DF$3)) -> 0 | DG11: =SUMPRODUCT((NOT(ISBLANK(DG$3:DG$3))*(DG$3:DG$3>$FB$3:$FB$3))+ISBLANK(DG$3:DG$3)) -> 0 | DH11: =SUMPRODUCT((NOT(ISBLANK(DH$3:DH$3))*(DH$3:DH$3>$FC$3:$FC$3))+ISBLANK(DH$3:DH$3)) -> 0 | DI11: =SUMPRODUCT((NOT(ISBLANK(DI$3:DI$3))*(DI$3:DI$3>$FD$3:$FD$3))+ISBLANK(DI$3:DI$3)) -> 0 | DJ11: =SUMPRODUCT((NOT(ISBLANK(DJ$3:DJ$3))*(DJ$3:DJ$3>$EY$3:$EY$3))+ISBLANK(DJ$3:DJ$3)) -> 0 | DK11: =SUMPRODUCT((NOT(ISBLANK(DK$3:DK$3))*(DK$3:DK$3>$EZ$3:$EZ$3))+ISBLANK(DK$3:DK$3)) -> 0 | DM11: =SUMPRODUCT((NOT(ISBLANK(DM$3:DM$3))*(DM$3:DM$3>$FA$3:$FA$3))+ISBLANK(DM$3:DM$3)) -> 0 | DN11: =SUMPRODUCT((NOT(ISBLANK(DN$3:DN$3))*(DN$3:DN$3>$FB$3:$FB$3))+ISBLANK(DN$3:DN$3)) -> 0 | DO11: =SUMPRODUCT((NOT(ISBLANK(DO$3:DO$3))*(DO$3:DO$3>$FC$3:$FC$3))+ISBLANK(DO$3:DO$3)) -> 0 | DP11: =SUMPRODUCT((NOT(ISBLANK(DP$3:DP$3))*(DP$3:DP$3>$FD$3:$FD$3))+ISBLANK(DP$3:DP$3)) -> 0 | DQ11: =SUMPRODUCT((NOT(ISBLANK(DQ$3:DQ$3))*(DQ$3:DQ$3>$EY$3:$EY$3))+ISBLANK(DQ$3:DQ$3)) -> 0 | DR11: =SUMPRODUCT((NOT(ISBLANK(DR$3:DR$3))*(DR$3:DR$3>$EZ$3:$EZ$3))+ISBLANK(DR$3:DR$3)) -> 0 | DT11: =SUMPRODUCT((NOT(ISBLANK(DT$3:DT$3))*(DT$3:DT$3>$FA$3:$FA$3))+ISBLANK(DT$3:DT$3)) -> 0 | DU11: =SUMPRODUCT((NOT(ISBLANK(DU$3:DU$3))*(DU$3:DU$3>$FB$3:$FB$3))+ISBLANK(DU$3:DU$3)) -> 0 | DV11: =SUMPRODUCT((NOT(ISBLANK(DV$3:DV$3))*(DV$3:DV$3>$FC$3:$FC$3))+ISBLANK(DV$3:DV$3)) -> 0 | DW11: =SUMPRODUCT((NOT(ISBLANK(DW$3:DW$3))*(DW$3:DW$3>$FD$3:$FD$3))+ISBLANK(DW$3:DW$3)) -> 0 | DX11: =SUMPRODUCT((NOT(ISBLANK(DX$3:DX$3))*(DX$3:DX$3>$EY$3:$EY$3))+ISBLANK(DX$3:DX$3)) -> 0 | DY11: =SUMPRODUCT((NOT(ISBLANK(DY$3:DY$3))*(DY$3:DY$3>$EZ$3:$EZ$3))+ISBLANK(DY$3:DY$3)) -> 0 | EA11: =SUMPRODUCT((NOT(ISBLANK(EA$3:EA$3))*(EA$3:EA$3>$FA$3:$FA$3))+ISBLANK(EA$3:EA$3)) -> 0 | EB11: =SUMPRODUCT((NOT(ISBLANK(EB$3:EB$3))*(EB$3:EB$3>$FB$3:$FB$3))+ISBLANK(EB$3:EB$3)) -> 0 | EC11: =SUMPRODUCT((NOT(ISBLANK(EC$3:EC$3))*(EC$3:EC$3>$FC$3:$FC$3))+ISBLANK(EC$3:EC$3)) -> 0 | ED11: =SUMPRODUCT((NOT(ISBLANK(ED$3:ED$3))*(ED$3:ED$3>$FD$3:$FD$3))+ISBLANK(ED$3:ED$3)) -> 0 | EE11: =SUMPRODUCT((NOT(ISBLANK(EE$3:EE$3))*(EE$3:EE$3>$EY$3:$EY$3))+ISBLANK(EE$3:EE$3)) -> 0 | EF11: =SUMPRODUCT((NOT(ISBLANK(EF$3:EF$3))*(EF$3:EF$3>$EZ$3:$EZ$3))+ISBLANK(EF$3:EF$3)) -> 0 | EH11: =SUMPRODUCT((NOT(ISBLANK(EH$3:EH$3))*(EH$3:EH$3>$FA$3:$FA$3))+ISBLANK(EH$3:EH$3)) -> 0 | EI11: =SUMPRODUCT((NOT(ISBLANK(EI$3:EI$3))*(EI$3:EI$3>$FB$3:$FB$3))+ISBLANK(EI$3:EI$3)) -> 0 | EJ11: =SUMPRODUCT((NOT(ISBLANK(EJ$3:EJ$3))*(EJ$3:EJ$3>$FC$3:$FC$3))+ISBLANK(EJ$3:EJ$3)) -> 0 | EK11: =SUMPRODUCT((NOT(ISBLANK(EK$3:EK$3))*(EK$3:EK$3>$FD$3:$FD$3))+ISBLANK(EK$3:EK$3)) -> 0 | EL11: =SUMPRODUCT((NOT(ISBLANK(EL$3:EL$3))*(EL$3:EL$3>$EY$3:$EY$3))+ISBLANK(EL$3:EL$3)) -> 0 | EM11: =SUMPRODUCT((NOT(ISBLANK(EM$3:EM$3))*(EM$3:EM$3>$EZ$3:$EZ$3))+ISBLANK(EM$3:EM$3)) -> 0 | EO11: =SUMPRODUCT((NOT(ISBLANK(EO$3:EO$3))*(EO$3:EO$3>$FA$3:$FA$3))+ISBLANK(EO$3:EO$3)) -> 0 | EP11: =SUMPRODUCT((NOT(ISBLANK(EP$3:EP$3))*(EP$3:EP$3>$FB$3:$FB$3))+ISBLANK(EP$3:EP$3)) -> 0 | EQ11: =SUMPRODUCT((NOT(ISBLANK(EQ$3:EQ$3))*(EQ$3:EQ$3>$FC$3:$FC$3))+ISBLANK(EQ$3:EQ$3)) -> 0 | ER11: =SUMPRODUCT((NOT(ISBLANK(ER$3:ER$3))*(ER$3:ER$3>$FD$3:$FD$3))+ISBLANK(ER$3:ER$3)) -> 0
