Workbook

Sheet Instances
B1: memelingo-1/simple_mlp-lpnmr-ht | H1: memelingo-1/simple_mlp-lpnmr-htc | N1: memelingo-1/simple_mlp-lpnmr-htcdl | T1: memelingo-1/simple_mlp-tplp-ht | Z1: memelingo-1/simple_mlp-tplp-htc | AF1: memelingo-1/simple_mlp-tplp-htcdl | AL1: min | AQ1: median | AV1: max
B2: time | C2: stime | D2: status | E2: rules | F2: gtime | G2: ctime | H2: time | I2: stime | J2: status | K2: rules | L2: gtime | M2: ctime | N2: time | O2: stime | P2: status | Q2: rules | R2: gtime | S2: ctime | T2: time | U2: stime | V2: status | W2: rules | X2: gtime | Y2: ctime | Z2: time | AA2: stime | AB2: status | AC2: rules | AD2: gtime | AE2: ctime | AF2: time | AG2: stime | AH2: status | AI2: rules | AJ2: gtime | AK2: ctime | AL2: time | AM2: stime | AN2: rules | AO2: gtime | AP2: ctime | AQ2: time | AR2: stime | AS2: rules | AT2: gtime | AU2: ctime | AV2: time | AW2: stime | AX2: rules | AY2: gtime | AZ2: ctime
A3: instances/size-1 | B3: 8.78 | C3: 0.01 | D3: SATISFIABLE | E3: 297060 | F3: 2.34 | G3: 2.348 | H3: 6.8 | I3: 0 | J3: SATISFIABLE | K3: 2014 | L3: 0.22 | M3: 0.221 | N3: 6.42 | O3: 0 | P3: SATISFIABLE | Q3: 2014 | R3: 0.15 | S3: 0.152 | T3: 8.36 | U3: 0.02 | V3: SATISFIABLE | W3: 334135 | X3: 2.06 | Y3: 2.081 | Z3: 6.42 | AA3: 0 | AB3: SATISFIABLE | AC3: 2249 | AD3: 0.21 | AE3: 0.209 | AF3: 6.54 | AG3: 0 | AH3: SATISFIABLE | AI3: 2249 | AJ3: 0.2 | AK3: 0.199 | AL3: =MIN($B3,$H3,$N3,$T3,$Z3,$AF3) -> 0 | AM3: =MIN($C3,$I3,$O3,$U3,$AA3,$AG3) -> 0 | AN3: =MIN($E3,$K3,$Q3,$W3,$AC3,$AI3) -> 0 | AO3: =MIN($F3,$L3,$R3,$X3,$AD3,$AJ3) -> 0 | AP3: =MIN($G3,$M3,$S3,$Y3,$AE3,$AK3) -> 0 | AQ3: =MEDIAN($B3,$H3,$N3,$T3,$Z3,$AF3) -> 0 | AR3: =MEDIAN($C3,$I3,$O3,$U3,$AA3,$AG3) -> 0 | AS3: =MEDIAN($E3,$K3,$Q3,$W3,$AC3,$AI3) -> 0 | AT3: =MEDIAN($F3,$L3,$R3,$X3,$AD3,$AJ3) -> 0 | AU3: =MEDIAN($G3,$M3,$S3,$Y3,$AE3,$AK3) -> 0 | AV3: =MAX($B3,$H3,$N3,$T3,$Z3,$AF3) -> 0 | AW3: =MAX($C3,$I3,$O3,$U3,$AA3,$AG3) -> 0 | AX3: =MAX($E3,$K3,$Q3,$W3,$AC3,$AI3) -> 0 | AY3: =MAX($F3,$L3,$R3,$X3,$AD3,$AJ3) -> 0 | AZ3: =MAX($G3,$M3,$S3,$Y3,$AE3,$AK3) -> 0
A4: instances/size-10 | B4: 1200 | H4: 6.15 | I4: 0 | J4: SATISFIABLE | K4: 2014 | L4: 0.15 | M4: 0.15 | N4: 6.34 | O4: 0 | P4: SATISFIABLE | Q4: 2014 | R4: 0.16 | S4: 0.158 | T4: 1200 | Z4: 6.74 | AA4: 0 | AB4: SATISFIABLE | AC4: 2249 | AD4: 0.22 | AE4: 0.221 | AF4: 6.67 | AG4: 0 | AH4: SATISFIABLE | AI4: 2249 | AJ4: 0.2 | AK4: 0.203 | AL4: =MIN($B4,$H4,$N4,$T4,$Z4,$AF4) -> 0 | AM4: =MIN($C4,$I4,$O4,$U4,$AA4,$AG4) -> 0 | AN4: =MIN($E4,$K4,$Q4,$W4,$AC4,$AI4) -> 0 | AO4: =MIN($F4,$L4,$R4,$X4,$AD4,$AJ4) -> 0 | AP4: =MIN($G4,$M4,$S4,$Y4,$AE4,$AK4) -> 0 | AQ4: =MEDIAN($B4,$H4,$N4,$T4,$Z4,$AF4) -> 0 | AR4: =MEDIAN($C4,$I4,$O4,$U4,$AA4,$AG4) -> 0 | AS4: =MEDIAN($E4,$K4,$Q4,$W4,$AC4,$AI4) -> 0 | AT4: =MEDIAN($F4,$L4,$R4,$X4,$AD4,$AJ4) -> 0 | AU4: =MEDIAN($G4,$M4,$S4,$Y4,$AE4,$AK4) -> 0 | AV4: =MAX($B4,$H4,$N4,$T4,$Z4,$AF4) -> 0 | AW4: =MAX($C4,$I4,$O4,$U4,$AA4,$AG4) -> 0 | AX4: =MAX($E4,$K4,$Q4,$W4,$AC4,$AI4) -> 0 | AY4: =MAX($F4,$L4,$R4,$X4,$AD4,$AJ4) -> 0 | AZ4: =MAX($G4,$M4,$S4,$Y4,$AE4,$AK4) -> 0
A5: instances/size-5 | B5: 76.77 | C5: 2.62 | D5: SATISFIABLE | E5: 7527300 | F5: 66.56 | G5: 69.181 | H5: 6.72 | I5: 0 | J5: SATISFIABLE | K5: 2014 | L5: 0.15 | M5: 0.147 | N5: 6.43 | O5: 0 | P5: SATISFIABLE | Q5: 2014 | R5: 0.16 | S5: 0.16 | T5: 77.9 | U5: 3.18 | V5: SATISFIABLE | W5: 8437935 | X5: 67.06 | Y5: 70.241 | Z5: 6.43 | AA5: 0 | AB5: SATISFIABLE | AC5: 2249 | AD5: 0.21 | AE5: 0.215 | AF5: 6.16 | AG5: 0 | AH5: SATISFIABLE | AI5: 2249 | AJ5: 0.2 | AK5: 0.195 | AL5: =MIN($B5,$H5,$N5,$T5,$Z5,$AF5) -> 0 | AM5: =MIN($C5,$I5,$O5,$U5,$AA5,$AG5) -> 0 | AN5: =MIN($E5,$K5,$Q5,$W5,$AC5,$AI5) -> 0 | AO5: =MIN($F5,$L5,$R5,$X5,$AD5,$AJ5) -> 0 | AP5: =MIN($G5,$M5,$S5,$Y5,$AE5,$AK5) -> 0 | AQ5: =MEDIAN($B5,$H5,$N5,$T5,$Z5,$AF5) -> 0 | AR5: =MEDIAN($C5,$I5,$O5,$U5,$AA5,$AG5) -> 0 | AS5: =MEDIAN($E5,$K5,$Q5,$W5,$AC5,$AI5) -> 0 | AT5: =MEDIAN($F5,$L5,$R5,$X5,$AD5,$AJ5) -> 0 | AU5: =MEDIAN($G5,$M5,$S5,$Y5,$AE5,$AK5) -> 0 | AV5: =MAX($B5,$H5,$N5,$T5,$Z5,$AF5) -> 0 | AW5: =MAX($C5,$I5,$O5,$U5,$AA5,$AG5) -> 0 | AX5: =MAX($E5,$K5,$Q5,$W5,$AC5,$AI5) -> 0 | AY5: =MAX($F5,$L5,$R5,$X5,$AD5,$AJ5) -> 0 | AZ5: =MAX($G5,$M5,$S5,$Y5,$AE5,$AK5) -> 0
A6: instances/size-7 | B6: 168.67 | C6: 5.85 | D6: SATISFIABLE | E6: 14772420 | F6: 154.3 | G6: 160.147 | H6: 6.5 | I6: 0 | J6: SATISFIABLE | K6: 2014 | L6: 0.17 | M6: 0.175 | N6: 6.67 | O6: 0 | P6: SATISFIABLE | Q6: 2014 | R6: 0.16 | S6: 0.157 | T6: 142.68 | U6: 8.15 | V6: SATISFIABLE | W6: 16555435 | X6: 126.05 | Y6: 134.198 | Z6: 6.48 | AA6: 0 | AB6: SATISFIABLE | AC6: 2249 | AD6: 0.22 | AE6: 0.224 | AF6: 6.41 | AG6: 0 | AH6: SATISFIABLE | AI6: 2249 | AJ6: 0.21 | AK6: 0.209 | AL6: =MIN($B6,$H6,$N6,$T6,$Z6,$AF6) -> 0 | AM6: =MIN($C6,$I6,$O6,$U6,$AA6,$AG6) -> 0 | AN6: =MIN($E6,$K6,$Q6,$W6,$AC6,$AI6) -> 0 | AO6: =MIN($F6,$L6,$R6,$X6,$AD6,$AJ6) -> 0 | AP6: =MIN($G6,$M6,$S6,$Y6,$AE6,$AK6) -> 0 | AQ6: =MEDIAN($B6,$H6,$N6,$T6,$Z6,$AF6) -> 0 | AR6: =MEDIAN($C6,$I6,$O6,$U6,$AA6,$AG6) -> 0 | AS6: =MEDIAN($E6,$K6,$Q6,$W6,$AC6,$AI6) -> 0 | AT6: =MEDIAN($F6,$L6,$R6,$X6,$AD6,$AJ6) -> 0 | AU6: =MEDIAN($G6,$M6,$S6,$Y6,$AE6,$AK6) -> 0 | AV6: =MAX($B6,$H6,$N6,$T6,$Z6,$AF6) -> 0 | AW6: =MAX($C6,$I6,$O6,$U6,$AA6,$AG6) -> 0 | AX6: =MAX($E6,$K6,$Q6,$W6,$AC6,$AI6) -> 0 | AY6: =MAX($F6,$L6,$R6,$X6,$AD6,$AJ6) -> 0 | AZ6: =MAX($G6,$M6,$S6,$Y6,$AE6,$AK6) -> 0
A8: SUM | B8: =SUM(B$3:B$6) -> 0 | C8: =SUM(C$3:C$6) -> 0 | E8: =SUM(E$3:E$6) -> 0 | F8: =SUM(F$3:F$6) -> 0 | G8: =SUM(G$3:G$6) -> 0 | H8: =SUM(H$3:H$6) -> 0 | I8: =SUM(I$3:I$6) -> 0 | K8: =SUM(K$3:K$6) -> 0 | L8: =SUM(L$3:L$6) -> 0 | M8: =SUM(M$3:M$6) -> 0 | N8: =SUM(N$3:N$6) -> 0 | O8: =SUM(O$3:O$6) -> 0 | Q8: =SUM(Q$3:Q$6) -> 0 | R8: =SUM(R$3:R$6) -> 0 | S8: =SUM(S$3:S$6) -> 0 | T8: =SUM(T$3:T$6) -> 0 | U8: =SUM(U$3:U$6) -> 0 | W8: =SUM(W$3:W$6) -> 0 | X8: =SUM(X$3:X$6) -> 0 | Y8: =SUM(Y$3:Y$6) -> 0 | Z8: =SUM(Z$3:Z$6) -> 0 | AA8: =SUM(AA$3:AA$6) -> 0 | AC8: =SUM(AC$3:AC$6) -> 0 | AD8: =SUM(AD$3:AD$6) -> 0 | AE8: =SUM(AE$3:AE$6) -> 0 | AF8: =SUM(AF$3:AF$6) -> 0 | AG8: =SUM(AG$3:AG$6) -> 0 | AI8: =SUM(AI$3:AI$6) -> 0 | AJ8: =SUM(AJ$3:AJ$6) -> 0 | AK8: =SUM(AK$3:AK$6) -> 0 | AL8: =SUM(AL$3:AL$6) -> 0 | AM8: =SUM(AM$3:AM$6) -> 0 | AN8: =SUM(AN$3:AN$6) -> 0 | AO8: =SUM(AO$3:AO$6) -> 0 | AP8: =SUM(AP$3:AP$6) -> 0 | ... AZ8: =SUM(AZ$3:AZ$6) -> 0
A9: AVG | B9: =AVERAGE(B$3:B$6) -> 0 | C9: =AVERAGE(C$3:C$6) -> 0 | E9: =AVERAGE(E$3:E$6) -> 0 | F9: =AVERAGE(F$3:F$6) -> 0 | G9: =AVERAGE(G$3:G$6) -> 0 | H9: =AVERAGE(H$3:H$6) -> 0 | I9: =AVERAGE(I$3:I$6) -> 0 | K9: =AVERAGE(K$3:K$6) -> 0 | L9: =AVERAGE(L$3:L$6) -> 0 | M9: =AVERAGE(M$3:M$6) -> 0 | N9: =AVERAGE(N$3:N$6) -> 0 | O9: =AVERAGE(O$3:O$6) -> 0 | Q9: =AVERAGE(Q$3:Q$6) -> 0 | R9: =AVERAGE(R$3:R$6) -> 0 | S9: =AVERAGE(S$3:S$6) -> 0 | T9: =AVERAGE(T$3:T$6) -> 0 | U9: =AVERAGE(U$3:U$6) -> 0 | W9: =AVERAGE(W$3:W$6) -> 0 | X9: =AVERAGE(X$3:X$6) -> 0 | Y9: =AVERAGE(Y$3:Y$6) -> 0 | Z9: =AVERAGE(Z$3:Z$6) -> 0 | AA9: =AVERAGE(AA$3:AA$6) -> 0 | AC9: =AVERAGE(AC$3:AC$6) -> 0 | AD9: =AVERAGE(AD$3:AD$6) -> 0 | AE9: =AVERAGE(AE$3:AE$6) -> 0 | AF9: =AVERAGE(AF$3:AF$6) -> 0 | AG9: =AVERAGE(AG$3:AG$6) -> 0 | AI9: =AVERAGE(AI$3:AI$6) -> 0 | AJ9: =AVERAGE(AJ$3:AJ$6) -> 0 | AK9: =AVERAGE(AK$3:AK$6) -> 0 | AL9: =AVERAGE(AL$3:AL$6) -> 0 | AM9: =AVERAGE(AM$3:AM$6) -> 0 | AN9: =AVERAGE(AN$3:AN$6) -> 0 | AO9: =AVERAGE(AO$3:AO$6) -> 0 | AP9: =AVERAGE(AP$3:AP$6) -> 0 | ... AZ9: =AVERAGE(AZ$3:AZ$6) -> 0
A10: DEV | B10: =STDEV(B$3:B$6) -> 0 | C10: =STDEV(C$3:C$6) -> 0 | E10: =STDEV(E$3:E$6) -> 0 | F10: =STDEV(F$3:F$6) -> 0 | G10: =STDEV(G$3:G$6) -> 0 | H10: =STDEV(H$3:H$6) -> 0 | I10: =STDEV(I$3:I$6) -> 0 | K10: =STDEV(K$3:K$6) -> 0 | L10: =STDEV(L$3:L$6) -> 0 | M10: =STDEV(M$3:M$6) -> 0 | N10: =STDEV(N$3:N$6) -> 0 | O10: =STDEV(O$3:O$6) -> 0 | Q10: =STDEV(Q$3:Q$6) -> 0 | R10: =STDEV(R$3:R$6) -> 0 | S10: =STDEV(S$3:S$6) -> 0 | T10: =STDEV(T$3:T$6) -> 0 | U10: =STDEV(U$3:U$6) -> 0 | W10: =STDEV(W$3:W$6) -> 0 | X10: =STDEV(X$3:X$6) -> 0 | Y10: =STDEV(Y$3:Y$6) -> 0 | Z10: =STDEV(Z$3:Z$6) -> 0 | AA10: =STDEV(AA$3:AA$6) -> 0 | AC10: =STDEV(AC$3:AC$6) -> 0 | AD10: =STDEV(AD$3:AD$6) -> 0 | AE10: =STDEV(AE$3:AE$6) -> 0 | AF10: =STDEV(AF$3:AF$6) -> 0 | AG10: =STDEV(AG$3:AG$6) -> 0 | AI10: =STDEV(AI$3:AI$6) -> 0 | AJ10: =STDEV(AJ$3:AJ$6) -> 0 | AK10: =STDEV(AK$3:AK$6) -> 0 | AL10: =STDEV(AL$3:AL$6) -> 0 | AM10: =STDEV(AM$3:AM$6) -> 0 | AN10: =STDEV(AN$3:AN$6) -> 0 | AO10: =STDEV(AO$3:AO$6) -> 0 | AP10: =STDEV(AP$3:AP$6) -> 0 | ... AZ10: =STDEV(AZ$3:AZ$6) -> 0
A11: DST | B11: =SUMPRODUCT(--(B$3:B$6-$AL$3:$AL$6)^2)^0.5 -> 0 | C11: =SUMPRODUCT(--(C$3:C$6-$AM$3:$AM$6)^2)^0.5 -> 0 | E11: =SUMPRODUCT(--(E$3:E$6-$AN$3:$AN$6)^2)^0.5 -> 0 | F11: =SUMPRODUCT(--(F$3:F$6-$AO$3:$AO$6)^2)^0.5 -> 0 | G11: =SUMPRODUCT(--(G$3:G$6-$AP$3:$AP$6)^2)^0.5 -> 0 | H11: =SUMPRODUCT(--(H$3:H$6-$AL$3:$AL$6)^2)^0.5 -> 0 | I11: =SUMPRODUCT(--(I$3:I$6-$AM$3:$AM$6)^2)^0.5 -> 0 | K11: =SUMPRODUCT(--(K$3:K$6-$AN$3:$AN$6)^2)^0.5 -> 0 | L11: =SUMPRODUCT(--(L$3:L$6-$AO$3:$AO$6)^2)^0.5 -> 0 | M11: =SUMPRODUCT(--(M$3:M$6-$AP$3:$AP$6)^2)^0.5 -> 0 | N11: =SUMPRODUCT(--(N$3:N$6-$AL$3:$AL$6)^2)^0.5 -> 0 | O11: =SUMPRODUCT(--(O$3:O$6-$AM$3:$AM$6)^2)^0.5 -> 0 | Q11: =SUMPRODUCT(--(Q$3:Q$6-$AN$3:$AN$6)^2)^0.5 -> 0 | R11: =SUMPRODUCT(--(R$3:R$6-$AO$3:$AO$6)^2)^0.5 -> 0 | S11: =SUMPRODUCT(--(S$3:S$6-$AP$3:$AP$6)^2)^0.5 -> 0 | T11: =SUMPRODUCT(--(T$3:T$6-$AL$3:$AL$6)^2)^0.5 -> 0 | U11: =SUMPRODUCT(--(U$3:U$6-$AM$3:$AM$6)^2)^0.5 -> 0 | W11: =SUMPRODUCT(--(W$3:W$6-$AN$3:$AN$6)^2)^0.5 -> 0 | X11: =SUMPRODUCT(--(X$3:X$6-$AO$3:$AO$6)^2)^0.5 -> 0 | Y11: =SUMPRODUCT(--(Y$3:Y$6-$AP$3:$AP$6)^2)^0.5 -> 0 | Z11: =SUMPRODUCT(--(Z$3:Z$6-$AL$3:$AL$6)^2)^0.5 -> 0 | AA11: =SUMPRODUCT(--(AA$3:AA$6-$AM$3:$AM$6)^2)^0.5 -> 0 | AC11: =SUMPRODUCT(--(AC$3:AC$6-$AN$3:$AN$6)^2)^0.5 -> 0 | AD11: =SUMPRODUCT(--(AD$3:AD$6-$AO$3:$AO$6)^2)^0.5 -> 0 | AE11: =SUMPRODUCT(--(AE$3:AE$6-$AP$3:$AP$6)^2)^0.5 -> 0 | AF11: =SUMPRODUCT(--(AF$3:AF$6-$AL$3:$AL$6)^2)^0.5 -> 0 | AG11: =SUMPRODUCT(--(AG$3:AG$6-$AM$3:$AM$6)^2)^0.5 -> 0 | AI11: =SUMPRODUCT(--(AI$3:AI$6-$AN$3:$AN$6)^2)^0.5 -> 0 | AJ11: =SUMPRODUCT(--(AJ$3:AJ$6-$AO$3:$AO$6)^2)^0.5 -> 0 | AK11: =SUMPRODUCT(--(AK$3:AK$6-$AP$3:$AP$6)^2)^0.5 -> 0
A12: BEST | B12: =SUMPRODUCT(NOT(ISBLANK(B$3:B$6))*(B$3:B$6=$AL$3:$AL$6)) -> 0 | C12: =SUMPRODUCT(NOT(ISBLANK(C$3:C$6))*(C$3:C$6=$AM$3:$AM$6)) -> 0 | E12: =SUMPRODUCT(NOT(ISBLANK(E$3:E$6))*(E$3:E$6=$AN$3:$AN$6)) -> 0 | F12: =SUMPRODUCT(NOT(ISBLANK(F$3:F$6))*(F$3:F$6=$AO$3:$AO$6)) -> 0 | G12: =SUMPRODUCT(NOT(ISBLANK(G$3:G$6))*(G$3:G$6=$AP$3:$AP$6)) -> 0 | H12: =SUMPRODUCT(NOT(ISBLANK(H$3:H$6))*(H$3:H$6=$AL$3:$AL$6)) -> 0 | I12: =SUMPRODUCT(NOT(ISBLANK(I$3:I$6))*(I$3:I$6=$AM$3:$AM$6)) -> 0 | K12: =SUMPRODUCT(NOT(ISBLANK(K$3:K$6))*(K$3:K$6=$AN$3:$AN$6)) -> 0 | L12: =SUMPRODUCT(NOT(ISBLANK(L$3:L$6))*(L$3:L$6=$AO$3:$AO$6)) -> 0 | M12: =SUMPRODUCT(NOT(ISBLANK(M$3:M$6))*(M$3:M$6=$AP$3:$AP$6)) -> 0 | N12: =SUMPRODUCT(NOT(ISBLANK(N$3:N$6))*(N$3:N$6=$AL$3:$AL$6)) -> 0 | O12: =SUMPRODUCT(NOT(ISBLANK(O$3:O$6))*(O$3:O$6=$AM$3:$AM$6)) -> 0 | Q12: =SUMPRODUCT(NOT(ISBLANK(Q$3:Q$6))*(Q$3:Q$6=$AN$3:$AN$6)) -> 0 | R12: =SUMPRODUCT(NOT(ISBLANK(R$3:R$6))*(R$3:R$6=$AO$3:$AO$6)) -> 0 | S12: =SUMPRODUCT(NOT(ISBLANK(S$3:S$6))*(S$3:S$6=$AP$3:$AP$6)) -> 0 | T12: =SUMPRODUCT(NOT(ISBLANK(T$3:T$6))*(T$3:T$6=$AL$3:$AL$6)) -> 0 | U12: =SUMPRODUCT(NOT(ISBLANK(U$3:U$6))*(U$3:U$6=$AM$3:$AM$6)) -> 0 | W12: =SUMPRODUCT(NOT(ISBLANK(W$3:W$6))*(W$3:W$6=$AN$3:$AN$6)) -> 0 | X12: =SUMPRODUCT(NOT(ISBLANK(X$3:X$6))*(X$3:X$6=$AO$3:$AO$6)) -> 0 | Y12: =SUMPRODUCT(NOT(ISBLANK(Y$3:Y$6))*(Y$3:Y$6=$AP$3:$AP$6)) -> 0 | Z12: =SUMPRODUCT(NOT(ISBLANK(Z$3:Z$6))*(Z$3:Z$6=$AL$3:$AL$6)) -> 0 | AA12: =SUMPRODUCT(NOT(ISBLANK(AA$3:AA$6))*(AA$3:AA$6=$AM$3:$AM$6)) -> 0 | AC12: =SUMPRODUCT(NOT(ISBLANK(AC$3:AC$6))*(AC$3:AC$6=$AN$3:$AN$6)) -> 0 | AD12: =SUMPRODUCT(NOT(ISBLANK(AD$3:AD$6))*(AD$3:AD$6=$AO$3:$AO$6)) -> 0 | AE12: =SUMPRODUCT(NOT(ISBLANK(AE$3:AE$6))*(AE$3:AE$6=$AP$3:$AP$6)) -> 0 | AF12: =SUMPRODUCT(NOT(ISBLANK(AF$3:AF$6))*(AF$3:AF$6=$AL$3:$AL$6)) -> 0 | AG12: =SUMPRODUCT(NOT(ISBLANK(AG$3:AG$6))*(AG$3:AG$6=$AM$3:$AM$6)) -> 0 | AI12: =SUMPRODUCT(NOT(ISBLANK(AI$3:AI$6))*(AI$3:AI$6=$AN$3:$AN$6)) -> 0 | AJ12: =SUMPRODUCT(NOT(ISBLANK(AJ$3:AJ$6))*(AJ$3:AJ$6=$AO$3:$AO$6)) -> 0 | AK12: =SUMPRODUCT(NOT(ISBLANK(AK$3:AK$6))*(AK$3:AK$6=$AP$3:$AP$6)) -> 0
A13: BETTER | B13: =SUMPRODUCT(NOT(ISBLANK(B$3:B$6))*(B$3:B$6<$AQ$3:$AQ$6)) -> 0 | C13: =SUMPRODUCT(NOT(ISBLANK(C$3:C$6))*(C$3:C$6<$AR$3:$AR$6)) -> 0 | E13: =SUMPRODUCT(NOT(ISBLANK(E$3:E$6))*(E$3:E$6<$AS$3:$AS$6)) -> 0 | F13: =SUMPRODUCT(NOT(ISBLANK(F$3:F$6))*(F$3:F$6<$AT$3:$AT$6)) -> 0 | G13: =SUMPRODUCT(NOT(ISBLANK(G$3:G$6))*(G$3:G$6<$AU$3:$AU$6)) -> 0 | H13: =SUMPRODUCT(NOT(ISBLANK(H$3:H$6))*(H$3:H$6<$AQ$3:$AQ$6)) -> 0 | I13: =SUMPRODUCT(NOT(ISBLANK(I$3:I$6))*(I$3:I$6<$AR$3:$AR$6)) -> 0 | K13: =SUMPRODUCT(NOT(ISBLANK(K$3:K$6))*(K$3:K$6<$AS$3:$AS$6)) -> 0 | L13: =SUMPRODUCT(NOT(ISBLANK(L$3:L$6))*(L$3:L$6<$AT$3:$AT$6)) -> 0 | M13: =SUMPRODUCT(NOT(ISBLANK(M$3:M$6))*(M$3:M$6<$AU$3:$AU$6)) -> 0 | N13: =SUMPRODUCT(NOT(ISBLANK(N$3:N$6))*(N$3:N$6<$AQ$3:$AQ$6)) -> 0 | O13: =SUMPRODUCT(NOT(ISBLANK(O$3:O$6))*(O$3:O$6<$AR$3:$AR$6)) -> 0 | Q13: =SUMPRODUCT(NOT(ISBLANK(Q$3:Q$6))*(Q$3:Q$6<$AS$3:$AS$6)) -> 0 | R13: =SUMPRODUCT(NOT(ISBLANK(R$3:R$6))*(R$3:R$6<$AT$3:$AT$6)) -> 0 | S13: =SUMPRODUCT(NOT(ISBLANK(S$3:S$6))*(S$3:S$6<$AU$3:$AU$6)) -> 0 | T13: =SUMPRODUCT(NOT(ISBLANK(T$3:T$6))*(T$3:T$6<$AQ$3:$AQ$6)) -> 0 | U13: =SUMPRODUCT(NOT(ISBLANK(U$3:U$6))*(U$3:U$6<$AR$3:$AR$6)) -> 0 | W13: =SUMPRODUCT(NOT(ISBLANK(W$3:W$6))*(W$3:W$6<$AS$3:$AS$6)) -> 0 | X13: =SUMPRODUCT(NOT(ISBLANK(X$3:X$6))*(X$3:X$6<$AT$3:$AT$6)) -> 0 | Y13: =SUMPRODUCT(NOT(ISBLANK(Y$3:Y$6))*(Y$3:Y$6<$AU$3:$AU$6)) -> 0 | Z13: =SUMPRODUCT(NOT(ISBLANK(Z$3:Z$6))*(Z$3:Z$6<$AQ$3:$AQ$6)) -> 0 | AA13: =SUMPRODUCT(NOT(ISBLANK(AA$3:AA$6))*(AA$3:AA$6<$AR$3:$AR$6)) -> 0 | AC13: =SUMPRODUCT(NOT(ISBLANK(AC$3:AC$6))*(AC$3:AC$6<$AS$3:$AS$6)) -> 0 | AD13: =SUMPRODUCT(NOT(ISBLANK(AD$3:AD$6))*(AD$3:AD$6<$AT$3:$AT$6)) -> 0 | AE13: =SUMPRODUCT(NOT(ISBLANK(AE$3:AE$6))*(AE$3:AE$6<$AU$3:$AU$6)) -> 0 | AF13: =SUMPRODUCT(NOT(ISBLANK(AF$3:AF$6))*(AF$3:AF$6<$AQ$3:$AQ$6)) -> 0 | AG13: =SUMPRODUCT(NOT(ISBLANK(AG$3:AG$6))*(AG$3:AG$6<$AR$3:$AR$6)) -> 0 | AI13: =SUMPRODUCT(NOT(ISBLANK(AI$3:AI$6))*(AI$3:AI$6<$AS$3:$AS$6)) -> 0 | AJ13: =SUMPRODUCT(NOT(ISBLANK(AJ$3:AJ$6))*(AJ$3:AJ$6<$AT$3:$AT$6)) -> 0 | AK13: =SUMPRODUCT(NOT(ISBLANK(AK$3:AK$6))*(AK$3:AK$6<$AU$3:$AU$6)) -> 0
A14: WORSE | B14: =SUMPRODUCT((NOT(ISBLANK(B$3:B$6))*(B$3:B$6>$AQ$3:$AQ$6))+ISBLANK(B$3:B$6)) -> 0 | C14: =SUMPRODUCT((NOT(ISBLANK(C$3:C$6))*(C$3:C$6>$AR$3:$AR$6))+ISBLANK(C$3:C$6)) -> 0 | E14: =SUMPRODUCT((NOT(ISBLANK(E$3:E$6))*(E$3:E$6>$AS$3:$AS$6))+ISBLANK(E$3:E$6)) -> 0 | F14: =SUMPRODUCT((NOT(ISBLANK(F$3:F$6))*(F$3:F$6>$AT$3:$AT$6))+ISBLANK(F$3:F$6)) -> 0 | G14: =SUMPRODUCT((NOT(ISBLANK(G$3:G$6))*(G$3:G$6>$AU$3:$AU$6))+ISBLANK(G$3:G$6)) -> 0 | H14: =SUMPRODUCT((NOT(ISBLANK(H$3:H$6))*(H$3:H$6>$AQ$3:$AQ$6))+ISBLANK(H$3:H$6)) -> 0 | I14: =SUMPRODUCT((NOT(ISBLANK(I$3:I$6))*(I$3:I$6>$AR$3:$AR$6))+ISBLANK(I$3:I$6)) -> 0 | K14: =SUMPRODUCT((NOT(ISBLANK(K$3:K$6))*(K$3:K$6>$AS$3:$AS$6))+ISBLANK(K$3:K$6)) -> 0 | L14: =SUMPRODUCT((NOT(ISBLANK(L$3:L$6))*(L$3:L$6>$AT$3:$AT$6))+ISBLANK(L$3:L$6)) -> 0 | M14: =SUMPRODUCT((NOT(ISBLANK(M$3:M$6))*(M$3:M$6>$AU$3:$AU$6))+ISBLANK(M$3:M$6)) -> 0 | N14: =SUMPRODUCT((NOT(ISBLANK(N$3:N$6))*(N$3:N$6>$AQ$3:$AQ$6))+ISBLANK(N$3:N$6)) -> 0 | O14: =SUMPRODUCT((NOT(ISBLANK(O$3:O$6))*(O$3:O$6>$AR$3:$AR$6))+ISBLANK(O$3:O$6)) -> 0 | Q14: =SUMPRODUCT((NOT(ISBLANK(Q$3:Q$6))*(Q$3:Q$6>$AS$3:$AS$6))+ISBLANK(Q$3:Q$6)) -> 0 | R14: =SUMPRODUCT((NOT(ISBLANK(R$3:R$6))*(R$3:R$6>$AT$3:$AT$6))+ISBLANK(R$3:R$6)) -> 0 | S14: =SUMPRODUCT((NOT(ISBLANK(S$3:S$6))*(S$3:S$6>$AU$3:$AU$6))+ISBLANK(S$3:S$6)) -> 0 | T14: =SUMPRODUCT((NOT(ISBLANK(T$3:T$6))*(T$3:T$6>$AQ$3:$AQ$6))+ISBLANK(T$3:T$6)) -> 0 | U14: =SUMPRODUCT((NOT(ISBLANK(U$3:U$6))*(U$3:U$6>$AR$3:$AR$6))+ISBLANK(U$3:U$6)) -> 0 | W14: =SUMPRODUCT((NOT(ISBLANK(W$3:W$6))*(W$3:W$6>$AS$3:$AS$6))+ISBLANK(W$3:W$6)) -> 0 | X14: =SUMPRODUCT((NOT(ISBLANK(X$3:X$6))*(X$3:X$6>$AT$3:$AT$6))+ISBLANK(X$3:X$6)) -> 0 | Y14: =SUMPRODUCT((NOT(ISBLANK(Y$3:Y$6))*(Y$3:Y$6>$AU$3:$AU$6))+ISBLANK(Y$3:Y$6)) -> 0 | Z14: =SUMPRODUCT((NOT(ISBLANK(Z$3:Z$6))*(Z$3:Z$6>$AQ$3:$AQ$6))+ISBLANK(Z$3:Z$6)) -> 0 | AA14: =SUMPRODUCT((NOT(ISBLANK(AA$3:AA$6))*(AA$3:AA$6>$AR$3:$AR$6))+ISBLANK(AA$3:AA$6)) -> 0 | AC14: =SUMPRODUCT((NOT(ISBLANK(AC$3:AC$6))*(AC$3:AC$6>$AS$3:$AS$6))+ISBLANK(AC$3:AC$6)) -> 0 | AD14: =SUMPRODUCT((NOT(ISBLANK(AD$3:AD$6))*(AD$3:AD$6>$AT$3:$AT$6))+ISBLANK(AD$3:AD$6)) -> 0 | AE14: =SUMPRODUCT((NOT(ISBLANK(AE$3:AE$6))*(AE$3:AE$6>$AU$3:$AU$6))+ISBLANK(AE$3:AE$6)) -> 0 | AF14: =SUMPRODUCT((NOT(ISBLANK(AF$3:AF$6))*(AF$3:AF$6>$AQ$3:$AQ$6))+ISBLANK(AF$3:AF$6)) -> 0 | AG14: =SUMPRODUCT((NOT(ISBLANK(AG$3:AG$6))*(AG$3:AG$6>$AR$3:$AR$6))+ISBLANK(AG$3:AG$6)) -> 0 | AI14: =SUMPRODUCT((NOT(ISBLANK(AI$3:AI$6))*(AI$3:AI$6>$AS$3:$AS$6))+ISBLANK(AI$3:AI$6)) -> 0 | AJ14: =SUMPRODUCT((NOT(ISBLANK(AJ$3:AJ$6))*(AJ$3:AJ$6>$AT$3:$AT$6))+ISBLANK(AJ$3:AJ$6)) -> 0 | AK14: =SUMPRODUCT((NOT(ISBLANK(AK$3:AK$6))*(AK$3:AK$6>$AU$3:$AU$6))+ISBLANK(AK$3:AK$6)) -> 0
A15: WORST | B15: =SUMPRODUCT((NOT(ISBLANK(B$3:B$6))*(B$3:B$6=$AV$3:$AV$6))+ISBLANK(B$3:B$6)) -> 0 | C15: =SUMPRODUCT((NOT(ISBLANK(C$3:C$6))*(C$3:C$6=$AW$3:$AW$6))+ISBLANK(C$3:C$6)) -> 0 | E15: =SUMPRODUCT((NOT(ISBLANK(E$3:E$6))*(E$3:E$6=$AX$3:$AX$6))+ISBLANK(E$3:E$6)) -> 0 | F15: =SUMPRODUCT((NOT(ISBLANK(F$3:F$6))*(F$3:F$6=$AY$3:$AY$6))+ISBLANK(F$3:F$6)) -> 0 | G15: =SUMPRODUCT((NOT(ISBLANK(G$3:G$6))*(G$3:G$6=$AZ$3:$AZ$6))+ISBLANK(G$3:G$6)) -> 0 | H15: =SUMPRODUCT((NOT(ISBLANK(H$3:H$6))*(H$3:H$6=$AV$3:$AV$6))+ISBLANK(H$3:H$6)) -> 0 | I15: =SUMPRODUCT((NOT(ISBLANK(I$3:I$6))*(I$3:I$6=$AW$3:$AW$6))+ISBLANK(I$3:I$6)) -> 0 | K15: =SUMPRODUCT((NOT(ISBLANK(K$3:K$6))*(K$3:K$6=$AX$3:$AX$6))+ISBLANK(K$3:K$6)) -> 0 | L15: =SUMPRODUCT((NOT(ISBLANK(L$3:L$6))*(L$3:L$6=$AY$3:$AY$6))+ISBLANK(L$3:L$6)) -> 0 | M15: =SUMPRODUCT((NOT(ISBLANK(M$3:M$6))*(M$3:M$6=$AZ$3:$AZ$6))+ISBLANK(M$3:M$6)) -> 0 | N15: =SUMPRODUCT((NOT(ISBLANK(N$3:N$6))*(N$3:N$6=$AV$3:$AV$6))+ISBLANK(N$3:N$6)) -> 0 | O15: =SUMPRODUCT((NOT(ISBLANK(O$3:O$6))*(O$3:O$6=$AW$3:$AW$6))+ISBLANK(O$3:O$6)) -> 0 | Q15: =SUMPRODUCT((NOT(ISBLANK(Q$3:Q$6))*(Q$3:Q$6=$AX$3:$AX$6))+ISBLANK(Q$3:Q$6)) -> 0 | R15: =SUMPRODUCT((NOT(ISBLANK(R$3:R$6))*(R$3:R$6=$AY$3:$AY$6))+ISBLANK(R$3:R$6)) -> 0 | S15: =SUMPRODUCT((NOT(ISBLANK(S$3:S$6))*(S$3:S$6=$AZ$3:$AZ$6))+ISBLANK(S$3:S$6)) -> 0 | T15: =SUMPRODUCT((NOT(ISBLANK(T$3:T$6))*(T$3:T$6=$AV$3:$AV$6))+ISBLANK(T$3:T$6)) -> 0 | U15: =SUMPRODUCT((NOT(ISBLANK(U$3:U$6))*(U$3:U$6=$AW$3:$AW$6))+ISBLANK(U$3:U$6)) -> 0 | W15: =SUMPRODUCT((NOT(ISBLANK(W$3:W$6))*(W$3:W$6=$AX$3:$AX$6))+ISBLANK(W$3:W$6)) -> 0 | X15: =SUMPRODUCT((NOT(ISBLANK(X$3:X$6))*(X$3:X$6=$AY$3:$AY$6))+ISBLANK(X$3:X$6)) -> 0 | Y15: =SUMPRODUCT((NOT(ISBLANK(Y$3:Y$6))*(Y$3:Y$6=$AZ$3:$AZ$6))+ISBLANK(Y$3:Y$6)) -> 0 | Z15: =SUMPRODUCT((NOT(ISBLANK(Z$3:Z$6))*(Z$3:Z$6=$AV$3:$AV$6))+ISBLANK(Z$3:Z$6)) -> 0 | AA15: =SUMPRODUCT((NOT(ISBLANK(AA$3:AA$6))*(AA$3:AA$6=$AW$3:$AW$6))+ISBLANK(AA$3:AA$6)) -> 0 | AC15: =SUMPRODUCT((NOT(ISBLANK(AC$3:AC$6))*(AC$3:AC$6=$AX$3:$AX$6))+ISBLANK(AC$3:AC$6)) -> 0 | AD15: =SUMPRODUCT((NOT(ISBLANK(AD$3:AD$6))*(AD$3:AD$6=$AY$3:$AY$6))+ISBLANK(AD$3:AD$6)) -> 0 | AE15: =SUMPRODUCT((NOT(ISBLANK(AE$3:AE$6))*(AE$3:AE$6=$AZ$3:$AZ$6))+ISBLANK(AE$3:AE$6)) -> 0 | AF15: =SUMPRODUCT((NOT(ISBLANK(AF$3:AF$6))*(AF$3:AF$6=$AV$3:$AV$6))+ISBLANK(AF$3:AF$6)) -> 0 | AG15: =SUMPRODUCT((NOT(ISBLANK(AG$3:AG$6))*(AG$3:AG$6=$AW$3:$AW$6))+ISBLANK(AG$3:AG$6)) -> 0 | AI15: =SUMPRODUCT((NOT(ISBLANK(AI$3:AI$6))*(AI$3:AI$6=$AX$3:$AX$6))+ISBLANK(AI$3:AI$6)) -> 0 | AJ15: =SUMPRODUCT((NOT(ISBLANK(AJ$3:AJ$6))*(AJ$3:AJ$6=$AY$3:$AY$6))+ISBLANK(AJ$3:AJ$6)) -> 0 | AK15: =SUMPRODUCT((NOT(ISBLANK(AK$3:AK$6))*(AK$3:AK$6=$AZ$3:$AZ$6))+ISBLANK(AK$3:AK$6)) -> 0

Sheet Merged Runs
A1: Merge criteria: | B1: memelingo-1/simple_mlp-lpnmr-ht | H1: memelingo-1/simple_mlp-lpnmr-htc | N1: memelingo-1/simple_mlp-lpnmr-htcdl | T1: memelingo-1/simple_mlp-tplp-ht | Z1: memelingo-1/simple_mlp-tplp-htc | AF1: memelingo-1/simple_mlp-tplp-htcdl | AL1: min | AQ1: median | AV1: max
A2: median | B2: time | C2: stime | D2: status | E2: rules | F2: gtime | G2: ctime | H2: time | I2: stime | J2: status | K2: rules | L2: gtime | M2: ctime | N2: time | O2: stime | P2: status | Q2: rules | R2: gtime | S2: ctime | T2: time | U2: stime | V2: status | W2: rules | X2: gtime | Y2: ctime | Z2: time | AA2: stime | AB2: status | AC2: rules | AD2: gtime | AE2: ctime | AF2: time | AG2: stime | AH2: status | AI2: rules | AJ2: gtime | AK2: ctime | AL2: time | AM2: stime | AN2: rules | AO2: gtime | AP2: ctime | AQ2: time | AR2: stime | AS2: rules | AT2: gtime | AU2: ctime | AV2: time | AW2: stime | AX2: rules | AY2: gtime | AZ2: ctime
A3: instances/size-1 | B3: {=_xlfn.SWITCH($A$2,"average", AVERAGE(Instances!B3:Instances!B3),"median", MEDIAN(Instances!B3:Instances!B3),"min", MIN(Instances!B3:Instances!B3),"max", MAX(Instances!B3:Instances!B3),"diff", MAX(Instances!B3:Instances!B3)-MIN(Instances!B3:Instances!B3))} -> 0 | C3: {=_xlfn.SWITCH($A$2,"average", AVERAGE(Instances!C3:Instances!C3),"median", MEDIAN(Instances!C3:Instances!C3),"min", MIN(Instances!C3:Instances!C3),"max", MAX(Instances!C3:Instances!C3),"diff", MAX(Instances!C3:Instances!C3)-MIN(Instances!C3:Instances!C3))} -> 0 | E3: {=_xlfn.SWITCH($A$2,"average", AVERAGE(Instances!E3:Instances!E3),"median", MEDIAN(Instances!E3:Instances!E3),"min", MIN(Instances!E3:Instances!E3),"max", MAX(Instances!E3:Instances!E3),"diff", MAX(Instances!E3:Instances!E3)-MIN(Instances!E3:Instances!E3))} -> 0 | F3: {=_xlfn.SWITCH($A$2,"average", AVERAGE(Instances!F3:Instances!F3),"median", MEDIAN(Instances!F3:Instances!F3),"min", MIN(Instances!F3:Instances!F3),"max", MAX(Instances!F3:Instances!F3),"diff", MAX(Instances!F3:Instances!F3)-MIN(Instances!F3:Instances!F3))} -> 0 | G3: {=_xlfn.SWITCH($A$2,"average", AVERAGE(Instances!G3:Instances!G3),"median", MEDIAN(Instances!G3:Instances!G3),"min", MIN(Instances!G3:Instances!G3),"max", MAX(Instances!G3:Instances!G3),"diff", MAX(Instances!G3:Instances!G3)-MIN(Instances!G3:Instances!G3))} -> 0 | H3: {=_xlfn.SWITCH($A$2,"average", AVERAGE(Instances!H3:Instances!H3),"median", MEDIAN(Instances!H3:Instances!H3),"min", MIN(Instances!H3:Instances!H3),"max", MAX(Instances!H3:Instances!H3),"diff", MAX(Instances!H3:Instances!H3)-MIN(Instances!H3:Instances!H3))} -> 0 | I3: {=_xlfn.SWITCH($A$2,"average", AVERAGE(Instances!I3:Instances!I3),"median", MEDIAN(Instances!I3:Instances!I3),"min", MIN(Instances!I3:Instances!I3),"max", MAX(Instances!I3:Instances!I3),"diff", MAX(Instances!I3:Instances!I3)-MIN(Instances!I3:Instances!I3))} -> 0 | K3: {=_xlfn.SWITCH($A$2,"average", AVERAGE(Instances!K3:Instances!K3),"median", MEDIAN(Instances!K3:Instances!K3),"min", MIN(Instances!K3:Instances!K3),"max", MAX(Instances!K3:Instances!K3),"diff", MAX(Instances!K3:Instances!K3)-MIN(Instances!K3:Instances!K3))} -> 0 | L3: {=_xlfn.SWITCH($A$2,"average", AVERAGE(Instances!L3:Instances!L3),"median", MEDIAN(Instances!L3:Instances!L3),"min", MIN(Instances!L3:Instances!L3),"max", MAX(Instances!L3:Instances!L3),"diff", MAX(Instances!L3:Instances!L3)-MIN(Instances!L3:Instances!L3))} -> 0 | M3: {=_xlfn.SWITCH($A$2,"average", AVERAGE(Instances!M3:Instances!M3),"median", MEDIAN(Instances!M3:Instances!M3),"min", MIN(Instances!M3:Instances!M3),"max", MAX(Instances!M3:Instances!M3),"diff", MAX(Instances!M3:Instances!M3)-MIN(Instances!M3:Instances!M3))} -> 0 | N3: {=_xlfn.SWITCH($A$2,"average", AVERAGE(Instances!N3:Instances!N3),"median", MEDIAN(Instances!N3:Instances!N3),"min", MIN(Instances!N3:Instances!N3),"max", MAX(Instances!N3:Instances!N3),"diff", MAX(Instances!N3:Instances!N3)-MIN(Instances!N3:Instances!N3))} -> 0 | O3: {=_xlfn.SWITCH($A$2,"average", AVERAGE(Instances!O3:Instances!O3),"median", MEDIAN(Instances!O3:Instances!O3),"min", MIN(Instances!O3:Instances!O3),"max", MAX(Instances!O3:Instances!O3),"diff", MAX(Instances!O3:Instances!O3)-MIN(Instances!O3:Instances!O3))} -> 0 | Q3: {=_xlfn.SWITCH($A$2,"average", AVERAGE(Instances!Q3:Instances!Q3),"median", MEDIAN(Instances!Q3:Instances!Q3),"min", MIN(Instances!Q3:Instances!Q3),"max", MAX(Instances!Q3:Instances!Q3),"diff", MAX(Instances!Q3:Instances!Q3)-MIN(Instances!Q3:Instances!Q3))} -> 0 | R3: {=_xlfn.SWITCH($A$2,"average", AVERAGE(Instances!R3:Instances!R3),"median", MEDIAN(Instances!R3:Instances!R3),"min", MIN(Instances!R3:Instances!R3),"max", MAX(Instances!R3:Instances!R3),"diff", MAX(Instances!R3:Instances!R3)-MIN(Instances!R3:Instances!R3))} -> 0 | S3: {=_xlfn.SWITCH($A$2,"average", AVERAGE(Instances!S3:Instances!S3),"median", MEDIAN(Instances!S3:Instances!S3),"min", MIN(Instances!S3:Instances!S3),"max", MAX(Instances!S3:Instances!S3),"diff", MAX(Instances!S3:Instances!S3)-MIN(Instances!S3:Instances!S3))} -> 0 | T3: {=_xlfn.SWITCH($A$2,"average", AVERAGE(Instances!T3:Instances!T3),"median", MEDIAN(Instances!T3:Instances!T3),"min", MIN(Instances!T3:Instances!T3),"max", MAX(Instances!T3:Instances!T3),"diff", MAX(Instances!T3:Instances!T3)-MIN(Instances!T3:Instances!T3))} -> 0 | U3: {=_xlfn.SWITCH($A$2,"average", AVERAGE(Instances!U3:Instances!U3),"median", MEDIAN(Instances!U3:Instances!U3),"min", MIN(Instances!U3:Instances!U3),"max", MAX(Instances!U3:Instances!U3),"diff", MAX(Instances!U3:Instances!U3)-MIN(Instances!U3:Instances!U3))} -> 0 | W3: {=_xlfn.SWITCH($A$2,"average", AVERAGE(Instances!W3:Instances!W3),"median", MEDIAN(Instances!W3:Instances!W3),"min", MIN(Instances!W3:Instances!W3),"max", MAX(Instances!W3:Instances!W3),"diff", MAX(Instances!W3:Instances!W3)-MIN(Instances!W3:Instances!W3))} -> 0 | X3: {=_xlfn.SWITCH($A$2,"average", AVERAGE(Instances!X3:Instances!X3),"median", MEDIAN(Instances!X3:Instances!X3),"min", MIN(Instances!X3:Instances!X3),"max", MAX(Instances!X3:Instances!X3),"diff", MAX(Instances!X3:Instances!X3)-MIN(Instances!X3:Instances!X3))} -> 0 | Y3: {=_xlfn.SWITCH($A$2,"average", AVERAGE(Instances!Y3:Instances!Y3),"median", MEDIAN(Instances!Y3:Instances!Y3),"min", MIN(Instances!Y3:Instances!Y3),"max", MAX(Instances!Y3:Instances!Y3),"diff", MAX(Instances!Y3:Instances!Y3)-MIN(Instances!Y3:Instances!Y3))} -> 0 | Z3: {=_xlfn.SWITCH($A$2,"average", AVERAGE(Instances!Z3:Instances!Z3),"median", MEDIAN(Instances!Z3:Instances!Z3),"min", MIN(Instances!Z3:Instances!Z3),"max", MAX(Instances!Z3:Instances!Z3),"diff", MAX(Instances!Z3:Instances!Z3)-MIN(Instances!Z3:Instances!Z3))} -> 0 | AA3: {=_xlfn.SWITCH($A$2,"average", AVERAGE(Instances!AA3:Instances!AA3),"median", MEDIAN(Instances!AA3:Instances!AA3),"min", MIN(Instances!AA3:Instances!AA3),"max", MAX(Instances!AA3:Instances!AA3),"diff", MAX(Instances!AA3:Instances!AA3)-MIN(Instances!AA3:Instances!AA3))} -> 0 | AC3: {=_xlfn.SWITCH($A$2,"average", AVERAGE(Instances!AC3:Instances!AC3),"median", MEDIAN(Instances!AC3:Instances!AC3),"min", MIN(Instances!AC3:Instances!AC3),"max", MAX(Instances!AC3:Instances!AC3),"diff", MAX(Instances!AC3:Instances!AC3)-MIN(Instances!AC3:Instances!AC3))} -> 0 | AD3: {=_xlfn.SWITCH($A$2,"average", AVERAGE(Instances!AD3:Instances!AD3),"median", MEDIAN(Instances!AD3:Instances!AD3),"min", MIN(Instances!AD3:Instances!AD3),"max", MAX(Instances!AD3:Instances!AD3),"diff", MAX(Instances!AD3:Instances!AD3)-MIN(Instances!AD3:Instances!AD3))} -> 0 | AE3: {=_xlfn.SWITCH($A$2,"average", AVERAGE(Instances!AE3:Instances!AE3),"median", MEDIAN(Instances!AE3:Instances!AE3),"min", MIN(Instances!AE3:Instances!AE3),"max", MAX(Instances!AE3:Instances!AE3),"diff", MAX(Instances!AE3:Instances!AE3)-MIN(Instances!AE3:Instances!AE3))} -> 0 | AF3: {=_xlfn.SWITCH($A$2,"average", AVERAGE(Instances!AF3:Instances!AF3),"median", MEDIAN(Instances!AF3:Instances!AF3),"min", MIN(Instances!AF3:Instances!AF3),"max", MAX(Instances!AF3:Instances!AF3),"diff", MAX(Instances!AF3:Instances!AF3)-MIN(Instances!AF3:Instances!AF3))} -> 0 | AG3: {=_xlfn.SWITCH($A$2,"average", AVERAGE(Instances!AG3:Instances!AG3),"median", MEDIAN(Instances!AG3:Instances!AG3),"min", MIN(Instances!AG3:Instances!AG3),"max", MAX(Instances!AG3:Instances!AG3),"diff", MAX(Instances!AG3:Instances!AG3)-MIN(Instances!AG3:Instances!AG3))} -> 0 | AI3: {=_xlfn.SWITCH($A$2,"average", AVERAGE(Instances!AI3:Instances!AI3),"median", MEDIAN(Instances!AI3:Instances!AI3),"min", MIN(Instances!AI3:Instances!AI3),"max", MAX(Instances!AI3:Instances!AI3),"diff", MAX(Instances!AI3:Instances!AI3)-MIN(Instances!AI3:Instances!AI3))} -> 0 | AJ3: {=_xlfn.SWITCH($A$2,"average", AVERAGE(Instances!AJ3:Instances!AJ3),"median", MEDIAN(Instances!AJ3:Instances!AJ3),"min", MIN(Instances!AJ3:Instances!AJ3),"max", MAX(Instances!AJ3:Instances!AJ3),"diff", MAX(Instances!AJ3:Instances!AJ3)-MIN(Instances!AJ3:Instances!AJ3))} -> 0 | AK3: {=_xlfn.SWITCH($A$2,"average", AVERAGE(Instances!AK3:Instances!AK3),"median", MEDIAN(Instances!AK3:Instances!AK3),"min", MIN(Instances!AK3:Instances!AK3),"max", MAX(Instances!AK3:Instances!AK3),"diff", MAX(Instances!AK3:Instances!AK3)-MIN(Instances!AK3:Instances!AK3))} -> 0 | AL3: =MIN($B3,$H3,$N3,$T3,$Z3,$AF3) -> 0 | AM3: =MIN($C3,$I3,$O3,$U3,$AA3,$AG3) -> 0 | AN3: =MIN($E3,$K3,$Q3,$W3,$AC3,$AI3) -> 0 | AO3: =MIN($F3,$L3,$R3,$X3,$AD3,$AJ3) -> 0 | AP3: =MIN($G3,$M3,$S3,$Y3,$AE3,$AK3) -> 0 | AQ3: =MEDIAN($B3,$H3,$N3,$T3,$Z3,$AF3) -> 0 | AR3: =MEDIAN($C3,$I3,$O3,$U3,$AA3,$AG3) -> 0 | AS3: =MEDIAN($E3,$K3,$Q3,$W3,$AC3,$AI3) -> 0 | AT3: =MEDIAN($F3,$L3,$R3,$X3,$AD3,$AJ3) -> 0 | AU3: =MEDIAN($G3,$M3,$S3,$Y3,$AE3,$AK3) -> 0 | AV3: =MAX($B3,$H3,$N3,$T3,$Z3,$AF3) -> 0 | AW3: =MAX($C3,$I3,$O3,$U3,$AA3,$AG3) -> 0 | AX3: =MAX($E3,$K3,$Q3,$W3,$AC3,$AI3) -> 0 | AY3: =MAX($F3,$L3,$R3,$X3,$AD3,$AJ3) -> 0 | AZ3: =MAX($G3,$M3,$S3,$Y3,$AE3,$AK3) -> 0
A4: instances/size-10 | B4: {=_xlfn.SWITCH($A$2,"average", AVERAGE(Instances!B4:Instances!B4),"median", MEDIAN(Instances!B4:Instances!B4),"min", MIN(Instances!B4:Instances!B4),"max", MAX(Instances!B4:Instances!B4),"diff", MAX(Instances!B4:Instances!B4)-MIN(Instances!B4:Instances!B4))} -> 0 | H4: {=_xlfn.SWITCH($A$2,"average", AVERAGE(Instances!H4:Instances!H4),"median", MEDIAN(Instances!H4:Instances!H4),"min", MIN(Instances!H4:Instances!H4),"max", MAX(Instances!H4:Instances!H4),"diff", MAX(Instances!H4:Instances!H4)-MIN(Instances!H4:Instances!H4))} -> 0 | I4: {=_xlfn.SWITCH($A$2,"average", AVERAGE(Instances!I4:Instances!I4),"median", MEDIAN(Instances!I4:Instances!I4),"min", MIN(Instances!I4:Instances!I4),"max", MAX(Instances!I4:Instances!I4),"diff", MAX(Instances!I4:Instances!I4)-MIN(Instances!I4:Instances!I4))} -> 0 | K4: {=_xlfn.SWITCH($A$2,"average", AVERAGE(Instances!K4:Instances!K4),"median", MEDIAN(Instances!K4:Instances!K4),"min", MIN(Instances!K4:Instances!K4),"max", MAX(Instances!K4:Instances!K4),"diff", MAX(Instances!K4:Instances!K4)-MIN(Instances!K4:Instances!K4))} -> 0 | L4: {=_xlfn.SWITCH($A$2,"average", AVERAGE(Instances!L4:Instances!L4),"median", MEDIAN(Instances!L4:Instances!L4),"min", MIN(Instances!L4:Instances!L4),"max", MAX(Instances!L4:Instances!L4),"diff", MAX(Instances!L4:Instances!L4)-MIN(Instances!L4:Instances!L4))} -> 0 | M4: {=_xlfn.SWITCH($A$2,"average", AVERAGE(Instances!M4:Instances!M4),"median", MEDIAN(Instances!M4:Instances!M4),"min", MIN(Instances!M4:Instances!M4),"max", MAX(Instances!M4:Instances!M4),"diff", MAX(Instances!M4:Instances!M4)-MIN(Instances!M4:Instances!M4))} -> 0 | N4: {=_xlfn.SWITCH($A$2,"average", AVERAGE(Instances!N4:Instances!N4),"median", MEDIAN(Instances!N4:Instances!N4),"min", MIN(Instances!N4:Instances!N4),"max", MAX(Instances!N4:Instances!N4),"diff", MAX(Instances!N4:Instances!N4)-MIN(Instances!N4:Instances!N4))} -> 0 | O4: {=_xlfn.SWITCH($A$2,"average", AVERAGE(Instances!O4:Instances!O4),"median", MEDIAN(Instances!O4:Instances!O4),"min", MIN(Instances!O4:Instances!O4),"max", MAX(Instances!O4:Instances!O4),"diff", MAX(Instances!O4:Instances!O4)-MIN(Instances!O4:Instances!O4))} -> 0 | Q4: {=_xlfn.SWITCH($A$2,"average", AVERAGE(Instances!Q4:Instances!Q4),"median", MEDIAN(Instances!Q4:Instances!Q4),"min", MIN(Instances!Q4:Instances!Q4),"max", MAX(Instances!Q4:Instances!Q4),"diff", MAX(Instances!Q4:Instances!Q4)-MIN(Instances!Q4:Instances!Q4))} -> 0 | R4: {=_xlfn.SWITCH($A$2,"average", AVERAGE(Instances!R4:Instances!R4),"median", MEDIAN(Instances!R4:Instances!R4),"min", MIN(Instances!R4:Instances!R4),"max", MAX(Instances!R4:Instances!R4),"diff", MAX(Instances!R4:Instances!R4)-MIN(Instances!R4:Instances!R4))} -> 0 | S4: {=_xlfn.SWITCH($A$2,"average", AVERAGE(Instances!S4:Instances!S4),"median", MEDIAN(Instances!S4:Instances!S4),"min", MIN(Instances!S4:Instances!S4),"max", MAX(Instances!S4:Instances!S4),"diff", MAX(Instances!S4:Instances!S4)-MIN(Instances!S4:Instances!S4))} -> 0 | T4: {=_xlfn.SWITCH($A$2,"average", AVERAGE(Instances!T4:Instances!T4),"median", MEDIAN(Instances!T4:Instances!T4),"min", MIN(Instances!T4:Instances!T4),"max", MAX(Instances!T4:Instances!T4),"diff", MAX(Instances!T4:Instances!T4)-MIN(Instances!T4:Instances!T4))} -> 0 | Z4: {=_xlfn.SWITCH($A$2,"average", AVERAGE(Instances!Z4:Instances!Z4),"median", MEDIAN(Instances!Z4:Instances!Z4),"min", MIN(Instances!Z4:Instances!Z4),"max", MAX(Instances!Z4:Instances!Z4),"diff", MAX(Instances!Z4:Instances!Z4)-MIN(Instances!Z4:Instances!Z4))} -> 0 | AA4: {=_xlfn.SWITCH($A$2,"average", AVERAGE(Instances!AA4:Instances!AA4),"median", MEDIAN(Instances!AA4:Instances!AA4),"min", MIN(Instances!AA4:Instances!AA4),"max", MAX(Instances!AA4:Instances!AA4),"diff", MAX(Instances!AA4:Instances!AA4)-MIN(Instances!AA4:Instances!AA4))} -> 0 | AC4: {=_xlfn.SWITCH($A$2,"average", AVERAGE(Instances!AC4:Instances!AC4),"median", MEDIAN(Instances!AC4:Instances!AC4),"min", MIN(Instances!AC4:Instances!AC4),"max", MAX(Instances!AC4:Instances!AC4),"diff", MAX(Instances!AC4:Instances!AC4)-MIN(Instances!AC4:Instances!AC4))} -> 0 | AD4: {=_xlfn.SWITCH($A$2,"average", AVERAGE(Instances!AD4:Instances!AD4),"median", MEDIAN(Instances!AD4:Instances!AD4),"min", MIN(Instances!AD4:Instances!AD4),"max", MAX(Instances!AD4:Instances!AD4),"diff", MAX(Instances!AD4:Instances!AD4)-MIN(Instances!AD4:Instances!AD4))} -> 0 | AE4: {=_xlfn.SWITCH($A$2,"average", AVERAGE(Instances!AE4:Instances!AE4),"median", MEDIAN(Instances!AE4:Instances!AE4),"min", MIN(Instances!AE4:Instances!AE4),"max", MAX(Instances!AE4:Instances!AE4),"diff", MAX(Instances!AE4:Instances!AE4)-MIN(Instances!AE4:Instances!AE4))} -> 0 | AF4: {=_xlfn.SWITCH($A$2,"average", AVERAGE(Instances!AF4:Instances!AF4),"median", MEDIAN(Instances!AF4:Instances!AF4),"min", MIN(Instances!AF4:Instances!AF4),"max", MAX(Instances!AF4:Instances!AF4),"diff", MAX(Instances!AF4:Instances!AF4)-MIN(Instances!AF4:Instances!AF4))} -> 0 | AG4: {=_xlfn.SWITCH($A$2,"average", AVERAGE(Instances!AG4:Instances!AG4),"median", MEDIAN(Instances!AG4:Instances!AG4),"min", MIN(Instances!AG4:Instances!AG4),"max", MAX(Instances!AG4:Instances!AG4),"diff", MAX(Instances!AG4:Instances!AG4)-MIN(Instances!AG4:Instances!AG4))} -> 0 | AI4: {=_xlfn.SWITCH($A$2,"average", AVERAGE(Instances!AI4:Instances!AI4),"median", MEDIAN(Instances!AI4:Instances!AI4),"min", MIN(Instances!AI4:Instances!AI4),"max", MAX(Instances!AI4:Instances!AI4),"diff", MAX(Instances!AI4:Instances!AI4)-MIN(Instances!AI4:Instances!AI4))} -> 0 | AJ4: {=_xlfn.SWITCH($A$2,"average", AVERAGE(Instances!AJ4:Instances!AJ4),"median", MEDIAN(Instances!AJ4:Instances!AJ4),"min", MIN(Instances!AJ4:Instances!AJ4),"max", MAX(Instances!AJ4:Instances!AJ4),"diff", MAX(Instances!AJ4:Instances!AJ4)-MIN(Instances!AJ4:Instances!AJ4))} -> 0 | AK4: {=_xlfn.SWITCH($A$2,"average", AVERAGE(Instances!AK4:Instances!AK4),"median", MEDIAN(Instances!AK4:Instances!AK4),"min", MIN(Instances!AK4:Instances!AK4),"max", MAX(Instances!AK4:Instances!AK4),"diff", MAX(Instances!AK4:Instances!AK4)-MIN(Instances!AK4:Instances!AK4))} -> 0 | AL4: =MIN($B4,$H4,$N4,$T4,$Z4,$AF4) -> 0 | AM4: =MIN($C4,$I4,$O4,$U4,$AA4,$AG4) -> 0 | AN4: =MIN($E4,$K4,$Q4,$W4,$AC4,$AI4) -> 0 | AO4: =MIN($F4,$L4,$R4,$X4,$AD4,$AJ4) -> 0 | AP4: =MIN($G4,$M4,$S4,$Y4,$AE4,$AK4) -> 0 | AQ4: =MEDIAN($B4,$H4,$N4,$T4,$Z4,$AF4) -> 0 | AR4: =MEDIAN($C4,$I4,$O4,$U4,$AA4,$AG4) -> 0 | AS4: =MEDIAN($E4,$K4,$Q4,$W4,$AC4,$AI4) -> 0 | AT4: =MEDIAN($F4,$L4,$R4,$X4,$AD4,$AJ4) -> 0 | AU4: =MEDIAN($G4,$M4,$S4,$Y4,$AE4,$AK4) -> 0 | AV4: =MAX($B4,$H4,$N4,$T4,$Z4,$AF4) -> 0 | AW4: =MAX($C4,$I4,$O4,$U4,$AA4,$AG4) -> 0 | AX4: =MAX($E4,$K4,$Q4,$W4,$AC4,$AI4) -> 0 | AY4: =MAX($F4,$L4,$R4,$X4,$AD4,$AJ4) -> 0 | AZ4: =MAX($G4,$M4,$S4,$Y4,$AE4,$AK4) -> 0
A5: instances/size-5 | B5: {=_xlfn.SWITCH($A$2,"average", AVERAGE(Instances!B5:Instances!B5),"median", MEDIAN(Instances!B5:Instances!B5),"min", MIN(Instances!B5:Instances!B5),"max", MAX(Instances!B5:Instances!B5),"diff", MAX(Instances!B5:Instances!B5)-MIN(Instances!B5:Instances!B5))} -> 0 | C5: {=_xlfn.SWITCH($A$2,"average", AVERAGE(Instances!C5:Instances!C5),"median", MEDIAN(Instances!C5:Instances!C5),"min", MIN(Instances!C5:Instances!C5),"max", MAX(Instances!C5:Instances!C5),"diff", MAX(Instances!C5:Instances!C5)-MIN(Instances!C5:Instances!C5))} -> 0 | E5: {=_xlfn.SWITCH($A$2,"average", AVERAGE(Instances!E5:Instances!E5),"median", MEDIAN(Instances!E5:Instances!E5),"min", MIN(Instances!E5:Instances!E5),"max", MAX(Instances!E5:Instances!E5),"diff", MAX(Instances!E5:Instances!E5)-MIN(Instances!E5:Instances!E5))} -> 0 | F5: {=_xlfn.SWITCH($A$2,"average", AVERAGE(Instances!F5:Instances!F5),"median", MEDIAN(Instances!F5:Instances!F5),"min", MIN(Instances!F5:Instances!F5),"max", MAX(Instances!F5:Instances!F5),"diff", MAX(Instances!F5:Instances!F5)-MIN(Instances!F5:Instances!F5))} -> 0 | G5: {=_xlfn.SWITCH($A$2,"average", AVERAGE(Instances!G5:Instances!G5),"median", MEDIAN(Instances!G5:Instances!G5),"min", MIN(Instances!G5:Instances!G5),"max", MAX(Instances!G5:Instances!G5),"diff", MAX(Instances!G5:Instances!G5)-MIN(Instances!G5:Instances!G5))} -> 0 | H5: {=_xlfn.SWITCH($A$2,"average", AVERAGE(Instances!H5:Instances!H5),"median", MEDIAN(Instances!H5:Instances!H5),"min", MIN(Instances!H5:Instances!H5),"max", MAX(Instances!H5:Instances!H5),"diff", MAX(Instances!H5:Instances!H5)-MIN(Instances!H5:Instances!H5))} -> 0 | I5: {=_xlfn.SWITCH($A$2,"average", AVERAGE(Instances!I5:Instances!I5),"median", MEDIAN(Instances!I5:Instances!I5),"min", MIN(Instances!I5:Instances!I5),"max", MAX(Instances!I5:Instances!I5),"diff", MAX(Instances!I5:Instances!I5)-MIN(Instances!I5:Instances!I5))} -> 0 | K5: {=_xlfn.SWITCH($A$2,"average", AVERAGE(Instances!K5:Instances!K5),"median", MEDIAN(Instances!K5:Instances!K5),"min", MIN(Instances!K5:Instances!K5),"max", MAX(Instances!K5:Instances!K5),"diff", MAX(Instances!K5:Instances!K5)-MIN(Instances!K5:Instances!K5))} -> 0 | L5: {=_xlfn.SWITCH($A$2,"average", AVERAGE(Instances!L5:Instances!L5),"median", MEDIAN(Instances!L5:Instances!L5),"min", MIN(Instances!L5:Instances!L5),"max", MAX(Instances!L5:Instances!L5),"diff", MAX(Instances!L5:Instances!L5)-MIN(Instances!L5:Instances!L5))} -> 0 | M5: {=_xlfn.SWITCH($A$2,"average", AVERAGE(Instances!M5:Instances!M5),"median", MEDIAN(Instances!M5:Instances!M5),"min", MIN(Instances!M5:Instances!M5),"max", MAX(Instances!M5:Instances!M5),"diff", MAX(Instances!M5:Instances!M5)-MIN(Instances!M5:Instances!M5))} -> 0 | N5: {=_xlfn.SWITCH($A$2,"average", AVERAGE(Instances!N5:Instances!N5),"median", MEDIAN(Instances!N5:Instances!N5),"min", MIN(Instances!N5:Instances!N5),"max", MAX(Instances!N5:Instances!N5),"diff", MAX(Instances!N5:Instances!N5)-MIN(Instances!N5:Instances!N5))} -> 0 | O5: {=_xlfn.SWITCH($A$2,"average", AVERAGE(Instances!O5:Instances!O5),"median", MEDIAN(Instances!O5:Instances!O5),"min", MIN(Instances!O5:Instances!O5),"max", MAX(Instances!O5:Instances!O5),"diff", MAX(Instances!O5:Instances!O5)-MIN(Instances!O5:Instances!O5))} -> 0 | Q5: {=_xlfn.SWITCH($A$2,"average", AVERAGE(Instances!Q5:Instances!Q5),"median", MEDIAN(Instances!Q5:Instances!Q5),"min", MIN(Instances!Q5:Instances!Q5),"max", MAX(Instances!Q5:Instances!Q5),"diff", MAX(Instances!Q5:Instances!Q5)-MIN(Instances!Q5:Instances!Q5))} -> 0 | R5: {=_xlfn.SWITCH($A$2,"average", AVERAGE(Instances!R5:Instances!R5),"median", MEDIAN(Instances!R5:Instances!R5),"min", MIN(Instances!R5:Instances!R5),"max", MAX(Instances!R5:Instances!R5),"diff", MAX(Instances!R5:Instances!R5)-MIN(Instances!R5:Instances!R5))} -> 0 | S5: {=_xlfn.SWITCH($A$2,"average", AVERAGE(Instances!S5:Instances!S5),"median", MEDIAN(Instances!S5:Instances!S5),"min", MIN(Instances!S5:Instances!S5),"max", MAX(Instances!S5:Instances!S5),"diff", MAX(Instances!S5:Instances!S5)-MIN(Instances!S5:Instances!S5))} -> 0 | T5: {=_xlfn.SWITCH($A$2,"average", AVERAGE(Instances!T5:Instances!T5),"median", MEDIAN(Instances!T5:Instances!T5),"min", MIN(Instances!T5:Instances!T5),"max", MAX(Instances!T5:Instances!T5),"diff", MAX(Instances!T5:Instances!T5)-MIN(Instances!T5:Instances!T5))} -> 0 | U5: {=_xlfn.SWITCH($A$2,"average", AVERAGE(Instances!U5:Instances!U5),"median", MEDIAN(Instances!U5:Instances!U5),"min", MIN(Instances!U5:Instances!U5),"max", MAX(Instances!U5:Instances!U5),"diff", MAX(Instances!U5:Instances!U5)-MIN(Instances!U5:Instances!U5))} -> 0 | W5: {=_xlfn.SWITCH($A$2,"average", AVERAGE(Instances!W5:Instances!W5),"median", MEDIAN(Instances!W5:Instances!W5),"min", MIN(Instances!W5:Instances!W5),"max", MAX(Instances!W5:Instances!W5),"diff", MAX(Instances!W5:Instances!W5)-MIN(Instances!W5:Instances!W5))} -> 0 | X5: {=_xlfn.SWITCH($A$2,"average", AVERAGE(Instances!X5:Instances!X5),"median", MEDIAN(Instances!X5:Instances!X5),"min", MIN(Instances!X5:Instances!X5),"max", MAX(Instances!X5:Instances!X5),"diff", MAX(Instances!X5:Instances!X5)-MIN(Instances!X5:Instances!X5))} -> 0 | Y5: {=_xlfn.SWITCH($A$2,"average", AVERAGE(Instances!Y5:Instances!Y5),"median", MEDIAN(Instances!Y5:Instances!Y5),"min", MIN(Instances!Y5:Instances!Y5),"max", MAX(Instances!Y5:Instances!Y5),"diff", MAX(Instances!Y5:Instances!Y5)-MIN(Instances!Y5:Instances!Y5))} -> 0 | Z5: {=_xlfn.SWITCH($A$2,"average", AVERAGE(Instances!Z5:Instances!Z5),"median", MEDIAN(Instances!Z5:Instances!Z5),"min", MIN(Instances!Z5:Instances!Z5),"max", MAX(Instances!Z5:Instances!Z5),"diff", MAX(Instances!Z5:Instances!Z5)-MIN(Instances!Z5:Instances!Z5))} -> 0 | AA5: {=_xlfn.SWITCH($A$2,"average", AVERAGE(Instances!AA5:Instances!AA5),"median", MEDIAN(Instances!AA5:Instances!AA5),"min", MIN(Instances!AA5:Instances!AA5),"max", MAX(Instances!AA5:Instances!AA5),"diff", MAX(Instances!AA5:Instances!AA5)-MIN(Instances!AA5:Instances!AA5))} -> 0 | AC5: {=_xlfn.SWITCH($A$2,"average", AVERAGE(Instances!AC5:Instances!AC5),"median", MEDIAN(Instances!AC5:Instances!AC5),"min", MIN(Instances!AC5:Instances!AC5),"max", MAX(Instances!AC5:Instances!AC5),"diff", MAX(Instances!AC5:Instances!AC5)-MIN(Instances!AC5:Instances!AC5))} -> 0 | AD5: {=_xlfn.SWITCH($A$2,"average", AVERAGE(Instances!AD5:Instances!AD5),"median", MEDIAN(Instances!AD5:Instances!AD5),"min", MIN(Instances!AD5:Instances!AD5),"max", MAX(Instances!AD5:Instances!AD5),"diff", MAX(Instances!AD5:Instances!AD5)-MIN(Instances!AD5:Instances!AD5))} -> 0 | AE5: {=_xlfn.SWITCH($A$2,"average", AVERAGE(Instances!AE5:Instances!AE5),"median", MEDIAN(Instances!AE5:Instances!AE5),"min", MIN(Instances!AE5:Instances!AE5),"max", MAX(Instances!AE5:Instances!AE5),"diff", MAX(Instances!AE5:Instances!AE5)-MIN(Instances!AE5:Instances!AE5))} -> 0 | AF5: {=_xlfn.SWITCH($A$2,"average", AVERAGE(Instances!AF5:Instances!AF5),"median", MEDIAN(Instances!AF5:Instances!AF5),"min", MIN(Instances!AF5:Instances!AF5),"max", MAX(Instances!AF5:Instances!AF5),"diff", MAX(Instances!AF5:Instances!AF5)-MIN(Instances!AF5:Instances!AF5))} -> 0 | AG5: {=_xlfn.SWITCH($A$2,"average", AVERAGE(Instances!AG5:Instances!AG5),"median", MEDIAN(Instances!AG5:Instances!AG5),"min", MIN(Instances!AG5:Instances!AG5),"max", MAX(Instances!AG5:Instances!AG5),"diff", MAX(Instances!AG5:Instances!AG5)-MIN(Instances!AG5:Instances!AG5))} -> 0 | AI5: {=_xlfn.SWITCH($A$2,"average", AVERAGE(Instances!AI5:Instances!AI5),"median", MEDIAN(Instances!AI5:Instances!AI5),"min", MIN(Instances!AI5:Instances!AI5),"max", MAX(Instances!AI5:Instances!AI5),"diff", MAX(Instances!AI5:Instances!AI5)-MIN(Instances!AI5:Instances!AI5))} -> 0 | AJ5: {=_xlfn.SWITCH($A$2,"average", AVERAGE(Instances!AJ5:Instances!AJ5),"median", MEDIAN(Instances!AJ5:Instances!AJ5),"min", MIN(Instances!AJ5:Instances!AJ5),"max", MAX(Instances!AJ5:Instances!AJ5),"diff", MAX(Instances!AJ5:Instances!AJ5)-MIN(Instances!AJ5:Instances!AJ5))} -> 0 | AK5: {=_xlfn.SWITCH($A$2,"average", AVERAGE(Instances!AK5:Instances!AK5),"median", MEDIAN(Instances!AK5:Instances!AK5),"min", MIN(Instances!AK5:Instances!AK5),"max", MAX(Instances!AK5:Instances!AK5),"diff", MAX(Instances!AK5:Instances!AK5)-MIN(Instances!AK5:Instances!AK5))} -> 0 | AL5: =MIN($B5,$H5,$N5,$T5,$Z5,$AF5) -> 0 | AM5: =MIN($C5,$I5,$O5,$U5,$AA5,$AG5) -> 0 | AN5: =MIN($E5,$K5,$Q5,$W5,$AC5,$AI5) -> 0 | AO5: =MIN($F5,$L5,$R5,$X5,$AD5,$AJ5) -> 0 | AP5: =MIN($G5,$M5,$S5,$Y5,$AE5,$AK5) -> 0 | AQ5: =MEDIAN($B5,$H5,$N5,$T5,$Z5,$AF5) -> 0 | AR5: =MEDIAN($C5,$I5,$O5,$U5,$AA5,$AG5) -> 0 | AS5: =MEDIAN($E5,$K5,$Q5,$W5,$AC5,$AI5) -> 0 | AT5: =MEDIAN($F5,$L5,$R5,$X5,$AD5,$AJ5) -> 0 | AU5: =MEDIAN($G5,$M5,$S5,$Y5,$AE5,$AK5) -> 0 | AV5: =MAX($B5,$H5,$N5,$T5,$Z5,$AF5) -> 0 | AW5: =MAX($C5,$I5,$O5,$U5,$AA5,$AG5) -> 0 | AX5: =MAX($E5,$K5,$Q5,$W5,$AC5,$AI5) -> 0 | AY5: =MAX($F5,$L5,$R5,$X5,$AD5,$AJ5) -> 0 | AZ5: =MAX($G5,$M5,$S5,$Y5,$AE5,$AK5) -> 0
A6: instances/size-7 | B6: {=_xlfn.SWITCH($A$2,"average", AVERAGE(Instances!B6:Instances!B6),"median", MEDIAN(Instances!B6:Instances!B6),"min", MIN(Instances!B6:Instances!B6),"max", MAX(Instances!B6:Instances!B6),"diff", MAX(Instances!B6:Instances!B6)-MIN(Instances!B6:Instances!B6))} -> 0 | C6: {=_xlfn.SWITCH($A$2,"average", AVERAGE(Instances!C6:Instances!C6),"median", MEDIAN(Instances!C6:Instances!C6),"min", MIN(Instances!C6:Instances!C6),"max", MAX(Instances!C6:Instances!C6),"diff", MAX(Instances!C6:Instances!C6)-MIN(Instances!C6:Instances!C6))} -> 0 | E6: {=_xlfn.SWITCH($A$2,"average", AVERAGE(Instances!E6:Instances!E6),"median", MEDIAN(Instances!E6:Instances!E6),"min", MIN(Instances!E6:Instances!E6),"max", MAX(Instances!E6:Instances!E6),"diff", MAX(Instances!E6:Instances!E6)-MIN(Instances!E6:Instances!E6))} -> 0 | F6: {=_xlfn.SWITCH($A$2,"average", AVERAGE(Instances!F6:Instances!F6),"median", MEDIAN(Instances!F6:Instances!F6),"min", MIN(Instances!F6:Instances!F6),"max", MAX(Instances!F6:Instances!F6),"diff", MAX(Instances!F6:Instances!F6)-MIN(Instances!F6:Instances!F6))} -> 0 | G6: {=_xlfn.SWITCH($A$2,"average", AVERAGE(Instances!G6:Instances!G6),"median", MEDIAN(Instances!G6:Instances!G6),"min", MIN(Instances!G6:Instances!G6),"max", MAX(Instances!G6:Instances!G6),"diff", MAX(Instances!G6:Instances!G6)-MIN(Instances!G6:Instances!G6))} -> 0 | H6: {=_xlfn.SWITCH($A$2,"average", AVERAGE(Instances!H6:Instances!H6),"median", MEDIAN(Instances!H6:Instances!H6),"min", MIN(Instances!H6:Instances!H6),"max", MAX(Instances!H6:Instances!H6),"diff", MAX(Instances!H6:Instances!H6)-MIN(Instances!H6:Instances!H6))} -> 0 | I6: {=_xlfn.SWITCH($A$2,"average", AVERAGE(Instances!I6:Instances!I6),"median", MEDIAN(Instances!I6:Instances!I6),"min", MIN(Instances!I6:Instances!I6),"max", MAX(Instances!I6:Instances!I6),"diff", MAX(Instances!I6:Instances!I6)-MIN(Instances!I6:Instances!I6))} -> 0 | K6: {=_xlfn.SWITCH($A$2,"average", AVERAGE(Instances!K6:Instances!K6),"median", MEDIAN(Instances!K6:Instances!K6),"min", MIN(Instances!K6:Instances!K6),"max", MAX(Instances!K6:Instances!K6),"diff", MAX(Instances!K6:Instances!K6)-MIN(Instances!K6:Instances!K6))} -> 0 | L6: {=_xlfn.SWITCH($A$2,"average", AVERAGE(Instances!L6:Instances!L6),"median", MEDIAN(Instances!L6:Instances!L6),"min", MIN(Instances!L6:Instances!L6),"max", MAX(Instances!L6:Instances!L6),"diff", MAX(Instances!L6:Instances!L6)-MIN(Instances!L6:Instances!L6))} -> 0 | M6: {=_xlfn.SWITCH($A$2,"average", AVERAGE(Instances!M6:Instances!M6),"median", MEDIAN(Instances!M6:Instances!M6),"min", MIN(Instances!M6:Instances!M6),"max", MAX(Instances!M6:Instances!M6),"diff", MAX(Instances!M6:Instances!M6)-MIN(Instances!M6:Instances!M6))} -> 0 | N6: {=_xlfn.SWITCH($A$2,"average", AVERAGE(Instances!N6:Instances!N6),"median", MEDIAN(Instances!N6:Instances!N6),"min", MIN(Instances!N6:Instances!N6),"max", MAX(Instances!N6:Instances!N6),"diff", MAX(Instances!N6:Instances!N6)-MIN(Instances!N6:Instances!N6))} -> 0 | O6: {=_xlfn.SWITCH($A$2,"average", AVERAGE(Instances!O6:Instances!O6),"median", MEDIAN(Instances!O6:Instances!O6),"min", MIN(Instances!O6:Instances!O6),"max", MAX(Instances!O6:Instances!O6),"diff", MAX(Instances!O6:Instances!O6)-MIN(Instances!O6:Instances!O6))} -> 0 | Q6: {=_xlfn.SWITCH($A$2,"average", AVERAGE(Instances!Q6:Instances!Q6),"median", MEDIAN(Instances!Q6:Instances!Q6),"min", MIN(Instances!Q6:Instances!Q6),"max", MAX(Instances!Q6:Instances!Q6),"diff", MAX(Instances!Q6:Instances!Q6)-MIN(Instances!Q6:Instances!Q6))} -> 0 | R6: {=_xlfn.SWITCH($A$2,"average", AVERAGE(Instances!R6:Instances!R6),"median", MEDIAN(Instances!R6:Instances!R6),"min", MIN(Instances!R6:Instances!R6),"max", MAX(Instances!R6:Instances!R6),"diff", MAX(Instances!R6:Instances!R6)-MIN(Instances!R6:Instances!R6))} -> 0 | S6: {=_xlfn.SWITCH($A$2,"average", AVERAGE(Instances!S6:Instances!S6),"median", MEDIAN(Instances!S6:Instances!S6),"min", MIN(Instances!S6:Instances!S6),"max", MAX(Instances!S6:Instances!S6),"diff", MAX(Instances!S6:Instances!S6)-MIN(Instances!S6:Instances!S6))} -> 0 | T6: {=_xlfn.SWITCH($A$2,"average", AVERAGE(Instances!T6:Instances!T6),"median", MEDIAN(Instances!T6:Instances!T6),"min", MIN(Instances!T6:Instances!T6),"max", MAX(Instances!T6:Instances!T6),"diff", MAX(Instances!T6:Instances!T6)-MIN(Instances!T6:Instances!T6))} -> 0 | U6: {=_xlfn.SWITCH($A$2,"average", AVERAGE(Instances!U6:Instances!U6),"median", MEDIAN(Instances!U6:Instances!U6),"min", MIN(Instances!U6:Instances!U6),"max", MAX(Instances!U6:Instances!U6),"diff", MAX(Instances!U6:Instances!U6)-MIN(Instances!U6:Instances!U6))} -> 0 | W6: {=_xlfn.SWITCH($A$2,"average", AVERAGE(Instances!W6:Instances!W6),"median", MEDIAN(Instances!W6:Instances!W6),"min", MIN(Instances!W6:Instances!W6),"max", MAX(Instances!W6:Instances!W6),"diff", MAX(Instances!W6:Instances!W6)-MIN(Instances!W6:Instances!W6))} -> 0 | X6: {=_xlfn.SWITCH($A$2,"average", AVERAGE(Instances!X6:Instances!X6),"median", MEDIAN(Instances!X6:Instances!X6),"min", MIN(Instances!X6:Instances!X6),"max", MAX(Instances!X6:Instances!X6),"diff", MAX(Instances!X6:Instances!X6)-MIN(Instances!X6:Instances!X6))} -> 0 | Y6: {=_xlfn.SWITCH($A$2,"average", AVERAGE(Instances!Y6:Instances!Y6),"median", MEDIAN(Instances!Y6:Instances!Y6),"min", MIN(Instances!Y6:Instances!Y6),"max", MAX(Instances!Y6:Instances!Y6),"diff", MAX(Instances!Y6:Instances!Y6)-MIN(Instances!Y6:Instances!Y6))} -> 0 | Z6: {=_xlfn.SWITCH($A$2,"average", AVERAGE(Instances!Z6:Instances!Z6),"median", MEDIAN(Instances!Z6:Instances!Z6),"min", MIN(Instances!Z6:Instances!Z6),"max", MAX(Instances!Z6:Instances!Z6),"diff", MAX(Instances!Z6:Instances!Z6)-MIN(Instances!Z6:Instances!Z6))} -> 0 | AA6: {=_xlfn.SWITCH($A$2,"average", AVERAGE(Instances!AA6:Instances!AA6),"median", MEDIAN(Instances!AA6:Instances!AA6),"min", MIN(Instances!AA6:Instances!AA6),"max", MAX(Instances!AA6:Instances!AA6),"diff", MAX(Instances!AA6:Instances!AA6)-MIN(Instances!AA6:Instances!AA6))} -> 0 | AC6: {=_xlfn.SWITCH($A$2,"average", AVERAGE(Instances!AC6:Instances!AC6),"median", MEDIAN(Instances!AC6:Instances!AC6),"min", MIN(Instances!AC6:Instances!AC6),"max", MAX(Instances!AC6:Instances!AC6),"diff", MAX(Instances!AC6:Instances!AC6)-MIN(Instances!AC6:Instances!AC6))} -> 0 | AD6: {=_xlfn.SWITCH($A$2,"average", AVERAGE(Instances!AD6:Instances!AD6),"median", MEDIAN(Instances!AD6:Instances!AD6),"min", MIN(Instances!AD6:Instances!AD6),"max", MAX(Instances!AD6:Instances!AD6),"diff", MAX(Instances!AD6:Instances!AD6)-MIN(Instances!AD6:Instances!AD6))} -> 0 | AE6: {=_xlfn.SWITCH($A$2,"average", AVERAGE(Instances!AE6:Instances!AE6),"median", MEDIAN(Instances!AE6:Instances!AE6),"min", MIN(Instances!AE6:Instances!AE6),"max", MAX(Instances!AE6:Instances!AE6),"diff", MAX(Instances!AE6:Instances!AE6)-MIN(Instances!AE6:Instances!AE6))} -> 0 | AF6: {=_xlfn.SWITCH($A$2,"average", AVERAGE(Instances!AF6:Instances!AF6),"median", MEDIAN(Instances!AF6:Instances!AF6),"min", MIN(Instances!AF6:Instances!AF6),"max", MAX(Instances!AF6:Instances!AF6),"diff", MAX(Instances!AF6:Instances!AF6)-MIN(Instances!AF6:Instances!AF6))} -> 0 | AG6: {=_xlfn.SWITCH($A$2,"average", AVERAGE(Instances!AG6:Instances!AG6),"median", MEDIAN(Instances!AG6:Instances!AG6),"min", MIN(Instances!AG6:Instances!AG6),"max", MAX(Instances!AG6:Instances!AG6),"diff", MAX(Instances!AG6:Instances!AG6)-MIN(Instances!AG6:Instances!AG6))} -> 0 | AI6: {=_xlfn.SWITCH($A$2,"average", AVERAGE(Instances!AI6:Instances!AI6),"median", MEDIAN(Instances!AI6:Instances!AI6),"min", MIN(Instances!AI6:Instances!AI6),"max", MAX(Instances!AI6:Instances!AI6),"diff", MAX(Instances!AI6:Instances!AI6)-MIN(Instances!AI6:Instances!AI6))} -> 0 | AJ6: {=_xlfn.SWITCH($A$2,"average", AVERAGE(Instances!AJ6:Instances!AJ6),"median", MEDIAN(Instances!AJ6:Instances!AJ6),"min", MIN(Instances!AJ6:Instances!AJ6),"max", MAX(Instances!AJ6:Instances!AJ6),"diff", MAX(Instances!AJ6:Instances!AJ6)-MIN(Instances!AJ6:Instances!AJ6))} -> 0 | AK6: {=_xlfn.SWITCH($A$2,"average", AVERAGE(Instances!AK6:Instances!AK6),"median", MEDIAN(Instances!AK6:Instances!AK6),"min", MIN(Instances!AK6:Instances!AK6),"max", MAX(Instances!AK6:Instances!AK6),"diff", MAX(Instances!AK6:Instances!AK6)-MIN(Instances!AK6:Instances!AK6))} -> 0 | AL6: =MIN($B6,$H6,$N6,$T6,$Z6,$AF6) -> 0 | AM6: =MIN($C6,$I6,$O6,$U6,$AA6,$AG6) -> 0 | AN6: =MIN($E6,$K6,$Q6,$W6,$AC6,$AI6) -> 0 | AO6: =MIN($F6,$L6,$R6,$X6,$AD6,$AJ6) -> 0 | AP6: =MIN($G6,$M6,$S6,$Y6,$AE6,$AK6) -> 0 | AQ6: =MEDIAN($B6,$H6,$N6,$T6,$Z6,$AF6) -> 0 | AR6: =MEDIAN($C6,$I6,$O6,$U6,$AA6,$AG6) -> 0 | AS6: =MEDIAN($E6,$K6,$Q6,$W6,$AC6,$AI6) -> 0 | AT6: =MEDIAN($F6,$L6,$R6,$X6,$AD6,$AJ6) -> 0 | AU6: =MEDIAN($G6,$M6,$S6,$Y6,$AE6,$AK6) -> 0 | AV6: =MAX($B6,$H6,$N6,$T6,$Z6,$AF6) -> 0 | AW6: =MAX($C6,$I6,$O6,$U6,$AA6,$AG6) -> 0 | AX6: =MAX($E6,$K6,$Q6,$W6,$AC6,$AI6) -> 0 | AY6: =MAX($F6,$L6,$R6,$X6,$AD6,$AJ6) -> 0 | AZ6: =MAX($G6,$M6,$S6,$Y6,$AE6,$AK6) -> 0
A8: SUM | B8: =SUM(B$3:B$6) -> 0 | C8: =SUM(C$3:C$6) -> 0 | E8: =SUM(E$3:E$6) -> 0 | F8: =SUM(F$3:F$6) -> 0 | G8: =SUM(G$3:G$6) -> 0 | H8: =SUM(H$3:H$6) -> 0 | I8: =SUM(I$3:I$6) -> 0 | K8: =SUM(K$3:K$6) -> 0 | L8: =SUM(L$3:L$6) -> 0 | M8: =SUM(M$3:M$6) -> 0 | N8: =SUM(N$3:N$6) -> 0 | O8: =SUM(O$3:O$6) -> 0 | Q8: =SUM(Q$3:Q$6) -> 0 | R8: =SUM(R$3:R$6) -> 0 | S8: =SUM(S$3:S$6) -> 0 | T8: =SUM(T$3:T$6) -> 0 | U8: =SUM(U$3:U$6) -> 0 | W8: =SUM(W$3:W$6) -> 0 | X8: =SUM(X$3:X$6) -> 0 | Y8: =SUM(Y$3:Y$6) -> 0 | Z8: =SUM(Z$3:Z$6) -> 0 | AA8: =SUM(AA$3:AA$6) -> 0 | AC8: =SUM(AC$3:AC$6) -> 0 | AD8: =SUM(AD$3:AD$6) -> 0 | AE8: =SUM(AE$3:AE$6) -> 0 | AF8: =SUM(AF$3:AF$6) -> 0 | AG8: =SUM(AG$3:AG$6) -> 0 | AI8: =SUM(AI$3:AI$6) -> 0 | AJ8: =SUM(AJ$3:AJ$6) -> 0 | AK8: =SUM(AK$3:AK$6) -> 0 | AL8: =SUM(AL$3:AL$6) -> 0 | AM8: =SUM(AM$3:AM$6) -> 0 | AN8: =SUM(AN$3:AN$6) -> 0 | AO8: =SUM(AO$3:AO$6) -> 0 | AP8: =SUM(AP$3:AP$6) -> 0 | ... AZ8: =SUM(AZ$3:AZ$6) -> 0
A9: AVG | B9: =AVERAGE(B$3:B$6) -> 0 | C9: =AVERAGE(C$3:C$6) -> 0 | E9: =AVERAGE(E$3:E$6) -> 0 | F9: =AVERAGE(F$3:F$6) -> 0 | G9: =AVERAGE(G$3:G$6) -> 0 | H9: =AVERAGE(H$3:H$6) -> 0 | I9: =AVERAGE(I$3:I$6) -> 0 | K9: =AVERAGE(K$3:K$6) -> 0 | L9: =AVERAGE(L$3:L$6) -> 0 | M9: =AVERAGE(M$3:M$6) -> 0 | N9: =AVERAGE(N$3:N$6) -> 0 | O9: =AVERAGE(O$3:O$6) -> 0 | Q9: =AVERAGE(Q$3:Q$6) -> 0 | R9: =AVERAGE(R$3:R$6) -> 0 | S9: =AVERAGE(S$3:S$6) -> 0 | T9: =AVERAGE(T$3:T$6) -> 0 | U9: =AVERAGE(U$3:U$6) -> 0 | W9: =AVERAGE(W$3:W$6) -> 0 | X9: =AVERAGE(X$3:X$6) -> 0 | Y9: =AVERAGE(Y$3:Y$6) -> 0 | Z9: =AVERAGE(Z$3:Z$6) -> 0 | AA9: =AVERAGE(AA$3:AA$6) -> 0 | AC9: =AVERAGE(AC$3:AC$6) -> 0 | AD9: =AVERAGE(AD$3:AD$6) -> 0 | AE9: =AVERAGE(AE$3:AE$6) -> 0 | AF9: =AVERAGE(AF$3:AF$6) -> 0 | AG9: =AVERAGE(AG$3:AG$6) -> 0 | AI9: =AVERAGE(AI$3:AI$6) -> 0 | AJ9: =AVERAGE(AJ$3:AJ$6) -> 0 | AK9: =AVERAGE(AK$3:AK$6) -> 0 | AL9: =AVERAGE(AL$3:AL$6) -> 0 | AM9: =AVERAGE(AM$3:AM$6) -> 0 | AN9: =AVERAGE(AN$3:AN$6) -> 0 | AO9: =AVERAGE(AO$3:AO$6) -> 0 | AP9: =AVERAGE(AP$3:AP$6) -> 0 | ... AZ9: =AVERAGE(AZ$3:AZ$6) -> 0
A10: DEV | B10: =STDEV(B$3:B$6) -> 0 | C10: =STDEV(C$3:C$6) -> 0 | E10: =STDEV(E$3:E$6) -> 0 | F10: =STDEV(F$3:F$6) -> 0 | G10: =STDEV(G$3:G$6) -> 0 | H10: =STDEV(H$3:H$6) -> 0 | I10: =STDEV(I$3:I$6) -> 0 | K10: =STDEV(K$3:K$6) -> 0 | L10: =STDEV(L$3:L$6) -> 0 | M10: =STDEV(M$3:M$6) -> 0 | N10: =STDEV(N$3:N$6) -> 0 | O10: =STDEV(O$3:O$6) -> 0 | Q10: =STDEV(Q$3:Q$6) -> 0 | R10: =STDEV(R$3:R$6) -> 0 | S10: =STDEV(S$3:S$6) -> 0 | T10: =STDEV(T$3:T$6) -> 0 | U10: =STDEV(U$3:U$6) -> 0 | W10: =STDEV(W$3:W$6) -> 0 | X10: =STDEV(X$3:X$6) -> 0 | Y10: =STDEV(Y$3:Y$6) -> 0 | Z10: =STDEV(Z$3:Z$6) -> 0 | AA10: =STDEV(AA$3:AA$6) -> 0 | AC10: =STDEV(AC$3:AC$6) -> 0 | AD10: =STDEV(AD$3:AD$6) -> 0 | AE10: =STDEV(AE$3:AE$6) -> 0 | AF10: =STDEV(AF$3:AF$6) -> 0 | AG10: =STDEV(AG$3:AG$6) -> 0 | AI10: =STDEV(AI$3:AI$6) -> 0 | AJ10: =STDEV(AJ$3:AJ$6) -> 0 | AK10: =STDEV(AK$3:AK$6) -> 0 | AL10: =STDEV(AL$3:AL$6) -> 0 | AM10: =STDEV(AM$3:AM$6) -> 0 | AN10: =STDEV(AN$3:AN$6) -> 0 | AO10: =STDEV(AO$3:AO$6) -> 0 | AP10: =STDEV(AP$3:AP$6) -> 0 | ... AZ10: =STDEV(AZ$3:AZ$6) -> 0
A11: DST | B11: =SUMPRODUCT(--(B$3:B$6-$AL$3:$AL$6)^2)^0.5 -> 0 | C11: =SUMPRODUCT(--(C$3:C$6-$AM$3:$AM$6)^2)^0.5 -> 0 | E11: =SUMPRODUCT(--(E$3:E$6-$AN$3:$AN$6)^2)^0.5 -> 0 | F11: =SUMPRODUCT(--(F$3:F$6-$AO$3:$AO$6)^2)^0.5 -> 0 | G11: =SUMPRODUCT(--(G$3:G$6-$AP$3:$AP$6)^2)^0.5 -> 0 | H11: =SUMPRODUCT(--(H$3:H$6-$AL$3:$AL$6)^2)^0.5 -> 0 | I11: =SUMPRODUCT(--(I$3:I$6-$AM$3:$AM$6)^2)^0.5 -> 0 | K11: =SUMPRODUCT(--(K$3:K$6-$AN$3:$AN$6)^2)^0.5 -> 0 | L11: =SUMPRODUCT(--(L$3:L$6-$AO$3:$AO$6)^2)^0.5 -> 0 | M11: =SUMPRODUCT(--(M$3:M$6-$AP$3:$AP$6)^2)^0.5 -> 0 | N11: =SUMPRODUCT(--(N$3:N$6-$AL$3:$AL$6)^2)^0.5 -> 0 | O11: =SUMPRODUCT(--(O$3:O$6-$AM$3:$AM$6)^2)^0.5 -> 0 | Q11: =SUMPRODUCT(--(Q$3:Q$6-$AN$3:$AN$6)^2)^0.5 -> 0 | R11: =SUMPRODUCT(--(R$3:R$6-$AO$3:$AO$6)^2)^0.5 -> 0 | S11: =SUMPRODUCT(--(S$3:S$6-$AP$3:$AP$6)^2)^0.5 -> 0 | T11: =SUMPRODUCT(--(T$3:T$6-$AL$3:$AL$6)^2)^0.5 -> 0 | U11: =SUMPRODUCT(--(U$3:U$6-$AM$3:$AM$6)^2)^0.5 -> 0 | W11: =SUMPRODUCT(--(W$3:W$6-$AN$3:$AN$6)^2)^0.5 -> 0 | X11: =SUMPRODUCT(--(X$3:X$6-$AO$3:$AO$6)^2)^0.5 -> 0 | Y11: =SUMPRODUCT(--(Y$3:Y$6-$AP$3:$AP$6)^2)^0.5 -> 0 | Z11: =SUMPRODUCT(--(Z$3:Z$6-$AL$3:$AL$6)^2)^0.5 -> 0 | AA11: =SUMPRODUCT(--(AA$3:AA$6-$AM$3:$AM$6)^2)^0.5 -> 0 | AC11: =SUMPRODUCT(--(AC$3:AC$6-$AN$3:$AN$6)^2)^0.5 -> 0 | AD11: =SUMPRODUCT(--(AD$3:AD$6-$AO$3:$AO$6)^2)^0.5 -> 0 | AE11: =SUMPRODUCT(--(AE$3:AE$6-$AP$3:$AP$6)^2)^0.5 -> 0 | AF11: =SUMPRODUCT(--(AF$3:AF$6-$AL$3:$AL$6)^2)^0.5 -> 0 | AG11: =SUMPRODUCT(--(AG$3:AG$6-$AM$3:$AM$6)^2)^0.5 -> 0 | AI11: =SUMPRODUCT(--(AI$3:AI$6-$AN$3:$AN$6)^2)^0.5 -> 0 | AJ11: =SUMPRODUCT(--(AJ$3:AJ$6-$AO$3:$AO$6)^2)^0.5 -> 0 | AK11: =SUMPRODUCT(--(AK$3:AK$6-$AP$3:$AP$6)^2)^0.5 -> 0
