Workbook

Sheet Instances
B1: memelingo-1/all-opts_mlp-tplp-ht_15_100 | I1: memelingo-1/all-opts_mlp-tplp-ht_15_150 | P1: memelingo-1/all-opts_mlp-tplp-ht_15_30 | W1: memelingo-1/all-opts_mlp-tplp-ht_15_50 | AD1: memelingo-1/all-opts_mlp-tplp-ht_20_100 | AK1: memelingo-1/all-opts_mlp-tplp-ht_20_150 | AR1: memelingo-1/all-opts_mlp-tplp-ht_20_30 | AY1: memelingo-1/all-opts_mlp-tplp-ht_20_50 | BF1: memelingo-1/all-opts_mlp-tplp-ht_25_100 | BM1: memelingo-1/all-opts_mlp-tplp-ht_25_150 | BT1: memelingo-1/all-opts_mlp-tplp-ht_25_30 | CA1: memelingo-1/all-opts_mlp-tplp-ht_25_50 | CH1: memelingo-1/all-opts_mlp-tplp-ht_30_100 | CO1: memelingo-1/all-opts_mlp-tplp-ht_30_150 | CV1: memelingo-1/all-opts_mlp-tplp-ht_30_30 | DC1: memelingo-1/all-opts_mlp-tplp-ht_30_50 | DJ1: memelingo-1/all-opts_mlp-tplp-ht_35_100 | DQ1: memelingo-1/all-opts_mlp-tplp-ht_35_150 | DX1: memelingo-1/all-opts_mlp-tplp-ht_35_30 | EE1: memelingo-1/all-opts_mlp-tplp-ht_35_50 | EL1: memelingo-1/all-opts_mlp-tplp-ht_40_100 | ES1: memelingo-1/all-opts_mlp-tplp-ht_40_150 | EZ1: memelingo-1/all-opts_mlp-tplp-ht_40_30 | FG1: memelingo-1/all-opts_mlp-tplp-ht_40_50 | FN1: memelingo-1/all-opts_mlp-tplp-ht_45_100 | FU1: memelingo-1/all-opts_mlp-tplp-ht_45_150 | GB1: memelingo-1/all-opts_mlp-tplp-ht_45_30 | GI1: memelingo-1/all-opts_mlp-tplp-ht_45_50 | GP1: memelingo-1/all-opts_mlp-tplp-htc_15_100 | GW1: memelingo-1/all-opts_mlp-tplp-htc_15_150 | HD1: memelingo-1/all-opts_mlp-tplp-htc_15_30 | HK1: memelingo-1/all-opts_mlp-tplp-htc_15_50 | HR1: memelingo-1/all-opts_mlp-tplp-htc_20_100 | HY1: memelingo-1/all-opts_mlp-tplp-htc_20_150 | IF1: memelingo-1/all-opts_mlp-tplp-htc_20_30 | IM1: memelingo-1/all-opts_mlp-tplp-htc_20_50 | IT1: memelingo-1/all-opts_mlp-tplp-htc_25_100 | JA1: memelingo-1/all-opts_mlp-tplp-htc_25_150 | JH1: memelingo-1/all-opts_mlp-tplp-htc_25_30 | JO1: memelingo-1/all-opts_mlp-tplp-htc_25_50 | JV1: memelingo-1/all-opts_mlp-tplp-htc_30_100 | KC1: memelingo-1/all-opts_mlp-tplp-htc_30_150 | KJ1: memelingo-1/all-opts_mlp-tplp-htc_30_30 | KQ1: memelingo-1/all-opts_mlp-tplp-htc_30_50 | KX1: memelingo-1/all-opts_mlp-tplp-htc_35_100 | LE1: memelingo-1/all-opts_mlp-tplp-htc_35_150 | LL1: memelingo-1/all-opts_mlp-tplp-htc_35_30 | LS1: memelingo-1/all-opts_mlp-tplp-htc_35_50 | LZ1: memelingo-1/all-opts_mlp-tplp-htc_40_100 | MG1: memelingo-1/all-opts_mlp-tplp-htc_40_150 | MN1: memelingo-1/all-opts_mlp-tplp-htc_40_30 | MU1: memelingo-1/all-opts_mlp-tplp-htc_40_50 | NB1: memelingo-1/all-opts_mlp-tplp-htc_45_100 | NI1: memelingo-1/all-opts_mlp-tplp-htc_45_150 | NP1: memelingo-1/all-opts_mlp-tplp-htc_45_30 | NW1: memelingo-1/all-opts_mlp-tplp-htc_45_50 | OD1: memelingo-1/all-opts_mlp-tplp-htcdl_15_100 | OK1: memelingo-1/all-opts_mlp-tplp-htcdl_15_150 | OR1: memelingo-1/all-opts_mlp-tplp-htcdl_15_30 | OY1: memelingo-1/all-opts_mlp-tplp-htcdl_15_50 | PF1: memelingo-1/all-opts_mlp-tplp-htcdl_20_100 | PM1: memelingo-1/all-opts_mlp-tplp-htcdl_20_150 | PT1: memelingo-1/all-opts_mlp-tplp-htcdl_20_30 | QA1: memelingo-1/all-opts_mlp-tplp-htcdl_20_50 | QH1: memelingo-1/all-opts_mlp-tplp-htcdl_25_100 | QO1: memelingo-1/all-opts_mlp-tplp-htcdl_25_150 | QV1: memelingo-1/all-opts_mlp-tplp-htcdl_25_30 | RC1: memelingo-1/all-opts_mlp-tplp-htcdl_25_50 | RJ1: memelingo-1/all-opts_mlp-tplp-htcdl_30_100 | RQ1: memelingo-1/all-opts_mlp-tplp-htcdl_30_150 | RX1: memelingo-1/all-opts_mlp-tplp-htcdl_30_30 | SE1: memelingo-1/all-opts_mlp-tplp-htcdl_30_50 | SL1: memelingo-1/all-opts_mlp-tplp-htcdl_35_100 | SS1: memelingo-1/all-opts_mlp-tplp-htcdl_35_150 | SZ1: memelingo-1/all-opts_mlp-tplp-htcdl_35_30 | TG1: memelingo-1/all-opts_mlp-tplp-htcdl_35_50 | TN1: memelingo-1/all-opts_mlp-tplp-htcdl_40_100 | TU1: memelingo-1/all-opts_mlp-tplp-htcdl_40_150 | UB1: memelingo-1/all-opts_mlp-tplp-htcdl_40_30 | UI1: memelingo-1/all-opts_mlp-tplp-htcdl_40_50 | UP1: memelingo-1/all-opts_mlp-tplp-htcdl_45_100 | UW1: memelingo-1/all-opts_mlp-tplp-htcdl_45_150 | VD1: memelingo-1/all-opts_mlp-tplp-htcdl_45_30 | VK1: memelingo-1/all-opts_mlp-tplp-htcdl_45_50 | VR1: min | VX1: median | WD1: max
B2: time | C2: stime | D2: status | E2: rules | F2: ctime | G2: fmtime | H2: memout | I2: time | J2: stime | K2: status | L2: rules | M2: ctime | N2: fmtime | O2: memout | P2: time | Q2: stime | R2: status | S2: rules | T2: ctime | U2: fmtime | V2: memout | W2: time | X2: stime | Y2: status | Z2: rules | AA2: ctime | AB2: fmtime | AC2: memout | AD2: time | AE2: stime | AF2: status | AG2: rules | AH2: ctime | AI2: fmtime | AJ2: memout | AK2: time | AL2: stime | AM2: status | AN2: rules | AO2: ctime | AP2: fmtime | AQ2: memout | AR2: time | AS2: stime | AT2: status | AU2: rules | AV2: ctime | AW2: fmtime | AX2: memout | AY2: time | AZ2: stime | BA2: status | BB2: rules | BC2: ctime | BD2: fmtime | BE2: memout | BF2: time | BG2: stime | BH2: status | BI2: rules | BJ2: ctime | BK2: fmtime | BL2: memout | BM2: time | BN2: stime | BO2: status | BP2: rules | BQ2: ctime | BR2: fmtime | BS2: memout | BT2: time | BU2: stime | BV2: status | BW2: rules | BX2: ctime | BY2: fmtime | BZ2: memout | CA2: time | CB2: stime | CC2: status | CD2: rules | CE2: ctime | CF2: fmtime | CG2: memout | CH2: time | CI2: stime | CJ2: status | CK2: rules | CL2: ctime | CM2: fmtime | CN2: memout | CO2: time | CP2: stime | CQ2: status | CR2: rules | CS2: ctime | CT2: fmtime | CU2: memout | CV2: time | CW2: stime | CX2: status | CY2: rules | CZ2: ctime | DA2: fmtime | DB2: memout | DC2: time | DD2: stime | DE2: status | DF2: rules | DG2: ctime | DH2: fmtime | DI2: memout | DJ2: time | DK2: stime | DL2: status | DM2: rules | DN2: ctime | DO2: fmtime | DP2: memout | DQ2: time | DR2: stime | DS2: status | DT2: rules | DU2: ctime | DV2: fmtime | DW2: memout | DX2: time | DY2: stime | DZ2: status | EA2: rules | EB2: ctime | EC2: fmtime | ED2: memout | EE2: time | EF2: stime | EG2: status | EH2: rules | EI2: ctime | EJ2: fmtime | EK2: memout | EL2: time | EM2: stime | EN2: status | EO2: rules | EP2: ctime | EQ2: fmtime | ER2: memout | ES2: time | ET2: stime | EU2: status | EV2: rules | EW2: ctime | EX2: fmtime | EY2: memout | EZ2: time | FA2: stime | FB2: status | FC2: rules | FD2: ctime | FE2: fmtime | FF2: memout | FG2: time | FH2: stime | FI2: status | FJ2: rules | FK2: ctime | FL2: fmtime | FM2: memout | FN2: time | FO2: stime | FP2: status | FQ2: rules | FR2: ctime | FS2: fmtime | FT2: memout | FU2: time | FV2: stime | FW2: status | FX2: rules | FY2: ctime | FZ2: fmtime | GA2: memout | GB2: time | GC2: stime | GD2: status | GE2: rules | GF2: ctime | GG2: fmtime | GH2: memout | GI2: time | GJ2: stime | GK2: status | GL2: rules | GM2: ctime | GN2: fmtime | GO2: memout | GP2: time | GQ2: stime | GR2: status | GS2: rules | GT2: ctime | GU2: fmtime | GV2: memout | GW2: time | GX2: stime | GY2: status | GZ2: rules | HA2: ctime | HB2: fmtime | HC2: memout | HD2: time | HE2: stime | HF2: status | HG2: rules | HH2: ctime | HI2: fmtime | HJ2: memout | HK2: time | HL2: stime | HM2: status | HN2: rules | HO2: ctime | HP2: fmtime | HQ2: memout | HR2: time | HS2: stime | HT2: status | HU2: rules | HV2: ctime | HW2: fmtime | HX2: memout | HY2: time | HZ2: stime | IA2: status | IB2: rules | IC2: ctime | ID2: fmtime | IE2: memout | IF2: time | IG2: stime | IH2: status | II2: rules | IJ2: ctime | IK2: fmtime | IL2: memout | IM2: time | IN2: stime | IO2: status | IP2: rules | IQ2: ctime | IR2: fmtime | IS2: memout | IT2: time | IU2: stime | IV2: status | IW2: rules | IX2: ctime | IY2: fmtime | IZ2: memout | JA2: time | JB2: stime | JC2: status | JD2: rules | JE2: ctime | JF2: fmtime | JG2: memout | JH2: time | JI2: stime | JJ2: status | JK2: rules | JL2: ctime | JM2: fmtime | JN2: memout | JO2: time | JP2: stime | JQ2: status | JR2: rules | JS2: ctime | JT2: fmtime | JU2: memout | JV2: time | JW2: stime | JX2: status | JY2: rules | JZ2: ctime | KA2: fmtime | KB2: memout | KC2: time | KD2: stime | KE2: status | KF2: rules | KG2: ctime | KH2: fmtime | KI2: memout | KJ2: time | KK2: stime | KL2: status | KM2: rules | KN2: ctime | KO2: fmtime | KP2: memout | KQ2: time | KR2: stime | KS2: status | KT2: rules | KU2: ctime | KV2: fmtime | KW2: memout | KX2: time | KY2: stime | KZ2: status | LA2: rules | LB2: ctime | LC2: fmtime | LD2: memout | LE2: time | LF2: stime | LG2: status | LH2: rules | LI2: ctime | LJ2: fmtime | LK2: memout | LL2: time | LM2: stime | LN2: status | LO2: rules | LP2: ctime | LQ2: fmtime | LR2: memout | LS2: time | LT2: stime | LU2: status | LV2: rules | LW2: ctime | LX2: fmtime | LY2: memout | LZ2: time | MA2: stime | MB2: status | MC2: rules | MD2: ctime | ME2: fmtime | MF2: memout | MG2: time | MH2: stime | MI2: status | MJ2: rules | MK2: ctime | ML2: fmtime | MM2: memout | MN2: time | MO2: stime | MP2: status | MQ2: rules | MR2: ctime | MS2: fmtime | MT2: memout | MU2: time | MV2: stime | MW2: status | MX2: rules | MY2: ctime | MZ2: fmtime | NA2: memout | NB2: time | NC2: stime | ND2: status | NE2: rules | NF2: ctime | NG2: fmtime | NH2: memout | NI2: time | NJ2: stime | NK2: status | NL2: rules | NM2: ctime | NN2: fmtime | NO2: memout | NP2: time | NQ2: stime | NR2: status | NS2: rules | NT2: ctime | NU2: fmtime | NV2: memout | NW2: time | NX2: stime | NY2: status | NZ2: rules | OA2: ctime | OB2: fmtime | OC2: memout | OD2: time | OE2: stime | OF2: status | OG2: rules | OH2: ctime | OI2: fmtime | OJ2: memout | OK2: time | OL2: stime | OM2: status | ON2: rules | OO2: ctime | OP2: fmtime | OQ2: memout | OR2: time | OS2: stime | OT2: status | OU2: rules | OV2: ctime | OW2: fmtime | OX2: memout | OY2: time | OZ2: stime | PA2: status | PB2: rules | PC2: ctime | PD2: fmtime | PE2: memout | PF2: time | PG2: stime | PH2: status | PI2: rules | PJ2: ctime | PK2: fmtime | PL2: memout | PM2: time | PN2: stime | PO2: status | PP2: rules | PQ2: ctime | PR2: fmtime | PS2: memout | PT2: time | PU2: stime | PV2: status | PW2: rules | PX2: ctime | PY2: fmtime | PZ2: memout | QA2: time | QB2: stime | QC2: status | QD2: rules | QE2: ctime | QF2: fmtime | QG2: memout | QH2: time | QI2: stime | QJ2: status | QK2: rules | QL2: ctime | QM2: fmtime | QN2: memout | QO2: time | QP2: stime | QQ2: status | QR2: rules | QS2: ctime | QT2: fmtime | QU2: memout | QV2: time | QW2: stime | QX2: status | QY2: rules | QZ2: ctime | RA2: fmtime | RB2: memout | RC2: time | RD2: stime | RE2: status | RF2: rules | RG2: ctime | RH2: fmtime | RI2: memout | RJ2: time | RK2: stime | RL2: status | RM2: rules | RN2: ctime | RO2: fmtime | RP2: memout | RQ2: time | RR2: stime | RS2: status | RT2: rules | RU2: ctime | RV2: fmtime | RW2: memout | RX2: time | RY2: stime | RZ2: status | SA2: rules | SB2: ctime | SC2: fmtime | SD2: memout | SE2: time | SF2: stime | SG2: status | SH2: rules | SI2: ctime | SJ2: fmtime | SK2: memout | SL2: time | SM2: stime | SN2: status | SO2: rules | SP2: ctime | SQ2: fmtime | SR2: memout | SS2: time | ST2: stime | SU2: status | SV2: rules | SW2: ctime | SX2: fmtime | SY2: memout | SZ2: time | TA2: stime | TB2: status | TC2: rules | TD2: ctime | TE2: fmtime | TF2: memout | TG2: time | TH2: stime | TI2: status | TJ2: rules | TK2: ctime | TL2: fmtime | TM2: memout | TN2: time | TO2: stime | TP2: status | TQ2: rules | TR2: ctime | TS2: fmtime | TT2: memout | TU2: time | TV2: stime | TW2: status | TX2: rules | TY2: ctime | TZ2: fmtime | UA2: memout | UB2: time | UC2: stime | UD2: status | UE2: rules | UF2: ctime | UG2: fmtime | UH2: memout | UI2: time | UJ2: stime | UK2: status | UL2: rules | UM2: ctime | UN2: fmtime | UO2: memout | UP2: time | UQ2: stime | UR2: status | US2: rules | UT2: ctime | UU2: fmtime | UV2: memout | UW2: time | UX2: stime | UY2: status | UZ2: rules | VA2: ctime | VB2: fmtime | VC2: memout | VD2: time | VE2: stime | VF2: status | VG2: rules | VH2: ctime | VI2: fmtime | VJ2: memout | VK2: time | VL2: stime | VM2: status | VN2: rules | VO2: ctime | VP2: fmtime | VQ2: memout | VR2: time | VS2: stime | VT2: rules | VU2: ctime | VV2: fmtime | VW2: memout | VX2: time | VY2: stime | VZ2: rules | WA2: ctime | WB2: fmtime | WC2: memout | WD2: time | WE2: stime | WF2: rules | WG2: ctime | WH2: fmtime | WI2: memout
A3: instances/random_x8_y8_a3 | B3: 1200 | C3: 1167.59 | D3: UNKNOWN | E3: 9474720 | F3: 1199.086 | G3: 0 | H3: 0 | I3: 1200 | J3: 1138.57 | K3: UNKNOWN | L3: 21288420 | M3: 1199.231 | N3: 0 | O3: 0 | P3: 1200 | Q3: 1184.33 | R3: UNKNOWN | S3: 1369140 | T3: 1199.122 | U3: 0 | V3: 0 | W3: 1200 | X3: 1182.4 | Y3: UNKNOWN | Z3: 2681020 | AA3: 1199.156 | AB3: 0 | AC3: 0 | AD3: 1200 | AJ3: 0 | AK3: 1200 | AQ3: 0 | AR3: 1200 | AX3: 0 | AY3: 1200 | BE3: 0 | BF3: 1200 | BL3: 0 | BM3: 1200 | BS3: 0 | BT3: 1200 | BZ3: 0 | CA3: 1200 | CG3: 0 | CH3: 1200 | CN3: 0 | CO3: 1200 | CU3: 0 | CV3: 1200 | DB3: 0 | DC3: 1200 | DI3: 0 | DJ3: 1200 | DP3: 0 | DQ3: 1200 | DR3: 412.02 | DS3: UNKNOWN | DT3: 102408790 | DU3: 1199.395 | DV3: 0 | DW3: 0 | DX3: 1200 | ED3: 0 | EE3: 1200 | EK3: 0 | EL3: 904.23 | EM3: 59.57 | EN3: SATISFIABLE | EO3: 51133870 | EP3: 901.396 | EQ3: 59.48 | ER3: 0 | ES3: 1200 | ET3: 195.21 | EU3: UNKNOWN | EV3: 129055070 | EW3: 1199.338 | EX3: 0 | EY3: 0 | EZ3: 17.62 | FA3: 0 | FB3: UNSATISFIABLE | FC3: 8662126 | FD3: 15.59 | FE3: 0 | FF3: 0 | FG3: 1200 | FH3: 433.09 | FI3: UNKNOWN | FJ3: 10357670 | FK3: 1199.066 | FL3: 0 | FM3: 0 | FN3: 1200 | FT3: 0 | FU3: 1200 | GA3: 0 | GB3: 1200 | GH3: 0 | GI3: 1200 | GO3: 0 | GP3: 1200 | GV3: 0 | GW3: 1200 | HC3: 0 | HD3: 1200 | HJ3: 0 | HK3: 1200 | HQ3: 0 | HR3: 1200 | HX3: 0 | HY3: 1200 | IE3: 0 | IF3: 1200 | IL3: 0 | IM3: 1200 | IS3: 0 | IT3: 672.96 | IU3: 571.65 | IV3: SATISFIABLE | IW3: 1735278 | IX3: 671.4 | IY3: 571.62 | IZ3: 0 | JA3: 324.6 | JB3: 227.62 | JC3: SATISFIABLE | JD3: 1735278 | JE3: 322.871 | JF3: 227.6 | JG3: 0 | JH3: 1200 | JN3: 0 | JO3: 1200 | JU3: 0 | JV3: 789.53 | JW3: 539.02 | JX3: SATISFIABLE | JY3: 2284058 | JZ3: 787.648 | KA3: 538.98 | KB3: 0 | KC3: 638.48 | KD3: 390.11 | KE3: SATISFIABLE | KF3: 2284058 | KG3: 636.633 | KH3: 390.08 | KI3: 0 | KJ3: 241.33 | KK3: 8.57 | KL3: UNSATISFIABLE | KM3: 2284058 | KN3: 239.311 | KO3: 0 | KP3: 0 | KQ3: 380.3 | KR3: 126.14 | KS3: SATISFIABLE | KT3: 2284058 | KU3: 378.267 | KV3: 126.1 | KW3: 0 | KX3: 1200 | LD3: 0 | LE3: 1200 | LK3: 0 | LL3: 498.74 | LM3: 0 | LN3: UNSATISFIABLE | LO3: 5812426 | LP3: 496.387 | LQ3: 0 | LR3: 0 | LS3: 523.48 | LT3: 64.37 | LU3: SATISFIABLE | LV3: 2906213 | LW3: 521.328 | LX3: 64.34 | LY3: 0 | LZ3: 1200 | MF3: 0 | MG3: 1200 | MM3: 0 | MN3: 1200 | MT3: 0 | MU3: 1200 | NA3: 0 | NB3: 1200 | NH3: 0 | NI3: 1200 | NO3: 0 | NP3: 1200 | NV3: 0 | NW3: 1200 | OC3: 0 | OD3: 392.08 | OE3: 372.25 | OF3: SATISFIABLE | OG3: 857843 | OH3: 390.805 | OI3: 372.23 | OJ3: 0 | OK3: 395.52 | OL3: 378.25 | OM3: SATISFIABLE | ON3: 857843 | OO3: 394.23 | OP3: 378.24 | OQ3: 0 | OR3: 1200 | OX3: 0 | OY3: 277.42 | OZ3: 260.66 | PA3: SATISFIABLE | PB3: 857843 | PC3: 276.165 | PD3: 260.65 | PE3: 0 | PF3: 461.78 | PG3: 412.72 | PH3: SATISFIABLE | PI3: 1259873 | PJ3: 460.25 | PK3: 412.71 | PL3: 0 | PM3: 414.8 | PN3: 374.76 | PO3: SATISFIABLE | PP3: 1259873 | PQ3: 413.387 | PR3: 374.75 | PS3: 0 | PT3: 1200 | PU3: 1160.23 | PV3: UNKNOWN | PW3: 1259873 | PX3: 1199.095 | PY3: 0 | PZ3: 0 | QA3: 684.57 | QB3: 636.42 | QC3: SATISFIABLE | QD3: 1259873 | QE3: 683.164 | QF3: 636.41 | QG3: 0 | QH3: 375.27 | QI3: 280.38 | QJ3: SATISFIABLE | QK3: 1735278 | QL3: 373.774 | QM3: 280.37 | QN3: 0 | QO3: 197.6 | QP3: 84.56 | QQ3: SATISFIABLE | QR3: 1735278 | QS3: 195.669 | QT3: 84.54 | QU3: 0 | QV3: 1200 | QW3: 1098.14 | QX3: UNKNOWN | QY3: 1735278 | QZ3: 1199.037 | RA3: 0 | RB3: 0 | RC3: 685.76 | RD3: 580.04 | RE3: SATISFIABLE | RF3: 1735278 | RG3: 684.117 | RH3: 580.02 | RI3: 0 | RJ3: 1200 | RP3: 0 | RQ3: 1200 | RW3: 0 | RX3: 1200 | SD3: 0 | SE3: 1200 | SK3: 0 | SL3: 1200 | SR3: 0 | SS3: 1200 | SY3: 0 | SZ3: 1200 | TF3: 0 | TG3: 1200 | TM3: 0 | TN3: 730.19 | TO3: 121.49 | TP3: SATISFIABLE | TQ3: 3601743 | TR3: 728.03 | TS3: 121.46 | TT3: 0 | TU3: 699.45 | TV3: 92.24 | TW3: SATISFIABLE | TX3: 3601743 | TY3: 697.21 | TZ3: 92.21 | UA3: 0 | UB3: 604.84 | UC3: 0 | UD3: UNSATISFIABLE | UE3: 3601743 | UF3: 602.328 | UG3: 0 | UH3: 0 | UI3: 975.87 | UJ3: 362.19 | UK3: SATISFIABLE | UL3: 3601743 | UM3: 973.857 | UN3: 362.17 | UO3: 0 | UP3: 841.92 | UQ3: 80.34 | UR3: SATISFIABLE | US3: 4370648 | UT3: 839.496 | UU3: 80.31 | UV3: 0 | UW3: 849.09 | UX3: 86.49 | UY3: SATISFIABLE | UZ3: 4370648 | VA3: 846.717 | VB3: 86.46 | VC3: 0 | VD3: 762.11 | VE3: 0 | VF3: UNSATISFIABLE | VG3: 4370648 | VH3: 759.445 | VI3: 0 | VJ3: 0 | VK3: 1193.06 | VL3: 432.07 | VM3: SATISFIABLE | VN3: 4370648 | VO3: 1190.858 | VP3: 432.04 | VQ3: 0 | VR3: =MIN($B3,$I3,$P3,$W3,$AD3,$AK3,$AR3,$AY3,$BF3,$BM3,$BT3,$CA3,$CH3,$CO3,$CV3,$DC3,$DJ3,$DQ3,$DX3,$EE3,$EL3,$ES3,$EZ3,$FG3,$FN3,$FU3,$GB3,$GI3,$GP3,$GW3,$HD3,$HK3,$HR3,$HY3,$IF3,$IM3,$IT3,$JA3,$JH3,$JO3,$JV3,$KC3,$KJ3,$KQ3,$KX3,$LE3,$LL3,$LS3,$LZ3,$MG3,$MN3,$MU3,$NB3,$NI3,$NP3,$NW3,$OD3,$OK3,$OR3,$OY3,$PF3,$PM3,$PT3,$QA3,$QH3,$QO3,$QV3,$RC3,$RJ3,$RQ3,$RX3,$SE3,$SL3,$SS3,$SZ3,$TG3,$TN3,$TU3,$UB3,$UI3,$UP3,$UW3,$VD3,$VK3) -> 0 | VS3: =MIN($C3,$J3,$Q3,$X3,$AE3,$AL3,$AS3,$AZ3,$BG3,$BN3,$BU3,$CB3,$CI3,$CP3,$CW3,$DD3,$DK3,$DR3,$DY3,$EF3,$EM3,$ET3,$FA3,$FH3,$FO3,$FV3,$GC3,$GJ3,$GQ3,$GX3,$HE3,$HL3,$HS3,$HZ3,$IG3,$IN3,$IU3,$JB3,$JI3,$JP3,$JW3,$KD3,$KK3,$KR3,$KY3,$LF3,$LM3,$LT3,$MA3,$MH3,$MO3,$MV3,$NC3,$NJ3,$NQ3,$NX3,$OE3,$OL3,$OS3,$OZ3,$PG3,$PN3,$PU3,$QB3,$QI3,$QP3,$QW3,$RD3,$RK3,$RR3,$RY3,$SF3,$SM3,$ST3,$TA3,$TH3,$TO3,$TV3,$UC3,$UJ3,$UQ3,$UX3,$VE3,$VL3) -> 0 | VT3: =MIN($E3,$L3,$S3,$Z3,$AG3,$AN3,$AU3,$BB3,$BI3,$BP3,$BW3,$CD3,$CK3,$CR3,$CY3,$DF3,$DM3,$DT3,$EA3,$EH3,$EO3,$EV3,$FC3,$FJ3,$FQ3,$FX3,$GE3,$GL3,$GS3,$GZ3,$HG3,$HN3,$HU3,$IB3,$II3,$IP3,$IW3,$JD3,$JK3,$JR3,$JY3,$KF3,$KM3,$KT3,$LA3,$LH3,$LO3,$LV3,$MC3,$MJ3,$MQ3,$MX3,$NE3,$NL3,$NS3,$NZ3,$OG3,$ON3,$OU3,$PB3,$PI3,$PP3,$PW3,$QD3,$QK3,$QR3,$QY3,$RF3,$RM3,$RT3,$SA3,$SH3,$SO3,$SV3,$TC3,$TJ3,$TQ3,$TX3,$UE3,$UL3,$US3,$UZ3,$VG3,$VN3) -> 0 | VU3: =MIN($F3,$M3,$T3,$AA3,$AH3,$AO3,$AV3,$BC3,$BJ3,$BQ3,$BX3,$CE3,$CL3,$CS3,$CZ3,$DG3,$DN3,$DU3,$EB3,$EI3,$EP3,$EW3,$FD3,$FK3,$FR3,$FY3,$GF3,$GM3,$GT3,$HA3,$HH3,$HO3,$HV3,$IC3,$IJ3,$IQ3,$IX3,$JE3,$JL3,$JS3,$JZ3,$KG3,$KN3,$KU3,$LB3,$LI3,$LP3,$LW3,$MD3,$MK3,$MR3,$MY3,$NF3,$NM3,$NT3,$OA3,$OH3,$OO3,$OV3,$PC3,$PJ3,$PQ3,$PX3,$QE3,$QL3,$QS3,$QZ3,$RG3,$RN3,$RU3,$SB3,$SI3,$SP3,$SW3,$TD3,$TK3,$TR3,$TY3,$UF3,$UM3,$UT3,$VA3,$VH3,$VO3) -> 0 | VV3: =MIN($G3,$N3,$U3,$AB3,$AI3,$AP3,$AW3,$BD3,$BK3,$BR3,$BY3,$CF3,$CM3,$CT3,$DA3,$DH3,$DO3,$DV3,$EC3,$EJ3,$EQ3,$EX3,$FE3,$FL3,$FS3,$FZ3,$GG3,$GN3,$GU3,$HB3,$HI3,$HP3,$HW3,$ID3,$IK3,$IR3,$IY3,$JF3,$JM3,$JT3,$KA3,$KH3,$KO3,$KV3,$LC3,$LJ3,$LQ3,$LX3,$ME3,$ML3,$MS3,$MZ3,$NG3,$NN3,$NU3,$OB3,$OI3,$OP3,$OW3,$PD3,$PK3,$PR3,$PY3,$QF3,$QM3,$QT3,$RA3,$RH3,$RO3,$RV3,$SC3,$SJ3,$SQ3,$SX3,$TE3,$TL3,$TS3,$TZ3,$UG3,$UN3,$UU3,$VB3,$VI3,$VP3) -> 0 | VW3: =MIN($H3,$O3,$V3,$AC3,$AJ3,$AQ3,$AX3,$BE3,$BL3,$BS3,$BZ3,$CG3,$CN3,$CU3,$DB3,$DI3,$DP3,$DW3,$ED3,$EK3,$ER3,$EY3,$FF3,$FM3,$FT3,$GA3,$GH3,$GO3,$GV3,$HC3,$HJ3,$HQ3,$HX3,$IE3,$IL3,$IS3,$IZ3,$JG3,$JN3,$JU3,$KB3,$KI3,$KP3,$KW3,$LD3,$LK3,$LR3,$LY3,$MF3,$MM3,$MT3,$NA3,$NH3,$NO3,$NV3,$OC3,$OJ3,$OQ3,$OX3,$PE3,$PL3,$PS3,$PZ3,$QG3,$QN3,$QU3,$RB3,$RI3,$RP3,$RW3,$SD3,$SK3,$SR3,$SY3,$TF3,$TM3,$TT3,$UA3,$UH3,$UO3,$UV3,$VC3,$VJ3,$VQ3) -> 0 | VX3: =MEDIAN($B3,$I3,$P3,$W3,$AD3,$AK3,$AR3,$AY3,$BF3,$BM3,$BT3,$CA3,$CH3,$CO3,$CV3,$DC3,$DJ3,$DQ3,$DX3,$EE3,$EL3,$ES3,$EZ3,$FG3,$FN3,$FU3,$GB3,$GI3,$GP3,$GW3,$HD3,$HK3,$HR3,$HY3,$IF3,$IM3,$IT3,$JA3,$JH3,$JO3,$JV3,$KC3,$KJ3,$KQ3,$KX3,$LE3,$LL3,$LS3,$LZ3,$MG3,$MN3,$MU3,$NB3,$NI3,$NP3,$NW3,$OD3,$OK3,$OR3,$OY3,$PF3,$PM3,$PT3,$QA3,$QH3,$QO3,$QV3,$RC3,$RJ3,$RQ3,$RX3,$SE3,$SL3,$SS3,$SZ3,$TG3,$TN3,$TU3,$UB3,$UI3,$UP3,$UW3,$VD3,$VK3) -> 0 | VY3: =MEDIAN($C3,$J3,$Q3,$X3,$AE3,$AL3,$AS3,$AZ3,$BG3,$BN3,$BU3,$CB3,$CI3,$CP3,$CW3,$DD3,$DK3,$DR3,$DY3,$EF3,$EM3,$ET3,$FA3,$FH3,$FO3,$FV3,$GC3,$GJ3,$GQ3,$GX3,$HE3,$HL3,$HS3,$HZ3,$IG3,$IN3,$IU3,$JB3,$JI3,$JP3,$JW3,$KD3,$KK3,$KR3,$KY3,$LF3,$LM3,$LT3,$MA3,$MH3,$MO3,$MV3,$NC3,$NJ3,$NQ3,$NX3,$OE3,$OL3,$OS3,$OZ3,$PG3,$PN3,$PU3,$QB3,$QI3,$QP3,$QW3,$RD3,$RK3,$RR3,$RY3,$SF3,$SM3,$ST3,$TA3,$TH3,$TO3,$TV3,$UC3,$UJ3,$UQ3,$UX3,$VE3,$VL3) -> 0 | VZ3: =MEDIAN($E3,$L3,$S3,$Z3,$AG3,$AN3,$AU3,$BB3,$BI3,$BP3,$BW3,$CD3,$CK3,$CR3,$CY3,$DF3,$DM3,$DT3,$EA3,$EH3,$EO3,$EV3,$FC3,$FJ3,$FQ3,$FX3,$GE3,$GL3,$GS3,$GZ3,$HG3,$HN3,$HU3,$IB3,$II3,$IP3,$IW3,$JD3,$JK3,$JR3,$JY3,$KF3,$KM3,$KT3,$LA3,$LH3,$LO3,$LV3,$MC3,$MJ3,$MQ3,$MX3,$NE3,$NL3,$NS3,$NZ3,$OG3,$ON3,$OU3,$PB3,$PI3,$PP3,$PW3,$QD3,$QK3,$QR3,$QY3,$RF3,$RM3,$RT3,$SA3,$SH3,$SO3,$SV3,$TC3,$TJ3,$TQ3,$TX3,$UE3,$UL3,$US3,$UZ3,$VG3,$VN3) -> 0 | WA3: =MEDIAN($F3,$M3,$T3,$AA3,$AH3,$AO3,$AV3,$BC3,$BJ3,$BQ3,$BX3,$CE3,$CL3,$CS3,$CZ3,$DG3,$DN3,$DU3,$EB3,$EI3,$EP3,$EW3,$FD3,$FK3,$FR3,$FY3,$GF3,$GM3,$GT3,$HA3,$HH3,$HO3,$HV3,$IC3,$IJ3,$IQ3,$IX3,$JE3,$JL3,$JS3,$JZ3,$KG3,$KN3,$KU3,$LB3,$LI3,$LP3,$LW3,$MD3,$MK3,$MR3,$MY3,$NF3,$NM3,$NT3,$OA3,$OH3,$OO3,$OV3,$PC3,$PJ3,$PQ3,$PX3,$QE3,$QL3,$QS3,$QZ3,$RG3,$RN3,$RU3,$SB3,$SI3,$SP3,$SW3,$TD3,$TK3,$TR3,$TY3,$UF3,$UM3,$UT3,$VA3,$VH3,$VO3) -> 0 | WB3: =MEDIAN($G3,$N3,$U3,$AB3,$AI3,$AP3,$AW3,$BD3,$BK3,$BR3,$BY3,$CF3,$CM3,$CT3,$DA3,$DH3,$DO3,$DV3,$EC3,$EJ3,$EQ3,$EX3,$FE3,$FL3,$FS3,$FZ3,$GG3,$GN3,$GU3,$HB3,$HI3,$HP3,$HW3,$ID3,$IK3,$IR3,$IY3,$JF3,$JM3,$JT3,$KA3,$KH3,$KO3,$KV3,$LC3,$LJ3,$LQ3,$LX3,$ME3,$ML3,$MS3,$MZ3,$NG3,$NN3,$NU3,$OB3,$OI3,$OP3,$OW3,$PD3,$PK3,$PR3,$PY3,$QF3,$QM3,$QT3,$RA3,$RH3,$RO3,$RV3,$SC3,$SJ3,$SQ3,$SX3,$TE3,$TL3,$TS3,$TZ3,$UG3,$UN3,$UU3,$VB3,$VI3,$VP3) -> 0 | WC3: =MEDIAN($H3,$O3,$V3,$AC3,$AJ3,$AQ3,$AX3,$BE3,$BL3,$BS3,$BZ3,$CG3,$CN3,$CU3,$DB3,$DI3,$DP3,$DW3,$ED3,$EK3,$ER3,$EY3,$FF3,$FM3,$FT3,$GA3,$GH3,$GO3,$GV3,$HC3,$HJ3,$HQ3,$HX3,$IE3,$IL3,$IS3,$IZ3,$JG3,$JN3,$JU3,$KB3,$KI3,$KP3,$KW3,$LD3,$LK3,$LR3,$LY3,$MF3,$MM3,$MT3,$NA3,$NH3,$NO3,$NV3,$OC3,$OJ3,$OQ3,$OX3,$PE3,$PL3,$PS3,$PZ3,$QG3,$QN3,$QU3,$RB3,$RI3,$RP3,$RW3,$SD3,$SK3,$SR3,$SY3,$TF3,$TM3,$TT3,$UA3,$UH3,$UO3,$UV3,$VC3,$VJ3,$VQ3) -> 0 | WD3: =MAX($B3,$I3,$P3,$W3,$AD3,$AK3,$AR3,$AY3,$BF3,$BM3,$BT3,$CA3,$CH3,$CO3,$CV3,$DC3,$DJ3,$DQ3,$DX3,$EE3,$EL3,$ES3,$EZ3,$FG3,$FN3,$FU3,$GB3,$GI3,$GP3,$GW3,$HD3,$HK3,$HR3,$HY3,$IF3,$IM3,$IT3,$JA3,$JH3,$JO3,$JV3,$KC3,$KJ3,$KQ3,$KX3,$LE3,$LL3,$LS3,$LZ3,$MG3,$MN3,$MU3,$NB3,$NI3,$NP3,$NW3,$OD3,$OK3,$OR3,$OY3,$PF3,$PM3,$PT3,$QA3,$QH3,$QO3,$QV3,$RC3,$RJ3,$RQ3,$RX3,$SE3,$SL3,$SS3,$SZ3,$TG3,$TN3,$TU3,$UB3,$UI3,$UP3,$UW3,$VD3,$VK3) -> 0 | WE3: =MAX($C3,$J3,$Q3,$X3,$AE3,$AL3,$AS3,$AZ3,$BG3,$BN3,$BU3,$CB3,$CI3,$CP3,$CW3,$DD3,$DK3,$DR3,$DY3,$EF3,$EM3,$ET3,$FA3,$FH3,$FO3,$FV3,$GC3,$GJ3,$GQ3,$GX3,$HE3,$HL3,$HS3,$HZ3,$IG3,$IN3,$IU3,$JB3,$JI3,$JP3,$JW3,$KD3,$KK3,$KR3,$KY3,$LF3,$LM3,$LT3,$MA3,$MH3,$MO3,$MV3,$NC3,$NJ3,$NQ3,$NX3,$OE3,$OL3,$OS3,$OZ3,$PG3,$PN3,$PU3,$QB3,$QI3,$QP3,$QW3,$RD3,$RK3,$RR3,$RY3,$SF3,$SM3,$ST3,$TA3,$TH3,$TO3,$TV3,$UC3,$UJ3,$UQ3,$UX3,$VE3,$VL3) -> 0 | WF3: =MAX($E3,$L3,$S3,$Z3,$AG3,$AN3,$AU3,$BB3,$BI3,$BP3,$BW3,$CD3,$CK3,$CR3,$CY3,$DF3,$DM3,$DT3,$EA3,$EH3,$EO3,$EV3,$FC3,$FJ3,$FQ3,$FX3,$GE3,$GL3,$GS3,$GZ3,$HG3,$HN3,$HU3,$IB3,$II3,$IP3,$IW3,$JD3,$JK3,$JR3,$JY3,$KF3,$KM3,$KT3,$LA3,$LH3,$LO3,$LV3,$MC3,$MJ3,$MQ3,$MX3,$NE3,$NL3,$NS3,$NZ3,$OG3,$ON3,$OU3,$PB3,$PI3,$PP3,$PW3,$QD3,$QK3,$QR3,$QY3,$RF3,$RM3,$RT3,$SA3,$SH3,$SO3,$SV3,$TC3,$TJ3,$TQ3,$TX3,$UE3,$UL3,$US3,$UZ3,$VG3,$VN3) -> 0 | WG3: =MAX($F3,$M3,$T3,$AA3,$AH3,$AO3,$AV3,$BC3,$BJ3,$BQ3,$BX3,$CE3,$CL3,$CS3,$CZ3,$DG3,$DN3,$DU3,$EB3,$EI3,$EP3,$EW3,$FD3,$FK3,$FR3,$FY3,$GF3,$GM3,$GT3,$HA3,$HH3,$HO3,$HV3,$IC3,$IJ3,$IQ3,$IX3,$JE3,$JL3,$JS3,$JZ3,$KG3,$KN3,$KU3,$LB3,$LI3,$LP3,$LW3,$MD3,$MK3,$MR3,$MY3,$NF3,$NM3,$NT3,$OA3,$OH3,$OO3,$OV3,$PC3,$PJ3,$PQ3,$PX3,$QE3,$QL3,$QS3,$QZ3,$RG3,$RN3,$RU3,$SB3,$SI3,$SP3,$SW3,$TD3,$TK3,$TR3,$TY3,$UF3,$UM3,$UT3,$VA3,$VH3,$VO3) -> 0 | WH3: =MAX($G3,$N3,$U3,$AB3,$AI3,$AP3,$AW3,$BD3,$BK3,$BR3,$BY3,$CF3,$CM3,$CT3,$DA3,$DH3,$DO3,$DV3,$EC3,$EJ3,$EQ3,$EX3,$FE3,$FL3,$FS3,$FZ3,$GG3,$GN3,$GU3,$HB3,$HI3,$HP3,$HW3,$ID3,$IK3,$IR3,$IY3,$JF3,$JM3,$JT3,$KA3,$KH3,$KO3,$KV3,$LC3,$LJ3,$LQ3,$LX3,$ME3,$ML3,$MS3,$MZ3,$NG3,$NN3,$NU3,$OB3,$OI3,$OP3,$OW3,$PD3,$PK3,$PR3,$PY3,$QF3,$QM3,$QT3,$RA3,$RH3,$RO3,$RV3,$SC3,$SJ3,$SQ3,$SX3,$TE3,$TL3,$TS3,$TZ3,$UG3,$UN3,$UU3,$VB3,$VI3,$VP3) -> 0 | WI3: =MAX($H3,$O3,$V3,$AC3,$AJ3,$AQ3,$AX3,$BE3,$BL3,$BS3,$BZ3,$CG3,$CN3,$CU3,$DB3,$DI3,$DP3,$DW3,$ED3,$EK3,$ER3,$EY3,$FF3,$FM3,$FT3,$GA3,$GH3,$GO3,$GV3,$HC3,$HJ3,$HQ3,$HX3,$IE3,$IL3,$IS3,$IZ3,$JG3,$JN3,$JU3,$KB3,$KI3,$KP3,$KW3,$LD3,$LK3,$LR3,$LY3,$MF3,$MM3,$MT3,$NA3,$NH3,$NO3,$NV3,$OC3,$OJ3,$OQ3,$OX3,$PE3,$PL3,$PS3,$PZ3,$QG3,$QN3,$QU3,$RB3,$RI3,$RP3,$RW3,$SD3,$SK3,$SR3,$SY3,$TF3,$TM3,$TT3,$UA3,$UH3,$UO3,$UV3,$VC3,$VJ3,$VQ3) -> 0
A4: instances/room_x8_y8_a3 | B4: 81.8 | C4: 46.03 | D4: SATISFIABLE | E4: 9601168 | F4: 80.288 | G4: 46 | H4: 0 | I4: 407.11 | J4: 335.12 | K4: SATISFIABLE | L4: 21414868 | M4: 405.654 | N4: 335.07 | O4: 0 | P4: 63 | Q4: 42.97 | R4: SATISFIABLE | S4: 1495588 | T4: 61.55 | U4: 42.96 | V4: 0 | W4: 115.62 | X4: 91.08 | Y4: SATISFIABLE | Z4: 2807468 | AA4: 113.994 | AB4: 91.07 | AC4: 0 | AD4: 1200 | AJ4: 0 | AK4: 1200 | AQ4: 0 | AR4: 1200 | AX4: 0 | AY4: 1200 | BE4: 0 | BF4: 1200 | BL4: 0 | BM4: 1200 | BS4: 0 | BT4: 1200 | BZ4: 0 | CA4: 1200 | CG4: 0 | CH4: 1200 | CN4: 0 | CO4: 1200 | CU4: 0 | CV4: 1200 | DB4: 0 | DC4: 1200 | DI4: 0 | DJ4: 1200 | DP4: 0 | DQ4: 1200 | DR4: 240.8 | DS4: UNKNOWN | DT4: 102831098 | DU4: 1199.126 | DV4: 0 | DW4: 0 | DX4: 1200 | ED4: 0 | EE4: 1200 | EK4: 0 | EL4: 1200 | EM4: 326.4 | EN4: UNKNOWN | EO4: 51657143 | EP4: 1199.161 | EQ4: 0 | ER4: 0 | ES4: 1200 | EY4: 0 | EZ4: 20.1 | FA4: 0 | FB4: UNSATISFIABLE | FC4: 9638682 | FD4: 17.798 | FE4: 0 | FF4: 0 | FG4: 1200 | FH4: 428.06 | FI4: UNKNOWN | FJ4: 10880943 | FK4: 1199.139 | FL4: 0 | FM4: 0 | FN4: 1200 | FT4: 0 | FU4: 1200 | GA4: 0 | GB4: 1200 | GH4: 0 | GI4: 1200 | GO4: 0 | GP4: 1200 | GV4: 0 | GW4: 1200 | HC4: 0 | HD4: 1200 | HJ4: 0 | HK4: 1200 | HQ4: 0 | HR4: 1200 | HX4: 0 | HY4: 1200 | IE4: 0 | IF4: 1200 | IL4: 0 | IM4: 1200 | IS4: 0 | IT4: 252.04 | IU4: 101.89 | IV4: SATISFIABLE | IW4: 1989199 | IX4: 249.925 | IY4: 101.86 | IZ4: 0 | JA4: 206.6 | JB4: 56.49 | JC4: SATISFIABLE | JD4: 1989199 | JE4: 204.478 | JF4: 56.45 | JG4: 0 | JH4: 1200 | JN4: 0 | JO4: 1200 | JU4: 0 | JV4: 353.24 | JW4: 32.91 | JX4: SATISFIABLE | JY4: 2617344 | JZ4: 350.893 | KA4: 32.86 | KB4: 0 | KC4: 392.87 | KD4: 46.35 | KE4: SATISFIABLE | KF4: 2617344 | KG4: 390.19 | KH4: 46.31 | KI4: 0 | KJ4: 382.76 | KK4: 37.36 | KL4: SATISFIABLE | KM4: 2617344 | KN4: 380.213 | KO4: 37.34 | KP4: 0 | KQ4: 597.27 | KR4: 268.77 | KS4: SATISFIABLE | KT4: 2617344 | KU4: 595.346 | KV4: 268.73 | KW4: 0 | KX4: 1200 | LD4: 0 | LE4: 1200 | LK4: 0 | LL4: 607.43 | LM4: 0 | LN4: UNSATISFIABLE | LO4: 6659328 | LP4: 605.208 | LQ4: 0 | LR4: 0 | LS4: 1200 | LT4: 588.2 | LU4: UNKNOWN | LV4: 3329664 | LW4: 1199.057 | LX4: 0 | LY4: 0 | LZ4: 1200 | MF4: 0 | MG4: 1200 | MM4: 0 | MN4: 1200 | MT4: 0 | MU4: 1200 | NA4: 0 | NB4: 1200 | NH4: 0 | NI4: 1200 | NO4: 0 | NP4: 1200 | NV4: 0 | NW4: 1200 | OC4: 0 | OD4: 66.78 | OE4: 40.48 | OF4: SATISFIABLE | OG4: 985434 | OH4: 65.42 | OI4: 40.47 | OJ4: 0 | OK4: 69.98 | OL4: 43.96 | OM4: SATISFIABLE | ON4: 985434 | OO4: 68.578 | OP4: 43.95 | OQ4: 0 | OR4: 1200 | OX4: 0 | OY4: 40.92 | OZ4: 16.63 | PA4: SATISFIABLE | PB4: 985434 | PC4: 39.345 | PD4: 16.62 | PE4: 0 | PF4: 80.6 | PG4: 28.46 | PH4: SATISFIABLE | PI4: 1445229 | PJ4: 78.821 | PK4: 28.45 | PL4: 0 | PM4: 92.92 | PN4: 31.21 | PO4: SATISFIABLE | PP4: 1445229 | PQ4: 91.091 | PR4: 31.19 | PS4: 0 | PT4: 79.02 | PU4: 29.05 | PV4: SATISFIABLE | PW4: 1445229 | PX4: 77.084 | PY4: 29.03 | PZ4: 0 | QA4: 80.12 | QB4: 17.76 | QC4: SATISFIABLE | QD4: 1445229 | QE4: 78.233 | QF4: 17.74 | QG4: 0 | QH4: 177.19 | QI4: 35.14 | QJ4: SATISFIABLE | QK4: 1989199 | QL4: 175.006 | QM4: 35.12 | QN4: 0 | QO4: 190.91 | QP4: 29.46 | QQ4: SATISFIABLE | QR4: 1989199 | QS4: 189.028 | QT4: 29.45 | QU4: 0 | QV4: 161.5 | QW4: 10.44 | QX4: SATISFIABLE | QY4: 1989199 | QZ4: 159.676 | RA4: 10.42 | RB4: 0 | RC4: 171.94 | RD4: 29.1 | RE4: SATISFIABLE | RF4: 1989199 | RG4: 169.903 | RH4: 29.08 | RI4: 0 | RJ4: 1200 | RP4: 0 | RQ4: 1200 | RW4: 0 | RX4: 1200 | SD4: 0 | SE4: 1200 | SK4: 0 | SL4: 1200 | SR4: 0 | SS4: 1200 | SY4: 0 | SZ4: 1200 | TF4: 0 | TG4: 1200 | TM4: 0 | TN4: 831.62 | TO4: 71.74 | TP4: SATISFIABLE | TQ4: 4126159 | TR4: 829.174 | TS4: 71.7 | TT4: 0 | TU4: 839.33 | TV4: 82.52 | TW4: SATISFIABLE | TX4: 4126159 | TY4: 837.037 | TZ4: 82.5 | UA4: 0 | UB4: 756.94 | UC4: 0 | UD4: UNSATISFIABLE | UE4: 4126159 | UF4: 754.424 | UG4: 0 | UH4: 0 | UI4: 1200 | UJ4: 442.74 | UK4: UNKNOWN | UL4: 4126159 | UM4: 1198.822 | UN4: 0 | UO4: 0 | UP4: 1177.15 | UQ4: 408.63 | UR4: SATISFIABLE | US4: 5006829 | UT4: 1174.712 | UU4: 408.59 | UV4: 0 | UW4: 948.12 | UX4: 178.17 | UY4: SATISFIABLE | UZ4: 5006829 | VA4: 945.493 | VB4: 178.13 | VC4: 0 | VD4: 769.39 | VE4: 0 | VF4: UNSATISFIABLE | VG4: 5006829 | VH4: 766.355 | VI4: 0 | VJ4: 0 | VK4: 816.63 | VL4: 46.53 | VM4: SATISFIABLE | VN4: 5006829 | VO4: 813.858 | VP4: 46.48 | VQ4: 0 | VR4: =MIN($B4,$I4,$P4,$W4,$AD4,$AK4,$AR4,$AY4,$BF4,$BM4,$BT4,$CA4,$CH4,$CO4,$CV4,$DC4,$DJ4,$DQ4,$DX4,$EE4,$EL4,$ES4,$EZ4,$FG4,$FN4,$FU4,$GB4,$GI4,$GP4,$GW4,$HD4,$HK4,$HR4,$HY4,$IF4,$IM4,$IT4,$JA4,$JH4,$JO4,$JV4,$KC4,$KJ4,$KQ4,$KX4,$LE4,$LL4,$LS4,$LZ4,$MG4,$MN4,$MU4,$NB4,$NI4,$NP4,$NW4,$OD4,$OK4,$OR4,$OY4,$PF4,$PM4,$PT4,$QA4,$QH4,$QO4,$QV4,$RC4,$RJ4,$RQ4,$RX4,$SE4,$SL4,$SS4,$SZ4,$TG4,$TN4,$TU4,$UB4,$UI4,$UP4,$UW4,$VD4,$VK4) -> 0 | VS4: =MIN($C4,$J4,$Q4,$X4,$AE4,$AL4,$AS4,$AZ4,$BG4,$BN4,$BU4,$CB4,$CI4,$CP4,$CW4,$DD4,$DK4,$DR4,$DY4,$EF4,$EM4,$ET4,$FA4,$FH4,$FO4,$FV4,$GC4,$GJ4,$GQ4,$GX4,$HE4,$HL4,$HS4,$HZ4,$IG4,$IN4,$IU4,$JB4,$JI4,$JP4,$JW4,$KD4,$KK4,$KR4,$KY4,$LF4,$LM4,$LT4,$MA4,$MH4,$MO4,$MV4,$NC4,$NJ4,$NQ4,$NX4,$OE4,$OL4,$OS4,$OZ4,$PG4,$PN4,$PU4,$QB4,$QI4,$QP4,$QW4,$RD4,$RK4,$RR4,$RY4,$SF4,$SM4,$ST4,$TA4,$TH4,$TO4,$TV4,$UC4,$UJ4,$UQ4,$UX4,$VE4,$VL4) -> 0 | VT4: =MIN($E4,$L4,$S4,$Z4,$AG4,$AN4,$AU4,$BB4,$BI4,$BP4,$BW4,$CD4,$CK4,$CR4,$CY4,$DF4,$DM4,$DT4,$EA4,$EH4,$EO4,$EV4,$FC4,$FJ4,$FQ4,$FX4,$GE4,$GL4,$GS4,$GZ4,$HG4,$HN4,$HU4,$IB4,$II4,$IP4,$IW4,$JD4,$JK4,$JR4,$JY4,$KF4,$KM4,$KT4,$LA4,$LH4,$LO4,$LV4,$MC4,$MJ4,$MQ4,$MX4,$NE4,$NL4,$NS4,$NZ4,$OG4,$ON4,$OU4,$PB4,$PI4,$PP4,$PW4,$QD4,$QK4,$QR4,$QY4,$RF4,$RM4,$RT4,$SA4,$SH4,$SO4,$SV4,$TC4,$TJ4,$TQ4,$TX4,$UE4,$UL4,$US4,$UZ4,$VG4,$VN4) -> 0 | VU4: =MIN($F4,$M4,$T4,$AA4,$AH4,$AO4,$AV4,$BC4,$BJ4,$BQ4,$BX4,$CE4,$CL4,$CS4,$CZ4,$DG4,$DN4,$DU4,$EB4,$EI4,$EP4,$EW4,$FD4,$FK4,$FR4,$FY4,$GF4,$GM4,$GT4,$HA4,$HH4,$HO4,$HV4,$IC4,$IJ4,$IQ4,$IX4,$JE4,$JL4,$JS4,$JZ4,$KG4,$KN4,$KU4,$LB4,$LI4,$LP4,$LW4,$MD4,$MK4,$MR4,$MY4,$NF4,$NM4,$NT4,$OA4,$OH4,$OO4,$OV4,$PC4,$PJ4,$PQ4,$PX4,$QE4,$QL4,$QS4,$QZ4,$RG4,$RN4,$RU4,$SB4,$SI4,$SP4,$SW4,$TD4,$TK4,$TR4,$TY4,$UF4,$UM4,$UT4,$VA4,$VH4,$VO4) -> 0 | VV4: =MIN($G4,$N4,$U4,$AB4,$AI4,$AP4,$AW4,$BD4,$BK4,$BR4,$BY4,$CF4,$CM4,$CT4,$DA4,$DH4,$DO4,$DV4,$EC4,$EJ4,$EQ4,$EX4,$FE4,$FL4,$FS4,$FZ4,$GG4,$GN4,$GU4,$HB4,$HI4,$HP4,$HW4,$ID4,$IK4,$IR4,$IY4,$JF4,$JM4,$JT4,$KA4,$KH4,$KO4,$KV4,$LC4,$LJ4,$LQ4,$LX4,$ME4,$ML4,$MS4,$MZ4,$NG4,$NN4,$NU4,$OB4,$OI4,$OP4,$OW4,$PD4,$PK4,$PR4,$PY4,$QF4,$QM4,$QT4,$RA4,$RH4,$RO4,$RV4,$SC4,$SJ4,$SQ4,$SX4,$TE4,$TL4,$TS4,$TZ4,$UG4,$UN4,$UU4,$VB4,$VI4,$VP4) -> 0 | VW4: =MIN($H4,$O4,$V4,$AC4,$AJ4,$AQ4,$AX4,$BE4,$BL4,$BS4,$BZ4,$CG4,$CN4,$CU4,$DB4,$DI4,$DP4,$DW4,$ED4,$EK4,$ER4,$EY4,$FF4,$FM4,$FT4,$GA4,$GH4,$GO4,$GV4,$HC4,$HJ4,$HQ4,$HX4,$IE4,$IL4,$IS4,$IZ4,$JG4,$JN4,$JU4,$KB4,$KI4,$KP4,$KW4,$LD4,$LK4,$LR4,$LY4,$MF4,$MM4,$MT4,$NA4,$NH4,$NO4,$NV4,$OC4,$OJ4,$OQ4,$OX4,$PE4,$PL4,$PS4,$PZ4,$QG4,$QN4,$QU4,$RB4,$RI4,$RP4,$RW4,$SD4,$SK4,$SR4,$SY4,$TF4,$TM4,$TT4,$UA4,$UH4,$UO4,$UV4,$VC4,$VJ4,$VQ4) -> 0 | VX4: =MEDIAN($B4,$I4,$P4,$W4,$AD4,$AK4,$AR4,$AY4,$BF4,$BM4,$BT4,$CA4,$CH4,$CO4,$CV4,$DC4,$DJ4,$DQ4,$DX4,$EE4,$EL4,$ES4,$EZ4,$FG4,$FN4,$FU4,$GB4,$GI4,$GP4,$GW4,$HD4,$HK4,$HR4,$HY4,$IF4,$IM4,$IT4,$JA4,$JH4,$JO4,$JV4,$KC4,$KJ4,$KQ4,$KX4,$LE4,$LL4,$LS4,$LZ4,$MG4,$MN4,$MU4,$NB4,$NI4,$NP4,$NW4,$OD4,$OK4,$OR4,$OY4,$PF4,$PM4,$PT4,$QA4,$QH4,$QO4,$QV4,$RC4,$RJ4,$RQ4,$RX4,$SE4,$SL4,$SS4,$SZ4,$TG4,$TN4,$TU4,$UB4,$UI4,$UP4,$UW4,$VD4,$VK4) -> 0 | VY4: =MEDIAN($C4,$J4,$Q4,$X4,$AE4,$AL4,$AS4,$AZ4,$BG4,$BN4,$BU4,$CB4,$CI4,$CP4,$CW4,$DD4,$DK4,$DR4,$DY4,$EF4,$EM4,$ET4,$FA4,$FH4,$FO4,$FV4,$GC4,$GJ4,$GQ4,$GX4,$HE4,$HL4,$HS4,$HZ4,$IG4,$IN4,$IU4,$JB4,$JI4,$JP4,$JW4,$KD4,$KK4,$KR4,$KY4,$LF4,$LM4,$LT4,$MA4,$MH4,$MO4,$MV4,$NC4,$NJ4,$NQ4,$NX4,$OE4,$OL4,$OS4,$OZ4,$PG4,$PN4,$PU4,$QB4,$QI4,$QP4,$QW4,$RD4,$RK4,$RR4,$RY4,$SF4,$SM4,$ST4,$TA4,$TH4,$TO4,$TV4,$UC4,$UJ4,$UQ4,$UX4,$VE4,$VL4) -> 0 | VZ4: =MEDIAN($E4,$L4,$S4,$Z4,$AG4,$AN4,$AU4,$BB4,$BI4,$BP4,$BW4,$CD4,$CK4,$CR4,$CY4,$DF4,$DM4,$DT4,$EA4,$EH4,$EO4,$EV4,$FC4,$FJ4,$FQ4,$FX4,$GE4,$GL4,$GS4,$GZ4,$HG4,$HN4,$HU4,$IB4,$II4,$IP4,$IW4,$JD4,$JK4,$JR4,$JY4,$KF4,$KM4,$KT4,$LA4,$LH4,$LO4,$LV4,$MC4,$MJ4,$MQ4,$MX4,$NE4,$NL4,$NS4,$NZ4,$OG4,$ON4,$OU4,$PB4,$PI4,$PP4,$PW4,$QD4,$QK4,$QR4,$QY4,$RF4,$RM4,$RT4,$SA4,$SH4,$SO4,$SV4,$TC4,$TJ4,$TQ4,$TX4,$UE4,$UL4,$US4,$UZ4,$VG4,$VN4) -> 0 | WA4: =MEDIAN($F4,$M4,$T4,$AA4,$AH4,$AO4,$AV4,$BC4,$BJ4,$BQ4,$BX4,$CE4,$CL4,$CS4,$CZ4,$DG4,$DN4,$DU4,$EB4,$EI4,$EP4,$EW4,$FD4,$FK4,$FR4,$FY4,$GF4,$GM4,$GT4,$HA4,$HH4,$HO4,$HV4,$IC4,$IJ4,$IQ4,$IX4,$JE4,$JL4,$JS4,$JZ4,$KG4,$KN4,$KU4,$LB4,$LI4,$LP4,$LW4,$MD4,$MK4,$MR4,$MY4,$NF4,$NM4,$NT4,$OA4,$OH4,$OO4,$OV4,$PC4,$PJ4,$PQ4,$PX4,$QE4,$QL4,$QS4,$QZ4,$RG4,$RN4,$RU4,$SB4,$SI4,$SP4,$SW4,$TD4,$TK4,$TR4,$TY4,$UF4,$UM4,$UT4,$VA4,$VH4,$VO4) -> 0 | WB4: =MEDIAN($G4,$N4,$U4,$AB4,$AI4,$AP4,$AW4,$BD4,$BK4,$BR4,$BY4,$CF4,$CM4,$CT4,$DA4,$DH4,$DO4,$DV4,$EC4,$EJ4,$EQ4,$EX4,$FE4,$FL4,$FS4,$FZ4,$GG4,$GN4,$GU4,$HB4,$HI4,$HP4,$HW4,$ID4,$IK4,$IR4,$IY4,$JF4,$JM4,$JT4,$KA4,$KH4,$KO4,$KV4,$LC4,$LJ4,$LQ4,$LX4,$ME4,$ML4,$MS4,$MZ4,$NG4,$NN4,$NU4,$OB4,$OI4,$OP4,$OW4,$PD4,$PK4,$PR4,$PY4,$QF4,$QM4,$QT4,$RA4,$RH4,$RO4,$RV4,$SC4,$SJ4,$SQ4,$SX4,$TE4,$TL4,$TS4,$TZ4,$UG4,$UN4,$UU4,$VB4,$VI4,$VP4) -> 0 | WC4: =MEDIAN($H4,$O4,$V4,$AC4,$AJ4,$AQ4,$AX4,$BE4,$BL4,$BS4,$BZ4,$CG4,$CN4,$CU4,$DB4,$DI4,$DP4,$DW4,$ED4,$EK4,$ER4,$EY4,$FF4,$FM4,$FT4,$GA4,$GH4,$GO4,$GV4,$HC4,$HJ4,$HQ4,$HX4,$IE4,$IL4,$IS4,$IZ4,$JG4,$JN4,$JU4,$KB4,$KI4,$KP4,$KW4,$LD4,$LK4,$LR4,$LY4,$MF4,$MM4,$MT4,$NA4,$NH4,$NO4,$NV4,$OC4,$OJ4,$OQ4,$OX4,$PE4,$PL4,$PS4,$PZ4,$QG4,$QN4,$QU4,$RB4,$RI4,$RP4,$RW4,$SD4,$SK4,$SR4,$SY4,$TF4,$TM4,$TT4,$UA4,$UH4,$UO4,$UV4,$VC4,$VJ4,$VQ4) -> 0 | WD4: =MAX($B4,$I4,$P4,$W4,$AD4,$AK4,$AR4,$AY4,$BF4,$BM4,$BT4,$CA4,$CH4,$CO4,$CV4,$DC4,$DJ4,$DQ4,$DX4,$EE4,$EL4,$ES4,$EZ4,$FG4,$FN4,$FU4,$GB4,$GI4,$GP4,$GW4,$HD4,$HK4,$HR4,$HY4,$IF4,$IM4,$IT4,$JA4,$JH4,$JO4,$JV4,$KC4,$KJ4,$KQ4,$KX4,$LE4,$LL4,$LS4,$LZ4,$MG4,$MN4,$MU4,$NB4,$NI4,$NP4,$NW4,$OD4,$OK4,$OR4,$OY4,$PF4,$PM4,$PT4,$QA4,$QH4,$QO4,$QV4,$RC4,$RJ4,$RQ4,$RX4,$SE4,$SL4,$SS4,$SZ4,$TG4,$TN4,$TU4,$UB4,$UI4,$UP4,$UW4,$VD4,$VK4) -> 0 | WE4: =MAX($C4,$J4,$Q4,$X4,$AE4,$AL4,$AS4,$AZ4,$BG4,$BN4,$BU4,$CB4,$CI4,$CP4,$CW4,$DD4,$DK4,$DR4,$DY4,$EF4,$EM4,$ET4,$FA4,$FH4,$FO4,$FV4,$GC4,$GJ4,$GQ4,$GX4,$HE4,$HL4,$HS4,$HZ4,$IG4,$IN4,$IU4,$JB4,$JI4,$JP4,$JW4,$KD4,$KK4,$KR4,$KY4,$LF4,$LM4,$LT4,$MA4,$MH4,$MO4,$MV4,$NC4,$NJ4,$NQ4,$NX4,$OE4,$OL4,$OS4,$OZ4,$PG4,$PN4,$PU4,$QB4,$QI4,$QP4,$QW4,$RD4,$RK4,$RR4,$RY4,$SF4,$SM4,$ST4,$TA4,$TH4,$TO4,$TV4,$UC4,$UJ4,$UQ4,$UX4,$VE4,$VL4) -> 0 | WF4: =MAX($E4,$L4,$S4,$Z4,$AG4,$AN4,$AU4,$BB4,$BI4,$BP4,$BW4,$CD4,$CK4,$CR4,$CY4,$DF4,$DM4,$DT4,$EA4,$EH4,$EO4,$EV4,$FC4,$FJ4,$FQ4,$FX4,$GE4,$GL4,$GS4,$GZ4,$HG4,$HN4,$HU4,$IB4,$II4,$IP4,$IW4,$JD4,$JK4,$JR4,$JY4,$KF4,$KM4,$KT4,$LA4,$LH4,$LO4,$LV4,$MC4,$MJ4,$MQ4,$MX4,$NE4,$NL4,$NS4,$NZ4,$OG4,$ON4,$OU4,$PB4,$PI4,$PP4,$PW4,$QD4,$QK4,$QR4,$QY4,$RF4,$RM4,$RT4,$SA4,$SH4,$SO4,$SV4,$TC4,$TJ4,$TQ4,$TX4,$UE4,$UL4,$US4,$UZ4,$VG4,$VN4) -> 0 | WG4: =MAX($F4,$M4,$T4,$AA4,$AH4,$AO4,$AV4,$BC4,$BJ4,$BQ4,$BX4,$CE4,$CL4,$CS4,$CZ4,$DG4,$DN4,$DU4,$EB4,$EI4,$EP4,$EW4,$FD4,$FK4,$FR4,$FY4,$GF4,$GM4,$GT4,$HA4,$HH4,$HO4,$HV4,$IC4,$IJ4,$IQ4,$IX4,$JE4,$JL4,$JS4,$JZ4,$KG4,$KN4,$KU4,$LB4,$LI4,$LP4,$LW4,$MD4,$MK4,$MR4,$MY4,$NF4,$NM4,$NT4,$OA4,$OH4,$OO4,$OV4,$PC4,$PJ4,$PQ4,$PX4,$QE4,$QL4,$QS4,$QZ4,$RG4,$RN4,$RU4,$SB4,$SI4,$SP4,$SW4,$TD4,$TK4,$TR4,$TY4,$UF4,$UM4,$UT4,$VA4,$VH4,$VO4) -> 0 | WH4: =MAX($G4,$N4,$U4,$AB4,$AI4,$AP4,$AW4,$BD4,$BK4,$BR4,$BY4,$CF4,$CM4,$CT4,$DA4,$DH4,$DO4,$DV4,$EC4,$EJ4,$EQ4,$EX4,$FE4,$FL4,$FS4,$FZ4,$GG4,$GN4,$GU4,$HB4,$HI4,$HP4,$HW4,$ID4,$IK4,$IR4,$IY4,$JF4,$JM4,$JT4,$KA4,$KH4,$KO4,$KV4,$LC4,$LJ4,$LQ4,$LX4,$ME4,$ML4,$MS4,$MZ4,$NG4,$NN4,$NU4,$OB4,$OI4,$OP4,$OW4,$PD4,$PK4,$PR4,$PY4,$QF4,$QM4,$QT4,$RA4,$RH4,$RO4,$RV4,$SC4,$SJ4,$SQ4,$SX4,$TE4,$TL4,$TS4,$TZ4,$UG4,$UN4,$UU4,$VB4,$VI4,$VP4) -> 0 | WI4: =MAX($H4,$O4,$V4,$AC4,$AJ4,$AQ4,$AX4,$BE4,$BL4,$BS4,$BZ4,$CG4,$CN4,$CU4,$DB4,$DI4,$DP4,$DW4,$ED4,$EK4,$ER4,$EY4,$FF4,$FM4,$FT4,$GA4,$GH4,$GO4,$GV4,$HC4,$HJ4,$HQ4,$HX4,$IE4,$IL4,$IS4,$IZ4,$JG4,$JN4,$JU4,$KB4,$KI4,$KP4,$KW4,$LD4,$LK4,$LR4,$LY4,$MF4,$MM4,$MT4,$NA4,$NH4,$NO4,$NV4,$OC4,$OJ4,$OQ4,$OX4,$PE4,$PL4,$PS4,$PZ4,$QG4,$QN4,$QU4,$RB4,$RI4,$RP4,$RW4,$SD4,$SK4,$SR4,$SY4,$TF4,$TM4,$TT4,$UA4,$UH4,$UO4,$UV4,$VC4,$VJ4,$VQ4) -> 0
A5: instances/warehouse_x8_y8_a3 | B5: 1200 | C5: 1176.36 | D5: UNKNOWN | E5: 9094947 | F5: 1199.14 | G5: 0 | H5: 0 | I5: 1200 | O5: 0 | P5: 1200 | Q5: 1192.99 | R5: UNKNOWN | S5: 989367 | T5: 1199.124 | U5: 0 | V5: 0 | W5: 1200 | X5: 1188.88 | Y5: UNKNOWN | Z5: 2301247 | AA5: 1199.132 | AB5: 0 | AC5: 0 | AD5: 1200 | AJ5: 0 | AK5: 1200 | AQ5: 0 | AR5: 1200 | AX5: 0 | AY5: 1200 | BE5: 0 | BF5: 1200 | BL5: 0 | BM5: 1200 | BS5: 0 | BT5: 1200 | BZ5: 0 | CA5: 1200 | CG5: 0 | CH5: 1200 | CN5: 0 | CO5: 1200 | CU5: 0 | CV5: 1200 | DB5: 0 | DC5: 1200 | DI5: 0 | DJ5: 1200 | DP5: 0 | DQ5: 821.73 | DR5: 387.81 | DS5: SATISFIABLE | DT5: 101111277 | DU5: 819.113 | DV5: 387.59 | DW5: 0 | DX5: 1200 | ED5: 0 | EE5: 1200 | EK5: 0 | EL5: 662.86 | EM5: 351.4 | EN5: SATISFIABLE | EO5: 49523672 | EP5: 660.562 | EQ5: 351.31 | ER5: 0 | ES5: 1200 | EY5: 0 | EZ5: 10.74 | FA5: 0 | FB5: UNSATISFIABLE | FC5: 5657598 | FD5: 9.208 | FE5: 0 | FF5: 0 | FG5: 404.71 | FH5: 184.6 | FI5: SATISFIABLE | FJ5: 8747472 | FK5: 402.597 | FL5: 184.58 | FM5: 0 | FN5: 1200 | FT5: 0 | FU5: 1200 | GA5: 0 | GB5: 1200 | GH5: 0 | GI5: 1200 | GO5: 0 | GP5: 1200 | GV5: 0 | GW5: 1200 | HC5: 0 | HD5: 1200 | HJ5: 0 | HK5: 1200 | HQ5: 0 | HR5: 1200 | HX5: 0 | HY5: 1200 | IE5: 0 | IF5: 1200 | IL5: 0 | IM5: 1200 | IS5: 0 | IT5: 145.51 | IU5: 113.56 | IV5: SATISFIABLE | IW5: 959494 | IX5: 144.133 | IY5: 113.54 | IZ5: 0 | JA5: 107.81 | JB5: 77.08 | JC5: SATISFIABLE | JD5: 959494 | JE5: 106.372 | JF5: 77.07 | JG5: 0 | JH5: 1200 | JN5: 0 | JO5: 1200 | JU5: 0 | JV5: 96.34 | JW5: 41.96 | JX5: SATISFIABLE | JY5: 1262189 | JZ5: 94.727 | KA5: 41.94 | KB5: 0 | KC5: 159.99 | KD5: 96.48 | KE5: SATISFIABLE | KF5: 1262189 | KG5: 158.235 | KH5: 96.45 | KI5: 0 | KJ5: 67.76 | KK5: 3.5 | KL5: SATISFIABLE | KM5: 1262189 | KN5: 66.08 | KO5: 3.49 | KP5: 0 | KQ5: 99.83 | KR5: 37.24 | KS5: SATISFIABLE | KT5: 1262189 | KU5: 98.069 | KV5: 37.22 | KW5: 0 | KX5: 1200 | LD5: 0 | LE5: 1200 | LK5: 0 | LL5: 119.97 | LM5: 0 | LN5: UNSATISFIABLE | LO5: 3209918 | LP5: 118.037 | LQ5: 0 | LR5: 0 | LS5: 146.38 | LT5: 27 | LU5: SATISFIABLE | LV5: 1604959 | LW5: 144.627 | LX5: 26.98 | LY5: 0 | LZ5: 1200 | MF5: 0 | MG5: 1200 | MM5: 0 | MN5: 1200 | MT5: 0 | MU5: 1200 | NA5: 0 | NB5: 1200 | NH5: 0 | NI5: 1200 | NO5: 0 | NP5: 1200 | NV5: 0 | NW5: 1200 | OC5: 0 | OD5: 199.5 | OE5: 191.83 | OF5: SATISFIABLE | OG5: 474329 | OH5: 198.374 | OI5: 191.82 | OJ5: 0 | OK5: 194.75 | OL5: 187.84 | OM5: SATISFIABLE | ON5: 474329 | OO5: 193.715 | OP5: 187.84 | OQ5: 0 | OR5: 1200 | OX5: 0 | OY5: 174.27 | OZ5: 166.49 | PA5: SATISFIABLE | PB5: 474329 | PC5: 173.014 | PD5: 166.48 | PE5: 0 | PF5: 107.91 | PG5: 92.45 | PH5: SATISFIABLE | PI5: 696874 | PJ5: 106.631 | PK5: 92.44 | PL5: 0 | PM5: 113.04 | PN5: 96.22 | PO5: SATISFIABLE | PP5: 696874 | PQ5: 111.679 | PR5: 96.21 | PS5: 0 | PT5: 46.18 | PU5: 30.11 | PV5: SATISFIABLE | PW5: 696874 | PX5: 44.826 | PY5: 30.1 | PZ5: 0 | QA5: 95.05 | QB5: 77.03 | QC5: SATISFIABLE | QD5: 696874 | QE5: 93.669 | QF5: 77.02 | QG5: 0 | QH5: 356.7 | QI5: 328.45 | QJ5: SATISFIABLE | QK5: 959494 | QL5: 355.148 | QM5: 328.44 | QN5: 0 | QO5: 410.98 | QP5: 383.1 | QQ5: SATISFIABLE | QR5: 959494 | QS5: 409.663 | QT5: 383.04 | QU5: 0 | QV5: 34.99 | QW5: 8.53 | QX5: SATISFIABLE | QY5: 959494 | QZ5: 33.49 | RA5: 8.51 | RB5: 0 | RC5: 68.07 | RD5: 38.39 | RE5: SATISFIABLE | RF5: 959494 | RG5: 66.598 | RH5: 38.38 | RI5: 0 | RJ5: 1200 | RP5: 0 | RQ5: 1200 | RW5: 0 | RX5: 1200 | SD5: 0 | SE5: 1200 | SK5: 0 | SL5: 1200 | SR5: 0 | SS5: 1200 | SY5: 0 | SZ5: 1200 | TF5: 0 | TG5: 1200 | TM5: 0 | TN5: 149.35 | TO5: 18.49 | TP5: SATISFIABLE | TQ5: 1987804 | TR5: 147.476 | TS5: 18.48 | TT5: 0 | TU5: 181.15 | TV5: 48.15 | TW5: SATISFIABLE | TX5: 1987804 | TY5: 179.171 | TZ5: 48.14 | UA5: 0 | UB5: 134.95 | UC5: 0 | UD5: UNSATISFIABLE | UE5: 1987804 | UF5: 133.002 | UG5: 0 | UH5: 0 | UI5: 154.22 | UJ5: 23 | UK5: SATISFIABLE | UL5: 1987804 | UM5: 152.305 | UN5: 22.98 | UO5: 0 | UP5: 301.55 | UQ5: 34.36 | UR5: SATISFIABLE | US5: 2410724 | UT5: 299.663 | UU5: 34.35 | UV5: 0 | UW5: 343.61 | UX5: 74.57 | UY5: SATISFIABLE | UZ5: 2410724 | VA5: 341.645 | VB5: 74.55 | VC5: 0 | VD5: 280.45 | VE5: 0 | VF5: UNSATISFIABLE | VG5: 2410724 | VH5: 278.195 | VI5: 0 | VJ5: 0 | VK5: 547.16 | VL5: 278.77 | VM5: SATISFIABLE | VN5: 2410724 | VO5: 545.321 | VP5: 278.75 | VQ5: 0 | VR5: =MIN($B5,$I5,$P5,$W5,$AD5,$AK5,$AR5,$AY5,$BF5,$BM5,$BT5,$CA5,$CH5,$CO5,$CV5,$DC5,$DJ5,$DQ5,$DX5,$EE5,$EL5,$ES5,$EZ5,$FG5,$FN5,$FU5,$GB5,$GI5,$GP5,$GW5,$HD5,$HK5,$HR5,$HY5,$IF5,$IM5,$IT5,$JA5,$JH5,$JO5,$JV5,$KC5,$KJ5,$KQ5,$KX5,$LE5,$LL5,$LS5,$LZ5,$MG5,$MN5,$MU5,$NB5,$NI5,$NP5,$NW5,$OD5,$OK5,$OR5,$OY5,$PF5,$PM5,$PT5,$QA5,$QH5,$QO5,$QV5,$RC5,$RJ5,$RQ5,$RX5,$SE5,$SL5,$SS5,$SZ5,$TG5,$TN5,$TU5,$UB5,$UI5,$UP5,$UW5,$VD5,$VK5) -> 0 | VS5: =MIN($C5,$J5,$Q5,$X5,$AE5,$AL5,$AS5,$AZ5,$BG5,$BN5,$BU5,$CB5,$CI5,$CP5,$CW5,$DD5,$DK5,$DR5,$DY5,$EF5,$EM5,$ET5,$FA5,$FH5,$FO5,$FV5,$GC5,$GJ5,$GQ5,$GX5,$HE5,$HL5,$HS5,$HZ5,$IG5,$IN5,$IU5,$JB5,$JI5,$JP5,$JW5,$KD5,$KK5,$KR5,$KY5,$LF5,$LM5,$LT5,$MA5,$MH5,$MO5,$MV5,$NC5,$NJ5,$NQ5,$NX5,$OE5,$OL5,$OS5,$OZ5,$PG5,$PN5,$PU5,$QB5,$QI5,$QP5,$QW5,$RD5,$RK5,$RR5,$RY5,$SF5,$SM5,$ST5,$TA5,$TH5,$TO5,$TV5,$UC5,$UJ5,$UQ5,$UX5,$VE5,$VL5) -> 0 | VT5: =MIN($E5,$L5,$S5,$Z5,$AG5,$AN5,$AU5,$BB5,$BI5,$BP5,$BW5,$CD5,$CK5,$CR5,$CY5,$DF5,$DM5,$DT5,$EA5,$EH5,$EO5,$EV5,$FC5,$FJ5,$FQ5,$FX5,$GE5,$GL5,$GS5,$GZ5,$HG5,$HN5,$HU5,$IB5,$II5,$IP5,$IW5,$JD5,$JK5,$JR5,$JY5,$KF5,$KM5,$KT5,$LA5,$LH5,$LO5,$LV5,$MC5,$MJ5,$MQ5,$MX5,$NE5,$NL5,$NS5,$NZ5,$OG5,$ON5,$OU5,$PB5,$PI5,$PP5,$PW5,$QD5,$QK5,$QR5,$QY5,$RF5,$RM5,$RT5,$SA5,$SH5,$SO5,$SV5,$TC5,$TJ5,$TQ5,$TX5,$UE5,$UL5,$US5,$UZ5,$VG5,$VN5) -> 0 | VU5: =MIN($F5,$M5,$T5,$AA5,$AH5,$AO5,$AV5,$BC5,$BJ5,$BQ5,$BX5,$CE5,$CL5,$CS5,$CZ5,$DG5,$DN5,$DU5,$EB5,$EI5,$EP5,$EW5,$FD5,$FK5,$FR5,$FY5,$GF5,$GM5,$GT5,$HA5,$HH5,$HO5,$HV5,$IC5,$IJ5,$IQ5,$IX5,$JE5,$JL5,$JS5,$JZ5,$KG5,$KN5,$KU5,$LB5,$LI5,$LP5,$LW5,$MD5,$MK5,$MR5,$MY5,$NF5,$NM5,$NT5,$OA5,$OH5,$OO5,$OV5,$PC5,$PJ5,$PQ5,$PX5,$QE5,$QL5,$QS5,$QZ5,$RG5,$RN5,$RU5,$SB5,$SI5,$SP5,$SW5,$TD5,$TK5,$TR5,$TY5,$UF5,$UM5,$UT5,$VA5,$VH5,$VO5) -> 0 | VV5: =MIN($G5,$N5,$U5,$AB5,$AI5,$AP5,$AW5,$BD5,$BK5,$BR5,$BY5,$CF5,$CM5,$CT5,$DA5,$DH5,$DO5,$DV5,$EC5,$EJ5,$EQ5,$EX5,$FE5,$FL5,$FS5,$FZ5,$GG5,$GN5,$GU5,$HB5,$HI5,$HP5,$HW5,$ID5,$IK5,$IR5,$IY5,$JF5,$JM5,$JT5,$KA5,$KH5,$KO5,$KV5,$LC5,$LJ5,$LQ5,$LX5,$ME5,$ML5,$MS5,$MZ5,$NG5,$NN5,$NU5,$OB5,$OI5,$OP5,$OW5,$PD5,$PK5,$PR5,$PY5,$QF5,$QM5,$QT5,$RA5,$RH5,$RO5,$RV5,$SC5,$SJ5,$SQ5,$SX5,$TE5,$TL5,$TS5,$TZ5,$UG5,$UN5,$UU5,$VB5,$VI5,$VP5) -> 0 | VW5: =MIN($H5,$O5,$V5,$AC5,$AJ5,$AQ5,$AX5,$BE5,$BL5,$BS5,$BZ5,$CG5,$CN5,$CU5,$DB5,$DI5,$DP5,$DW5,$ED5,$EK5,$ER5,$EY5,$FF5,$FM5,$FT5,$GA5,$GH5,$GO5,$GV5,$HC5,$HJ5,$HQ5,$HX5,$IE5,$IL5,$IS5,$IZ5,$JG5,$JN5,$JU5,$KB5,$KI5,$KP5,$KW5,$LD5,$LK5,$LR5,$LY5,$MF5,$MM5,$MT5,$NA5,$NH5,$NO5,$NV5,$OC5,$OJ5,$OQ5,$OX5,$PE5,$PL5,$PS5,$PZ5,$QG5,$QN5,$QU5,$RB5,$RI5,$RP5,$RW5,$SD5,$SK5,$SR5,$SY5,$TF5,$TM5,$TT5,$UA5,$UH5,$UO5,$UV5,$VC5,$VJ5,$VQ5) -> 0 | VX5: =MEDIAN($B5,$I5,$P5,$W5,$AD5,$AK5,$AR5,$AY5,$BF5,$BM5,$BT5,$CA5,$CH5,$CO5,$CV5,$DC5,$DJ5,$DQ5,$DX5,$EE5,$EL5,$ES5,$EZ5,$FG5,$FN5,$FU5,$GB5,$GI5,$GP5,$GW5,$HD5,$HK5,$HR5,$HY5,$IF5,$IM5,$IT5,$JA5,$JH5,$JO5,$JV5,$KC5,$KJ5,$KQ5,$KX5,$LE5,$LL5,$LS5,$LZ5,$MG5,$MN5,$MU5,$NB5,$NI5,$NP5,$NW5,$OD5,$OK5,$OR5,$OY5,$PF5,$PM5,$PT5,$QA5,$QH5,$QO5,$QV5,$RC5,$RJ5,$RQ5,$RX5,$SE5,$SL5,$SS5,$SZ5,$TG5,$TN5,$TU5,$UB5,$UI5,$UP5,$UW5,$VD5,$VK5) -> 0 | VY5: =MEDIAN($C5,$J5,$Q5,$X5,$AE5,$AL5,$AS5,$AZ5,$BG5,$BN5,$BU5,$CB5,$CI5,$CP5,$CW5,$DD5,$DK5,$DR5,$DY5,$EF5,$EM5,$ET5,$FA5,$FH5,$FO5,$FV5,$GC5,$GJ5,$GQ5,$GX5,$HE5,$HL5,$HS5,$HZ5,$IG5,$IN5,$IU5,$JB5,$JI5,$JP5,$JW5,$KD5,$KK5,$KR5,$KY5,$LF5,$LM5,$LT5,$MA5,$MH5,$MO5,$MV5,$NC5,$NJ5,$NQ5,$NX5,$OE5,$OL5,$OS5,$OZ5,$PG5,$PN5,$PU5,$QB5,$QI5,$QP5,$QW5,$RD5,$RK5,$RR5,$RY5,$SF5,$SM5,$ST5,$TA5,$TH5,$TO5,$TV5,$UC5,$UJ5,$UQ5,$UX5,$VE5,$VL5) -> 0 | VZ5: =MEDIAN($E5,$L5,$S5,$Z5,$AG5,$AN5,$AU5,$BB5,$BI5,$BP5,$BW5,$CD5,$CK5,$CR5,$CY5,$DF5,$DM5,$DT5,$EA5,$EH5,$EO5,$EV5,$FC5,$FJ5,$FQ5,$FX5,$GE5,$GL5,$GS5,$GZ5,$HG5,$HN5,$HU5,$IB5,$II5,$IP5,$IW5,$JD5,$JK5,$JR5,$JY5,$KF5,$KM5,$KT5,$LA5,$LH5,$LO5,$LV5,$MC5,$MJ5,$MQ5,$MX5,$NE5,$NL5,$NS5,$NZ5,$OG5,$ON5,$OU5,$PB5,$PI5,$PP5,$PW5,$QD5,$QK5,$QR5,$QY5,$RF5,$RM5,$RT5,$SA5,$SH5,$SO5,$SV5,$TC5,$TJ5,$TQ5,$TX5,$UE5,$UL5,$US5,$UZ5,$VG5,$VN5) -> 0 | WA5: =MEDIAN($F5,$M5,$T5,$AA5,$AH5,$AO5,$AV5,$BC5,$BJ5,$BQ5,$BX5,$CE5,$CL5,$CS5,$CZ5,$DG5,$DN5,$DU5,$EB5,$EI5,$EP5,$EW5,$FD5,$FK5,$FR5,$FY5,$GF5,$GM5,$GT5,$HA5,$HH5,$HO5,$HV5,$IC5,$IJ5,$IQ5,$IX5,$JE5,$JL5,$JS5,$JZ5,$KG5,$KN5,$KU5,$LB5,$LI5,$LP5,$LW5,$MD5,$MK5,$MR5,$MY5,$NF5,$NM5,$NT5,$OA5,$OH5,$OO5,$OV5,$PC5,$PJ5,$PQ5,$PX5,$QE5,$QL5,$QS5,$QZ5,$RG5,$RN5,$RU5,$SB5,$SI5,$SP5,$SW5,$TD5,$TK5,$TR5,$TY5,$UF5,$UM5,$UT5,$VA5,$VH5,$VO5) -> 0 | WB5: =MEDIAN($G5,$N5,$U5,$AB5,$AI5,$AP5,$AW5,$BD5,$BK5,$BR5,$BY5,$CF5,$CM5,$CT5,$DA5,$DH5,$DO5,$DV5,$EC5,$EJ5,$EQ5,$EX5,$FE5,$FL5,$FS5,$FZ5,$GG5,$GN5,$GU5,$HB5,$HI5,$HP5,$HW5,$ID5,$IK5,$IR5,$IY5,$JF5,$JM5,$JT5,$KA5,$KH5,$KO5,$KV5,$LC5,$LJ5,$LQ5,$LX5,$ME5,$ML5,$MS5,$MZ5,$NG5,$NN5,$NU5,$OB5,$OI5,$OP5,$OW5,$PD5,$PK5,$PR5,$PY5,$QF5,$QM5,$QT5,$RA5,$RH5,$RO5,$RV5,$SC5,$SJ5,$SQ5,$SX5,$TE5,$TL5,$TS5,$TZ5,$UG5,$UN5,$UU5,$VB5,$VI5,$VP5) -> 0 | WC5: =MEDIAN($H5,$O5,$V5,$AC5,$AJ5,$AQ5,$AX5,$BE5,$BL5,$BS5,$BZ5,$CG5,$CN5,$CU5,$DB5,$DI5,$DP5,$DW5,$ED5,$EK5,$ER5,$EY5,$FF5,$FM5,$FT5,$GA5,$GH5,$GO5,$GV5,$HC5,$HJ5,$HQ5,$HX5,$IE5,$IL5,$IS5,$IZ5,$JG5,$JN5,$JU5,$KB5,$KI5,$KP5,$KW5,$LD5,$LK5,$LR5,$LY5,$MF5,$MM5,$MT5,$NA5,$NH5,$NO5,$NV5,$OC5,$OJ5,$OQ5,$OX5,$PE5,$PL5,$PS5,$PZ5,$QG5,$QN5,$QU5,$RB5,$RI5,$RP5,$RW5,$SD5,$SK5,$SR5,$SY5,$TF5,$TM5,$TT5,$UA5,$UH5,$UO5,$UV5,$VC5,$VJ5,$VQ5) -> 0 | WD5: =MAX($B5,$I5,$P5,$W5,$AD5,$AK5,$AR5,$AY5,$BF5,$BM5,$BT5,$CA5,$CH5,$CO5,$CV5,$DC5,$DJ5,$DQ5,$DX5,$EE5,$EL5,$ES5,$EZ5,$FG5,$FN5,$FU5,$GB5,$GI5,$GP5,$GW5,$HD5,$HK5,$HR5,$HY5,$IF5,$IM5,$IT5,$JA5,$JH5,$JO5,$JV5,$KC5,$KJ5,$KQ5,$KX5,$LE5,$LL5,$LS5,$LZ5,$MG5,$MN5,$MU5,$NB5,$NI5,$NP5,$NW5,$OD5,$OK5,$OR5,$OY5,$PF5,$PM5,$PT5,$QA5,$QH5,$QO5,$QV5,$RC5,$RJ5,$RQ5,$RX5,$SE5,$SL5,$SS5,$SZ5,$TG5,$TN5,$TU5,$UB5,$UI5,$UP5,$UW5,$VD5,$VK5) -> 0 | WE5: =MAX($C5,$J5,$Q5,$X5,$AE5,$AL5,$AS5,$AZ5,$BG5,$BN5,$BU5,$CB5,$CI5,$CP5,$CW5,$DD5,$DK5,$DR5,$DY5,$EF5,$EM5,$ET5,$FA5,$FH5,$FO5,$FV5,$GC5,$GJ5,$GQ5,$GX5,$HE5,$HL5,$HS5,$HZ5,$IG5,$IN5,$IU5,$JB5,$JI5,$JP5,$JW5,$KD5,$KK5,$KR5,$KY5,$LF5,$LM5,$LT5,$MA5,$MH5,$MO5,$MV5,$NC5,$NJ5,$NQ5,$NX5,$OE5,$OL5,$OS5,$OZ5,$PG5,$PN5,$PU5,$QB5,$QI5,$QP5,$QW5,$RD5,$RK5,$RR5,$RY5,$SF5,$SM5,$ST5,$TA5,$TH5,$TO5,$TV5,$UC5,$UJ5,$UQ5,$UX5,$VE5,$VL5) -> 0 | WF5: =MAX($E5,$L5,$S5,$Z5,$AG5,$AN5,$AU5,$BB5,$BI5,$BP5,$BW5,$CD5,$CK5,$CR5,$CY5,$DF5,$DM5,$DT5,$EA5,$EH5,$EO5,$EV5,$FC5,$FJ5,$FQ5,$FX5,$GE5,$GL5,$GS5,$GZ5,$HG5,$HN5,$HU5,$IB5,$II5,$IP5,$IW5,$JD5,$JK5,$JR5,$JY5,$KF5,$KM5,$KT5,$LA5,$LH5,$LO5,$LV5,$MC5,$MJ5,$MQ5,$MX5,$NE5,$NL5,$NS5,$NZ5,$OG5,$ON5,$OU5,$PB5,$PI5,$PP5,$PW5,$QD5,$QK5,$QR5,$QY5,$RF5,$RM5,$RT5,$SA5,$SH5,$SO5,$SV5,$TC5,$TJ5,$TQ5,$TX5,$UE5,$UL5,$US5,$UZ5,$VG5,$VN5) -> 0 | WG5: =MAX($F5,$M5,$T5,$AA5,$AH5,$AO5,$AV5,$BC5,$BJ5,$BQ5,$BX5,$CE5,$CL5,$CS5,$CZ5,$DG5,$DN5,$DU5,$EB5,$EI5,$EP5,$EW5,$FD5,$FK5,$FR5,$FY5,$GF5,$GM5,$GT5,$HA5,$HH5,$HO5,$HV5,$IC5,$IJ5,$IQ5,$IX5,$JE5,$JL5,$JS5,$JZ5,$KG5,$KN5,$KU5,$LB5,$LI5,$LP5,$LW5,$MD5,$MK5,$MR5,$MY5,$NF5,$NM5,$NT5,$OA5,$OH5,$OO5,$OV5,$PC5,$PJ5,$PQ5,$PX5,$QE5,$QL5,$QS5,$QZ5,$RG5,$RN5,$RU5,$SB5,$SI5,$SP5,$SW5,$TD5,$TK5,$TR5,$TY5,$UF5,$UM5,$UT5,$VA5,$VH5,$VO5) -> 0 | WH5: =MAX($G5,$N5,$U5,$AB5,$AI5,$AP5,$AW5,$BD5,$BK5,$BR5,$BY5,$CF5,$CM5,$CT5,$DA5,$DH5,$DO5,$DV5,$EC5,$EJ5,$EQ5,$EX5,$FE5,$FL5,$FS5,$FZ5,$GG5,$GN5,$GU5,$HB5,$HI5,$HP5,$HW5,$ID5,$IK5,$IR5,$IY5,$JF5,$JM5,$JT5,$KA5,$KH5,$KO5,$KV5,$LC5,$LJ5,$LQ5,$LX5,$ME5,$ML5,$MS5,$MZ5,$NG5,$NN5,$NU5,$OB5,$OI5,$OP5,$OW5,$PD5,$PK5,$PR5,$PY5,$QF5,$QM5,$QT5,$RA5,$RH5,$RO5,$RV5,$SC5,$SJ5,$SQ5,$SX5,$TE5,$TL5,$TS5,$TZ5,$UG5,$UN5,$UU5,$VB5,$VI5,$VP5) -> 0 | WI5: =MAX($H5,$O5,$V5,$AC5,$AJ5,$AQ5,$AX5,$BE5,$BL5,$BS5,$BZ5,$CG5,$CN5,$CU5,$DB5,$DI5,$DP5,$DW5,$ED5,$EK5,$ER5,$EY5,$FF5,$FM5,$FT5,$GA5,$GH5,$GO5,$GV5,$HC5,$HJ5,$HQ5,$HX5,$IE5,$IL5,$IS5,$IZ5,$JG5,$JN5,$JU5,$KB5,$KI5,$KP5,$KW5,$LD5,$LK5,$LR5,$LY5,$MF5,$MM5,$MT5,$NA5,$NH5,$NO5,$NV5,$OC5,$OJ5,$OQ5,$OX5,$PE5,$PL5,$PS5,$PZ5,$QG5,$QN5,$QU5,$RB5,$RI5,$RP5,$RW5,$SD5,$SK5,$SR5,$SY5,$TF5,$TM5,$TT5,$UA5,$UH5,$UO5,$UV5,$VC5,$VJ5,$VQ5) -> 0
A7: SUM | B7: =SUM(B$3:B$5) -> 0 | C7: =SUM(C$3:C$5) -> 0 | E7: =SUM(E$3:E$5) -> 0 | F7: =SUM(F$3:F$5) -> 0 | G7: =SUM(G$3:G$5) -> 0 | H7: =SUM(H$3:H$5) -> 0 | I7: =SUM(I$3:I$5) -> 0 | J7: =SUM(J$3:J$5) -> 0 | L7: =SUM(L$3:L$5) -> 0 | M7: =SUM(M$3:M$5) -> 0 | N7: =SUM(N$3:N$5) -> 0 | O7: =SUM(O$3:O$5) -> 0 | P7: =SUM(P$3:P$5) -> 0 | Q7: =SUM(Q$3:Q$5) -> 0 | S7: =SUM(S$3:S$5) -> 0 | T7: =SUM(T$3:T$5) -> 0 | U7: =SUM(U$3:U$5) -> 0 | V7: =SUM(V$3:V$5) -> 0 | W7: =SUM(W$3:W$5) -> 0 | X7: =SUM(X$3:X$5) -> 0 | Z7: =SUM(Z$3:Z$5) -> 0 | AA7: =SUM(AA$3:AA$5) -> 0 | AB7: =SUM(AB$3:AB$5) -> 0 | AC7: =SUM(AC$3:AC$5) -> 0 | AD7: =SUM(AD$3:AD$5) -> 0 | AJ7: =SUM(AJ$3:AJ$5) -> 0 | AK7: =SUM(AK$3:AK$5) -> 0 | AQ7: =SUM(AQ$3:AQ$5) -> 0 | AR7: =SUM(AR$3:AR$5) -> 0 | AX7: =SUM(AX$3:AX$5) -> 0 | AY7: =SUM(AY$3:AY$5) -> 0 | BE7: =SUM(BE$3:BE$5) -> 0 | BF7: =SUM(BF$3:BF$5) -> 0 | BL7: =SUM(BL$3:BL$5) -> 0 | BM7: =SUM(BM$3:BM$5) -> 0 | BS7: =SUM(BS$3:BS$5) -> 0 | BT7: =SUM(BT$3:BT$5) -> 0 | BZ7: =SUM(BZ$3:BZ$5) -> 0 | CA7: =SUM(CA$3:CA$5) -> 0 | CG7: =SUM(CG$3:CG$5) -> 0 | CH7: =SUM(CH$3:CH$5) -> 0 | CN7: =SUM(CN$3:CN$5) -> 0 | CO7: =SUM(CO$3:CO$5) -> 0 | CU7: =SUM(CU$3:CU$5) -> 0 | CV7: =SUM(CV$3:CV$5) -> 0 | DB7: =SUM(DB$3:DB$5) -> 0 | DC7: =SUM(DC$3:DC$5) -> 0 | DI7: =SUM(DI$3:DI$5) -> 0 | DJ7: =SUM(DJ$3:DJ$5) -> 0 | DP7: =SUM(DP$3:DP$5) -> 0 | DQ7: =SUM(DQ$3:DQ$5) -> 0 | DR7: =SUM(DR$3:DR$5) -> 0 | DT7: =SUM(DT$3:DT$5) -> 0 | DU7: =SUM(DU$3:DU$5) -> 0 | DV7: =SUM(DV$3:DV$5) -> 0 | DW7: =SUM(DW$3:DW$5) -> 0 | DX7: =SUM(DX$3:DX$5) -> 0 | ED7: =SUM(ED$3:ED$5) -> 0 | EE7: =SUM(EE$3:EE$5) -> 0 | EK7: =SUM(EK$3:EK$5) -> 0 | EL7: =SUM(EL$3:EL$5) -> 0 | EM7: =SUM(EM$3:EM$5) -> 0 | EO7: =SUM(EO$3:EO$5) -> 0 | EP7: =SUM(EP$3:EP$5) -> 0 | EQ7: =SUM(EQ$3:EQ$5) -> 0 | ER7: =SUM(ER$3:ER$5) -> 0 | ES7: =SUM(ES$3:ES$5) -> 0 | ET7: =SUM(ET$3:ET$5) -> 0 | EV7: =SUM(EV$3:EV$5) -> 0 | EW7: =SUM(EW$3:EW$5) -> 0 | EX7: =SUM(EX$3:EX$5) -> 0 | EY7: =SUM(EY$3:EY$5) -> 0 | EZ7: =SUM(EZ$3:EZ$5) -> 0 | FA7: =SUM(FA$3:FA$5) -> 0 | FC7: =SUM(FC$3:FC$5) -> 0 | FD7: =SUM(FD$3:FD$5) -> 0 | FE7: =SUM(FE$3:FE$5) -> 0 | FF7: =SUM(FF$3:FF$5) -> 0 | FG7: =SUM(FG$3:FG$5) -> 0 | FH7: =SUM(FH$3:FH$5) -> 0 | FJ7: =SUM(FJ$3:FJ$5) -> 0 | FK7: =SUM(FK$3:FK$5) -> 0 | FL7: =SUM(FL$3:FL$5) -> 0 | FM7: =SUM(FM$3:FM$5) -> 0 | FN7: =SUM(FN$3:FN$5) -> 0 | FT7: =SUM(FT$3:FT$5) -> 0 | FU7: =SUM(FU$3:FU$5) -> 0 | GA7: =SUM(GA$3:GA$5) -> 0 | GB7: =SUM(GB$3:GB$5) -> 0 | GH7: =SUM(GH$3:GH$5) -> 0 | GI7: =SUM(GI$3:GI$5) -> 0 | GO7: =SUM(GO$3:GO$5) -> 0 | GP7: =SUM(GP$3:GP$5) -> 0 | GV7: =SUM(GV$3:GV$5) -> 0 | GW7: =SUM(GW$3:GW$5) -> 0 | HC7: =SUM(HC$3:HC$5) -> 0 | HD7: =SUM(HD$3:HD$5) -> 0 | HJ7: =SUM(HJ$3:HJ$5) -> 0 | HK7: =SUM(HK$3:HK$5) -> 0 | HQ7: =SUM(HQ$3:HQ$5) -> 0 | HR7: =SUM(HR$3:HR$5) -> 0 | HX7: =SUM(HX$3:HX$5) -> 0 | HY7: =SUM(HY$3:HY$5) -> 0 | IE7: =SUM(IE$3:IE$5) -> 0 | IF7: =SUM(IF$3:IF$5) -> 0 | IL7: =SUM(IL$3:IL$5) -> 0 | IM7: =SUM(IM$3:IM$5) -> 0 | IS7: =SUM(IS$3:IS$5) -> 0 | IT7: =SUM(IT$3:IT$5) -> 0 | IU7: =SUM(IU$3:IU$5) -> 0 | IW7: =SUM(IW$3:IW$5) -> 0 | IX7: =SUM(IX$3:IX$5) -> 0 | IY7: =SUM(IY$3:IY$5) -> 0 | IZ7: =SUM(IZ$3:IZ$5) -> 0 | JA7: =SUM(JA$3:JA$5) -> 0 | JB7: =SUM(JB$3:JB$5) -> 0 | JD7: =SUM(JD$3:JD$5) -> 0 | JE7: =SUM(JE$3:JE$5) -> 0 | JF7: =SUM(JF$3:JF$5) -> 0 | JG7: =SUM(JG$3:JG$5) -> 0 | JH7: =SUM(JH$3:JH$5) -> 0 | JN7: =SUM(JN$3:JN$5) -> 0 | JO7: =SUM(JO$3:JO$5) -> 0 | JU7: =SUM(JU$3:JU$5) -> 0 | JV7: =SUM(JV$3:JV$5) -> 0 | JW7: =SUM(JW$3:JW$5) -> 0 | JY7: =SUM(JY$3:JY$5) -> 0 | JZ7: =SUM(JZ$3:JZ$5) -> 0 | KA7: =SUM(KA$3:KA$5) -> 0 | KB7: =SUM(KB$3:KB$5) -> 0 | KC7: =SUM(KC$3:KC$5) -> 0 | KD7: =SUM(KD$3:KD$5) -> 0 | KF7: =SUM(KF$3:KF$5) -> 0 | KG7: =SUM(KG$3:KG$5) -> 0 | KH7: =SUM(KH$3:KH$5) -> 0 | KI7: =SUM(KI$3:KI$5) -> 0 | KJ7: =SUM(KJ$3:KJ$5) -> 0 | KK7: =SUM(KK$3:KK$5) -> 0 | KM7: =SUM(KM$3:KM$5) -> 0 | KN7: =SUM(KN$3:KN$5) -> 0 | KO7: =SUM(KO$3:KO$5) -> 0 | KP7: =SUM(KP$3:KP$5) -> 0 | KQ7: =SUM(KQ$3:KQ$5) -> 0 | KR7: =SUM(KR$3:KR$5) -> 0 | KT7: =SUM(KT$3:KT$5) -> 0 | KU7: =SUM(KU$3:KU$5) -> 0 | KV7: =SUM(KV$3:KV$5) -> 0 | KW7: =SUM(KW$3:KW$5) -> 0 | KX7: =SUM(KX$3:KX$5) -> 0 | LD7: =SUM(LD$3:LD$5) -> 0 | LE7: =SUM(LE$3:LE$5) -> 0 | LK7: =SUM(LK$3:LK$5) -> 0 | LL7: =SUM(LL$3:LL$5) -> 0 | LM7: =SUM(LM$3:LM$5) -> 0 | LO7: =SUM(LO$3:LO$5) -> 0 | LP7: =SUM(LP$3:LP$5) -> 0 | LQ7: =SUM(LQ$3:LQ$5) -> 0 | LR7: =SUM(LR$3:LR$5) -> 0 | LS7: =SUM(LS$3:LS$5) -> 0 | LT7: =SUM(LT$3:LT$5) -> 0 | LV7: =SUM(LV$3:LV$5) -> 0 | LW7: =SUM(LW$3:LW$5) -> 0 | LX7: =SUM(LX$3:LX$5) -> 0 | LY7: =SUM(LY$3:LY$5) -> 0 | LZ7: =SUM(LZ$3:LZ$5) -> 0 | MF7: =SUM(MF$3:MF$5) -> 0 | MG7: =SUM(MG$3:MG$5) -> 0 | MM7: =SUM(MM$3:MM$5) -> 0 | MN7: =SUM(MN$3:MN$5) -> 0 | MT7: =SUM(MT$3:MT$5) -> 0 | MU7: =SUM(MU$3:MU$5) -> 0 | NA7: =SUM(NA$3:NA$5) -> 0 | NB7: =SUM(NB$3:NB$5) -> 0 | NH7: =SUM(NH$3:NH$5) -> 0 | NI7: =SUM(NI$3:NI$5) -> 0 | NO7: =SUM(NO$3:NO$5) -> 0 | NP7: =SUM(NP$3:NP$5) -> 0 | NV7: =SUM(NV$3:NV$5) -> 0 | NW7: =SUM(NW$3:NW$5) -> 0 | OC7: =SUM(OC$3:OC$5) -> 0 | OD7: =SUM(OD$3:OD$5) -> 0 | OE7: =SUM(OE$3:OE$5) -> 0 | OG7: =SUM(OG$3:OG$5) -> 0 | OH7: =SUM(OH$3:OH$5) -> 0 | OI7: =SUM(OI$3:OI$5) -> 0 | OJ7: =SUM(OJ$3:OJ$5) -> 0 | OK7: =SUM(OK$3:OK$5) -> 0 | OL7: =SUM(OL$3:OL$5) -> 0 | ON7: =SUM(ON$3:ON$5) -> 0 | OO7: =SUM(OO$3:OO$5) -> 0 | OP7: =SUM(OP$3:OP$5) -> 0 | OQ7: =SUM(OQ$3:OQ$5) -> 0 | OR7: =SUM(OR$3:OR$5) -> 0 | OX7: =SUM(OX$3:OX$5) -> 0 | OY7: =SUM(OY$3:OY$5) -> 0 | OZ7: =SUM(OZ$3:OZ$5) -> 0 | PB7: =SUM(PB$3:PB$5) -> 0 | PC7: =SUM(PC$3:PC$5) -> 0 | PD7: =SUM(PD$3:PD$5) -> 0 | PE7: =SUM(PE$3:PE$5) -> 0 | PF7: =SUM(PF$3:PF$5) -> 0 | PG7: =SUM(PG$3:PG$5) -> 0 | PI7: =SUM(PI$3:PI$5) -> 0 | PJ7: =SUM(PJ$3:PJ$5) -> 0 | PK7: =SUM(PK$3:PK$5) -> 0 | PL7: =SUM(PL$3:PL$5) -> 0 | PM7: =SUM(PM$3:PM$5) -> 0 | PN7: =SUM(PN$3:PN$5) -> 0 | PP7: =SUM(PP$3:PP$5) -> 0 | PQ7: =SUM(PQ$3:PQ$5) -> 0 | PR7: =SUM(PR$3:PR$5) -> 0 | PS7: =SUM(PS$3:PS$5) -> 0 | PT7: =SUM(PT$3:PT$5) -> 0 | PU7: =SUM(PU$3:PU$5) -> 0 | PW7: =SUM(PW$3:PW$5) -> 0 | PX7: =SUM(PX$3:PX$5) -> 0 | PY7: =SUM(PY$3:PY$5) -> 0 | PZ7: =SUM(PZ$3:PZ$5) -> 0 | QA7: =SUM(QA$3:QA$5) -> 0 | QB7: =SUM(QB$3:QB$5) -> 0 | QD7: =SUM(QD$3:QD$5) -> 0 | QE7: =SUM(QE$3:QE$5) -> 0 | QF7: =SUM(QF$3:QF$5) -> 0 | QG7: =SUM(QG$3:QG$5) -> 0 | QH7: =SUM(QH$3:QH$5) -> 0 | QI7: =SUM(QI$3:QI$5) -> 0 | QK7: =SUM(QK$3:QK$5) -> 0 | QL7: =SUM(QL$3:QL$5) -> 0 | QM7: =SUM(QM$3:QM$5) -> 0 | QN7: =SUM(QN$3:QN$5) -> 0 | QO7: =SUM(QO$3:QO$5) -> 0 | QP7: =SUM(QP$3:QP$5) -> 0 | QR7: =SUM(QR$3:QR$5) -> 0 | QS7: =SUM(QS$3:QS$5) -> 0 | QT7: =SUM(QT$3:QT$5) -> 0 | QU7: =SUM(QU$3:QU$5) -> 0 | QV7: =SUM(QV$3:QV$5) -> 0 | QW7: =SUM(QW$3:QW$5) -> 0 | QY7: =SUM(QY$3:QY$5) -> 0 | QZ7: =SUM(QZ$3:QZ$5) -> 0 | RA7: =SUM(RA$3:RA$5) -> 0 | RB7: =SUM(RB$3:RB$5) -> 0 | RC7: =SUM(RC$3:RC$5) -> 0 | RD7: =SUM(RD$3:RD$5) -> 0 | RF7: =SUM(RF$3:RF$5) -> 0 | RG7: =SUM(RG$3:RG$5) -> 0 | RH7: =SUM(RH$3:RH$5) -> 0 | RI7: =SUM(RI$3:RI$5) -> 0 | RJ7: =SUM(RJ$3:RJ$5) -> 0 | RP7: =SUM(RP$3:RP$5) -> 0 | RQ7: =SUM(RQ$3:RQ$5) -> 0 | RW7: =SUM(RW$3:RW$5) -> 0 | RX7: =SUM(RX$3:RX$5) -> 0 | SD7: =SUM(SD$3:SD$5) -> 0 | SE7: =SUM(SE$3:SE$5) -> 0 | SK7: =SUM(SK$3:SK$5) -> 0 | SL7: =SUM(SL$3:SL$5) -> 0 | SR7: =SUM(SR$3:SR$5) -> 0 | SS7: =SUM(SS$3:SS$5) -> 0 | SY7: =SUM(SY$3:SY$5) -> 0 | SZ7: =SUM(SZ$3:SZ$5) -> 0 | TF7: =SUM(TF$3:TF$5) -> 0 | TG7: =SUM(TG$3:TG$5) -> 0 | TM7: =SUM(TM$3:TM$5) -> 0 | TN7: =SUM(TN$3:TN$5) -> 0 | TO7: =SUM(TO$3:TO$5) -> 0 | TQ7: =SUM(TQ$3:TQ$5) -> 0 | TR7: =SUM(TR$3:TR$5) -> 0 | TS7: =SUM(TS$3:TS$5) -> 0 | TT7: =SUM(TT$3:TT$5) -> 0 | TU7: =SUM(TU$3:TU$5) -> 0 | TV7: =SUM(TV$3:TV$5) -> 0 | TX7: =SUM(TX$3:TX$5) -> 0 | TY7: =SUM(TY$3:TY$5) -> 0 | TZ7: =SUM(TZ$3:TZ$5) -> 0 | UA7: =SUM(UA$3:UA$5) -> 0 | UB7: =SUM(UB$3:UB$5) -> 0 | UC7: =SUM(UC$3:UC$5) -> 0 | UE7: =SUM(UE$3:UE$5) -> 0 | UF7: =SUM(UF$3:UF$5) -> 0 | UG7: =SUM(UG$3:UG$5) -> 0 | UH7: =SUM(UH$3:UH$5) -> 0 | UI7: =SUM(UI$3:UI$5) -> 0 | UJ7: =SUM(UJ$3:UJ$5) -> 0 | UL7: =SUM(UL$3:UL$5) -> 0 | UM7: =SUM(UM$3:UM$5) -> 0 | UN7: =SUM(UN$3:UN$5) -> 0 | UO7: =SUM(UO$3:UO$5) -> 0 | UP7: =SUM(UP$3:UP$5) -> 0 | UQ7: =SUM(UQ$3:UQ$5) -> 0 | US7: =SUM(US$3:US$5) -> 0 | UT7: =SUM(UT$3:UT$5) -> 0 | UU7: =SUM(UU$3:UU$5) -> 0 | UV7: =SUM(UV$3:UV$5) -> 0 | UW7: =SUM(UW$3:UW$5) -> 0 | UX7: =SUM(UX$3:UX$5) -> 0 | UZ7: =SUM(UZ$3:UZ$5) -> 0 | VA7: =SUM(VA$3:VA$5) -> 0 | VB7: =SUM(VB$3:VB$5) -> 0 | VC7: =SUM(VC$3:VC$5) -> 0 | VD7: =SUM(VD$3:VD$5) -> 0 | VE7: =SUM(VE$3:VE$5) -> 0 | VG7: =SUM(VG$3:VG$5) -> 0 | VH7: =SUM(VH$3:VH$5) -> 0 | VI7: =SUM(VI$3:VI$5) -> 0 | VJ7: =SUM(VJ$3:VJ$5) -> 0 | VK7: =SUM(VK$3:VK$5) -> 0 | VL7: =SUM(VL$3:VL$5) -> 0 | VN7: =SUM(VN$3:VN$5) -> 0 | VO7: =SUM(VO$3:VO$5) -> 0 | VP7: =SUM(VP$3:VP$5) -> 0 | VQ7: =SUM(VQ$3:VQ$5) -> 0 | VR7: =SUM(VR$3:VR$5) -> 0 | VS7: =SUM(VS$3:VS$5) -> 0 | VT7: =SUM(VT$3:VT$5) -> 0 | VU7: =SUM(VU$3:VU$5) -> 0 | ... WI7: =SUM(WI$3:WI$5) -> 0
