Workbook

Sheet Instances
B1: memelingo-1/setting-ht6_10_mlp-tplp-ht | O1: memelingo-1/setting-ht6_11_mlp-tplp-ht | AB1: memelingo-1/setting-ht6_12_mlp-tplp-ht | AO1: memelingo-1/setting-ht6_13_mlp-tplp-ht | BB1: memelingo-1/setting-ht6_14_mlp-tplp-ht | BO1: memelingo-1/setting-ht6_15_mlp-tplp-ht | CB1: memelingo-1/setting-htc_10_mlp-tplp-htc | CO1: memelingo-1/setting-htc_10_mlp-tplp-htc-dl | DB1: memelingo-1/setting-htc_11_mlp-tplp-htc | DO1: memelingo-1/setting-htc_11_mlp-tplp-htc-dl | EB1: memelingo-1/setting-htc_12_mlp-tplp-htc | EO1: memelingo-1/setting-htc_12_mlp-tplp-htc-dl | FB1: memelingo-1/setting-htc_13_mlp-tplp-htc | FO1: memelingo-1/setting-htc_13_mlp-tplp-htc-dl | GB1: memelingo-1/setting-htc_14_mlp-tplp-htc | GO1: memelingo-1/setting-htc_14_mlp-tplp-htc-dl | HB1: memelingo-1/setting-htc_15_mlp-tplp-htc | HO1: memelingo-1/setting-htc_15_mlp-tplp-htc-dl | IB1: min | IN1: median | IZ1: max
B2: time | C2: ctime | D2: stime | E2: gtime | F2: timeout | G2: conflicts | H2: choices | I2: mem | J2: error | K2: memout | L2: status | M2: atoms | N2: rules | O2: time | P2: ctime | Q2: stime | R2: gtime | S2: timeout | T2: conflicts | U2: choices | V2: mem | W2: error | X2: memout | Y2: status | Z2: atoms | AA2: rules | AB2: time | AC2: ctime | AD2: stime | AE2: gtime | AF2: timeout | AG2: conflicts | AH2: choices | AI2: mem | AJ2: error | AK2: memout | AL2: status | AM2: atoms | AN2: rules | AO2: time | AP2: ctime | AQ2: stime | AR2: gtime | AS2: timeout | AT2: conflicts | AU2: choices | AV2: mem | AW2: error | AX2: memout | AY2: status | AZ2: atoms | BA2: rules | BB2: time | BC2: ctime | BD2: stime | BE2: gtime | BF2: timeout | BG2: conflicts | BH2: choices | BI2: mem | BJ2: error | BK2: memout | BL2: status | BM2: atoms | BN2: rules | BO2: time | BP2: ctime | BQ2: stime | BR2: gtime | BS2: timeout | BT2: conflicts | BU2: choices | BV2: mem | BW2: error | BX2: memout | BY2: status | BZ2: atoms | CA2: rules | CB2: time | CC2: ctime | CD2: stime | CE2: gtime | CF2: timeout | CG2: conflicts | CH2: choices | CI2: mem | CJ2: error | CK2: memout | CL2: status | CM2: atoms | CN2: rules | CO2: time | CP2: ctime | CQ2: stime | CR2: gtime | CS2: timeout | CT2: conflicts | CU2: choices | CV2: mem | CW2: error | CX2: memout | CY2: status | CZ2: atoms | DA2: rules | DB2: time | DC2: ctime | DD2: stime | DE2: gtime | DF2: timeout | DG2: conflicts | DH2: choices | DI2: mem | DJ2: error | DK2: memout | DL2: status | DM2: atoms | DN2: rules | DO2: time | DP2: ctime | DQ2: stime | DR2: gtime | DS2: timeout | DT2: conflicts | DU2: choices | DV2: mem | DW2: error | DX2: memout | DY2: status | DZ2: atoms | EA2: rules | EB2: time | EC2: ctime | ED2: stime | EE2: gtime | EF2: timeout | EG2: conflicts | EH2: choices | EI2: mem | EJ2: error | EK2: memout | EL2: status | EM2: atoms | EN2: rules | EO2: time | EP2: ctime | EQ2: stime | ER2: gtime | ES2: timeout | ET2: conflicts | EU2: choices | EV2: mem | EW2: error | EX2: memout | EY2: status | EZ2: atoms | FA2: rules | FB2: time | FC2: ctime | FD2: stime | FE2: gtime | FF2: timeout | FG2: conflicts | FH2: choices | FI2: mem | FJ2: error | FK2: memout | FL2: status | FM2: atoms | FN2: rules | FO2: time | FP2: ctime | FQ2: stime | FR2: gtime | FS2: timeout | FT2: conflicts | FU2: choices | FV2: mem | FW2: error | FX2: memout | FY2: status | FZ2: atoms | GA2: rules | GB2: time | GC2: ctime | GD2: stime | GE2: gtime | GF2: timeout | GG2: conflicts | GH2: choices | GI2: mem | GJ2: error | GK2: memout | GL2: status | GM2: atoms | GN2: rules | GO2: time | GP2: ctime | GQ2: stime | GR2: gtime | GS2: timeout | GT2: conflicts | GU2: choices | GV2: mem | GW2: error | GX2: memout | GY2: status | GZ2: atoms | HA2: rules | HB2: time | HC2: ctime | HD2: stime | HE2: gtime | HF2: timeout | HG2: conflicts | HH2: choices | HI2: mem | HJ2: error | HK2: memout | HL2: status | HM2: atoms | HN2: rules | HO2: time | HP2: ctime | HQ2: stime | HR2: gtime | HS2: timeout | HT2: conflicts | HU2: choices | HV2: mem | HW2: error | HX2: memout | HY2: status | HZ2: atoms | IA2: rules | IB2: time | IC2: ctime | ID2: stime | IE2: gtime | IF2: timeout | IG2: conflicts | IH2: choices | II2: mem | IJ2: error | IK2: memout | IL2: atoms | IM2: rules | IN2: time | IO2: ctime | IP2: stime | IQ2: gtime | IR2: timeout | IS2: conflicts | IT2: choices | IU2: mem | IV2: error | IW2: memout | IX2: atoms | IY2: rules | IZ2: time | JA2: ctime | JB2: stime | JC2: gtime | JD2: timeout | JE2: conflicts | JF2: choices | JG2: mem | JH2: error | JI2: memout | JJ2: atoms | JK2: rules
A3: instances/ft06 | B3: 263.56 | C3: 256.534 | D3: 243.62 | E3: 12.91 | F3: 0 | G3: 336033 | H3: 8327188 | I3: 952 | J3: 0 | K3: 0 | L3: UNSATISFIABLE | M3: 47528 | N3: 1876691 | O3: 240.64 | P3: 233.57 | Q3: 218.19 | R3: 15.38 | S3: 0 | T3: 270711 | U3: 8550692 | V3: 1128 | W3: 0 | X3: 0 | Y3: SATISFIABLE | Z3: 52893 | AA3: 2238045 | AB3: 217.35 | AC3: 210.197 | AD3: 192.69 | AE3: 17.51 | AF3: 0 | AG3: 248316 | AH3: 7459553 | AI3: 1317 | AJ3: 0 | AK3: 0 | AL3: SATISFIABLE | AM3: 58422 | AN3: 2621303 | AO3: 193.44 | AP3: 186.945 | AQ3: 166.77 | AR3: 20.17 | AS3: 0 | AT3: 183329 | AU3: 4107960 | AV3: 1529 | AW3: 0 | AX3: 0 | AY3: SATISFIABLE | AZ3: 64115 | BA3: 3024254 | BB3: 58.93 | BC3: 52.353 | BD3: 28.74 | BE3: 23.61 | BF3: 0 | BG3: 34744 | BH3: 1331332 | BI3: 1717 | BJ3: 0 | BK3: 0 | BL3: SATISFIABLE | BM3: 69972 | BN3: 3444750 | BO3: 206.18 | BP3: 199.265 | BQ3: 172.87 | BR3: 26.39 | BS3: 0 | BT3: 171293 | BU3: 4445841 | BV3: 1921 | BW3: 0 | BX3: 0 | BY3: SATISFIABLE | BZ3: 75993 | CA3: 3880706 | CB3: 8.8 | CC3: 2.651 | CD3: 1.77 | CE3: 0.88 | CF3: 0 | CG3: 6813 | CH3: 15233 | CI3: 123 | CJ3: 0 | CK3: 0 | CL3: UNSATISFIABLE | CM3: 48065 | CN3: 78267 | CO3: 10.58 | CP3: 3.601 | CQ3: 2.71 | CR3: 0.89 | CS3: 0 | CT3: 7465 | CU3: 301753 | CV3: 119 | CW3: 0 | CX3: 0 | CY3: UNSATISFIABLE | CZ3: 48065 | DA3: 78267 | DB3: 11.78 | DC3: 4.967 | DD3: 3.96 | DE3: 1.01 | DF3: 0 | DG3: 12907 | DH3: 32866 | DI3: 135 | DJ3: 0 | DK3: 0 | DL3: SATISFIABLE | DM3: 53579 | DN3: 89157 | DO3: 11.52 | DP3: 4.613 | DQ3: 3.62 | DR3: 0.99 | DS3: 0 | DT3: 8490 | DU3: 419869 | DV3: 129 | DW3: 0 | DX3: 0 | DY3: SATISFIABLE | DZ3: 53579 | EA3: 89157 | EB3: 13.02 | EC3: 6.321 | ED3: 5.22 | EE3: 1.1 | EF3: 0 | EG3: 14025 | EH3: 37338 | EI3: 147 | EJ3: 0 | EK3: 0 | EL3: SATISFIABLE | EM3: 59280 | EN3: 100659 | EO3: 12.11 | EP3: 5.562 | EQ3: 4.48 | ER3: 1.08 | ES3: 0 | ET3: 6809 | EU3: 632401 | EV3: 142 | EW3: 0 | EX3: 0 | EY3: SATISFIABLE | EZ3: 59280 | FA3: 100659 | FB3: 14.18 | FC3: 7.261 | FD3: 6.02 | FE3: 1.24 | FF3: 0 | FG3: 15988 | FH3: 49492 | FI3: 159 | FJ3: 0 | FK3: 0 | FL3: SATISFIABLE | FM3: 65168 | FN3: 112773 | FO3: 13.83 | FP3: 6.828 | FQ3: 5.62 | FR3: 1.21 | FS3: 0 | FT3: 5824 | FU3: 875008 | FV3: 152 | FW3: 0 | FX3: 0 | FY3: SATISFIABLE | FZ3: 65168 | GA3: 112773 | GB3: 14.83 | GC3: 7.817 | GD3: 6.44 | GE3: 1.38 | GF3: 0 | GG3: 15018 | GH3: 63923 | GI3: 172 | GJ3: 0 | GK3: 0 | GL3: SATISFIABLE | GM3: 71243 | GN3: 125499 | GO3: 15.84 | GP3: 8.88 | GQ3: 7.52 | GR3: 1.36 | GS3: 0 | GT3: 5221 | GU3: 1135706 | GV3: 164 | GW3: 0 | GX3: 0 | GY3: SATISFIABLE | GZ3: 71243 | HA3: 125499 | HB3: 15.08 | HC3: 8.149 | HD3: 6.62 | HE3: 1.53 | HF3: 0 | HG3: 13581 | HH3: 66864 | HI3: 182 | HJ3: 0 | HK3: 0 | HL3: SATISFIABLE | HM3: 77505 | HN3: 138837 | HO3: 19.82 | HP3: 12.886 | HQ3: 11.43 | HR3: 1.46 | HS3: 0 | HT3: 8238 | HU3: 1421040 | HV3: 178 | HW3: 0 | HX3: 0 | HY3: SATISFIABLE | HZ3: 77505 | IA3: 138837 | IB3: =MIN($B3,$O3,$AB3,$AO3,$BB3,$BO3,$CB3,$CO3,$DB3,$DO3,$EB3,$EO3,$FB3,$FO3,$GB3,$GO3,$HB3,$HO3) -> 0 | IC3: =MIN($C3,$P3,$AC3,$AP3,$BC3,$BP3,$CC3,$CP3,$DC3,$DP3,$EC3,$EP3,$FC3,$FP3,$GC3,$GP3,$HC3,$HP3) -> 0 | ID3: =MIN($D3,$Q3,$AD3,$AQ3,$BD3,$BQ3,$CD3,$CQ3,$DD3,$DQ3,$ED3,$EQ3,$FD3,$FQ3,$GD3,$GQ3,$HD3,$HQ3) -> 0 | IE3: =MIN($E3,$R3,$AE3,$AR3,$BE3,$BR3,$CE3,$CR3,$DE3,$DR3,$EE3,$ER3,$FE3,$FR3,$GE3,$GR3,$HE3,$HR3) -> 0 | IF3: =MIN($F3,$S3,$AF3,$AS3,$BF3,$BS3,$CF3,$CS3,$DF3,$DS3,$EF3,$ES3,$FF3,$FS3,$GF3,$GS3,$HF3,$HS3) -> 0 | IG3: =MIN($G3,$T3,$AG3,$AT3,$BG3,$BT3,$CG3,$CT3,$DG3,$DT3,$EG3,$ET3,$FG3,$FT3,$GG3,$GT3,$HG3,$HT3) -> 0 | IH3: =MIN($H3,$U3,$AH3,$AU3,$BH3,$BU3,$CH3,$CU3,$DH3,$DU3,$EH3,$EU3,$FH3,$FU3,$GH3,$GU3,$HH3,$HU3) -> 0 | II3: =MIN($I3,$V3,$AI3,$AV3,$BI3,$BV3,$CI3,$CV3,$DI3,$DV3,$EI3,$EV3,$FI3,$FV3,$GI3,$GV3,$HI3,$HV3) -> 0 | IJ3: =MIN($J3,$W3,$AJ3,$AW3,$BJ3,$BW3,$CJ3,$CW3,$DJ3,$DW3,$EJ3,$EW3,$FJ3,$FW3,$GJ3,$GW3,$HJ3,$HW3) -> 0 | IK3: =MIN($K3,$X3,$AK3,$AX3,$BK3,$BX3,$CK3,$CX3,$DK3,$DX3,$EK3,$EX3,$FK3,$FX3,$GK3,$GX3,$HK3,$HX3) -> 0 | IL3: =MIN($M3,$Z3,$AM3,$AZ3,$BM3,$BZ3,$CM3,$CZ3,$DM3,$DZ3,$EM3,$EZ3,$FM3,$FZ3,$GM3,$GZ3,$HM3,$HZ3) -> 0 | IM3: =MIN($N3,$AA3,$AN3,$BA3,$BN3,$CA3,$CN3,$DA3,$DN3,$EA3,$EN3,$FA3,$FN3,$GA3,$GN3,$HA3,$HN3,$IA3) -> 0 | IN3: =MEDIAN($B3,$O3,$AB3,$AO3,$BB3,$BO3,$CB3,$CO3,$DB3,$DO3,$EB3,$EO3,$FB3,$FO3,$GB3,$GO3,$HB3,$HO3) -> 0 | IO3: =MEDIAN($C3,$P3,$AC3,$AP3,$BC3,$BP3,$CC3,$CP3,$DC3,$DP3,$EC3,$EP3,$FC3,$FP3,$GC3,$GP3,$HC3,$HP3) -> 0 | IP3: =MEDIAN($D3,$Q3,$AD3,$AQ3,$BD3,$BQ3,$CD3,$CQ3,$DD3,$DQ3,$ED3,$EQ3,$FD3,$FQ3,$GD3,$GQ3,$HD3,$HQ3) -> 0 | IQ3: =MEDIAN($E3,$R3,$AE3,$AR3,$BE3,$BR3,$CE3,$CR3,$DE3,$DR3,$EE3,$ER3,$FE3,$FR3,$GE3,$GR3,$HE3,$HR3) -> 0 | IR3: =MEDIAN($F3,$S3,$AF3,$AS3,$BF3,$BS3,$CF3,$CS3,$DF3,$DS3,$EF3,$ES3,$FF3,$FS3,$GF3,$GS3,$HF3,$HS3) -> 0 | IS3: =MEDIAN($G3,$T3,$AG3,$AT3,$BG3,$BT3,$CG3,$CT3,$DG3,$DT3,$EG3,$ET3,$FG3,$FT3,$GG3,$GT3,$HG3,$HT3) -> 0 | IT3: =MEDIAN($H3,$U3,$AH3,$AU3,$BH3,$BU3,$CH3,$CU3,$DH3,$DU3,$EH3,$EU3,$FH3,$FU3,$GH3,$GU3,$HH3,$HU3) -> 0 | IU3: =MEDIAN($I3,$V3,$AI3,$AV3,$BI3,$BV3,$CI3,$CV3,$DI3,$DV3,$EI3,$EV3,$FI3,$FV3,$GI3,$GV3,$HI3,$HV3) -> 0 | IV3: =MEDIAN($J3,$W3,$AJ3,$AW3,$BJ3,$BW3,$CJ3,$CW3,$DJ3,$DW3,$EJ3,$EW3,$FJ3,$FW3,$GJ3,$GW3,$HJ3,$HW3) -> 0 | IW3: =MEDIAN($K3,$X3,$AK3,$AX3,$BK3,$BX3,$CK3,$CX3,$DK3,$DX3,$EK3,$EX3,$FK3,$FX3,$GK3,$GX3,$HK3,$HX3) -> 0 | IX3: =MEDIAN($M3,$Z3,$AM3,$AZ3,$BM3,$BZ3,$CM3,$CZ3,$DM3,$DZ3,$EM3,$EZ3,$FM3,$FZ3,$GM3,$GZ3,$HM3,$HZ3) -> 0 | IY3: =MEDIAN($N3,$AA3,$AN3,$BA3,$BN3,$CA3,$CN3,$DA3,$DN3,$EA3,$EN3,$FA3,$FN3,$GA3,$GN3,$HA3,$HN3,$IA3) -> 0 | IZ3: =MAX($B3,$O3,$AB3,$AO3,$BB3,$BO3,$CB3,$CO3,$DB3,$DO3,$EB3,$EO3,$FB3,$FO3,$GB3,$GO3,$HB3,$HO3) -> 0 | JA3: =MAX($C3,$P3,$AC3,$AP3,$BC3,$BP3,$CC3,$CP3,$DC3,$DP3,$EC3,$EP3,$FC3,$FP3,$GC3,$GP3,$HC3,$HP3) -> 0 | JB3: =MAX($D3,$Q3,$AD3,$AQ3,$BD3,$BQ3,$CD3,$CQ3,$DD3,$DQ3,$ED3,$EQ3,$FD3,$FQ3,$GD3,$GQ3,$HD3,$HQ3) -> 0 | JC3: =MAX($E3,$R3,$AE3,$AR3,$BE3,$BR3,$CE3,$CR3,$DE3,$DR3,$EE3,$ER3,$FE3,$FR3,$GE3,$GR3,$HE3,$HR3) -> 0 | JD3: =MAX($F3,$S3,$AF3,$AS3,$BF3,$BS3,$CF3,$CS3,$DF3,$DS3,$EF3,$ES3,$FF3,$FS3,$GF3,$GS3,$HF3,$HS3) -> 0 | JE3: =MAX($G3,$T3,$AG3,$AT3,$BG3,$BT3,$CG3,$CT3,$DG3,$DT3,$EG3,$ET3,$FG3,$FT3,$GG3,$GT3,$HG3,$HT3) -> 0 | JF3: =MAX($H3,$U3,$AH3,$AU3,$BH3,$BU3,$CH3,$CU3,$DH3,$DU3,$EH3,$EU3,$FH3,$FU3,$GH3,$GU3,$HH3,$HU3) -> 0 | JG3: =MAX($I3,$V3,$AI3,$AV3,$BI3,$BV3,$CI3,$CV3,$DI3,$DV3,$EI3,$EV3,$FI3,$FV3,$GI3,$GV3,$HI3,$HV3) -> 0 | JH3: =MAX($J3,$W3,$AJ3,$AW3,$BJ3,$BW3,$CJ3,$CW3,$DJ3,$DW3,$EJ3,$EW3,$FJ3,$FW3,$GJ3,$GW3,$HJ3,$HW3) -> 0 | JI3: =MAX($K3,$X3,$AK3,$AX3,$BK3,$BX3,$CK3,$CX3,$DK3,$DX3,$EK3,$EX3,$FK3,$FX3,$GK3,$GX3,$HK3,$HX3) -> 0 | JJ3: =MAX($M3,$Z3,$AM3,$AZ3,$BM3,$BZ3,$CM3,$CZ3,$DM3,$DZ3,$EM3,$EZ3,$FM3,$FZ3,$GM3,$GZ3,$HM3,$HZ3) -> 0 | JK3: =MAX($N3,$AA3,$AN3,$BA3,$BN3,$CA3,$CN3,$DA3,$DN3,$EA3,$EN3,$FA3,$FN3,$GA3,$GN3,$HA3,$HN3,$IA3) -> 0
B4: 265.79 | C4: 258.087 | D4: 245.22 | E4: 12.87 | F4: 0 | G4: 336033 | H4: 8327188 | I4: 954 | J4: 0 | K4: 0 | L4: UNSATISFIABLE | M4: 47528 | N4: 1876691 | O4: 232.67 | P4: 225.528 | Q4: 210.3 | R4: 15.23 | S4: 0 | T4: 270711 | U4: 8550692 | V4: 1131 | W4: 0 | X4: 0 | Y4: SATISFIABLE | Z4: 52893 | AA4: 2238045 | AB4: 226.62 | AC4: 220.035 | AD4: 202.58 | AE4: 17.45 | AF4: 0 | AG4: 248316 | AH4: 7459553 | AI4: 1371 | AJ4: 0 | AK4: 0 | AL4: SATISFIABLE | AM4: 58422 | AN4: 2621303 | AO4: 191.5 | AP4: 184.876 | AQ4: 164.29 | AR4: 20.59 | AS4: 0 | AT4: 183329 | AU4: 4107960 | AV4: 1511 | AW4: 0 | AX4: 0 | AY4: SATISFIABLE | AZ4: 64115 | BA4: 3024254 | BB4: 60.18 | BC4: 53.478 | BD4: 29.61 | BE4: 23.87 | BF4: 0 | BG4: 34744 | BH4: 1331332 | BI4: 1726 | BJ4: 0 | BK4: 0 | BL4: SATISFIABLE | BM4: 69972 | BN4: 3444750 | BO4: 211.69 | BP4: 204.377 | BQ4: 177.63 | BR4: 26.75 | BS4: 0 | BT4: 171293 | BU4: 4445841 | BV4: 2001 | BW4: 0 | BX4: 0 | BY4: SATISFIABLE | BZ4: 75993 | CA4: 3880706 | CB4: 8.81 | CC4: 2.673 | CD4: 1.78 | CE4: 0.89 | CF4: 0 | CG4: 6813 | CH4: 15233 | CI4: 122 | CJ4: 0 | CK4: 0 | CL4: UNSATISFIABLE | CM4: 48065 | CN4: 78267 | CO4: 10.48 | CP4: 3.546 | CQ4: 2.66 | CR4: 0.89 | CS4: 0 | CT4: 7465 | CU4: 301753 | CV4: 120 | CW4: 0 | CX4: 0 | CY4: UNSATISFIABLE | CZ4: 48065 | DA4: 78267 | DB4: 11.95 | DC4: 4.985 | DD4: 3.96 | DE4: 1.03 | DF4: 0 | DG4: 12907 | DH4: 32866 | DI4: 135 | DJ4: 0 | DK4: 0 | DL4: SATISFIABLE | DM4: 53579 | DN4: 89157 | DO4: 11.53 | DP4: 4.641 | DQ4: 3.64 | DR4: 1 | DS4: 0 | DT4: 8490 | DU4: 419869 | DV4: 129 | DW4: 0 | DX4: 0 | DY4: SATISFIABLE | DZ4: 53579 | EA4: 89157 | EB4: 13.44 | EC4: 6.421 | ED4: 5.29 | EE4: 1.13 | EF4: 0 | EG4: 14025 | EH4: 37338 | EI4: 147 | EJ4: 0 | EK4: 0 | EL4: SATISFIABLE | EM4: 59280 | EN4: 100659 | EO4: 12.55 | EP4: 5.635 | EQ4: 4.52 | ER4: 1.12 | ES4: 0 | ET4: 6809 | EU4: 632401 | EV4: 141 | EW4: 0 | EX4: 0 | EY4: SATISFIABLE | EZ4: 59280 | FA4: 100659 | FB4: 14.28 | FC4: 7.326 | FD4: 6.08 | FE4: 1.25 | FF4: 0 | FG4: 15988 | FH4: 49492 | FI4: 159 | FJ4: 0 | FK4: 0 | FL4: SATISFIABLE | FM4: 65168 | FN4: 112773 | FO4: 13.8 | FP4: 6.819 | FQ4: 5.62 | FR4: 1.2 | FS4: 0 | FT4: 5824 | FU4: 875008 | FV4: 152 | FW4: 0 | FX4: 0 | FY4: SATISFIABLE | FZ4: 65168 | GA4: 112773 | GB4: 14.86 | GC4: 7.869 | GD4: 6.49 | GE4: 1.38 | GF4: 0 | GG4: 15018 | GH4: 63923 | GI4: 170 | GJ4: 0 | GK4: 0 | GL4: SATISFIABLE | GM4: 71243 | GN4: 125499 | GO4: 15.9 | GP4: 8.918 | GQ4: 7.55 | GR4: 1.37 | GS4: 0 | GT4: 5221 | GU4: 1135706 | GV4: 164 | GW4: 0 | GX4: 0 | GY4: SATISFIABLE | GZ4: 71243 | HA4: 125499 | HB4: 14.94 | HC4: 8.101 | HD4: 6.59 | HE4: 1.51 | HF4: 0 | HG4: 13581 | HH4: 66864 | HI4: 181 | HJ4: 0 | HK4: 0 | HL4: SATISFIABLE | HM4: 77505 | HN4: 138837 | HO4: 19.92 | HP4: 12.985 | HQ4: 11.5 | HR4: 1.48 | HS4: 0 | HT4: 8238 | HU4: 1421040 | HV4: 177 | HW4: 0 | HX4: 0 | HY4: SATISFIABLE | HZ4: 77505 | IA4: 138837 | IB4: =MIN($B4,$O4,$AB4,$AO4,$BB4,$BO4,$CB4,$CO4,$DB4,$DO4,$EB4,$EO4,$FB4,$FO4,$GB4,$GO4,$HB4,$HO4) -> 0 | IC4: =MIN($C4,$P4,$AC4,$AP4,$BC4,$BP4,$CC4,$CP4,$DC4,$DP4,$EC4,$EP4,$FC4,$FP4,$GC4,$GP4,$HC4,$HP4) -> 0 | ID4: =MIN($D4,$Q4,$AD4,$AQ4,$BD4,$BQ4,$CD4,$CQ4,$DD4,$DQ4,$ED4,$EQ4,$FD4,$FQ4,$GD4,$GQ4,$HD4,$HQ4) -> 0 | IE4: =MIN($E4,$R4,$AE4,$AR4,$BE4,$BR4,$CE4,$CR4,$DE4,$DR4,$EE4,$ER4,$FE4,$FR4,$GE4,$GR4,$HE4,$HR4) -> 0 | IF4: =MIN($F4,$S4,$AF4,$AS4,$BF4,$BS4,$CF4,$CS4,$DF4,$DS4,$EF4,$ES4,$FF4,$FS4,$GF4,$GS4,$HF4,$HS4) -> 0 | IG4: =MIN($G4,$T4,$AG4,$AT4,$BG4,$BT4,$CG4,$CT4,$DG4,$DT4,$EG4,$ET4,$FG4,$FT4,$GG4,$GT4,$HG4,$HT4) -> 0 | IH4: =MIN($H4,$U4,$AH4,$AU4,$BH4,$BU4,$CH4,$CU4,$DH4,$DU4,$EH4,$EU4,$FH4,$FU4,$GH4,$GU4,$HH4,$HU4) -> 0 | II4: =MIN($I4,$V4,$AI4,$AV4,$BI4,$BV4,$CI4,$CV4,$DI4,$DV4,$EI4,$EV4,$FI4,$FV4,$GI4,$GV4,$HI4,$HV4) -> 0 | IJ4: =MIN($J4,$W4,$AJ4,$AW4,$BJ4,$BW4,$CJ4,$CW4,$DJ4,$DW4,$EJ4,$EW4,$FJ4,$FW4,$GJ4,$GW4,$HJ4,$HW4) -> 0 | IK4: =MIN($K4,$X4,$AK4,$AX4,$BK4,$BX4,$CK4,$CX4,$DK4,$DX4,$EK4,$EX4,$FK4,$FX4,$GK4,$GX4,$HK4,$HX4) -> 0 | IL4: =MIN($M4,$Z4,$AM4,$AZ4,$BM4,$BZ4,$CM4,$CZ4,$DM4,$DZ4,$EM4,$EZ4,$FM4,$FZ4,$GM4,$GZ4,$HM4,$HZ4) -> 0 | IM4: =MIN($N4,$AA4,$AN4,$BA4,$BN4,$CA4,$CN4,$DA4,$DN4,$EA4,$EN4,$FA4,$FN4,$GA4,$GN4,$HA4,$HN4,$IA4) -> 0 | IN4: =MEDIAN($B4,$O4,$AB4,$AO4,$BB4,$BO4,$CB4,$CO4,$DB4,$DO4,$EB4,$EO4,$FB4,$FO4,$GB4,$GO4,$HB4,$HO4) -> 0 | IO4: =MEDIAN($C4,$P4,$AC4,$AP4,$BC4,$BP4,$CC4,$CP4,$DC4,$DP4,$EC4,$EP4,$FC4,$FP4,$GC4,$GP4,$HC4,$HP4) -> 0 | IP4: =MEDIAN($D4,$Q4,$AD4,$AQ4,$BD4,$BQ4,$CD4,$CQ4,$DD4,$DQ4,$ED4,$EQ4,$FD4,$FQ4,$GD4,$GQ4,$HD4,$HQ4) -> 0 | IQ4: =MEDIAN($E4,$R4,$AE4,$AR4,$BE4,$BR4,$CE4,$CR4,$DE4,$DR4,$EE4,$ER4,$FE4,$FR4,$GE4,$GR4,$HE4,$HR4) -> 0 | IR4: =MEDIAN($F4,$S4,$AF4,$AS4,$BF4,$BS4,$CF4,$CS4,$DF4,$DS4,$EF4,$ES4,$FF4,$FS4,$GF4,$GS4,$HF4,$HS4) -> 0 | IS4: =MEDIAN($G4,$T4,$AG4,$AT4,$BG4,$BT4,$CG4,$CT4,$DG4,$DT4,$EG4,$ET4,$FG4,$FT4,$GG4,$GT4,$HG4,$HT4) -> 0 | IT4: =MEDIAN($H4,$U4,$AH4,$AU4,$BH4,$BU4,$CH4,$CU4,$DH4,$DU4,$EH4,$EU4,$FH4,$FU4,$GH4,$GU4,$HH4,$HU4) -> 0 | IU4: =MEDIAN($I4,$V4,$AI4,$AV4,$BI4,$BV4,$CI4,$CV4,$DI4,$DV4,$EI4,$EV4,$FI4,$FV4,$GI4,$GV4,$HI4,$HV4) -> 0 | IV4: =MEDIAN($J4,$W4,$AJ4,$AW4,$BJ4,$BW4,$CJ4,$CW4,$DJ4,$DW4,$EJ4,$EW4,$FJ4,$FW4,$GJ4,$GW4,$HJ4,$HW4) -> 0 | IW4: =MEDIAN($K4,$X4,$AK4,$AX4,$BK4,$BX4,$CK4,$CX4,$DK4,$DX4,$EK4,$EX4,$FK4,$FX4,$GK4,$GX4,$HK4,$HX4) -> 0 | IX4: =MEDIAN($M4,$Z4,$AM4,$AZ4,$BM4,$BZ4,$CM4,$CZ4,$DM4,$DZ4,$EM4,$EZ4,$FM4,$FZ4,$GM4,$GZ4,$HM4,$HZ4) -> 0 | IY4: =MEDIAN($N4,$AA4,$AN4,$BA4,$BN4,$CA4,$CN4,$DA4,$DN4,$EA4,$EN4,$FA4,$FN4,$GA4,$GN4,$HA4,$HN4,$IA4) -> 0 | IZ4: =MAX($B4,$O4,$AB4,$AO4,$BB4,$BO4,$CB4,$CO4,$DB4,$DO4,$EB4,$EO4,$FB4,$FO4,$GB4,$GO4,$HB4,$HO4) -> 0 | JA4: =MAX($C4,$P4,$AC4,$AP4,$BC4,$BP4,$CC4,$CP4,$DC4,$DP4,$EC4,$EP4,$FC4,$FP4,$GC4,$GP4,$HC4,$HP4) -> 0 | JB4: =MAX($D4,$Q4,$AD4,$AQ4,$BD4,$BQ4,$CD4,$CQ4,$DD4,$DQ4,$ED4,$EQ4,$FD4,$FQ4,$GD4,$GQ4,$HD4,$HQ4) -> 0 | JC4: =MAX($E4,$R4,$AE4,$AR4,$BE4,$BR4,$CE4,$CR4,$DE4,$DR4,$EE4,$ER4,$FE4,$FR4,$GE4,$GR4,$HE4,$HR4) -> 0 | JD4: =MAX($F4,$S4,$AF4,$AS4,$BF4,$BS4,$CF4,$CS4,$DF4,$DS4,$EF4,$ES4,$FF4,$FS4,$GF4,$GS4,$HF4,$HS4) -> 0 | JE4: =MAX($G4,$T4,$AG4,$AT4,$BG4,$BT4,$CG4,$CT4,$DG4,$DT4,$EG4,$ET4,$FG4,$FT4,$GG4,$GT4,$HG4,$HT4) -> 0 | JF4: =MAX($H4,$U4,$AH4,$AU4,$BH4,$BU4,$CH4,$CU4,$DH4,$DU4,$EH4,$EU4,$FH4,$FU4,$GH4,$GU4,$HH4,$HU4) -> 0 | JG4: =MAX($I4,$V4,$AI4,$AV4,$BI4,$BV4,$CI4,$CV4,$DI4,$DV4,$EI4,$EV4,$FI4,$FV4,$GI4,$GV4,$HI4,$HV4) -> 0 | JH4: =MAX($J4,$W4,$AJ4,$AW4,$BJ4,$BW4,$CJ4,$CW4,$DJ4,$DW4,$EJ4,$EW4,$FJ4,$FW4,$GJ4,$GW4,$HJ4,$HW4) -> 0 | JI4: =MAX($K4,$X4,$AK4,$AX4,$BK4,$BX4,$CK4,$CX4,$DK4,$DX4,$EK4,$EX4,$FK4,$FX4,$GK4,$GX4,$HK4,$HX4) -> 0 | JJ4: =MAX($M4,$Z4,$AM4,$AZ4,$BM4,$BZ4,$CM4,$CZ4,$DM4,$DZ4,$EM4,$EZ4,$FM4,$FZ4,$GM4,$GZ4,$HM4,$HZ4) -> 0 | JK4: =MAX($N4,$AA4,$AN4,$BA4,$BN4,$CA4,$CN4,$DA4,$DN4,$EA4,$EN4,$FA4,$FN4,$GA4,$GN4,$HA4,$HN4,$IA4) -> 0
A6: SUM | B6: =SUM(B$3:B$4) -> 0 | C6: =SUM(C$3:C$4) -> 0 | D6: =SUM(D$3:D$4) -> 0 | E6: =SUM(E$3:E$4) -> 0 | F6: =SUM(F$3:F$4) -> 0 | G6: =SUM(G$3:G$4) -> 0 | H6: =SUM(H$3:H$4) -> 0 | I6: =SUM(I$3:I$4) -> 0 | ... K6: =SUM(K$3:K$4) -> 0 | M6: =SUM(M$3:M$4) -> 0 | N6: =SUM(N$3:N$4) -> 0 | O6: =SUM(O$3:O$4) -> 0 | P6: =SUM(P$3:P$4) -> 0 | Q6: =SUM(Q$3:Q$4) -> 0 | R6: =SUM(R$3:R$4) -> 0 | S6: =SUM(S$3:S$4) -> 0 | T6: =SUM(T$3:T$4) -> 0 | ... X6: =SUM(X$3:X$4) -> 0 | Z6: =SUM(Z$3:Z$4) -> 0 | AA6: =SUM(AA$3:AA$4) -> 0 | AB6: =SUM(AB$3:AB$4) -> 0 | AC6: =SUM(AC$3:AC$4) -> 0 | AD6: =SUM(AD$3:AD$4) -> 0 | AE6: =SUM(AE$3:AE$4) -> 0 | AF6: =SUM(AF$3:AF$4) -> 0 | AG6: =SUM(AG$3:AG$4) -> 0 | ... AK6: =SUM(AK$3:AK$4) -> 0 | AM6: =SUM(AM$3:AM$4) -> 0 | AN6: =SUM(AN$3:AN$4) -> 0 | AO6: =SUM(AO$3:AO$4) -> 0 | AP6: =SUM(AP$3:AP$4) -> 0 | AQ6: =SUM(AQ$3:AQ$4) -> 0 | AR6: =SUM(AR$3:AR$4) -> 0 | AS6: =SUM(AS$3:AS$4) -> 0 | AT6: =SUM(AT$3:AT$4) -> 0 | ... AX6: =SUM(AX$3:AX$4) -> 0 | AZ6: =SUM(AZ$3:AZ$4) -> 0 | BA6: =SUM(BA$3:BA$4) -> 0 | BB6: =SUM(BB$3:BB$4) -> 0 | BC6: =SUM(BC$3:BC$4) -> 0 | BD6: =SUM(BD$3:BD$4) -> 0 | BE6: =SUM(BE$3:BE$4) -> 0 | BF6: =SUM(BF$3:BF$4) -> 0 | BG6: =SUM(BG$3:BG$4) -> 0 | ... BK6: =SUM(BK$3:BK$4) -> 0 | BM6: =SUM(BM$3:BM$4) -> 0 | BN6: =SUM(BN$3:BN$4) -> 0 | BO6: =SUM(BO$3:BO$4) -> 0 | BP6: =SUM(BP$3:BP$4) -> 0 | BQ6: =SUM(BQ$3:BQ$4) -> 0 | BR6: =SUM(BR$3:BR$4) -> 0 | BS6: =SUM(BS$3:BS$4) -> 0 | BT6: =SUM(BT$3:BT$4) -> 0 | ... BX6: =SUM(BX$3:BX$4) -> 0 | BZ6: =SUM(BZ$3:BZ$4) -> 0 | CA6: =SUM(CA$3:CA$4) -> 0 | CB6: =SUM(CB$3:CB$4) -> 0 | CC6: =SUM(CC$3:CC$4) -> 0 | CD6: =SUM(CD$3:CD$4) -> 0 | CE6: =SUM(CE$3:CE$4) -> 0 | CF6: =SUM(CF$3:CF$4) -> 0 | CG6: =SUM(CG$3:CG$4) -> 0 | ... CK6: =SUM(CK$3:CK$4) -> 0 | CM6: =SUM(CM$3:CM$4) -> 0 | CN6: =SUM(CN$3:CN$4) -> 0 | CO6: =SUM(CO$3:CO$4) -> 0 | CP6: =SUM(CP$3:CP$4) -> 0 | CQ6: =SUM(CQ$3:CQ$4) -> 0 | CR6: =SUM(CR$3:CR$4) -> 0 | CS6: =SUM(CS$3:CS$4) -> 0 | CT6: =SUM(CT$3:CT$4) -> 0 | ... CX6: =SUM(CX$3:CX$4) -> 0 | CZ6: =SUM(CZ$3:CZ$4) -> 0 | DA6: =SUM(DA$3:DA$4) -> 0 | DB6: =SUM(DB$3:DB$4) -> 0 | DC6: =SUM(DC$3:DC$4) -> 0 | DD6: =SUM(DD$3:DD$4) -> 0 | DE6: =SUM(DE$3:DE$4) -> 0 | DF6: =SUM(DF$3:DF$4) -> 0 | DG6: =SUM(DG$3:DG$4) -> 0 | ... DK6: =SUM(DK$3:DK$4) -> 0 | DM6: =SUM(DM$3:DM$4) -> 0 | DN6: =SUM(DN$3:DN$4) -> 0 | DO6: =SUM(DO$3:DO$4) -> 0 | DP6: =SUM(DP$3:DP$4) -> 0 | DQ6: =SUM(DQ$3:DQ$4) -> 0 | DR6: =SUM(DR$3:DR$4) -> 0 | DS6: =SUM(DS$3:DS$4) -> 0 | DT6: =SUM(DT$3:DT$4) -> 0 | ... DX6: =SUM(DX$3:DX$4) -> 0 | DZ6: =SUM(DZ$3:DZ$4) -> 0 | EA6: =SUM(EA$3:EA$4) -> 0 | EB6: =SUM(EB$3:EB$4) -> 0 | EC6: =SUM(EC$3:EC$4) -> 0 | ED6: =SUM(ED$3:ED$4) -> 0 | EE6: =SUM(EE$3:EE$4) -> 0 | EF6: =SUM(EF$3:EF$4) -> 0 | EG6: =SUM(EG$3:EG$4) -> 0 | ... EK6: =SUM(EK$3:EK$4) -> 0 | EM6: =SUM(EM$3:EM$4) -> 0 | EN6: =SUM(EN$3:EN$4) -> 0 | EO6: =SUM(EO$3:EO$4) -> 0 | EP6: =SUM(EP$3:EP$4) -> 0 | EQ6: =SUM(EQ$3:EQ$4) -> 0 | ER6: =SUM(ER$3:ER$4) -> 0 | ES6: =SUM(ES$3:ES$4) -> 0 | ET6: =SUM(ET$3:ET$4) -> 0 | ... EX6: =SUM(EX$3:EX$4) -> 0 | EZ6: =SUM(EZ$3:EZ$4) -> 0 | FA6: =SUM(FA$3:FA$4) -> 0 | FB6: =SUM(FB$3:FB$4) -> 0 | FC6: =SUM(FC$3:FC$4) -> 0 | FD6: =SUM(FD$3:FD$4) -> 0 | FE6: =SUM(FE$3:FE$4) -> 0 | FF6: =SUM(FF$3:FF$4) -> 0 | FG6: =SUM(FG$3:FG$4) -> 0 | ... FK6: =SUM(FK$3:FK$4) -> 0 | FM6: =SUM(FM$3:FM$4) -> 0 | FN6: =SUM(FN$3:FN$4) -> 0 | FO6: =SUM(FO$3:FO$4) -> 0 | FP6: =SUM(FP$3:FP$4) -> 0 | FQ6: =SUM(FQ$3:FQ$4) -> 0 | FR6: =SUM(FR$3:FR$4) -> 0 | FS6: =SUM(FS$3:FS$4) -> 0 | FT6: =SUM(FT$3:FT$4) -> 0 | ... FX6: =SUM(FX$3:FX$4) -> 0 | FZ6: =SUM(FZ$3:FZ$4) -> 0 | GA6: =SUM(GA$3:GA$4) -> 0 | GB6: =SUM(GB$3:GB$4) -> 0 | GC6: =SUM(GC$3:GC$4) -> 0 | GD6: =SUM(GD$3:GD$4) -> 0 | GE6: =SUM(GE$3:GE$4) -> 0 | GF6: =SUM(GF$3:GF$4) -> 0 | GG6: =SUM(GG$3:GG$4) -> 0 | ... GK6: =SUM(GK$3:GK$4) -> 0 | GM6: =SUM(GM$3:GM$4) -> 0 | GN6: =SUM(GN$3:GN$4) -> 0 | GO6: =SUM(GO$3:GO$4) -> 0 | GP6: =SUM(GP$3:GP$4) -> 0 | GQ6: =SUM(GQ$3:GQ$4) -> 0 | GR6: =SUM(GR$3:GR$4) -> 0 | GS6: =SUM(GS$3:GS$4) -> 0 | GT6: =SUM(GT$3:GT$4) -> 0 | ... GX6: =SUM(GX$3:GX$4) -> 0 | GZ6: =SUM(GZ$3:GZ$4) -> 0 | HA6: =SUM(HA$3:HA$4) -> 0 | HB6: =SUM(HB$3:HB$4) -> 0 | HC6: =SUM(HC$3:HC$4) -> 0 | HD6: =SUM(HD$3:HD$4) -> 0 | HE6: =SUM(HE$3:HE$4) -> 0 | HF6: =SUM(HF$3:HF$4) -> 0 | HG6: =SUM(HG$3:HG$4) -> 0 | ... HK6: =SUM(HK$3:HK$4) -> 0 | HM6: =SUM(HM$3:HM$4) -> 0 | HN6: =SUM(HN$3:HN$4) -> 0 | HO6: =SUM(HO$3:HO$4) -> 0 | HP6: =SUM(HP$3:HP$4) -> 0 | HQ6: =SUM(HQ$3:HQ$4) -> 0 | HR6: =SUM(HR$3:HR$4) -> 0 | HS6: =SUM(HS$3:HS$4) -> 0 | HT6: =SUM(HT$3:HT$4) -> 0 | ... HX6: =SUM(HX$3:HX$4) -> 0 | HZ6: =SUM(HZ$3:HZ$4) -> 0 | IA6: =SUM(IA$3:IA$4) -> 0 | IB6: =SUM(IB$3:IB$4) -> 0 | IC6: =SUM(IC$3:IC$4) -> 0 | ID6: =SUM(ID$3:ID$4) -> 0 | IE6: =SUM(IE$3:IE$4) -> 0 | IF6: =SUM(IF$3:IF$4) -> 0 | IG6: =SUM(IG$3:IG$4) -> 0 | ... JK6: =SUM(JK$3:JK$4) -> 0
A7: AVG | B7: =AVERAGE(B$3:B$4) -> 0 | C7: =AVERAGE(C$3:C$4) -> 0 | D7: =AVERAGE(D$3:D$4) -> 0 | E7: =AVERAGE(E$3:E$4) -> 0 | F7: =AVERAGE(F$3:F$4) -> 0 | G7: =AVERAGE(G$3:G$4) -> 0 | H7: =AVERAGE(H$3:H$4) -> 0 | I7: =AVERAGE(I$3:I$4) -> 0 | ... K7: =AVERAGE(K$3:K$4) -> 0 | M7: =AVERAGE(M$3:M$4) -> 0 | N7: =AVERAGE(N$3:N$4) -> 0 | O7: =AVERAGE(O$3:O$4) -> 0 | P7: =AVERAGE(P$3:P$4) -> 0 | Q7: =AVERAGE(Q$3:Q$4) -> 0 | R7: =AVERAGE(R$3:R$4) -> 0 | S7: =AVERAGE(S$3:S$4) -> 0 | T7: =AVERAGE(T$3:T$4) -> 0 | ... X7: =AVERAGE(X$3:X$4) -> 0 | Z7: =AVERAGE(Z$3:Z$4) -> 0 | AA7: =AVERAGE(AA$3:AA$4) -> 0 | AB7: =AVERAGE(AB$3:AB$4) -> 0 | AC7: =AVERAGE(AC$3:AC$4) -> 0 | AD7: =AVERAGE(AD$3:AD$4) -> 0 | AE7: =AVERAGE(AE$3:AE$4) -> 0 | AF7: =AVERAGE(AF$3:AF$4) -> 0 | AG7: =AVERAGE(AG$3:AG$4) -> 0 | ... AK7: =AVERAGE(AK$3:AK$4) -> 0 | AM7: =AVERAGE(AM$3:AM$4) -> 0 | AN7: =AVERAGE(AN$3:AN$4) -> 0 | AO7: =AVERAGE(AO$3:AO$4) -> 0 | AP7: =AVERAGE(AP$3:AP$4) -> 0 | AQ7: =AVERAGE(AQ$3:AQ$4) -> 0 | AR7: =AVERAGE(AR$3:AR$4) -> 0 | AS7: =AVERAGE(AS$3:AS$4) -> 0 | AT7: =AVERAGE(AT$3:AT$4) -> 0 | ... AX7: =AVERAGE(AX$3:AX$4) -> 0 | AZ7: =AVERAGE(AZ$3:AZ$4) -> 0 | BA7: =AVERAGE(BA$3:BA$4) -> 0 | BB7: =AVERAGE(BB$3:BB$4) -> 0 | BC7: =AVERAGE(BC$3:BC$4) -> 0 | BD7: =AVERAGE(BD$3:BD$4) -> 0 | BE7: =AVERAGE(BE$3:BE$4) -> 0 | BF7: =AVERAGE(BF$3:BF$4) -> 0 | BG7: =AVERAGE(BG$3:BG$4) -> 0 | ... BK7: =AVERAGE(BK$3:BK$4) -> 0 | BM7: =AVERAGE(BM$3:BM$4) -> 0 | BN7: =AVERAGE(BN$3:BN$4) -> 0 | BO7: =AVERAGE(BO$3:BO$4) -> 0 | BP7: =AVERAGE(BP$3:BP$4) -> 0 | BQ7: =AVERAGE(BQ$3:BQ$4) -> 0 | BR7: =AVERAGE(BR$3:BR$4) -> 0 | BS7: =AVERAGE(BS$3:BS$4) -> 0 | BT7: =AVERAGE(BT$3:BT$4) -> 0 | ... BX7: =AVERAGE(BX$3:BX$4) -> 0 | BZ7: =AVERAGE(BZ$3:BZ$4) -> 0 | CA7: =AVERAGE(CA$3:CA$4) -> 0 | CB7: =AVERAGE(CB$3:CB$4) -> 0 | CC7: =AVERAGE(CC$3:CC$4) -> 0 | CD7: =AVERAGE(CD$3:CD$4) -> 0 | CE7: =AVERAGE(CE$3:CE$4) -> 0 | CF7: =AVERAGE(CF$3:CF$4) -> 0 | CG7: =AVERAGE(CG$3:CG$4) -> 0 | ... CK7: =AVERAGE(CK$3:CK$4) -> 0 | CM7: =AVERAGE(CM$3:CM$4) -> 0 | CN7: =AVERAGE(CN$3:CN$4) -> 0 | CO7: =AVERAGE(CO$3:CO$4) -> 0 | CP7: =AVERAGE(CP$3:CP$4) -> 0 | CQ7: =AVERAGE(CQ$3:CQ$4) -> 0 | CR7: =AVERAGE(CR$3:CR$4) -> 0 | CS7: =AVERAGE(CS$3:CS$4) -> 0 | CT7: =AVERAGE(CT$3:CT$4) -> 0 | ... CX7: =AVERAGE(CX$3:CX$4) -> 0 | CZ7: =AVERAGE(CZ$3:CZ$4) -> 0 | DA7: =AVERAGE(DA$3:DA$4) -> 0 | DB7: =AVERAGE(DB$3:DB$4) -> 0 | DC7: =AVERAGE(DC$3:DC$4) -> 0 | DD7: =AVERAGE(DD$3:DD$4) -> 0 | DE7: =AVERAGE(DE$3:DE$4) -> 0 | DF7: =AVERAGE(DF$3:DF$4) -> 0 | DG7: =AVERAGE(DG$3:DG$4) -> 0 | ... DK7: =AVERAGE(DK$3:DK$4) -> 0 | DM7: =AVERAGE(DM$3:DM$4) -> 0 | DN7: =AVERAGE(DN$3:DN$4) -> 0 | DO7: =AVERAGE(DO$3:DO$4) -> 0 | DP7: =AVERAGE(DP$3:DP$4) -> 0 | DQ7: =AVERAGE(DQ$3:DQ$4) -> 0 | DR7: =AVERAGE(DR$3:DR$4) -> 0 | DS7: =AVERAGE(DS$3:DS$4) -> 0 | DT7: =AVERAGE(DT$3:DT$4) -> 0 | ... DX7: =AVERAGE(DX$3:DX$4) -> 0 | DZ7: =AVERAGE(DZ$3:DZ$4) -> 0 | EA7: =AVERAGE(EA$3:EA$4) -> 0 | EB7: =AVERAGE(EB$3:EB$4) -> 0 | EC7: =AVERAGE(EC$3:EC$4) -> 0 | ED7: =AVERAGE(ED$3:ED$4) -> 0 | EE7: =AVERAGE(EE$3:EE$4) -> 0 | EF7: =AVERAGE(EF$3:EF$4) -> 0 | EG7: =AVERAGE(EG$3:EG$4) -> 0 | ... EK7: =AVERAGE(EK$3:EK$4) -> 0 | EM7: =AVERAGE(EM$3:EM$4) -> 0 | EN7: =AVERAGE(EN$3:EN$4) -> 0 | EO7: =AVERAGE(EO$3:EO$4) -> 0 | EP7: =AVERAGE(EP$3:EP$4) -> 0 | EQ7: =AVERAGE(EQ$3:EQ$4) -> 0 | ER7: =AVERAGE(ER$3:ER$4) -> 0 | ES7: =AVERAGE(ES$3:ES$4) -> 0 | ET7: =AVERAGE(ET$3:ET$4) -> 0 | ... EX7: =AVERAGE(EX$3:EX$4) -> 0 | EZ7: =AVERAGE(EZ$3:EZ$4) -> 0 | FA7: =AVERAGE(FA$3:FA$4) -> 0 | FB7: =AVERAGE(FB$3:FB$4) -> 0 | FC7: =AVERAGE(FC$3:FC$4) -> 0 | FD7: =AVERAGE(FD$3:FD$4) -> 0 | FE7: =AVERAGE(FE$3:FE$4) -> 0 | FF7: =AVERAGE(FF$3:FF$4) -> 0 | FG7: =AVERAGE(FG$3:FG$4) -> 0 | ... FK7: =AVERAGE(FK$3:FK$4) -> 0 | FM7: =AVERAGE(FM$3:FM$4) -> 0 | FN7: =AVERAGE(FN$3:FN$4) -> 0 | FO7: =AVERAGE(FO$3:FO$4) -> 0 | FP7: =AVERAGE(FP$3:FP$4) -> 0 | FQ7: =AVERAGE(FQ$3:FQ$4) -> 0 | FR7: =AVERAGE(FR$3:FR$4) -> 0 | FS7: =AVERAGE(FS$3:FS$4) -> 0 | FT7: =AVERAGE(FT$3:FT$4) -> 0 | ... FX7: =AVERAGE(FX$3:FX$4) -> 0 | FZ7: =AVERAGE(FZ$3:FZ$4) -> 0 | GA7: =AVERAGE(GA$3:GA$4) -> 0 | GB7: =AVERAGE(GB$3:GB$4) -> 0 | GC7: =AVERAGE(GC$3:GC$4) -> 0 | GD7: =AVERAGE(GD$3:GD$4) -> 0 | GE7: =AVERAGE(GE$3:GE$4) -> 0 | GF7: =AVERAGE(GF$3:GF$4) -> 0 | GG7: =AVERAGE(GG$3:GG$4) -> 0 | ... GK7: =AVERAGE(GK$3:GK$4) -> 0 | GM7: =AVERAGE(GM$3:GM$4) -> 0 | GN7: =AVERAGE(GN$3:GN$4) -> 0 | GO7: =AVERAGE(GO$3:GO$4) -> 0 | GP7: =AVERAGE(GP$3:GP$4) -> 0 | GQ7: =AVERAGE(GQ$3:GQ$4) -> 0 | GR7: =AVERAGE(GR$3:GR$4) -> 0 | GS7: =AVERAGE(GS$3:GS$4) -> 0 | GT7: =AVERAGE(GT$3:GT$4) -> 0 | ... GX7: =AVERAGE(GX$3:GX$4) -> 0 | GZ7: =AVERAGE(GZ$3:GZ$4) -> 0 | HA7: =AVERAGE(HA$3:HA$4) -> 0 | HB7: =AVERAGE(HB$3:HB$4) -> 0 | HC7: =AVERAGE(HC$3:HC$4) -> 0 | HD7: =AVERAGE(HD$3:HD$4) -> 0 | HE7: =AVERAGE(HE$3:HE$4) -> 0 | HF7: =AVERAGE(HF$3:HF$4) -> 0 | HG7: =AVERAGE(HG$3:HG$4) -> 0 | ... HK7: =AVERAGE(HK$3:HK$4) -> 0 | HM7: =AVERAGE(HM$3:HM$4) -> 0 | HN7: =AVERAGE(HN$3:HN$4) -> 0 | HO7: =AVERAGE(HO$3:HO$4) -> 0 | HP7: =AVERAGE(HP$3:HP$4) -> 0 | HQ7: =AVERAGE(HQ$3:HQ$4) -> 0 | HR7: =AVERAGE(HR$3:HR$4) -> 0 | HS7: =AVERAGE(HS$3:HS$4) -> 0 | HT7: =AVERAGE(HT$3:HT$4) -> 0 | ... HX7: =AVERAGE(HX$3:HX$4) -> 0 | HZ7: =AVERAGE(HZ$3:HZ$4) -> 0 | IA7: =AVERAGE(IA$3:IA$4) -> 0 | IB7: =AVERAGE(IB$3:IB$4) -> 0 | IC7: =AVERAGE(IC$3:IC$4) -> 0 | ID7: =AVERAGE(ID$3:ID$4) -> 0 | IE7: =AVERAGE(IE$3:IE$4) -> 0 | IF7: =AVERAGE(IF$3:IF$4) -> 0 | IG7: =AVERAGE(IG$3:IG$4) -> 0 | ... JK7: =AVERAGE(JK$3:JK$4) -> 0
A8: DEV | B8: =STDEV(B$3:B$4) -> 0 | C8: =STDEV(C$3:C$4) -> 0 | D8: =STDEV(D$3:D$4) -> 0 | E8: =STDEV(E$3:E$4) -> 0 | F8: =STDEV(F$3:F$4) -> 0 | G8: =STDEV(G$3:G$4) -> 0 | H8: =STDEV(H$3:H$4) -> 0 | I8: =STDEV(I$3:I$4) -> 0 | ... K8: =STDEV(K$3:K$4) -> 0 | M8: =STDEV(M$3:M$4) -> 0 | N8: =STDEV(N$3:N$4) -> 0 | O8: =STDEV(O$3:O$4) -> 0 | P8: =STDEV(P$3:P$4) -> 0 | Q8: =STDEV(Q$3:Q$4) -> 0 | R8: =STDEV(R$3:R$4) -> 0 | S8: =STDEV(S$3:S$4) -> 0 | T8: =STDEV(T$3:T$4) -> 0 | ... X8: =STDEV(X$3:X$4) -> 0 | Z8: =STDEV(Z$3:Z$4) -> 0 | AA8: =STDEV(AA$3:AA$4) -> 0 | AB8: =STDEV(AB$3:AB$4) -> 0 | AC8: =STDEV(AC$3:AC$4) -> 0 | AD8: =STDEV(AD$3:AD$4) -> 0 | AE8: =STDEV(AE$3:AE$4) -> 0 | AF8: =STDEV(AF$3:AF$4) -> 0 | AG8: =STDEV(AG$3:AG$4) -> 0 | ... AK8: =STDEV(AK$3:AK$4) -> 0 | AM8: =STDEV(AM$3:AM$4) -> 0 | AN8: =STDEV(AN$3:AN$4) -> 0 | AO8: =STDEV(AO$3:AO$4) -> 0 | AP8: =STDEV(AP$3:AP$4) -> 0 | AQ8: =STDEV(AQ$3:AQ$4) -> 0 | AR8: =STDEV(AR$3:AR$4) -> 0 | AS8: =STDEV(AS$3:AS$4) -> 0 | AT8: =STDEV(AT$3:AT$4) -> 0 | ... AX8: =STDEV(AX$3:AX$4) -> 0 | AZ8: =STDEV(AZ$3:AZ$4) -> 0 | BA8: =STDEV(BA$3:BA$4) -> 0 | BB8: =STDEV(BB$3:BB$4) -> 0 | BC8: =STDEV(BC$3:BC$4) -> 0 | BD8: =STDEV(BD$3:BD$4) -> 0 | BE8: =STDEV(BE$3:BE$4) -> 0 | BF8: =STDEV(BF$3:BF$4) -> 0 | BG8: =STDEV(BG$3:BG$4) -> 0 | ... BK8: =STDEV(BK$3:BK$4) -> 0 | BM8: =STDEV(BM$3:BM$4) -> 0 | BN8: =STDEV(BN$3:BN$4) -> 0 | BO8: =STDEV(BO$3:BO$4) -> 0 | BP8: =STDEV(BP$3:BP$4) -> 0 | BQ8: =STDEV(BQ$3:BQ$4) -> 0 | BR8: =STDEV(BR$3:BR$4) -> 0 | BS8: =STDEV(BS$3:BS$4) -> 0 | BT8: =STDEV(BT$3:BT$4) -> 0 | ... BX8: =STDEV(BX$3:BX$4) -> 0 | BZ8: =STDEV(BZ$3:BZ$4) -> 0 | CA8: =STDEV(CA$3:CA$4) -> 0 | CB8: =STDEV(CB$3:CB$4) -> 0 | CC8: =STDEV(CC$3:CC$4) -> 0 | CD8: =STDEV(CD$3:CD$4) -> 0 | CE8: =STDEV(CE$3:CE$4) -> 0 | CF8: =STDEV(CF$3:CF$4) -> 0 | CG8: =STDEV(CG$3:CG$4) -> 0 | ... CK8: =STDEV(CK$3:CK$4) -> 0 | CM8: =STDEV(CM$3:CM$4) -> 0 | CN8: =STDEV(CN$3:CN$4) -> 0 | CO8: =STDEV(CO$3:CO$4) -> 0 | CP8: =STDEV(CP$3:CP$4) -> 0 | CQ8: =STDEV(CQ$3:CQ$4) -> 0 | CR8: =STDEV(CR$3:CR$4) -> 0 | CS8: =STDEV(CS$3:CS$4) -> 0 | CT8: =STDEV(CT$3:CT$4) -> 0 | ... CX8: =STDEV(CX$3:CX$4) -> 0 | CZ8: =STDEV(CZ$3:CZ$4) -> 0 | DA8: =STDEV(DA$3:DA$4) -> 0 | DB8: =STDEV(DB$3:DB$4) -> 0 | DC8: =STDEV(DC$3:DC$4) -> 0 | DD8: =STDEV(DD$3:DD$4) -> 0 | DE8: =STDEV(DE$3:DE$4) -> 0 | DF8: =STDEV(DF$3:DF$4) -> 0 | DG8: =STDEV(DG$3:DG$4) -> 0 | ... DK8: =STDEV(DK$3:DK$4) -> 0 | DM8: =STDEV(DM$3:DM$4) -> 0 | DN8: =STDEV(DN$3:DN$4) -> 0 | DO8: =STDEV(DO$3:DO$4) -> 0 | DP8: =STDEV(DP$3:DP$4) -> 0 | DQ8: =STDEV(DQ$3:DQ$4) -> 0 | DR8: =STDEV(DR$3:DR$4) -> 0 | DS8: =STDEV(DS$3:DS$4) -> 0 | DT8: =STDEV(DT$3:DT$4) -> 0 | ... DX8: =STDEV(DX$3:DX$4) -> 0 | DZ8: =STDEV(DZ$3:DZ$4) -> 0 | EA8: =STDEV(EA$3:EA$4) -> 0 | EB8: =STDEV(EB$3:EB$4) -> 0 | EC8: =STDEV(EC$3:EC$4) -> 0 | ED8: =STDEV(ED$3:ED$4) -> 0 | EE8: =STDEV(EE$3:EE$4) -> 0 | EF8: =STDEV(EF$3:EF$4) -> 0 | EG8: =STDEV(EG$3:EG$4) -> 0 | ... EK8: =STDEV(EK$3:EK$4) -> 0 | EM8: =STDEV(EM$3:EM$4) -> 0 | EN8: =STDEV(EN$3:EN$4) -> 0 | EO8: =STDEV(EO$3:EO$4) -> 0 | EP8: =STDEV(EP$3:EP$4) -> 0 | EQ8: =STDEV(EQ$3:EQ$4) -> 0 | ER8: =STDEV(ER$3:ER$4) -> 0 | ES8: =STDEV(ES$3:ES$4) -> 0 | ET8: =STDEV(ET$3:ET$4) -> 0 | ... EX8: =STDEV(EX$3:EX$4) -> 0 | EZ8: =STDEV(EZ$3:EZ$4) -> 0 | FA8: =STDEV(FA$3:FA$4) -> 0 | FB8: =STDEV(FB$3:FB$4) -> 0 | FC8: =STDEV(FC$3:FC$4) -> 0 | FD8: =STDEV(FD$3:FD$4) -> 0 | FE8: =STDEV(FE$3:FE$4) -> 0 | FF8: =STDEV(FF$3:FF$4) -> 0 | FG8: =STDEV(FG$3:FG$4) -> 0 | ... FK8: =STDEV(FK$3:FK$4) -> 0 | FM8: =STDEV(FM$3:FM$4) -> 0 | FN8: =STDEV(FN$3:FN$4) -> 0 | FO8: =STDEV(FO$3:FO$4) -> 0 | FP8: =STDEV(FP$3:FP$4) -> 0 | FQ8: =STDEV(FQ$3:FQ$4) -> 0 | FR8: =STDEV(FR$3:FR$4) -> 0 | FS8: =STDEV(FS$3:FS$4) -> 0 | FT8: =STDEV(FT$3:FT$4) -> 0 | ... FX8: =STDEV(FX$3:FX$4) -> 0 | FZ8: =STDEV(FZ$3:FZ$4) -> 0 | GA8: =STDEV(GA$3:GA$4) -> 0 | GB8: =STDEV(GB$3:GB$4) -> 0 | GC8: =STDEV(GC$3:GC$4) -> 0 | GD8: =STDEV(GD$3:GD$4) -> 0 | GE8: =STDEV(GE$3:GE$4) -> 0 | GF8: =STDEV(GF$3:GF$4) -> 0 | GG8: =STDEV(GG$3:GG$4) -> 0 | ... GK8: =STDEV(GK$3:GK$4) -> 0 | GM8: =STDEV(GM$3:GM$4) -> 0 | GN8: =STDEV(GN$3:GN$4) -> 0 | GO8: =STDEV(GO$3:GO$4) -> 0 | GP8: =STDEV(GP$3:GP$4) -> 0 | GQ8: =STDEV(GQ$3:GQ$4) -> 0 | GR8: =STDEV(GR$3:GR$4) -> 0 | GS8: =STDEV(GS$3:GS$4) -> 0 | GT8: =STDEV(GT$3:GT$4) -> 0 | ... GX8: =STDEV(GX$3:GX$4) -> 0 | GZ8: =STDEV(GZ$3:GZ$4) -> 0 | HA8: =STDEV(HA$3:HA$4) -> 0 | HB8: =STDEV(HB$3:HB$4) -> 0 | HC8: =STDEV(HC$3:HC$4) -> 0 | HD8: =STDEV(HD$3:HD$4) -> 0 | HE8: =STDEV(HE$3:HE$4) -> 0 | HF8: =STDEV(HF$3:HF$4) -> 0 | HG8: =STDEV(HG$3:HG$4) -> 0 | ... HK8: =STDEV(HK$3:HK$4) -> 0 | HM8: =STDEV(HM$3:HM$4) -> 0 | HN8: =STDEV(HN$3:HN$4) -> 0 | HO8: =STDEV(HO$3:HO$4) -> 0 | HP8: =STDEV(HP$3:HP$4) -> 0 | HQ8: =STDEV(HQ$3:HQ$4) -> 0 | HR8: =STDEV(HR$3:HR$4) -> 0 | HS8: =STDEV(HS$3:HS$4) -> 0 | HT8: =STDEV(HT$3:HT$4) -> 0 | ... HX8: =STDEV(HX$3:HX$4) -> 0 | HZ8: =STDEV(HZ$3:HZ$4) -> 0 | IA8: =STDEV(IA$3:IA$4) -> 0 | IB8: =STDEV(IB$3:IB$4) -> 0 | IC8: =STDEV(IC$3:IC$4) -> 0 | ID8: =STDEV(ID$3:ID$4) -> 0 | IE8: =STDEV(IE$3:IE$4) -> 0 | IF8: =STDEV(IF$3:IF$4) -> 0 | IG8: =STDEV(IG$3:IG$4) -> 0 | ... JK8: =STDEV(JK$3:JK$4) -> 0
A9: DST | B9: =SUMPRODUCT(--(B$3:B$4-$IB$3:$IB$4)^2)^0.5 -> 0 | C9: =SUMPRODUCT(--(C$3:C$4-$IC$3:$IC$4)^2)^0.5 -> 0 | D9: =SUMPRODUCT(--(D$3:D$4-$ID$3:$ID$4)^2)^0.5 -> 0 | E9: =SUMPRODUCT(--(E$3:E$4-$IE$3:$IE$4)^2)^0.5 -> 0 | F9: =SUMPRODUCT(--(F$3:F$4-$IF$3:$IF$4)^2)^0.5 -> 0 | G9: =SUMPRODUCT(--(G$3:G$4-$IG$3:$IG$4)^2)^0.5 -> 0 | H9: =SUMPRODUCT(--(H$3:H$4-$IH$3:$IH$4)^2)^0.5 -> 0 | I9: =SUMPRODUCT(--(I$3:I$4-$II$3:$II$4)^2)^0.5 -> 0 | J9: =SUMPRODUCT(--(J$3:J$4-$IJ$3:$IJ$4)^2)^0.5 -> 0 | K9: =SUMPRODUCT(--(K$3:K$4-$IK$3:$IK$4)^2)^0.5 -> 0 | M9: =SUMPRODUCT(--(M$3:M$4-$IL$3:$IL$4)^2)^0.5 -> 0 | N9: =SUMPRODUCT(--(N$3:N$4-$IM$3:$IM$4)^2)^0.5 -> 0 | O9: =SUMPRODUCT(--(O$3:O$4-$IB$3:$IB$4)^2)^0.5 -> 0 | P9: =SUMPRODUCT(--(P$3:P$4-$IC$3:$IC$4)^2)^0.5 -> 0 | Q9: =SUMPRODUCT(--(Q$3:Q$4-$ID$3:$ID$4)^2)^0.5 -> 0 | R9: =SUMPRODUCT(--(R$3:R$4-$IE$3:$IE$4)^2)^0.5 -> 0 | S9: =SUMPRODUCT(--(S$3:S$4-$IF$3:$IF$4)^2)^0.5 -> 0 | T9: =SUMPRODUCT(--(T$3:T$4-$IG$3:$IG$4)^2)^0.5 -> 0 | U9: =SUMPRODUCT(--(U$3:U$4-$IH$3:$IH$4)^2)^0.5 -> 0 | V9: =SUMPRODUCT(--(V$3:V$4-$II$3:$II$4)^2)^0.5 -> 0 | W9: =SUMPRODUCT(--(W$3:W$4-$IJ$3:$IJ$4)^2)^0.5 -> 0 | X9: =SUMPRODUCT(--(X$3:X$4-$IK$3:$IK$4)^2)^0.5 -> 0 | Z9: =SUMPRODUCT(--(Z$3:Z$4-$IL$3:$IL$4)^2)^0.5 -> 0 | AA9: =SUMPRODUCT(--(AA$3:AA$4-$IM$3:$IM$4)^2)^0.5 -> 0 | AB9: =SUMPRODUCT(--(AB$3:AB$4-$IB$3:$IB$4)^2)^0.5 -> 0 | AC9: =SUMPRODUCT(--(AC$3:AC$4-$IC$3:$IC$4)^2)^0.5 -> 0 | AD9: =SUMPRODUCT(--(AD$3:AD$4-$ID$3:$ID$4)^2)^0.5 -> 0 | AE9: =SUMPRODUCT(--(AE$3:AE$4-$IE$3:$IE$4)^2)^0.5 -> 0 | AF9: =SUMPRODUCT(--(AF$3:AF$4-$IF$3:$IF$4)^2)^0.5 -> 0 | AG9: =SUMPRODUCT(--(AG$3:AG$4-$IG$3:$IG$4)^2)^0.5 -> 0 | AH9: =SUMPRODUCT(--(AH$3:AH$4-$IH$3:$IH$4)^2)^0.5 -> 0 | AI9: =SUMPRODUCT(--(AI$3:AI$4-$II$3:$II$4)^2)^0.5 -> 0 | AJ9: =SUMPRODUCT(--(AJ$3:AJ$4-$IJ$3:$IJ$4)^2)^0.5 -> 0 | AK9: =SUMPRODUCT(--(AK$3:AK$4-$IK$3:$IK$4)^2)^0.5 -> 0 | AM9: =SUMPRODUCT(--(AM$3:AM$4-$IL$3:$IL$4)^2)^0.5 -> 0 | AN9: =SUMPRODUCT(--(AN$3:AN$4-$IM$3:$IM$4)^2)^0.5 -> 0 | AO9: =SUMPRODUCT(--(AO$3:AO$4-$IB$3:$IB$4)^2)^0.5 -> 0 | AP9: =SUMPRODUCT(--(AP$3:AP$4-$IC$3:$IC$4)^2)^0.5 -> 0 | AQ9: =SUMPRODUCT(--(AQ$3:AQ$4-$ID$3:$ID$4)^2)^0.5 -> 0 | AR9: =SUMPRODUCT(--(AR$3:AR$4-$IE$3:$IE$4)^2)^0.5 -> 0 | AS9: =SUMPRODUCT(--(AS$3:AS$4-$IF$3:$IF$4)^2)^0.5 -> 0 | AT9: =SUMPRODUCT(--(AT$3:AT$4-$IG$3:$IG$4)^2)^0.5 -> 0 | AU9: =SUMPRODUCT(--(AU$3:AU$4-$IH$3:$IH$4)^2)^0.5 -> 0 | AV9: =SUMPRODUCT(--(AV$3:AV$4-$II$3:$II$4)^2)^0.5 -> 0 | AW9: =SUMPRODUCT(--(AW$3:AW$4-$IJ$3:$IJ$4)^2)^0.5 -> 0 | AX9: =SUMPRODUCT(--(AX$3:AX$4-$IK$3:$IK$4)^2)^0.5 -> 0 | AZ9: =SUMPRODUCT(--(AZ$3:AZ$4-$IL$3:$IL$4)^2)^0.5 -> 0 | BA9: =SUMPRODUCT(--(BA$3:BA$4-$IM$3:$IM$4)^2)^0.5 -> 0 | BB9: =SUMPRODUCT(--(BB$3:BB$4-$IB$3:$IB$4)^2)^0.5 -> 0 | BC9: =SUMPRODUCT(--(BC$3:BC$4-$IC$3:$IC$4)^2)^0.5 -> 0 | BD9: =SUMPRODUCT(--(BD$3:BD$4-$ID$3:$ID$4)^2)^0.5 -> 0 | BE9: =SUMPRODUCT(--(BE$3:BE$4-$IE$3:$IE$4)^2)^0.5 -> 0 | BF9: =SUMPRODUCT(--(BF$3:BF$4-$IF$3:$IF$4)^2)^0.5 -> 0 | BG9: =SUMPRODUCT(--(BG$3:BG$4-$IG$3:$IG$4)^2)^0.5 -> 0 | BH9: =SUMPRODUCT(--(BH$3:BH$4-$IH$3:$IH$4)^2)^0.5 -> 0 | BI9: =SUMPRODUCT(--(BI$3:BI$4-$II$3:$II$4)^2)^0.5 -> 0 | BJ9: =SUMPRODUCT(--(BJ$3:BJ$4-$IJ$3:$IJ$4)^2)^0.5 -> 0 | BK9: =SUMPRODUCT(--(BK$3:BK$4-$IK$3:$IK$4)^2)^0.5 -> 0 | BM9: =SUMPRODUCT(--(BM$3:BM$4-$IL$3:$IL$4)^2)^0.5 -> 0 | BN9: =SUMPRODUCT(--(BN$3:BN$4-$IM$3:$IM$4)^2)^0.5 -> 0 | BO9: =SUMPRODUCT(--(BO$3:BO$4-$IB$3:$IB$4)^2)^0.5 -> 0 | BP9: =SUMPRODUCT(--(BP$3:BP$4-$IC$3:$IC$4)^2)^0.5 -> 0 | BQ9: =SUMPRODUCT(--(BQ$3:BQ$4-$ID$3:$ID$4)^2)^0.5 -> 0 | BR9: =SUMPRODUCT(--(BR$3:BR$4-$IE$3:$IE$4)^2)^0.5 -> 0 | BS9: =SUMPRODUCT(--(BS$3:BS$4-$IF$3:$IF$4)^2)^0.5 -> 0 | BT9: =SUMPRODUCT(--(BT$3:BT$4-$IG$3:$IG$4)^2)^0.5 -> 0 | BU9: =SUMPRODUCT(--(BU$3:BU$4-$IH$3:$IH$4)^2)^0.5 -> 0 | BV9: =SUMPRODUCT(--(BV$3:BV$4-$II$3:$II$4)^2)^0.5 -> 0 | BW9: =SUMPRODUCT(--(BW$3:BW$4-$IJ$3:$IJ$4)^2)^0.5 -> 0 | BX9: =SUMPRODUCT(--(BX$3:BX$4-$IK$3:$IK$4)^2)^0.5 -> 0 | BZ9: =SUMPRODUCT(--(BZ$3:BZ$4-$IL$3:$IL$4)^2)^0.5 -> 0 | CA9: =SUMPRODUCT(--(CA$3:CA$4-$IM$3:$IM$4)^2)^0.5 -> 0 | CB9: =SUMPRODUCT(--(CB$3:CB$4-$IB$3:$IB$4)^2)^0.5 -> 0 | CC9: =SUMPRODUCT(--(CC$3:CC$4-$IC$3:$IC$4)^2)^0.5 -> 0 | CD9: =SUMPRODUCT(--(CD$3:CD$4-$ID$3:$ID$4)^2)^0.5 -> 0 | CE9: =SUMPRODUCT(--(CE$3:CE$4-$IE$3:$IE$4)^2)^0.5 -> 0 | CF9: =SUMPRODUCT(--(CF$3:CF$4-$IF$3:$IF$4)^2)^0.5 -> 0 | CG9: =SUMPRODUCT(--(CG$3:CG$4-$IG$3:$IG$4)^2)^0.5 -> 0 | CH9: =SUMPRODUCT(--(CH$3:CH$4-$IH$3:$IH$4)^2)^0.5 -> 0 | CI9: =SUMPRODUCT(--(CI$3:CI$4-$II$3:$II$4)^2)^0.5 -> 0 | CJ9: =SUMPRODUCT(--(CJ$3:CJ$4-$IJ$3:$IJ$4)^2)^0.5 -> 0 | CK9: =SUMPRODUCT(--(CK$3:CK$4-$IK$3:$IK$4)^2)^0.5 -> 0 | CM9: =SUMPRODUCT(--(CM$3:CM$4-$IL$3:$IL$4)^2)^0.5 -> 0 | CN9: =SUMPRODUCT(--(CN$3:CN$4-$IM$3:$IM$4)^2)^0.5 -> 0 | CO9: =SUMPRODUCT(--(CO$3:CO$4-$IB$3:$IB$4)^2)^0.5 -> 0 | CP9: =SUMPRODUCT(--(CP$3:CP$4-$IC$3:$IC$4)^2)^0.5 -> 0 | CQ9: =SUMPRODUCT(--(CQ$3:CQ$4-$ID$3:$ID$4)^2)^0.5 -> 0 | CR9: =SUMPRODUCT(--(CR$3:CR$4-$IE$3:$IE$4)^2)^0.5 -> 0 | CS9: =SUMPRODUCT(--(CS$3:CS$4-$IF$3:$IF$4)^2)^0.5 -> 0 | CT9: =SUMPRODUCT(--(CT$3:CT$4-$IG$3:$IG$4)^2)^0.5 -> 0 | CU9: =SUMPRODUCT(--(CU$3:CU$4-$IH$3:$IH$4)^2)^0.5 -> 0 | CV9: =SUMPRODUCT(--(CV$3:CV$4-$II$3:$II$4)^2)^0.5 -> 0 | CW9: =SUMPRODUCT(--(CW$3:CW$4-$IJ$3:$IJ$4)^2)^0.5 -> 0 | CX9: =SUMPRODUCT(--(CX$3:CX$4-$IK$3:$IK$4)^2)^0.5 -> 0 | CZ9: =SUMPRODUCT(--(CZ$3:CZ$4-$IL$3:$IL$4)^2)^0.5 -> 0 | DA9: =SUMPRODUCT(--(DA$3:DA$4-$IM$3:$IM$4)^2)^0.5 -> 0 | DB9: =SUMPRODUCT(--(DB$3:DB$4-$IB$3:$IB$4)^2)^0.5 -> 0 | DC9: =SUMPRODUCT(--(DC$3:DC$4-$IC$3:$IC$4)^2)^0.5 -> 0 | DD9: =SUMPRODUCT(--(DD$3:DD$4-$ID$3:$ID$4)^2)^0.5 -> 0 | DE9: =SUMPRODUCT(--(DE$3:DE$4-$IE$3:$IE$4)^2)^0.5 -> 0 | DF9: =SUMPRODUCT(--(DF$3:DF$4-$IF$3:$IF$4)^2)^0.5 -> 0 | DG9: =SUMPRODUCT(--(DG$3:DG$4-$IG$3:$IG$4)^2)^0.5 -> 0 | DH9: =SUMPRODUCT(--(DH$3:DH$4-$IH$3:$IH$4)^2)^0.5 -> 0 | DI9: =SUMPRODUCT(--(DI$3:DI$4-$II$3:$II$4)^2)^0.5 -> 0 | DJ9: =SUMPRODUCT(--(DJ$3:DJ$4-$IJ$3:$IJ$4)^2)^0.5 -> 0 | DK9: =SUMPRODUCT(--(DK$3:DK$4-$IK$3:$IK$4)^2)^0.5 -> 0 | DM9: =SUMPRODUCT(--(DM$3:DM$4-$IL$3:$IL$4)^2)^0.5 -> 0 | DN9: =SUMPRODUCT(--(DN$3:DN$4-$IM$3:$IM$4)^2)^0.5 -> 0 | DO9: =SUMPRODUCT(--(DO$3:DO$4-$IB$3:$IB$4)^2)^0.5 -> 0 | DP9: =SUMPRODUCT(--(DP$3:DP$4-$IC$3:$IC$4)^2)^0.5 -> 0 | DQ9: =SUMPRODUCT(--(DQ$3:DQ$4-$ID$3:$ID$4)^2)^0.5 -> 0 | DR9: =SUMPRODUCT(--(DR$3:DR$4-$IE$3:$IE$4)^2)^0.5 -> 0 | DS9: =SUMPRODUCT(--(DS$3:DS$4-$IF$3:$IF$4)^2)^0.5 -> 0 | DT9: =SUMPRODUCT(--(DT$3:DT$4-$IG$3:$IG$4)^2)^0.5 -> 0 | DU9: =SUMPRODUCT(--(DU$3:DU$4-$IH$3:$IH$4)^2)^0.5 -> 0 | DV9: =SUMPRODUCT(--(DV$3:DV$4-$II$3:$II$4)^2)^0.5 -> 0 | DW9: =SUMPRODUCT(--(DW$3:DW$4-$IJ$3:$IJ$4)^2)^0.5 -> 0 | DX9: =SUMPRODUCT(--(DX$3:DX$4-$IK$3:$IK$4)^2)^0.5 -> 0 | DZ9: =SUMPRODUCT(--(DZ$3:DZ$4-$IL$3:$IL$4)^2)^0.5 -> 0 | EA9: =SUMPRODUCT(--(EA$3:EA$4-$IM$3:$IM$4)^2)^0.5 -> 0 | EB9: =SUMPRODUCT(--(EB$3:EB$4-$IB$3:$IB$4)^2)^0.5 -> 0 | EC9: =SUMPRODUCT(--(EC$3:EC$4-$IC$3:$IC$4)^2)^0.5 -> 0 | ED9: =SUMPRODUCT(--(ED$3:ED$4-$ID$3:$ID$4)^2)^0.5 -> 0 | EE9: =SUMPRODUCT(--(EE$3:EE$4-$IE$3:$IE$4)^2)^0.5 -> 0 | EF9: =SUMPRODUCT(--(EF$3:EF$4-$IF$3:$IF$4)^2)^0.5 -> 0 | EG9: =SUMPRODUCT(--(EG$3:EG$4-$IG$3:$IG$4)^2)^0.5 -> 0 | EH9: =SUMPRODUCT(--(EH$3:EH$4-$IH$3:$IH$4)^2)^0.5 -> 0 | EI9: =SUMPRODUCT(--(EI$3:EI$4-$II$3:$II$4)^2)^0.5 -> 0 | EJ9: =SUMPRODUCT(--(EJ$3:EJ$4-$IJ$3:$IJ$4)^2)^0.5 -> 0 | EK9: =SUMPRODUCT(--(EK$3:EK$4-$IK$3:$IK$4)^2)^0.5 -> 0 | EM9: =SUMPRODUCT(--(EM$3:EM$4-$IL$3:$IL$4)^2)^0.5 -> 0 | EN9: =SUMPRODUCT(--(EN$3:EN$4-$IM$3:$IM$4)^2)^0.5 -> 0 | EO9: =SUMPRODUCT(--(EO$3:EO$4-$IB$3:$IB$4)^2)^0.5 -> 0 | EP9: =SUMPRODUCT(--(EP$3:EP$4-$IC$3:$IC$4)^2)^0.5 -> 0 | EQ9: =SUMPRODUCT(--(EQ$3:EQ$4-$ID$3:$ID$4)^2)^0.5 -> 0 | ER9: =SUMPRODUCT(--(ER$3:ER$4-$IE$3:$IE$4)^2)^0.5 -> 0 | ES9: =SUMPRODUCT(--(ES$3:ES$4-$IF$3:$IF$4)^2)^0.5 -> 0 | ET9: =SUMPRODUCT(--(ET$3:ET$4-$IG$3:$IG$4)^2)^0.5 -> 0 | EU9: =SUMPRODUCT(--(EU$3:EU$4-$IH$3:$IH$4)^2)^0.5 -> 0 | EV9: =SUMPRODUCT(--(EV$3:EV$4-$II$3:$II$4)^2)^0.5 -> 0 | EW9: =SUMPRODUCT(--(EW$3:EW$4-$IJ$3:$IJ$4)^2)^0.5 -> 0 | EX9: =SUMPRODUCT(--(EX$3:EX$4-$IK$3:$IK$4)^2)^0.5 -> 0 | EZ9: =SUMPRODUCT(--(EZ$3:EZ$4-$IL$3:$IL$4)^2)^0.5 -> 0 | FA9: =SUMPRODUCT(--(FA$3:FA$4-$IM$3:$IM$4)^2)^0.5 -> 0 | FB9: =SUMPRODUCT(--(FB$3:FB$4-$IB$3:$IB$4)^2)^0.5 -> 0 | FC9: =SUMPRODUCT(--(FC$3:FC$4-$IC$3:$IC$4)^2)^0.5 -> 0 | FD9: =SUMPRODUCT(--(FD$3:FD$4-$ID$3:$ID$4)^2)^0.5 -> 0 | FE9: =SUMPRODUCT(--(FE$3:FE$4-$IE$3:$IE$4)^2)^0.5 -> 0 | FF9: =SUMPRODUCT(--(FF$3:FF$4-$IF$3:$IF$4)^2)^0.5 -> 0 | FG9: =SUMPRODUCT(--(FG$3:FG$4-$IG$3:$IG$4)^2)^0.5 -> 0 | FH9: =SUMPRODUCT(--(FH$3:FH$4-$IH$3:$IH$4)^2)^0.5 -> 0 | FI9: =SUMPRODUCT(--(FI$3:FI$4-$II$3:$II$4)^2)^0.5 -> 0 | FJ9: =SUMPRODUCT(--(FJ$3:FJ$4-$IJ$3:$IJ$4)^2)^0.5 -> 0 | FK9: =SUMPRODUCT(--(FK$3:FK$4-$IK$3:$IK$4)^2)^0.5 -> 0 | FM9: =SUMPRODUCT(--(FM$3:FM$4-$IL$3:$IL$4)^2)^0.5 -> 0 | FN9: =SUMPRODUCT(--(FN$3:FN$4-$IM$3:$IM$4)^2)^0.5 -> 0 | FO9: =SUMPRODUCT(--(FO$3:FO$4-$IB$3:$IB$4)^2)^0.5 -> 0 | FP9: =SUMPRODUCT(--(FP$3:FP$4-$IC$3:$IC$4)^2)^0.5 -> 0 | FQ9: =SUMPRODUCT(--(FQ$3:FQ$4-$ID$3:$ID$4)^2)^0.5 -> 0 | FR9: =SUMPRODUCT(--(FR$3:FR$4-$IE$3:$IE$4)^2)^0.5 -> 0 | FS9: =SUMPRODUCT(--(FS$3:FS$4-$IF$3:$IF$4)^2)^0.5 -> 0 | FT9: =SUMPRODUCT(--(FT$3:FT$4-$IG$3:$IG$4)^2)^0.5 -> 0 | FU9: =SUMPRODUCT(--(FU$3:FU$4-$IH$3:$IH$4)^2)^0.5 -> 0 | FV9: =SUMPRODUCT(--(FV$3:FV$4-$II$3:$II$4)^2)^0.5 -> 0 | FW9: =SUMPRODUCT(--(FW$3:FW$4-$IJ$3:$IJ$4)^2)^0.5 -> 0 | FX9: =SUMPRODUCT(--(FX$3:FX$4-$IK$3:$IK$4)^2)^0.5 -> 0 | FZ9: =SUMPRODUCT(--(FZ$3:FZ$4-$IL$3:$IL$4)^2)^0.5 -> 0 | GA9: =SUMPRODUCT(--(GA$3:GA$4-$IM$3:$IM$4)^2)^0.5 -> 0 | GB9: =SUMPRODUCT(--(GB$3:GB$4-$IB$3:$IB$4)^2)^0.5 -> 0 | GC9: =SUMPRODUCT(--(GC$3:GC$4-$IC$3:$IC$4)^2)^0.5 -> 0 | GD9: =SUMPRODUCT(--(GD$3:GD$4-$ID$3:$ID$4)^2)^0.5 -> 0 | GE9: =SUMPRODUCT(--(GE$3:GE$4-$IE$3:$IE$4)^2)^0.5 -> 0 | GF9: =SUMPRODUCT(--(GF$3:GF$4-$IF$3:$IF$4)^2)^0.5 -> 0 | GG9: =SUMPRODUCT(--(GG$3:GG$4-$IG$3:$IG$4)^2)^0.5 -> 0 | GH9: =SUMPRODUCT(--(GH$3:GH$4-$IH$3:$IH$4)^2)^0.5 -> 0 | GI9: =SUMPRODUCT(--(GI$3:GI$4-$II$3:$II$4)^2)^0.5 -> 0 | GJ9: =SUMPRODUCT(--(GJ$3:GJ$4-$IJ$3:$IJ$4)^2)^0.5 -> 0 | GK9: =SUMPRODUCT(--(GK$3:GK$4-$IK$3:$IK$4)^2)^0.5 -> 0 | GM9: =SUMPRODUCT(--(GM$3:GM$4-$IL$3:$IL$4)^2)^0.5 -> 0 | GN9: =SUMPRODUCT(--(GN$3:GN$4-$IM$3:$IM$4)^2)^0.5 -> 0 | GO9: =SUMPRODUCT(--(GO$3:GO$4-$IB$3:$IB$4)^2)^0.5 -> 0 | GP9: =SUMPRODUCT(--(GP$3:GP$4-$IC$3:$IC$4)^2)^0.5 -> 0 | GQ9: =SUMPRODUCT(--(GQ$3:GQ$4-$ID$3:$ID$4)^2)^0.5 -> 0 | GR9: =SUMPRODUCT(--(GR$3:GR$4-$IE$3:$IE$4)^2)^0.5 -> 0 | GS9: =SUMPRODUCT(--(GS$3:GS$4-$IF$3:$IF$4)^2)^0.5 -> 0 | GT9: =SUMPRODUCT(--(GT$3:GT$4-$IG$3:$IG$4)^2)^0.5 -> 0 | GU9: =SUMPRODUCT(--(GU$3:GU$4-$IH$3:$IH$4)^2)^0.5 -> 0 | GV9: =SUMPRODUCT(--(GV$3:GV$4-$II$3:$II$4)^2)^0.5 -> 0 | GW9: =SUMPRODUCT(--(GW$3:GW$4-$IJ$3:$IJ$4)^2)^0.5 -> 0 | GX9: =SUMPRODUCT(--(GX$3:GX$4-$IK$3:$IK$4)^2)^0.5 -> 0 | GZ9: =SUMPRODUCT(--(GZ$3:GZ$4-$IL$3:$IL$4)^2)^0.5 -> 0 | HA9: =SUMPRODUCT(--(HA$3:HA$4-$IM$3:$IM$4)^2)^0.5 -> 0 | HB9: =SUMPRODUCT(--(HB$3:HB$4-$IB$3:$IB$4)^2)^0.5 -> 0 | HC9: =SUMPRODUCT(--(HC$3:HC$4-$IC$3:$IC$4)^2)^0.5 -> 0 | HD9: =SUMPRODUCT(--(HD$3:HD$4-$ID$3:$ID$4)^2)^0.5 -> 0 | HE9: =SUMPRODUCT(--(HE$3:HE$4-$IE$3:$IE$4)^2)^0.5 -> 0 | HF9: =SUMPRODUCT(--(HF$3:HF$4-$IF$3:$IF$4)^2)^0.5 -> 0 | HG9: =SUMPRODUCT(--(HG$3:HG$4-$IG$3:$IG$4)^2)^0.5 -> 0 | HH9: =SUMPRODUCT(--(HH$3:HH$4-$IH$3:$IH$4)^2)^0.5 -> 0 | HI9: =SUMPRODUCT(--(HI$3:HI$4-$II$3:$II$4)^2)^0.5 -> 0 | HJ9: =SUMPRODUCT(--(HJ$3:HJ$4-$IJ$3:$IJ$4)^2)^0.5 -> 0 | HK9: =SUMPRODUCT(--(HK$3:HK$4-$IK$3:$IK$4)^2)^0.5 -> 0 | HM9: =SUMPRODUCT(--(HM$3:HM$4-$IL$3:$IL$4)^2)^0.5 -> 0 | HN9: =SUMPRODUCT(--(HN$3:HN$4-$IM$3:$IM$4)^2)^0.5 -> 0 | HO9: =SUMPRODUCT(--(HO$3:HO$4-$IB$3:$IB$4)^2)^0.5 -> 0 | HP9: =SUMPRODUCT(--(HP$3:HP$4-$IC$3:$IC$4)^2)^0.5 -> 0 | HQ9: =SUMPRODUCT(--(HQ$3:HQ$4-$ID$3:$ID$4)^2)^0.5 -> 0 | HR9: =SUMPRODUCT(--(HR$3:HR$4-$IE$3:$IE$4)^2)^0.5 -> 0 | HS9: =SUMPRODUCT(--(HS$3:HS$4-$IF$3:$IF$4)^2)^0.5 -> 0 | HT9: =SUMPRODUCT(--(HT$3:HT$4-$IG$3:$IG$4)^2)^0.5 -> 0 | HU9: =SUMPRODUCT(--(HU$3:HU$4-$IH$3:$IH$4)^2)^0.5 -> 0 | HV9: =SUMPRODUCT(--(HV$3:HV$4-$II$3:$II$4)^2)^0.5 -> 0 | HW9: =SUMPRODUCT(--(HW$3:HW$4-$IJ$3:$IJ$4)^2)^0.5 -> 0 | HX9: =SUMPRODUCT(--(HX$3:HX$4-$IK$3:$IK$4)^2)^0.5 -> 0 | HZ9: =SUMPRODUCT(--(HZ$3:HZ$4-$IL$3:$IL$4)^2)^0.5 -> 0 | IA9: =SUMPRODUCT(--(IA$3:IA$4-$IM$3:$IM$4)^2)^0.5 -> 0
