Workbook

Sheet Instances
B1: memelingo-1/lambda-large_mlp-tplp-htc_100 | I1: memelingo-1/lambda-large_mlp-tplp-htc_150 | P1: memelingo-1/lambda-large_mlp-tplp-htc_200 | W1: memelingo-1/lambda-large_mlp-tplp-htcdl_100 | AD1: memelingo-1/lambda-large_mlp-tplp-htcdl_150 | AK1: memelingo-1/lambda-large_mlp-tplp-htcdl_200 | AR1: memelingo-1/lambda-small_mlp-tplp-ht_10 | AY1: memelingo-1/lambda-small_mlp-tplp-ht_15 | BF1: memelingo-1/lambda-small_mlp-tplp-ht_20 | BM1: memelingo-1/lambda-small_mlp-tplp-ht_25 | BT1: memelingo-1/lambda-small_mlp-tplp-ht_30 | CA1: memelingo-1/lambda-small_mlp-tplp-ht_35 | CH1: memelingo-1/lambda-small_mlp-tplp-ht_40 | CO1: memelingo-1/lambda-small_mlp-tplp-ht_45 | CV1: memelingo-1/lambda-small_mlp-tplp-ht_50 | DC1: memelingo-1/lambda-small_mlp-tplp-htc_10 | DJ1: memelingo-1/lambda-small_mlp-tplp-htc_15 | DQ1: memelingo-1/lambda-small_mlp-tplp-htc_20 | DX1: memelingo-1/lambda-small_mlp-tplp-htc_25 | EE1: memelingo-1/lambda-small_mlp-tplp-htc_30 | EL1: memelingo-1/lambda-small_mlp-tplp-htc_35 | ES1: memelingo-1/lambda-small_mlp-tplp-htc_40 | EZ1: memelingo-1/lambda-small_mlp-tplp-htc_45 | FG1: memelingo-1/lambda-small_mlp-tplp-htc_50 | FN1: memelingo-1/lambda-small_mlp-tplp-htcdl_10 | FU1: memelingo-1/lambda-small_mlp-tplp-htcdl_15 | GB1: memelingo-1/lambda-small_mlp-tplp-htcdl_20 | GI1: memelingo-1/lambda-small_mlp-tplp-htcdl_25 | GP1: memelingo-1/lambda-small_mlp-tplp-htcdl_30 | GW1: memelingo-1/lambda-small_mlp-tplp-htcdl_35 | HD1: memelingo-1/lambda-small_mlp-tplp-htcdl_40 | HK1: memelingo-1/lambda-small_mlp-tplp-htcdl_45 | HR1: memelingo-1/lambda-small_mlp-tplp-htcdl_50 | HY1: min | IE1: median | IK1: max
B2: time | C2: stime | D2: status | E2: rules | F2: ctime | G2: fmtime | H2: memout | I2: time | J2: stime | K2: status | L2: rules | M2: ctime | N2: fmtime | O2: memout | P2: time | Q2: stime | R2: status | S2: rules | T2: ctime | U2: fmtime | V2: memout | W2: time | X2: stime | Y2: status | Z2: rules | AA2: ctime | AB2: fmtime | AC2: memout | AD2: time | AE2: stime | AF2: status | AG2: rules | AH2: ctime | AI2: fmtime | AJ2: memout | AK2: time | AL2: stime | AM2: status | AN2: rules | AO2: ctime | AP2: fmtime | AQ2: memout | AR2: time | AS2: stime | AT2: status | AU2: rules | AV2: ctime | AW2: fmtime | AX2: memout | AY2: time | AZ2: stime | BA2: status | BB2: rules | BC2: ctime | BD2: fmtime | BE2: memout | BF2: time | BG2: stime | BH2: status | BI2: rules | BJ2: ctime | BK2: fmtime | BL2: memout | BM2: time | BN2: stime | BO2: status | BP2: rules | BQ2: ctime | BR2: fmtime | BS2: memout | BT2: time | BU2: stime | BV2: status | BW2: rules | BX2: ctime | BY2: fmtime | BZ2: memout | CA2: time | CB2: stime | CC2: status | CD2: rules | CE2: ctime | CF2: fmtime | CG2: memout | CH2: time | CI2: stime | CJ2: status | CK2: rules | CL2: ctime | CM2: fmtime | CN2: memout | CO2: time | CP2: stime | CQ2: status | CR2: rules | CS2: ctime | CT2: fmtime | CU2: memout | CV2: time | CW2: stime | CX2: status | CY2: rules | CZ2: ctime | DA2: fmtime | DB2: memout | DC2: time | DD2: stime | DE2: status | DF2: rules | DG2: ctime | DH2: fmtime | DI2: memout | DJ2: time | DK2: stime | DL2: status | DM2: rules | DN2: ctime | DO2: fmtime | DP2: memout | DQ2: time | DR2: stime | DS2: status | DT2: rules | DU2: ctime | DV2: fmtime | DW2: memout | DX2: time | DY2: stime | DZ2: status | EA2: rules | EB2: ctime | EC2: fmtime | ED2: memout | EE2: time | EF2: stime | EG2: status | EH2: rules | EI2: ctime | EJ2: fmtime | EK2: memout | EL2: time | EM2: stime | EN2: status | EO2: rules | EP2: ctime | EQ2: fmtime | ER2: memout | ES2: time | ET2: stime | EU2: status | EV2: rules | EW2: ctime | EX2: fmtime | EY2: memout | EZ2: time | FA2: stime | FB2: status | FC2: rules | FD2: ctime | FE2: fmtime | FF2: memout | FG2: time | FH2: stime | FI2: status | FJ2: rules | FK2: ctime | FL2: fmtime | FM2: memout | FN2: time | FO2: stime | FP2: status | FQ2: rules | FR2: ctime | FS2: fmtime | FT2: memout | FU2: time | FV2: stime | FW2: status | FX2: rules | FY2: ctime | FZ2: fmtime | GA2: memout | GB2: time | GC2: stime | GD2: status | GE2: rules | GF2: ctime | GG2: fmtime | GH2: memout | GI2: time | GJ2: stime | GK2: status | GL2: rules | GM2: ctime | GN2: fmtime | GO2: memout | GP2: time | GQ2: stime | GR2: status | GS2: rules | GT2: ctime | GU2: fmtime | GV2: memout | GW2: time | GX2: stime | GY2: status | GZ2: rules | HA2: ctime | HB2: fmtime | HC2: memout | HD2: time | HE2: stime | HF2: status | HG2: rules | HH2: ctime | HI2: fmtime | HJ2: memout | HK2: time | HL2: stime | HM2: status | HN2: rules | HO2: ctime | HP2: fmtime | HQ2: memout | HR2: time | HS2: stime | HT2: status | HU2: rules | HV2: ctime | HW2: fmtime | HX2: memout | HY2: time | HZ2: stime | IA2: rules | IB2: ctime | IC2: fmtime | ID2: memout | IE2: time | IF2: stime | IG2: rules | IH2: ctime | II2: fmtime | IJ2: memout | IK2: time | IL2: stime | IM2: rules | IN2: ctime | IO2: fmtime | IP2: memout
A3: instances/ft06 | AR3: 158.46 | AS3: 145.77 | AT3: UNSATISFIABLE | AU3: 1680929 | AV3: 148.319 | AW3: 0 | AX3: 0 | AY3: 1200 | AZ3: 1189.46 | BA3: UNKNOWN | BB3: 3477919 | BC3: 1193.971 | BD3: 0 | BE3: 0 | BF3: 1200 | BG3: 1187.07 | BH3: UNKNOWN | BI3: 5585084 | BJ3: 1194.495 | BK3: 0 | BL3: 0 | BM3: 1200 | BN3: 1183.66 | BO3: UNKNOWN | BP3: 7799174 | BQ3: 1194.111 | BR3: 0 | BS3: 0 | BT3: 1200 | BU3: 1180.29 | BV3: UNKNOWN | BW3: 9950689 | BX3: 1193.64 | BY3: 0 | BZ3: 0 | CA3: 1200 | CB3: 1177.13 | CC3: UNKNOWN | CD3: 11903879 | CE3: 1192.921 | CF3: 0 | CG3: 0 | CH3: 739.95 | CI3: 711.73 | CJ3: SATISFIABLE | CK3: 13556744 | CL3: 729.882 | CM3: 711.72 | CN3: 0 | CO3: 228.49 | CP3: 202.39 | CQ3: SATISFIABLE | CR3: 14841034 | CS3: 221.798 | CT3: 202.37 | CU3: 0 | CV3: 48.46 | CW3: 18.31 | CX3: SATISFIABLE | CY3: 15722249 | CZ3: 40.677 | DA3: 18.3 | DB3: 0 | DC3: 10.23 | DD3: 3.04 | DE3: UNSATISFIABLE | DF3: 62428 | DG3: 3.52 | DH3: 0 | DI3: 0 | DJ3: 400.47 | DK3: 392.52 | DL3: UNSATISFIABLE | DM3: 103743 | DN3: 393.202 | DO3: 0 | DP3: 0 | DQ3: 22.79 | DR3: 13.46 | DS3: SATISFIABLE | DT3: 152933 | DU3: 14.37 | DV3: 13.45 | DW3: 0 | DX3: 1200 | DY3: 1192.51 | DZ3: UNKNOWN | EA3: 209998 | EB3: 1193.69 | EC3: 0 | ED3: 0 | EE3: 106.84 | EF3: 98.28 | EG3: SATISFIABLE | EH3: 274938 | EI3: 99.871 | EJ3: 98.28 | EK3: 0 | EL3: 277.28 | EM3: 268.62 | EN3: SATISFIABLE | EO3: 347753 | EP3: 270.621 | EQ3: 268.61 | ER3: 0 | ES3: 44.08 | ET3: 35.02 | EU3: SATISFIABLE | EV3: 428443 | EW3: 37.554 | EX3: 35.01 | EY3: 0 | EZ3: 33.72 | FA3: 23.18 | FB3: SATISFIABLE | FC3: 517008 | FD3: 26.265 | FE3: 23.17 | FF3: 0 | FG3: 61.18 | FH3: 50.91 | FI3: SATISFIABLE | FJ3: 613448 | FK3: 54.06 | FL3: 50.9 | FM3: 0 | FN3: 8.01 | FO3: 0.49 | FP3: UNSATISFIABLE | FQ3: 62428 | FR3: 0.963 | FS3: 0 | FT3: 0 | FU3: 560.66 | FV3: 553.83 | FW3: UNSATISFIABLE | FX3: 103743 | FY3: 554.42 | FZ3: 0 | GA3: 0 | GB3: 1134.68 | GC3: 1126.37 | GD3: SATISFIABLE | GE3: 152933 | GF3: 1127.328 | GG3: 1126.36 | GH3: 0 | GI3: 1200 | GJ3: 1192.5 | GK3: UNKNOWN | GL3: 209998 | GM3: 1193.672 | GN3: 0 | GO3: 0 | GP3: 290.76 | GQ3: 282.75 | GR3: SATISFIABLE | GS3: 274938 | GT3: 284.221 | GU3: 282.75 | GV3: 0 | GW3: 428.22 | GX3: 419.95 | GY3: SATISFIABLE | GZ3: 347753 | HA3: 421.776 | HB3: 419.94 | HC3: 0 | HD3: 98.96 | HE3: 89.97 | HF3: SATISFIABLE | HG3: 428443 | HH3: 92.233 | HI3: 89.96 | HJ3: 0 | HK3: 95.96 | HL3: 86.98 | HM3: SATISFIABLE | HN3: 517008 | HO3: 89.486 | HP3: 86.98 | HQ3: 0 | HR3: 35.78 | HS3: 26.33 | HT3: SATISFIABLE | HU3: 613448 | HV3: 29.187 | HW3: 26.32 | HX3: 0 | HY3: =MIN($B3,$I3,$P3,$W3,$AD3,$AK3,$AR3,$AY3,$BF3,$BM3,$BT3,$CA3,$CH3,$CO3,$CV3,$DC3,$DJ3,$DQ3,$DX3,$EE3,$EL3,$ES3,$EZ3,$FG3,$FN3,$FU3,$GB3,$GI3,$GP3,$GW3,$HD3,$HK3,$HR3) -> 0 | HZ3: =MIN($C3,$J3,$Q3,$X3,$AE3,$AL3,$AS3,$AZ3,$BG3,$BN3,$BU3,$CB3,$CI3,$CP3,$CW3,$DD3,$DK3,$DR3,$DY3,$EF3,$EM3,$ET3,$FA3,$FH3,$FO3,$FV3,$GC3,$GJ3,$GQ3,$GX3,$HE3,$HL3,$HS3) -> 0 | IA3: =MIN($E3,$L3,$S3,$Z3,$AG3,$AN3,$AU3,$BB3,$BI3,$BP3,$BW3,$CD3,$CK3,$CR3,$CY3,$DF3,$DM3,$DT3,$EA3,$EH3,$EO3,$EV3,$FC3,$FJ3,$FQ3,$FX3,$GE3,$GL3,$GS3,$GZ3,$HG3,$HN3,$HU3) -> 0 | IB3: =MIN($F3,$M3,$T3,$AA3,$AH3,$AO3,$AV3,$BC3,$BJ3,$BQ3,$BX3,$CE3,$CL3,$CS3,$CZ3,$DG3,$DN3,$DU3,$EB3,$EI3,$EP3,$EW3,$FD3,$FK3,$FR3,$FY3,$GF3,$GM3,$GT3,$HA3,$HH3,$HO3,$HV3) -> 0 | IC3: =MIN($G3,$N3,$U3,$AB3,$AI3,$AP3,$AW3,$BD3,$BK3,$BR3,$BY3,$CF3,$CM3,$CT3,$DA3,$DH3,$DO3,$DV3,$EC3,$EJ3,$EQ3,$EX3,$FE3,$FL3,$FS3,$FZ3,$GG3,$GN3,$GU3,$HB3,$HI3,$HP3,$HW3) -> 0 | ID3: =MIN($H3,$O3,$V3,$AC3,$AJ3,$AQ3,$AX3,$BE3,$BL3,$BS3,$BZ3,$CG3,$CN3,$CU3,$DB3,$DI3,$DP3,$DW3,$ED3,$EK3,$ER3,$EY3,$FF3,$FM3,$FT3,$GA3,$GH3,$GO3,$GV3,$HC3,$HJ3,$HQ3,$HX3) -> 0 | IE3: =MEDIAN($B3,$I3,$P3,$W3,$AD3,$AK3,$AR3,$AY3,$BF3,$BM3,$BT3,$CA3,$CH3,$CO3,$CV3,$DC3,$DJ3,$DQ3,$DX3,$EE3,$EL3,$ES3,$EZ3,$FG3,$FN3,$FU3,$GB3,$GI3,$GP3,$GW3,$HD3,$HK3,$HR3) -> 0 | IF3: =MEDIAN($C3,$J3,$Q3,$X3,$AE3,$AL3,$AS3,$AZ3,$BG3,$BN3,$BU3,$CB3,$CI3,$CP3,$CW3,$DD3,$DK3,$DR3,$DY3,$EF3,$EM3,$ET3,$FA3,$FH3,$FO3,$FV3,$GC3,$GJ3,$GQ3,$GX3,$HE3,$HL3,$HS3) -> 0 | IG3: =MEDIAN($E3,$L3,$S3,$Z3,$AG3,$AN3,$AU3,$BB3,$BI3,$BP3,$BW3,$CD3,$CK3,$CR3,$CY3,$DF3,$DM3,$DT3,$EA3,$EH3,$EO3,$EV3,$FC3,$FJ3,$FQ3,$FX3,$GE3,$GL3,$GS3,$GZ3,$HG3,$HN3,$HU3) -> 0 | IH3: =MEDIAN($F3,$M3,$T3,$AA3,$AH3,$AO3,$AV3,$BC3,$BJ3,$BQ3,$BX3,$CE3,$CL3,$CS3,$CZ3,$DG3,$DN3,$DU3,$EB3,$EI3,$EP3,$EW3,$FD3,$FK3,$FR3,$FY3,$GF3,$GM3,$GT3,$HA3,$HH3,$HO3,$HV3) -> 0 | II3: =MEDIAN($G3,$N3,$U3,$AB3,$AI3,$AP3,$AW3,$BD3,$BK3,$BR3,$BY3,$CF3,$CM3,$CT3,$DA3,$DH3,$DO3,$DV3,$EC3,$EJ3,$EQ3,$EX3,$FE3,$FL3,$FS3,$FZ3,$GG3,$GN3,$GU3,$HB3,$HI3,$HP3,$HW3) -> 0 | IJ3: =MEDIAN($H3,$O3,$V3,$AC3,$AJ3,$AQ3,$AX3,$BE3,$BL3,$BS3,$BZ3,$CG3,$CN3,$CU3,$DB3,$DI3,$DP3,$DW3,$ED3,$EK3,$ER3,$EY3,$FF3,$FM3,$FT3,$GA3,$GH3,$GO3,$GV3,$HC3,$HJ3,$HQ3,$HX3) -> 0 | IK3: =MAX($B3,$I3,$P3,$W3,$AD3,$AK3,$AR3,$AY3,$BF3,$BM3,$BT3,$CA3,$CH3,$CO3,$CV3,$DC3,$DJ3,$DQ3,$DX3,$EE3,$EL3,$ES3,$EZ3,$FG3,$FN3,$FU3,$GB3,$GI3,$GP3,$GW3,$HD3,$HK3,$HR3) -> 0 | IL3: =MAX($C3,$J3,$Q3,$X3,$AE3,$AL3,$AS3,$AZ3,$BG3,$BN3,$BU3,$CB3,$CI3,$CP3,$CW3,$DD3,$DK3,$DR3,$DY3,$EF3,$EM3,$ET3,$FA3,$FH3,$FO3,$FV3,$GC3,$GJ3,$GQ3,$GX3,$HE3,$HL3,$HS3) -> 0 | IM3: =MAX($E3,$L3,$S3,$Z3,$AG3,$AN3,$AU3,$BB3,$BI3,$BP3,$BW3,$CD3,$CK3,$CR3,$CY3,$DF3,$DM3,$DT3,$EA3,$EH3,$EO3,$EV3,$FC3,$FJ3,$FQ3,$FX3,$GE3,$GL3,$GS3,$GZ3,$HG3,$HN3,$HU3) -> 0 | IN3: =MAX($F3,$M3,$T3,$AA3,$AH3,$AO3,$AV3,$BC3,$BJ3,$BQ3,$BX3,$CE3,$CL3,$CS3,$CZ3,$DG3,$DN3,$DU3,$EB3,$EI3,$EP3,$EW3,$FD3,$FK3,$FR3,$FY3,$GF3,$GM3,$GT3,$HA3,$HH3,$HO3,$HV3) -> 0 | IO3: =MAX($G3,$N3,$U3,$AB3,$AI3,$AP3,$AW3,$BD3,$BK3,$BR3,$BY3,$CF3,$CM3,$CT3,$DA3,$DH3,$DO3,$DV3,$EC3,$EJ3,$EQ3,$EX3,$FE3,$FL3,$FS3,$FZ3,$GG3,$GN3,$GU3,$HB3,$HI3,$HP3,$HW3) -> 0 | IP3: =MAX($H3,$O3,$V3,$AC3,$AJ3,$AQ3,$AX3,$BE3,$BL3,$BS3,$BZ3,$CG3,$CN3,$CU3,$DB3,$DI3,$DP3,$DW3,$ED3,$EK3,$ER3,$EY3,$FF3,$FM3,$FT3,$GA3,$GH3,$GO3,$GV3,$HC3,$HJ3,$HQ3,$HX3) -> 0
A4: instances/ft10 | B4: 1200 | C4: 1148.6 | D4: UNKNOWN | E4: 6162257 | F4: 1194.466 | G4: 0 | H4: 0 | I4: 1200 | J4: 1095.38 | K4: UNKNOWN | L4: 12901932 | M4: 1194.449 | N4: 0 | O4: 0 | P4: 1200 | V4: 0 | W4: 1200 | AC4: 0 | AD4: 1200 | AJ4: 0 | AK4: 1200 | AQ4: 0 | HY4: =MIN($B4,$I4,$P4,$W4,$AD4,$AK4,$AR4,$AY4,$BF4,$BM4,$BT4,$CA4,$CH4,$CO4,$CV4,$DC4,$DJ4,$DQ4,$DX4,$EE4,$EL4,$ES4,$EZ4,$FG4,$FN4,$FU4,$GB4,$GI4,$GP4,$GW4,$HD4,$HK4,$HR4) -> 0 | HZ4: =MIN($C4,$J4,$Q4,$X4,$AE4,$AL4,$AS4,$AZ4,$BG4,$BN4,$BU4,$CB4,$CI4,$CP4,$CW4,$DD4,$DK4,$DR4,$DY4,$EF4,$EM4,$ET4,$FA4,$FH4,$FO4,$FV4,$GC4,$GJ4,$GQ4,$GX4,$HE4,$HL4,$HS4) -> 0 | IA4: =MIN($E4,$L4,$S4,$Z4,$AG4,$AN4,$AU4,$BB4,$BI4,$BP4,$BW4,$CD4,$CK4,$CR4,$CY4,$DF4,$DM4,$DT4,$EA4,$EH4,$EO4,$EV4,$FC4,$FJ4,$FQ4,$FX4,$GE4,$GL4,$GS4,$GZ4,$HG4,$HN4,$HU4) -> 0 | IB4: =MIN($F4,$M4,$T4,$AA4,$AH4,$AO4,$AV4,$BC4,$BJ4,$BQ4,$BX4,$CE4,$CL4,$CS4,$CZ4,$DG4,$DN4,$DU4,$EB4,$EI4,$EP4,$EW4,$FD4,$FK4,$FR4,$FY4,$GF4,$GM4,$GT4,$HA4,$HH4,$HO4,$HV4) -> 0 | IC4: =MIN($G4,$N4,$U4,$AB4,$AI4,$AP4,$AW4,$BD4,$BK4,$BR4,$BY4,$CF4,$CM4,$CT4,$DA4,$DH4,$DO4,$DV4,$EC4,$EJ4,$EQ4,$EX4,$FE4,$FL4,$FS4,$FZ4,$GG4,$GN4,$GU4,$HB4,$HI4,$HP4,$HW4) -> 0 | ID4: =MIN($H4,$O4,$V4,$AC4,$AJ4,$AQ4,$AX4,$BE4,$BL4,$BS4,$BZ4,$CG4,$CN4,$CU4,$DB4,$DI4,$DP4,$DW4,$ED4,$EK4,$ER4,$EY4,$FF4,$FM4,$FT4,$GA4,$GH4,$GO4,$GV4,$HC4,$HJ4,$HQ4,$HX4) -> 0 | IE4: =MEDIAN($B4,$I4,$P4,$W4,$AD4,$AK4,$AR4,$AY4,$BF4,$BM4,$BT4,$CA4,$CH4,$CO4,$CV4,$DC4,$DJ4,$DQ4,$DX4,$EE4,$EL4,$ES4,$EZ4,$FG4,$FN4,$FU4,$GB4,$GI4,$GP4,$GW4,$HD4,$HK4,$HR4) -> 0 | IF4: =MEDIAN($C4,$J4,$Q4,$X4,$AE4,$AL4,$AS4,$AZ4,$BG4,$BN4,$BU4,$CB4,$CI4,$CP4,$CW4,$DD4,$DK4,$DR4,$DY4,$EF4,$EM4,$ET4,$FA4,$FH4,$FO4,$FV4,$GC4,$GJ4,$GQ4,$GX4,$HE4,$HL4,$HS4) -> 0 | IG4: =MEDIAN($E4,$L4,$S4,$Z4,$AG4,$AN4,$AU4,$BB4,$BI4,$BP4,$BW4,$CD4,$CK4,$CR4,$CY4,$DF4,$DM4,$DT4,$EA4,$EH4,$EO4,$EV4,$FC4,$FJ4,$FQ4,$FX4,$GE4,$GL4,$GS4,$GZ4,$HG4,$HN4,$HU4) -> 0 | IH4: =MEDIAN($F4,$M4,$T4,$AA4,$AH4,$AO4,$AV4,$BC4,$BJ4,$BQ4,$BX4,$CE4,$CL4,$CS4,$CZ4,$DG4,$DN4,$DU4,$EB4,$EI4,$EP4,$EW4,$FD4,$FK4,$FR4,$FY4,$GF4,$GM4,$GT4,$HA4,$HH4,$HO4,$HV4) -> 0 | II4: =MEDIAN($G4,$N4,$U4,$AB4,$AI4,$AP4,$AW4,$BD4,$BK4,$BR4,$BY4,$CF4,$CM4,$CT4,$DA4,$DH4,$DO4,$DV4,$EC4,$EJ4,$EQ4,$EX4,$FE4,$FL4,$FS4,$FZ4,$GG4,$GN4,$GU4,$HB4,$HI4,$HP4,$HW4) -> 0 | IJ4: =MEDIAN($H4,$O4,$V4,$AC4,$AJ4,$AQ4,$AX4,$BE4,$BL4,$BS4,$BZ4,$CG4,$CN4,$CU4,$DB4,$DI4,$DP4,$DW4,$ED4,$EK4,$ER4,$EY4,$FF4,$FM4,$FT4,$GA4,$GH4,$GO4,$GV4,$HC4,$HJ4,$HQ4,$HX4) -> 0 | IK4: =MAX($B4,$I4,$P4,$W4,$AD4,$AK4,$AR4,$AY4,$BF4,$BM4,$BT4,$CA4,$CH4,$CO4,$CV4,$DC4,$DJ4,$DQ4,$DX4,$EE4,$EL4,$ES4,$EZ4,$FG4,$FN4,$FU4,$GB4,$GI4,$GP4,$GW4,$HD4,$HK4,$HR4) -> 0 | IL4: =MAX($C4,$J4,$Q4,$X4,$AE4,$AL4,$AS4,$AZ4,$BG4,$BN4,$BU4,$CB4,$CI4,$CP4,$CW4,$DD4,$DK4,$DR4,$DY4,$EF4,$EM4,$ET4,$FA4,$FH4,$FO4,$FV4,$GC4,$GJ4,$GQ4,$GX4,$HE4,$HL4,$HS4) -> 0 | IM4: =MAX($E4,$L4,$S4,$Z4,$AG4,$AN4,$AU4,$BB4,$BI4,$BP4,$BW4,$CD4,$CK4,$CR4,$CY4,$DF4,$DM4,$DT4,$EA4,$EH4,$EO4,$EV4,$FC4,$FJ4,$FQ4,$FX4,$GE4,$GL4,$GS4,$GZ4,$HG4,$HN4,$HU4) -> 0 | IN4: =MAX($F4,$M4,$T4,$AA4,$AH4,$AO4,$AV4,$BC4,$BJ4,$BQ4,$BX4,$CE4,$CL4,$CS4,$CZ4,$DG4,$DN4,$DU4,$EB4,$EI4,$EP4,$EW4,$FD4,$FK4,$FR4,$FY4,$GF4,$GM4,$GT4,$HA4,$HH4,$HO4,$HV4) -> 0 | IO4: =MAX($G4,$N4,$U4,$AB4,$AI4,$AP4,$AW4,$BD4,$BK4,$BR4,$BY4,$CF4,$CM4,$CT4,$DA4,$DH4,$DO4,$DV4,$EC4,$EJ4,$EQ4,$EX4,$FE4,$FL4,$FS4,$FZ4,$GG4,$GN4,$GU4,$HB4,$HI4,$HP4,$HW4) -> 0 | IP4: =MAX($H4,$O4,$V4,$AC4,$AJ4,$AQ4,$AX4,$BE4,$BL4,$BS4,$BZ4,$CG4,$CN4,$CU4,$DB4,$DI4,$DP4,$DW4,$ED4,$EK4,$ER4,$EY4,$FF4,$FM4,$FT4,$GA4,$GH4,$GO4,$GV4,$HC4,$HJ4,$HQ4,$HX4) -> 0
A6: SUM | B6: =SUM(B$3:B$4) -> 0 | C6: =SUM(C$3:C$4) -> 0 | E6: =SUM(E$3:E$4) -> 0 | F6: =SUM(F$3:F$4) -> 0 | G6: =SUM(G$3:G$4) -> 0 | H6: =SUM(H$3:H$4) -> 0 | I6: =SUM(I$3:I$4) -> 0 | J6: =SUM(J$3:J$4) -> 0 | L6: =SUM(L$3:L$4) -> 0 | M6: =SUM(M$3:M$4) -> 0 | N6: =SUM(N$3:N$4) -> 0 | O6: =SUM(O$3:O$4) -> 0 | P6: =SUM(P$3:P$4) -> 0 | V6: =SUM(V$3:V$4) -> 0 | W6: =SUM(W$3:W$4) -> 0 | AC6: =SUM(AC$3:AC$4) -> 0 | AD6: =SUM(AD$3:AD$4) -> 0 | AJ6: =SUM(AJ$3:AJ$4) -> 0 | AK6: =SUM(AK$3:AK$4) -> 0 | AQ6: =SUM(AQ$3:AQ$4) -> 0 | AR6: =SUM(AR$3:AR$4) -> 0 | AS6: =SUM(AS$3:AS$4) -> 0 | AU6: =SUM(AU$3:AU$4) -> 0 | AV6: =SUM(AV$3:AV$4) -> 0 | AW6: =SUM(AW$3:AW$4) -> 0 | AX6: =SUM(AX$3:AX$4) -> 0 | AY6: =SUM(AY$3:AY$4) -> 0 | AZ6: =SUM(AZ$3:AZ$4) -> 0 | BB6: =SUM(BB$3:BB$4) -> 0 | BC6: =SUM(BC$3:BC$4) -> 0 | BD6: =SUM(BD$3:BD$4) -> 0 | BE6: =SUM(BE$3:BE$4) -> 0 | BF6: =SUM(BF$3:BF$4) -> 0 | BG6: =SUM(BG$3:BG$4) -> 0 | BI6: =SUM(BI$3:BI$4) -> 0 | BJ6: =SUM(BJ$3:BJ$4) -> 0 | BK6: =SUM(BK$3:BK$4) -> 0 | BL6: =SUM(BL$3:BL$4) -> 0 | BM6: =SUM(BM$3:BM$4) -> 0 | BN6: =SUM(BN$3:BN$4) -> 0 | BP6: =SUM(BP$3:BP$4) -> 0 | BQ6: =SUM(BQ$3:BQ$4) -> 0 | BR6: =SUM(BR$3:BR$4) -> 0 | BS6: =SUM(BS$3:BS$4) -> 0 | BT6: =SUM(BT$3:BT$4) -> 0 | BU6: =SUM(BU$3:BU$4) -> 0 | BW6: =SUM(BW$3:BW$4) -> 0 | BX6: =SUM(BX$3:BX$4) -> 0 | BY6: =SUM(BY$3:BY$4) -> 0 | BZ6: =SUM(BZ$3:BZ$4) -> 0 | CA6: =SUM(CA$3:CA$4) -> 0 | CB6: =SUM(CB$3:CB$4) -> 0 | CD6: =SUM(CD$3:CD$4) -> 0 | CE6: =SUM(CE$3:CE$4) -> 0 | CF6: =SUM(CF$3:CF$4) -> 0 | CG6: =SUM(CG$3:CG$4) -> 0 | CH6: =SUM(CH$3:CH$4) -> 0 | CI6: =SUM(CI$3:CI$4) -> 0 | CK6: =SUM(CK$3:CK$4) -> 0 | CL6: =SUM(CL$3:CL$4) -> 0 | CM6: =SUM(CM$3:CM$4) -> 0 | CN6: =SUM(CN$3:CN$4) -> 0 | CO6: =SUM(CO$3:CO$4) -> 0 | CP6: =SUM(CP$3:CP$4) -> 0 | CR6: =SUM(CR$3:CR$4) -> 0 | CS6: =SUM(CS$3:CS$4) -> 0 | CT6: =SUM(CT$3:CT$4) -> 0 | CU6: =SUM(CU$3:CU$4) -> 0 | CV6: =SUM(CV$3:CV$4) -> 0 | CW6: =SUM(CW$3:CW$4) -> 0 | CY6: =SUM(CY$3:CY$4) -> 0 | CZ6: =SUM(CZ$3:CZ$4) -> 0 | DA6: =SUM(DA$3:DA$4) -> 0 | DB6: =SUM(DB$3:DB$4) -> 0 | DC6: =SUM(DC$3:DC$4) -> 0 | DD6: =SUM(DD$3:DD$4) -> 0 | DF6: =SUM(DF$3:DF$4) -> 0 | DG6: =SUM(DG$3:DG$4) -> 0 | DH6: =SUM(DH$3:DH$4) -> 0 | DI6: =SUM(DI$3:DI$4) -> 0 | DJ6: =SUM(DJ$3:DJ$4) -> 0 | DK6: =SUM(DK$3:DK$4) -> 0 | DM6: =SUM(DM$3:DM$4) -> 0 | DN6: =SUM(DN$3:DN$4) -> 0 | DO6: =SUM(DO$3:DO$4) -> 0 | DP6: =SUM(DP$3:DP$4) -> 0 | DQ6: =SUM(DQ$3:DQ$4) -> 0 | DR6: =SUM(DR$3:DR$4) -> 0 | DT6: =SUM(DT$3:DT$4) -> 0 | DU6: =SUM(DU$3:DU$4) -> 0 | DV6: =SUM(DV$3:DV$4) -> 0 | DW6: =SUM(DW$3:DW$4) -> 0 | DX6: =SUM(DX$3:DX$4) -> 0 | DY6: =SUM(DY$3:DY$4) -> 0 | EA6: =SUM(EA$3:EA$4) -> 0 | EB6: =SUM(EB$3:EB$4) -> 0 | EC6: =SUM(EC$3:EC$4) -> 0 | ED6: =SUM(ED$3:ED$4) -> 0 | EE6: =SUM(EE$3:EE$4) -> 0 | EF6: =SUM(EF$3:EF$4) -> 0 | EH6: =SUM(EH$3:EH$4) -> 0 | EI6: =SUM(EI$3:EI$4) -> 0 | EJ6: =SUM(EJ$3:EJ$4) -> 0 | EK6: =SUM(EK$3:EK$4) -> 0 | EL6: =SUM(EL$3:EL$4) -> 0 | EM6: =SUM(EM$3:EM$4) -> 0 | EO6: =SUM(EO$3:EO$4) -> 0 | EP6: =SUM(EP$3:EP$4) -> 0 | EQ6: =SUM(EQ$3:EQ$4) -> 0 | ER6: =SUM(ER$3:ER$4) -> 0 | ES6: =SUM(ES$3:ES$4) -> 0 | ET6: =SUM(ET$3:ET$4) -> 0 | EV6: =SUM(EV$3:EV$4) -> 0 | EW6: =SUM(EW$3:EW$4) -> 0 | EX6: =SUM(EX$3:EX$4) -> 0 | EY6: =SUM(EY$3:EY$4) -> 0 | EZ6: =SUM(EZ$3:EZ$4) -> 0 | FA6: =SUM(FA$3:FA$4) -> 0 | FC6: =SUM(FC$3:FC$4) -> 0 | FD6: =SUM(FD$3:FD$4) -> 0 | FE6: =SUM(FE$3:FE$4) -> 0 | FF6: =SUM(FF$3:FF$4) -> 0 | FG6: =SUM(FG$3:FG$4) -> 0 | FH6: =SUM(FH$3:FH$4) -> 0 | FJ6: =SUM(FJ$3:FJ$4) -> 0 | FK6: =SUM(FK$3:FK$4) -> 0 | FL6: =SUM(FL$3:FL$4) -> 0 | FM6: =SUM(FM$3:FM$4) -> 0 | FN6: =SUM(FN$3:FN$4) -> 0 | FO6: =SUM(FO$3:FO$4) -> 0 | FQ6: =SUM(FQ$3:FQ$4) -> 0 | FR6: =SUM(FR$3:FR$4) -> 0 | FS6: =SUM(FS$3:FS$4) -> 0 | FT6: =SUM(FT$3:FT$4) -> 0 | FU6: =SUM(FU$3:FU$4) -> 0 | FV6: =SUM(FV$3:FV$4) -> 0 | FX6: =SUM(FX$3:FX$4) -> 0 | FY6: =SUM(FY$3:FY$4) -> 0 | FZ6: =SUM(FZ$3:FZ$4) -> 0 | GA6: =SUM(GA$3:GA$4) -> 0 | GB6: =SUM(GB$3:GB$4) -> 0 | GC6: =SUM(GC$3:GC$4) -> 0 | GE6: =SUM(GE$3:GE$4) -> 0 | GF6: =SUM(GF$3:GF$4) -> 0 | GG6: =SUM(GG$3:GG$4) -> 0 | GH6: =SUM(GH$3:GH$4) -> 0 | GI6: =SUM(GI$3:GI$4) -> 0 | GJ6: =SUM(GJ$3:GJ$4) -> 0 | GL6: =SUM(GL$3:GL$4) -> 0 | GM6: =SUM(GM$3:GM$4) -> 0 | GN6: =SUM(GN$3:GN$4) -> 0 | GO6: =SUM(GO$3:GO$4) -> 0 | GP6: =SUM(GP$3:GP$4) -> 0 | GQ6: =SUM(GQ$3:GQ$4) -> 0 | GS6: =SUM(GS$3:GS$4) -> 0 | GT6: =SUM(GT$3:GT$4) -> 0 | GU6: =SUM(GU$3:GU$4) -> 0 | GV6: =SUM(GV$3:GV$4) -> 0 | GW6: =SUM(GW$3:GW$4) -> 0 | GX6: =SUM(GX$3:GX$4) -> 0 | GZ6: =SUM(GZ$3:GZ$4) -> 0 | HA6: =SUM(HA$3:HA$4) -> 0 | HB6: =SUM(HB$3:HB$4) -> 0 | HC6: =SUM(HC$3:HC$4) -> 0 | HD6: =SUM(HD$3:HD$4) -> 0 | HE6: =SUM(HE$3:HE$4) -> 0 | HG6: =SUM(HG$3:HG$4) -> 0 | HH6: =SUM(HH$3:HH$4) -> 0 | HI6: =SUM(HI$3:HI$4) -> 0 | HJ6: =SUM(HJ$3:HJ$4) -> 0 | HK6: =SUM(HK$3:HK$4) -> 0 | HL6: =SUM(HL$3:HL$4) -> 0 | HN6: =SUM(HN$3:HN$4) -> 0 | HO6: =SUM(HO$3:HO$4) -> 0 | HP6: =SUM(HP$3:HP$4) -> 0 | HQ6: =SUM(HQ$3:HQ$4) -> 0 | HR6: =SUM(HR$3:HR$4) -> 0 | HS6: =SUM(HS$3:HS$4) -> 0 | HU6: =SUM(HU$3:HU$4) -> 0 | HV6: =SUM(HV$3:HV$4) -> 0 | HW6: =SUM(HW$3:HW$4) -> 0 | HX6: =SUM(HX$3:HX$4) -> 0 | HY6: =SUM(HY$3:HY$4) -> 0 | HZ6: =SUM(HZ$3:HZ$4) -> 0 | IA6: =SUM(IA$3:IA$4) -> 0 | IB6: =SUM(IB$3:IB$4) -> 0 | ... IP6: =SUM(IP$3:IP$4) -> 0
A7: AVG | B7: =AVERAGE(B$3:B$4) -> 0 | C7: =AVERAGE(C$3:C$4) -> 0 | E7: =AVERAGE(E$3:E$4) -> 0 | F7: =AVERAGE(F$3:F$4) -> 0 | G7: =AVERAGE(G$3:G$4) -> 0 | H7: =AVERAGE(H$3:H$4) -> 0 | I7: =AVERAGE(I$3:I$4) -> 0 | J7: =AVERAGE(J$3:J$4) -> 0 | L7: =AVERAGE(L$3:L$4) -> 0 | M7: =AVERAGE(M$3:M$4) -> 0 | N7: =AVERAGE(N$3:N$4) -> 0 | O7: =AVERAGE(O$3:O$4) -> 0 | P7: =AVERAGE(P$3:P$4) -> 0 | V7: =AVERAGE(V$3:V$4) -> 0 | W7: =AVERAGE(W$3:W$4) -> 0 | AC7: =AVERAGE(AC$3:AC$4) -> 0 | AD7: =AVERAGE(AD$3:AD$4) -> 0 | AJ7: =AVERAGE(AJ$3:AJ$4) -> 0 | AK7: =AVERAGE(AK$3:AK$4) -> 0 | AQ7: =AVERAGE(AQ$3:AQ$4) -> 0 | AR7: =AVERAGE(AR$3:AR$4) -> 0 | AS7: =AVERAGE(AS$3:AS$4) -> 0 | AU7: =AVERAGE(AU$3:AU$4) -> 0 | AV7: =AVERAGE(AV$3:AV$4) -> 0 | AW7: =AVERAGE(AW$3:AW$4) -> 0 | AX7: =AVERAGE(AX$3:AX$4) -> 0 | AY7: =AVERAGE(AY$3:AY$4) -> 0 | AZ7: =AVERAGE(AZ$3:AZ$4) -> 0 | BB7: =AVERAGE(BB$3:BB$4) -> 0 | BC7: =AVERAGE(BC$3:BC$4) -> 0 | BD7: =AVERAGE(BD$3:BD$4) -> 0 | BE7: =AVERAGE(BE$3:BE$4) -> 0 | BF7: =AVERAGE(BF$3:BF$4) -> 0 | BG7: =AVERAGE(BG$3:BG$4) -> 0 | BI7: =AVERAGE(BI$3:BI$4) -> 0 | BJ7: =AVERAGE(BJ$3:BJ$4) -> 0 | BK7: =AVERAGE(BK$3:BK$4) -> 0 | BL7: =AVERAGE(BL$3:BL$4) -> 0 | BM7: =AVERAGE(BM$3:BM$4) -> 0 | BN7: =AVERAGE(BN$3:BN$4) -> 0 | BP7: =AVERAGE(BP$3:BP$4) -> 0 | BQ7: =AVERAGE(BQ$3:BQ$4) -> 0 | BR7: =AVERAGE(BR$3:BR$4) -> 0 | BS7: =AVERAGE(BS$3:BS$4) -> 0 | BT7: =AVERAGE(BT$3:BT$4) -> 0 | BU7: =AVERAGE(BU$3:BU$4) -> 0 | BW7: =AVERAGE(BW$3:BW$4) -> 0 | BX7: =AVERAGE(BX$3:BX$4) -> 0 | BY7: =AVERAGE(BY$3:BY$4) -> 0 | BZ7: =AVERAGE(BZ$3:BZ$4) -> 0 | CA7: =AVERAGE(CA$3:CA$4) -> 0 | CB7: =AVERAGE(CB$3:CB$4) -> 0 | CD7: =AVERAGE(CD$3:CD$4) -> 0 | CE7: =AVERAGE(CE$3:CE$4) -> 0 | CF7: =AVERAGE(CF$3:CF$4) -> 0 | CG7: =AVERAGE(CG$3:CG$4) -> 0 | CH7: =AVERAGE(CH$3:CH$4) -> 0 | CI7: =AVERAGE(CI$3:CI$4) -> 0 | CK7: =AVERAGE(CK$3:CK$4) -> 0 | CL7: =AVERAGE(CL$3:CL$4) -> 0 | CM7: =AVERAGE(CM$3:CM$4) -> 0 | CN7: =AVERAGE(CN$3:CN$4) -> 0 | CO7: =AVERAGE(CO$3:CO$4) -> 0 | CP7: =AVERAGE(CP$3:CP$4) -> 0 | CR7: =AVERAGE(CR$3:CR$4) -> 0 | CS7: =AVERAGE(CS$3:CS$4) -> 0 | CT7: =AVERAGE(CT$3:CT$4) -> 0 | CU7: =AVERAGE(CU$3:CU$4) -> 0 | CV7: =AVERAGE(CV$3:CV$4) -> 0 | CW7: =AVERAGE(CW$3:CW$4) -> 0 | CY7: =AVERAGE(CY$3:CY$4) -> 0 | CZ7: =AVERAGE(CZ$3:CZ$4) -> 0 | DA7: =AVERAGE(DA$3:DA$4) -> 0 | DB7: =AVERAGE(DB$3:DB$4) -> 0 | DC7: =AVERAGE(DC$3:DC$4) -> 0 | DD7: =AVERAGE(DD$3:DD$4) -> 0 | DF7: =AVERAGE(DF$3:DF$4) -> 0 | DG7: =AVERAGE(DG$3:DG$4) -> 0 | DH7: =AVERAGE(DH$3:DH$4) -> 0 | DI7: =AVERAGE(DI$3:DI$4) -> 0 | DJ7: =AVERAGE(DJ$3:DJ$4) -> 0 | DK7: =AVERAGE(DK$3:DK$4) -> 0 | DM7: =AVERAGE(DM$3:DM$4) -> 0 | DN7: =AVERAGE(DN$3:DN$4) -> 0 | DO7: =AVERAGE(DO$3:DO$4) -> 0 | DP7: =AVERAGE(DP$3:DP$4) -> 0 | DQ7: =AVERAGE(DQ$3:DQ$4) -> 0 | DR7: =AVERAGE(DR$3:DR$4) -> 0 | DT7: =AVERAGE(DT$3:DT$4) -> 0 | DU7: =AVERAGE(DU$3:DU$4) -> 0 | DV7: =AVERAGE(DV$3:DV$4) -> 0 | DW7: =AVERAGE(DW$3:DW$4) -> 0 | DX7: =AVERAGE(DX$3:DX$4) -> 0 | DY7: =AVERAGE(DY$3:DY$4) -> 0 | EA7: =AVERAGE(EA$3:EA$4) -> 0 | EB7: =AVERAGE(EB$3:EB$4) -> 0 | EC7: =AVERAGE(EC$3:EC$4) -> 0 | ED7: =AVERAGE(ED$3:ED$4) -> 0 | EE7: =AVERAGE(EE$3:EE$4) -> 0 | EF7: =AVERAGE(EF$3:EF$4) -> 0 | EH7: =AVERAGE(EH$3:EH$4) -> 0 | EI7: =AVERAGE(EI$3:EI$4) -> 0 | EJ7: =AVERAGE(EJ$3:EJ$4) -> 0 | EK7: =AVERAGE(EK$3:EK$4) -> 0 | EL7: =AVERAGE(EL$3:EL$4) -> 0 | EM7: =AVERAGE(EM$3:EM$4) -> 0 | EO7: =AVERAGE(EO$3:EO$4) -> 0 | EP7: =AVERAGE(EP$3:EP$4) -> 0 | EQ7: =AVERAGE(EQ$3:EQ$4) -> 0 | ER7: =AVERAGE(ER$3:ER$4) -> 0 | ES7: =AVERAGE(ES$3:ES$4) -> 0 | ET7: =AVERAGE(ET$3:ET$4) -> 0 | EV7: =AVERAGE(EV$3:EV$4) -> 0 | EW7: =AVERAGE(EW$3:EW$4) -> 0 | EX7: =AVERAGE(EX$3:EX$4) -> 0 | EY7: =AVERAGE(EY$3:EY$4) -> 0 | EZ7: =AVERAGE(EZ$3:EZ$4) -> 0 | FA7: =AVERAGE(FA$3:FA$4) -> 0 | FC7: =AVERAGE(FC$3:FC$4) -> 0 | FD7: =AVERAGE(FD$3:FD$4) -> 0 | FE7: =AVERAGE(FE$3:FE$4) -> 0 | FF7: =AVERAGE(FF$3:FF$4) -> 0 | FG7: =AVERAGE(FG$3:FG$4) -> 0 | FH7: =AVERAGE(FH$3:FH$4) -> 0 | FJ7: =AVERAGE(FJ$3:FJ$4) -> 0 | FK7: =AVERAGE(FK$3:FK$4) -> 0 | FL7: =AVERAGE(FL$3:FL$4) -> 0 | FM7: =AVERAGE(FM$3:FM$4) -> 0 | FN7: =AVERAGE(FN$3:FN$4) -> 0 | FO7: =AVERAGE(FO$3:FO$4) -> 0 | FQ7: =AVERAGE(FQ$3:FQ$4) -> 0 | FR7: =AVERAGE(FR$3:FR$4) -> 0 | FS7: =AVERAGE(FS$3:FS$4) -> 0 | FT7: =AVERAGE(FT$3:FT$4) -> 0 | FU7: =AVERAGE(FU$3:FU$4) -> 0 | FV7: =AVERAGE(FV$3:FV$4) -> 0 | FX7: =AVERAGE(FX$3:FX$4) -> 0 | FY7: =AVERAGE(FY$3:FY$4) -> 0 | FZ7: =AVERAGE(FZ$3:FZ$4) -> 0 | GA7: =AVERAGE(GA$3:GA$4) -> 0 | GB7: =AVERAGE(GB$3:GB$4) -> 0 | GC7: =AVERAGE(GC$3:GC$4) -> 0 | GE7: =AVERAGE(GE$3:GE$4) -> 0 | GF7: =AVERAGE(GF$3:GF$4) -> 0 | GG7: =AVERAGE(GG$3:GG$4) -> 0 | GH7: =AVERAGE(GH$3:GH$4) -> 0 | GI7: =AVERAGE(GI$3:GI$4) -> 0 | GJ7: =AVERAGE(GJ$3:GJ$4) -> 0 | GL7: =AVERAGE(GL$3:GL$4) -> 0 | GM7: =AVERAGE(GM$3:GM$4) -> 0 | GN7: =AVERAGE(GN$3:GN$4) -> 0 | GO7: =AVERAGE(GO$3:GO$4) -> 0 | GP7: =AVERAGE(GP$3:GP$4) -> 0 | GQ7: =AVERAGE(GQ$3:GQ$4) -> 0 | GS7: =AVERAGE(GS$3:GS$4) -> 0 | GT7: =AVERAGE(GT$3:GT$4) -> 0 | GU7: =AVERAGE(GU$3:GU$4) -> 0 | GV7: =AVERAGE(GV$3:GV$4) -> 0 | GW7: =AVERAGE(GW$3:GW$4) -> 0 | GX7: =AVERAGE(GX$3:GX$4) -> 0 | GZ7: =AVERAGE(GZ$3:GZ$4) -> 0 | HA7: =AVERAGE(HA$3:HA$4) -> 0 | HB7: =AVERAGE(HB$3:HB$4) -> 0 | HC7: =AVERAGE(HC$3:HC$4) -> 0 | HD7: =AVERAGE(HD$3:HD$4) -> 0 | HE7: =AVERAGE(HE$3:HE$4) -> 0 | HG7: =AVERAGE(HG$3:HG$4) -> 0 | HH7: =AVERAGE(HH$3:HH$4) -> 0 | HI7: =AVERAGE(HI$3:HI$4) -> 0 | HJ7: =AVERAGE(HJ$3:HJ$4) -> 0 | HK7: =AVERAGE(HK$3:HK$4) -> 0 | HL7: =AVERAGE(HL$3:HL$4) -> 0 | HN7: =AVERAGE(HN$3:HN$4) -> 0 | HO7: =AVERAGE(HO$3:HO$4) -> 0 | HP7: =AVERAGE(HP$3:HP$4) -> 0 | HQ7: =AVERAGE(HQ$3:HQ$4) -> 0 | HR7: =AVERAGE(HR$3:HR$4) -> 0 | HS7: =AVERAGE(HS$3:HS$4) -> 0 | HU7: =AVERAGE(HU$3:HU$4) -> 0 | HV7: =AVERAGE(HV$3:HV$4) -> 0 | HW7: =AVERAGE(HW$3:HW$4) -> 0 | HX7: =AVERAGE(HX$3:HX$4) -> 0 | HY7: =AVERAGE(HY$3:HY$4) -> 0 | HZ7: =AVERAGE(HZ$3:HZ$4) -> 0 | IA7: =AVERAGE(IA$3:IA$4) -> 0 | IB7: =AVERAGE(IB$3:IB$4) -> 0 | ... IP7: =AVERAGE(IP$3:IP$4) -> 0
A8: DEV | B8: =STDEV(B$3:B$4) -> 0 | C8: =STDEV(C$3:C$4) -> 0 | E8: =STDEV(E$3:E$4) -> 0 | F8: =STDEV(F$3:F$4) -> 0 | G8: =STDEV(G$3:G$4) -> 0 | H8: =STDEV(H$3:H$4) -> 0 | I8: =STDEV(I$3:I$4) -> 0 | J8: =STDEV(J$3:J$4) -> 0 | L8: =STDEV(L$3:L$4) -> 0 | M8: =STDEV(M$3:M$4) -> 0 | N8: =STDEV(N$3:N$4) -> 0 | O8: =STDEV(O$3:O$4) -> 0 | P8: =STDEV(P$3:P$4) -> 0 | V8: =STDEV(V$3:V$4) -> 0 | W8: =STDEV(W$3:W$4) -> 0 | AC8: =STDEV(AC$3:AC$4) -> 0 | AD8: =STDEV(AD$3:AD$4) -> 0 | AJ8: =STDEV(AJ$3:AJ$4) -> 0 | AK8: =STDEV(AK$3:AK$4) -> 0 | AQ8: =STDEV(AQ$3:AQ$4) -> 0 | AR8: =STDEV(AR$3:AR$4) -> 0 | AS8: =STDEV(AS$3:AS$4) -> 0 | AU8: =STDEV(AU$3:AU$4) -> 0 | AV8: =STDEV(AV$3:AV$4) -> 0 | AW8: =STDEV(AW$3:AW$4) -> 0 | AX8: =STDEV(AX$3:AX$4) -> 0 | AY8: =STDEV(AY$3:AY$4) -> 0 | AZ8: =STDEV(AZ$3:AZ$4) -> 0 | BB8: =STDEV(BB$3:BB$4) -> 0 | BC8: =STDEV(BC$3:BC$4) -> 0 | BD8: =STDEV(BD$3:BD$4) -> 0 | BE8: =STDEV(BE$3:BE$4) -> 0 | BF8: =STDEV(BF$3:BF$4) -> 0 | BG8: =STDEV(BG$3:BG$4) -> 0 | BI8: =STDEV(BI$3:BI$4) -> 0 | BJ8: =STDEV(BJ$3:BJ$4) -> 0 | BK8: =STDEV(BK$3:BK$4) -> 0 | BL8: =STDEV(BL$3:BL$4) -> 0 | BM8: =STDEV(BM$3:BM$4) -> 0 | BN8: =STDEV(BN$3:BN$4) -> 0 | BP8: =STDEV(BP$3:BP$4) -> 0 | BQ8: =STDEV(BQ$3:BQ$4) -> 0 | BR8: =STDEV(BR$3:BR$4) -> 0 | BS8: =STDEV(BS$3:BS$4) -> 0 | BT8: =STDEV(BT$3:BT$4) -> 0 | BU8: =STDEV(BU$3:BU$4) -> 0 | BW8: =STDEV(BW$3:BW$4) -> 0 | BX8: =STDEV(BX$3:BX$4) -> 0 | BY8: =STDEV(BY$3:BY$4) -> 0 | BZ8: =STDEV(BZ$3:BZ$4) -> 0 | CA8: =STDEV(CA$3:CA$4) -> 0 | CB8: =STDEV(CB$3:CB$4) -> 0 | CD8: =STDEV(CD$3:CD$4) -> 0 | CE8: =STDEV(CE$3:CE$4) -> 0 | CF8: =STDEV(CF$3:CF$4) -> 0 | CG8: =STDEV(CG$3:CG$4) -> 0 | CH8: =STDEV(CH$3:CH$4) -> 0 | CI8: =STDEV(CI$3:CI$4) -> 0 | CK8: =STDEV(CK$3:CK$4) -> 0 | CL8: =STDEV(CL$3:CL$4) -> 0 | CM8: =STDEV(CM$3:CM$4) -> 0 | CN8: =STDEV(CN$3:CN$4) -> 0 | CO8: =STDEV(CO$3:CO$4) -> 0 | CP8: =STDEV(CP$3:CP$4) -> 0 | CR8: =STDEV(CR$3:CR$4) -> 0 | CS8: =STDEV(CS$3:CS$4) -> 0 | CT8: =STDEV(CT$3:CT$4) -> 0 | CU8: =STDEV(CU$3:CU$4) -> 0 | CV8: =STDEV(CV$3:CV$4) -> 0 | CW8: =STDEV(CW$3:CW$4) -> 0 | CY8: =STDEV(CY$3:CY$4) -> 0 | CZ8: =STDEV(CZ$3:CZ$4) -> 0 | DA8: =STDEV(DA$3:DA$4) -> 0 | DB8: =STDEV(DB$3:DB$4) -> 0 | DC8: =STDEV(DC$3:DC$4) -> 0 | DD8: =STDEV(DD$3:DD$4) -> 0 | DF8: =STDEV(DF$3:DF$4) -> 0 | DG8: =STDEV(DG$3:DG$4) -> 0 | DH8: =STDEV(DH$3:DH$4) -> 0 | DI8: =STDEV(DI$3:DI$4) -> 0 | DJ8: =STDEV(DJ$3:DJ$4) -> 0 | DK8: =STDEV(DK$3:DK$4) -> 0 | DM8: =STDEV(DM$3:DM$4) -> 0 | DN8: =STDEV(DN$3:DN$4) -> 0 | DO8: =STDEV(DO$3:DO$4) -> 0 | DP8: =STDEV(DP$3:DP$4) -> 0 | DQ8: =STDEV(DQ$3:DQ$4) -> 0 | DR8: =STDEV(DR$3:DR$4) -> 0 | DT8: =STDEV(DT$3:DT$4) -> 0 | DU8: =STDEV(DU$3:DU$4) -> 0 | DV8: =STDEV(DV$3:DV$4) -> 0 | DW8: =STDEV(DW$3:DW$4) -> 0 | DX8: =STDEV(DX$3:DX$4) -> 0 | DY8: =STDEV(DY$3:DY$4) -> 0 | EA8: =STDEV(EA$3:EA$4) -> 0 | EB8: =STDEV(EB$3:EB$4) -> 0 | EC8: =STDEV(EC$3:EC$4) -> 0 | ED8: =STDEV(ED$3:ED$4) -> 0 | EE8: =STDEV(EE$3:EE$4) -> 0 | EF8: =STDEV(EF$3:EF$4) -> 0 | EH8: =STDEV(EH$3:EH$4) -> 0 | EI8: =STDEV(EI$3:EI$4) -> 0 | EJ8: =STDEV(EJ$3:EJ$4) -> 0 | EK8: =STDEV(EK$3:EK$4) -> 0 | EL8: =STDEV(EL$3:EL$4) -> 0 | EM8: =STDEV(EM$3:EM$4) -> 0 | EO8: =STDEV(EO$3:EO$4) -> 0 | EP8: =STDEV(EP$3:EP$4) -> 0 | EQ8: =STDEV(EQ$3:EQ$4) -> 0 | ER8: =STDEV(ER$3:ER$4) -> 0 | ES8: =STDEV(ES$3:ES$4) -> 0 | ET8: =STDEV(ET$3:ET$4) -> 0 | EV8: =STDEV(EV$3:EV$4) -> 0 | EW8: =STDEV(EW$3:EW$4) -> 0 | EX8: =STDEV(EX$3:EX$4) -> 0 | EY8: =STDEV(EY$3:EY$4) -> 0 | EZ8: =STDEV(EZ$3:EZ$4) -> 0 | FA8: =STDEV(FA$3:FA$4) -> 0 | FC8: =STDEV(FC$3:FC$4) -> 0 | FD8: =STDEV(FD$3:FD$4) -> 0 | FE8: =STDEV(FE$3:FE$4) -> 0 | FF8: =STDEV(FF$3:FF$4) -> 0 | FG8: =STDEV(FG$3:FG$4) -> 0 | FH8: =STDEV(FH$3:FH$4) -> 0 | FJ8: =STDEV(FJ$3:FJ$4) -> 0 | FK8: =STDEV(FK$3:FK$4) -> 0 | FL8: =STDEV(FL$3:FL$4) -> 0 | FM8: =STDEV(FM$3:FM$4) -> 0 | FN8: =STDEV(FN$3:FN$4) -> 0 | FO8: =STDEV(FO$3:FO$4) -> 0 | FQ8: =STDEV(FQ$3:FQ$4) -> 0 | FR8: =STDEV(FR$3:FR$4) -> 0 | FS8: =STDEV(FS$3:FS$4) -> 0 | FT8: =STDEV(FT$3:FT$4) -> 0 | FU8: =STDEV(FU$3:FU$4) -> 0 | FV8: =STDEV(FV$3:FV$4) -> 0 | FX8: =STDEV(FX$3:FX$4) -> 0 | FY8: =STDEV(FY$3:FY$4) -> 0 | FZ8: =STDEV(FZ$3:FZ$4) -> 0 | GA8: =STDEV(GA$3:GA$4) -> 0 | GB8: =STDEV(GB$3:GB$4) -> 0 | GC8: =STDEV(GC$3:GC$4) -> 0 | GE8: =STDEV(GE$3:GE$4) -> 0 | GF8: =STDEV(GF$3:GF$4) -> 0 | GG8: =STDEV(GG$3:GG$4) -> 0 | GH8: =STDEV(GH$3:GH$4) -> 0 | GI8: =STDEV(GI$3:GI$4) -> 0 | GJ8: =STDEV(GJ$3:GJ$4) -> 0 | GL8: =STDEV(GL$3:GL$4) -> 0 | GM8: =STDEV(GM$3:GM$4) -> 0 | GN8: =STDEV(GN$3:GN$4) -> 0 | GO8: =STDEV(GO$3:GO$4) -> 0 | GP8: =STDEV(GP$3:GP$4) -> 0 | GQ8: =STDEV(GQ$3:GQ$4) -> 0 | GS8: =STDEV(GS$3:GS$4) -> 0 | GT8: =STDEV(GT$3:GT$4) -> 0 | GU8: =STDEV(GU$3:GU$4) -> 0 | GV8: =STDEV(GV$3:GV$4) -> 0 | GW8: =STDEV(GW$3:GW$4) -> 0 | GX8: =STDEV(GX$3:GX$4) -> 0 | GZ8: =STDEV(GZ$3:GZ$4) -> 0 | HA8: =STDEV(HA$3:HA$4) -> 0 | HB8: =STDEV(HB$3:HB$4) -> 0 | HC8: =STDEV(HC$3:HC$4) -> 0 | HD8: =STDEV(HD$3:HD$4) -> 0 | HE8: =STDEV(HE$3:HE$4) -> 0 | HG8: =STDEV(HG$3:HG$4) -> 0 | HH8: =STDEV(HH$3:HH$4) -> 0 | HI8: =STDEV(HI$3:HI$4) -> 0 | HJ8: =STDEV(HJ$3:HJ$4) -> 0 | HK8: =STDEV(HK$3:HK$4) -> 0 | HL8: =STDEV(HL$3:HL$4) -> 0 | HN8: =STDEV(HN$3:HN$4) -> 0 | HO8: =STDEV(HO$3:HO$4) -> 0 | HP8: =STDEV(HP$3:HP$4) -> 0 | HQ8: =STDEV(HQ$3:HQ$4) -> 0 | HR8: =STDEV(HR$3:HR$4) -> 0 | HS8: =STDEV(HS$3:HS$4) -> 0 | HU8: =STDEV(HU$3:HU$4) -> 0 | HV8: =STDEV(HV$3:HV$4) -> 0 | HW8: =STDEV(HW$3:HW$4) -> 0 | HX8: =STDEV(HX$3:HX$4) -> 0 | HY8: =STDEV(HY$3:HY$4) -> 0 | HZ8: =STDEV(HZ$3:HZ$4) -> 0 | IA8: =STDEV(IA$3:IA$4) -> 0 | IB8: =STDEV(IB$3:IB$4) -> 0 | ... IP8: =STDEV(IP$3:IP$4) -> 0
A9: DST | B9: =SUMPRODUCT(--(B$3:B$4-$HY$3:$HY$4)^2)^0.5 -> 0 | C9: =SUMPRODUCT(--(C$3:C$4-$HZ$3:$HZ$4)^2)^0.5 -> 0 | E9: =SUMPRODUCT(--(E$3:E$4-$IA$3:$IA$4)^2)^0.5 -> 0 | F9: =SUMPRODUCT(--(F$3:F$4-$IB$3:$IB$4)^2)^0.5 -> 0 | G9: =SUMPRODUCT(--(G$3:G$4-$IC$3:$IC$4)^2)^0.5 -> 0 | H9: =SUMPRODUCT(--(H$3:H$4-$ID$3:$ID$4)^2)^0.5 -> 0 | I9: =SUMPRODUCT(--(I$3:I$4-$HY$3:$HY$4)^2)^0.5 -> 0 | J9: =SUMPRODUCT(--(J$3:J$4-$HZ$3:$HZ$4)^2)^0.5 -> 0 | L9: =SUMPRODUCT(--(L$3:L$4-$IA$3:$IA$4)^2)^0.5 -> 0 | M9: =SUMPRODUCT(--(M$3:M$4-$IB$3:$IB$4)^2)^0.5 -> 0 | N9: =SUMPRODUCT(--(N$3:N$4-$IC$3:$IC$4)^2)^0.5 -> 0 | O9: =SUMPRODUCT(--(O$3:O$4-$ID$3:$ID$4)^2)^0.5 -> 0 | P9: =SUMPRODUCT(--(P$3:P$4-$HY$3:$HY$4)^2)^0.5 -> 0 | V9: =SUMPRODUCT(--(V$3:V$4-$ID$3:$ID$4)^2)^0.5 -> 0 | W9: =SUMPRODUCT(--(W$3:W$4-$HY$3:$HY$4)^2)^0.5 -> 0 | AC9: =SUMPRODUCT(--(AC$3:AC$4-$ID$3:$ID$4)^2)^0.5 -> 0 | AD9: =SUMPRODUCT(--(AD$3:AD$4-$HY$3:$HY$4)^2)^0.5 -> 0 | AJ9: =SUMPRODUCT(--(AJ$3:AJ$4-$ID$3:$ID$4)^2)^0.5 -> 0 | AK9: =SUMPRODUCT(--(AK$3:AK$4-$HY$3:$HY$4)^2)^0.5 -> 0 | AQ9: =SUMPRODUCT(--(AQ$3:AQ$4-$ID$3:$ID$4)^2)^0.5 -> 0 | AR9: =SUMPRODUCT(--(AR$3:AR$4-$HY$3:$HY$4)^2)^0.5 -> 0 | AS9: =SUMPRODUCT(--(AS$3:AS$4-$HZ$3:$HZ$4)^2)^0.5 -> 0 | AU9: =SUMPRODUCT(--(AU$3:AU$4-$IA$3:$IA$4)^2)^0.5 -> 0 | AV9: =SUMPRODUCT(--(AV$3:AV$4-$IB$3:$IB$4)^2)^0.5 -> 0 | AW9: =SUMPRODUCT(--(AW$3:AW$4-$IC$3:$IC$4)^2)^0.5 -> 0 | AX9: =SUMPRODUCT(--(AX$3:AX$4-$ID$3:$ID$4)^2)^0.5 -> 0 | AY9: =SUMPRODUCT(--(AY$3:AY$4-$HY$3:$HY$4)^2)^0.5 -> 0 | AZ9: =SUMPRODUCT(--(AZ$3:AZ$4-$HZ$3:$HZ$4)^2)^0.5 -> 0 | BB9: =SUMPRODUCT(--(BB$3:BB$4-$IA$3:$IA$4)^2)^0.5 -> 0 | BC9: =SUMPRODUCT(--(BC$3:BC$4-$IB$3:$IB$4)^2)^0.5 -> 0 | BD9: =SUMPRODUCT(--(BD$3:BD$4-$IC$3:$IC$4)^2)^0.5 -> 0 | BE9: =SUMPRODUCT(--(BE$3:BE$4-$ID$3:$ID$4)^2)^0.5 -> 0 | BF9: =SUMPRODUCT(--(BF$3:BF$4-$HY$3:$HY$4)^2)^0.5 -> 0 | BG9: =SUMPRODUCT(--(BG$3:BG$4-$HZ$3:$HZ$4)^2)^0.5 -> 0 | BI9: =SUMPRODUCT(--(BI$3:BI$4-$IA$3:$IA$4)^2)^0.5 -> 0 | BJ9: =SUMPRODUCT(--(BJ$3:BJ$4-$IB$3:$IB$4)^2)^0.5 -> 0 | BK9: =SUMPRODUCT(--(BK$3:BK$4-$IC$3:$IC$4)^2)^0.5 -> 0 | BL9: =SUMPRODUCT(--(BL$3:BL$4-$ID$3:$ID$4)^2)^0.5 -> 0 | BM9: =SUMPRODUCT(--(BM$3:BM$4-$HY$3:$HY$4)^2)^0.5 -> 0 | BN9: =SUMPRODUCT(--(BN$3:BN$4-$HZ$3:$HZ$4)^2)^0.5 -> 0 | BP9: =SUMPRODUCT(--(BP$3:BP$4-$IA$3:$IA$4)^2)^0.5 -> 0 | BQ9: =SUMPRODUCT(--(BQ$3:BQ$4-$IB$3:$IB$4)^2)^0.5 -> 0 | BR9: =SUMPRODUCT(--(BR$3:BR$4-$IC$3:$IC$4)^2)^0.5 -> 0 | BS9: =SUMPRODUCT(--(BS$3:BS$4-$ID$3:$ID$4)^2)^0.5 -> 0 | BT9: =SUMPRODUCT(--(BT$3:BT$4-$HY$3:$HY$4)^2)^0.5 -> 0 | BU9: =SUMPRODUCT(--(BU$3:BU$4-$HZ$3:$HZ$4)^2)^0.5 -> 0 | BW9: =SUMPRODUCT(--(BW$3:BW$4-$IA$3:$IA$4)^2)^0.5 -> 0 | BX9: =SUMPRODUCT(--(BX$3:BX$4-$IB$3:$IB$4)^2)^0.5 -> 0 | BY9: =SUMPRODUCT(--(BY$3:BY$4-$IC$3:$IC$4)^2)^0.5 -> 0 | BZ9: =SUMPRODUCT(--(BZ$3:BZ$4-$ID$3:$ID$4)^2)^0.5 -> 0 | CA9: =SUMPRODUCT(--(CA$3:CA$4-$HY$3:$HY$4)^2)^0.5 -> 0 | CB9: =SUMPRODUCT(--(CB$3:CB$4-$HZ$3:$HZ$4)^2)^0.5 -> 0 | CD9: =SUMPRODUCT(--(CD$3:CD$4-$IA$3:$IA$4)^2)^0.5 -> 0 | CE9: =SUMPRODUCT(--(CE$3:CE$4-$IB$3:$IB$4)^2)^0.5 -> 0 | CF9: =SUMPRODUCT(--(CF$3:CF$4-$IC$3:$IC$4)^2)^0.5 -> 0 | CG9: =SUMPRODUCT(--(CG$3:CG$4-$ID$3:$ID$4)^2)^0.5 -> 0 | CH9: =SUMPRODUCT(--(CH$3:CH$4-$HY$3:$HY$4)^2)^0.5 -> 0 | CI9: =SUMPRODUCT(--(CI$3:CI$4-$HZ$3:$HZ$4)^2)^0.5 -> 0 | CK9: =SUMPRODUCT(--(CK$3:CK$4-$IA$3:$IA$4)^2)^0.5 -> 0 | CL9: =SUMPRODUCT(--(CL$3:CL$4-$IB$3:$IB$4)^2)^0.5 -> 0 | CM9: =SUMPRODUCT(--(CM$3:CM$4-$IC$3:$IC$4)^2)^0.5 -> 0 | CN9: =SUMPRODUCT(--(CN$3:CN$4-$ID$3:$ID$4)^2)^0.5 -> 0 | CO9: =SUMPRODUCT(--(CO$3:CO$4-$HY$3:$HY$4)^2)^0.5 -> 0 | CP9: =SUMPRODUCT(--(CP$3:CP$4-$HZ$3:$HZ$4)^2)^0.5 -> 0 | CR9: =SUMPRODUCT(--(CR$3:CR$4-$IA$3:$IA$4)^2)^0.5 -> 0 | CS9: =SUMPRODUCT(--(CS$3:CS$4-$IB$3:$IB$4)^2)^0.5 -> 0 | CT9: =SUMPRODUCT(--(CT$3:CT$4-$IC$3:$IC$4)^2)^0.5 -> 0 | CU9: =SUMPRODUCT(--(CU$3:CU$4-$ID$3:$ID$4)^2)^0.5 -> 0 | CV9: =SUMPRODUCT(--(CV$3:CV$4-$HY$3:$HY$4)^2)^0.5 -> 0 | CW9: =SUMPRODUCT(--(CW$3:CW$4-$HZ$3:$HZ$4)^2)^0.5 -> 0 | CY9: =SUMPRODUCT(--(CY$3:CY$4-$IA$3:$IA$4)^2)^0.5 -> 0 | CZ9: =SUMPRODUCT(--(CZ$3:CZ$4-$IB$3:$IB$4)^2)^0.5 -> 0 | DA9: =SUMPRODUCT(--(DA$3:DA$4-$IC$3:$IC$4)^2)^0.5 -> 0 | DB9: =SUMPRODUCT(--(DB$3:DB$4-$ID$3:$ID$4)^2)^0.5 -> 0 | DC9: =SUMPRODUCT(--(DC$3:DC$4-$HY$3:$HY$4)^2)^0.5 -> 0 | DD9: =SUMPRODUCT(--(DD$3:DD$4-$HZ$3:$HZ$4)^2)^0.5 -> 0 | DF9: =SUMPRODUCT(--(DF$3:DF$4-$IA$3:$IA$4)^2)^0.5 -> 0 | DG9: =SUMPRODUCT(--(DG$3:DG$4-$IB$3:$IB$4)^2)^0.5 -> 0 | DH9: =SUMPRODUCT(--(DH$3:DH$4-$IC$3:$IC$4)^2)^0.5 -> 0 | DI9: =SUMPRODUCT(--(DI$3:DI$4-$ID$3:$ID$4)^2)^0.5 -> 0 | DJ9: =SUMPRODUCT(--(DJ$3:DJ$4-$HY$3:$HY$4)^2)^0.5 -> 0 | DK9: =SUMPRODUCT(--(DK$3:DK$4-$HZ$3:$HZ$4)^2)^0.5 -> 0 | DM9: =SUMPRODUCT(--(DM$3:DM$4-$IA$3:$IA$4)^2)^0.5 -> 0 | DN9: =SUMPRODUCT(--(DN$3:DN$4-$IB$3:$IB$4)^2)^0.5 -> 0 | DO9: =SUMPRODUCT(--(DO$3:DO$4-$IC$3:$IC$4)^2)^0.5 -> 0 | DP9: =SUMPRODUCT(--(DP$3:DP$4-$ID$3:$ID$4)^2)^0.5 -> 0 | DQ9: =SUMPRODUCT(--(DQ$3:DQ$4-$HY$3:$HY$4)^2)^0.5 -> 0 | DR9: =SUMPRODUCT(--(DR$3:DR$4-$HZ$3:$HZ$4)^2)^0.5 -> 0 | DT9: =SUMPRODUCT(--(DT$3:DT$4-$IA$3:$IA$4)^2)^0.5 -> 0 | DU9: =SUMPRODUCT(--(DU$3:DU$4-$IB$3:$IB$4)^2)^0.5 -> 0 | DV9: =SUMPRODUCT(--(DV$3:DV$4-$IC$3:$IC$4)^2)^0.5 -> 0 | DW9: =SUMPRODUCT(--(DW$3:DW$4-$ID$3:$ID$4)^2)^0.5 -> 0 | DX9: =SUMPRODUCT(--(DX$3:DX$4-$HY$3:$HY$4)^2)^0.5 -> 0 | DY9: =SUMPRODUCT(--(DY$3:DY$4-$HZ$3:$HZ$4)^2)^0.5 -> 0 | EA9: =SUMPRODUCT(--(EA$3:EA$4-$IA$3:$IA$4)^2)^0.5 -> 0 | EB9: =SUMPRODUCT(--(EB$3:EB$4-$IB$3:$IB$4)^2)^0.5 -> 0 | EC9: =SUMPRODUCT(--(EC$3:EC$4-$IC$3:$IC$4)^2)^0.5 -> 0 | ED9: =SUMPRODUCT(--(ED$3:ED$4-$ID$3:$ID$4)^2)^0.5 -> 0 | EE9: =SUMPRODUCT(--(EE$3:EE$4-$HY$3:$HY$4)^2)^0.5 -> 0 | EF9: =SUMPRODUCT(--(EF$3:EF$4-$HZ$3:$HZ$4)^2)^0.5 -> 0 | EH9: =SUMPRODUCT(--(EH$3:EH$4-$IA$3:$IA$4)^2)^0.5 -> 0 | EI9: =SUMPRODUCT(--(EI$3:EI$4-$IB$3:$IB$4)^2)^0.5 -> 0 | EJ9: =SUMPRODUCT(--(EJ$3:EJ$4-$IC$3:$IC$4)^2)^0.5 -> 0 | EK9: =SUMPRODUCT(--(EK$3:EK$4-$ID$3:$ID$4)^2)^0.5 -> 0 | EL9: =SUMPRODUCT(--(EL$3:EL$4-$HY$3:$HY$4)^2)^0.5 -> 0 | EM9: =SUMPRODUCT(--(EM$3:EM$4-$HZ$3:$HZ$4)^2)^0.5 -> 0 | EO9: =SUMPRODUCT(--(EO$3:EO$4-$IA$3:$IA$4)^2)^0.5 -> 0 | EP9: =SUMPRODUCT(--(EP$3:EP$4-$IB$3:$IB$4)^2)^0.5 -> 0 | EQ9: =SUMPRODUCT(--(EQ$3:EQ$4-$IC$3:$IC$4)^2)^0.5 -> 0 | ER9: =SUMPRODUCT(--(ER$3:ER$4-$ID$3:$ID$4)^2)^0.5 -> 0 | ES9: =SUMPRODUCT(--(ES$3:ES$4-$HY$3:$HY$4)^2)^0.5 -> 0 | ET9: =SUMPRODUCT(--(ET$3:ET$4-$HZ$3:$HZ$4)^2)^0.5 -> 0 | EV9: =SUMPRODUCT(--(EV$3:EV$4-$IA$3:$IA$4)^2)^0.5 -> 0 | EW9: =SUMPRODUCT(--(EW$3:EW$4-$IB$3:$IB$4)^2)^0.5 -> 0 | EX9: =SUMPRODUCT(--(EX$3:EX$4-$IC$3:$IC$4)^2)^0.5 -> 0 | EY9: =SUMPRODUCT(--(EY$3:EY$4-$ID$3:$ID$4)^2)^0.5 -> 0 | EZ9: =SUMPRODUCT(--(EZ$3:EZ$4-$HY$3:$HY$4)^2)^0.5 -> 0 | FA9: =SUMPRODUCT(--(FA$3:FA$4-$HZ$3:$HZ$4)^2)^0.5 -> 0 | FC9: =SUMPRODUCT(--(FC$3:FC$4-$IA$3:$IA$4)^2)^0.5 -> 0 | FD9: =SUMPRODUCT(--(FD$3:FD$4-$IB$3:$IB$4)^2)^0.5 -> 0 | FE9: =SUMPRODUCT(--(FE$3:FE$4-$IC$3:$IC$4)^2)^0.5 -> 0 | FF9: =SUMPRODUCT(--(FF$3:FF$4-$ID$3:$ID$4)^2)^0.5 -> 0 | FG9: =SUMPRODUCT(--(FG$3:FG$4-$HY$3:$HY$4)^2)^0.5 -> 0 | FH9: =SUMPRODUCT(--(FH$3:FH$4-$HZ$3:$HZ$4)^2)^0.5 -> 0 | FJ9: =SUMPRODUCT(--(FJ$3:FJ$4-$IA$3:$IA$4)^2)^0.5 -> 0 | FK9: =SUMPRODUCT(--(FK$3:FK$4-$IB$3:$IB$4)^2)^0.5 -> 0 | FL9: =SUMPRODUCT(--(FL$3:FL$4-$IC$3:$IC$4)^2)^0.5 -> 0 | FM9: =SUMPRODUCT(--(FM$3:FM$4-$ID$3:$ID$4)^2)^0.5 -> 0 | FN9: =SUMPRODUCT(--(FN$3:FN$4-$HY$3:$HY$4)^2)^0.5 -> 0 | FO9: =SUMPRODUCT(--(FO$3:FO$4-$HZ$3:$HZ$4)^2)^0.5 -> 0 | FQ9: =SUMPRODUCT(--(FQ$3:FQ$4-$IA$3:$IA$4)^2)^0.5 -> 0 | FR9: =SUMPRODUCT(--(FR$3:FR$4-$IB$3:$IB$4)^2)^0.5 -> 0 | FS9: =SUMPRODUCT(--(FS$3:FS$4-$IC$3:$IC$4)^2)^0.5 -> 0 | FT9: =SUMPRODUCT(--(FT$3:FT$4-$ID$3:$ID$4)^2)^0.5 -> 0 | FU9: =SUMPRODUCT(--(FU$3:FU$4-$HY$3:$HY$4)^2)^0.5 -> 0 | FV9: =SUMPRODUCT(--(FV$3:FV$4-$HZ$3:$HZ$4)^2)^0.5 -> 0 | FX9: =SUMPRODUCT(--(FX$3:FX$4-$IA$3:$IA$4)^2)^0.5 -> 0 | FY9: =SUMPRODUCT(--(FY$3:FY$4-$IB$3:$IB$4)^2)^0.5 -> 0 | FZ9: =SUMPRODUCT(--(FZ$3:FZ$4-$IC$3:$IC$4)^2)^0.5 -> 0 | GA9: =SUMPRODUCT(--(GA$3:GA$4-$ID$3:$ID$4)^2)^0.5 -> 0 | GB9: =SUMPRODUCT(--(GB$3:GB$4-$HY$3:$HY$4)^2)^0.5 -> 0 | GC9: =SUMPRODUCT(--(GC$3:GC$4-$HZ$3:$HZ$4)^2)^0.5 -> 0 | GE9: =SUMPRODUCT(--(GE$3:GE$4-$IA$3:$IA$4)^2)^0.5 -> 0 | GF9: =SUMPRODUCT(--(GF$3:GF$4-$IB$3:$IB$4)^2)^0.5 -> 0 | GG9: =SUMPRODUCT(--(GG$3:GG$4-$IC$3:$IC$4)^2)^0.5 -> 0 | GH9: =SUMPRODUCT(--(GH$3:GH$4-$ID$3:$ID$4)^2)^0.5 -> 0 | GI9: =SUMPRODUCT(--(GI$3:GI$4-$HY$3:$HY$4)^2)^0.5 -> 0 | GJ9: =SUMPRODUCT(--(GJ$3:GJ$4-$HZ$3:$HZ$4)^2)^0.5 -> 0 | GL9: =SUMPRODUCT(--(GL$3:GL$4-$IA$3:$IA$4)^2)^0.5 -> 0 | GM9: =SUMPRODUCT(--(GM$3:GM$4-$IB$3:$IB$4)^2)^0.5 -> 0 | GN9: =SUMPRODUCT(--(GN$3:GN$4-$IC$3:$IC$4)^2)^0.5 -> 0 | GO9: =SUMPRODUCT(--(GO$3:GO$4-$ID$3:$ID$4)^2)^0.5 -> 0 | GP9: =SUMPRODUCT(--(GP$3:GP$4-$HY$3:$HY$4)^2)^0.5 -> 0 | GQ9: =SUMPRODUCT(--(GQ$3:GQ$4-$HZ$3:$HZ$4)^2)^0.5 -> 0 | GS9: =SUMPRODUCT(--(GS$3:GS$4-$IA$3:$IA$4)^2)^0.5 -> 0 | GT9: =SUMPRODUCT(--(GT$3:GT$4-$IB$3:$IB$4)^2)^0.5 -> 0 | GU9: =SUMPRODUCT(--(GU$3:GU$4-$IC$3:$IC$4)^2)^0.5 -> 0 | GV9: =SUMPRODUCT(--(GV$3:GV$4-$ID$3:$ID$4)^2)^0.5 -> 0 | GW9: =SUMPRODUCT(--(GW$3:GW$4-$HY$3:$HY$4)^2)^0.5 -> 0 | GX9: =SUMPRODUCT(--(GX$3:GX$4-$HZ$3:$HZ$4)^2)^0.5 -> 0 | GZ9: =SUMPRODUCT(--(GZ$3:GZ$4-$IA$3:$IA$4)^2)^0.5 -> 0 | HA9: =SUMPRODUCT(--(HA$3:HA$4-$IB$3:$IB$4)^2)^0.5 -> 0 | HB9: =SUMPRODUCT(--(HB$3:HB$4-$IC$3:$IC$4)^2)^0.5 -> 0 | HC9: =SUMPRODUCT(--(HC$3:HC$4-$ID$3:$ID$4)^2)^0.5 -> 0 | HD9: =SUMPRODUCT(--(HD$3:HD$4-$HY$3:$HY$4)^2)^0.5 -> 0 | HE9: =SUMPRODUCT(--(HE$3:HE$4-$HZ$3:$HZ$4)^2)^0.5 -> 0 | HG9: =SUMPRODUCT(--(HG$3:HG$4-$IA$3:$IA$4)^2)^0.5 -> 0 | HH9: =SUMPRODUCT(--(HH$3:HH$4-$IB$3:$IB$4)^2)^0.5 -> 0 | HI9: =SUMPRODUCT(--(HI$3:HI$4-$IC$3:$IC$4)^2)^0.5 -> 0 | HJ9: =SUMPRODUCT(--(HJ$3:HJ$4-$ID$3:$ID$4)^2)^0.5 -> 0 | HK9: =SUMPRODUCT(--(HK$3:HK$4-$HY$3:$HY$4)^2)^0.5 -> 0 | HL9: =SUMPRODUCT(--(HL$3:HL$4-$HZ$3:$HZ$4)^2)^0.5 -> 0 | HN9: =SUMPRODUCT(--(HN$3:HN$4-$IA$3:$IA$4)^2)^0.5 -> 0 | HO9: =SUMPRODUCT(--(HO$3:HO$4-$IB$3:$IB$4)^2)^0.5 -> 0 | HP9: =SUMPRODUCT(--(HP$3:HP$4-$IC$3:$IC$4)^2)^0.5 -> 0 | HQ9: =SUMPRODUCT(--(HQ$3:HQ$4-$ID$3:$ID$4)^2)^0.5 -> 0 | HR9: =SUMPRODUCT(--(HR$3:HR$4-$HY$3:$HY$4)^2)^0.5 -> 0 | HS9: =SUMPRODUCT(--(HS$3:HS$4-$HZ$3:$HZ$4)^2)^0.5 -> 0 | HU9: =SUMPRODUCT(--(HU$3:HU$4-$IA$3:$IA$4)^2)^0.5 -> 0 | HV9: =SUMPRODUCT(--(HV$3:HV$4-$IB$3:$IB$4)^2)^0.5 -> 0 | HW9: =SUMPRODUCT(--(HW$3:HW$4-$IC$3:$IC$4)^2)^0.5 -> 0 | HX9: =SUMPRODUCT(--(HX$3:HX$4-$ID$3:$ID$4)^2)^0.5 -> 0
A10: BEST | B10: =SUMPRODUCT(NOT(ISBLANK(B$3:B$4))*(B$3:B$4=$HY$3:$HY$4)) -> 0 | C10: =SUMPRODUCT(NOT(ISBLANK(C$3:C$4))*(C$3:C$4=$HZ$3:$HZ$4)) -> 0 | E10: =SUMPRODUCT(NOT(ISBLANK(E$3:E$4))*(E$3:E$4=$IA$3:$IA$4)) -> 0 | F10: =SUMPRODUCT(NOT(ISBLANK(F$3:F$4))*(F$3:F$4=$IB$3:$IB$4)) -> 0 | G10: =SUMPRODUCT(NOT(ISBLANK(G$3:G$4))*(G$3:G$4=$IC$3:$IC$4)) -> 0 | H10: =SUMPRODUCT(NOT(ISBLANK(H$3:H$4))*(H$3:H$4=$ID$3:$ID$4)) -> 0 | I10: =SUMPRODUCT(NOT(ISBLANK(I$3:I$4))*(I$3:I$4=$HY$3:$HY$4)) -> 0 | J10: =SUMPRODUCT(NOT(ISBLANK(J$3:J$4))*(J$3:J$4=$HZ$3:$HZ$4)) -> 0 | L10: =SUMPRODUCT(NOT(ISBLANK(L$3:L$4))*(L$3:L$4=$IA$3:$IA$4)) -> 0 | M10: =SUMPRODUCT(NOT(ISBLANK(M$3:M$4))*(M$3:M$4=$IB$3:$IB$4)) -> 0 | N10: =SUMPRODUCT(NOT(ISBLANK(N$3:N$4))*(N$3:N$4=$IC$3:$IC$4)) -> 0 | O10: =SUMPRODUCT(NOT(ISBLANK(O$3:O$4))*(O$3:O$4=$ID$3:$ID$4)) -> 0 | P10: =SUMPRODUCT(NOT(ISBLANK(P$3:P$4))*(P$3:P$4=$HY$3:$HY$4)) -> 0 | V10: =SUMPRODUCT(NOT(ISBLANK(V$3:V$4))*(V$3:V$4=$ID$3:$ID$4)) -> 0 | W10: =SUMPRODUCT(NOT(ISBLANK(W$3:W$4))*(W$3:W$4=$HY$3:$HY$4)) -> 0 | AC10: =SUMPRODUCT(NOT(ISBLANK(AC$3:AC$4))*(AC$3:AC$4=$ID$3:$ID$4)) -> 0 | AD10: =SUMPRODUCT(NOT(ISBLANK(AD$3:AD$4))*(AD$3:AD$4=$HY$3:$HY$4)) -> 0 | AJ10: =SUMPRODUCT(NOT(ISBLANK(AJ$3:AJ$4))*(AJ$3:AJ$4=$ID$3:$ID$4)) -> 0 | AK10: =SUMPRODUCT(NOT(ISBLANK(AK$3:AK$4))*(AK$3:AK$4=$HY$3:$HY$4)) -> 0 | AQ10: =SUMPRODUCT(NOT(ISBLANK(AQ$3:AQ$4))*(AQ$3:AQ$4=$ID$3:$ID$4)) -> 0 | AR10: =SUMPRODUCT(NOT(ISBLANK(AR$3:AR$4))*(AR$3:AR$4=$HY$3:$HY$4)) -> 0 | AS10: =SUMPRODUCT(NOT(ISBLANK(AS$3:AS$4))*(AS$3:AS$4=$HZ$3:$HZ$4)) -> 0 | AU10: =SUMPRODUCT(NOT(ISBLANK(AU$3:AU$4))*(AU$3:AU$4=$IA$3:$IA$4)) -> 0 | AV10: =SUMPRODUCT(NOT(ISBLANK(AV$3:AV$4))*(AV$3:AV$4=$IB$3:$IB$4)) -> 0 | AW10: =SUMPRODUCT(NOT(ISBLANK(AW$3:AW$4))*(AW$3:AW$4=$IC$3:$IC$4)) -> 0 | AX10: =SUMPRODUCT(NOT(ISBLANK(AX$3:AX$4))*(AX$3:AX$4=$ID$3:$ID$4)) -> 0 | AY10: =SUMPRODUCT(NOT(ISBLANK(AY$3:AY$4))*(AY$3:AY$4=$HY$3:$HY$4)) -> 0 | AZ10: =SUMPRODUCT(NOT(ISBLANK(AZ$3:AZ$4))*(AZ$3:AZ$4=$HZ$3:$HZ$4)) -> 0 | BB10: =SUMPRODUCT(NOT(ISBLANK(BB$3:BB$4))*(BB$3:BB$4=$IA$3:$IA$4)) -> 0 | BC10: =SUMPRODUCT(NOT(ISBLANK(BC$3:BC$4))*(BC$3:BC$4=$IB$3:$IB$4)) -> 0 | BD10: =SUMPRODUCT(NOT(ISBLANK(BD$3:BD$4))*(BD$3:BD$4=$IC$3:$IC$4)) -> 0 | BE10: =SUMPRODUCT(NOT(ISBLANK(BE$3:BE$4))*(BE$3:BE$4=$ID$3:$ID$4)) -> 0 | BF10: =SUMPRODUCT(NOT(ISBLANK(BF$3:BF$4))*(BF$3:BF$4=$HY$3:$HY$4)) -> 0 | BG10: =SUMPRODUCT(NOT(ISBLANK(BG$3:BG$4))*(BG$3:BG$4=$HZ$3:$HZ$4)) -> 0 | BI10: =SUMPRODUCT(NOT(ISBLANK(BI$3:BI$4))*(BI$3:BI$4=$IA$3:$IA$4)) -> 0 | BJ10: =SUMPRODUCT(NOT(ISBLANK(BJ$3:BJ$4))*(BJ$3:BJ$4=$IB$3:$IB$4)) -> 0 | BK10: =SUMPRODUCT(NOT(ISBLANK(BK$3:BK$4))*(BK$3:BK$4=$IC$3:$IC$4)) -> 0 | BL10: =SUMPRODUCT(NOT(ISBLANK(BL$3:BL$4))*(BL$3:BL$4=$ID$3:$ID$4)) -> 0 | BM10: =SUMPRODUCT(NOT(ISBLANK(BM$3:BM$4))*(BM$3:BM$4=$HY$3:$HY$4)) -> 0 | BN10: =SUMPRODUCT(NOT(ISBLANK(BN$3:BN$4))*(BN$3:BN$4=$HZ$3:$HZ$4)) -> 0 | BP10: =SUMPRODUCT(NOT(ISBLANK(BP$3:BP$4))*(BP$3:BP$4=$IA$3:$IA$4)) -> 0 | BQ10: =SUMPRODUCT(NOT(ISBLANK(BQ$3:BQ$4))*(BQ$3:BQ$4=$IB$3:$IB$4)) -> 0 | BR10: =SUMPRODUCT(NOT(ISBLANK(BR$3:BR$4))*(BR$3:BR$4=$IC$3:$IC$4)) -> 0 | BS10: =SUMPRODUCT(NOT(ISBLANK(BS$3:BS$4))*(BS$3:BS$4=$ID$3:$ID$4)) -> 0 | BT10: =SUMPRODUCT(NOT(ISBLANK(BT$3:BT$4))*(BT$3:BT$4=$HY$3:$HY$4)) -> 0 | BU10: =SUMPRODUCT(NOT(ISBLANK(BU$3:BU$4))*(BU$3:BU$4=$HZ$3:$HZ$4)) -> 0 | BW10: =SUMPRODUCT(NOT(ISBLANK(BW$3:BW$4))*(BW$3:BW$4=$IA$3:$IA$4)) -> 0 | BX10: =SUMPRODUCT(NOT(ISBLANK(BX$3:BX$4))*(BX$3:BX$4=$IB$3:$IB$4)) -> 0 | BY10: =SUMPRODUCT(NOT(ISBLANK(BY$3:BY$4))*(BY$3:BY$4=$IC$3:$IC$4)) -> 0 | BZ10: =SUMPRODUCT(NOT(ISBLANK(BZ$3:BZ$4))*(BZ$3:BZ$4=$ID$3:$ID$4)) -> 0 | CA10: =SUMPRODUCT(NOT(ISBLANK(CA$3:CA$4))*(CA$3:CA$4=$HY$3:$HY$4)) -> 0 | CB10: =SUMPRODUCT(NOT(ISBLANK(CB$3:CB$4))*(CB$3:CB$4=$HZ$3:$HZ$4)) -> 0 | CD10: =SUMPRODUCT(NOT(ISBLANK(CD$3:CD$4))*(CD$3:CD$4=$IA$3:$IA$4)) -> 0 | CE10: =SUMPRODUCT(NOT(ISBLANK(CE$3:CE$4))*(CE$3:CE$4=$IB$3:$IB$4)) -> 0 | CF10: =SUMPRODUCT(NOT(ISBLANK(CF$3:CF$4))*(CF$3:CF$4=$IC$3:$IC$4)) -> 0 | CG10: =SUMPRODUCT(NOT(ISBLANK(CG$3:CG$4))*(CG$3:CG$4=$ID$3:$ID$4)) -> 0 | CH10: =SUMPRODUCT(NOT(ISBLANK(CH$3:CH$4))*(CH$3:CH$4=$HY$3:$HY$4)) -> 0 | CI10: =SUMPRODUCT(NOT(ISBLANK(CI$3:CI$4))*(CI$3:CI$4=$HZ$3:$HZ$4)) -> 0 | CK10: =SUMPRODUCT(NOT(ISBLANK(CK$3:CK$4))*(CK$3:CK$4=$IA$3:$IA$4)) -> 0 | CL10: =SUMPRODUCT(NOT(ISBLANK(CL$3:CL$4))*(CL$3:CL$4=$IB$3:$IB$4)) -> 0 | CM10: =SUMPRODUCT(NOT(ISBLANK(CM$3:CM$4))*(CM$3:CM$4=$IC$3:$IC$4)) -> 0 | CN10: =SUMPRODUCT(NOT(ISBLANK(CN$3:CN$4))*(CN$3:CN$4=$ID$3:$ID$4)) -> 0 | CO10: =SUMPRODUCT(NOT(ISBLANK(CO$3:CO$4))*(CO$3:CO$4=$HY$3:$HY$4)) -> 0 | CP10: =SUMPRODUCT(NOT(ISBLANK(CP$3:CP$4))*(CP$3:CP$4=$HZ$3:$HZ$4)) -> 0 | CR10: =SUMPRODUCT(NOT(ISBLANK(CR$3:CR$4))*(CR$3:CR$4=$IA$3:$IA$4)) -> 0 | CS10: =SUMPRODUCT(NOT(ISBLANK(CS$3:CS$4))*(CS$3:CS$4=$IB$3:$IB$4)) -> 0 | CT10: =SUMPRODUCT(NOT(ISBLANK(CT$3:CT$4))*(CT$3:CT$4=$IC$3:$IC$4)) -> 0 | CU10: =SUMPRODUCT(NOT(ISBLANK(CU$3:CU$4))*(CU$3:CU$4=$ID$3:$ID$4)) -> 0 | CV10: =SUMPRODUCT(NOT(ISBLANK(CV$3:CV$4))*(CV$3:CV$4=$HY$3:$HY$4)) -> 0 | CW10: =SUMPRODUCT(NOT(ISBLANK(CW$3:CW$4))*(CW$3:CW$4=$HZ$3:$HZ$4)) -> 0 | CY10: =SUMPRODUCT(NOT(ISBLANK(CY$3:CY$4))*(CY$3:CY$4=$IA$3:$IA$4)) -> 0 | CZ10: =SUMPRODUCT(NOT(ISBLANK(CZ$3:CZ$4))*(CZ$3:CZ$4=$IB$3:$IB$4)) -> 0 | DA10: =SUMPRODUCT(NOT(ISBLANK(DA$3:DA$4))*(DA$3:DA$4=$IC$3:$IC$4)) -> 0 | DB10: =SUMPRODUCT(NOT(ISBLANK(DB$3:DB$4))*(DB$3:DB$4=$ID$3:$ID$4)) -> 0 | DC10: =SUMPRODUCT(NOT(ISBLANK(DC$3:DC$4))*(DC$3:DC$4=$HY$3:$HY$4)) -> 0 | DD10: =SUMPRODUCT(NOT(ISBLANK(DD$3:DD$4))*(DD$3:DD$4=$HZ$3:$HZ$4)) -> 0 | DF10: =SUMPRODUCT(NOT(ISBLANK(DF$3:DF$4))*(DF$3:DF$4=$IA$3:$IA$4)) -> 0 | DG10: =SUMPRODUCT(NOT(ISBLANK(DG$3:DG$4))*(DG$3:DG$4=$IB$3:$IB$4)) -> 0 | DH10: =SUMPRODUCT(NOT(ISBLANK(DH$3:DH$4))*(DH$3:DH$4=$IC$3:$IC$4)) -> 0 | DI10: =SUMPRODUCT(NOT(ISBLANK(DI$3:DI$4))*(DI$3:DI$4=$ID$3:$ID$4)) -> 0 | DJ10: =SUMPRODUCT(NOT(ISBLANK(DJ$3:DJ$4))*(DJ$3:DJ$4=$HY$3:$HY$4)) -> 0 | DK10: =SUMPRODUCT(NOT(ISBLANK(DK$3:DK$4))*(DK$3:DK$4=$HZ$3:$HZ$4)) -> 0 | DM10: =SUMPRODUCT(NOT(ISBLANK(DM$3:DM$4))*(DM$3:DM$4=$IA$3:$IA$4)) -> 0 | DN10: =SUMPRODUCT(NOT(ISBLANK(DN$3:DN$4))*(DN$3:DN$4=$IB$3:$IB$4)) -> 0 | DO10: =SUMPRODUCT(NOT(ISBLANK(DO$3:DO$4))*(DO$3:DO$4=$IC$3:$IC$4)) -> 0 | DP10: =SUMPRODUCT(NOT(ISBLANK(DP$3:DP$4))*(DP$3:DP$4=$ID$3:$ID$4)) -> 0 | DQ10: =SUMPRODUCT(NOT(ISBLANK(DQ$3:DQ$4))*(DQ$3:DQ$4=$HY$3:$HY$4)) -> 0 | DR10: =SUMPRODUCT(NOT(ISBLANK(DR$3:DR$4))*(DR$3:DR$4=$HZ$3:$HZ$4)) -> 0 | DT10: =SUMPRODUCT(NOT(ISBLANK(DT$3:DT$4))*(DT$3:DT$4=$IA$3:$IA$4)) -> 0 | DU10: =SUMPRODUCT(NOT(ISBLANK(DU$3:DU$4))*(DU$3:DU$4=$IB$3:$IB$4)) -> 0 | DV10: =SUMPRODUCT(NOT(ISBLANK(DV$3:DV$4))*(DV$3:DV$4=$IC$3:$IC$4)) -> 0 | DW10: =SUMPRODUCT(NOT(ISBLANK(DW$3:DW$4))*(DW$3:DW$4=$ID$3:$ID$4)) -> 0 | DX10: =SUMPRODUCT(NOT(ISBLANK(DX$3:DX$4))*(DX$3:DX$4=$HY$3:$HY$4)) -> 0 | DY10: =SUMPRODUCT(NOT(ISBLANK(DY$3:DY$4))*(DY$3:DY$4=$HZ$3:$HZ$4)) -> 0 | EA10: =SUMPRODUCT(NOT(ISBLANK(EA$3:EA$4))*(EA$3:EA$4=$IA$3:$IA$4)) -> 0 | EB10: =SUMPRODUCT(NOT(ISBLANK(EB$3:EB$4))*(EB$3:EB$4=$IB$3:$IB$4)) -> 0 | EC10: =SUMPRODUCT(NOT(ISBLANK(EC$3:EC$4))*(EC$3:EC$4=$IC$3:$IC$4)) -> 0 | ED10: =SUMPRODUCT(NOT(ISBLANK(ED$3:ED$4))*(ED$3:ED$4=$ID$3:$ID$4)) -> 0 | EE10: =SUMPRODUCT(NOT(ISBLANK(EE$3:EE$4))*(EE$3:EE$4=$HY$3:$HY$4)) -> 0 | EF10: =SUMPRODUCT(NOT(ISBLANK(EF$3:EF$4))*(EF$3:EF$4=$HZ$3:$HZ$4)) -> 0 | EH10: =SUMPRODUCT(NOT(ISBLANK(EH$3:EH$4))*(EH$3:EH$4=$IA$3:$IA$4)) -> 0 | EI10: =SUMPRODUCT(NOT(ISBLANK(EI$3:EI$4))*(EI$3:EI$4=$IB$3:$IB$4)) -> 0 | EJ10: =SUMPRODUCT(NOT(ISBLANK(EJ$3:EJ$4))*(EJ$3:EJ$4=$IC$3:$IC$4)) -> 0 | EK10: =SUMPRODUCT(NOT(ISBLANK(EK$3:EK$4))*(EK$3:EK$4=$ID$3:$ID$4)) -> 0 | EL10: =SUMPRODUCT(NOT(ISBLANK(EL$3:EL$4))*(EL$3:EL$4=$HY$3:$HY$4)) -> 0 | EM10: =SUMPRODUCT(NOT(ISBLANK(EM$3:EM$4))*(EM$3:EM$4=$HZ$3:$HZ$4)) -> 0 | EO10: =SUMPRODUCT(NOT(ISBLANK(EO$3:EO$4))*(EO$3:EO$4=$IA$3:$IA$4)) -> 0 | EP10: =SUMPRODUCT(NOT(ISBLANK(EP$3:EP$4))*(EP$3:EP$4=$IB$3:$IB$4)) -> 0 | EQ10: =SUMPRODUCT(NOT(ISBLANK(EQ$3:EQ$4))*(EQ$3:EQ$4=$IC$3:$IC$4)) -> 0 | ER10: =SUMPRODUCT(NOT(ISBLANK(ER$3:ER$4))*(ER$3:ER$4=$ID$3:$ID$4)) -> 0 | ES10: =SUMPRODUCT(NOT(ISBLANK(ES$3:ES$4))*(ES$3:ES$4=$HY$3:$HY$4)) -> 0 | ET10: =SUMPRODUCT(NOT(ISBLANK(ET$3:ET$4))*(ET$3:ET$4=$HZ$3:$HZ$4)) -> 0 | EV10: =SUMPRODUCT(NOT(ISBLANK(EV$3:EV$4))*(EV$3:EV$4=$IA$3:$IA$4)) -> 0 | EW10: =SUMPRODUCT(NOT(ISBLANK(EW$3:EW$4))*(EW$3:EW$4=$IB$3:$IB$4)) -> 0 | EX10: =SUMPRODUCT(NOT(ISBLANK(EX$3:EX$4))*(EX$3:EX$4=$IC$3:$IC$4)) -> 0 | EY10: =SUMPRODUCT(NOT(ISBLANK(EY$3:EY$4))*(EY$3:EY$4=$ID$3:$ID$4)) -> 0 | EZ10: =SUMPRODUCT(NOT(ISBLANK(EZ$3:EZ$4))*(EZ$3:EZ$4=$HY$3:$HY$4)) -> 0 | FA10: =SUMPRODUCT(NOT(ISBLANK(FA$3:FA$4))*(FA$3:FA$4=$HZ$3:$HZ$4)) -> 0 | FC10: =SUMPRODUCT(NOT(ISBLANK(FC$3:FC$4))*(FC$3:FC$4=$IA$3:$IA$4)) -> 0 | FD10: =SUMPRODUCT(NOT(ISBLANK(FD$3:FD$4))*(FD$3:FD$4=$IB$3:$IB$4)) -> 0 | FE10: =SUMPRODUCT(NOT(ISBLANK(FE$3:FE$4))*(FE$3:FE$4=$IC$3:$IC$4)) -> 0 | FF10: =SUMPRODUCT(NOT(ISBLANK(FF$3:FF$4))*(FF$3:FF$4=$ID$3:$ID$4)) -> 0 | FG10: =SUMPRODUCT(NOT(ISBLANK(FG$3:FG$4))*(FG$3:FG$4=$HY$3:$HY$4)) -> 0 | FH10: =SUMPRODUCT(NOT(ISBLANK(FH$3:FH$4))*(FH$3:FH$4=$HZ$3:$HZ$4)) -> 0 | FJ10: =SUMPRODUCT(NOT(ISBLANK(FJ$3:FJ$4))*(FJ$3:FJ$4=$IA$3:$IA$4)) -> 0 | FK10: =SUMPRODUCT(NOT(ISBLANK(FK$3:FK$4))*(FK$3:FK$4=$IB$3:$IB$4)) -> 0 | FL10: =SUMPRODUCT(NOT(ISBLANK(FL$3:FL$4))*(FL$3:FL$4=$IC$3:$IC$4)) -> 0 | FM10: =SUMPRODUCT(NOT(ISBLANK(FM$3:FM$4))*(FM$3:FM$4=$ID$3:$ID$4)) -> 0 | FN10: =SUMPRODUCT(NOT(ISBLANK(FN$3:FN$4))*(FN$3:FN$4=$HY$3:$HY$4)) -> 0 | FO10: =SUMPRODUCT(NOT(ISBLANK(FO$3:FO$4))*(FO$3:FO$4=$HZ$3:$HZ$4)) -> 0 | FQ10: =SUMPRODUCT(NOT(ISBLANK(FQ$3:FQ$4))*(FQ$3:FQ$4=$IA$3:$IA$4)) -> 0 | FR10: =SUMPRODUCT(NOT(ISBLANK(FR$3:FR$4))*(FR$3:FR$4=$IB$3:$IB$4)) -> 0 | FS10: =SUMPRODUCT(NOT(ISBLANK(FS$3:FS$4))*(FS$3:FS$4=$IC$3:$IC$4)) -> 0 | FT10: =SUMPRODUCT(NOT(ISBLANK(FT$3:FT$4))*(FT$3:FT$4=$ID$3:$ID$4)) -> 0 | FU10: =SUMPRODUCT(NOT(ISBLANK(FU$3:FU$4))*(FU$3:FU$4=$HY$3:$HY$4)) -> 0 | FV10: =SUMPRODUCT(NOT(ISBLANK(FV$3:FV$4))*(FV$3:FV$4=$HZ$3:$HZ$4)) -> 0 | FX10: =SUMPRODUCT(NOT(ISBLANK(FX$3:FX$4))*(FX$3:FX$4=$IA$3:$IA$4)) -> 0 | FY10: =SUMPRODUCT(NOT(ISBLANK(FY$3:FY$4))*(FY$3:FY$4=$IB$3:$IB$4)) -> 0 | FZ10: =SUMPRODUCT(NOT(ISBLANK(FZ$3:FZ$4))*(FZ$3:FZ$4=$IC$3:$IC$4)) -> 0 | GA10: =SUMPRODUCT(NOT(ISBLANK(GA$3:GA$4))*(GA$3:GA$4=$ID$3:$ID$4)) -> 0 | GB10: =SUMPRODUCT(NOT(ISBLANK(GB$3:GB$4))*(GB$3:GB$4=$HY$3:$HY$4)) -> 0 | GC10: =SUMPRODUCT(NOT(ISBLANK(GC$3:GC$4))*(GC$3:GC$4=$HZ$3:$HZ$4)) -> 0 | GE10: =SUMPRODUCT(NOT(ISBLANK(GE$3:GE$4))*(GE$3:GE$4=$IA$3:$IA$4)) -> 0 | GF10: =SUMPRODUCT(NOT(ISBLANK(GF$3:GF$4))*(GF$3:GF$4=$IB$3:$IB$4)) -> 0 | GG10: =SUMPRODUCT(NOT(ISBLANK(GG$3:GG$4))*(GG$3:GG$4=$IC$3:$IC$4)) -> 0 | GH10: =SUMPRODUCT(NOT(ISBLANK(GH$3:GH$4))*(GH$3:GH$4=$ID$3:$ID$4)) -> 0 | GI10: =SUMPRODUCT(NOT(ISBLANK(GI$3:GI$4))*(GI$3:GI$4=$HY$3:$HY$4)) -> 0 | GJ10: =SUMPRODUCT(NOT(ISBLANK(GJ$3:GJ$4))*(GJ$3:GJ$4=$HZ$3:$HZ$4)) -> 0 | GL10: =SUMPRODUCT(NOT(ISBLANK(GL$3:GL$4))*(GL$3:GL$4=$IA$3:$IA$4)) -> 0 | GM10: =SUMPRODUCT(NOT(ISBLANK(GM$3:GM$4))*(GM$3:GM$4=$IB$3:$IB$4)) -> 0 | GN10: =SUMPRODUCT(NOT(ISBLANK(GN$3:GN$4))*(GN$3:GN$4=$IC$3:$IC$4)) -> 0 | GO10: =SUMPRODUCT(NOT(ISBLANK(GO$3:GO$4))*(GO$3:GO$4=$ID$3:$ID$4)) -> 0 | GP10: =SUMPRODUCT(NOT(ISBLANK(GP$3:GP$4))*(GP$3:GP$4=$HY$3:$HY$4)) -> 0 | GQ10: =SUMPRODUCT(NOT(ISBLANK(GQ$3:GQ$4))*(GQ$3:GQ$4=$HZ$3:$HZ$4)) -> 0 | GS10: =SUMPRODUCT(NOT(ISBLANK(GS$3:GS$4))*(GS$3:GS$4=$IA$3:$IA$4)) -> 0 | GT10: =SUMPRODUCT(NOT(ISBLANK(GT$3:GT$4))*(GT$3:GT$4=$IB$3:$IB$4)) -> 0 | GU10: =SUMPRODUCT(NOT(ISBLANK(GU$3:GU$4))*(GU$3:GU$4=$IC$3:$IC$4)) -> 0 | GV10: =SUMPRODUCT(NOT(ISBLANK(GV$3:GV$4))*(GV$3:GV$4=$ID$3:$ID$4)) -> 0 | GW10: =SUMPRODUCT(NOT(ISBLANK(GW$3:GW$4))*(GW$3:GW$4=$HY$3:$HY$4)) -> 0 | GX10: =SUMPRODUCT(NOT(ISBLANK(GX$3:GX$4))*(GX$3:GX$4=$HZ$3:$HZ$4)) -> 0 | GZ10: =SUMPRODUCT(NOT(ISBLANK(GZ$3:GZ$4))*(GZ$3:GZ$4=$IA$3:$IA$4)) -> 0 | HA10: =SUMPRODUCT(NOT(ISBLANK(HA$3:HA$4))*(HA$3:HA$4=$IB$3:$IB$4)) -> 0 | HB10: =SUMPRODUCT(NOT(ISBLANK(HB$3:HB$4))*(HB$3:HB$4=$IC$3:$IC$4)) -> 0 | HC10: =SUMPRODUCT(NOT(ISBLANK(HC$3:HC$4))*(HC$3:HC$4=$ID$3:$ID$4)) -> 0 | HD10: =SUMPRODUCT(NOT(ISBLANK(HD$3:HD$4))*(HD$3:HD$4=$HY$3:$HY$4)) -> 0 | HE10: =SUMPRODUCT(NOT(ISBLANK(HE$3:HE$4))*(HE$3:HE$4=$HZ$3:$HZ$4)) -> 0 | HG10: =SUMPRODUCT(NOT(ISBLANK(HG$3:HG$4))*(HG$3:HG$4=$IA$3:$IA$4)) -> 0 | HH10: =SUMPRODUCT(NOT(ISBLANK(HH$3:HH$4))*(HH$3:HH$4=$IB$3:$IB$4)) -> 0 | HI10: =SUMPRODUCT(NOT(ISBLANK(HI$3:HI$4))*(HI$3:HI$4=$IC$3:$IC$4)) -> 0 | HJ10: =SUMPRODUCT(NOT(ISBLANK(HJ$3:HJ$4))*(HJ$3:HJ$4=$ID$3:$ID$4)) -> 0 | HK10: =SUMPRODUCT(NOT(ISBLANK(HK$3:HK$4))*(HK$3:HK$4=$HY$3:$HY$4)) -> 0 | HL10: =SUMPRODUCT(NOT(ISBLANK(HL$3:HL$4))*(HL$3:HL$4=$HZ$3:$HZ$4)) -> 0 | HN10: =SUMPRODUCT(NOT(ISBLANK(HN$3:HN$4))*(HN$3:HN$4=$IA$3:$IA$4)) -> 0 | HO10: =SUMPRODUCT(NOT(ISBLANK(HO$3:HO$4))*(HO$3:HO$4=$IB$3:$IB$4)) -> 0 | HP10: =SUMPRODUCT(NOT(ISBLANK(HP$3:HP$4))*(HP$3:HP$4=$IC$3:$IC$4)) -> 0 | HQ10: =SUMPRODUCT(NOT(ISBLANK(HQ$3:HQ$4))*(HQ$3:HQ$4=$ID$3:$ID$4)) -> 0 | HR10: =SUMPRODUCT(NOT(ISBLANK(HR$3:HR$4))*(HR$3:HR$4=$HY$3:$HY$4)) -> 0 | HS10: =SUMPRODUCT(NOT(ISBLANK(HS$3:HS$4))*(HS$3:HS$4=$HZ$3:$HZ$4)) -> 0 | HU10: =SUMPRODUCT(NOT(ISBLANK(HU$3:HU$4))*(HU$3:HU$4=$IA$3:$IA$4)) -> 0 | HV10: =SUMPRODUCT(NOT(ISBLANK(HV$3:HV$4))*(HV$3:HV$4=$IB$3:$IB$4)) -> 0 | HW10: =SUMPRODUCT(NOT(ISBLANK(HW$3:HW$4))*(HW$3:HW$4=$IC$3:$IC$4)) -> 0 | HX10: =SUMPRODUCT(NOT(ISBLANK(HX$3:HX$4))*(HX$3:HX$4=$ID$3:$ID$4)) -> 0
