Workbook

Sheet Instances
B1: memelingo-1/all-opts_mlp-tplp-ht_15_100 | I1: memelingo-1/all-opts_mlp-tplp-ht_15_150 | P1: memelingo-1/all-opts_mlp-tplp-ht_15_30 | W1: memelingo-1/all-opts_mlp-tplp-ht_15_50 | AD1: memelingo-1/all-opts_mlp-tplp-ht_20_100 | AK1: memelingo-1/all-opts_mlp-tplp-ht_20_150 | AR1: memelingo-1/all-opts_mlp-tplp-ht_20_30 | AY1: memelingo-1/all-opts_mlp-tplp-ht_20_50 | BF1: memelingo-1/all-opts_mlp-tplp-ht_25_100 | BM1: memelingo-1/all-opts_mlp-tplp-ht_25_150 | BT1: memelingo-1/all-opts_mlp-tplp-ht_25_30 | CA1: memelingo-1/all-opts_mlp-tplp-ht_25_50 | CH1: memelingo-1/all-opts_mlp-tplp-ht_30_100 | CO1: memelingo-1/all-opts_mlp-tplp-ht_30_150 | CV1: memelingo-1/all-opts_mlp-tplp-ht_30_30 | DC1: memelingo-1/all-opts_mlp-tplp-ht_30_50 | DJ1: memelingo-1/all-opts_mlp-tplp-ht_35_100 | DQ1: memelingo-1/all-opts_mlp-tplp-ht_35_150 | DX1: memelingo-1/all-opts_mlp-tplp-ht_35_30 | EE1: memelingo-1/all-opts_mlp-tplp-ht_35_50 | EL1: memelingo-1/all-opts_mlp-tplp-ht_40_100 | ES1: memelingo-1/all-opts_mlp-tplp-ht_40_150 | EZ1: memelingo-1/all-opts_mlp-tplp-ht_40_30 | FG1: memelingo-1/all-opts_mlp-tplp-ht_40_50 | FN1: memelingo-1/all-opts_mlp-tplp-ht_45_100 | FU1: memelingo-1/all-opts_mlp-tplp-ht_45_150 | GB1: memelingo-1/all-opts_mlp-tplp-ht_45_30 | GI1: memelingo-1/all-opts_mlp-tplp-ht_45_50 | GP1: memelingo-1/all-opts_mlp-tplp-htc_15_100 | GW1: memelingo-1/all-opts_mlp-tplp-htc_15_150 | HD1: memelingo-1/all-opts_mlp-tplp-htc_15_30 | HK1: memelingo-1/all-opts_mlp-tplp-htc_15_50 | HR1: memelingo-1/all-opts_mlp-tplp-htc_20_100 | HY1: memelingo-1/all-opts_mlp-tplp-htc_20_150 | IF1: memelingo-1/all-opts_mlp-tplp-htc_20_30 | IM1: memelingo-1/all-opts_mlp-tplp-htc_20_50 | IT1: memelingo-1/all-opts_mlp-tplp-htc_25_100 | JA1: memelingo-1/all-opts_mlp-tplp-htc_25_150 | JH1: memelingo-1/all-opts_mlp-tplp-htc_25_30 | JO1: memelingo-1/all-opts_mlp-tplp-htc_25_50 | JV1: memelingo-1/all-opts_mlp-tplp-htc_30_100 | KC1: memelingo-1/all-opts_mlp-tplp-htc_30_150 | KJ1: memelingo-1/all-opts_mlp-tplp-htc_30_30 | KQ1: memelingo-1/all-opts_mlp-tplp-htc_30_50 | KX1: memelingo-1/all-opts_mlp-tplp-htc_35_100 | LE1: memelingo-1/all-opts_mlp-tplp-htc_35_150 | LL1: memelingo-1/all-opts_mlp-tplp-htc_35_30 | LS1: memelingo-1/all-opts_mlp-tplp-htc_35_50 | LZ1: memelingo-1/all-opts_mlp-tplp-htc_40_100 | MG1: memelingo-1/all-opts_mlp-tplp-htc_40_150 | MN1: memelingo-1/all-opts_mlp-tplp-htc_40_30 | MU1: memelingo-1/all-opts_mlp-tplp-htc_40_50 | NB1: memelingo-1/all-opts_mlp-tplp-htc_45_100 | NI1: memelingo-1/all-opts_mlp-tplp-htc_45_150 | NP1: memelingo-1/all-opts_mlp-tplp-htc_45_30 | NW1: memelingo-1/all-opts_mlp-tplp-htc_45_50 | OD1: memelingo-1/all-opts_mlp-tplp-htcdl_15_100 | OK1: memelingo-1/all-opts_mlp-tplp-htcdl_15_150 | OR1: memelingo-1/all-opts_mlp-tplp-htcdl_15_30 | OY1: memelingo-1/all-opts_mlp-tplp-htcdl_15_50 | PF1: memelingo-1/all-opts_mlp-tplp-htcdl_20_100 | PM1: memelingo-1/all-opts_mlp-tplp-htcdl_20_150 | PT1: memelingo-1/all-opts_mlp-tplp-htcdl_20_30 | QA1: memelingo-1/all-opts_mlp-tplp-htcdl_20_50 | QH1: memelingo-1/all-opts_mlp-tplp-htcdl_25_100 | QO1: memelingo-1/all-opts_mlp-tplp-htcdl_25_150 | QV1: memelingo-1/all-opts_mlp-tplp-htcdl_25_30 | RC1: memelingo-1/all-opts_mlp-tplp-htcdl_25_50 | RJ1: memelingo-1/all-opts_mlp-tplp-htcdl_30_100 | RQ1: memelingo-1/all-opts_mlp-tplp-htcdl_30_150 | RX1: memelingo-1/all-opts_mlp-tplp-htcdl_30_30 | SE1: memelingo-1/all-opts_mlp-tplp-htcdl_30_50 | SL1: memelingo-1/all-opts_mlp-tplp-htcdl_35_100 | SS1: memelingo-1/all-opts_mlp-tplp-htcdl_35_150 | SZ1: memelingo-1/all-opts_mlp-tplp-htcdl_35_30 | TG1: memelingo-1/all-opts_mlp-tplp-htcdl_35_50 | TN1: memelingo-1/all-opts_mlp-tplp-htcdl_40_100 | TU1: memelingo-1/all-opts_mlp-tplp-htcdl_40_150 | UB1: memelingo-1/all-opts_mlp-tplp-htcdl_40_30 | UI1: memelingo-1/all-opts_mlp-tplp-htcdl_40_50 | UP1: memelingo-1/all-opts_mlp-tplp-htcdl_45_100 | UW1: memelingo-1/all-opts_mlp-tplp-htcdl_45_150 | VD1: memelingo-1/all-opts_mlp-tplp-htcdl_45_30 | VK1: memelingo-1/all-opts_mlp-tplp-htcdl_45_50 | VR1: min | VX1: median | WD1: max
B2: time | C2: stime | D2: status | E2: rules | F2: ctime | G2: fmtime | H2: memout | I2: time | J2: stime | K2: status | L2: rules | M2: ctime | N2: fmtime | O2: memout | P2: time | Q2: stime | R2: status | S2: rules | T2: ctime | U2: fmtime | V2: memout | W2: time | X2: stime | Y2: status | Z2: rules | AA2: ctime | AB2: fmtime | AC2: memout | AD2: time | AE2: stime | AF2: status | AG2: rules | AH2: ctime | AI2: fmtime | AJ2: memout | AK2: time | AL2: stime | AM2: status | AN2: rules | AO2: ctime | AP2: fmtime | AQ2: memout | AR2: time | AS2: stime | AT2: status | AU2: rules | AV2: ctime | AW2: fmtime | AX2: memout | AY2: time | AZ2: stime | BA2: status | BB2: rules | BC2: ctime | BD2: fmtime | BE2: memout | BF2: time | BG2: stime | BH2: status | BI2: rules | BJ2: ctime | BK2: fmtime | BL2: memout | BM2: time | BN2: stime | BO2: status | BP2: rules | BQ2: ctime | BR2: fmtime | BS2: memout | BT2: time | BU2: stime | BV2: status | BW2: rules | BX2: ctime | BY2: fmtime | BZ2: memout | CA2: time | CB2: stime | CC2: status | CD2: rules | CE2: ctime | CF2: fmtime | CG2: memout | CH2: time | CI2: stime | CJ2: status | CK2: rules | CL2: ctime | CM2: fmtime | CN2: memout | CO2: time | CP2: stime | CQ2: status | CR2: rules | CS2: ctime | CT2: fmtime | CU2: memout | CV2: time | CW2: stime | CX2: status | CY2: rules | CZ2: ctime | DA2: fmtime | DB2: memout | DC2: time | DD2: stime | DE2: status | DF2: rules | DG2: ctime | DH2: fmtime | DI2: memout | DJ2: time | DK2: stime | DL2: status | DM2: rules | DN2: ctime | DO2: fmtime | DP2: memout | DQ2: time | DR2: stime | DS2: status | DT2: rules | DU2: ctime | DV2: fmtime | DW2: memout | DX2: time | DY2: stime | DZ2: status | EA2: rules | EB2: ctime | EC2: fmtime | ED2: memout | EE2: time | EF2: stime | EG2: status | EH2: rules | EI2: ctime | EJ2: fmtime | EK2: memout | EL2: time | EM2: stime | EN2: status | EO2: rules | EP2: ctime | EQ2: fmtime | ER2: memout | ES2: time | ET2: stime | EU2: status | EV2: rules | EW2: ctime | EX2: fmtime | EY2: memout | EZ2: time | FA2: stime | FB2: status | FC2: rules | FD2: ctime | FE2: fmtime | FF2: memout | FG2: time | FH2: stime | FI2: status | FJ2: rules | FK2: ctime | FL2: fmtime | FM2: memout | FN2: time | FO2: stime | FP2: status | FQ2: rules | FR2: ctime | FS2: fmtime | FT2: memout | FU2: time | FV2: stime | FW2: status | FX2: rules | FY2: ctime | FZ2: fmtime | GA2: memout | GB2: time | GC2: stime | GD2: status | GE2: rules | GF2: ctime | GG2: fmtime | GH2: memout | GI2: time | GJ2: stime | GK2: status | GL2: rules | GM2: ctime | GN2: fmtime | GO2: memout | GP2: time | GQ2: stime | GR2: status | GS2: rules | GT2: ctime | GU2: fmtime | GV2: memout | GW2: time | GX2: stime | GY2: status | GZ2: rules | HA2: ctime | HB2: fmtime | HC2: memout | HD2: time | HE2: stime | HF2: status | HG2: rules | HH2: ctime | HI2: fmtime | HJ2: memout | HK2: time | HL2: stime | HM2: status | HN2: rules | HO2: ctime | HP2: fmtime | HQ2: memout | HR2: time | HS2: stime | HT2: status | HU2: rules | HV2: ctime | HW2: fmtime | HX2: memout | HY2: time | HZ2: stime | IA2: status | IB2: rules | IC2: ctime | ID2: fmtime | IE2: memout | IF2: time | IG2: stime | IH2: status | II2: rules | IJ2: ctime | IK2: fmtime | IL2: memout | IM2: time | IN2: stime | IO2: status | IP2: rules | IQ2: ctime | IR2: fmtime | IS2: memout | IT2: time | IU2: stime | IV2: status | IW2: rules | IX2: ctime | IY2: fmtime | IZ2: memout | JA2: time | JB2: stime | JC2: status | JD2: rules | JE2: ctime | JF2: fmtime | JG2: memout | JH2: time | JI2: stime | JJ2: status | JK2: rules | JL2: ctime | JM2: fmtime | JN2: memout | JO2: time | JP2: stime | JQ2: status | JR2: rules | JS2: ctime | JT2: fmtime | JU2: memout | JV2: time | JW2: stime | JX2: status | JY2: rules | JZ2: ctime | KA2: fmtime | KB2: memout | KC2: time | KD2: stime | KE2: status | KF2: rules | KG2: ctime | KH2: fmtime | KI2: memout | KJ2: time | KK2: stime | KL2: status | KM2: rules | KN2: ctime | KO2: fmtime | KP2: memout | KQ2: time | KR2: stime | KS2: status | KT2: rules | KU2: ctime | KV2: fmtime | KW2: memout | KX2: time | KY2: stime | KZ2: status | LA2: rules | LB2: ctime | LC2: fmtime | LD2: memout | LE2: time | LF2: stime | LG2: status | LH2: rules | LI2: ctime | LJ2: fmtime | LK2: memout | LL2: time | LM2: stime | LN2: status | LO2: rules | LP2: ctime | LQ2: fmtime | LR2: memout | LS2: time | LT2: stime | LU2: status | LV2: rules | LW2: ctime | LX2: fmtime | LY2: memout | LZ2: time | MA2: stime | MB2: status | MC2: rules | MD2: ctime | ME2: fmtime | MF2: memout | MG2: time | MH2: stime | MI2: status | MJ2: rules | MK2: ctime | ML2: fmtime | MM2: memout | MN2: time | MO2: stime | MP2: status | MQ2: rules | MR2: ctime | MS2: fmtime | MT2: memout | MU2: time | MV2: stime | MW2: status | MX2: rules | MY2: ctime | MZ2: fmtime | NA2: memout | NB2: time | NC2: stime | ND2: status | NE2: rules | NF2: ctime | NG2: fmtime | NH2: memout | NI2: time | NJ2: stime | NK2: status | NL2: rules | NM2: ctime | NN2: fmtime | NO2: memout | NP2: time | NQ2: stime | NR2: status | NS2: rules | NT2: ctime | NU2: fmtime | NV2: memout | NW2: time | NX2: stime | NY2: status | NZ2: rules | OA2: ctime | OB2: fmtime | OC2: memout | OD2: time | OE2: stime | OF2: status | OG2: rules | OH2: ctime | OI2: fmtime | OJ2: memout | OK2: time | OL2: stime | OM2: status | ON2: rules | OO2: ctime | OP2: fmtime | OQ2: memout | OR2: time | OS2: stime | OT2: status | OU2: rules | OV2: ctime | OW2: fmtime | OX2: memout | OY2: time | OZ2: stime | PA2: status | PB2: rules | PC2: ctime | PD2: fmtime | PE2: memout | PF2: time | PG2: stime | PH2: status | PI2: rules | PJ2: ctime | PK2: fmtime | PL2: memout | PM2: time | PN2: stime | PO2: status | PP2: rules | PQ2: ctime | PR2: fmtime | PS2: memout | PT2: time | PU2: stime | PV2: status | PW2: rules | PX2: ctime | PY2: fmtime | PZ2: memout | QA2: time | QB2: stime | QC2: status | QD2: rules | QE2: ctime | QF2: fmtime | QG2: memout | QH2: time | QI2: stime | QJ2: status | QK2: rules | QL2: ctime | QM2: fmtime | QN2: memout | QO2: time | QP2: stime | QQ2: status | QR2: rules | QS2: ctime | QT2: fmtime | QU2: memout | QV2: time | QW2: stime | QX2: status | QY2: rules | QZ2: ctime | RA2: fmtime | RB2: memout | RC2: time | RD2: stime | RE2: status | RF2: rules | RG2: ctime | RH2: fmtime | RI2: memout | RJ2: time | RK2: stime | RL2: status | RM2: rules | RN2: ctime | RO2: fmtime | RP2: memout | RQ2: time | RR2: stime | RS2: status | RT2: rules | RU2: ctime | RV2: fmtime | RW2: memout | RX2: time | RY2: stime | RZ2: status | SA2: rules | SB2: ctime | SC2: fmtime | SD2: memout | SE2: time | SF2: stime | SG2: status | SH2: rules | SI2: ctime | SJ2: fmtime | SK2: memout | SL2: time | SM2: stime | SN2: status | SO2: rules | SP2: ctime | SQ2: fmtime | SR2: memout | SS2: time | ST2: stime | SU2: status | SV2: rules | SW2: ctime | SX2: fmtime | SY2: memout | SZ2: time | TA2: stime | TB2: status | TC2: rules | TD2: ctime | TE2: fmtime | TF2: memout | TG2: time | TH2: stime | TI2: status | TJ2: rules | TK2: ctime | TL2: fmtime | TM2: memout | TN2: time | TO2: stime | TP2: status | TQ2: rules | TR2: ctime | TS2: fmtime | TT2: memout | TU2: time | TV2: stime | TW2: status | TX2: rules | TY2: ctime | TZ2: fmtime | UA2: memout | UB2: time | UC2: stime | UD2: status | UE2: rules | UF2: ctime | UG2: fmtime | UH2: memout | UI2: time | UJ2: stime | UK2: status | UL2: rules | UM2: ctime | UN2: fmtime | UO2: memout | UP2: time | UQ2: stime | UR2: status | US2: rules | UT2: ctime | UU2: fmtime | UV2: memout | UW2: time | UX2: stime | UY2: status | UZ2: rules | VA2: ctime | VB2: fmtime | VC2: memout | VD2: time | VE2: stime | VF2: status | VG2: rules | VH2: ctime | VI2: fmtime | VJ2: memout | VK2: time | VL2: stime | VM2: status | VN2: rules | VO2: ctime | VP2: fmtime | VQ2: memout | VR2: time | VS2: stime | VT2: rules | VU2: ctime | VV2: fmtime | VW2: memout | VX2: time | VY2: stime | VZ2: rules | WA2: ctime | WB2: fmtime | WC2: memout | WD2: time | WE2: stime | WF2: rules | WG2: ctime | WH2: fmtime | WI2: memout
A3: instances/random_x8_y8_a3 | B3: 1200 | C3: 1159.41 | D3: UNKNOWN | E3: 12014961 | F3: 1193.92 | G3: 0 | H3: 0 | I3: 1200 | J3: 1140.88 | K3: UNKNOWN | L3: 25042111 | M3: 1193.171 | N3: 0 | O3: 0 | P3: 1200 | Q3: 1178.75 | R3: UNKNOWN | S3: 3092551 | T3: 1194.349 | U3: 0 | V3: 0 | W3: 1200 | X3: 1175.11 | Y3: UNKNOWN | Z3: 4532811 | AA3: 1193.482 | AB3: 0 | AC3: 0 | AD3: 1200 | AE3: 1133.9 | AF3: UNKNOWN | AG3: 19677381 | AH3: 1193.976 | AI3: 0 | AJ3: 0 | AK3: 1200 | AL3: 1061.67 | AM3: UNKNOWN | AN3: 42704281 | AO3: 1194.142 | AP3: 0 | AQ3: 0 | AR3: 1200 | AS3: 1175.31 | AT3: UNKNOWN | AU3: 4273321 | AV3: 1193.926 | AW3: 0 | AX3: 0 | AY3: 1200 | AZ3: 1164.53 | BA3: UNKNOWN | BB3: 6670481 | BC3: 1193.952 | BD3: 0 | BE3: 0 | BF3: 1200 | BG3: 1122.76 | BH3: UNKNOWN | BI3: 28629901 | BJ3: 1191.904 | BK3: 0 | BL3: 0 | BM3: 1200 | BN3: 1035.06 | BO3: UNKNOWN | BP3: 64149676 | BQ3: 1190.779 | BR3: 0 | BS3: 0 | BT3: 1200 | BU3: 1165.49 | BV3: UNKNOWN | BW3: 5458816 | BX3: 1193.764 | BY3: 0 | BZ3: 0 | CA3: 666.41 | CB3: 625.06 | CC3: SATISFIABLE | CD3: 8917626 | CE3: 656.77 | CF3: 625 | CG3: 0 | CH3: 873.08 | CI3: 770.85 | CJ3: SATISFIABLE | CK3: 38566021 | CL3: 863.52 | CM3: 770.73 | CN3: 0 | CO3: 1200 | CP3: 964.16 | CQ3: UNKNOWN | CR3: 88871796 | CS3: 1189.69 | CT3: 0 | CU3: 0 | CV3: 48.72 | CW3: 6.45 | CX3: UNSATISFIABLE | CY3: 6622515 | CZ3: 39.685 | DA3: 0 | DB3: 0 | DC3: 236.49 | DD3: 186.2 | DE3: SATISFIABLE | DF3: 11167746 | DG3: 225.684 | DH3: 186.13 | DI3: 0 | DJ3: 462.87 | DK3: 332.94 | DL3: SATISFIABLE | DM3: 49199866 | DN3: 452.369 | DO3: 332.8 | DP3: 0 | DQ3: 1200 | DR3: 761.31 | DS3: UNKNOWN | DT3: 116384766 | DU3: 1193.501 | DV3: 0 | DW3: 0 | DX3: 37.63 | DY3: 0 | DZ3: UNSATISFIABLE | EA3: 15365214 | EB3: 27.927 | EC3: 0 | ED3: 0 | EE3: 150.04 | EF3: 90.5 | EG3: SATISFIABLE | EH3: 13334966 | EI3: 139.436 | EJ3: 90.43 | EK3: 0 | EL3: 246.66 | EM3: 31.2 | EN3: SATISFIABLE | EO3: 60266186 | EP3: 234.666 | EQ3: 31.06 | ER3: 0 | ES3: 971.65 | ET3: 459.01 | EU3: SATISFIABLE | EV3: 146223336 | EW3: 960.002 | EX3: 458.57 | EY3: 0 | EZ3: 48.78 | FA3: 0 | FB3: UNSATISFIABLE | FC3: 17544044 | FD3: 38.96 | FE3: 0 | FF3: 0 | FG3: 88.83 | FH3: 3.2 | FI3: SATISFIABLE | FJ3: 15354036 | FK3: 77.767 | FL3: 3.1 | FM3: 0 | FN3: 232.76 | FO3: 4.58 | FP3: SATISFIABLE | FQ3: 71520356 | FR3: 221.363 | FS3: 4.44 | FT3: 0 | FU3: 714.32 | FV3: 54.58 | FW3: SATISFIABLE | FX3: 177942881 | FY3: 700.974 | FZ3: 54.32 | GA3: 0 | GB3: 54.43 | GC3: 0 | GD3: UNSATISFIABLE | GE3: 19832224 | GF3: 44.51 | GG3: 0 | GH3: 0 | GI3: 102.62 | GJ3: 3.03 | GK3: SATISFIABLE | GL3: 17180331 | GM3: 90.879 | GN3: 2.9 | GO3: 0 | GP3: 844.04 | GQ3: 816.73 | GR3: SATISFIABLE | GS3: 2529416 | GT3: 837.106 | GU3: 816.66 | GV3: 0 | GW3: 800.98 | GX3: 773.94 | GY3: SATISFIABLE | GZ3: 2529416 | HA3: 793.574 | HB3: 773.89 | HC3: 0 | HD3: 475.37 | HE3: 447.01 | HF3: UNSATISFIABLE | HG3: 2529416 | HH3: 467.248 | HI3: 0 | HJ3: 0 | HK3: 833.89 | HL3: 809.55 | HM3: SATISFIABLE | HN3: 2529416 | HO3: 826.505 | HP3: 809.48 | HQ3: 0 | HR3: 290.98 | HS3: 257.84 | HT3: SATISFIABLE | HU3: 3467646 | HV3: 282.968 | HW3: 257.74 | HX3: 0 | HY3: 364.04 | HZ3: 328.42 | IA3: SATISFIABLE | IB3: 3467646 | IC3: 355.324 | ID3: 328.32 | IE3: 0 | IF3: 1200 | IG3: 1168.54 | IH3: UNKNOWN | II3: 3467646 | IJ3: 1192.908 | IK3: 0 | IL3: 0 | IM3: 604.15 | IN3: 570.93 | IO3: SATISFIABLE | IP3: 3467646 | IQ3: 595.737 | IR3: 570.84 | IS3: 0 | IT3: 523.13 | IU3: 483.07 | IV3: SATISFIABLE | IW3: 4479301 | IX3: 514.833 | IY3: 482.94 | IZ3: 0 | JA3: 251.65 | JB3: 208.29 | JC3: SATISFIABLE | JD3: 4479301 | JE3: 243.137 | JF3: 208.2 | JG3: 0 | JH3: 250.94 | JI3: 205.9 | JJ3: UNSATISFIABLE | JK3: 4479301 | JL3: 241.638 | JM3: 0 | JN3: 0 | JO3: 224.1 | JP3: 179.59 | JQ3: SATISFIABLE | JR3: 4479301 | JS3: 214.856 | JT3: 179.46 | JU3: 0 | JV3: 164.68 | JW3: 118.19 | JX3: SATISFIABLE | JY3: 5564381 | JZ3: 156.518 | KA3: 118.08 | KB3: 0 | KC3: 292.17 | KD3: 246.48 | KE3: SATISFIABLE | KF3: 5564381 | KG3: 283.545 | KH3: 246.33 | KI3: 0 | KJ3: 52 | KK3: 2.13 | KL3: UNSATISFIABLE | KM3: 5564381 | KN3: 43.025 | KO3: 0 | KP3: 0 | KQ3: 1028.5 | KR3: 984.74 | KS3: SATISFIABLE | KT3: 5564381 | KU3: 1020.798 | KV3: 984.58 | KW3: 0 | KX3: 695.38 | KY3: 642.62 | KZ3: SATISFIABLE | LA3: 6722886 | LB3: 686.966 | LC3: 642.47 | LD3: 0 | LE3: 98.91 | LF3: 46.38 | LG3: SATISFIABLE | LH3: 6722886 | LI3: 88.026 | LJ3: 46.25 | LK3: 0 | LL3: 56.7 | LM3: 0 | LN3: UNSATISFIABLE | LO3: 13445772 | LP3: 47.302 | LQ3: 0 | LR3: 0 | LS3: 114.4 | LT3: 55.08 | LU3: SATISFIABLE | LV3: 6722886 | LW3: 105.139 | LX3: 54.9 | LY3: 0 | LZ3: 187.37 | MA3: 123.92 | MB3: SATISFIABLE | MC3: 7954816 | MD3: 174.768 | ME3: 123.78 | MF3: 0 | MG3: 211.59 | MH3: 149.21 | MI3: SATISFIABLE | MJ3: 7954816 | MK3: 200.13 | ML3: 149.05 | MM3: 0 | MN3: 62.66 | MO3: 0 | MP3: UNSATISFIABLE | MQ3: 15909632 | MR3: 49.292 | MS3: 0 | MT3: 0 | MU3: 82.63 | MV3: 16.48 | MW3: SATISFIABLE | MX3: 7954816 | MY3: 69.277 | MZ3: 16.35 | NA3: 0 | NB3: 131.71 | NC3: 54.36 | ND3: SATISFIABLE | NE3: 9260171 | NF3: 117.605 | NG3: 54.17 | NH3: 0 | NI3: 408.72 | NJ3: 331.53 | NK3: SATISFIABLE | NL3: 9260171 | NM3: 394.694 | NN3: 331.33 | NO3: 0 | NP3: 73.44 | NQ3: 0 | NR3: UNSATISFIABLE | NS3: 18520342 | NT3: 60.318 | NU3: 0 | NV3: 0 | NW3: 156.04 | NX3: 78.08 | NY3: SATISFIABLE | NZ3: 9260171 | OA3: 144.871 | OB3: 77.91 | OC3: 0 | OD3: 95.37 | OE3: 67.1 | OF3: SATISFIABLE | OG3: 2529416 | OH3: 87.385 | OI3: 67.02 | OJ3: 0 | OK3: 95.34 | OL3: 67.1 | OM3: SATISFIABLE | ON3: 2529416 | OO3: 87.296 | OP3: 67.03 | OQ3: 0 | OR3: 93.72 | OS3: 69.16 | OT3: UNSATISFIABLE | OU3: 2529416 | OV3: 85.194 | OW3: 0 | OX3: 0 | OY3: 83.5 | OZ3: 57.75 | PA3: SATISFIABLE | PB3: 2529416 | PC3: 76.02 | PD3: 57.69 | PE3: 0 | PF3: 52.13 | PG3: 20.21 | PH3: SATISFIABLE | PI3: 3467646 | PJ3: 43.977 | PK3: 20.12 | PL3: 0 | PM3: 55.22 | PN3: 19.62 | PO3: SATISFIABLE | PP3: 3467646 | PQ3: 46.938 | PR3: 19.52 | PS3: 0 | PT3: 513.72 | PU3: 478.78 | PV3: UNSATISFIABLE | PW3: 3467646 | PX3: 505.792 | PY3: 0 | PZ3: 0 | QA3: 57.57 | QB3: 25.64 | QC3: SATISFIABLE | QD3: 3467646 | QE3: 49.289 | QF3: 25.55 | QG3: 0 | QH3: 59.94 | QI3: 19.32 | QJ3: SATISFIABLE | QK3: 4479301 | QL3: 50.466 | QM3: 19.2 | QN3: 0 | QO3: 66.29 | QP3: 21.45 | QQ3: SATISFIABLE | QR3: 4479301 | QS3: 57.286 | QT3: 21.32 | QU3: 0 | QV3: 521.08 | QW3: 475.91 | QX3: UNSATISFIABLE | QY3: 4479301 | QZ3: 511.944 | RA3: 0 | RB3: 0 | RC3: 94.57 | RD3: 50 | RE3: SATISFIABLE | RF3: 4479301 | RG3: 85.965 | RH3: 49.88 | RI3: 0 | RJ3: 114.52 | RK3: 65.61 | RL3: SATISFIABLE | RM3: 5564381 | RN3: 105.964 | RO3: 65.5 | RP3: 0 | RQ3: 111.86 | RR3: 58.49 | RS3: SATISFIABLE | RT3: 5564381 | RU3: 103.033 | RV3: 58.4 | RW3: 0 | RX3: 50.34 | RY3: 1.64 | RZ3: UNSATISFIABLE | SA3: 5564381 | SB3: 41.688 | SC3: 0 | SD3: 0 | SE3: 278.54 | SF3: 224.52 | SG3: SATISFIABLE | SH3: 5564381 | SI3: 269.832 | SJ3: 224.41 | SK3: 0 | SL3: 86.25 | SM3: 20.61 | SN3: SATISFIABLE | SO3: 6722886 | SP3: 75.984 | SQ3: 20.44 | SR3: 0 | SS3: 72.03 | ST3: 16.42 | SU3: SATISFIABLE | SV3: 6722886 | SW3: 62.747 | SX3: 16.3 | SY3: 0 | SZ3: 60.87 | TA3: 0 | TB3: UNSATISFIABLE | TC3: 6722886 | TD3: 50.359 | TE3: 0 | TF3: 0 | TG3: 82.82 | TH3: 16.24 | TI3: SATISFIABLE | TJ3: 6722886 | TK3: 72.401 | TL3: 16.07 | TM3: 0 | TN3: 77.31 | TO3: 12.5 | TP3: SATISFIABLE | TQ3: 7954816 | TR3: 65.264 | TS3: 12.37 | TT3: 0 | TU3: 77.27 | TV3: 12.48 | TW3: SATISFIABLE | TX3: 7954816 | TY3: 65.222 | TZ3: 12.35 | UA3: 0 | UB3: 62.55 | UC3: 0 | UD3: UNSATISFIABLE | UE3: 7954816 | UF3: 51.02 | UG3: 0 | UH3: 0 | UI3: 69.81 | UJ3: 5.27 | UK3: SATISFIABLE | UL3: 7954816 | UM3: 58.49 | UN3: 5.13 | UO3: 0 | UP3: 91 | UQ3: 13.43 | UR3: SATISFIABLE | US3: 9260171 | UT3: 80.226 | UU3: 13.27 | UV3: 0 | UW3: 90.61 | UX3: 13.44 | UY3: SATISFIABLE | UZ3: 9260171 | VA3: 79.889 | VB3: 13.29 | VC3: 0 | VD3: 77.07 | VE3: 0 | VF3: UNSATISFIABLE | VG3: 9260171 | VH3: 63.277 | VI3: 0 | VJ3: 0 | VK3: 92.4 | VL3: 13.68 | VM3: SATISFIABLE | VN3: 9260171 | VO3: 80.166 | VP3: 13.52 | VQ3: 0 | VR3: =MIN($B3,$I3,$P3,$W3,$AD3,$AK3,$AR3,$AY3,$BF3,$BM3,$BT3,$CA3,$CH3,$CO3,$CV3,$DC3,$DJ3,$DQ3,$DX3,$EE3,$EL3,$ES3,$EZ3,$FG3,$FN3,$FU3,$GB3,$GI3,$GP3,$GW3,$HD3,$HK3,$HR3,$HY3,$IF3,$IM3,$IT3,$JA3,$JH3,$JO3,$JV3,$KC3,$KJ3,$KQ3,$KX3,$LE3,$LL3,$LS3,$LZ3,$MG3,$MN3,$MU3,$NB3,$NI3,$NP3,$NW3,$OD3,$OK3,$OR3,$OY3,$PF3,$PM3,$PT3,$QA3,$QH3,$QO3,$QV3,$RC3,$RJ3,$RQ3,$RX3,$SE3,$SL3,$SS3,$SZ3,$TG3,$TN3,$TU3,$UB3,$UI3,$UP3,$UW3,$VD3,$VK3) -> 0 | VS3: =MIN($C3,$J3,$Q3,$X3,$AE3,$AL3,$AS3,$AZ3,$BG3,$BN3,$BU3,$CB3,$CI3,$CP3,$CW3,$DD3,$DK3,$DR3,$DY3,$EF3,$EM3,$ET3,$FA3,$FH3,$FO3,$FV3,$GC3,$GJ3,$GQ3,$GX3,$HE3,$HL3,$HS3,$HZ3,$IG3,$IN3,$IU3,$JB3,$JI3,$JP3,$JW3,$KD3,$KK3,$KR3,$KY3,$LF3,$LM3,$LT3,$MA3,$MH3,$MO3,$MV3,$NC3,$NJ3,$NQ3,$NX3,$OE3,$OL3,$OS3,$OZ3,$PG3,$PN3,$PU3,$QB3,$QI3,$QP3,$QW3,$RD3,$RK3,$RR3,$RY3,$SF3,$SM3,$ST3,$TA3,$TH3,$TO3,$TV3,$UC3,$UJ3,$UQ3,$UX3,$VE3,$VL3) -> 0 | VT3: =MIN($E3,$L3,$S3,$Z3,$AG3,$AN3,$AU3,$BB3,$BI3,$BP3,$BW3,$CD3,$CK3,$CR3,$CY3,$DF3,$DM3,$DT3,$EA3,$EH3,$EO3,$EV3,$FC3,$FJ3,$FQ3,$FX3,$GE3,$GL3,$GS3,$GZ3,$HG3,$HN3,$HU3,$IB3,$II3,$IP3,$IW3,$JD3,$JK3,$JR3,$JY3,$KF3,$KM3,$KT3,$LA3,$LH3,$LO3,$LV3,$MC3,$MJ3,$MQ3,$MX3,$NE3,$NL3,$NS3,$NZ3,$OG3,$ON3,$OU3,$PB3,$PI3,$PP3,$PW3,$QD3,$QK3,$QR3,$QY3,$RF3,$RM3,$RT3,$SA3,$SH3,$SO3,$SV3,$TC3,$TJ3,$TQ3,$TX3,$UE3,$UL3,$US3,$UZ3,$VG3,$VN3) -> 0 | VU3: =MIN($F3,$M3,$T3,$AA3,$AH3,$AO3,$AV3,$BC3,$BJ3,$BQ3,$BX3,$CE3,$CL3,$CS3,$CZ3,$DG3,$DN3,$DU3,$EB3,$EI3,$EP3,$EW3,$FD3,$FK3,$FR3,$FY3,$GF3,$GM3,$GT3,$HA3,$HH3,$HO3,$HV3,$IC3,$IJ3,$IQ3,$IX3,$JE3,$JL3,$JS3,$JZ3,$KG3,$KN3,$KU3,$LB3,$LI3,$LP3,$LW3,$MD3,$MK3,$MR3,$MY3,$NF3,$NM3,$NT3,$OA3,$OH3,$OO3,$OV3,$PC3,$PJ3,$PQ3,$PX3,$QE3,$QL3,$QS3,$QZ3,$RG3,$RN3,$RU3,$SB3,$SI3,$SP3,$SW3,$TD3,$TK3,$TR3,$TY3,$UF3,$UM3,$UT3,$VA3,$VH3,$VO3) -> 0 | VV3: =MIN($G3,$N3,$U3,$AB3,$AI3,$AP3,$AW3,$BD3,$BK3,$BR3,$BY3,$CF3,$CM3,$CT3,$DA3,$DH3,$DO3,$DV3,$EC3,$EJ3,$EQ3,$EX3,$FE3,$FL3,$FS3,$FZ3,$GG3,$GN3,$GU3,$HB3,$HI3,$HP3,$HW3,$ID3,$IK3,$IR3,$IY3,$JF3,$JM3,$JT3,$KA3,$KH3,$KO3,$KV3,$LC3,$LJ3,$LQ3,$LX3,$ME3,$ML3,$MS3,$MZ3,$NG3,$NN3,$NU3,$OB3,$OI3,$OP3,$OW3,$PD3,$PK3,$PR3,$PY3,$QF3,$QM3,$QT3,$RA3,$RH3,$RO3,$RV3,$SC3,$SJ3,$SQ3,$SX3,$TE3,$TL3,$TS3,$TZ3,$UG3,$UN3,$UU3,$VB3,$VI3,$VP3) -> 0 | VW3: =MIN($H3,$O3,$V3,$AC3,$AJ3,$AQ3,$AX3,$BE3,$BL3,$BS3,$BZ3,$CG3,$CN3,$CU3,$DB3,$DI3,$DP3,$DW3,$ED3,$EK3,$ER3,$EY3,$FF3,$FM3,$FT3,$GA3,$GH3,$GO3,$GV3,$HC3,$HJ3,$HQ3,$HX3,$IE3,$IL3,$IS3,$IZ3,$JG3,$JN3,$JU3,$KB3,$KI3,$KP3,$KW3,$LD3,$LK3,$LR3,$LY3,$MF3,$MM3,$MT3,$NA3,$NH3,$NO3,$NV3,$OC3,$OJ3,$OQ3,$OX3,$PE3,$PL3,$PS3,$PZ3,$QG3,$QN3,$QU3,$RB3,$RI3,$RP3,$RW3,$SD3,$SK3,$SR3,$SY3,$TF3,$TM3,$TT3,$UA3,$UH3,$UO3,$UV3,$VC3,$VJ3,$VQ3) -> 0 | VX3: =MEDIAN($B3,$I3,$P3,$W3,$AD3,$AK3,$AR3,$AY3,$BF3,$BM3,$BT3,$CA3,$CH3,$CO3,$CV3,$DC3,$DJ3,$DQ3,$DX3,$EE3,$EL3,$ES3,$EZ3,$FG3,$FN3,$FU3,$GB3,$GI3,$GP3,$GW3,$HD3,$HK3,$HR3,$HY3,$IF3,$IM3,$IT3,$JA3,$JH3,$JO3,$JV3,$KC3,$KJ3,$KQ3,$KX3,$LE3,$LL3,$LS3,$LZ3,$MG3,$MN3,$MU3,$NB3,$NI3,$NP3,$NW3,$OD3,$OK3,$OR3,$OY3,$PF3,$PM3,$PT3,$QA3,$QH3,$QO3,$QV3,$RC3,$RJ3,$RQ3,$RX3,$SE3,$SL3,$SS3,$SZ3,$TG3,$TN3,$TU3,$UB3,$UI3,$UP3,$UW3,$VD3,$VK3) -> 0 | VY3: =MEDIAN($C3,$J3,$Q3,$X3,$AE3,$AL3,$AS3,$AZ3,$BG3,$BN3,$BU3,$CB3,$CI3,$CP3,$CW3,$DD3,$DK3,$DR3,$DY3,$EF3,$EM3,$ET3,$FA3,$FH3,$FO3,$FV3,$GC3,$GJ3,$GQ3,$GX3,$HE3,$HL3,$HS3,$HZ3,$IG3,$IN3,$IU3,$JB3,$JI3,$JP3,$JW3,$KD3,$KK3,$KR3,$KY3,$LF3,$LM3,$LT3,$MA3,$MH3,$MO3,$MV3,$NC3,$NJ3,$NQ3,$NX3,$OE3,$OL3,$OS3,$OZ3,$PG3,$PN3,$PU3,$QB3,$QI3,$QP3,$QW3,$RD3,$RK3,$RR3,$RY3,$SF3,$SM3,$ST3,$TA3,$TH3,$TO3,$TV3,$UC3,$UJ3,$UQ3,$UX3,$VE3,$VL3) -> 0 | VZ3: =MEDIAN($E3,$L3,$S3,$Z3,$AG3,$AN3,$AU3,$BB3,$BI3,$BP3,$BW3,$CD3,$CK3,$CR3,$CY3,$DF3,$DM3,$DT3,$EA3,$EH3,$EO3,$EV3,$FC3,$FJ3,$FQ3,$FX3,$GE3,$GL3,$GS3,$GZ3,$HG3,$HN3,$HU3,$IB3,$II3,$IP3,$IW3,$JD3,$JK3,$JR3,$JY3,$KF3,$KM3,$KT3,$LA3,$LH3,$LO3,$LV3,$MC3,$MJ3,$MQ3,$MX3,$NE3,$NL3,$NS3,$NZ3,$OG3,$ON3,$OU3,$PB3,$PI3,$PP3,$PW3,$QD3,$QK3,$QR3,$QY3,$RF3,$RM3,$RT3,$SA3,$SH3,$SO3,$SV3,$TC3,$TJ3,$TQ3,$TX3,$UE3,$UL3,$US3,$UZ3,$VG3,$VN3) -> 0 | WA3: =MEDIAN($F3,$M3,$T3,$AA3,$AH3,$AO3,$AV3,$BC3,$BJ3,$BQ3,$BX3,$CE3,$CL3,$CS3,$CZ3,$DG3,$DN3,$DU3,$EB3,$EI3,$EP3,$EW3,$FD3,$FK3,$FR3,$FY3,$GF3,$GM3,$GT3,$HA3,$HH3,$HO3,$HV3,$IC3,$IJ3,$IQ3,$IX3,$JE3,$JL3,$JS3,$JZ3,$KG3,$KN3,$KU3,$LB3,$LI3,$LP3,$LW3,$MD3,$MK3,$MR3,$MY3,$NF3,$NM3,$NT3,$OA3,$OH3,$OO3,$OV3,$PC3,$PJ3,$PQ3,$PX3,$QE3,$QL3,$QS3,$QZ3,$RG3,$RN3,$RU3,$SB3,$SI3,$SP3,$SW3,$TD3,$TK3,$TR3,$TY3,$UF3,$UM3,$UT3,$VA3,$VH3,$VO3) -> 0 | WB3: =MEDIAN($G3,$N3,$U3,$AB3,$AI3,$AP3,$AW3,$BD3,$BK3,$BR3,$BY3,$CF3,$CM3,$CT3,$DA3,$DH3,$DO3,$DV3,$EC3,$EJ3,$EQ3,$EX3,$FE3,$FL3,$FS3,$FZ3,$GG3,$GN3,$GU3,$HB3,$HI3,$HP3,$HW3,$ID3,$IK3,$IR3,$IY3,$JF3,$JM3,$JT3,$KA3,$KH3,$KO3,$KV3,$LC3,$LJ3,$LQ3,$LX3,$ME3,$ML3,$MS3,$MZ3,$NG3,$NN3,$NU3,$OB3,$OI3,$OP3,$OW3,$PD3,$PK3,$PR3,$PY3,$QF3,$QM3,$QT3,$RA3,$RH3,$RO3,$RV3,$SC3,$SJ3,$SQ3,$SX3,$TE3,$TL3,$TS3,$TZ3,$UG3,$UN3,$UU3,$VB3,$VI3,$VP3) -> 0 | WC3: =MEDIAN($H3,$O3,$V3,$AC3,$AJ3,$AQ3,$AX3,$BE3,$BL3,$BS3,$BZ3,$CG3,$CN3,$CU3,$DB3,$DI3,$DP3,$DW3,$ED3,$EK3,$ER3,$EY3,$FF3,$FM3,$FT3,$GA3,$GH3,$GO3,$GV3,$HC3,$HJ3,$HQ3,$HX3,$IE3,$IL3,$IS3,$IZ3,$JG3,$JN3,$JU3,$KB3,$KI3,$KP3,$KW3,$LD3,$LK3,$LR3,$LY3,$MF3,$MM3,$MT3,$NA3,$NH3,$NO3,$NV3,$OC3,$OJ3,$OQ3,$OX3,$PE3,$PL3,$PS3,$PZ3,$QG3,$QN3,$QU3,$RB3,$RI3,$RP3,$RW3,$SD3,$SK3,$SR3,$SY3,$TF3,$TM3,$TT3,$UA3,$UH3,$UO3,$UV3,$VC3,$VJ3,$VQ3) -> 0 | WD3: =MAX($B3,$I3,$P3,$W3,$AD3,$AK3,$AR3,$AY3,$BF3,$BM3,$BT3,$CA3,$CH3,$CO3,$CV3,$DC3,$DJ3,$DQ3,$DX3,$EE3,$EL3,$ES3,$EZ3,$FG3,$FN3,$FU3,$GB3,$GI3,$GP3,$GW3,$HD3,$HK3,$HR3,$HY3,$IF3,$IM3,$IT3,$JA3,$JH3,$JO3,$JV3,$KC3,$KJ3,$KQ3,$KX3,$LE3,$LL3,$LS3,$LZ3,$MG3,$MN3,$MU3,$NB3,$NI3,$NP3,$NW3,$OD3,$OK3,$OR3,$OY3,$PF3,$PM3,$PT3,$QA3,$QH3,$QO3,$QV3,$RC3,$RJ3,$RQ3,$RX3,$SE3,$SL3,$SS3,$SZ3,$TG3,$TN3,$TU3,$UB3,$UI3,$UP3,$UW3,$VD3,$VK3) -> 0 | WE3: =MAX($C3,$J3,$Q3,$X3,$AE3,$AL3,$AS3,$AZ3,$BG3,$BN3,$BU3,$CB3,$CI3,$CP3,$CW3,$DD3,$DK3,$DR3,$DY3,$EF3,$EM3,$ET3,$FA3,$FH3,$FO3,$FV3,$GC3,$GJ3,$GQ3,$GX3,$HE3,$HL3,$HS3,$HZ3,$IG3,$IN3,$IU3,$JB3,$JI3,$JP3,$JW3,$KD3,$KK3,$KR3,$KY3,$LF3,$LM3,$LT3,$MA3,$MH3,$MO3,$MV3,$NC3,$NJ3,$NQ3,$NX3,$OE3,$OL3,$OS3,$OZ3,$PG3,$PN3,$PU3,$QB3,$QI3,$QP3,$QW3,$RD3,$RK3,$RR3,$RY3,$SF3,$SM3,$ST3,$TA3,$TH3,$TO3,$TV3,$UC3,$UJ3,$UQ3,$UX3,$VE3,$VL3) -> 0 | WF3: =MAX($E3,$L3,$S3,$Z3,$AG3,$AN3,$AU3,$BB3,$BI3,$BP3,$BW3,$CD3,$CK3,$CR3,$CY3,$DF3,$DM3,$DT3,$EA3,$EH3,$EO3,$EV3,$FC3,$FJ3,$FQ3,$FX3,$GE3,$GL3,$GS3,$GZ3,$HG3,$HN3,$HU3,$IB3,$II3,$IP3,$IW3,$JD3,$JK3,$JR3,$JY3,$KF3,$KM3,$KT3,$LA3,$LH3,$LO3,$LV3,$MC3,$MJ3,$MQ3,$MX3,$NE3,$NL3,$NS3,$NZ3,$OG3,$ON3,$OU3,$PB3,$PI3,$PP3,$PW3,$QD3,$QK3,$QR3,$QY3,$RF3,$RM3,$RT3,$SA3,$SH3,$SO3,$SV3,$TC3,$TJ3,$TQ3,$TX3,$UE3,$UL3,$US3,$UZ3,$VG3,$VN3) -> 0 | WG3: =MAX($F3,$M3,$T3,$AA3,$AH3,$AO3,$AV3,$BC3,$BJ3,$BQ3,$BX3,$CE3,$CL3,$CS3,$CZ3,$DG3,$DN3,$DU3,$EB3,$EI3,$EP3,$EW3,$FD3,$FK3,$FR3,$FY3,$GF3,$GM3,$GT3,$HA3,$HH3,$HO3,$HV3,$IC3,$IJ3,$IQ3,$IX3,$JE3,$JL3,$JS3,$JZ3,$KG3,$KN3,$KU3,$LB3,$LI3,$LP3,$LW3,$MD3,$MK3,$MR3,$MY3,$NF3,$NM3,$NT3,$OA3,$OH3,$OO3,$OV3,$PC3,$PJ3,$PQ3,$PX3,$QE3,$QL3,$QS3,$QZ3,$RG3,$RN3,$RU3,$SB3,$SI3,$SP3,$SW3,$TD3,$TK3,$TR3,$TY3,$UF3,$UM3,$UT3,$VA3,$VH3,$VO3) -> 0 | WH3: =MAX($G3,$N3,$U3,$AB3,$AI3,$AP3,$AW3,$BD3,$BK3,$BR3,$BY3,$CF3,$CM3,$CT3,$DA3,$DH3,$DO3,$DV3,$EC3,$EJ3,$EQ3,$EX3,$FE3,$FL3,$FS3,$FZ3,$GG3,$GN3,$GU3,$HB3,$HI3,$HP3,$HW3,$ID3,$IK3,$IR3,$IY3,$JF3,$JM3,$JT3,$KA3,$KH3,$KO3,$KV3,$LC3,$LJ3,$LQ3,$LX3,$ME3,$ML3,$MS3,$MZ3,$NG3,$NN3,$NU3,$OB3,$OI3,$OP3,$OW3,$PD3,$PK3,$PR3,$PY3,$QF3,$QM3,$QT3,$RA3,$RH3,$RO3,$RV3,$SC3,$SJ3,$SQ3,$SX3,$TE3,$TL3,$TS3,$TZ3,$UG3,$UN3,$UU3,$VB3,$VI3,$VP3) -> 0 | WI3: =MAX($H3,$O3,$V3,$AC3,$AJ3,$AQ3,$AX3,$BE3,$BL3,$BS3,$BZ3,$CG3,$CN3,$CU3,$DB3,$DI3,$DP3,$DW3,$ED3,$EK3,$ER3,$EY3,$FF3,$FM3,$FT3,$GA3,$GH3,$GO3,$GV3,$HC3,$HJ3,$HQ3,$HX3,$IE3,$IL3,$IS3,$IZ3,$JG3,$JN3,$JU3,$KB3,$KI3,$KP3,$KW3,$LD3,$LK3,$LR3,$LY3,$MF3,$MM3,$MT3,$NA3,$NH3,$NO3,$NV3,$OC3,$OJ3,$OQ3,$OX3,$PE3,$PL3,$PS3,$PZ3,$QG3,$QN3,$QU3,$RB3,$RI3,$RP3,$RW3,$SD3,$SK3,$SR3,$SY3,$TF3,$TM3,$TT3,$UA3,$UH3,$UO3,$UV3,$VC3,$VJ3,$VQ3) -> 0
A4: instances/room_x8_y8_a3 | B4: 49.38 | C4: 0.76 | D4: SATISFIABLE | E4: 12688878 | F4: 41.389 | G4: 0.72 | H4: 0 | I4: 312.86 | J4: 243.42 | K4: SATISFIABLE | L4: 25716028 | M4: 305.357 | N4: 243.34 | O4: 0 | P4: 26.58 | Q4: 0.95 | R4: SATISFIABLE | S4: 3766468 | T4: 19.688 | U4: 0.92 | V4: 0 | W4: 45.88 | X4: 16.81 | Y4: SATISFIABLE | Z4: 5206728 | AA4: 37.788 | AB4: 16.78 | AC4: 0 | AD4: 91.8 | AE4: 15.52 | AF4: SATISFIABLE | AG4: 20582163 | AH4: 82.569 | AI4: 15.43 | AJ4: 0 | AK4: 159.16 | AL4: 9.62 | AM4: SATISFIABLE | AN4: 43609063 | AO4: 149.825 | AP4: 9.52 | AQ4: 0 | AR4: 31.56 | AS4: 0.5 | AT4: SATISFIABLE | AU4: 5178103 | AV4: 24.063 | AW4: 0.46 | AX4: 0 | AY4: 49.67 | AZ4: 4.87 | BA4: SATISFIABLE | BB4: 7575263 | BC4: 41.053 | BD4: 4.81 | BE4: 0 | BF4: 95.46 | BG4: 9.92 | BH4: SATISFIABLE | BI4: 29776348 | BJ4: 84.747 | BK4: 9.84 | BL4: 0 | BM4: 175.46 | BN4: 3.07 | BO4: SATISFIABLE | BP4: 65296123 | BQ4: 163.922 | BR4: 2.99 | BS4: 0 | BT4: 89.68 | BU4: 39.5 | BV4: SATISFIABLE | BW4: 6605263 | BX4: 79.998 | BY4: 39.42 | BZ4: 0 | CA4: 51.75 | CB4: 4.01 | CC4: SATISFIABLE | CD4: 10064073 | CE4: 41.589 | CF4: 3.96 | CG4: 0 | CH4: 132.79 | CI4: 21.06 | CJ4: SATISFIABLE | CK4: 39964933 | CL4: 121.534 | CM4: 20.98 | CN4: 0 | CO4: 609.38 | CP4: 362.55 | CQ4: SATISFIABLE | CR4: 90270708 | CS4: 597.004 | CT4: 362.37 | CU4: 0 | CV4: 58.87 | CW4: 5.21 | CX4: SATISFIABLE | CY4: 8021427 | CZ4: 47.023 | DA4: 5.14 | DB4: 0 | DC4: 70.6 | DD4: 11.92 | DE4: SATISFIABLE | DF4: 12566658 | DG4: 59.806 | DH4: 11.84 | DI4: 0 | DJ4: 167.36 | DK4: 25.56 | DL4: SATISFIABLE | DM4: 50862043 | DN4: 156.351 | DO4: 25.45 | DP4: 0 | DQ4: 683.44 | DR4: 241.56 | DS4: SATISFIABLE | DT4: 118046943 | DU4: 671.512 | DV4: 241.25 | DW4: 0 | DX4: 48.57 | DY4: 0 | DZ4: UNSATISFIABLE | EA4: 18660360 | EB4: 37.405 | EC4: 0 | ED4: 0 | EE4: 96.51 | EF4: 23.93 | EG4: SATISFIABLE | EH4: 14997143 | EI4: 83.764 | EJ4: 23.83 | EK4: 0 | EL4: 313 | EM4: 94.7 | EN4: SATISFIABLE | EO4: 62202428 | EP4: 300.345 | EQ4: 94.51 | ER4: 0 | ES4: 660.11 | ET4: 138.14 | EU4: SATISFIABLE | EV4: 148159578 | EW4: 647.491 | EX4: 137.87 | EY4: 0 | EZ4: 60.76 | FA4: 0 | FB4: UNSATISFIABLE | FC4: 21346280 | FD4: 49.654 | FE4: 0 | FF4: 0 | FG4: 150.03 | FH4: 46.8 | FI4: SATISFIABLE | FJ4: 17290278 | FK4: 137.408 | FL4: 46.67 | FM4: 0 | FN4: 336.39 | FO4: 87.62 | FP4: SATISFIABLE | FQ4: 73741463 | FR4: 323.316 | FS4: 87.44 | FT4: 0 | FU4: 1200 | FV4: 570.3 | FW4: UNKNOWN | FX4: 180163988 | FY4: 1193.365 | FZ4: 0 | GA4: 0 | GB4: 65.54 | GC4: 0 | GD4: UNSATISFIABLE | GE4: 24157750 | GF4: 53.986 | GG4: 0 | GH4: 0 | GI4: 170.95 | GJ4: 52.57 | GK4: SATISFIABLE | GL4: 19401438 | GM4: 157.621 | GN4: 52.43 | GO4: 0 | GP4: 34.36 | GQ4: 0.56 | GR4: SATISFIABLE | GS4: 3203441 | GT4: 26.108 | GU4: 0.45 | GV4: 0 | GW4: 36.24 | GX4: 2.84 | GY4: SATISFIABLE | GZ4: 3203441 | HA4: 27.636 | HB4: 2.76 | HC4: 0 | HD4: 36.22 | HE4: 2.51 | HF4: SATISFIABLE | HG4: 3203441 | HH4: 28.046 | HI4: 2.42 | HJ4: 0 | HK4: 36.21 | HL4: 0.55 | HM4: SATISFIABLE | HN4: 3203441 | HO4: 26.17 | HP4: 0.44 | HQ4: 0 | HR4: 60.65 | HS4: 19.71 | HT4: SATISFIABLE | HU4: 4372536 | HV4: 51.652 | HW4: 19.6 | HX4: 0 | HY4: 45.2 | HZ4: 2.71 | IA4: SATISFIABLE | IB4: 4372536 | IC4: 36.398 | ID4: 2.59 | IE4: 0 | IF4: 46.2 | IG4: 6.43 | IH4: SATISFIABLE | II4: 4372536 | IJ4: 37.562 | IK4: 6.32 | IL4: 0 | IM4: 55.22 | IN4: 14.88 | IO4: SATISFIABLE | IP4: 4372536 | IQ4: 46.463 | IR4: 14.78 | IS4: 0 | IT4: 82.41 | IU4: 36.85 | IV4: SATISFIABLE | IW4: 5625856 | IX4: 72.953 | IY4: 36.7 | IZ4: 0 | JA4: 137.8 | JB4: 85.57 | JC4: SATISFIABLE | JD4: 5625856 | JE4: 128.198 | JF4: 85.43 | JG4: 0 | JH4: 59.95 | JI4: 6.36 | JJ4: SATISFIABLE | JK4: 5625856 | JL4: 50.306 | JM4: 6.22 | JN4: 0 | JO4: 58.41 | JP4: 4.88 | JQ4: SATISFIABLE | JR4: 5625856 | JS4: 48.204 | JT4: 4.72 | JU4: 0 | JV4: 78.83 | JW4: 21.77 | JX4: SATISFIABLE | JY4: 6963401 | JZ4: 69.258 | KA4: 21.64 | KB4: 0 | KC4: 71.89 | KD4: 15.65 | KE4: SATISFIABLE | KF4: 6963401 | KG4: 62.276 | KH4: 15.53 | KI4: 0 | KJ4: 64.09 | KK4: 5.91 | KL4: SATISFIABLE | KM4: 6963401 | KN4: 55.089 | KO4: 5.77 | KP4: 0 | KQ4: 81.89 | KR4: 24.86 | KS4: SATISFIABLE | KT4: 6963401 | KU4: 72.751 | KV4: 24.73 | KW4: 0 | KX4: 136.46 | KY4: 62.02 | KZ4: SATISFIABLE | LA4: 8385171 | LB4: 125.593 | LC4: 61.84 | LD4: 0 | LE4: 154.04 | LF4: 85.63 | LG4: SATISFIABLE | LH4: 8385171 | LI4: 144.121 | LJ4: 85.49 | LK4: 0 | LL4: 77.79 | LM4: 0 | LN4: UNSATISFIABLE | LO4: 16770342 | LP4: 66.561 | LQ4: 0 | LR4: 0 | LS4: 116.36 | LT4: 45.31 | LU4: SATISFIABLE | LV4: 8385171 | LW4: 104.739 | LX4: 45.1 | LY4: 0 | LZ4: 480.28 | MA4: 402.26 | MB4: SATISFIABLE | MC4: 9891166 | MD4: 466.641 | ME4: 402.07 | MF4: 0 | MG4: 194.77 | MH4: 116.89 | MI4: SATISFIABLE | MJ4: 9891166 | MK4: 181.339 | ML4: 116.71 | MM4: 0 | MN4: 76.19 | MO4: 0 | MP4: UNSATISFIABLE | MQ4: 19782332 | MR4: 61.819 | MS4: 0 | MT4: 0 | MU4: 119.96 | MV4: 39.82 | MW4: SATISFIABLE | MX4: 9891166 | MY4: 106.255 | MZ4: 39.64 | NA4: 0 | NB4: 147.94 | NC4: 49.94 | ND4: SATISFIABLE | NE4: 11481386 | NF4: 126.343 | NG4: 49.71 | NH4: 0 | NI4: 162.19 | NJ4: 72.22 | NK4: SATISFIABLE | NL4: 11481386 | NM4: 147.572 | NN4: 72.01 | NO4: 0 | NP4: 89 | NQ4: 0 | NR4: UNSATISFIABLE | NS4: 22962772 | NT4: 73.688 | NU4: 0 | NV4: 0 | NW4: 145.76 | NX4: 52.32 | NY4: SATISFIABLE | NZ4: 11481386 | OA4: 132.693 | OB4: 52.14 | OC4: 0 | OD4: 40.96 | OE4: 7.09 | OF4: SATISFIABLE | OG4: 3203441 | OH4: 32.409 | OI4: 7.01 | OJ4: 0 | OK4: 40.92 | OL4: 7.08 | OM4: SATISFIABLE | ON4: 3203441 | OO4: 32.565 | OP4: 7 | OQ4: 0 | OR4: 35.51 | OS4: 5.63 | OT4: SATISFIABLE | OU4: 3203441 | OV4: 25.862 | OW4: 5.57 | OX4: 0 | OY4: 34.19 | OZ4: 5.63 | PA4: SATISFIABLE | PB4: 3203441 | PC4: 26.25 | PD4: 5.55 | PE4: 0 | PF4: 55.87 | PG4: 16.2 | PH4: SATISFIABLE | PI4: 4372536 | PJ4: 48.033 | PK4: 16.1 | PL4: 0 | PM4: 62.4 | PN4: 21.26 | PO4: SATISFIABLE | PP4: 4372536 | PQ4: 53.406 | PR4: 21.15 | PS4: 0 | PT4: 58.26 | PU4: 14.05 | PV4: SATISFIABLE | PW4: 4372536 | PX4: 48.956 | PY4: 13.94 | PZ4: 0 | QA4: 54.62 | QB4: 16.97 | QC4: SATISFIABLE | QD4: 4372536 | QE4: 46.23 | QF4: 16.87 | QG4: 0 | QH4: 51.49 | QI4: 4.64 | QJ4: SATISFIABLE | QK4: 5625856 | QL4: 42.671 | QM4: 4.54 | QN4: 0 | QO4: 58.06 | QP4: 6 | QQ4: SATISFIABLE | QR4: 5625856 | QS4: 48.316 | QT4: 5.86 | QU4: 0 | QV4: 60.65 | QW4: 6.73 | QX4: SATISFIABLE | QY4: 5625856 | QZ4: 50.984 | RA4: 6.59 | RB4: 0 | RC4: 59.62 | RD4: 5.95 | RE4: SATISFIABLE | RF4: 5625856 | RG4: 50.127 | RH4: 5.81 | RI4: 0 | RJ4: 66.87 | RK4: 7.3 | RL4: SATISFIABLE | RM4: 6963401 | RN4: 57.491 | RO4: 7.16 | RP4: 0 | RQ4: 70.71 | RR4: 7.13 | RS4: SATISFIABLE | RT4: 6963401 | RU4: 61.128 | RV4: 7 | RW4: 0 | RX4: 59.82 | RY4: 2.25 | RZ4: SATISFIABLE | SA4: 6963401 | SB4: 50.48 | SC4: 2.12 | SD4: 0 | SE4: 76 | SF4: 8.96 | SG4: SATISFIABLE | SH4: 6963401 | SI4: 65.479 | SJ4: 8.8 | SK4: 0 | SL4: 110.08 | SM4: 26.19 | SN4: SATISFIABLE | SO4: 8385171 | SP4: 98.2 | SQ4: 25.99 | SR4: 0 | SS4: 110.71 | ST4: 26.59 | SU4: SATISFIABLE | SV4: 8385171 | SW4: 98.873 | SX4: 26.39 | SY4: 0 | SZ4: 75.67 | TA4: 0 | TB4: UNSATISFIABLE | TC4: 8385171 | TD4: 64.789 | TE4: 0 | TF4: 0 | TG4: 92.59 | TH4: 8.57 | TI4: SATISFIABLE | TJ4: 8385171 | TK4: 81.225 | TL4: 8.37 | TM4: 0 | TN4: 107.92 | TO4: 28.9 | TP4: SATISFIABLE | TQ4: 9891166 | TR4: 95.777 | TS4: 28.74 | TT4: 0 | TU4: 107.82 | TV4: 28.85 | TW4: SATISFIABLE | TX4: 9891166 | TY4: 95.631 | TZ4: 28.68 | UA4: 0 | UB4: 75 | UC4: 0 | UD4: UNSATISFIABLE | UE4: 9891166 | UF4: 63.499 | UG4: 0 | UH4: 0 | UI4: 93.35 | UJ4: 13.1 | UK4: SATISFIABLE | UL4: 9891166 | UM4: 80.007 | UN4: 12.94 | UO4: 0 | UP4: 113.55 | UQ4: 22 | UR4: SATISFIABLE | US4: 11481386 | UT4: 101.425 | UU4: 21.83 | UV4: 0 | UW4: 113.93 | UX4: 21.97 | UY4: SATISFIABLE | UZ4: 11481386 | VA4: 101.154 | VB4: 21.79 | VC4: 0 | VD4: 90.42 | VE4: 0 | VF4: UNSATISFIABLE | VG4: 11481386 | VH4: 75.992 | VI4: 0 | VJ4: 0 | VK4: 105.97 | VL4: 12.86 | VM4: SATISFIABLE | VN4: 11481386 | VO4: 92.547 | VP4: 12.68 | VQ4: 0 | VR4: =MIN($B4,$I4,$P4,$W4,$AD4,$AK4,$AR4,$AY4,$BF4,$BM4,$BT4,$CA4,$CH4,$CO4,$CV4,$DC4,$DJ4,$DQ4,$DX4,$EE4,$EL4,$ES4,$EZ4,$FG4,$FN4,$FU4,$GB4,$GI4,$GP4,$GW4,$HD4,$HK4,$HR4,$HY4,$IF4,$IM4,$IT4,$JA4,$JH4,$JO4,$JV4,$KC4,$KJ4,$KQ4,$KX4,$LE4,$LL4,$LS4,$LZ4,$MG4,$MN4,$MU4,$NB4,$NI4,$NP4,$NW4,$OD4,$OK4,$OR4,$OY4,$PF4,$PM4,$PT4,$QA4,$QH4,$QO4,$QV4,$RC4,$RJ4,$RQ4,$RX4,$SE4,$SL4,$SS4,$SZ4,$TG4,$TN4,$TU4,$UB4,$UI4,$UP4,$UW4,$VD4,$VK4) -> 0 | VS4: =MIN($C4,$J4,$Q4,$X4,$AE4,$AL4,$AS4,$AZ4,$BG4,$BN4,$BU4,$CB4,$CI4,$CP4,$CW4,$DD4,$DK4,$DR4,$DY4,$EF4,$EM4,$ET4,$FA4,$FH4,$FO4,$FV4,$GC4,$GJ4,$GQ4,$GX4,$HE4,$HL4,$HS4,$HZ4,$IG4,$IN4,$IU4,$JB4,$JI4,$JP4,$JW4,$KD4,$KK4,$KR4,$KY4,$LF4,$LM4,$LT4,$MA4,$MH4,$MO4,$MV4,$NC4,$NJ4,$NQ4,$NX4,$OE4,$OL4,$OS4,$OZ4,$PG4,$PN4,$PU4,$QB4,$QI4,$QP4,$QW4,$RD4,$RK4,$RR4,$RY4,$SF4,$SM4,$ST4,$TA4,$TH4,$TO4,$TV4,$UC4,$UJ4,$UQ4,$UX4,$VE4,$VL4) -> 0 | VT4: =MIN($E4,$L4,$S4,$Z4,$AG4,$AN4,$AU4,$BB4,$BI4,$BP4,$BW4,$CD4,$CK4,$CR4,$CY4,$DF4,$DM4,$DT4,$EA4,$EH4,$EO4,$EV4,$FC4,$FJ4,$FQ4,$FX4,$GE4,$GL4,$GS4,$GZ4,$HG4,$HN4,$HU4,$IB4,$II4,$IP4,$IW4,$JD4,$JK4,$JR4,$JY4,$KF4,$KM4,$KT4,$LA4,$LH4,$LO4,$LV4,$MC4,$MJ4,$MQ4,$MX4,$NE4,$NL4,$NS4,$NZ4,$OG4,$ON4,$OU4,$PB4,$PI4,$PP4,$PW4,$QD4,$QK4,$QR4,$QY4,$RF4,$RM4,$RT4,$SA4,$SH4,$SO4,$SV4,$TC4,$TJ4,$TQ4,$TX4,$UE4,$UL4,$US4,$UZ4,$VG4,$VN4) -> 0 | VU4: =MIN($F4,$M4,$T4,$AA4,$AH4,$AO4,$AV4,$BC4,$BJ4,$BQ4,$BX4,$CE4,$CL4,$CS4,$CZ4,$DG4,$DN4,$DU4,$EB4,$EI4,$EP4,$EW4,$FD4,$FK4,$FR4,$FY4,$GF4,$GM4,$GT4,$HA4,$HH4,$HO4,$HV4,$IC4,$IJ4,$IQ4,$IX4,$JE4,$JL4,$JS4,$JZ4,$KG4,$KN4,$KU4,$LB4,$LI4,$LP4,$LW4,$MD4,$MK4,$MR4,$MY4,$NF4,$NM4,$NT4,$OA4,$OH4,$OO4,$OV4,$PC4,$PJ4,$PQ4,$PX4,$QE4,$QL4,$QS4,$QZ4,$RG4,$RN4,$RU4,$SB4,$SI4,$SP4,$SW4,$TD4,$TK4,$TR4,$TY4,$UF4,$UM4,$UT4,$VA4,$VH4,$VO4) -> 0 | VV4: =MIN($G4,$N4,$U4,$AB4,$AI4,$AP4,$AW4,$BD4,$BK4,$BR4,$BY4,$CF4,$CM4,$CT4,$DA4,$DH4,$DO4,$DV4,$EC4,$EJ4,$EQ4,$EX4,$FE4,$FL4,$FS4,$FZ4,$GG4,$GN4,$GU4,$HB4,$HI4,$HP4,$HW4,$ID4,$IK4,$IR4,$IY4,$JF4,$JM4,$JT4,$KA4,$KH4,$KO4,$KV4,$LC4,$LJ4,$LQ4,$LX4,$ME4,$ML4,$MS4,$MZ4,$NG4,$NN4,$NU4,$OB4,$OI4,$OP4,$OW4,$PD4,$PK4,$PR4,$PY4,$QF4,$QM4,$QT4,$RA4,$RH4,$RO4,$RV4,$SC4,$SJ4,$SQ4,$SX4,$TE4,$TL4,$TS4,$TZ4,$UG4,$UN4,$UU4,$VB4,$VI4,$VP4) -> 0 | VW4: =MIN($H4,$O4,$V4,$AC4,$AJ4,$AQ4,$AX4,$BE4,$BL4,$BS4,$BZ4,$CG4,$CN4,$CU4,$DB4,$DI4,$DP4,$DW4,$ED4,$EK4,$ER4,$EY4,$FF4,$FM4,$FT4,$GA4,$GH4,$GO4,$GV4,$HC4,$HJ4,$HQ4,$HX4,$IE4,$IL4,$IS4,$IZ4,$JG4,$JN4,$JU4,$KB4,$KI4,$KP4,$KW4,$LD4,$LK4,$LR4,$LY4,$MF4,$MM4,$MT4,$NA4,$NH4,$NO4,$NV4,$OC4,$OJ4,$OQ4,$OX4,$PE4,$PL4,$PS4,$PZ4,$QG4,$QN4,$QU4,$RB4,$RI4,$RP4,$RW4,$SD4,$SK4,$SR4,$SY4,$TF4,$TM4,$TT4,$UA4,$UH4,$UO4,$UV4,$VC4,$VJ4,$VQ4) -> 0 | VX4: =MEDIAN($B4,$I4,$P4,$W4,$AD4,$AK4,$AR4,$AY4,$BF4,$BM4,$BT4,$CA4,$CH4,$CO4,$CV4,$DC4,$DJ4,$DQ4,$DX4,$EE4,$EL4,$ES4,$EZ4,$FG4,$FN4,$FU4,$GB4,$GI4,$GP4,$GW4,$HD4,$HK4,$HR4,$HY4,$IF4,$IM4,$IT4,$JA4,$JH4,$JO4,$JV4,$KC4,$KJ4,$KQ4,$KX4,$LE4,$LL4,$LS4,$LZ4,$MG4,$MN4,$MU4,$NB4,$NI4,$NP4,$NW4,$OD4,$OK4,$OR4,$OY4,$PF4,$PM4,$PT4,$QA4,$QH4,$QO4,$QV4,$RC4,$RJ4,$RQ4,$RX4,$SE4,$SL4,$SS4,$SZ4,$TG4,$TN4,$TU4,$UB4,$UI4,$UP4,$UW4,$VD4,$VK4) -> 0 | VY4: =MEDIAN($C4,$J4,$Q4,$X4,$AE4,$AL4,$AS4,$AZ4,$BG4,$BN4,$BU4,$CB4,$CI4,$CP4,$CW4,$DD4,$DK4,$DR4,$DY4,$EF4,$EM4,$ET4,$FA4,$FH4,$FO4,$FV4,$GC4,$GJ4,$GQ4,$GX4,$HE4,$HL4,$HS4,$HZ4,$IG4,$IN4,$IU4,$JB4,$JI4,$JP4,$JW4,$KD4,$KK4,$KR4,$KY4,$LF4,$LM4,$LT4,$MA4,$MH4,$MO4,$MV4,$NC4,$NJ4,$NQ4,$NX4,$OE4,$OL4,$OS4,$OZ4,$PG4,$PN4,$PU4,$QB4,$QI4,$QP4,$QW4,$RD4,$RK4,$RR4,$RY4,$SF4,$SM4,$ST4,$TA4,$TH4,$TO4,$TV4,$UC4,$UJ4,$UQ4,$UX4,$VE4,$VL4) -> 0 | VZ4: =MEDIAN($E4,$L4,$S4,$Z4,$AG4,$AN4,$AU4,$BB4,$BI4,$BP4,$BW4,$CD4,$CK4,$CR4,$CY4,$DF4,$DM4,$DT4,$EA4,$EH4,$EO4,$EV4,$FC4,$FJ4,$FQ4,$FX4,$GE4,$GL4,$GS4,$GZ4,$HG4,$HN4,$HU4,$IB4,$II4,$IP4,$IW4,$JD4,$JK4,$JR4,$JY4,$KF4,$KM4,$KT4,$LA4,$LH4,$LO4,$LV4,$MC4,$MJ4,$MQ4,$MX4,$NE4,$NL4,$NS4,$NZ4,$OG4,$ON4,$OU4,$PB4,$PI4,$PP4,$PW4,$QD4,$QK4,$QR4,$QY4,$RF4,$RM4,$RT4,$SA4,$SH4,$SO4,$SV4,$TC4,$TJ4,$TQ4,$TX4,$UE4,$UL4,$US4,$UZ4,$VG4,$VN4) -> 0 | WA4: =MEDIAN($F4,$M4,$T4,$AA4,$AH4,$AO4,$AV4,$BC4,$BJ4,$BQ4,$BX4,$CE4,$CL4,$CS4,$CZ4,$DG4,$DN4,$DU4,$EB4,$EI4,$EP4,$EW4,$FD4,$FK4,$FR4,$FY4,$GF4,$GM4,$GT4,$HA4,$HH4,$HO4,$HV4,$IC4,$IJ4,$IQ4,$IX4,$JE4,$JL4,$JS4,$JZ4,$KG4,$KN4,$KU4,$LB4,$LI4,$LP4,$LW4,$MD4,$MK4,$MR4,$MY4,$NF4,$NM4,$NT4,$OA4,$OH4,$OO4,$OV4,$PC4,$PJ4,$PQ4,$PX4,$QE4,$QL4,$QS4,$QZ4,$RG4,$RN4,$RU4,$SB4,$SI4,$SP4,$SW4,$TD4,$TK4,$TR4,$TY4,$UF4,$UM4,$UT4,$VA4,$VH4,$VO4) -> 0 | WB4: =MEDIAN($G4,$N4,$U4,$AB4,$AI4,$AP4,$AW4,$BD4,$BK4,$BR4,$BY4,$CF4,$CM4,$CT4,$DA4,$DH4,$DO4,$DV4,$EC4,$EJ4,$EQ4,$EX4,$FE4,$FL4,$FS4,$FZ4,$GG4,$GN4,$GU4,$HB4,$HI4,$HP4,$HW4,$ID4,$IK4,$IR4,$IY4,$JF4,$JM4,$JT4,$KA4,$KH4,$KO4,$KV4,$LC4,$LJ4,$LQ4,$LX4,$ME4,$ML4,$MS4,$MZ4,$NG4,$NN4,$NU4,$OB4,$OI4,$OP4,$OW4,$PD4,$PK4,$PR4,$PY4,$QF4,$QM4,$QT4,$RA4,$RH4,$RO4,$RV4,$SC4,$SJ4,$SQ4,$SX4,$TE4,$TL4,$TS4,$TZ4,$UG4,$UN4,$UU4,$VB4,$VI4,$VP4) -> 0 | WC4: =MEDIAN($H4,$O4,$V4,$AC4,$AJ4,$AQ4,$AX4,$BE4,$BL4,$BS4,$BZ4,$CG4,$CN4,$CU4,$DB4,$DI4,$DP4,$DW4,$ED4,$EK4,$ER4,$EY4,$FF4,$FM4,$FT4,$GA4,$GH4,$GO4,$GV4,$HC4,$HJ4,$HQ4,$HX4,$IE4,$IL4,$IS4,$IZ4,$JG4,$JN4,$JU4,$KB4,$KI4,$KP4,$KW4,$LD4,$LK4,$LR4,$LY4,$MF4,$MM4,$MT4,$NA4,$NH4,$NO4,$NV4,$OC4,$OJ4,$OQ4,$OX4,$PE4,$PL4,$PS4,$PZ4,$QG4,$QN4,$QU4,$RB4,$RI4,$RP4,$RW4,$SD4,$SK4,$SR4,$SY4,$TF4,$TM4,$TT4,$UA4,$UH4,$UO4,$UV4,$VC4,$VJ4,$VQ4) -> 0 | WD4: =MAX($B4,$I4,$P4,$W4,$AD4,$AK4,$AR4,$AY4,$BF4,$BM4,$BT4,$CA4,$CH4,$CO4,$CV4,$DC4,$DJ4,$DQ4,$DX4,$EE4,$EL4,$ES4,$EZ4,$FG4,$FN4,$FU4,$GB4,$GI4,$GP4,$GW4,$HD4,$HK4,$HR4,$HY4,$IF4,$IM4,$IT4,$JA4,$JH4,$JO4,$JV4,$KC4,$KJ4,$KQ4,$KX4,$LE4,$LL4,$LS4,$LZ4,$MG4,$MN4,$MU4,$NB4,$NI4,$NP4,$NW4,$OD4,$OK4,$OR4,$OY4,$PF4,$PM4,$PT4,$QA4,$QH4,$QO4,$QV4,$RC4,$RJ4,$RQ4,$RX4,$SE4,$SL4,$SS4,$SZ4,$TG4,$TN4,$TU4,$UB4,$UI4,$UP4,$UW4,$VD4,$VK4) -> 0 | WE4: =MAX($C4,$J4,$Q4,$X4,$AE4,$AL4,$AS4,$AZ4,$BG4,$BN4,$BU4,$CB4,$CI4,$CP4,$CW4,$DD4,$DK4,$DR4,$DY4,$EF4,$EM4,$ET4,$FA4,$FH4,$FO4,$FV4,$GC4,$GJ4,$GQ4,$GX4,$HE4,$HL4,$HS4,$HZ4,$IG4,$IN4,$IU4,$JB4,$JI4,$JP4,$JW4,$KD4,$KK4,$KR4,$KY4,$LF4,$LM4,$LT4,$MA4,$MH4,$MO4,$MV4,$NC4,$NJ4,$NQ4,$NX4,$OE4,$OL4,$OS4,$OZ4,$PG4,$PN4,$PU4,$QB4,$QI4,$QP4,$QW4,$RD4,$RK4,$RR4,$RY4,$SF4,$SM4,$ST4,$TA4,$TH4,$TO4,$TV4,$UC4,$UJ4,$UQ4,$UX4,$VE4,$VL4) -> 0 | WF4: =MAX($E4,$L4,$S4,$Z4,$AG4,$AN4,$AU4,$BB4,$BI4,$BP4,$BW4,$CD4,$CK4,$CR4,$CY4,$DF4,$DM4,$DT4,$EA4,$EH4,$EO4,$EV4,$FC4,$FJ4,$FQ4,$FX4,$GE4,$GL4,$GS4,$GZ4,$HG4,$HN4,$HU4,$IB4,$II4,$IP4,$IW4,$JD4,$JK4,$JR4,$JY4,$KF4,$KM4,$KT4,$LA4,$LH4,$LO4,$LV4,$MC4,$MJ4,$MQ4,$MX4,$NE4,$NL4,$NS4,$NZ4,$OG4,$ON4,$OU4,$PB4,$PI4,$PP4,$PW4,$QD4,$QK4,$QR4,$QY4,$RF4,$RM4,$RT4,$SA4,$SH4,$SO4,$SV4,$TC4,$TJ4,$TQ4,$TX4,$UE4,$UL4,$US4,$UZ4,$VG4,$VN4) -> 0 | WG4: =MAX($F4,$M4,$T4,$AA4,$AH4,$AO4,$AV4,$BC4,$BJ4,$BQ4,$BX4,$CE4,$CL4,$CS4,$CZ4,$DG4,$DN4,$DU4,$EB4,$EI4,$EP4,$EW4,$FD4,$FK4,$FR4,$FY4,$GF4,$GM4,$GT4,$HA4,$HH4,$HO4,$HV4,$IC4,$IJ4,$IQ4,$IX4,$JE4,$JL4,$JS4,$JZ4,$KG4,$KN4,$KU4,$LB4,$LI4,$LP4,$LW4,$MD4,$MK4,$MR4,$MY4,$NF4,$NM4,$NT4,$OA4,$OH4,$OO4,$OV4,$PC4,$PJ4,$PQ4,$PX4,$QE4,$QL4,$QS4,$QZ4,$RG4,$RN4,$RU4,$SB4,$SI4,$SP4,$SW4,$TD4,$TK4,$TR4,$TY4,$UF4,$UM4,$UT4,$VA4,$VH4,$VO4) -> 0 | WH4: =MAX($G4,$N4,$U4,$AB4,$AI4,$AP4,$AW4,$BD4,$BK4,$BR4,$BY4,$CF4,$CM4,$CT4,$DA4,$DH4,$DO4,$DV4,$EC4,$EJ4,$EQ4,$EX4,$FE4,$FL4,$FS4,$FZ4,$GG4,$GN4,$GU4,$HB4,$HI4,$HP4,$HW4,$ID4,$IK4,$IR4,$IY4,$JF4,$JM4,$JT4,$KA4,$KH4,$KO4,$KV4,$LC4,$LJ4,$LQ4,$LX4,$ME4,$ML4,$MS4,$MZ4,$NG4,$NN4,$NU4,$OB4,$OI4,$OP4,$OW4,$PD4,$PK4,$PR4,$PY4,$QF4,$QM4,$QT4,$RA4,$RH4,$RO4,$RV4,$SC4,$SJ4,$SQ4,$SX4,$TE4,$TL4,$TS4,$TZ4,$UG4,$UN4,$UU4,$VB4,$VI4,$VP4) -> 0 | WI4: =MAX($H4,$O4,$V4,$AC4,$AJ4,$AQ4,$AX4,$BE4,$BL4,$BS4,$BZ4,$CG4,$CN4,$CU4,$DB4,$DI4,$DP4,$DW4,$ED4,$EK4,$ER4,$EY4,$FF4,$FM4,$FT4,$GA4,$GH4,$GO4,$GV4,$HC4,$HJ4,$HQ4,$HX4,$IE4,$IL4,$IS4,$IZ4,$JG4,$JN4,$JU4,$KB4,$KI4,$KP4,$KW4,$LD4,$LK4,$LR4,$LY4,$MF4,$MM4,$MT4,$NA4,$NH4,$NO4,$NV4,$OC4,$OJ4,$OQ4,$OX4,$PE4,$PL4,$PS4,$PZ4,$QG4,$QN4,$QU4,$RB4,$RI4,$RP4,$RW4,$SD4,$SK4,$SR4,$SY4,$TF4,$TM4,$TT4,$UA4,$UH4,$UO4,$UV4,$VC4,$VJ4,$VQ4) -> 0
A5: instances/warehouse_x8_y8_a3 | B5: 1200 | C5: 1173.91 | D5: UNKNOWN | E5: 10365798 | F5: 1194.545 | G5: 0 | H5: 0 | I5: 1200 | J5: 1143.66 | K5: UNKNOWN | L5: 23392948 | M5: 1193.569 | N5: 0 | O5: 0 | P5: 1200 | Q5: 1186.86 | R5: UNKNOWN | S5: 1443388 | T5: 1193.814 | U5: 0 | V5: 0 | W5: 1200 | X5: 1184.76 | Y5: UNKNOWN | Z5: 2883648 | AA5: 1193.951 | AB5: 0 | AC5: 0 | AD5: 393.14 | AE5: 341.24 | AF5: SATISFIABLE | AG5: 17448298 | AH5: 386.262 | AI5: 341.16 | AJ5: 0 | AK5: 1010.3 | AL5: 891.08 | AM5: SATISFIABLE | AN5: 40475198 | AO5: 1003.246 | AP5: 890.94 | AQ5: 0 | AR5: 17.92 | AS5: 3.87 | AT5: SATISFIABLE | AU5: 2044238 | AV5: 11.019 | AW5: 3.85 | AX5: 0 | AY5: 72.66 | AZ5: 53.33 | BA5: SATISFIABLE | BB5: 4441398 | BC5: 66.246 | BD5: 53.29 | BE5: 0 | BF5: 212.62 | BG5: 151.85 | BH5: SATISFIABLE | BI5: 25787598 | BJ5: 203.255 | BK5: 151.74 | BL5: 0 | BM5: 157.54 | BN5: 9.12 | BO5: SATISFIABLE | BP5: 61307373 | BQ5: 147.736 | BR5: 9.05 | BS5: 0 | BT5: 22.2 | BU5: 1.73 | BV5: SATISFIABLE | BW5: 2616513 | BX5: 14.858 | BY5: 1.69 | BZ5: 0 | CA5: 51.25 | CB5: 28.02 | CC5: SATISFIABLE | CD5: 6075323 | CE5: 42.86 | CF5: 27.99 | CG5: 0 | CH5: 93.13 | CI5: 11.27 | CJ5: SATISFIABLE | CK5: 35077198 | CL5: 83.205 | CM5: 11.21 | CN5: 0 | CO5: 406.14 | CP5: 192.23 | CQ5: SATISFIABLE | CR5: 85382973 | CS5: 395.801 | CT5: 192.04 | CU5: 0 | CV5: 42.29 | CW5: 19.94 | CX5: SATISFIABLE | CY5: 3133692 | CZ5: 32.823 | DA5: 19.9 | DB5: 0 | DC5: 30.93 | DD5: 3.79 | DE5: SATISFIABLE | DF5: 7678923 | DG5: 22.702 | DH5: 3.75 | DI5: 0 | DJ5: 113.58 | DK5: 8.43 | DL5: SATISFIABLE | DM5: 45031223 | DN5: 103.837 | DO5: 8.37 | DP5: 0 | DQ5: 1093.58 | DR5: 686.84 | DS5: SATISFIABLE | DT5: 112216123 | DU5: 1084 | DV5: 686.57 | DW5: 0 | DX5: 18.25 | DY5: 0 | DZ5: UNSATISFIABLE | EA5: 7118480 | EB5: 10.302 | EC5: 0 | ED5: 0 | EE5: 34.17 | EF5: 1.17 | EG5: SATISFIABLE | EH5: 9166323 | EI5: 24.838 | EJ5: 1.12 | EK5: 0 | EL5: 180.79 | EM5: 11.39 | EN5: SATISFIABLE | EO5: 55384423 | EP5: 171.928 | EQ5: 11.3 | ER5: 0 | ES5: 638.91 | ET5: 103.43 | EU5: SATISFIABLE | EV5: 141341573 | EW5: 629.286 | EX5: 103.23 | EY5: 0 | EZ5: 22.19 | FA5: 0 | FB5: UNSATISFIABLE | FC5: 7997610 | FD5: 14.349 | FE5: 0 | FF5: 0 | FG5: 71.21 | FH5: 25.22 | FI5: SATISFIABLE | FJ5: 10472273 | FK5: 62.64 | FL5: 25.15 | FM5: 0 | FN5: 215.65 | FO5: 18.85 | FP5: SATISFIABLE | FQ5: 65892173 | FR5: 206.475 | FS5: 18.75 | FT5: 0 | FU5: 669.34 | FV5: 102.42 | FW5: SATISFIABLE | FX5: 172314698 | FY5: 659.699 | FZ5: 102.22 | GA5: 0 | GB5: 23.17 | GC5: 0 | GD5: UNSATISFIABLE | GE5: 8936140 | GF5: 15.661 | GG5: 0 | GH5: 0 | GI5: 101.22 | GJ5: 49.22 | GK5: SATISFIABLE | GL5: 11552148 | GM5: 92.864 | GN5: 49.14 | GO5: 0 | GP5: 240.54 | GQ5: 227.01 | GR5: SATISFIABLE | GS5: 879920 | GT5: 233.922 | GU5: 226.96 | GV5: 0 | GW5: 313.68 | GX5: 300.12 | GY5: SATISFIABLE | GZ5: 879920 | HA5: 306.817 | HB5: 300.08 | HC5: 0 | HD5: 184.46 | HE5: 167.68 | HF5: SATISFIABLE | HG5: 879920 | HH5: 174.78 | HI5: 167.64 | HJ5: 0 | HK5: 233.63 | HL5: 219.51 | HM5: SATISFIABLE | HN5: 879920 | HO5: 226.585 | HP5: 219.47 | HQ5: 0 | HR5: 58.97 | HS5: 43.45 | HT5: SATISFIABLE | HU5: 1238230 | HV5: 51.85 | HW5: 43.4 | HX5: 0 | HY5: 23.32 | HZ5: 7.92 | IA5: SATISFIABLE | IB5: 1238230 | IC5: 16.164 | ID5: 7.87 | IE5: 0 | IF5: 40.9 | IG5: 25.55 | IH5: SATISFIABLE | II5: 1238230 | IJ5: 33.624 | IK5: 25.5 | IL5: 0 | IM5: 37.91 | IN5: 21.42 | IO5: SATISFIABLE | IP5: 1238230 | IQ5: 30.468 | IR5: 21.36 | IS5: 0 | IT5: 28.34 | IU5: 7.77 | IV5: SATISFIABLE | IW5: 1636665 | IX5: 19.091 | IY5: 7.72 | IZ5: 0 | JA5: 34.19 | JB5: 14.01 | JC5: SATISFIABLE | JD5: 1636665 | JE5: 26.695 | JF5: 13.94 | JG5: 0 | JH5: 22.64 | JI5: 2 | JJ5: SATISFIABLE | JK5: 1636665 | JL5: 14.964 | JM5: 1.93 | JN5: 0 | JO5: 32.97 | JP5: 11.78 | JQ5: SATISFIABLE | JR5: 1636665 | JS5: 24.431 | JT5: 11.71 | JU5: 0 | JV5: 25.61 | JW5: 4.13 | JX5: SATISFIABLE | JY5: 2075225 | JZ5: 18.451 | KA5: 4.06 | KB5: 0 | KC5: 27.48 | KD5: 7.14 | KE5: SATISFIABLE | KF5: 2075225 | KG5: 20.754 | KH5: 7.07 | KI5: 0 | KJ5: 24.44 | KK5: 2.24 | KL5: SATISFIABLE | KM5: 2075225 | KN5: 17.254 | KO5: 2.18 | KP5: 0 | KQ5: 38.69 | KR5: 18.73 | KS5: SATISFIABLE | KT5: 2075225 | KU5: 31.784 | KV5: 18.66 | KW5: 0 | KX5: 77.2 | KY5: 50.83 | KZ5: SATISFIABLE | LA5: 2553910 | LB5: 69.45 | LC5: 50.73 | LD5: 0 | LE5: 29.03 | LF5: 3.9 | LG5: SATISFIABLE | LH5: 2553910 | LI5: 21.824 | LJ5: 3.81 | LK5: 0 | LL5: 27.94 | LM5: 0 | LN5: UNSATISFIABLE | LO5: 5107820 | LP5: 20.205 | LQ5: 0 | LR5: 0 | LS5: 53.86 | LT5: 28.3 | LU5: SATISFIABLE | LV5: 2553910 | LW5: 46.585 | LX5: 28.22 | LY5: 0 | LZ5: 183.01 | MA5: 153.79 | MB5: SATISFIABLE | MC5: 3072720 | MD5: 173.822 | ME5: 153.7 | MF5: 0 | MG5: 78.98 | MH5: 47.9 | MI5: SATISFIABLE | MJ5: 3072720 | MK5: 67.929 | ML5: 47.82 | MM5: 0 | MN5: 30.12 | MO5: 0 | MP5: UNSATISFIABLE | MQ5: 6145440 | MR5: 18.913 | MS5: 0 | MT5: 0 | MU5: 36.98 | MV5: 5.41 | MW5: SATISFIABLE | MX5: 3072720 | MY5: 26.249 | MZ5: 5.33 | NA5: 0 | NB5: 107.73 | NC5: 71.73 | ND5: SATISFIABLE | NE5: 3631655 | NF5: 96.714 | NG5: 71.63 | NH5: 0 | NI5: 59.07 | NJ5: 24.62 | NK5: SATISFIABLE | NL5: 3631655 | NM5: 49.55 | NN5: 24.52 | NO5: 0 | NP5: 32.66 | NQ5: 0 | NR5: UNSATISFIABLE | NS5: 7263310 | NT5: 23.532 | NU5: 0 | NV5: 0 | NW5: 46.56 | NX5: 8.43 | NY5: SATISFIABLE | NZ5: 3631655 | OA5: 35.525 | OB5: 8.34 | OC5: 0 | OD5: 19.35 | OE5: 6.47 | OF5: SATISFIABLE | OG5: 879920 | OH5: 12.375 | OI5: 6.43 | OJ5: 0 | OK5: 20.21 | OL5: 6.48 | OM5: SATISFIABLE | ON5: 879920 | OO5: 13.427 | OP5: 6.44 | OQ5: 0 | OR5: 25.97 | OS5: 10.37 | OT5: SATISFIABLE | OU5: 879920 | OV5: 15.962 | OW5: 10.33 | OX5: 0 | OY5: 19.41 | OZ5: 5.05 | PA5: SATISFIABLE | PB5: 879920 | PC5: 10.828 | PD5: 5.02 | PE5: 0 | PF5: 23.31 | PG5: 7.63 | PH5: SATISFIABLE | PI5: 1238230 | PJ5: 16.791 | PK5: 7.59 | PL5: 0 | PM5: 22.81 | PN5: 8.06 | PO5: SATISFIABLE | PP5: 1238230 | PQ5: 15.565 | PR5: 8.01 | PS5: 0 | PT5: 26.24 | PU5: 8.96 | PV5: SATISFIABLE | PW5: 1238230 | PX5: 18.702 | PY5: 8.9 | PZ5: 0 | QA5: 23.31 | QB5: 7.98 | QC5: SATISFIABLE | QD5: 1238230 | QE5: 16.16 | QF5: 7.94 | QG5: 0 | QH5: 51.09 | QI5: 30.31 | QJ5: SATISFIABLE | QK5: 1636665 | QL5: 43.382 | QM5: 30.25 | QN5: 0 | QO5: 41.15 | QP5: 22.9 | QQ5: SATISFIABLE | QR5: 1636665 | QS5: 33.823 | QT5: 22.85 | QU5: 0 | QV5: 33.33 | QW5: 12.42 | QX5: SATISFIABLE | QY5: 1636665 | QZ5: 25.593 | RA5: 12.36 | RB5: 0 | RC5: 52.46 | RD5: 31.39 | RE5: SATISFIABLE | RF5: 1636665 | RG5: 44.622 | RH5: 31.32 | RI5: 0 | RJ5: 32.81 | RK5: 11.25 | RL5: SATISFIABLE | RM5: 2075225 | RN5: 25.47 | RO5: 11.19 | RP5: 0 | RQ5: 35.07 | RR5: 12.81 | RS5: SATISFIABLE | RT5: 2075225 | RU5: 27.537 | RV5: 12.73 | RW5: 0 | RX5: 22.43 | RY5: 0.87 | RZ5: SATISFIABLE | SA5: 2075225 | SB5: 15.03 | SC5: 0.8 | SD5: 0 | SE5: 58.18 | SF5: 35.77 | SG5: SATISFIABLE | SH5: 2075225 | SI5: 50.608 | SJ5: 35.69 | SK5: 0 | SL5: 45.04 | SM5: 14.34 | SN5: SATISFIABLE | SO5: 2553910 | SP5: 36.768 | SQ5: 14.24 | SR5: 0 | SS5: 44.46 | ST5: 14.44 | SU5: SATISFIABLE | SV5: 2553910 | SW5: 36.659 | SX5: 14.34 | SY5: 0 | SZ5: 27.24 | TA5: 0 | TB5: UNSATISFIABLE | TC5: 2553910 | TD5: 18.951 | TE5: 0 | TF5: 0 | TG5: 38.69 | TH5: 7.71 | TI5: SATISFIABLE | TJ5: 2553910 | TK5: 30.342 | TL5: 7.61 | TM5: 0 | TN5: 38.11 | TO5: 8.49 | TP5: SATISFIABLE | TQ5: 3072720 | TR5: 29.614 | TS5: 8.41 | TT5: 0 | TU5: 39.66 | TV5: 8.47 | TW5: SATISFIABLE | TX5: 3072720 | TY5: 29.639 | TZ5: 8.39 | UA5: 0 | UB5: 30.96 | UC5: 0 | UD5: UNSATISFIABLE | UE5: 3072720 | UF5: 19.977 | UG5: 0 | UH5: 0 | UI5: 31.72 | UJ5: 0.83 | UK5: SATISFIABLE | UL5: 3072720 | UM5: 21.952 | UN5: 0.75 | UO5: 0 | UP5: 50.06 | UQ5: 14.62 | UR5: SATISFIABLE | US5: 3631655 | UT5: 41.172 | UU5: 14.53 | UV5: 0 | UW5: 50.01 | UX5: 14.62 | UY5: SATISFIABLE | UZ5: 3631655 | VA5: 41.199 | VB5: 14.53 | VC5: 0 | VD5: 36.23 | VE5: 0 | VF5: UNSATISFIABLE | VG5: 3631655 | VH5: 24.902 | VI5: 0 | VJ5: 0 | VK5: 40.86 | VL5: 5.18 | VM5: SATISFIABLE | VN5: 3631655 | VO5: 31.73 | VP5: 5.09 | VQ5: 0 | VR5: =MIN($B5,$I5,$P5,$W5,$AD5,$AK5,$AR5,$AY5,$BF5,$BM5,$BT5,$CA5,$CH5,$CO5,$CV5,$DC5,$DJ5,$DQ5,$DX5,$EE5,$EL5,$ES5,$EZ5,$FG5,$FN5,$FU5,$GB5,$GI5,$GP5,$GW5,$HD5,$HK5,$HR5,$HY5,$IF5,$IM5,$IT5,$JA5,$JH5,$JO5,$JV5,$KC5,$KJ5,$KQ5,$KX5,$LE5,$LL5,$LS5,$LZ5,$MG5,$MN5,$MU5,$NB5,$NI5,$NP5,$NW5,$OD5,$OK5,$OR5,$OY5,$PF5,$PM5,$PT5,$QA5,$QH5,$QO5,$QV5,$RC5,$RJ5,$RQ5,$RX5,$SE5,$SL5,$SS5,$SZ5,$TG5,$TN5,$TU5,$UB5,$UI5,$UP5,$UW5,$VD5,$VK5) -> 0 | VS5: =MIN($C5,$J5,$Q5,$X5,$AE5,$AL5,$AS5,$AZ5,$BG5,$BN5,$BU5,$CB5,$CI5,$CP5,$CW5,$DD5,$DK5,$DR5,$DY5,$EF5,$EM5,$ET5,$FA5,$FH5,$FO5,$FV5,$GC5,$GJ5,$GQ5,$GX5,$HE5,$HL5,$HS5,$HZ5,$IG5,$IN5,$IU5,$JB5,$JI5,$JP5,$JW5,$KD5,$KK5,$KR5,$KY5,$LF5,$LM5,$LT5,$MA5,$MH5,$MO5,$MV5,$NC5,$NJ5,$NQ5,$NX5,$OE5,$OL5,$OS5,$OZ5,$PG5,$PN5,$PU5,$QB5,$QI5,$QP5,$QW5,$RD5,$RK5,$RR5,$RY5,$SF5,$SM5,$ST5,$TA5,$TH5,$TO5,$TV5,$UC5,$UJ5,$UQ5,$UX5,$VE5,$VL5) -> 0 | VT5: =MIN($E5,$L5,$S5,$Z5,$AG5,$AN5,$AU5,$BB5,$BI5,$BP5,$BW5,$CD5,$CK5,$CR5,$CY5,$DF5,$DM5,$DT5,$EA5,$EH5,$EO5,$EV5,$FC5,$FJ5,$FQ5,$FX5,$GE5,$GL5,$GS5,$GZ5,$HG5,$HN5,$HU5,$IB5,$II5,$IP5,$IW5,$JD5,$JK5,$JR5,$JY5,$KF5,$KM5,$KT5,$LA5,$LH5,$LO5,$LV5,$MC5,$MJ5,$MQ5,$MX5,$NE5,$NL5,$NS5,$NZ5,$OG5,$ON5,$OU5,$PB5,$PI5,$PP5,$PW5,$QD5,$QK5,$QR5,$QY5,$RF5,$RM5,$RT5,$SA5,$SH5,$SO5,$SV5,$TC5,$TJ5,$TQ5,$TX5,$UE5,$UL5,$US5,$UZ5,$VG5,$VN5) -> 0 | VU5: =MIN($F5,$M5,$T5,$AA5,$AH5,$AO5,$AV5,$BC5,$BJ5,$BQ5,$BX5,$CE5,$CL5,$CS5,$CZ5,$DG5,$DN5,$DU5,$EB5,$EI5,$EP5,$EW5,$FD5,$FK5,$FR5,$FY5,$GF5,$GM5,$GT5,$HA5,$HH5,$HO5,$HV5,$IC5,$IJ5,$IQ5,$IX5,$JE5,$JL5,$JS5,$JZ5,$KG5,$KN5,$KU5,$LB5,$LI5,$LP5,$LW5,$MD5,$MK5,$MR5,$MY5,$NF5,$NM5,$NT5,$OA5,$OH5,$OO5,$OV5,$PC5,$PJ5,$PQ5,$PX5,$QE5,$QL5,$QS5,$QZ5,$RG5,$RN5,$RU5,$SB5,$SI5,$SP5,$SW5,$TD5,$TK5,$TR5,$TY5,$UF5,$UM5,$UT5,$VA5,$VH5,$VO5) -> 0 | VV5: =MIN($G5,$N5,$U5,$AB5,$AI5,$AP5,$AW5,$BD5,$BK5,$BR5,$BY5,$CF5,$CM5,$CT5,$DA5,$DH5,$DO5,$DV5,$EC5,$EJ5,$EQ5,$EX5,$FE5,$FL5,$FS5,$FZ5,$GG5,$GN5,$GU5,$HB5,$HI5,$HP5,$HW5,$ID5,$IK5,$IR5,$IY5,$JF5,$JM5,$JT5,$KA5,$KH5,$KO5,$KV5,$LC5,$LJ5,$LQ5,$LX5,$ME5,$ML5,$MS5,$MZ5,$NG5,$NN5,$NU5,$OB5,$OI5,$OP5,$OW5,$PD5,$PK5,$PR5,$PY5,$QF5,$QM5,$QT5,$RA5,$RH5,$RO5,$RV5,$SC5,$SJ5,$SQ5,$SX5,$TE5,$TL5,$TS5,$TZ5,$UG5,$UN5,$UU5,$VB5,$VI5,$VP5) -> 0 | VW5: =MIN($H5,$O5,$V5,$AC5,$AJ5,$AQ5,$AX5,$BE5,$BL5,$BS5,$BZ5,$CG5,$CN5,$CU5,$DB5,$DI5,$DP5,$DW5,$ED5,$EK5,$ER5,$EY5,$FF5,$FM5,$FT5,$GA5,$GH5,$GO5,$GV5,$HC5,$HJ5,$HQ5,$HX5,$IE5,$IL5,$IS5,$IZ5,$JG5,$JN5,$JU5,$KB5,$KI5,$KP5,$KW5,$LD5,$LK5,$LR5,$LY5,$MF5,$MM5,$MT5,$NA5,$NH5,$NO5,$NV5,$OC5,$OJ5,$OQ5,$OX5,$PE5,$PL5,$PS5,$PZ5,$QG5,$QN5,$QU5,$RB5,$RI5,$RP5,$RW5,$SD5,$SK5,$SR5,$SY5,$TF5,$TM5,$TT5,$UA5,$UH5,$UO5,$UV5,$VC5,$VJ5,$VQ5) -> 0 | VX5: =MEDIAN($B5,$I5,$P5,$W5,$AD5,$AK5,$AR5,$AY5,$BF5,$BM5,$BT5,$CA5,$CH5,$CO5,$CV5,$DC5,$DJ5,$DQ5,$DX5,$EE5,$EL5,$ES5,$EZ5,$FG5,$FN5,$FU5,$GB5,$GI5,$GP5,$GW5,$HD5,$HK5,$HR5,$HY5,$IF5,$IM5,$IT5,$JA5,$JH5,$JO5,$JV5,$KC5,$KJ5,$KQ5,$KX5,$LE5,$LL5,$LS5,$LZ5,$MG5,$MN5,$MU5,$NB5,$NI5,$NP5,$NW5,$OD5,$OK5,$OR5,$OY5,$PF5,$PM5,$PT5,$QA5,$QH5,$QO5,$QV5,$RC5,$RJ5,$RQ5,$RX5,$SE5,$SL5,$SS5,$SZ5,$TG5,$TN5,$TU5,$UB5,$UI5,$UP5,$UW5,$VD5,$VK5) -> 0 | VY5: =MEDIAN($C5,$J5,$Q5,$X5,$AE5,$AL5,$AS5,$AZ5,$BG5,$BN5,$BU5,$CB5,$CI5,$CP5,$CW5,$DD5,$DK5,$DR5,$DY5,$EF5,$EM5,$ET5,$FA5,$FH5,$FO5,$FV5,$GC5,$GJ5,$GQ5,$GX5,$HE5,$HL5,$HS5,$HZ5,$IG5,$IN5,$IU5,$JB5,$JI5,$JP5,$JW5,$KD5,$KK5,$KR5,$KY5,$LF5,$LM5,$LT5,$MA5,$MH5,$MO5,$MV5,$NC5,$NJ5,$NQ5,$NX5,$OE5,$OL5,$OS5,$OZ5,$PG5,$PN5,$PU5,$QB5,$QI5,$QP5,$QW5,$RD5,$RK5,$RR5,$RY5,$SF5,$SM5,$ST5,$TA5,$TH5,$TO5,$TV5,$UC5,$UJ5,$UQ5,$UX5,$VE5,$VL5) -> 0 | VZ5: =MEDIAN($E5,$L5,$S5,$Z5,$AG5,$AN5,$AU5,$BB5,$BI5,$BP5,$BW5,$CD5,$CK5,$CR5,$CY5,$DF5,$DM5,$DT5,$EA5,$EH5,$EO5,$EV5,$FC5,$FJ5,$FQ5,$FX5,$GE5,$GL5,$GS5,$GZ5,$HG5,$HN5,$HU5,$IB5,$II5,$IP5,$IW5,$JD5,$JK5,$JR5,$JY5,$KF5,$KM5,$KT5,$LA5,$LH5,$LO5,$LV5,$MC5,$MJ5,$MQ5,$MX5,$NE5,$NL5,$NS5,$NZ5,$OG5,$ON5,$OU5,$PB5,$PI5,$PP5,$PW5,$QD5,$QK5,$QR5,$QY5,$RF5,$RM5,$RT5,$SA5,$SH5,$SO5,$SV5,$TC5,$TJ5,$TQ5,$TX5,$UE5,$UL5,$US5,$UZ5,$VG5,$VN5) -> 0 | WA5: =MEDIAN($F5,$M5,$T5,$AA5,$AH5,$AO5,$AV5,$BC5,$BJ5,$BQ5,$BX5,$CE5,$CL5,$CS5,$CZ5,$DG5,$DN5,$DU5,$EB5,$EI5,$EP5,$EW5,$FD5,$FK5,$FR5,$FY5,$GF5,$GM5,$GT5,$HA5,$HH5,$HO5,$HV5,$IC5,$IJ5,$IQ5,$IX5,$JE5,$JL5,$JS5,$JZ5,$KG5,$KN5,$KU5,$LB5,$LI5,$LP5,$LW5,$MD5,$MK5,$MR5,$MY5,$NF5,$NM5,$NT5,$OA5,$OH5,$OO5,$OV5,$PC5,$PJ5,$PQ5,$PX5,$QE5,$QL5,$QS5,$QZ5,$RG5,$RN5,$RU5,$SB5,$SI5,$SP5,$SW5,$TD5,$TK5,$TR5,$TY5,$UF5,$UM5,$UT5,$VA5,$VH5,$VO5) -> 0 | WB5: =MEDIAN($G5,$N5,$U5,$AB5,$AI5,$AP5,$AW5,$BD5,$BK5,$BR5,$BY5,$CF5,$CM5,$CT5,$DA5,$DH5,$DO5,$DV5,$EC5,$EJ5,$EQ5,$EX5,$FE5,$FL5,$FS5,$FZ5,$GG5,$GN5,$GU5,$HB5,$HI5,$HP5,$HW5,$ID5,$IK5,$IR5,$IY5,$JF5,$JM5,$JT5,$KA5,$KH5,$KO5,$KV5,$LC5,$LJ5,$LQ5,$LX5,$ME5,$ML5,$MS5,$MZ5,$NG5,$NN5,$NU5,$OB5,$OI5,$OP5,$OW5,$PD5,$PK5,$PR5,$PY5,$QF5,$QM5,$QT5,$RA5,$RH5,$RO5,$RV5,$SC5,$SJ5,$SQ5,$SX5,$TE5,$TL5,$TS5,$TZ5,$UG5,$UN5,$UU5,$VB5,$VI5,$VP5) -> 0 | WC5: =MEDIAN($H5,$O5,$V5,$AC5,$AJ5,$AQ5,$AX5,$BE5,$BL5,$BS5,$BZ5,$CG5,$CN5,$CU5,$DB5,$DI5,$DP5,$DW5,$ED5,$EK5,$ER5,$EY5,$FF5,$FM5,$FT5,$GA5,$GH5,$GO5,$GV5,$HC5,$HJ5,$HQ5,$HX5,$IE5,$IL5,$IS5,$IZ5,$JG5,$JN5,$JU5,$KB5,$KI5,$KP5,$KW5,$LD5,$LK5,$LR5,$LY5,$MF5,$MM5,$MT5,$NA5,$NH5,$NO5,$NV5,$OC5,$OJ5,$OQ5,$OX5,$PE5,$PL5,$PS5,$PZ5,$QG5,$QN5,$QU5,$RB5,$RI5,$RP5,$RW5,$SD5,$SK5,$SR5,$SY5,$TF5,$TM5,$TT5,$UA5,$UH5,$UO5,$UV5,$VC5,$VJ5,$VQ5) -> 0 | WD5: =MAX($B5,$I5,$P5,$W5,$AD5,$AK5,$AR5,$AY5,$BF5,$BM5,$BT5,$CA5,$CH5,$CO5,$CV5,$DC5,$DJ5,$DQ5,$DX5,$EE5,$EL5,$ES5,$EZ5,$FG5,$FN5,$FU5,$GB5,$GI5,$GP5,$GW5,$HD5,$HK5,$HR5,$HY5,$IF5,$IM5,$IT5,$JA5,$JH5,$JO5,$JV5,$KC5,$KJ5,$KQ5,$KX5,$LE5,$LL5,$LS5,$LZ5,$MG5,$MN5,$MU5,$NB5,$NI5,$NP5,$NW5,$OD5,$OK5,$OR5,$OY5,$PF5,$PM5,$PT5,$QA5,$QH5,$QO5,$QV5,$RC5,$RJ5,$RQ5,$RX5,$SE5,$SL5,$SS5,$SZ5,$TG5,$TN5,$TU5,$UB5,$UI5,$UP5,$UW5,$VD5,$VK5) -> 0 | WE5: =MAX($C5,$J5,$Q5,$X5,$AE5,$AL5,$AS5,$AZ5,$BG5,$BN5,$BU5,$CB5,$CI5,$CP5,$CW5,$DD5,$DK5,$DR5,$DY5,$EF5,$EM5,$ET5,$FA5,$FH5,$FO5,$FV5,$GC5,$GJ5,$GQ5,$GX5,$HE5,$HL5,$HS5,$HZ5,$IG5,$IN5,$IU5,$JB5,$JI5,$JP5,$JW5,$KD5,$KK5,$KR5,$KY5,$LF5,$LM5,$LT5,$MA5,$MH5,$MO5,$MV5,$NC5,$NJ5,$NQ5,$NX5,$OE5,$OL5,$OS5,$OZ5,$PG5,$PN5,$PU5,$QB5,$QI5,$QP5,$QW5,$RD5,$RK5,$RR5,$RY5,$SF5,$SM5,$ST5,$TA5,$TH5,$TO5,$TV5,$UC5,$UJ5,$UQ5,$UX5,$VE5,$VL5) -> 0 | WF5: =MAX($E5,$L5,$S5,$Z5,$AG5,$AN5,$AU5,$BB5,$BI5,$BP5,$BW5,$CD5,$CK5,$CR5,$CY5,$DF5,$DM5,$DT5,$EA5,$EH5,$EO5,$EV5,$FC5,$FJ5,$FQ5,$FX5,$GE5,$GL5,$GS5,$GZ5,$HG5,$HN5,$HU5,$IB5,$II5,$IP5,$IW5,$JD5,$JK5,$JR5,$JY5,$KF5,$KM5,$KT5,$LA5,$LH5,$LO5,$LV5,$MC5,$MJ5,$MQ5,$MX5,$NE5,$NL5,$NS5,$NZ5,$OG5,$ON5,$OU5,$PB5,$PI5,$PP5,$PW5,$QD5,$QK5,$QR5,$QY5,$RF5,$RM5,$RT5,$SA5,$SH5,$SO5,$SV5,$TC5,$TJ5,$TQ5,$TX5,$UE5,$UL5,$US5,$UZ5,$VG5,$VN5) -> 0 | WG5: =MAX($F5,$M5,$T5,$AA5,$AH5,$AO5,$AV5,$BC5,$BJ5,$BQ5,$BX5,$CE5,$CL5,$CS5,$CZ5,$DG5,$DN5,$DU5,$EB5,$EI5,$EP5,$EW5,$FD5,$FK5,$FR5,$FY5,$GF5,$GM5,$GT5,$HA5,$HH5,$HO5,$HV5,$IC5,$IJ5,$IQ5,$IX5,$JE5,$JL5,$JS5,$JZ5,$KG5,$KN5,$KU5,$LB5,$LI5,$LP5,$LW5,$MD5,$MK5,$MR5,$MY5,$NF5,$NM5,$NT5,$OA5,$OH5,$OO5,$OV5,$PC5,$PJ5,$PQ5,$PX5,$QE5,$QL5,$QS5,$QZ5,$RG5,$RN5,$RU5,$SB5,$SI5,$SP5,$SW5,$TD5,$TK5,$TR5,$TY5,$UF5,$UM5,$UT5,$VA5,$VH5,$VO5) -> 0 | WH5: =MAX($G5,$N5,$U5,$AB5,$AI5,$AP5,$AW5,$BD5,$BK5,$BR5,$BY5,$CF5,$CM5,$CT5,$DA5,$DH5,$DO5,$DV5,$EC5,$EJ5,$EQ5,$EX5,$FE5,$FL5,$FS5,$FZ5,$GG5,$GN5,$GU5,$HB5,$HI5,$HP5,$HW5,$ID5,$IK5,$IR5,$IY5,$JF5,$JM5,$JT5,$KA5,$KH5,$KO5,$KV5,$LC5,$LJ5,$LQ5,$LX5,$ME5,$ML5,$MS5,$MZ5,$NG5,$NN5,$NU5,$OB5,$OI5,$OP5,$OW5,$PD5,$PK5,$PR5,$PY5,$QF5,$QM5,$QT5,$RA5,$RH5,$RO5,$RV5,$SC5,$SJ5,$SQ5,$SX5,$TE5,$TL5,$TS5,$TZ5,$UG5,$UN5,$UU5,$VB5,$VI5,$VP5) -> 0 | WI5: =MAX($H5,$O5,$V5,$AC5,$AJ5,$AQ5,$AX5,$BE5,$BL5,$BS5,$BZ5,$CG5,$CN5,$CU5,$DB5,$DI5,$DP5,$DW5,$ED5,$EK5,$ER5,$EY5,$FF5,$FM5,$FT5,$GA5,$GH5,$GO5,$GV5,$HC5,$HJ5,$HQ5,$HX5,$IE5,$IL5,$IS5,$IZ5,$JG5,$JN5,$JU5,$KB5,$KI5,$KP5,$KW5,$LD5,$LK5,$LR5,$LY5,$MF5,$MM5,$MT5,$NA5,$NH5,$NO5,$NV5,$OC5,$OJ5,$OQ5,$OX5,$PE5,$PL5,$PS5,$PZ5,$QG5,$QN5,$QU5,$RB5,$RI5,$RP5,$RW5,$SD5,$SK5,$SR5,$SY5,$TF5,$TM5,$TT5,$UA5,$UH5,$UO5,$UV5,$VC5,$VJ5,$VQ5) -> 0
